Workbook
Name aa: #REF!
Name aaa: #REF!
Name aaaaa: #REF!
Name aaaaaaa: #REF!
Name asd: '[1]Market ( Mar) '!#REF!
Name atr: #REF!
Name b: #REF!
Name bb: #REF!
Name Beg_Bal: #REF!
Name Cash_Cr: #REF!
Name Cash_Dr: #REF!
Name cc: #REF!
Name ccc: #REF!
Name cft: #REF!
Name cr: #REF!
Name crs: #REF!
Name cvvvv: #REF!
Name cwer: #REF!
Name Data: #REF!
Name dd: #REF!
Name ddd: #REF!
Name dddd: #N/A
Name dr: #REF!
Name drs: #REF!
Name dsfas: #REF!
Name eeee: #REF!
Name End_Bal: #REF!
Name Extra_Pay: #REF!
Name fgf: #REF!
Name fgjhj: #REF!
Name ftyu: #REF!
Name Full_Print: #REF!
Name fusales4: #REF!
Name gg: #REF!
Name gggggg: #REF!
Name Header_Row: ROW(#REF!)
Name hjj: #REF!
Name hjjj: #REF!
Name hjkjk: #REF!
Name hmjhj: #REF!
Name ii: #REF!
Name III: #REF!
Name Int: #REF!
Name Interest_Rate: #REF!
Name jbkjkl: #REF!
Name Journal_Cr: #REF!
Name Journal_Dr: #REF!
Name kdt: #REF!
Name Last_Row: IF(Values_Entered,Header_Row+Number_of_Payments,Header_Row)
Name Loan_Amount: #REF!
Name Loan_Start: #REF!
Name Loan_Years: #REF!
Name LSO: #REF!
Name lsoq: #REF!
Name lsoq1: #REF!
Name mms: #REF!
Name neew: #REF!
Name New: #REF!
Name NOV: #REF!
Name Num_Pmt_Per_Year: #REF!

Sheet 2026-FUS
A1: Meiktila Market - Wholesales List ( 2026 - January)
G2: 1st Jan | J2: 2nd Jan | M2: 3rd Jan | P2: 4th Jan | S2: 5th Jan | V2: 6th Jan | Y2: 7th Jan | AB2: 8th Jan | AE2: 9th Jan | AH2: 10th Jan | AK2: 10-Days | AN2: 45668 | AQ2: 45669 | AT2: 45670 | AW2: 45671 | AZ2: 45672 | BC2: 45673 | BF2: 45674 | BI2: 45675 | BL2: 45676 | BO2: 45677 | BR2: 20-days | BU2: 45678 | BX2: 45679 | CA2: 45680 | CD2: 45681 | CG2: 45682 | CJ2: 45683 | CM2: 45684 | CP2: 45685 | CS2: 45686 | CV2: 45687 | CY2: 45688 | DB2: Month Till Date
A3: Sr No. | B3: Customer Name | D3: Area | F3: Outlet Type | G3: PKT | H3: BOT | I3: Lit | J3: PKT | K3: BOT | L3: Lit | M3: PKT | N3: BOT | O3: Lit | P3: PKT | Q3: BOT | R3: Lit | S3: PKT | T3: BOT | U3: Lit | V3: PKT | W3: BOT | X3: Lit | Y3: PKT | Z3: BOT | AA3: Lit | AB3: PKT | AC3: BOT | AD3: Lit | AE3: PKT | AF3: BOT | AG3: Lit | AH3: PKT | AI3: BOT | AJ3: Lit | AK3: PKT | AL3: BOT | AM3: Lit | AN3: PKT | AO3: BOT | AP3: Lit | AQ3: PKT | AR3: BOT | AS3: Lit | AT3: PKT | AU3: BOT | AV3: Lit | AW3: PKT | AX3: BOT | AY3: Lit | AZ3: PKT | BA3: BOT | BB3: Lit | BC3: PKT | BD3: BOT | BE3: Lit | BF3: PKT | BG3: BOT | BH3: Lit | BI3: PKT | BJ3: BOT | BK3: Lit | BL3: PKT | BM3: BOT | BN3: Lit | BO3: PKT | BP3: BOT | BQ3: Lit | BR3: PKT | BT3: Lit | BU3: PKT | BV3: BOT | BW3: Lit | BX3: PKT | BY3: BOT | BZ3: Lit | CA3: PKT | CB3: BOT | CC3: Lit | CD3: PKT | CE3: BOT | CF3: Lit | CG3: PKT | CH3: BOT | CI3: Lit | CJ3: PKT | CK3: BOT | CL3: Lit | CM3: PKT | CN3: BOT | CO3: Lit | CP3: PKT | CQ3: BOT | CR3: Lit | CS3: PKT | CT3: BOT | CU3: Lit | CV3: PKT | CW3: BOT | CX3: Lit | CY3: PKT | CZ3: BOT | DA3: Lit | DB3: PKT | DC3: BOT | DD3: Lit
A4: 1 | B4: ရွှေမြင်း | C4: Golden Horse | D4: မိတ္ထီလာ | E4: Meikhtila | F4: Wholesale | M4: 470 | N4: 8240 | O4: 5792 | S4: 573 | T4: 9022 | U4: 6206.08 | V4: 370 | W4: 6160 | X4: 4417.6 | Y4: 486 | Z4: 7444 | AA4: 4893.76 | AB4: 160 | AC4: 2740 | AD4: 1753.6 | AE4: 259 | AF4: 3946 | AG4: 2878.24 | AH4: 170 | AI4: 2780 | AJ4: 1779.2 | AK4: =AH4+AE4+AB4+Y4+V4+S4+P4+M4+J4+G4 -> 2488 | AL4: =AI4+AF4+AC4+Z4+W4+T4+Q4+N4+K4+H4 -> 40332 | AM4: =AJ4+AG4+AD4+AA4+X4+U4+R4+O4+L4+I4 -> 27720.48 | AQ4: 565 | AR4: 9740 | AS4: 6708.8 | AT4: 630 | AU4: 10200 | AV4: 6571.2 | AW4: 320 | AX4: 6480 | AY4: 4147.2 | AZ4: 170 | BA4: 2930 | BB4: 1875.2 | BC4: 300 | BD4: 4790 | BE4: 3195.2 | BF4: 50 | BG4: 1000 | BH4: 640 | BL4: 635 | BM4: 10870 | BN4: 7432 | BO4: 340 | BP4: 5360 | BQ4: 3646.4 | BR4: =BO4+BL4+BI4+BF4+BC4+AZ4+AW4+AT4+AQ4+AN4+AK4 -> 5498 | BS4: =BP4+BM4+BJ4+BG4+BD4+BA4+AX4+AU4+AR4+AO4+AL4 -> 91702 | BT4: =BQ4+BN4+BK4+BH4+BE4+BB4+AY4+AV4+AS4+AP4+AM4 -> 61936.48 | BU4: 235 | BV4: 3620 | BW4: 2360 | BX4: 288 | BY4: 4892 | BZ4: 3217.28 | CA4: 290 | CB4: 4960 | CC4: 3354.4 | CD4: 179 | CE4: 3206 | CF4: 2051.84 | CJ4: 433 | CK4: 7012 | CL4: 4660.48 | CM4: 530 | CN4: 7800 | CO4: 5215.2 | CP4: 160 | CQ4: 3000 | CR4: 2006.4 | CS4: 380 | CT4: 5240 | CU4: 3526.4 | CV4: 230 | CW4: 3780 | CX4: 2505.6 | CY4: 470 | CZ4: 8280 | DA4: 5515.2 | DB4: =CY4+CV4+CS4+CP4+CM4+CJ4+CG4+CD4+CA4+BX4+BU4+BR4 -> 8693 | DC4: =CZ4+CW4+CT4+CQ4+CN4+CK4+CH4+CE4+CB4+BY4+BV4+BS4 -> 143492 | DD4: =DA4+CX4+CU4+CR4+CO4+CL4+CI4+CF4+CC4+BZ4+BW4+BT4 -> 96349.28
A5: 2 | B5: ရွှေခြင်္သေ့ | C5: Golden Lion | D5: မိတ္ထီလာ | E5: Meikhtila | F5: Contract | J5: 145 | K5: 2580 | L5: 1651.2 | M5: 280 | N5: 4080 | O5: 2913.6 | S5: 80 | T5: 1300 | U5: 875.2 | V5: 170 | W5: 2670 | X5: 1838.4 | Y5: 80 | Z5: 1310 | AA5: 968 | AB5: 90 | AC5: 1360 | AD5: 870.4 | AE5: 150 | AF5: 2560 | AG5: 1724.8 | AK5: =AH5+AE5+AB5+Y5+V5+S5+P5+M5+J5+G5 -> 995 | AL5: =AI5+AF5+AC5+Z5+W5+T5+Q5+N5+K5+H5 -> 15860 | AM5: =AJ5+AG5+AD5+AA5+X5+U5+R5+O5+L5+I5 -> 10841.6 | AQ5: 185 | AR5: 2890 | AS5: 1948 | AT5: 160 | AU5: 2560 | AV5: 1703.2 | AW5: 75 | AX5: 1270 | AY5: 877.6 | AZ5: 10 | BA5: 180 | BB5: 132 | BC5: 160 | BD5: 2620 | BE5: 1720 | BL5: 255 | BM5: 4230 | BN5: 2784 | BO5: 75 | BP5: 1290 | BQ5: 847.2 | BR5: =BO5+BL5+BI5+BF5+BC5+AZ5+AW5+AT5+AQ5+AN5+AK5 -> 1915 | BS5: =BP5+BM5+BJ5+BG5+BD5+BA5+AX5+AU5+AR5+AO5+AL5 -> 30900 | BT5: =BQ5+BN5+BK5+BH5+BE5+BB5+AY5+AV5+AS5+AP5+AM5 -> 20853.6 | BU5: 80 | BV5: 1280 | BW5: 905.6 | BX5: 85 | BY5: 1310 | BZ5: 903.2 | CA5: 80 | CB5: 1320 | CC5: 844.8 | CD5: 60 | CE5: 1120 | CF5: 760 | CJ5: 190 | CK5: 2700 | CL5: 1857.6 | CM5: 75 | CN5: 1300 | CO5: 832 | CP5: 70 | CQ5: 1220 | CR5: 802.4 | CS5: 80 | CT5: 1300 | CU5: 875.2 | CV5: 80 | CW5: 1240 | CX5: 858.4 | CY5: 85 | CZ5: 1330 | DA5: 872.8 | DB5: =CY5+CV5+CS5+CP5+CM5+CJ5+CG5+CD5+CA5+BX5+BU5+BR5 -> 2800 | DC5: =CZ5+CW5+CT5+CQ5+CN5+CK5+CH5+CE5+CB5+BY5+BV5+BS5 -> 45020 | DD5: =DA5+CX5+CU5+CR5+CO5+CL5+CI5+CF5+CC5+BZ5+BW5+BT5 -> 30365.6
A6: 3 | B6: ကောင်းသန့် | C6: Kaung Thant | D6: မိတ္ထီလာ | E6: Meikhtila | F6: Contract | M6: 324 | N6: 4886 | O6: 3127.04 | S6: 122 | T6: 1888 | U6: 1215.52 | V6: 220 | W6: 3280 | X6: 2099.2 | Y6: 177 | Z6: 3478 | AA6: 2225.92 | AB6: 165 | AC6: 2960 | AD6: 1894.4 | AE6: 204 | AF6: 3906 | AG6: 2499.84 | AK6: =AH6+AE6+AB6+Y6+V6+S6+P6+M6+J6+G6 -> 1212 | AL6: =AI6+AF6+AC6+Z6+W6+T6+Q6+N6+K6+H6 -> 20398 | AM6: =AJ6+AG6+AD6+AA6+X6+U6+R6+O6+L6+I6 -> 13061.92 | AQ6: 280 | AR6: 4870 | AS6: 3116.8 | AT6: 103 | AU6: 1592 | AV6: 1018.88 | AW6: 405 | AX6: 6320 | AY6: 4044.8 | AZ6: 48 | BA6: 822 | BB6: 526.08 | BC6: 393 | BD6: 6202 | BE6: 3969.28 | BF6: 170 | BG6: 2580 | BH6: 1651.2 | BL6: 235 | BM6: 3540 | BN6: 2265.6 | BO6: 45 | BP6: 730 | BQ6: 467.2 | BR6: =BO6+BL6+BI6+BF6+BC6+AZ6+AW6+AT6+AQ6+AN6+AK6 -> 2891 | BS6: =BP6+BM6+BJ6+BG6+BD6+BA6+AX6+AU6+AR6+AO6+AL6 -> 47054 | BT6: =BQ6+BN6+BK6+BH6+BE6+BB6+AY6+AV6+AS6+AP6+AM6 -> 30121.76 | BU6: 290 | BV6: 4660 | BW6: 2982.4 | CA6: 215 | CB6: 3460 | CC6: 2214.4 | CD6: 185 | CE6: 2790 | CF6: 1785.6 | CJ6: 180 | CK6: 2720 | CL6: 1740.8 | CM6: 105 | CN6: 1670 | CO6: 1068.8 | CP6: 266 | CQ6: 4474 | CR6: 2863.36 | CS6: 45 | CT6: 880 | CU6: 563.2 | CV6: 55 | CW6: 820 | CX6: 524.8 | CY6: 230 | CZ6: 3720 | DA6: 2380.8 | DB6: =CY6+CV6+CS6+CP6+CM6+CJ6+CG6+CD6+CA6+BX6+BU6+BR6 -> 4462 | DC6: =CZ6+CW6+CT6+CQ6+CN6+CK6+CH6+CE6+CB6+BY6+BV6+BS6 -> 72248 | DD6: =DA6+CX6+CU6+CR6+CO6+CL6+CI6+CF6+CC6+BZ6+BW6+BT6 -> 46245.92
A7: 4 | B7: ဦးဝင်းနိုင် | C7: U Win Naing | D7: လျှော်ပင် | E7: Wundwin | F7: Contract | J7: 105 | K7: 1560 | L7: 996 | M7: 305 | N7: 4324 | O7: 3277.6 | S7: 322 | T7: 4828 | U7: 3478.72 | V7: 220 | W7: 3280 | X7: 2099.2 | Y7: 217 | Z7: 3148 | AA7: 2101.12 | AB7: 220 | AC7: 3080 | AD7: 1971.2 | AH7: 575 | AI7: 9580 | AJ7: 6186.4 | AK7: =AH7+AE7+AB7+Y7+V7+S7+P7+M7+J7+G7 -> 1964 | AL7: =AI7+AF7+AC7+Z7+W7+T7+Q7+N7+K7+H7 -> 29800 | AM7: =AJ7+AG7+AD7+AA7+X7+U7+R7+O7+L7+I7 -> 20110.24 | AQ7: 220 | AR7: 3350 | AS7: 2292.8 | AT7: 270 | AU7: 4140 | AV7: 2736 | AW7: 110 | AX7: 1660 | AY7: 1189.12 | AZ7: 243 | BA7: 4042 | BB7: 2673.28 | BC7: 80 | BD7: 1120 | BE7: 716.8 | BF7: 113 | BG7: 1782 | BH7: 1140.48 | BL7: 70 | BM7: 980 | BN7: 627.2 | BO7: 195 | BP7: 2916 | BQ7: 1977.6 | BR7: =BO7+BL7+BI7+BF7+BC7+AZ7+AW7+AT7+AQ7+AN7+AK7 -> 3265 | BS7: =BP7+BM7+BJ7+BG7+BD7+BA7+AX7+AU7+AR7+AO7+AL7 -> 49790 | BT7: =BQ7+BN7+BK7+BH7+BE7+BB7+AY7+AV7+AS7+AP7+AM7 -> 33463.52 | BU7: 412 | BV7: 7388 | BW7: 4913.12 | CA7: 206 | CB7: 2944 | CC7: 2078.56 | CD7: 182 | CE7: 2568 | CF7: 1816.32 | CJ7: 382 | CK7: 5984 | CL7: 3953.6 | CM7: 383 | CN7: 6542 | CO7: 4369.28 | CP7: 78 | CQ7: 1062 | CR7: 744.48 | CV7: 437 | CW7: 6218 | CX7: 4071.2 | CY7: 200 | CZ7: 3880 | DA7: 2615.2 | DB7: =CY7+CV7+CS7+CP7+CM7+CJ7+CG7+CD7+CA7+BX7+BU7+BR7 -> 5545 | DC7: =CZ7+CW7+CT7+CQ7+CN7+CK7+CH7+CE7+CB7+BY7+BV7+BS7 -> 86376 | DD7: =DA7+CX7+CU7+CR7+CO7+CL7+CI7+CF7+CC7+BZ7+BW7+BT7 -> 58025.28
A8: 5 | B8: ကျော်ကြား | C8: Kyaw Kyar | D8: မလှိုင် | E8: Mahlaing | F8: Contract | S8: 720 | T8: 11080 | U8: 7307.2 | Y8: 90 | Z8: 1660 | AA8: 1062.4 | AE8: 210 | AF8: 3540 | AG8: 2265.6 | AK8: =AH8+AE8+AB8+Y8+V8+S8+P8+M8+J8+G8 -> 1020 | AL8: =AI8+AF8+AC8+Z8+W8+T8+Q8+N8+K8+H8 -> 16280 | AM8: =AJ8+AG8+AD8+AA8+X8+U8+R8+O8+L8+I8 -> 10635.2 | AW8: 120 | AX8: 1640 | AY8: 1064 | BF8: 270 | BG8: 4540 | BH8: 2992 | BR8: =BO8+BL8+BI8+BF8+BC8+AZ8+AW8+AT8+AQ8+AN8+AK8 -> 1410 | BS8: =BP8+BM8+BJ8+BG8+BD8+BA8+AX8+AU8+AR8+AO8+AL8 -> 22460 | BT8: =BQ8+BN8+BK8+BH8+BE8+BB8+AY8+AV8+AS8+AP8+AM8 -> 14691.2 | BU8: 70 | BV8: 1320 | BW8: 974.4 | CD8: 215 | CE8: 3910 | CF8: 2502.4 | CJ8: 50 | CK8: 700 | CL8: 448 | CV8: 150 | CW8: 2600 | CX8: 1664 | DB8: =CY8+CV8+CS8+CP8+CM8+CJ8+CG8+CD8+CA8+BX8+BU8+BR8 -> 1895 | DC8: =CZ8+CW8+CT8+CQ8+CN8+CK8+CH8+CE8+CB8+BY8+BV8+BS8 -> 30990 | DD8: =DA8+CX8+CU8+CR8+CO8+CL8+CI8+CF8+CC8+BZ8+BW8+BT8 -> 20280
A9: 6 | B9: မယဉ်ယဉ်အေး | C9: Ma Yin Yin Aye | D9: မလှိုင် | E9: Mahlaing | F9: Contract | M9: 115 | N9: 1810 | O9: 1158.4 | S9: 320 | T9: 5480 | U9: 3507.2 | AB9: 70 | AC9: 980 | AD9: 627.2 | AH9: 140 | AI9: 2160 | AJ9: 1382.4 | AK9: =AH9+AE9+AB9+Y9+V9+S9+P9+M9+J9+G9 -> 645 | AL9: =AI9+AF9+AC9+Z9+W9+T9+Q9+N9+K9+H9 -> 10430 | AM9: =AJ9+AG9+AD9+AA9+X9+U9+R9+O9+L9+I9 -> 6675.2 | AQ9: 45 | AR9: 830 | AS9: 531.2 | AZ9: 150 | BA9: 2100 | BB9: 1344 | BC9: 200 | BD9: 3200 | BE9: 2048 | BF9: 180 | BG9: 3120 | BH9: 1996.8 | BR9: =BO9+BL9+BI9+BF9+BC9+AZ9+AW9+AT9+AQ9+AN9+AK9 -> 1220 | BS9: =BP9+BM9+BJ9+BG9+BD9+BA9+AX9+AU9+AR9+AO9+AL9 -> 19680 | BT9: =BQ9+BN9+BK9+BH9+BE9+BB9+AY9+AV9+AS9+AP9+AM9 -> 12595.2 | CA9: 120 | CB9: 2080 | CC9: 1331.2 | CM9: 250 | CN9: 4000 | CO9: 2560 | CY9: 80 | CZ9: 1320 | DA9: 844.8 | DB9: =CY9+CV9+CS9+CP9+CM9+CJ9+CG9+CD9+CA9+BX9+BU9+BR9 -> 1670 | DC9: =CZ9+CW9+CT9+CQ9+CN9+CK9+CH9+CE9+CB9+BY9+BV9+BS9 -> 27080 | DD9: =DA9+CX9+CU9+CR9+CO9+CL9+CI9+CF9+CC9+BZ9+BW9+BT9 -> 17331.2
A10: 7 | B10: စံချိန် | C10: Sanchain | D10: ရမည်းသင်း | E10: Yamethin | F10: Contract | V10: 200 | W10: 2800 | X10: 1792 | AK10: =AH10+AE10+AB10+Y10+V10+S10+P10+M10+J10+G10 -> 200 | AL10: =AI10+AF10+AC10+Z10+W10+T10+Q10+N10+K10+H10 -> 2800 | AM10: =AJ10+AG10+AD10+AA10+X10+U10+R10+O10+L10+I10 -> 1792 | BO10: 100 | BP10: 1400 | BQ10: 896 | BR10: =BO10+BL10+BI10+BF10+BC10+AZ10+AW10+AT10+AQ10+AN10+AK10 -> 300 | BS10: =BP10+BM10+BJ10+BG10+BD10+BA10+AX10+AU10+AR10+AO10+AL10 -> 4200 | BT10: =BQ10+BN10+BK10+BH10+BE10+BB10+AY10+AV10+AS10+AP10+AM10 -> 2688 | CS10: 300 | CT10: 5200 | CU10: 3232 | CY10: 100 | CZ10: 1400 | DA10: 896 | DB10: =CY10+CV10+CS10+CP10+CM10+CJ10+CG10+CD10+CA10+BX10+BU10+BR10 -> 700 | DC10: =CZ10+CW10+CT10+CQ10+CN10+CK10+CH10+CE10+CB10+BY10+BV10+BS10 -> 10800 | DD10: =DA10+CX10+CU10+CR10+CO10+CL10+CI10+CF10+CC10+BZ10+BW10+BT10 -> 6816
A11: 8 | B11: ဦးရဲမြင့် | C11: U Ye Myint | D11: ပျော်ဘွယ် | E11: Pyawbwe | F11: Contract | S11: 420 | T11: 6180 | U11: 3955.2 | Y11: 410 | Z11: 6340 | AA11: 4057.6 | AE11: 170 | AF11: 3580 | AG11: 2291.2 | AH11: 460 | AI11: 6440 | AJ11: 4121.6 | AK11: =AH11+AE11+AB11+Y11+V11+S11+P11+M11+J11+G11 -> 1460 | AL11: =AI11+AF11+AC11+Z11+W11+T11+Q11+N11+K11+H11 -> 22540 | AM11: =AJ11+AG11+AD11+AA11+X11+U11+R11+O11+L11+I11 -> 14425.6 | AT11: 460 | AU11: 6440 | AV11: 4121.6 | AW11: 395 | AX11: 6130 | AY11: 3923.2 | AZ11: 395 | BA11: 6130 | BB11: 3923.2 | BC11: 490 | BD11: 7160 | BE11: 4582.4 | BR11: =BO11+BL11+BI11+BF11+BC11+AZ11+AW11+AT11+AQ11+AN11+AK11 -> 3200 | BS11: =BP11+BM11+BJ11+BG11+BD11+BA11+AX11+AU11+AR11+AO11+AL11 -> 48400 | BT11: =BQ11+BN11+BK11+BH11+BE11+BB11+AY11+AV11+AS11+AP11+AM11 -> 30976 | BU11: 365 | BV11: 5410 | BW11: 3462.4 | BX11: 160 | BY11: 2240 | BZ11: 1433.6 | CA11: 290 | CB11: 4960 | CC11: 3174.4 | CM11: 315 | CN11: 4910 | CO11: 3178.4 | CP11: 420 | CQ11: 5880 | CR11: 3763.2 | CV11: 410 | CW11: 6040 | CX11: 3865.6 | CY11: 390 | CZ11: 6060 | DA11: 3878.4 | DB11: =CY11+CV11+CS11+CP11+CM11+CJ11+CG11+CD11+CA11+BX11+BU11+BR11 -> 5550 | DC11: =CZ11+CW11+CT11+CQ11+CN11+CK11+CH11+CE11+CB11+BY11+BV11+BS11 -> 83900 | DD11: =DA11+CX11+CU11+CR11+CO11+CL11+CI11+CF11+CC11+BZ11+BW11+BT11 -> 53732
A12: 9 | B12: လွင် | C12: Lwin | D12: ကျောက်ပန်းတောင်း | E12: Kyaukpadaung | F12: Contract | S12: 250 | T12: 3500 | U12: 2240 | Y12: 280 | Z12: 4220 | AA12: 2700.8 | AK12: =AH12+AE12+AB12+Y12+V12+S12+P12+M12+J12+G12 -> 530 | AL12: =AI12+AF12+AC12+Z12+W12+T12+Q12+N12+K12+H12 -> 7720 | AM12: =AJ12+AG12+AD12+AA12+X12+U12+R12+O12+L12+I12 -> 4940.8 | AQ12: 315 | AR12: 4240 | AS12: 2990.8 | AT12: 300 | AU12: 4700 | AV12: 2960 | BC12: 300 | BD12: 4000 | BE12: 2992 | BO12: 500 | BP12: 8000 | BQ12: 5072 | BR12: =BO12+BL12+BI12+BF12+BC12+AZ12+AW12+AT12+AQ12+AN12+AK12 -> 1945 | BS12: =BP12+BM12+BJ12+BG12+BD12+BA12+AX12+AU12+AR12+AO12+AL12 -> 28660 | BT12: =BQ12+BN12+BK12+BH12+BE12+BB12+AY12+AV12+AS12+AP12+AM12 -> 18955.6 | CD12: 320 | CE12: 4400 | CF12: 2844.8 | CP12: 310 | CQ12: 5280 | CR12: 3304.8 | CY12: 530 | CZ12: 7360 | DA12: 4840 | DB12: =CY12+CV12+CS12+CP12+CM12+CJ12+CG12+CD12+CA12+BX12+BU12+BR12 -> 3105 | DC12: =CZ12+CW12+CT12+CQ12+CN12+CK12+CH12+CE12+CB12+BY12+BV12+BS12 -> 45700 | DD12: =DA12+CX12+CU12+CR12+CO12+CL12+CI12+CF12+CC12+BZ12+BW12+BT12 -> 29945.2
A13: 10 | B13: ဦးစိုးဝင်း | C13: U Soe Win | D13: ကျောက်ပန်းတောင်း | E13: Kyaukpadaung | F13: Contract | AK13: =AH13+AE13+AB13+Y13+V13+S13+P13+M13+J13+G13 -> 0 | AL13: =AI13+AF13+AC13+Z13+W13+T13+Q13+N13+K13+H13 -> 0 | AM13: =AJ13+AG13+AD13+AA13+X13+U13+R13+O13+L13+I13 -> 0 | BR13: =BO13+BL13+BI13+BF13+BC13+AZ13+AW13+AT13+AQ13+AN13+AK13 -> 0 | BS13: =BP13+BM13+BJ13+BG13+BD13+BA13+AX13+AU13+AR13+AO13+AL13 -> 0 | BT13: =BQ13+BN13+BK13+BH13+BE13+BB13+AY13+AV13+AS13+AP13+AM13 -> 0 | CD13: 280 | CE13: 4220 | CF13: 2700.8 | CS13: 600 | CT13: 8400 | CU13: 5376 | DB13: =CY13+CV13+CS13+CP13+CM13+CJ13+CG13+CD13+CA13+BX13+BU13+BR13 -> 880 | DC13: =CZ13+CW13+CT13+CQ13+CN13+CK13+CH13+CE13+CB13+BY13+BV13+BS13 -> 12620 | DD13: =DA13+CX13+CU13+CR13+CO13+CL13+CI13+CF13+CC13+BZ13+BW13+BT13 -> 8076.8
A14: 11 | B14: ဦးသိန်းစိုး | C14: U Thein Soe | D14: ကျောက်ပန်းတောင်း | E14: Kyaukpadaung | F14: Contract | Y14: 225 | Z14: 2950 | AA14: 2320 | AK14: =AH14+AE14+AB14+Y14+V14+S14+P14+M14+J14+G14 -> 225 | AL14: =AI14+AF14+AC14+Z14+W14+T14+Q14+N14+K14+H14 -> 2950 | AM14: =AJ14+AG14+AD14+AA14+X14+U14+R14+O14+L14+I14 -> 2320 | AT14: 300 | AU14: 5700 | AV14: 3504 | BL14: 150 | BM14: 2100 | BN14: 1344 | BR14: =BO14+BL14+BI14+BF14+BC14+AZ14+AW14+AT14+AQ14+AN14+AK14 -> 675 | BS14: =BP14+BM14+BJ14+BG14+BD14+BA14+AX14+AU14+AR14+AO14+AL14 -> 10750 | BT14: =BQ14+BN14+BK14+BH14+BE14+BB14+AY14+AV14+AS14+AP14+AM14 -> 7168 | CD14: 200 | CE14: 2800 | CF14: 1792 | CP14: 260 | CQ14: 4240 | CR14: 2713.6 | DB14: =CY14+CV14+CS14+CP14+CM14+CJ14+CG14+CD14+CA14+BX14+BU14+BR14 -> 1135 | DC14: =CZ14+CW14+CT14+CQ14+CN14+CK14+CH14+CE14+CB14+BY14+BV14+BS14 -> 17790 | DD14: =DA14+CX14+CU14+CR14+CO14+CL14+CI14+CF14+CC14+BZ14+BW14+BT14 -> 11673.6
A15: 12 | B15: ကောင်းထက်သူ | C15: Kaung Htet Thu | D15: ကျောက်ပန်းတောင်း | E15: Kyaukpadaung | F15: Contract | AE15: 250 | AF15: 4000 | AG15: 2512 | AK15: =AH15+AE15+AB15+Y15+V15+S15+P15+M15+J15+G15 -> 250 | AL15: =AI15+AF15+AC15+Z15+W15+T15+Q15+N15+K15+H15 -> 4000 | AM15: =AJ15+AG15+AD15+AA15+X15+U15+R15+O15+L15+I15 -> 2512 | BL15: 250 | BM15: 3500 | BN15: 2240 | BR15: =BO15+BL15+BI15+BF15+BC15+AZ15+AW15+AT15+AQ15+AN15+AK15 -> 500 | BS15: =BP15+BM15+BJ15+BG15+BD15+BA15+AX15+AU15+AR15+AO15+AL15 -> 7500 | BT15: =BQ15+BN15+BK15+BH15+BE15+BB15+AY15+AV15+AS15+AP15+AM15 -> 4752 | CM15: 290 | CN15: 4720 | CO15: 3059.2 | DB15: =CY15+CV15+CS15+CP15+CM15+CJ15+CG15+CD15+CA15+BX15+BU15+BR15 -> 790 | DC15: =CZ15+CW15+CT15+CQ15+CN15+CK15+CH15+CE15+CB15+BY15+BV15+BS15 -> 12220 | DD15: =DA15+CX15+CU15+CR15+CO15+CL15+CI15+CF15+CC15+BZ15+BW15+BT15 -> 7811.2
A16: 13 | B16: ကောင်းဆုဝေ | C16: Kaung Su Wai | D16: ကျောက်ပန်းတောင်း | E16: Kyaukpadaung | F16: Contract | V16: 550 | W16: 7700 | X16: 4928 | AK16: =AH16+AE16+AB16+Y16+V16+S16+P16+M16+J16+G16 -> 550 | AL16: =AI16+AF16+AC16+Z16+W16+T16+Q16+N16+K16+H16 -> 7700 | AM16: =AJ16+AG16+AD16+AA16+X16+U16+R16+O16+L16+I16 -> 4928 | BF16: 250 | BG16: 3500 | BH16: 2240 | BO16: 250 | BP16: 3500 | BQ16: 2240 | BR16: =BO16+BL16+BI16+BF16+BC16+AZ16+AW16+AT16+AQ16+AN16+AK16 -> 1050 | BS16: =BP16+BM16+BJ16+BG16+BD16+BA16+AX16+AU16+AR16+AO16+AL16 -> 14700 | BT16: =BQ16+BN16+BK16+BH16+BE16+BB16+AY16+AV16+AS16+AP16+AM16 -> 9408 | CP16: 250 | CQ16: 3500 | CR16: 2240 | CV16: 250 | CW16: 3500 | CX16: 2240 | DB16: =CY16+CV16+CS16+CP16+CM16+CJ16+CG16+CD16+CA16+BX16+BU16+BR16 -> 1550 | DC16: =CZ16+CW16+CT16+CQ16+CN16+CK16+CH16+CE16+CB16+BY16+BV16+BS16 -> 21700 | DD16: =DA16+CX16+CU16+CR16+CO16+CL16+CI16+CF16+CC16+BZ16+BW16+BT16 -> 13888
A17: 14 | B17: မြို့မ | C17: MyoMa | D17: တောင်သာ | E17: Taungtha | F17: Contract | AK17: =AH17+AE17+AB17+Y17+V17+S17+P17+M17+J17+G17 -> 0 | AL17: =AI17+AF17+AC17+Z17+W17+T17+Q17+N17+K17+H17 -> 0 | AM17: =AJ17+AG17+AD17+AA17+X17+U17+R17+O17+L17+I17 -> 0 | AT17: 100 | AU17: 1200 | AV17: 1200 | BR17: =BO17+BL17+BI17+BF17+BC17+AZ17+AW17+AT17+AQ17+AN17+AK17 -> 100 | BS17: =BP17+BM17+BJ17+BG17+BD17+BA17+AX17+AU17+AR17+AO17+AL17 -> 1200 | BT17: =BQ17+BN17+BK17+BH17+BE17+BB17+AY17+AV17+AS17+AP17+AM17 -> 1200 | DB17: =CY17+CV17+CS17+CP17+CM17+CJ17+CG17+CD17+CA17+BX17+BU17+BR17 -> 100 | DC17: =CZ17+CW17+CT17+CQ17+CN17+CK17+CH17+CE17+CB17+BY17+BV17+BS17 -> 1200 | DD17: =DA17+CX17+CU17+CR17+CO17+CL17+CI17+CF17+CC17+BZ17+BW17+BT17 -> 1200
A18: 15 | B18: မိုးယံ | C18: Moe Yan | D18: ရမည်းသင်း | E18: Yamethin | F18: Contract | S18: 50 | T18: 600 | U18: 600 | AB18: 50 | AC18: 700 | AD18: 448 | AK18: =AH18+AE18+AB18+Y18+V18+S18+P18+M18+J18+G18 -> 100 | AL18: =AI18+AF18+AC18+Z18+W18+T18+Q18+N18+K18+H18 -> 1300 | AM18: =AJ18+AG18+AD18+AA18+X18+U18+R18+O18+L18+I18 -> 1048 | BL18: 102 | BM18: 1408 | BN18: 891.52 | BR18: =BO18+BL18+BI18+BF18+BC18+AZ18+AW18+AT18+AQ18+AN18+AK18 -> 202 | BS18: =BP18+BM18+BJ18+BG18+BD18+BA18+AX18+AU18+AR18+AO18+AL18 -> 2708 | BT18: =BQ18+BN18+BK18+BH18+BE18+BB18+AY18+AV18+AS18+AP18+AM18 -> 1939.52 | BU18: 50 | BV18: 700 | BW18: 448 | CJ18: 60 | CK18: 840 | CL18: 744 | DB18: =CY18+CV18+CS18+CP18+CM18+CJ18+CG18+CD18+CA18+BX18+BU18+BR18 -> 312 | DC18: =CZ18+CW18+CT18+CQ18+CN18+CK18+CH18+CE18+CB18+BY18+BV18+BS18 -> 4248 | DD18: =DA18+CX18+CU18+CR18+CO18+CL18+CI18+CF18+CC18+BZ18+BW18+BT18 -> 3131.52
A19: 16 | B19: ကောင်းဟိန်း | C19: Kaung Hein | D19: ပခုက္ကူ | E19: Pakokku | F19: Contract | AK19: =AH19+AE19+AB19+Y19+V19+S19+P19+M19+J19+G19 -> 0 | AL19: =AI19+AF19+AC19+Z19+W19+T19+Q19+N19+K19+H19 -> 0 | AM19: =AJ19+AG19+AD19+AA19+X19+U19+R19+O19+L19+I19 -> 0 | BR19: =BO19+BL19+BI19+BF19+BC19+AZ19+AW19+AT19+AQ19+AN19+AK19 -> 0 | BS19: =BP19+BM19+BJ19+BG19+BD19+BA19+AX19+AU19+AR19+AO19+AL19 -> 0 | BT19: =BQ19+BN19+BK19+BH19+BE19+BB19+AY19+AV19+AS19+AP19+AM19 -> 0 | CA19: 250 | CB19: 3400 | CC19: 2392 | DB19: =CY19+CV19+CS19+CP19+CM19+CJ19+CG19+CD19+CA19+BX19+BU19+BR19 -> 250 | DC19: =CZ19+CW19+CT19+CQ19+CN19+CK19+CH19+CE19+CB19+BY19+BV19+BS19 -> 3400 | DD19: =DA19+CX19+CU19+CR19+CO19+CL19+CI19+CF19+CC19+BZ19+BW19+BT19 -> 2392
A20: 17 | B20: Summer-1 | C20: Summer-1 | D20: မိတ္ထီလာ | E20: Meikhtila | F20: Wholesale | J20: 120 | K20: 2880 | L20: 1843.2 | S20: 150 | T20: 2600 | U20: 1664 | AB20: 100 | AC20: 2400 | AD20: 1536 | AE20: 240 | AF20: 4660 | AG20: 2982.4 | AH20: 200 | AI20: 2800 | AJ20: 1792 | AK20: =AH20+AE20+AB20+Y20+V20+S20+P20+M20+J20+G20 -> 810 | AL20: =AI20+AF20+AC20+Z20+W20+T20+Q20+N20+K20+H20 -> 15340 | AM20: =AJ20+AG20+AD20+AA20+X20+U20+R20+O20+L20+I20 -> 9817.6 | AW20: 30 | AX20: 720 | AY20: 460.8 | AZ20: 380 | BA20: 7020 | BB20: 4492.8 | BC20: 200 | BD20: 2800 | BE20: 1792 | BF20: 130 | BG20: 2320 | BH20: 1484.8 | BO20: 100 | BP20: 1400 | BQ20: 896 | BR20: =BO20+BL20+BI20+BF20+BC20+AZ20+AW20+AT20+AQ20+AN20+AK20 -> 1650 | BS20: =BP20+BM20+BJ20+BG20+BD20+BA20+AX20+AU20+AR20+AO20+AL20 -> 29600 | BT20: =BQ20+BN20+BK20+BH20+BE20+BB20+AY20+AV20+AS20+AP20+AM20 -> 18944 | BX20: 200 | BY20: 3300 | BZ20: 2112 | CD20: 60 | CE20: 900 | CF20: 662.4 | CM20: 120 | CN20: 2880 | CO20: 1843.2 | CP20: 150 | CQ20: 2600 | CR20: 1664 | DB20: =CY20+CV20+CS20+CP20+CM20+CJ20+CG20+CD20+CA20+BX20+BU20+BR20 -> 2180 | DC20: =CZ20+CW20+CT20+CQ20+CN20+CK20+CH20+CE20+CB20+BY20+BV20+BS20 -> 39280 | DD20: =DA20+CX20+CU20+CR20+CO20+CL20+CI20+CF20+CC20+BZ20+BW20+BT20 -> 25225.6
A21: 18 | B21: Summer-2 | C21: Summer-2 | D21: မိတ္ထီလာ | E21: Meikhtila | F21: Wholesale | M21: 145 | N21: 2280 | O21: 1891.2 | V21: 177 | W21: 3188 | X21: 2169.92 | Y21: 75 | Z21: 1300 | AA21: 832 | AB21: 100 | AC21: 1400 | AD21: 896 | AE21: 45 | AF21: 1080 | AG21: 691.2 | AK21: =AH21+AE21+AB21+Y21+V21+S21+P21+M21+J21+G21 -> 542 | AL21: =AI21+AF21+AC21+Z21+W21+T21+Q21+N21+K21+H21 -> 9248 | AM21: =AJ21+AG21+AD21+AA21+X21+U21+R21+O21+L21+I21 -> 6480.32 | AQ21: 45 | AR21: 1080 | AS21: 691.2 | AT21: 100 | AU21: 1320 | AV21: 1017.6 | AZ21: 145 | BA21: 2420 | BB21: 1678.4 | BL21: 85 | BM21: 2040 | BN21: 1305.6 | BO21: 90 | BP21: 1360 | BQ21: 870.4 | BR21: =BO21+BL21+BI21+BF21+BC21+AZ21+AW21+AT21+AQ21+AN21+AK21 -> 1007 | BS21: =BP21+BM21+BJ21+BG21+BD21+BA21+AX21+AU21+AR21+AO21+AL21 -> 17468 | BT21: =BQ21+BN21+BK21+BH21+BE21+BB21+AY21+AV21+AS21+AP21+AM21 -> 12043.52 | BU21: 80 | BV21: 1120 | BW21: 716.8 | BX21: 100 | BY21: 1500 | BZ21: 1176 | CD21: 45 | CE21: 1080 | CF21: 691.2 | CM21: 145 | CN21: 2440 | CO21: 1648 | CP21: 100 | CQ21: 1400 | CR21: 896 | CS21: 100 | CT21: 1300 | CU21: 1048 | CV21: 45 | CW21: 1080 | CX21: 691.2 | DB21: =CY21+CV21+CS21+CP21+CM21+CJ21+CG21+CD21+CA21+BX21+BU21+BR21 -> 1622 | DC21: =CZ21+CW21+CT21+CQ21+CN21+CK21+CH21+CE21+CB21+BY21+BV21+BS21 -> 27388 | DD21: =DA21+CX21+CU21+CR21+CO21+CL21+CI21+CF21+CC21+BZ21+BW21+BT21 -> 18910.72
A22: 19 | B22: ဦးအေးခင်မောင် | C22: U Aye Khin Maung | D22: မိတ္ထီလာ | E22: Meikhtila | F22: Wholesale | M22: 100 | N22: 1900 | O22: 1216 | Y22: 100 | Z22: 1400 | AA22: 896 | AK22: =AH22+AE22+AB22+Y22+V22+S22+P22+M22+J22+G22 -> 200 | AL22: =AI22+AF22+AC22+Z22+W22+T22+Q22+N22+K22+H22 -> 3300 | AM22: =AJ22+AG22+AD22+AA22+X22+U22+R22+O22+L22+I22 -> 2112 | AQ22: 50 | AR22: 1200 | AS22: 768 | AT22: 50 | AU22: 1200 | AV22: 768 | BF22: 60 | BG22: 840 | BH22: 537.6 | BR22: =BO22+BL22+BI22+BF22+BC22+AZ22+AW22+AT22+AQ22+AN22+AK22 -> 360 | BS22: =BP22+BM22+BJ22+BG22+BD22+BA22+AX22+AU22+AR22+AO22+AL22 -> 6540 | BT22: =BQ22+BN22+BK22+BH22+BE22+BB22+AY22+AV22+AS22+AP22+AM22 -> 4185.6 | CA22: 100 | CB22: 1400 | CC22: 896 | CP22: 50 | CQ22: 1200 | CR22: 768 | DB22: =CY22+CV22+CS22+CP22+CM22+CJ22+CG22+CD22+CA22+BX22+BU22+BR22 -> 510 | DC22: =CZ22+CW22+CT22+CQ22+CN22+CK22+CH22+CE22+CB22+BY22+BV22+BS22 -> 9140 | DD22: =DA22+CX22+CU22+CR22+CO22+CL22+CI22+CF22+CC22+BZ22+BW22+BT22 -> 5849.6
A23: 20 | B23: ဦးကျော်လှ | C23: U Kyaw Hla | D23: သာစည် | E23: Tharzi | F23: Wholesale | S23: 75 | T23: 1250 | U23: 800 | Y23: 50 | Z23: 700 | AA23: 448 | AK23: =AH23+AE23+AB23+Y23+V23+S23+P23+M23+J23+G23 -> 125 | AL23: =AI23+AF23+AC23+Z23+W23+T23+Q23+N23+K23+H23 -> 1950 | AM23: =AJ23+AG23+AD23+AA23+X23+U23+R23+O23+L23+I23 -> 1248 | AQ23: 105 | AR23: 1670 | AS23: 1068.8 | BR23: =BO23+BL23+BI23+BF23+BC23+AZ23+AW23+AT23+AQ23+AN23+AK23 -> 230 | BS23: =BP23+BM23+BJ23+BG23+BD23+BA23+AX23+AU23+AR23+AO23+AL23 -> 3620 | BT23: =BQ23+BN23+BK23+BH23+BE23+BB23+AY23+AV23+AS23+AP23+AM23 -> 2316.8 | BU23: 115 | BV23: 1660 | BW23: 1062.4 | BX23: 60 | BY23: 1040 | BZ23: 665.6 | CP23: 30 | CQ23: 420 | CR23: 268.8 | DB23: =CY23+CV23+CS23+CP23+CM23+CJ23+CG23+CD23+CA23+BX23+BU23+BR23 -> 435 | DC23: =CZ23+CW23+CT23+CQ23+CN23+CK23+CH23+CE23+CB23+BY23+BV23+BS23 -> 6740 | DD23: =DA23+CX23+CU23+CR23+CO23+CL23+CI23+CF23+CC23+BZ23+BW23+BT23 -> 4313.6
A24: 21 | B24: ဦးဝင်းအောင်ကြွယ် | C24: U Win Aung Kyawe | D24: ပျော်ဘွယ် | E24: Pyawbwe | F24: Wholesale | Y24: 120 | Z24: 1580 | AA24: 1047.2 | AK24: =AH24+AE24+AB24+Y24+V24+S24+P24+M24+J24+G24 -> 120 | AL24: =AI24+AF24+AC24+Z24+W24+T24+Q24+N24+K24+H24 -> 1580 | AM24: =AJ24+AG24+AD24+AA24+X24+U24+R24+O24+L24+I24 -> 1047.2 | AT24: 150 | AU24: 2100 | AV24: 1344 | BR24: =BO24+BL24+BI24+BF24+BC24+AZ24+AW24+AT24+AQ24+AN24+AK24 -> 270 | BS24: =BP24+BM24+BJ24+BG24+BD24+BA24+AX24+AU24+AR24+AO24+AL24 -> 3680 | BT24: =BQ24+BN24+BK24+BH24+BE24+BB24+AY24+AV24+AS24+AP24+AM24 -> 2391.2 | CA24: 100 | CB24: 1400 | CC24: 896 | DB24: =CY24+CV24+CS24+CP24+CM24+CJ24+CG24+CD24+CA24+BX24+BU24+BR24 -> 370 | DC24: =CZ24+CW24+CT24+CQ24+CN24+CK24+CH24+CE24+CB24+BY24+BV24+BS24 -> 5080 | DD24: =DA24+CX24+CU24+CR24+CO24+CL24+CI24+CF24+CC24+BZ24+BW24+BT24 -> 3287.2
A25: 22 | B25: ဦးအောင်မိုး | C25: U Aung Moe | D25: ရမည်းသင်း | E25: Yamethin | F25: Wholesale | S25: 100 | T25: 1200 | U25: 1200 | V25: 100 | W25: 1400 | X25: 896 | Y25: 100 | Z25: 2400 | AA25: 1440 | AK25: =AH25+AE25+AB25+Y25+V25+S25+P25+M25+J25+G25 -> 300 | AL25: =AI25+AF25+AC25+Z25+W25+T25+Q25+N25+K25+H25 -> 5000 | AM25: =AJ25+AG25+AD25+AA25+X25+U25+R25+O25+L25+I25 -> 3536 | BR25: =BO25+BL25+BI25+BF25+BC25+AZ25+AW25+AT25+AQ25+AN25+AK25 -> 300 | BS25: =BP25+BM25+BJ25+BG25+BD25+BA25+AX25+AU25+AR25+AO25+AL25 -> 5000 | BT25: =BQ25+BN25+BK25+BH25+BE25+BB25+AY25+AV25+AS25+AP25+AM25 -> 3536 | CD25: 100 | CE25: 1400 | CF25: 896 | CY25: 100 | CZ25: 1400 | DA25: 896 | DB25: =CY25+CV25+CS25+CP25+CM25+CJ25+CG25+CD25+CA25+BX25+BU25+BR25 -> 500 | DC25: =CZ25+CW25+CT25+CQ25+CN25+CK25+CH25+CE25+CB25+BY25+BV25+BS25 -> 7800 | DD25: =DA25+CX25+CU25+CR25+CO25+CL25+CI25+CF25+CC25+BZ25+BW25+BT25 -> 5328
A26: 23 | B26: ဒေါ်ခင်စန်းမြင့် | C26: Daw Khin San Myint | D26: ကျောက်ပန်းတောင်း | E26: Kyaukpadaung | F26: Wholesale | AH26: 280 | AI26: 4220 | AJ26: 2672 | AK26: =AH26+AE26+AB26+Y26+V26+S26+P26+M26+J26+G26 -> 280 | AL26: =AI26+AF26+AC26+Z26+W26+T26+Q26+N26+K26+H26 -> 4220 | AM26: =AJ26+AG26+AD26+AA26+X26+U26+R26+O26+L26+I26 -> 2672 | BR26: =BO26+BL26+BI26+BF26+BC26+AZ26+AW26+AT26+AQ26+AN26+AK26 -> 280 | BS26: =BP26+BM26+BJ26+BG26+BD26+BA26+AX26+AU26+AR26+AO26+AL26 -> 4220 | BT26: =BQ26+BN26+BK26+BH26+BE26+BB26+AY26+AV26+AS26+AP26+AM26 -> 2672 | CS26: 230 | CT26: 3220 | CU26: 2060.8 | DB26: =CY26+CV26+CS26+CP26+CM26+CJ26+CG26+CD26+CA26+BX26+BU26+BR26 -> 510 | DC26: =CZ26+CW26+CT26+CQ26+CN26+CK26+CH26+CE26+CB26+BY26+BV26+BS26 -> 7440 | DD26: =DA26+CX26+CU26+CR26+CO26+CL26+CI26+CF26+CC26+BZ26+BW26+BT26 -> 4732.8
A27: 24 | B27: ရတနာ | C27: Yadana | D27: ပုဂံ | E27: Bagan | F27: Wholesale | AK27: =AH27+AE27+AB27+Y27+V27+S27+P27+M27+J27+G27 -> 0 | AL27: =AI27+AF27+AC27+Z27+W27+T27+Q27+N27+K27+H27 -> 0 | AM27: =AJ27+AG27+AD27+AA27+X27+U27+R27+O27+L27+I27 -> 0 | BR27: =BO27+BL27+BI27+BF27+BC27+AZ27+AW27+AT27+AQ27+AN27+AK27 -> 0 | BS27: =BP27+BM27+BJ27+BG27+BD27+BA27+AX27+AU27+AR27+AO27+AL27 -> 0 | BT27: =BQ27+BN27+BK27+BH27+BE27+BB27+AY27+AV27+AS27+AP27+AM27 -> 0 | DB27: =CY27+CV27+CS27+CP27+CM27+CJ27+CG27+CD27+CA27+BX27+BU27+BR27 -> 0 | DC27: =CZ27+CW27+CT27+CQ27+CN27+CK27+CH27+CE27+CB27+BY27+BV27+BS27 -> 0 | DD27: =DA27+CX27+CU27+CR27+CO27+CL27+CI27+CF27+CC27+BZ27+BW27+BT27 -> 0
A28: 25 | B28: ဦးတင်မောင် | C28: U Tin Maung | D28: ပခုက္ကူ | E28: Pakokku | F28: Wholesale | AK28: =AH28+AE28+AB28+Y28+V28+S28+P28+M28+J28+G28 -> 0 | AL28: =AI28+AF28+AC28+Z28+W28+T28+Q28+N28+K28+H28 -> 0 | AM28: =AJ28+AG28+AD28+AA28+X28+U28+R28+O28+L28+I28 -> 0 | AZ28: 250 | BA28: 3500 | BB28: 2240 | BR28: =BO28+BL28+BI28+BF28+BC28+AZ28+AW28+AT28+AQ28+AN28+AK28 -> 250 | BS28: =BP28+BM28+BJ28+BG28+BD28+BA28+AX28+AU28+AR28+AO28+AL28 -> 3500 | BT28: =BQ28+BN28+BK28+BH28+BE28+BB28+AY28+AV28+AS28+AP28+AM28 -> 2240 | CA28: 200 | CB28: 2800 | CC28: 1792 | CY28: 100 | CZ28: 1400 | DA28: 896 | DB28: =CY28+CV28+CS28+CP28+CM28+CJ28+CG28+CD28+CA28+BX28+BU28+BR28 -> 550 | DC28: =CZ28+CW28+CT28+CQ28+CN28+CK28+CH28+CE28+CB28+BY28+BV28+BS28 -> 7700 | DD28: =DA28+CX28+CU28+CR28+CO28+CL28+CI28+CF28+CC28+BZ28+BW28+BT28 -> 4928
A29: Total (25) | G29: =SUM(G4:G28) -> 0 | H29: =SUM(H4:H28) -> 0 | I29: =SUM(I4:I28) -> 0 | J29: =SUM(J4:J28) -> 370 | K29: =SUM(K4:K28) -> 7020 | L29: =SUM(L4:L28) -> 4490.4 | M29: =SUM(M4:M28) -> 1739 | N29: =SUM(N4:N28) -> 27520 | ... AY29: =SUM(AY4:AY28) -> 15706.72 | AZ29: 1791 | BA29: 29144 | BB29: 18884.96 | BC29: 2123 | BD29: 31892 | BE29: 21015.68 | BF29: 1223 | BG29: 19682 | BH29: 12682.88 | BI29: =SUM(BI4:BI28) -> 0 | BJ29: =SUM(BJ4:BJ28) -> 0 | BK29: =SUM(BK4:BK28) -> 0 | BL29: =SUM(BL4:BL28) -> 1782 | BM29: =SUM(BM4:BM28) -> 28668 | BN29: =SUM(BN4:BN28) -> 18889.92 | BO29: =SUM(BO4:BO28) -> 1695 | BP29: =SUM(BP4:BP28) -> 25956 | ... DD29: =SUM(DD4:DD28) -> 479839.12
A30: 1 | B30: ရွှေကမ္ဘာ | C30: Golden World | D30: မိတ္ထီလာ | E30: Meikhtila | F30: Semi Wholesale | AK30: =AH30+AE30+AB30+Y30+V30+S30+P30+M30+J30+G30 -> 0 | AL30: =AI30+AF30+AC30+Z30+W30+T30+Q30+N30+K30+H30 -> 0 | AM30: =AJ30+AG30+AD30+AA30+X30+U30+R30+O30+L30+I30 -> 0 | AQ30: 90 | AR30: 1260 | AS30: 806.4 | AZ30: 45 | BA30: 1080 | BB30: 691.2 | BR30: =BO30+BL30+BI30+BF30+BC30+AZ30+AW30+AT30+AQ30+AN30+AK30 -> 135 | BS30: =BP30+BM30+BJ30+BG30+BD30+BA30+AX30+AU30+AR30+AO30+AL30 -> 2340 | BT30: =BQ30+BN30+BK30+BH30+BE30+BB30+AY30+AV30+AS30+AP30+AM30 -> 1497.6 | CP30: 45 | CQ30: 1080 | CR30: 691.2 | DB30: =CY30+CV30+CS30+CP30+CM30+CJ30+CG30+CD30+CA30+BX30+BU30+BR30 -> 180 | DC30: =CZ30+CW30+CT30+CQ30+CN30+CK30+CH30+CE30+CB30+BY30+BV30+BS30 -> 3420 | DD30: =DA30+CX30+CU30+CR30+CO30+CL30+CI30+CF30+CC30+BZ30+BW30+BT30 -> 2188.8
A31: 2 | B31: ဦးမောင်ငယ် | C31: U Mg Ngwe | D31: ရမည်းသင်း | E31: Yamethin | F31: Semi Wholesale | AK31: =AH31+AE31+AB31+Y31+V31+S31+P31+M31+J31+G31 -> 0 | AL31: =AI31+AF31+AC31+Z31+W31+T31+Q31+N31+K31+H31 -> 0 | AM31: =AJ31+AG31+AD31+AA31+X31+U31+R31+O31+L31+I31 -> 0 | BR31: =BO31+BL31+BI31+BF31+BC31+AZ31+AW31+AT31+AQ31+AN31+AK31 -> 0 | BS31: =BP31+BM31+BJ31+BG31+BD31+BA31+AX31+AU31+AR31+AO31+AL31 -> 0 | BT31: =BQ31+BN31+BK31+BH31+BE31+BB31+AY31+AV31+AS31+AP31+AM31 -> 0 | DB31: =CY31+CV31+CS31+CP31+CM31+CJ31+CG31+CD31+CA31+BX31+BU31+BR31 -> 0 | DC31: =CZ31+CW31+CT31+CQ31+CN31+CK31+CH31+CE31+CB31+BY31+BV31+BS31 -> 0 | DD31: =DA31+CX31+CU31+CR31+CO31+CL31+CI31+CF31+CC31+BZ31+BW31+BT31 -> 0
A32: 3 | B32: ကိုလှဌေးအောင် | C32: U Hla Htay Aung | D32: မြင်းခြံ | E32: Myingyun | F32: Semi Wholesale | AK32: =AH32+AE32+AB32+Y32+V32+S32+P32+M32+J32+G32 -> 0 | AL32: =AI32+AF32+AC32+Z32+W32+T32+Q32+N32+K32+H32 -> 0 | AM32: =AJ32+AG32+AD32+AA32+X32+U32+R32+O32+L32+I32 -> 0 | AZ32: 200 | BA32: 3300 | BB32: 2112 | BR32: =BO32+BL32+BI32+BF32+BC32+AZ32+AW32+AT32+AQ32+AN32+AK32 -> 200 | BS32: =BP32+BM32+BJ32+BG32+BD32+BA32+AX32+AU32+AR32+AO32+AL32 -> 3300 | BT32: =BQ32+BN32+BK32+BH32+BE32+BB32+AY32+AV32+AS32+AP32+AM32 -> 2112 | DB32: =CY32+CV32+CS32+CP32+CM32+CJ32+CG32+CD32+CA32+BX32+BU32+BR32 -> 200 | DC32: =CZ32+CW32+CT32+CQ32+CN32+CK32+CH32+CE32+CB32+BY32+BV32+BS32 -> 3300 | DD32: =DA32+CX32+CU32+CR32+CO32+CL32+CI32+CF32+CC32+BZ32+BW32+BT32 -> 2112
A33: 4 | B33: ပြည်ဖြိုးကြွယ် | C33: Pyae Phyo Kywe | D33: မြင်းခြံ | E33: Myingyun | F33: Semi Wholesale | AK33: =AH33+AE33+AB33+Y33+V33+S33+P33+M33+J33+G33 -> 0 | AL33: =AI33+AF33+AC33+Z33+W33+T33+Q33+N33+K33+H33 -> 0 | AM33: =AJ33+AG33+AD33+AA33+X33+U33+R33+O33+L33+I33 -> 0 | AZ33: 220 | BA33: 4280 | BB33: 2739.2 | BR33: =BO33+BL33+BI33+BF33+BC33+AZ33+AW33+AT33+AQ33+AN33+AK33 -> 220 | BS33: =BP33+BM33+BJ33+BG33+BD33+BA33+AX33+AU33+AR33+AO33+AL33 -> 4280 | BT33: =BQ33+BN33+BK33+BH33+BE33+BB33+AY33+AV33+AS33+AP33+AM33 -> 2739.2 | DB33: =CY33+CV33+CS33+CP33+CM33+CJ33+CG33+CD33+CA33+BX33+BU33+BR33 -> 220 | DC33: =CZ33+CW33+CT33+CQ33+CN33+CK33+CH33+CE33+CB33+BY33+BV33+BS33 -> 4280 | DD33: =DA33+CX33+CU33+CR33+CO33+CL33+CI33+CF33+CC33+BZ33+BW33+BT33 -> 2739.2
A34: 5 | B34: ဝတိံယံ | C34: Wattainyan | D34: ပခုက္ကူ | E34: Pakokku | F34: Semi Wholesale | AK34: =AH34+AE34+AB34+Y34+V34+S34+P34+M34+J34+G34 -> 0 | AL34: =AI34+AF34+AC34+Z34+W34+T34+Q34+N34+K34+H34 -> 0 | AM34: =AJ34+AG34+AD34+AA34+X34+U34+R34+O34+L34+I34 -> 0 | BR34: =BO34+BL34+BI34+BF34+BC34+AZ34+AW34+AT34+AQ34+AN34+AK34 -> 0 | BS34: =BP34+BM34+BJ34+BG34+BD34+BA34+AX34+AU34+AR34+AO34+AL34 -> 0 | BT34: =BQ34+BN34+BK34+BH34+BE34+BB34+AY34+AV34+AS34+AP34+AM34 -> 0 | CA34: 200 | CB34: 2800 | CC34: 1792 | DB34: =CY34+CV34+CS34+CP34+CM34+CJ34+CG34+CD34+CA34+BX34+BU34+BR34 -> 200 | DC34: =CZ34+CW34+CT34+CQ34+CN34+CK34+CH34+CE34+CB34+BY34+BV34+BS34 -> 2800 | DD34: =DA34+CX34+CU34+CR34+CO34+CL34+CI34+CF34+CC34+BZ34+BW34+BT34 -> 1792
A35: 6 | B35: ပျားနက် | C35: Black Bee | D35: ပခုက္ကူ | E35: Pakokku | F35: Semi Wholesale | AK35: =AH35+AE35+AB35+Y35+V35+S35+P35+M35+J35+G35 -> 0 | AL35: =AI35+AF35+AC35+Z35+W35+T35+Q35+N35+K35+H35 -> 0 | AM35: =AJ35+AG35+AD35+AA35+X35+U35+R35+O35+L35+I35 -> 0 | BR35: =BO35+BL35+BI35+BF35+BC35+AZ35+AW35+AT35+AQ35+AN35+AK35 -> 0 | BS35: =BP35+BM35+BJ35+BG35+BD35+BA35+AX35+AU35+AR35+AO35+AL35 -> 0 | BT35: =BQ35+BN35+BK35+BH35+BE35+BB35+AY35+AV35+AS35+AP35+AM35 -> 0 | CA35: 100 | CB35: 1400 | CC35: 896 | DB35: =CY35+CV35+CS35+CP35+CM35+CJ35+CG35+CD35+CA35+BX35+BU35+BR35 -> 100 | DC35: =CZ35+CW35+CT35+CQ35+CN35+CK35+CH35+CE35+CB35+BY35+BV35+BS35 -> 1400 | DD35: =DA35+CX35+CU35+CR35+CO35+CL35+CI35+CF35+CC35+BZ35+BW35+BT35 -> 896
A36: 7 | B36: ရွှေရောင်စင် | C36: Shwe Yaung Sin | D36: ပခုက္ကူ | E36: Pakokku | F36: Semi Wholesale | AK36: =AH36+AE36+AB36+Y36+V36+S36+P36+M36+J36+G36 -> 0 | AL36: =AI36+AF36+AC36+Z36+W36+T36+Q36+N36+K36+H36 -> 0 | AM36: =AJ36+AG36+AD36+AA36+X36+U36+R36+O36+L36+I36 -> 0 | AZ36: 100 | BA36: 1400 | BB36: 896 | BR36: =BO36+BL36+BI36+BF36+BC36+AZ36+AW36+AT36+AQ36+AN36+AK36 -> 100 | BS36: =BP36+BM36+BJ36+BG36+BD36+BA36+AX36+AU36+AR36+AO36+AL36 -> 1400 | BT36: =BQ36+BN36+BK36+BH36+BE36+BB36+AY36+AV36+AS36+AP36+AM36 -> 896 | CA36: 200 | CB36: 2800 | CC36: 1792 | DB36: =CY36+CV36+CS36+CP36+CM36+CJ36+CG36+CD36+CA36+BX36+BU36+BR36 -> 300 | DC36: =CZ36+CW36+CT36+CQ36+CN36+CK36+CH36+CE36+CB36+BY36+BV36+BS36 -> 4200 | DD36: =DA36+CX36+CU36+CR36+CO36+CL36+CI36+CF36+CC36+BZ36+BW36+BT36 -> 2688
A37: 8 | B37: A1 | C37: A-1 | D37: ပုဂံ | E37: Bagan | F37: Semi Wholesale | AE37: 300 | AF37: 3700 | AG37: 3448 | AK37: =AH37+AE37+AB37+Y37+V37+S37+P37+M37+J37+G37 -> 300 | AL37: =AI37+AF37+AC37+Z37+W37+T37+Q37+N37+K37+H37 -> 3700 | AM37: =AJ37+AG37+AD37+AA37+X37+U37+R37+O37+L37+I37 -> 3448 | BR37: =BO37+BL37+BI37+BF37+BC37+AZ37+AW37+AT37+AQ37+AN37+AK37 -> 300 | BS37: =BP37+BM37+BJ37+BG37+BD37+BA37+AX37+AU37+AR37+AO37+AL37 -> 3700 | BT37: =BQ37+BN37+BK37+BH37+BE37+BB37+AY37+AV37+AS37+AP37+AM37 -> 3448 | DB37: =CY37+CV37+CS37+CP37+CM37+CJ37+CG37+CD37+CA37+BX37+BU37+BR37 -> 300 | DC37: =CZ37+CW37+CT37+CQ37+CN37+CK37+CH37+CE37+CB37+BY37+BV37+BS37 -> 3700 | DD37: =DA37+CX37+CU37+CR37+CO37+CL37+CI37+CF37+CC37+BZ37+BW37+BT37 -> 3448
A38: 9 | B38: ‌ရွှေခေတ် | C38: Shwe Khit | D38: မလှိုင် | E38: Mahlaing | F38: Semi Wholesale | S38: 75 | T38: 950 | U38: 824 | AK38: =AH38+AE38+AB38+Y38+V38+S38+P38+M38+J38+G38 -> 75 | AL38: =AI38+AF38+AC38+Z38+W38+T38+Q38+N38+K38+H38 -> 950 | AM38: =AJ38+AG38+AD38+AA38+X38+U38+R38+O38+L38+I38 -> 824 | BC38: 57 | BD38: 794 | BE38: 509.6 | BR38: =BO38+BL38+BI38+BF38+BC38+AZ38+AW38+AT38+AQ38+AN38+AK38 -> 132 | BS38: =BP38+BM38+BJ38+BG38+BD38+BA38+AX38+AU38+AR38+AO38+AL38 -> 1744 | BT38: =BQ38+BN38+BK38+BH38+BE38+BB38+AY38+AV38+AS38+AP38+AM38 -> 1333.6 | CS38: 120 | CT38: 1480 | CU38: 1379.2 | DB38: =CY38+CV38+CS38+CP38+CM38+CJ38+CG38+CD38+CA38+BX38+BU38+BR38 -> 252 | DC38: =CZ38+CW38+CT38+CQ38+CN38+CK38+CH38+CE38+CB38+BY38+BV38+BS38 -> 3224 | DD38: =DA38+CX38+CU38+CR38+CO38+CL38+CI38+CF38+CC38+BZ38+BW38+BT38 -> 2712.8
A39: 10 | B39: ဟိန်းမြန်မာ | C39: Hein Myanmar | D39: မလှိုင် | E39: Mahlaing | F39: Semi Wholesale | S39: 60 | T39: 840 | U39: 537.6 | AK39: =AH39+AE39+AB39+Y39+V39+S39+P39+M39+J39+G39 -> 60 | AL39: =AI39+AF39+AC39+Z39+W39+T39+Q39+N39+K39+H39 -> 840 | AM39: =AJ39+AG39+AD39+AA39+X39+U39+R39+O39+L39+I39 -> 537.6 | BR39: =BO39+BL39+BI39+BF39+BC39+AZ39+AW39+AT39+AQ39+AN39+AK39 -> 60 | BS39: =BP39+BM39+BJ39+BG39+BD39+BA39+AX39+AU39+AR39+AO39+AL39 -> 840 | BT39: =BQ39+BN39+BK39+BH39+BE39+BB39+AY39+AV39+AS39+AP39+AM39 -> 537.6 | CJ39: 60 | CK39: 890 | CL39: 569.6 | DB39: =CY39+CV39+CS39+CP39+CM39+CJ39+CG39+CD39+CA39+BX39+BU39+BR39 -> 120 | DC39: =CZ39+CW39+CT39+CQ39+CN39+CK39+CH39+CE39+CB39+BY39+BV39+BS39 -> 1730 | DD39: =DA39+CX39+CU39+CR39+CO39+CL39+CI39+CF39+CC39+BZ39+BW39+BT39 -> 1107.2
A40: Total (10) | G40: =SUM(G30:G39) -> 0 | H40: =SUM(H30:H39) -> 0 | I40: =SUM(I30:I39) -> 0 | J40: =SUM(J30:J39) -> 0 | K40: =SUM(K30:K39) -> 0 | L40: =SUM(L30:L39) -> 0 | M40: =SUM(M30:M39) -> 0 | N40: =SUM(N30:N39) -> 0 | ... AY40: =SUM(AY30:AY39) -> 0 | AZ40: 565 | BA40: 10060 | BB40: 6438.4 | BC40: 57 | BD40: 794 | BE40: 509.6 | BF40: 0 | BG40: 0 | BH40: 0 | BI40: =SUM(BI30:BI39) -> 0 | BJ40: =SUM(BJ30:BJ39) -> 0 | BK40: =SUM(BK30:BK39) -> 0 | BL40: =SUM(BL30:BL39) -> 0 | BM40: =SUM(BM30:BM39) -> 0 | BN40: =SUM(BN30:BN39) -> 0 | BO40: =SUM(BO30:BO39) -> 0 | BP40: =SUM(BP30:BP39) -> 0 | ... DD40: =SUM(DD30:DD39) -> 19684
...

Sheet FollowUpSales
I1: 2026 | J1: Q1 | M1: Q2 | P1: Q3 | S1: Q4
J2: January | K2: February | L2: March | M2: April | N2: May | O2: June | P2: July | Q2: August | R2: September | S2: October | T2: November | U2: December
I3: Target (Bot) | J3: 1003247 | K3: 1003247 | L3: 1003247 | M3: 926074 | N3: 926074 | O3: 926074 | P3: 964660 | Q3: 964660 | R3: 964660 | S3: 964660 | T3: 964660 | U3: 964660 | V3: =SUM(J3:U3) -> 11575923
I4: Target (Liter) | J4: 664538 | K4: 664538 | L4: 664538 | M4: 613420 | N4: 613420 | O4: 613420 | P4: 638979 | Q4: 638979 | R4: 638979 | S4: 638979 | T4: 638979 | U4: 638979 | V4: =SUM(J4:U4) -> 7667748
I5: WS (Bot) | J5: =O50 -> 729352 | K5: =X50 -> 650576 | L5: =AG50 -> 464262 | V5: =SUM(J5:U5) -> 1844190
I6: Semi WS | J6: =O66 -> 28054 | K6: =X66 -> 21814 | L6: =AG66 -> 23916 | V6: =SUM(J6:U6) -> 73784
V7: =SUM(J7:U7) -> 0
I8: Van (Bot) | J8: =O74 -> 65581 | K8: =X74 -> 57351 | L8: =AG74 -> 39008 | V8: =SUM(J8:U8) -> 161940
I9: Total Sales (BOT) | J9: =SUM(J5:J8) -> 822987 | K9: =SUM(K5:K8) -> 729741 | L9: =SUM(L5:L8) -> 527186 | V9: =SUM(J9:U9) -> 2079914
I10: Total Sales (Liter) | J10: =P50+P66+P74 -> 549147.6 | K10: =Y50+Y66+Y74 -> 486294.32 | L10: =AH50+AH66+AH74 -> 353283.56 | V10: =SUM(J10:U10) -> 1388725.5
I11: Ach % (Bot) | J11: =J9/J3 -> 0.82032341 | K11: =K9/K3 -> 0.7273792 | L11: =L9/L3 -> 0.52547977 | M11: =M9/M3 -> 0 | N11: =N9/N3 -> 0 | O11: =+O9/O3 -> 0 | P11: =P9/P3 -> 0 | Q11: =+Q9/Q3 -> 0 | R11: =+R9/R3 -> 0 | S11: =S9/S3 -> 0 | T11: =+T9/T3 -> 0 | U11: =+U9/U3 -> 0 | V11: =+V9/V3 -> 0.17967587
I12: Ach % (Liter) | J12: =J10/J4 -> 0.82635997 | K12: =+K10/K4 -> 0.73177805 | L12: =+L10/L4 -> 0.53162281 | M12: =M10/M4 -> 0 | N12: =+N10/N4 -> 0 | O12: =+O10/O4 -> 0 | P12: =P10/P4 -> 0 | Q12: =+Q10/Q4 -> 0 | R12: =+R10/R4 -> 0 | S12: =S10/S4 -> 0 | T12: =+T10/T4 -> 0 | U12: =+U10/U4 -> 0 | V12: =V10/V4 -> 0.18111256
J14: Contribution
J15: January | K15: February | L15: March | M15: April | N15: May | O15: June | P15: July | Q15: August | R15: September | S15: October | T15: November | U15: December
I16: WS | J16: 0.88 | K16: 0.88 | L16: 0.88
I17: SemiWS | J17: 0.05 | K17: 0.05 | L17: 0.05
I18: VAN | J18: 0.07 | K18: 0.07 | L18: 0.07
J19: 1 | K19: 1 | L19: 1 | M19: 1 | N19: 1 | O19: 1 | P19: 1 | Q19: 1 | R19: 1 | S19: 1 | T19: 1 | U19: 1
I21: Quarter 1
B22: Wholesales Follow Up - (Region) | I22: Jan'26 | R22: Feb'26 | AA22: Mar'26 | AJ22: Q1 Total
I23: =J4*J16 -> 584793.44 | K23: 10 | M23: 20 | O23: 30 | Q23: Ach % | R23: =K16*K4 -> 584793.44 | T23: 10 | V23: 20 | X23: 30 | Z23: Ach % | AA23: =L16*L4 -> 584793.44 | AC23: 10 | AE23: 20 | AG23: 30 | AI23: Ach % | AJ23: Target | AK23: Sales | AL23: Ach %
A24: Sr No. | B24: Customer Name | D24: Area | F24: Outlet Type | G24: Cons% | H24: Resp By | I24: Bottle | J24: Liter | K24: Bottle | L24: Ltr | M24: Bottle | N24: Ltr | O24: Bottle | P24: Ltr | Q24: Liter | R24: Bottle | S24: Liter | T24: Bottle | U24: Ltr | V24: Bottle | W24: Ltr | X24: Bottle | Y24: Ltr | Z24: Liter | AA24: Bottle | AB24: Liter | AC24: Bottle | AD24: Ltr | AE24: Bottle | AF24: Ltr | AG24: Bottle | AH24: Ltr | AI24: Liter | AJ24: Liter | AK24: Liter | AL24: Liter
A25: 1 | B25: ရွှေမြင်း | C25: Golden Horse | D25: မိတ္ထီလာ | E25: Meikhtila | F25: Wholesale | G25: 0.2 | I25: 161000 | J25: 116958.69 | K25: ='2026-FUS'!AL4 -> 40332 | L25: ='2026-FUS'!AM4 -> 27720.48 | M25: ='2026-FUS'!BS4 -> 91702 | N25: ='2026-FUS'!BT4 -> 61936.48 | O25: ='2026-FUS'!DC4 -> 143492 | P25: ='2026-FUS'!DD4 -> 96349.28 | Q25: =IFERROR((P25/J25),0) -> 0.82378899 | R25: 161000 | S25: 116958.69 | T25: ='2026-FUS'!AL51 -> 43466 | U25: ='2026-FUS'!AM51 -> 28855.04 | V25: ='2026-FUS'!BS51 -> 87306 | W25: ='2026-FUS'!BT51 -> 57654.24 | X25: ='2026-FUS'!DC51 -> 129856 | Y25: ='2026-FUS'!DD51 -> 85707.04 | Z25: =IFERROR((Y25/S25),0) -> 0.73279755 | AA25: 161000 | AB25: 116958.69 | AC25: ='2026-FUS'!AL99 -> 49940 | AD25: ='2026-FUS'!AM99 -> 33020 | AE25: ='2026-FUS'!BS99 -> 87732 | AF25: ='2026-FUS'!BT99 -> 58157.28 | AG25: ='2026-FUS'!DC99 -> 87732 | AH25: ='2026-FUS'!DD99 -> 58157.28 | AI25: =IFERROR((AH25/AB25),0) -> 0.49724634 | AJ25: =+J25+S25+AB25 -> 350876.06 | AK25: =+P25+Y25+AH25 -> 240213.6 | AL25: =IFERROR((AK25/AJ25),0) -> 0.68461096
A26: 2 | B26: ရွှေခြင်္သေ့ | C26: Golden Lion | D26: မိတ္ထီလာ | E26: Meikhtila | F26: Contract | G26: 0.05 | I26: 44800 | J26: 29239.672 | K26: ='2026-FUS'!AL5 -> 15860 | L26: ='2026-FUS'!AM5 -> 10841.6 | M26: ='2026-FUS'!BS5 -> 30900 | N26: ='2026-FUS'!BT5 -> 20853.6 | O26: ='2026-FUS'!DC5 -> 45020 | P26: ='2026-FUS'!DD5 -> 30365.6 | Q26: =IFERROR((P26/J26),0) -> 1.0385069 | R26: 44800 | S26: 29239.672 | T26: ='2026-FUS'!AL52 -> 16110 | U26: ='2026-FUS'!AM52 -> 10754.4 | V26: ='2026-FUS'!BS52 -> 27940 | W26: ='2026-FUS'!BT52 -> 18584.8 | X26: ='2026-FUS'!DC52 -> 38530 | Y26: ='2026-FUS'!DD52 -> 25568.8 | Z26: =IFERROR((Y26/S26),0) -> 0.87445577 | AA26: 44800 | AB26: 29239.672 | AC26: ='2026-FUS'!AL100 -> 10460 | AD26: ='2026-FUS'!AM100 -> 6888.8 | AE26: ='2026-FUS'!BS100 -> 18190 | AF26: ='2026-FUS'!BT100 -> 12138.4 | AG26: ='2026-FUS'!DC100 -> 18190 | AH26: ='2026-FUS'!DD100 -> 12138.4 | AI26: =IFERROR((AH26/AB26),0) -> 0.41513462 | AJ26: =+J26+S26+AB26 -> 87719.016 | AK26: =+P26+Y26+AH26 -> 68072.8 | AL26: =IFERROR((AK26/AJ26),0) -> 0.77603242
A27: 3 | B27: ကောင်းသန့် | C27: Kaung Thant | D27: မိတ္ထီလာ | E27: Meikhtila | F27: Contract | G27: 0.08 | I27: 65800 | J27: 46783.475 | K27: ='2026-FUS'!AL6 -> 20398 | L27: ='2026-FUS'!AM6 -> 13061.92 | M27: ='2026-FUS'!BS6 -> 47054 | N27: ='2026-FUS'!BT6 -> 30121.76 | O27: ='2026-FUS'!DC6 -> 72248 | P27: ='2026-FUS'!DD6 -> 46245.92 | Q27: =IFERROR((P27/J27),0) -> 0.98850972 | R27: 65800 | S27: 46783.475 | T27: ='2026-FUS'!AL53 -> 18882 | U27: ='2026-FUS'!AM53 -> 12084.48 | V27: ='2026-FUS'!BS53 -> 38018 | W27: ='2026-FUS'!BT53 -> 24335.12 | X27: ='2026-FUS'!DC53 -> 52316 | Y27: ='2026-FUS'!DD53 -> 33485.84 | Z27: =IFERROR((Y27/S27),0) -> 0.71576213 | AA27: 65800 | AB27: 46783.475 | AC27: ='2026-FUS'!AL101 -> 9470 | AD27: ='2026-FUS'!AM101 -> 6060.8 | AE27: ='2026-FUS'!BS101 -> 24722 | AF27: ='2026-FUS'!BT101 -> 15822.08 | AG27: ='2026-FUS'!DC101 -> 24722 | AH27: ='2026-FUS'!DD101 -> 15822.08 | AI27: =IFERROR((AH27/AB27),0) -> 0.33819805 | AJ27: =+J27+S27+AB27 -> 140350.43 | AK27: =+P27+Y27+AH27 -> 95553.84 | AL27: =IFERROR((AK27/AJ27),0) -> 0.6808233
A28: 4 | B28: ဦးဝင်းနိုင် | C28: U Win Naing | D28: လျှော်ပင် | E28: Wundwin | F28: Contract | G28: 0.11 | I28: 89600 | J28: 64327.278 | K28: ='2026-FUS'!AL7 -> 29800 | L28: ='2026-FUS'!AM7 -> 20110.24 | M28: ='2026-FUS'!BS7 -> 49790 | N28: ='2026-FUS'!BT7 -> 33463.52 | O28: ='2026-FUS'!DC7 -> 86376 | P28: ='2026-FUS'!DD7 -> 58025.28 | Q28: =IFERROR((P28/J28),0) -> 0.90203226 | R28: 89600 | S28: 64327.278 | T28: ='2026-FUS'!AL54 -> 25736 | U28: ='2026-FUS'!AM54 -> 16773.44 | V28: ='2026-FUS'!BS54 -> 64940 | W28: ='2026-FUS'!BT54 -> 42447.68 | X28: ='2026-FUS'!DC54 -> 95264 | Y28: ='2026-FUS'!DD54 -> 62258.72 | Z28: =IFERROR((Y28/S28),0) -> 0.96784322 | AA28: 89600 | AB28: 64327.278 | AC28: ='2026-FUS'!AL102 -> 43258 | AD28: ='2026-FUS'!AM102 -> 28714.24 | AE28: ='2026-FUS'!BS102 -> 64890 | AF28: ='2026-FUS'!BT102 -> 43144.32 | AG28: ='2026-FUS'!DC102 -> 64890 | AH28: ='2026-FUS'!DD102 -> 43144.32 | AI28: =IFERROR((AH28/AB28),0) -> 0.67070022 | AJ28: =+J28+S28+AB28 -> 192981.84 | AK28: =+P28+Y28+AH28 -> 163428.32 | AL28: =IFERROR((AK28/AJ28),0) -> 0.84685856
A29: 5 | B29: ကျော်ကြား | C29: Kyaw Kyar | D29: မလှိုင် | E29: Mahlaing | F29: Contract | G29: 0.04 | I29: 29400 | J29: 23391.738 | K29: ='2026-FUS'!AL8 -> 16280 | L29: ='2026-FUS'!AM8 -> 10635.2 | M29: ='2026-FUS'!BS8 -> 22460 | N29: ='2026-FUS'!BT8 -> 14691.2 | O29: ='2026-FUS'!DC8 -> 30990 | P29: ='2026-FUS'!DD8 -> 20280 | Q29: =IFERROR((P29/J29),0) -> 0.86697279 | R29: 29400 | S29: 23391.738 | T29: ='2026-FUS'!AL55 -> 10880 | U29: ='2026-FUS'!AM55 -> 7092.8 | V29: ='2026-FUS'!BS55 -> 18480 | W29: ='2026-FUS'!BT55 -> 11956.8 | X29: ='2026-FUS'!DC55 -> 27540 | Y29: ='2026-FUS'!DD55 -> 17884.8 | Z29: =IFERROR((Y29/S29),0) -> 0.76457766 | AA29: 29400 | AB29: 23391.738 | AC29: ='2026-FUS'!AL103 -> 13730 | AD29: ='2026-FUS'!AM103 -> 8787.2 | AE29: ='2026-FUS'!BS103 -> 21410 | AF29: ='2026-FUS'!BT103 -> 13918.4 | AG29: ='2026-FUS'!DC103 -> 21410 | AH29: ='2026-FUS'!DD103 -> 13918.4 | AI29: =IFERROR((AH29/AB29),0) -> 0.59501351 | AJ29: =+J29+S29+AB29 -> 70175.213 | AK29: =+P29+Y29+AH29 -> 52083.2 | AL29: =IFERROR((AK29/AJ29),0) -> 0.74218799
A30: 6 | B30: မယဉ်ယဉ်အေး | C30: Ma Yin Yin Aye | D30: မလှိုင် | E30: Mahlaing | F30: Contract | G30: 0.03 | I30: 29400 | J30: 17543.803 | K30: ='2026-FUS'!AL9 -> 10430 | L30: ='2026-FUS'!AM9 -> 6675.2 | M30: ='2026-FUS'!BS9 -> 19680 | N30: ='2026-FUS'!BT9 -> 12595.2 | O30: ='2026-FUS'!DC9 -> 27080 | P30: ='2026-FUS'!DD9 -> 17331.2 | Q30: =IFERROR((P30/J30),0) -> 0.98788158 | R30: 29400 | S30: 17543.803 | T30: ='2026-FUS'!AL56 -> 9220 | U30: ='2026-FUS'!AM56 -> 6116.8 | V30: ='2026-FUS'!BS56 -> 24960 | W30: ='2026-FUS'!BT56 -> 16190.4 | X30: ='2026-FUS'!DC56 -> 34160 | Y30: ='2026-FUS'!DD56 -> 22078.4 | Z30: =IFERROR((Y30/S30),0) -> 1.2584728 | AA30: 29400 | AB30: 17543.803 | AC30: ='2026-FUS'!AL104 -> 9180 | AD30: ='2026-FUS'!AM104 -> 5875.2 | AE30: ='2026-FUS'!BS104 -> 25200 | AF30: ='2026-FUS'!BT104 -> 16560 | AG30: ='2026-FUS'!DC104 -> 25200 | AH30: ='2026-FUS'!DD104 -> 16560 | AI30: =IFERROR((AH30/AB30),0) -> 0.94392304 | AJ30: =+J30+S30+AB30 -> 52631.41 | AK30: =+P30+Y30+AH30 -> 55969.6 | AL30: =IFERROR((AK30/AJ30),0) -> 1.0634258
A31: 7 | B31: စံချိန် | C31: Sanchain | D31: ရမည်းသင်း | E31: Yamethin | F31: Contract | G31: 0.01 | I31: 11200 | J31: 5847.9344 | K31: ='2026-FUS'!AL10 -> 2800 | L31: ='2026-FUS'!AM10 -> 1792 | M31: ='2026-FUS'!BS10 -> 4200 | N31: ='2026-FUS'!BT10 -> 2688 | O31: ='2026-FUS'!DC10 -> 10800 | P31: ='2026-FUS'!DD10 -> 6816 | Q31: =IFERROR((P31/J31),0) -> 1.1655398 | R31: 11200 | S31: 5847.9344 | T31: ='2026-FUS'!AL57 -> 4200 | U31: ='2026-FUS'!AM57 -> 2688 | V31: ='2026-FUS'!BS57 -> 4200 | W31: ='2026-FUS'!BT57 -> 2688 | X31: ='2026-FUS'!DC57 -> 8400 | Y31: ='2026-FUS'!DD57 -> 5376 | Z31: =IFERROR((Y31/S31),0) -> 0.91929896 | AA31: 11200 | AB31: 5847.9344 | AC31: ='2026-FUS'!AL105 -> 0 | AD31: ='2026-FUS'!AM105 -> 0 | AE31: ='2026-FUS'!BS105 -> 0 | AF31: ='2026-FUS'!BT105 -> 0 | AG31: ='2026-FUS'!DC105 -> 0 | AH31: ='2026-FUS'!DD105 -> 0 | AI31: =IFERROR((AH31/AB31),0) -> 0 | AJ31: =+J31+S31+AB31 -> 17543.803 | AK31: =+P31+Y31+AH31 -> 12192 | AL31: =IFERROR((AK31/AJ31),0) -> 0.69494624
A32: 8 | B32: ဦးရဲမြင့် | C32: U Ye Myint | D32: ပျော်ဘွယ် | E32: Pyawbwe | F32: Contract | G32: 0.09 | I32: 70000 | J32: 52631.41 | K32: ='2026-FUS'!AL11 -> 22540 | L32: ='2026-FUS'!AM11 -> 14425.6 | M32: ='2026-FUS'!BS11 -> 48400 | N32: ='2026-FUS'!BT11 -> 30976 | O32: ='2026-FUS'!DC11 -> 83900 | P32: ='2026-FUS'!DD11 -> 53732 | Q32: =IFERROR((P32/J32),0) -> 1.0209113 | R32: 70000 | S32: 52631.41 | T32: ='2026-FUS'!AL58 -> 19010 | U32: ='2026-FUS'!AM58 -> 12166.4 | V32: ='2026-FUS'!BS58 -> 47050 | W32: ='2026-FUS'!BT58 -> 30148 | X32: ='2026-FUS'!DC58 -> 69770 | Y32: ='2026-FUS'!DD58 -> 44688.8 | Z32: =IFERROR((Y32/S32),0) -> 0.84908993 | AA32: 70000 | AB32: 52631.41 | AC32: ='2026-FUS'!AL106 -> 25990 | AD32: ='2026-FUS'!AM106 -> 16669.6 | AE32: ='2026-FUS'!BS106 -> 46240 | AF32: ='2026-FUS'!BT106 -> 29629.6 | AG32: ='2026-FUS'!DC106 -> 46240 | AH32: ='2026-FUS'!DD106 -> 29629.6 | AI32: =IFERROR((AH32/AB32),0) -> 0.56296421 | AJ32: =+J32+S32+AB32 -> 157894.23 | AK32: =+P32+Y32+AH32 -> 128050.4 | AL32: =IFERROR((AK32/AJ32),0) -> 0.81098848
A33: 9 | B33: လွင် | C33: Lwin | D33: ကျောက်ပန်းတောင်း | E33: Kyaukpadaung | F33: Contract | G33: 0.05 | I33: 42000 | J33: 29239.672 | K33: ='2026-FUS'!AL12 -> 7720 | L33: ='2026-FUS'!AM12 -> 4940.8 | M33: ='2026-FUS'!BS12 -> 28660 | N33: ='2026-FUS'!BT12 -> 18955.6 | O33: ='2026-FUS'!DC12 -> 45700 | P33: ='2026-FUS'!DD12 -> 29945.2 | Q33: =IFERROR((P33/J33),0) -> 1.0241291 | R33: 42000 | S33: 29239.672 | T33: ='2026-FUS'!AL59 -> 12680 | U33: ='2026-FUS'!AM59 -> 8249.6 | V33: ='2026-FUS'!BS59 -> 24380 | W33: ='2026-FUS'!BT59 -> 15923.6 | X33: ='2026-FUS'!DC59 -> 36340 | Y33: ='2026-FUS'!DD59 -> 24061.6 | Z33: =IFERROR((Y33/S33),0) -> 0.82290937 | AA33: 42000 | AB33: 29239.672 | AC33: ='2026-FUS'!AL107 -> 13410 | AD33: ='2026-FUS'!AM107 -> 8482.8 | AE33: ='2026-FUS'!BS107 -> 34430 | AF33: ='2026-FUS'!BT107 -> 22079.6 | AG33: ='2026-FUS'!DC107 -> 34430 | AH33: ='2026-FUS'!DD107 -> 22079.6 | AI33: =IFERROR((AH33/AB33),0) -> 0.75512475 | AJ33: =+J33+S33+AB33 -> 87719.016 | AK33: =+P33+Y33+AH33 -> 76086.4 | AL33: =IFERROR((AK33/AJ33),0) -> 0.86738775
A34: 10 | B34: ဦးစိုးဝင်း | C34: U Soe Win | D34: ကျောက်ပန်းတောင်း | E34: Kyaukpadaung | F34: Contract | G34: 0.04 | I34: 32200 | J34: 23391.738 | K34: ='2026-FUS'!AL13 -> 0 | L34: ='2026-FUS'!AM13 -> 0 | M34: ='2026-FUS'!BS13 -> 0 | N34: ='2026-FUS'!BT13 -> 0 | O34: ='2026-FUS'!DC13 -> 12620 | P34: ='2026-FUS'!DD13 -> 8076.8 | Q34: =IFERROR((P34/J34),0) -> 0.34528431 | R34: 32200 | S34: 23391.738 | T34: ='2026-FUS'!AL60 -> 0 | U34: ='2026-FUS'!AM60 -> 0 | V34: ='2026-FUS'!BS60 -> 7740 | W34: ='2026-FUS'!BT60 -> 4953.6 | X34: ='2026-FUS'!DC60 -> 7740 | Y34: ='2026-FUS'!DD60 -> 4953.6 | Z34: =IFERROR((Y34/S34),0) -> 0.21176708 | AA34: 32200 | AB34: 23391.738 | AC34: ='2026-FUS'!AL108 -> 3600 | AD34: ='2026-FUS'!AM108 -> 3600 | AE34: ='2026-FUS'!BS108 -> 12700 | AF34: ='2026-FUS'!BT108 -> 9424 | AG34: ='2026-FUS'!DC108 -> 12700 | AH34: ='2026-FUS'!DD108 -> 9424 | AI34: =IFERROR((AH34/AB34),0) -> 0.4028773 | AJ34: =+J34+S34+AB34 -> 70175.213 | AK34: =+P34+Y34+AH34 -> 22454.4 | AL34: =IFERROR((AK34/AJ34),0) -> 0.31997623
A35: 11 | B35: ဦးသိန်းစိုး | C35: U Thein Soe | D35: ကျောက်ပန်းတောင်း | E35: Kyaukpadaung | F35: Contract | G35: 0.02 | I35: 22400 | J35: 11695.869 | K35: ='2026-FUS'!AL14 -> 2950 | L35: ='2026-FUS'!AM14 -> 2320 | M35: ='2026-FUS'!BS14 -> 10750 | N35: ='2026-FUS'!BT14 -> 7168 | O35: ='2026-FUS'!DC14 -> 17790 | P35: ='2026-FUS'!DD14 -> 11673.6 | Q35: =IFERROR((P35/J35),0) -> 0.99809601 | R35: 22400 | S35: 11695.869 | T35: ='2026-FUS'!AL61 -> 3320 | U35: ='2026-FUS'!AM61 -> 2556.8 | V35: ='2026-FUS'!BS61 -> 5420 | W35: ='2026-FUS'!BT61 -> 3900.8 | X35: ='2026-FUS'!DC61 -> 13120 | Y35: ='2026-FUS'!DD61 -> 8828.8 | Z35: =IFERROR((Y35/S35),0) -> 0.75486483 | AA35: 22400 | AB35: 11695.869 | AC35: ='2026-FUS'!AL109 -> 5400 | AD35: ='2026-FUS'!AM109 -> 3480 | AE35: ='2026-FUS'!BS109 -> 11000 | AF35: ='2026-FUS'!BT109 -> 7064 | AG35: ='2026-FUS'!DC109 -> 11000 | AH35: ='2026-FUS'!DD109 -> 7064 | AI35: =IFERROR((AH35/AB35),0) -> 0.60397394 | AJ35: =+J35+S35+AB35 -> 35087.606 | AK35: =+P35+Y35+AH35 -> 27566.4 | AL35: =IFERROR((AK35/AJ35),0) -> 0.78564493
A36: 12 | B36: ကောင်းထက်သူ | C36: Kaung Htet Thu | D36: ကျောက်ပန်းတောင်း | E36: Kyaukpadaung | F36: Contract | G36: 0.02 | I36: 16800 | J36: 11695.869 | K36: ='2026-FUS'!AL15 -> 4000 | L36: ='2026-FUS'!AM15 -> 2512 | M36: ='2026-FUS'!BS15 -> 7500 | N36: ='2026-FUS'!BT15 -> 4752 | O36: ='2026-FUS'!DC15 -> 12220 | P36: ='2026-FUS'!DD15 -> 7811.2 | Q36: =IFERROR((P36/J36),0) -> 0.66785975 | R36: 16800 | S36: 11695.869 | T36: ='2026-FUS'!AL62 -> 7980 | U36: ='2026-FUS'!AM62 -> 5059.2 | V36: ='2026-FUS'!BS62 -> 11260 | W36: ='2026-FUS'!BT62 -> 7331.2 | X36: ='2026-FUS'!DC62 -> 15460 | Y36: ='2026-FUS'!DD62 -> 10019.2 | Z36: =IFERROR((Y36/S36),0) -> 0.85664436 | AA36: 16800 | AB36: 11695.869 | AC36: ='2026-FUS'!AL110 -> 3440 | AD36: ='2026-FUS'!AM110 -> 2331.2 | AE36: ='2026-FUS'!BS110 -> 13040 | AF36: ='2026-FUS'!BT110 -> 8427.2 | AG36: ='2026-FUS'!DC110 -> 13040 | AH36: ='2026-FUS'!DD110 -> 8427.2 | AI36: =IFERROR((AH36/AB36),0) -> 0.72052792 | AJ36: =+J36+S36+AB36 -> 35087.606 | AK36: =+P36+Y36+AH36 -> 26257.6 | AL36: =IFERROR((AK36/AJ36),0) -> 0.74834401
... A49: 25 | B49: ဦးတင်မောင် | C49: U Tin Maung | D49: ပခုက္ကူ | E49: Pakokku | F49: Wholesale | G49: 0.01 | I49: 12600 | J49: 5847.9344 | K49: ='2026-FUS'!AL28 -> 0 | L49: ='2026-FUS'!AM28 -> 0 | M49: ='2026-FUS'!BS28 -> 3500 | N49: ='2026-FUS'!BT28 -> 2240 | O49: ='2026-FUS'!DC28 -> 7700 | P49: ='2026-FUS'!DD28 -> 4928 | Q49: =IFERROR((P49/J49),0) -> 0.84269071 | R49: 12600 | S49: 5847.9344 | T49: ='2026-FUS'!AL75 -> 0 | U49: ='2026-FUS'!AM75 -> 0 | V49: ='2026-FUS'!BS75 -> 0 | W49: ='2026-FUS'!BT75 -> 0 | X49: ='2026-FUS'!DC75 -> 0 | Y49: ='2026-FUS'!DD75 -> 0 | Z49: =IFERROR((Y49/S49),0) -> 0 | AA49: 12600 | AB49: 5847.9344 | AC49: ='2026-FUS'!AL123 -> 0 | AD49: ='2026-FUS'!AM123 -> 0 | AE49: ='2026-FUS'!BS123 -> 2600 | AF49: ='2026-FUS'!BT123 -> 2096 | AG49: ='2026-FUS'!DC123 -> 2600 | AH49: ='2026-FUS'!DD123 -> 2096 | AI49: =IFERROR((AH49/AB49),0) -> 0.35841715 | AJ49: =+J49+S49+AB49 -> 17543.803 | AK49: =+P49+Y49+AH49 -> 7024 | AL49: =IFERROR((AK49/AJ49),0) -> 0.40036929
B50: Total Wholesales ( 25) | G50: =SUM(G25:G49) -> 1 | I50: =SUM(I25:I49) -> 844900 | J50: =SUM(J25:J49) -> 584793.44 | K50: =SUM(K25:K49) -> 222748 | L50: =SUM(L25:L49) -> 147924.16 | M50: =SUM(M25:M49) -> 453332 | N50: =SUM(N25:N49) -> 299078 | O50: =SUM(O25:O49) -> 729352 | P50: =SUM(P25:P49) -> 479839.12 | Q50: =IFERROR((P50/J50),0) -> 0.82052754 | R50: =SUM(R25:R49) -> 844900 | S50: =SUM(S25:S49) -> 584793.44 | T50: =SUM(T25:T49) -> 210944 | U50: =SUM(U25:U49) -> 138688.16 | V50: =SUM(V25:V49) -> 446874 | W50: =SUM(W25:W49) -> 291956.64 | X50: =SUM(X25:X49) -> 650576 | Y50: =SUM(Y25:Y49) -> 425536.4 | Z50: =IFERROR((Y50/S50),0) -> 0.72766959 | AA50: =SUM(AA25:AA49) -> 844900 | AB50: =SUM(AB25:AB49) -> 584793.44 | AC50: =SUM(AC25:AC49) -> 238838 | AD50: =SUM(AD25:AD49) -> 157172.24 | AE50: =SUM(AE25:AE49) -> 464262 | AF50: =SUM(AF25:AF49) -> 305594.16 | AG50: =SUM(AG25:AG49) -> 464262 | AH50: =SUM(AH25:AH49) -> 305594.16 | AI50: =IFERROR((AH50/AB50),0) -> 0.5225677 | AJ50: =SUM(AJ25:AJ47) -> 1719292.7 | AK50: =+P50+Y50+AH50 -> 1210969.7 | AL50: =IFERROR((AK50/AJ50),0) -> 0.70434177
I52: Quarter 1
B53: Semi Wholesales Follow Up - (Region) | I53: Jan'26 | R53: Feb'26 | AA53: Mar'26 | AJ53: Q1 Total
I54: =J4*J17 -> 33226.9 | K54: 10 | M54: 20 | O54: 30 | Q54: Ach % | R54: =K17*K4 -> 33226.9 | T54: 10 | V54: 20 | X54: 30 | Z54: Ach % | AA54: =L17*L4 -> 33226.9 | AC54: 10 | AE54: 20 | AG54: 30 | AI54: Ach % | AJ54: Target | AK54: Sales | AL54: Ach %
A55: Sr No. | B55: Customer Name | D55: Area | F55: Outlet Type | G55: Cons% | H55: Resp By | I55: Bottle | J55: Liter | K55: Bottle | L55: Ltr | M55: Bottle | N55: Ltr | O55: Bottle | P55: Ltr | Q55: Liter | R55: Bottle | S55: Liter | T55: Bottle | U55: Ltr | V55: Bottle | W55: Ltr | X55: Bottle | Y55: Ltr | Z55: Liter | AA55: Bottle | AB55: Liter | AC55: Bottle | AD55: Ltr | AE55: Bottle | AF55: Ltr | AG55: Bottle | AH55: Ltr | AI55: Liter | AJ55: Liter | AK55: Liter | AL55: Liter
...

Sheet SUM
C1: ‌ရွှေမြင်း | CH1: Total (PKT) | CI1: =CE40 -> 47986 | CK1: 12 | CL1: 14
A2: No | B2: Outlet Name | C2: SKU | CH2: Total (BOT) | CI2: =CF40 -> 757406 | CK2: 24 | CL2: 40
C3: သံပုရာ (1*14) | E3: ရှောက်ပျား (1*14) | G3: လိမ္မော်ဖြူ (1*24) | I3: ဒဂုံသန့် (1*14) | K3: ကင်းမြီးကောက် (1*14) | M3: ဇေသန့် (1*14) | O3: ဒဂုံနာနတ် (1*24) | Q3: Black Cat (1*24) | S3: ဇေRedပု (1*14) | U3: ဇေရမ် (1*14) | W3: ကောင်းကြည် (1*14) | Y3: မိုးနဲကွန်ကီး (1*14) | AA3: 2 in 1 မက (1*14) | AC3: Vodka(1*12) (700ml) | AE3: ZayRed(1*12) (700ml) | AG3: Formula Rum(1*12) (700ml) | AI3: Formula Rum(1*24) (350ml) | AK3: ကောင်းကြည်(1*12) (600ml) | AM3: ကောင်းကြည် (1*12) (1000ml) | AO3: ဇေ (1*12) (600ml) | AQ3: ဇေ (1*12) (1000ml) | AS3: ဇေ Red(1*12) (1000ml) | AU3: ဇေRedပု(1*12) 680ml | AW3: ရွှေမင်းသားခေါင်ရည် (1*24) | AY3: ချယ်ရီအရက်သန့် (1*14) | BA3: ဒဂုံမန်ကျည်းအရက် (1*14) | BC3: ချယ်ရီကော်(1*24) (600 ml) | BE3: ချယ်ရီသံပုရာ(1*24) (600ml) | BG3: ချယ်ရီသံပုရာ(1*12) (1000 ml) | BI3: မိုးနဲကွန်ကီးကော်1L (1*24) | BK3: မိုးနဲကွန်ကီးကော်1L (1*12) | BM3: ရွှေမန်းပုလင်း (1*14) | BO3: ရွှေမန်းကော်ဗူး 1L (1*12) | BS3: ရွှေမင်းသားမန်ကျည်းခေါင်ရည် (1*14) | BU3: ရွှေမင်းသားခေါင်ရည် ကော်ဗူး (1*12) | BW3: ရွှေမင်းသားမန်ကျည်း ခေါင်ရည်ကော်ဗူး (1*12) | CE3: Total Sales
C4: PKT | D4: BOT | E4: PKT | F4: BOT | G4: PKT | H4: BOT | I4: PKT | J4: BOT | L4: BOT | M4: PKT | N4: BOT | O4: PKT | P4: BOT | Q4: PKT | R4: BOT | S4: PKT | T4: BOT | U4: PKT | V4: BOT | W4: PKT | X4: BOT | Y4: PKT | Z4: BOT | AA4: PKT | AB4: BOT | AC4: PKT | AD4: BOT | AE4: PKT | AF4: BOT | AG4: PKT | AH4: BOT | AI4: PKT | AJ4: BOT | AK4: PKT | AL4: BOT | AM4: PKT | AN4: BOT | AO4: PKT | AP4: BOT | AQ4: PKT | AR4: BOT | AS4: PKT | AT4: BOT | AU4: PKT | AV4: BOT | AW4: PKT | AX4: BOT | AY4: PKT | AZ4: BOT | BA4: PKT | BB4: BOT | BC4: PKT | BD4: BOT | BE4: PKT | BF4: BOT | BG4: PKT | BH4: BOT | BI4: PTK | BJ4: BOT | BK4: PTK | BL4: BOT | BM4: PTK | BN4: BOT | BO4: PTK | BP4: BOT | BQ4: PKT | BR4: BOT | BS4: PKT | BT4: BOT | BU4: PKT | BV4: BOT | BW4: PKT | BX4: BOT | BY4: PKT | BZ4: BOT | CA4: PKT | CB4: BOT | CC4: PKT | CD4: BOT | CE4: PKT | CF4: BOT
A5: 1 | B5: ရွှေမြင်း | C5: =ရွှေမြင်း!C34 -> 414 | D5: =ရွှေမြင်း!D34 -> 5796 | E5: =ရွှေမြင်း!E34 -> 1956 | F5: =ရွှေမြင်း!F34 -> 27384 | G5: =ရွှေမြင်း!G34 -> 2305 | H5: =ရွှေမြင်း!H34 -> 55320 | I5: =ရွှေမြင်း!I34 -> 311 | J5: =ရွှေမြင်း!J34 -> 4354 | ... BW5: =ရွှေမြင်း!BW34 -> 0 | BX5: =BW5*12 -> 0 | CE5: =CC5+CA5+BY5+BW5+BU5+BS5+BQ5+BO5+BM5+BK5+BI5+BG5+BE5+BC5+BA5+AY5+AW5+AU5+AS5+AQ5+AO5+AM5+AK5+AI5+AG5+AE5+AC5+AA5+Y5+W5+U5+S5+Q5+O5+M5+K5+I5+G5+E5+C5 -> 8693 | CF5: =CD5+CB5+BZ5+BX5+BV5+BT5+BR5+BP5+BN5+BL5+BJ5+BH5+BF5+BD5+BB5+AZ5+AX5+AV5+AT5+AR5+AP5+AN5+AL5+AJ5+AH5+AF5+AD5+AB5+Z5+X5+V5+T5+R5+P5+N5+L5+J5+H5+F5+D5 -> 143492 | CG5: =CF5='2026-FUS'!DC4 -> TRUE
A6: 2 | B6: ရွှေခြင်္သေ့ | C6: =ရွှေခြင်္သေ့!C34 -> 210 | D6: =ရွှေခြင်္သေ့!D34 -> 2940 | E6: =ရွှေခြင်္သေ့!E34 -> 485 | F6: =ရွှေခြင်္သေ့!F34 -> 6790 | G6: =ရွှေခြင်္သေ့!G34 -> 610 | H6: =ရွှေခြင်္သေ့!H34 -> 14640 | I6: =ရွှေခြင်္သေ့!I34 -> 0 | J6: =ရွှေခြင်္သေ့!J34 -> 0 | ... BW6: =ရွှေခြင်္သေ့!BW34 -> 0 | BX6: =BW6*12 -> 0 | CE6: =CC6+CA6+BY6+BW6+BU6+BS6+BQ6+BO6+BM6+BK6+BI6+BG6+BE6+BC6+BA6+AY6+AW6+AU6+AS6+AQ6+AO6+AM6+AK6+AI6+AG6+AE6+AC6+AA6+Y6+W6+U6+S6+Q6+O6+M6+K6+I6+G6+E6+C6 -> 2800 | CF6: =CD6+CB6+BZ6+BX6+BV6+BT6+BR6+BP6+BN6+BL6+BJ6+BH6+BF6+BD6+BB6+AZ6+AX6+AV6+AT6+AR6+AP6+AN6+AL6+AJ6+AH6+AF6+AD6+AB6+Z6+X6+V6+T6+R6+P6+N6+L6+J6+H6+F6+D6 -> 45020 | CG6: =CF6='2026-FUS'!DC5 -> TRUE
