Workbook
Name aa: #REF!
Name aa: #REF!
Name aaa: #REF!
Name aaa: #REF!
Name aaaaa: #REF!
Name aaaaaaa: #REF!
Name aaaaaaa: #REF!
Name asd: '[1]Market ( Mar) '!#REF!
Name atr: #REF!
Name b: #REF!
Name bb: #REF!
Name Beg_Bal: #REF!
Name Cash_Cr: #REF!
Name Cash_Dr: #REF!
Name cc: #REF!
Name ccc: #REF!
Name cr: #REF!
Name crs: #REF!
Name cvvvv: #REF!
Name Data: #REF!
Name dd: #REF!
Name ddd: #REF!
Name dddd: #N/A
Name dr: #REF!
Name drs: #REF!
Name dsfas: #REF!
Name eeee: #REF!
Name End_Bal: #REF!
Name Extra_Pay: #REF!
Name fgf: #REF!
Name fgjhj: #REF!
Name Full_Print: #REF!
Name Header_Row: ROW(#REF!)
Name hjj: #REF!
Name hjkjk: #REF!
Name hmjhj: #REF!
Name ii: #REF!
Name III: #REF!
Name Int: #REF!
Name Interest_Rate: #REF!
Name jbkjkl: #REF!
Name Journal_Cr: #REF!
Name Journal_Dr: #REF!
Name kdt: #REF!
Name Last_Row: IF('7-MTL'!Values_Entered,Header_Row+'7-MTL'!Number_of_Payments,Header_Row)
Name Last_Row: IF('Compare for MTL'!Values_Entered,Header_Row+'Compare for MTL'!Number_of_Payments,Header_Row)
Name Last_Row: IF(CopareforKK!Values_Entered,Header_Row+CopareforKK!Number_of_Payments,Header_Row)
Name Last_Row: IF(Price!Values_Entered,Header_Row+Price!Number_of_Payments,Header_Row)
Name Last_Row: IF(Values_Entered,Header_Row+Number_of_Payments,Header_Row)
Name Loan_Amount: #REF!
Name Loan_Amount: #REF!
Name Loan_Start: #REF!
Name Loan_Start: #REF!
Name Loan_Years: #REF!
Name Loan_Years: #REF!
Name LSO: #REF!
Name lsoq: #REF!
Name mms: #REF!
Name neew: #REF!
Name New: #REF!

Sheet Price
A1: စဉ် | B1: အမျိုးအမည် | C1: ML | D1: ထုပ်ပိုးပုံ | E1: 1bot | F1: 1 Pk
A3: 1 | B3: ဇေ Vodka | C3: 0.7 | D3: ၁ x ၁၂ | E3: 2020 | F3: =E3*12 -> 24240
A4: 2 | B4: ဇေ အရက်သန့် | C4: 0.64 | D4: ၁ x ၁၄ | E4: 1380 | F4: =E4*14 -> 19320
A5: 3 | B5: "ဇေ" ကော်ဘူး (1 Liter) | C5: 1 | D5: ၁ x ၁၂ | E5: 1680 | F5: =E5*12 -> 20160
A6: 4 | B6: "ဇေ" ကော်ဘူး (0.6 Liter) | C6: 0.6 | D6: ၁ x ၁၂ | E6: 1130 | F6: =E6*12 -> 13560
A7: 5 | B7: ဇေRed ကော်ဘူး (1 Liter) 30% | C7: 1 | D7: ၁ x၁၂ | E7: 1680 | F7: =E7*12 -> 20160
A8: 6 | B8: ကောင်းကြည် (1 Liter ) 25% | C8: 1 | D8: ၁ x ၁၂ | E8: 1530 | F8: =E8*12 -> 18360
A9: 7 | B9: ကောင်းကြည် (0.6 Liter ) 25% | C9: 1 | D9: ၁ x ၁၂ | E9: 1090 | F9: =E9*12 -> 13080
A10: 8 | B10: ရွှေမင်းသားမန်းကျည်းခေါင်ရည်(0.6 Liter) | C10: 0.6 | D10: ၁ x ၁၂ | E10: 800 | F10: =E10*12 -> 9600
A11: 9 | B11: ရွှေမင်းသားခေါင်ရည် (0.6 Liter) | C11: 0.6 | D11: ၁ x ၁၂ | E11: 800 | F11: =E11*12 -> 9600
A12: 10 | B12: ရွှေမင်းသားခေါင်ရည် | C12: 0.64 | D12: ၁ x ၂၄ | E12: 800 | F12: =E12*24 -> 19200
A13: 11 | B13: ရွှေမင်းသားမန်ကျည်းခေါင်ရည် | C13: 0.64 | D13: ၁ x ၁၄ | E13: 830 | F13: =E13*14 -> 11620
A14: 12 | B14: Zeyawaddy Rum 43% | C14: 0.68 | D14: ၁ x၁၂ | E14: 1550 | F14: =E14*12 -> 18600
A15: 13 | B15: ဇေယျဝတီ Red | C15: 0.7 | D15: ၁ x ၁၂ | E15: 1800 | F15: =E15*12 -> 21600
A16: 14 | B16: ဇေယျဝတီ Red | C16: 0.64 | D16: ၁ x ၁၄ | E16: 1330 | F16: =E16*14 -> 18620
A17: 15 | B17: ဇေယျဝတီ Red (ပု) | C17: 0.64 | D17: ၁ x၁၄ | E17: 1600 | F17: =E17*14 -> 22400
A18: 16 | B18: 2 in 1 မန်ကျည်း | C18: 0.64 | D18: ၁ x ၁၄ | E18: 1350 | F18: =E18*14 -> 18900
A19: 17 | B19: ဒဂုံမန်ကျည်းအရက် | C19: 0.64 | D19: ၁ x ၁၄ | E19: 1280 | F19: =E19*14 -> 17920
A20: 18 | B20: ကောင်းကြည် | C20: 0.64 | D20: ၁ x ၁၄ | E20: 1330 | F20: =E20*14 -> 18620
A21: 19 | B21: သံပုရာအရက် | C21: 0.64 | D21: ၁ x ၁၄ | E21: 1330 | F21: =E21*14 -> 18620
A22: 20 | B22: ဒဂုံနာနတ်ဝိုင် | C22: 0.64 | D22: ၁ x ၂၄ | E22: 1330 | F22: =E22*24 -> 31920
A23: 21 | B23: ဒဂုံအရက်သန့် | C23: 0.64 | D23: ၁ x ၁၄ | E23: 1330 | F23: =E23*14 -> 18620
A24: 22 | B24: လိမ္မော်ဖြူ | C24: 0.64 | D24: ၁ x ၂၄ | E24: 1330 | F24: =E24*24 -> 31920
A25: 23 | B25: Black Cat | C25: 0.64 | D25: ၁ x ၂၄ | E25: 1330 | F25: =E25*24 -> 31920
A26: 24 | B26: ကင်းမြီးကောက် | C26: 0.64 | D26: ၁ x ၁၄ | E26: 1330 | F26: =E26*14 -> 18620
A27: 25 | B27: မြန်မာရှောက်ပျား | C27: 0.64 | D27: ၁ x ၁၄ | E27: 1370 | F27: =E27*14 -> 19180
A28: 26 | B28: မိုးနဲကွန်ကီ | C28: 0.64 | D28: ၁ x ၁၄ | E28: 1700 | F28: =E28*14 -> 23800
A29: 27 | B29: မိုးနဲကွန်ကီးကော်ဘူး | C29: 1 | D29: ၁ x ၁၂ | E29: 2100 | F29: =E29*12 -> 25200
A30: 28 | B30: Formula Rum 700ml | C30: 0.7 | D30: ၁ x ၁၂ | E30: 3600 | F30: =E30*12 -> 43200
A31: 29 | B31: Formula Rum 350ml | C31: 0.35 | D31: ၁ x ၂၄ | E31: 2100 | F31: =E31*24 -> 50400
A32: 30 | B32: ချယ်ရီအရက်သန့် | C32: 0.64 | D32: ၁ x ၁၄ | E32: 1380 | F32: =E32*14 -> 19320
A33: 31 | B33: ချယ်ရီကော်ဘူး(.6 Liter) | C33: 0.6 | D33: ၁ x ၂၄ | E33: 875 | F33: =E33*24 -> 21000
A34: 32 | B34: ချယ်ရီသံပုရာကော်ဘူး(.6 Liter) | C34: 0.6 | D34: ၁ x ၂၄ | E34: 915 | F34: =E34*24 -> 21960
A35: 33 | B35: ချယ်ရီသံပုရာကော်ဘူး(1 Liter) | C35: 1 | D35: ၁ x ၁၂ | E35: 1260 | F35: =E35*12 -> 15120
A36: 34 | B36: ရွှေမန်း Rum | C36: 0.64 | D36: ၁ x ၁၄ | E36: 1500 | F36: =E36*12 -> 18000
A37: 35 | B37: ရွှေမန်းRum ကော်ဘူး (1 Liter) | C37: 1 | D37: ၁ x 12 | E37: 1600 | F37: =E37*12 -> 19200
A38: 36 | B38: Col 700ml | C38: 0.7 | D38: ၁ x ၁၂ | E38: 4500 | F38: =E38*12 -> 54000
A39: 37 | B39: Col 350ml | C39: 0.35 | D39: ၁ x ၂၄ | E39: 2300 | F39: =E39*24 -> 55200
A40: 38 | B40: Col 175ml | C40: 0.175 | D40: ၁ x ၄၈ | E40: 1300 | F40: =E40*48 -> 62400
A41: 39 | B41: Col 700ml Smooth | C41: 0.7 | D41: ၁ x ၁၂ | E41: 5200 | F41: =E41*12 -> 62400
...

Sheet 7-MTL
A1: MTL | CH1: 2025
A2: Sr. | B2: Product Name | D2: Ranking | E2: ML | F2: Packing | G2: Sales Price | H2: 44562 | J2: 44593 | L2: 44621 | N2: 44652 | P2: 44682 | R2: 44713 | T2: 44743 | V2: 44774 | X2: 44805 | Z2: 44835 | AB2: 44866 | AD2: 44896 | AF2: 2022 Sum | AH2: 44927 | AJ2: 44958 | AL2: 44986 | AN2: 45017 | AP2: 45047 | AR2: 45078 | AT2: 45108 | AV2: 45139 | AX2: 45170 | AZ2: 45200 | BB2: 45231 | BD2: 45261 | BF2: 2023 Sum | BH2: 45292 | BJ2: 45323 | BL2: 45352 | BN2: 45383 | BP2: 45413 | BR2: 45444 | BT2: 45474 | BV2: 45505 | BX2: 45536 | BZ2: 45566 | CB2: 45597 | CD2: 45627 | CF2: 2024 Sum | CH2: 45658 | CJ2: 45689 | CL2: 45717 | CN2: 45748 | CP2: 45778 | CR2: 45809 | CT2: 45839 | CV2: 45870 | CX2: 45901 | CZ2: 45931 | DB2: 45962 | DD2: 45992 | DF2: 2025 Total | DH2: 46023 | DJ2: 46054 | DL2: 46082 | DN2: 46113 | DP2: 46143 | DR2: 46174 | DT2: 46204 | DV2: 46235 | DX2: 46266 | DZ2: 46296 | EB2: 46327 | ED2: 46357 | EF2: 2026 Total
H3: Bot | I3: Lit | J3: Bot | K3: Lit | L3: Bot | M3: Lit | N3: Bot | O3: Lit | P3: Bot | Q3: Lit | R3: Bot | S3: Lit | T3: Bot | U3: Lit | V3: Bot | W3: Lit | X3: Bot | Y3: Lit | Z3: Bot | AA3: Lit | AB3: Bot | AC3: Lit | AD3: Bot | AE3: Lit | AF3: Bot | AG3: Lit | AH3: Bot | AI3: Lit | AJ3: Bot | AK3: Lit | AL3: Bot | AM3: Lit | AN3: Bot | AO3: Lit | AP3: Bot | AQ3: Lit | AR3: Bot | AS3: Lit | AT3: Bot | AU3: Lit | AV3: Bot | AW3: Lit | AX3: Bot | AY3: Lit | AZ3: Bot | BA3: Lit | BB3: Bot | BC3: Lit | BD3: Bot | BE3: Lit | BF3: Bot | BG3: Lit | BH3: Bot | BI3: Lit | BJ3: Bot | BK3: Lit | BL3: Bot | BM3: Lit | BN3: Bot | BO3: Lit | BP3: Bot | BQ3: Lit | BR3: Bot | BS3: Lit | BT3: Bot | BU3: Lit | BV3: Bot | BW3: Lit | BX3: Bot | BY3: Lit | BZ3: Bot | CA3: Lit | CB3: Bot | CC3: Lit | CD3: Bot | CE3: Lit | CF3: Bot | CG3: Lit | CH3: Bot | CI3: Lit | CJ3: Bot | CK3: Lit | CL3: Bot | CM3: Lit | CN3: Bot | CO3: Lit | CP3: Bot | CQ3: Lit | CR3: Bot | CS3: Lit | CT3: Bot | CU3: Lit | CV3: Bot | CW3: Lit | CX3: Bot | CY3: Lit | CZ3: Bot | DA3: Lit | DB3: Bot | DC3: Lit | DD3: Bot | DE3: Lit | DF3: Bot | DG3: Lit | DH3: Bot | DI3: Lit | DJ3: Bot | DK3: Lit | DL3: Bot | DM3: Lit | DN3: Bot | DO3: Lit | DP3: Bot | DQ3: Lit | DR3: Bot | DS3: Lit | DT3: Bot | DU3: Lit | DV3: Bot | DW3: Lit | DX3: Bot | DY3: Lit | DZ3: Bot | EA3: Lit | EB3: Bot | EC3: Lit | ED3: Bot | EE3: Lit | EF3: Bot | EG3: Lit
A4: 1 | B4: "Zay" Vodka 700-ml | C4: ပုလင်း | D4: =RANK(DF4,$DF$4:$DF$144) -> 24 | E4: 0.7 | F4: 1 * 12 | G4: 2020 | H4: 19961 | I4: =H4*$E4 -> 13972.7 | J4: 12844 | K4: =J4*$E4 -> 8990.8 | L4: 22152 | M4: =L4*$E4 -> 15506.4 | N4: 13368 | O4: =N4*$E4 -> 9357.6 | P4: 13720 | Q4: =P4*$E4 -> 9604 | R4: 8880 | S4: =R4*$E4 -> 6216 | T4: 8208 | U4: =T4*$E4 -> 5745.6 | V4: 14127 | W4: =V4*$E4 -> 9888.9 | X4: 6948 | Y4: =X4*$E4 -> 4863.6 | Z4: 3876 | AA4: =Z4*$E4 -> 2713.2 | AB4: 5580 | AC4: =AB4*$E4 -> 3906 | AD4: 4932 | AE4: =AD4*$E4 -> 3452.4 | AF4: =(AD4+AB4+Z4+X4+V4+T4+R4+P4+N4+L4+J4+H4)/1 -> 134596 | AG4: =AF4*$E4 -> 94217.2 | AH4: 6960 | AI4: =AH4*$E4 -> 4872 | AJ4: 6120 | AK4: =AJ4*$E4 -> 4284 | AL4: 4584 | AM4: =AL4*$E4 -> 3208.8 | AN4: 2172 | AO4: =AN4*$E4 -> 1520.4 | AP4: 3288 | AQ4: =AP4*$E4 -> 2301.6 | AR4: 3060 | AS4: =AR4*$E4 -> 2142 | AT4: 2472 | AU4: =AT4*$E4 -> 1730.4 | AV4: 2232 | AW4: =AV4*$E4 -> 1562.4 | AX4: 1032 | AY4: =AX4*$E4 -> 722.4 | AZ4: 2856 | BA4: =AZ4*$E4 -> 1999.2 | BB4: 2235 | BC4: =BB4*$E4 -> 1564.5 | BD4: 3036 | BE4: =BD4*$E4 -> 2125.2 | BF4: =(BD4+BB4+AZ4+AX4+AV4+AT4+AR4+AP4+AN4+AL4+AJ4+AH4)/1 -> 40047 | BG4: =BF4*$E4 -> 28032.9 | BH4: 2178 | BI4: =BH4*$E4 -> 1524.6 | BJ4: 2118 | BK4: =BJ4*$E4 -> 1482.6 | BL4: 2737 | BM4: =BL4*$E4 -> 1915.9 | BN4: 2268 | BO4: =BN4*$E4 -> 1587.6 | BP4: 1992 | BQ4: =BP4*$E4 -> 1394.4 | BR4: 1452 | BS4: =BR4*$E4 -> 1016.4 | BT4: 2598 | BU4: =BT4*$E4 -> 1818.6 | BV4: 2496 | BW4: =BV4*$E4 -> 1747.2 | BX4: 1668 | BY4: =BX4*$E4 -> 1167.6 | BZ4: 948 | CA4: =BZ4*$E4 -> 663.6 | CB4: 1212 | CC4: =CB4*$E4 -> 848.4 | CD4: 3264 | CE4: =CD4*$E4 -> 2284.8 | CF4: =(CD4+CB4+BZ4+BX4+BV4+BT4+BR4+BP4+BN4+BL4+BJ4+BH4)/1 -> 24931 | CG4: =CF4*$E4 -> 17451.7 | CH4: 1308 | CI4: =CH4*$E4 -> 915.6 | CJ4: 1860 | CK4: =CJ4*$E4 -> 1302 | CL4: 840 | CM4: =CL4*$E4 -> 588 | CN4: 358 | CO4: =CN4*$E4 -> 250.6 | CP4: 2640 | CQ4: =CP4*$E4 -> 1848 | CR4: 696 | CS4: =CR4*$E4 -> 487.2 | CT4: 576 | CU4: =CT4*$E4 -> 403.2 | CV4: 660 | CW4: =CV4*$E4 -> 462 | CX4: 1322 | CY4: 925.4 | CZ4: 624 | DA4: 436.8 | DB4: 1740 | DC4: 1218 | DD4: 960 | DE4: 672 | DF4: =SUM(CH4,CJ4,CL4,CN4,CP4,CR4,CT4,CV4,CX4,CZ4,DB4,DD4) -> 13584 | DG4: =DF4*$E4 -> 9508.8 | DH4: 1224 | DI4: 856.8 | DJ4: 900 | DK4: =DJ4*$E4 -> 630 | EF4: =SUM(DH4,DJ4,DL4,DN4,DP4,DR4,DT4,DV4,DX4,DZ4,EB4,ED4) -> 2124 | EG4: =SUM(DI4,DK4,DM4,DO4,DQ4,DS4,DU4,DW4,DY4,EA4,EC4,EE4) -> 1486.8
I5: =H5*$E5 -> 0 | K5: =J5*$E5 -> 0 | M5: =L5*$E5 -> 0 | O5: =N5*$E5 -> 0 | Q5: =P5*$E5 -> 0 | S5: =R5*$E5 -> 0 | U5: =T5*$E5 -> 0 | W5: =V5*$E5 -> 0 | Y5: =X5*$E5 -> 0 | AA5: =Z5*$E5 -> 0 | AC5: =AB5*$E5 -> 0 | AE5: =AD5*$E5 -> 0 | AF5: =(AD5+AB5+Z5+X5+V5+T5+R5+P5+N5+L5+J5+H5)/1 -> 0 | AG5: =AF5*$E5 -> 0 | AI5: =AH5*$E5 -> 0 | AK5: =AJ5*$E5 -> 0 | AM5: =AL5*$E5 -> 0 | AO5: =AN5*$E5 -> 0 | AQ5: =AP5*$E5 -> 0 | AS5: =AR5*$E5 -> 0 | AU5: =AT5*$E5 -> 0 | AW5: =AV5*$E5 -> 0 | AY5: =AX5*$E5 -> 0 | BA5: =AZ5*$E5 -> 0 | BC5: =BB5*$E5 -> 0 | BE5: =BD5*$E5 -> 0 | BF5: =(BD5+BB5+AZ5+AX5+AV5+AT5+AR5+AP5+AN5+AL5+AJ5+AH5)/1 -> 0 | BG5: =BF5*$E5 -> 0 | BI5: =BH5*$E5 -> 0 | BK5: =BJ5*$E5 -> 0 | BM5: =BL5*$E5 -> 0 | BO5: =BN5*$E5 -> 0 | BQ5: =BP5*$E5 -> 0 | BS5: =BR5*$E5 -> 0 | BU5: =BT5*$E5 -> 0 | BW5: =BV5*$E5 -> 0 | BY5: =BX5*$E5 -> 0 | CA5: =BZ5*$E5 -> 0 | CC5: =CB5*$E5 -> 0 | CE5: =CD5*$E5 -> 0 | CF5: =(CD5+CB5+BZ5+BX5+BV5+BT5+BR5+BP5+BN5+BL5+BJ5+BH5)/1 -> 0 | CG5: =CF5*$E5 -> 0 | CI5: =CH5*$E5 -> 0 | CK5: =CJ5*$E5 -> 0 | CM5: =CL5*$E5 -> 0 | CO5: =CN5*$E5 -> 0 | CQ5: =CP5*$E5 -> 0 | CS5: =CR5*$E5 -> 0 | CU5: =CT5*$E5 -> 0 | CW5: =CV5*$E5 -> 0 | CY5: 0 | DA5: 0 | DC5: 0 | DE5: 0 | DF5: =SUM(CH5,CJ5,CL5,CN5,CP5,CR5,CT5,CV5,CX5,CZ5,DB5,DD5) -> 0 | DG5: =DF5*$E5 -> 0 | DI5: 0 | DK5: =DJ5*$E5 -> 0 | EF5: =SUM(DH5,DJ5,DL5,DN5,DP5,DR5,DT5,DV5,DX5,DZ5,EB5,ED5) -> 0 | EG5: =SUM(DI5,DK5,DM5,DO5,DQ5,DS5,DU5,DW5,DY5,EA5,EC5,EE5) -> 0
A6: 2 | B6: "Zay" Vodka (1 Liter) | C6: ‌ကော်ဘူး | D6: =RANK(DF6,$DF$4:$DF$144) -> 35 | E6: 1 | F6: 1 * 12 | I6: =H6*$E6 -> 0 | K6: =J6*$E6 -> 0 | M6: =L6*$E6 -> 0 | O6: =N6*$E6 -> 0 | Q6: =P6*$E6 -> 0 | S6: =R6*$E6 -> 0 | U6: =T6*$E6 -> 0 | W6: =V6*$E6 -> 0 | Y6: =X6*$E6 -> 0 | AA6: =Z6*$E6 -> 0 | AC6: =AB6*$E6 -> 0 | AE6: =AD6*$E6 -> 0 | AF6: =(AD6+AB6+Z6+X6+V6+T6+R6+P6+N6+L6+J6+H6)/1 -> 0 | AG6: =AF6*$E6 -> 0 | AI6: =AH6*$E6 -> 0 | AK6: =AJ6*$E6 -> 0 | AM6: =AL6*$E6 -> 0 | AO6: =AN6*$E6 -> 0 | AQ6: =AP6*$E6 -> 0 | AS6: =AR6*$E6 -> 0 | AU6: =AT6*$E6 -> 0 | AW6: =AV6*$E6 -> 0 | AY6: =AX6*$E6 -> 0 | BA6: =AZ6*$E6 -> 0 | BC6: =BB6*$E6 -> 0 | BE6: =BD6*$E6 -> 0 | BF6: =(BD6+BB6+AZ6+AX6+AV6+AT6+AR6+AP6+AN6+AL6+AJ6+AH6)/1 -> 0 | BG6: =BF6*$E6 -> 0 | BI6: =BH6*$E6 -> 0 | BK6: =BJ6*$E6 -> 0 | BM6: =BL6*$E6 -> 0 | BO6: =BN6*$E6 -> 0 | BQ6: =BP6*$E6 -> 0 | BS6: =BR6*$E6 -> 0 | BU6: =BT6*$E6 -> 0 | BW6: =BV6*$E6 -> 0 | BY6: =BX6*$E6 -> 0 | CA6: =BZ6*$E6 -> 0 | CC6: =CB6*$E6 -> 0 | CE6: =CD6*$E6 -> 0 | CF6: =(CD6+CB6+BZ6+BX6+BV6+BT6+BR6+BP6+BN6+BL6+BJ6+BH6)/1 -> 0 | CG6: =CF6*$E6 -> 0 | CI6: =CH6*$E6 -> 0 | CK6: =CJ6*$E6 -> 0 | CM6: =CL6*$E6 -> 0 | CO6: =CN6*$E6 -> 0 | CQ6: =CP6*$E6 -> 0 | CS6: =CR6*$E6 -> 0 | CU6: =CT6*$E6 -> 0 | CW6: =CV6*$E6 -> 0 | CY6: 0 | DA6: 0 | DC6: 0 | DE6: 0 | DF6: =SUM(CH6,CJ6,CL6,CN6,CP6,CR6,CT6,CV6,CX6,CZ6,DB6,DD6) -> 0 | DG6: =DF6*$E6 -> 0 | DI6: 0 | DK6: =DJ6*$E6 -> 0 | EF6: =SUM(DH6,DJ6,DL6,DN6,DP6,DR6,DT6,DV6,DX6,DZ6,EB6,ED6) -> 0 | EG6: =SUM(DI6,DK6,DM6,DO6,DQ6,DS6,DU6,DW6,DY6,EA6,EC6,EE6) -> 0
A7: 3 | B7: "Zay" (1 Liter) | C7: ‌ကော်ဘူး | D7: =RANK(DF7,$DF$4:$DF$144) -> 34 | E7: 1 | F7: 1 * 12 | G7: 1680 | H7: 972 | I7: =H7*$E7 -> 972 | J7: 468 | K7: =J7*$E7 -> 468 | M7: =L7*$E7 -> 0 | N7: 420 | O7: =N7*$E7 -> 420 | P7: 600 | Q7: =P7*$E7 -> 600 | S7: =R7*$E7 -> 0 | U7: =T7*$E7 -> 0 | V7: 420 | W7: =V7*$E7 -> 420 | X7: 288 | Y7: =X7*$E7 -> 288 | Z7: 180 | AA7: =Z7*$E7 -> 180 | AC7: =AB7*$E7 -> 0 | AD7: 120 | AE7: =AD7*$E7 -> 120 | AF7: =(AD7+AB7+Z7+X7+V7+T7+R7+P7+N7+L7+J7+H7)/1 -> 3468 | AG7: =AF7*$E7 -> 3468 | AH7: 120 | AI7: =AH7*$E7 -> 120 | AK7: =AJ7*$E7 -> 0 | AL7: 60 | AM7: =AL7*$E7 -> 60 | AO7: =AN7*$E7 -> 0 | AP7: 300 | AQ7: =AP7*$E7 -> 300 | AS7: =AR7*$E7 -> 0 | AU7: =AT7*$E7 -> 0 | AW7: =AV7*$E7 -> 0 | AX7: 180 | AY7: =AX7*$E7 -> 180 | AZ7: 12 | BA7: =AZ7*$E7 -> 12 | BB7: 828 | BC7: =BB7*$E7 -> 828 | BD7: 600 | BE7: =BD7*$E7 -> 600 | BF7: =(BD7+BB7+AZ7+AX7+AV7+AT7+AR7+AP7+AN7+AL7+AJ7+AH7)/1 -> 2100 | BG7: =BF7*$E7 -> 2100 | BI7: =BH7*$E7 -> 0 | BJ7: 240 | BK7: =BJ7*$E7 -> 240 | BM7: =BL7*$E7 -> 0 | BO7: =BN7*$E7 -> 0 | BP7: 660 | BQ7: =BP7*$E7 -> 660 | BS7: =BR7*$E7 -> 0 | BU7: =BT7*$E7 -> 0 | BW7: =BV7*$E7 -> 0 | BY7: =BX7*$E7 -> 0 | CA7: =BZ7*$E7 -> 0 | CC7: =CB7*$E7 -> 0 | CE7: =CD7*$E7 -> 0 | CF7: =(CD7+CB7+BZ7+BX7+BV7+BT7+BR7+BP7+BN7+BL7+BJ7+BH7)/1 -> 900 | CG7: =CF7*$E7 -> 900 | CI7: =CH7*$E7 -> 0 | CK7: =CJ7*$E7 -> 0 | CM7: =CL7*$E7 -> 0 | CO7: =CN7*$E7 -> 0 | CQ7: =CP7*$E7 -> 0 | CS7: =CR7*$E7 -> 0 | CT7: 24 | CU7: =CT7*$E7 -> 24 | CW7: =CV7*$E7 -> 0 | CY7: 0 | DA7: 0 | DC7: 0 | DE7: 0 | DF7: =SUM(CH7,CJ7,CL7,CN7,CP7,CR7,CT7,CV7,CX7,CZ7,DB7,DD7) -> 24 | DG7: =DF7*$E7 -> 24 | DI7: 0 | DK7: =DJ7*$E7 -> 0 | EF7: =SUM(DH7,DJ7,DL7,DN7,DP7,DR7,DT7,DV7,DX7,DZ7,EB7,ED7) -> 0 | EG7: =SUM(DI7,DK7,DM7,DO7,DQ7,DS7,DU7,DW7,DY7,EA7,EC7,EE7) -> 0
A8: 4 | B8: "Zay" (0.6 Liter) | C8: ‌ကော်ဘူး | D8: =RANK(DF8,$DF$4:$DF$144) -> 35 | E8: 0.6 | F8: 1 * 12 | G8: 1130 | I8: =H8*$E8 -> 0 | K8: =J8*$E8 -> 0 | M8: =L8*$E8 -> 0 | O8: =N8*$E8 -> 0 | P8: 84 | Q8: =P8*$E8 -> 50.4 | R8: 720 | S8: =R8*$E8 -> 432 | U8: =T8*$E8 -> 0 | V8: 24 | W8: =V8*$E8 -> 14.4 | Y8: =X8*$E8 -> 0 | AA8: =Z8*$E8 -> 0 | AC8: =AB8*$E8 -> 0 | AE8: =AD8*$E8 -> 0 | AF8: =(AD8+AB8+Z8+X8+V8+T8+R8+P8+N8+L8+J8+H8)/1 -> 828 | AG8: =AF8*$E8 -> 496.8 | AH8: 60 | AI8: =AH8*$E8 -> 36 | AK8: =AJ8*$E8 -> 0 | AM8: =AL8*$E8 -> 0 | AO8: =AN8*$E8 -> 0 | AQ8: =AP8*$E8 -> 0 | AS8: =AR8*$E8 -> 0 | AU8: =AT8*$E8 -> 0 | AW8: =AV8*$E8 -> 0 | AY8: =AX8*$E8 -> 0 | BA8: =AZ8*$E8 -> 0 | BB8: 60 | BC8: =BB8*$E8 -> 36 | BE8: =BD8*$E8 -> 0 | BF8: =(BD8+BB8+AZ8+AX8+AV8+AT8+AR8+AP8+AN8+AL8+AJ8+AH8)/1 -> 120 | BG8: =BF8*$E8 -> 72 | BI8: =BH8*$E8 -> 0 | BK8: =BJ8*$E8 -> 0 | BM8: =BL8*$E8 -> 0 | BO8: =BN8*$E8 -> 0 | BQ8: =BP8*$E8 -> 0 | BS8: =BR8*$E8 -> 0 | BU8: =BT8*$E8 -> 0 | BW8: =BV8*$E8 -> 0 | BY8: =BX8*$E8 -> 0 | CA8: =BZ8*$E8 -> 0 | CC8: =CB8*$E8 -> 0 | CE8: =CD8*$E8 -> 0 | CF8: =(CD8+CB8+BZ8+BX8+BV8+BT8+BR8+BP8+BN8+BL8+BJ8+BH8)/1 -> 0 | CG8: =CF8*$E8 -> 0 | CI8: =CH8*$E8 -> 0 | CK8: =CJ8*$E8 -> 0 | CM8: =CL8*$E8 -> 0 | CO8: =CN8*$E8 -> 0 | CQ8: =CP8*$E8 -> 0 | CS8: =CR8*$E8 -> 0 | CU8: =CT8*$E8 -> 0 | CW8: =CV8*$E8 -> 0 | CY8: 0 | DA8: 0 | DC8: 0 | DE8: 0 | DF8: =SUM(CH8,CJ8,CL8,CN8,CP8,CR8,CT8,CV8,CX8,CZ8,DB8,DD8) -> 0 | DG8: =DF8*$E8 -> 0 | DI8: 0 | DK8: =DJ8*$E8 -> 0 | EF8: =SUM(DH8,DJ8,DL8,DN8,DP8,DR8,DT8,DV8,DX8,DZ8,EB8,ED8) -> 0 | EG8: =SUM(DI8,DK8,DM8,DO8,DQ8,DS8,DU8,DW8,DY8,EA8,EC8,EE8) -> 0
A9: 5 | B9: "Zay" (0.35 Liter) | C9: ‌ကော်ဘူး | D9: =RANK(DF9,$DF$4:$DF$144) -> 35 | E9: 0.35 | F9: 1 * 40 | I9: =H9*$E9 -> 0 | K9: =J9*$E9 -> 0 | M9: =L9*$E9 -> 0 | O9: =N9*$E9 -> 0 | Q9: =P9*$E9 -> 0 | S9: =R9*$E9 -> 0 | U9: =T9*$E9 -> 0 | W9: =V9*$E9 -> 0 | Y9: =X9*$E9 -> 0 | AA9: =Z9*$E9 -> 0 | AC9: =AB9*$E9 -> 0 | AE9: =AD9*$E9 -> 0 | AF9: =(AD9+AB9+Z9+X9+V9+T9+R9+P9+N9+L9+J9+H9)/1 -> 0 | AG9: =AF9*$E9 -> 0 | AI9: =AH9*$E9 -> 0 | AK9: =AJ9*$E9 -> 0 | AM9: =AL9*$E9 -> 0 | AO9: =AN9*$E9 -> 0 | AQ9: =AP9*$E9 -> 0 | AS9: =AR9*$E9 -> 0 | AU9: =AT9*$E9 -> 0 | AW9: =AV9*$E9 -> 0 | AY9: =AX9*$E9 -> 0 | BA9: =AZ9*$E9 -> 0 | BC9: =BB9*$E9 -> 0 | BE9: =BD9*$E9 -> 0 | BF9: =(BD9+BB9+AZ9+AX9+AV9+AT9+AR9+AP9+AN9+AL9+AJ9+AH9)/1 -> 0 | BG9: =BF9*$E9 -> 0 | BI9: =BH9*$E9 -> 0 | BK9: =BJ9*$E9 -> 0 | BM9: =BL9*$E9 -> 0 | BO9: =BN9*$E9 -> 0 | BQ9: =BP9*$E9 -> 0 | BS9: =BR9*$E9 -> 0 | BU9: =BT9*$E9 -> 0 | BW9: =BV9*$E9 -> 0 | BY9: =BX9*$E9 -> 0 | CA9: =BZ9*$E9 -> 0 | CC9: =CB9*$E9 -> 0 | CE9: =CD9*$E9 -> 0 | CF9: =(CD9+CB9+BZ9+BX9+BV9+BT9+BR9+BP9+BN9+BL9+BJ9+BH9)/1 -> 0 | CG9: =CF9*$E9 -> 0 | CI9: =CH9*$E9 -> 0 | CK9: =CJ9*$E9 -> 0 | CM9: =CL9*$E9 -> 0 | CO9: =CN9*$E9 -> 0 | CQ9: =CP9*$E9 -> 0 | CS9: =CR9*$E9 -> 0 | CU9: =CT9*$E9 -> 0 | CW9: =CV9*$E9 -> 0 | CY9: 0 | DA9: 0 | DC9: 0 | DE9: 0 | DF9: =SUM(CH9,CJ9,CL9,CN9,CP9,CR9,CT9,CV9,CX9,CZ9,DB9,DD9) -> 0 | DG9: =DF9*$E9 -> 0 | DI9: 0 | DK9: =DJ9*$E9 -> 0 | EF9: =SUM(DH9,DJ9,DL9,DN9,DP9,DR9,DT9,DV9,DX9,DZ9,EB9,ED9) -> 0 | EG9: =SUM(DI9,DK9,DM9,DO9,DQ9,DS9,DU9,DW9,DY9,EA9,EC9,EE9) -> 0
A10: 6 | B10: "Zay" Vodka | C10: ပုလင်း | D10: =RANK(DF10,$DF$4:$DF$144) -> 35 | E10: 0.7 | F10: 1 * 12 | I10: =H10*$E10 -> 0 | K10: =J10*$E10 -> 0 | M10: =L10*$E10 -> 0 | O10: =N10*$E10 -> 0 | Q10: =P10*$E10 -> 0 | S10: =R10*$E10 -> 0 | U10: =T10*$E10 -> 0 | W10: =V10*$E10 -> 0 | Y10: =X10*$E10 -> 0 | AA10: =Z10*$E10 -> 0 | AC10: =AB10*$E10 -> 0 | AE10: =AD10*$E10 -> 0 | AF10: =(AD10+AB10+Z10+X10+V10+T10+R10+P10+N10+L10+J10+H10)/1 -> 0 | AG10: =AF10*$E10 -> 0 | AI10: =AH10*$E10 -> 0 | AK10: =AJ10*$E10 -> 0 | AM10: =AL10*$E10 -> 0 | AO10: =AN10*$E10 -> 0 | AQ10: =AP10*$E10 -> 0 | AS10: =AR10*$E10 -> 0 | AU10: =AT10*$E10 -> 0 | AW10: =AV10*$E10 -> 0 | AY10: =AX10*$E10 -> 0 | BA10: =AZ10*$E10 -> 0 | BC10: =BB10*$E10 -> 0 | BE10: =BD10*$E10 -> 0 | BF10: =(BD10+BB10+AZ10+AX10+AV10+AT10+AR10+AP10+AN10+AL10+AJ10+AH10)/1 -> 0 | BG10: =BF10*$E10 -> 0 | BI10: =BH10*$E10 -> 0 | BK10: =BJ10*$E10 -> 0 | BM10: =BL10*$E10 -> 0 | BO10: =BN10*$E10 -> 0 | BQ10: =BP10*$E10 -> 0 | BS10: =BR10*$E10 -> 0 | BU10: =BT10*$E10 -> 0 | BW10: =BV10*$E10 -> 0 | BY10: =BX10*$E10 -> 0 | CA10: =BZ10*$E10 -> 0 | CC10: =CB10*$E10 -> 0 | CE10: =CD10*$E10 -> 0 | CF10: =(CD10+CB10+BZ10+BX10+BV10+BT10+BR10+BP10+BN10+BL10+BJ10+BH10)/1 -> 0 | CG10: =CF10*$E10 -> 0 | CI10: =CH10*$E10 -> 0 | CK10: =CJ10*$E10 -> 0 | CM10: =CL10*$E10 -> 0 | CO10: =CN10*$E10 -> 0 | CQ10: =CP10*$E10 -> 0 | CS10: =CR10*$E10 -> 0 | CU10: =CT10*$E10 -> 0 | CW10: =CV10*$E10 -> 0 | CY10: 0 | DA10: 0 | DC10: 0 | DE10: 0 | DF10: =SUM(CH10,CJ10,CL10,CN10,CP10,CR10,CT10,CV10,CX10,CZ10,DB10,DD10) -> 0 | DG10: =DF10*$E10 -> 0 | DI10: 0 | DK10: =DJ10*$E10 -> 0 | EF10: =SUM(DH10,DJ10,DL10,DN10,DP10,DR10,DT10,DV10,DX10,DZ10,EB10,ED10) -> 0 | EG10: =SUM(DI10,DK10,DM10,DO10,DQ10,DS10,DU10,DW10,DY10,EA10,EC10,EE10) -> 0
A11: 7 | B11: "Zay" Vodka - 640ml | C11: ပုလင်း | D11: =RANK(DF11,$DF$4:$DF$144) -> 35 | E11: 0.64 | F11: 1 * 24 | I11: =H11*$E11 -> 0 | K11: =J11*$E11 -> 0 | M11: =L11*$E11 -> 0 | O11: =N11*$E11 -> 0 | Q11: =P11*$E11 -> 0 | S11: =R11*$E11 -> 0 | U11: =T11*$E11 -> 0 | W11: =V11*$E11 -> 0 | Y11: =X11*$E11 -> 0 | AA11: =Z11*$E11 -> 0 | AC11: =AB11*$E11 -> 0 | AE11: =AD11*$E11 -> 0 | AF11: =(AD11+AB11+Z11+X11+V11+T11+R11+P11+N11+L11+J11+H11)/1 -> 0 | AG11: =AF11*$E11 -> 0 | AI11: =AH11*$E11 -> 0 | AK11: =AJ11*$E11 -> 0 | AM11: =AL11*$E11 -> 0 | AO11: =AN11*$E11 -> 0 | AQ11: =AP11*$E11 -> 0 | AS11: =AR11*$E11 -> 0 | AU11: =AT11*$E11 -> 0 | AW11: =AV11*$E11 -> 0 | AY11: =AX11*$E11 -> 0 | BA11: =AZ11*$E11 -> 0 | BC11: =BB11*$E11 -> 0 | BE11: =BD11*$E11 -> 0 | BF11: =(BD11+BB11+AZ11+AX11+AV11+AT11+AR11+AP11+AN11+AL11+AJ11+AH11)/1 -> 0 | BG11: =BF11*$E11 -> 0 | BI11: =BH11*$E11 -> 0 | BK11: =BJ11*$E11 -> 0 | BM11: =BL11*$E11 -> 0 | BO11: =BN11*$E11 -> 0 | BQ11: =BP11*$E11 -> 0 | BS11: =BR11*$E11 -> 0 | BU11: =BT11*$E11 -> 0 | BW11: =BV11*$E11 -> 0 | BY11: =BX11*$E11 -> 0 | CA11: =BZ11*$E11 -> 0 | CC11: =CB11*$E11 -> 0 | CE11: =CD11*$E11 -> 0 | CF11: =(CD11+CB11+BZ11+BX11+BV11+BT11+BR11+BP11+BN11+BL11+BJ11+BH11)/1 -> 0 | CG11: =CF11*$E11 -> 0 | CI11: =CH11*$E11 -> 0 | CK11: =CJ11*$E11 -> 0 | CM11: =CL11*$E11 -> 0 | CO11: =CN11*$E11 -> 0 | CQ11: =CP11*$E11 -> 0 | CS11: =CR11*$E11 -> 0 | CU11: =CT11*$E11 -> 0 | CW11: =CV11*$E11 -> 0 | CY11: 0 | DA11: 0 | DC11: 0 | DE11: 0 | DF11: =SUM(CH11,CJ11,CL11,CN11,CP11,CR11,CT11,CV11,CX11,CZ11,DB11,DD11) -> 0 | DG11: =DF11*$E11 -> 0 | DI11: 0 | DK11: =DJ11*$E11 -> 0 | EF11: =SUM(DH11,DJ11,DL11,DN11,DP11,DR11,DT11,DV11,DX11,DZ11,EB11,ED11) -> 0 | EG11: =SUM(DI11,DK11,DM11,DO11,DQ11,DS11,DU11,DW11,DY11,EA11,EC11,EE11) -> 0
A12: 8 | B12: "Zay" Vodka - 640ml | C12: ပုလင်း | D12: =RANK(DF12,$DF$4:$DF$144) -> 2 | E12: 0.64 | F12: 1 * 14 | G12: 1380 | H12: 143122 | I12: =H12*$E12 -> 91598.08 | J12: 132174 | K12: =J12*$E12 -> 84591.36 | L12: 157940 | M12: =L12*$E12 -> 101081.6 | N12: 137970 | O12: =N12*$E12 -> 88300.8 | P12: 133700 | Q12: =P12*$E12 -> 85568 | R12: 144732 | S12: =R12*$E12 -> 92628.48 | T12: 133392 | U12: =T12*$E12 -> 85370.88 | V12: 124475 | W12: =V12*$E12 -> 79664 | X12: 130676 | Y12: =X12*$E12 -> 83632.64 | Z12: 155238 | AA12: =Z12*$E12 -> 99352.32 | AB12: 159313 | AC12: =AB12*$E12 -> 101960.32 | AD12: 163240 | AE12: =AD12*$E12 -> 104473.6 | AF12: =(AD12+AB12+Z12+X12+V12+T12+R12+P12+N12+L12+J12+H12)/1 -> 1715972 | AG12: =AF12*$E12 -> 1098222.1 | AH12: 171178 | AI12: =AH12*$E12 -> 109553.92 | AJ12: 119966 | AK12: =AJ12*$E12 -> 76778.24 | AL12: 137872 | AM12: =AL12*$E12 -> 88238.08 | AN12: 122472 | AO12: =AN12*$E12 -> 78382.08 | AP12: 120876 | AQ12: =AP12*$E12 -> 77360.64 | AR12: 127344 | AS12: =AR12*$E12 -> 81500.16 | AT12: 132384 | AU12: =AT12*$E12 -> 84725.76 | AV12: 161325 | AW12: =AV12*$E12 -> 103248 | AX12: 133912 | AY12: =AX12*$E12 -> 85703.68 | AZ12: 168854 | BA12: =AZ12*$E12 -> 108066.56 | BB12: 150325 | BC12: =BB12*$E12 -> 96208 | BD12: 185822 | BE12: =BD12*$E12 -> 118926.08 | BF12: =(BD12+BB12+AZ12+AX12+AV12+AT12+AR12+AP12+AN12+AL12+AJ12+AH12)/1 -> 1732330 | BG12: =BF12*$E12 -> 1108691.2 | BH12: 175070 | BI12: =BH12*$E12 -> 112044.8 | BJ12: 155676 | BK12: =BJ12*$E12 -> 99632.64 | BL12: 162568 | BM12: =BL12*$E12 -> 104043.52 | BN12: 148862 | BO12: =BN12*$E12 -> 95271.68 | BP12: 160404 | BQ12: =BP12*$E12 -> 102658.56 | BR12: 149233 | BS12: =BR12*$E12 -> 95509.12 | BT12: 157353 | BU12: =BT12*$E12 -> 100705.92 | BV12: 179116 | BW12: =BV12*$E12 -> 114634.24 | BX12: 170683 | BY12: =BX12*$E12 -> 109237.12 | BZ12: 185136 | CA12: =BZ12*$E12 -> 118487.04 | CB12: 155498 | CC12: =CB12*$E12 -> 99518.72 | CD12: 193405 | CE12: =CD12*$E12 -> 123779.2 | CF12: =(CD12+CB12+BZ12+BX12+BV12+BT12+BR12+BP12+BN12+BL12+BJ12+BH12)/1 -> 1993004 | CG12: =CF12*$E12 -> 1275522.6 | CH12: 179189 | CI12: =CH12*$E12 -> 114680.96 | CJ12: 156743 | CK12: =CJ12*$E12 -> 100315.52 | CL12: 209757 | CM12: =CL12*$E12 -> 134244.48 | CN12: 163352 | CO12: =CN12*$E12 -> 104545.28 | CP12: 167668 | CQ12: =CP12*$E12 -> 107307.52 | CR12: 169518 | CS12: =CR12*$E12 -> 108491.52 | CT12: 154737 | CU12: =CT12*$E12 -> 99031.68 | CV12: 177450 | CW12: =CV12*$E12 -> 113568 | CX12: 159414 | CY12: 102024.96 | CZ12: 150772 | DA12: 96494.08 | DB12: 171122 | DC12: 109518.08 | DD12: 181923 | DE12: 116430.72 | DF12: =SUM(CH12,CJ12,CL12,CN12,CP12,CR12,CT12,CV12,CX12,CZ12,DB12,DD12) -> 2041645 | DG12: =DF12*$E12 -> 1306652.8 | DH12: 128898 | DI12: 82494.72 | DJ12: 121791 | DK12: =DJ12*$E12 -> 77946.24 | EF12: =SUM(DH12,DJ12,DL12,DN12,DP12,DR12,DT12,DV12,DX12,DZ12,EB12,ED12) -> 250689 | EG12: =SUM(DI12,DK12,DM12,DO12,DQ12,DS12,DU12,DW12,DY12,EA12,EC12,EE12) -> 160440.96
A13: 9 | B13: "Zay" Vodka - 640ml | C13: ပုလင်း | D13: =RANK(DF13,$DF$4:$DF$144) -> 35 | E13: 0.64 | F13: 1 * 12 | I13: =H13*$E13 -> 0 | K13: =J13*$E13 -> 0 | M13: =L13*$E13 -> 0 | O13: =N13*$E13 -> 0 | Q13: =P13*$E13 -> 0 | S13: =R13*$E13 -> 0 | U13: =T13*$E13 -> 0 | W13: =V13*$E13 -> 0 | Y13: =X13*$E13 -> 0 | AA13: =Z13*$E13 -> 0 | AC13: =AB13*$E13 -> 0 | AE13: =AD13*$E13 -> 0 | AF13: =(AD13+AB13+Z13+X13+V13+T13+R13+P13+N13+L13+J13+H13)/1 -> 0 | AG13: =AF13*$E13 -> 0 | AI13: =AH13*$E13 -> 0 | AK13: =AJ13*$E13 -> 0 | AM13: =AL13*$E13 -> 0 | AO13: =AN13*$E13 -> 0 | AQ13: =AP13*$E13 -> 0 | AS13: =AR13*$E13 -> 0 | AU13: =AT13*$E13 -> 0 | AW13: =AV13*$E13 -> 0 | AY13: =AX13*$E13 -> 0 | BA13: =AZ13*$E13 -> 0 | BC13: =BB13*$E13 -> 0 | BE13: =BD13*$E13 -> 0 | BF13: =(BD13+BB13+AZ13+AX13+AV13+AT13+AR13+AP13+AN13+AL13+AJ13+AH13)/1 -> 0 | BG13: =BF13*$E13 -> 0 | BI13: =BH13*$E13 -> 0 | BK13: =BJ13*$E13 -> 0 | BM13: =BL13*$E13 -> 0 | BO13: =BN13*$E13 -> 0 | BQ13: =BP13*$E13 -> 0 | BS13: =BR13*$E13 -> 0 | BU13: =BT13*$E13 -> 0 | BW13: =BV13*$E13 -> 0 | BY13: =BX13*$E13 -> 0 | CA13: =BZ13*$E13 -> 0 | CC13: =CB13*$E13 -> 0 | CE13: =CD13*$E13 -> 0 | CF13: =(CD13+CB13+BZ13+BX13+BV13+BT13+BR13+BP13+BN13+BL13+BJ13+BH13)/1 -> 0 | CG13: =CF13*$E13 -> 0 | CI13: =CH13*$E13 -> 0 | CK13: =CJ13*$E13 -> 0 | CM13: =CL13*$E13 -> 0 | CO13: =CN13*$E13 -> 0 | CQ13: =CP13*$E13 -> 0 | CS13: =CR13*$E13 -> 0 | CU13: =CT13*$E13 -> 0 | CW13: =CV13*$E13 -> 0 | CY13: 0 | DA13: 0 | DC13: 0 | DE13: 0 | DF13: =SUM(CH13,CJ13,CL13,CN13,CP13,CR13,CT13,CV13,CX13,CZ13,DB13,DD13) -> 0 | DG13: =DF13*$E13 -> 0 | DI13: 0 | DK13: =DJ13*$E13 -> 0 | EF13: =SUM(DH13,DJ13,DL13,DN13,DP13,DR13,DT13,DV13,DX13,DZ13,EB13,ED13) -> 0 | EG13: =SUM(DI13,DK13,DM13,DO13,DQ13,DS13,DU13,DW13,DY13,EA13,EC13,EE13) -> 0
A14: 10 | B14: "Zay" - 640ml | C14: ပုလင်း | D14: =RANK(DF14,$DF$4:$DF$144) -> 35 | E14: 0.64 | F14: 1 * 14 | I14: =H14*$E14 -> 0 | K14: =J14*$E14 -> 0 | M14: =L14*$E14 -> 0 | O14: =N14*$E14 -> 0 | Q14: =P14*$E14 -> 0 | S14: =R14*$E14 -> 0 | U14: =T14*$E14 -> 0 | W14: =V14*$E14 -> 0 | Y14: =X14*$E14 -> 0 | AA14: =Z14*$E14 -> 0 | AC14: =AB14*$E14 -> 0 | AE14: =AD14*$E14 -> 0 | AF14: =(AD14+AB14+Z14+X14+V14+T14+R14+P14+N14+L14+J14+H14)/1 -> 0 | AG14: =AF14*$E14 -> 0 | AI14: =AH14*$E14 -> 0 | AK14: =AJ14*$E14 -> 0 | AM14: =AL14*$E14 -> 0 | AO14: =AN14*$E14 -> 0 | AQ14: =AP14*$E14 -> 0 | AS14: =AR14*$E14 -> 0 | AU14: =AT14*$E14 -> 0 | AW14: =AV14*$E14 -> 0 | AY14: =AX14*$E14 -> 0 | BA14: =AZ14*$E14 -> 0 | BC14: =BB14*$E14 -> 0 | BE14: =BD14*$E14 -> 0 | BF14: =(BD14+BB14+AZ14+AX14+AV14+AT14+AR14+AP14+AN14+AL14+AJ14+AH14)/1 -> 0 | BG14: =BF14*$E14 -> 0 | BI14: =BH14*$E14 -> 0 | BK14: =BJ14*$E14 -> 0 | BM14: =BL14*$E14 -> 0 | BO14: =BN14*$E14 -> 0 | BQ14: =BP14*$E14 -> 0 | BS14: =BR14*$E14 -> 0 | BU14: =BT14*$E14 -> 0 | BW14: =BV14*$E14 -> 0 | BY14: =BX14*$E14 -> 0 | CA14: =BZ14*$E14 -> 0 | CC14: =CB14*$E14 -> 0 | CE14: =CD14*$E14 -> 0 | CF14: =(CD14+CB14+BZ14+BX14+BV14+BT14+BR14+BP14+BN14+BL14+BJ14+BH14)/1 -> 0 | CG14: =CF14*$E14 -> 0 | CI14: =CH14*$E14 -> 0 | CK14: =CJ14*$E14 -> 0 | CM14: =CL14*$E14 -> 0 | CO14: =CN14*$E14 -> 0 | CQ14: =CP14*$E14 -> 0 | CS14: =CR14*$E14 -> 0 | CU14: =CT14*$E14 -> 0 | CW14: =CV14*$E14 -> 0 | CY14: 0 | DA14: 0 | DC14: 0 | DE14: 0 | DF14: =SUM(CH14,CJ14,CL14,CN14,CP14,CR14,CT14,CV14,CX14,CZ14,DB14,DD14) -> 0 | DG14: =DF14*$E14 -> 0 | DI14: 0 | DK14: =DJ14*$E14 -> 0 | EF14: =SUM(DH14,DJ14,DL14,DN14,DP14,DR14,DT14,DV14,DX14,DZ14,EB14,ED14) -> 0 | EG14: =SUM(DI14,DK14,DM14,DO14,DQ14,DS14,DU14,DW14,DY14,EA14,EC14,EE14) -> 0
I15: =H15*$E15 -> 0 | K15: =J15*$E15 -> 0 | M15: =L15*$E15 -> 0 | O15: =N15*$E15 -> 0 | Q15: =P15*$E15 -> 0 | S15: =R15*$E15 -> 0 | U15: =T15*$E15 -> 0 | W15: =V15*$E15 -> 0 | Y15: =X15*$E15 -> 0 | AA15: =Z15*$E15 -> 0 | AC15: =AB15*$E15 -> 0 | AE15: =AD15*$E15 -> 0 | AF15: =(AD15+AB15+Z15+X15+V15+T15+R15+P15+N15+L15+J15+H15)/1 -> 0 | AG15: =AF15*$E15 -> 0 | AI15: =AH15*$E15 -> 0 | AK15: =AJ15*$E15 -> 0 | AM15: =AL15*$E15 -> 0 | AO15: =AN15*$E15 -> 0 | AQ15: =AP15*$E15 -> 0 | AS15: =AR15*$E15 -> 0 | AU15: =AT15*$E15 -> 0 | AW15: =AV15*$E15 -> 0 | AY15: =AX15*$E15 -> 0 | BA15: =AZ15*$E15 -> 0 | BC15: =BB15*$E15 -> 0 | BE15: =BD15*$E15 -> 0 | BF15: =(BD15+BB15+AZ15+AX15+AV15+AT15+AR15+AP15+AN15+AL15+AJ15+AH15)/1 -> 0 | BG15: =BF15*$E15 -> 0 | BI15: =BH15*$E15 -> 0 | BK15: =BJ15*$E15 -> 0 | BM15: =BL15*$E15 -> 0 | BO15: =BN15*$E15 -> 0 | BQ15: =BP15*$E15 -> 0 | BS15: =BR15*$E15 -> 0 | BU15: =BT15*$E15 -> 0 | BW15: =BV15*$E15 -> 0 | BY15: =BX15*$E15 -> 0 | CA15: =BZ15*$E15 -> 0 | CC15: =CB15*$E15 -> 0 | CE15: =CD15*$E15 -> 0 | CF15: =(CD15+CB15+BZ15+BX15+BV15+BT15+BR15+BP15+BN15+BL15+BJ15+BH15)/1 -> 0 | CG15: =CF15*$E15 -> 0 | CI15: =CH15*$E15 -> 0 | CK15: =CJ15*$E15 -> 0 | CM15: =CL15*$E15 -> 0 | CO15: =CN15*$E15 -> 0 | CQ15: =CP15*$E15 -> 0 | CS15: =CR15*$E15 -> 0 | CU15: =CT15*$E15 -> 0 | CW15: =CV15*$E15 -> 0 | CY15: 0 | DA15: 0 | DC15: 0 | DE15: 0 | DF15: =SUM(CH15,CJ15,CL15,CN15,CP15,CR15,CT15,CV15,CX15,CZ15,DB15,DD15) -> 0 | DG15: =DF15*$E15 -> 0 | DI15: 0 | DK15: =DJ15*$E15 -> 0 | EF15: =SUM(DH15,DJ15,DL15,DN15,DP15,DR15,DT15,DV15,DX15,DZ15,EB15,ED15) -> 0 | EG15: =SUM(DI15,DK15,DM15,DO15,DQ15,DS15,DU15,DW15,DY15,EA15,EC15,EE15) -> 0
A16: 11 | B16: Kaung Kyi (1 Liter)_25% | C16: ‌ကော်ဘူး | D16: =RANK(DF16,$DF$4:$DF$144) -> 8 | E16: 1 | F16: 1 * 12 | G16: 1530 | H16: 8475 | I16: =H16*$E16 -> 8475 | J16: 7344 | K16: =J16*$E16 -> 7344 | L16: 14040 | M16: =L16*$E16 -> 14040 | N16: 10788 | O16: =N16*$E16 -> 10788 | P16: 5844 | Q16: =P16*$E16 -> 5844 | R16: 7104 | S16: =R16*$E16 -> 7104 | T16: 10047 | U16: =T16*$E16 -> 10047 | V16: 12900 | W16: =V16*$E16 -> 12900 | X16: 8244 | Y16: =X16*$E16 -> 8244 | Z16: 9120 | AA16: =Z16*$E16 -> 9120 | AB16: 13236 | AC16: =AB16*$E16 -> 13236 | AD16: 10632 | AE16: =AD16*$E16 -> 10632 | AF16: =(AD16+AB16+Z16+X16+V16+T16+R16+P16+N16+L16+J16+H16)/1 -> 117774 | AG16: =AF16*$E16 -> 117774 | AH16: 12312 | AI16: =AH16*$E16 -> 12312 | AJ16: 6684 | AK16: =AJ16*$E16 -> 6684 | AL16: 12432 | AM16: =AL16*$E16 -> 12432 | AN16: 12108 | AO16: =AN16*$E16 -> 12108 | AP16: 12456 | AQ16: =AP16*$E16 -> 12456 | AR16: 13150 | AS16: =AR16*$E16 -> 13150 | AT16: 15358 | AU16: =AT16*$E16 -> 15358 | AV16: 10075 | AW16: =AV16*$E16 -> 10075 | AX16: 13018 | AY16: =AX16*$E16 -> 13018 | AZ16: 10356 | BA16: =AZ16*$E16 -> 10356 | BB16: 16800 | BC16: =BB16*$E16 -> 16800 | BD16: 16884 | BE16: =BD16*$E16 -> 16884 | BF16: =(BD16+BB16+AZ16+AX16+AV16+AT16+AR16+AP16+AN16+AL16+AJ16+AH16)/1 -> 151633 | BG16: =BF16*$E16 -> 151633 | BH16: 15300 | BI16: =BH16*$E16 -> 15300 | BJ16: 13344 | BK16: =BJ16*$E16 -> 13344 | BL16: 11724 | BM16: =BL16*$E16 -> 11724 | BN16: 18996 | BO16: =BN16*$E16 -> 18996 | BP16: 9228 | BQ16: =BP16*$E16 -> 9228 | BR16: 13296 | BS16: =BR16*$E16 -> 13296 | BT16: 18504 | BU16: =BT16*$E16 -> 18504 | BV16: 21840 | BW16: =BV16*$E16 -> 21840 | BX16: 19896 | BY16: =BX16*$E16 -> 19896 | BZ16: 28848 | CA16: =BZ16*$E16 -> 28848 | CB16: 25560 | CC16: =CB16*$E16 -> 25560 | CD16: 36288 | CE16: =CD16*$E16 -> 36288 | CF16: =(CD16+CB16+BZ16+BX16+BV16+BT16+BR16+BP16+BN16+BL16+BJ16+BH16)/1 -> 232824 | CG16: =CF16*$E16 -> 232824 | CH16: 33792 | CI16: =CH16*$E16 -> 33792 | CJ16: 20238 | CK16: =CJ16*$E16 -> 20238 | CL16: 48540 | CM16: =CL16*$E16 -> 48540 | CN16: 22764 | CO16: =CN16*$E16 -> 22764 | CP16: 26844 | CQ16: =CP16*$E16 -> 26844 | CR16: 33972 | CS16: =CR16*$E16 -> 33972 | CT16: 40620 | CU16: =CT16*$E16 -> 40620 | CV16: 36588 | CW16: =CV16*$E16 -> 36588 | CX16: 57684 | CY16: 57684 | CZ16: 67716 | DA16: 67716 | DB16: 32580 | DC16: 32580 | DD16: 53064 | DE16: 53064 | DF16: =SUM(CH16,CJ16,CL16,CN16,CP16,CR16,CT16,CV16,CX16,CZ16,DB16,DD16) -> 474402 | DG16: =DF16*$E16 -> 474402 | DH16: 51190 | DI16: 51190 | DJ16: 42868 | DK16: =DJ16*$E16 -> 42868 | EF16: =SUM(DH16,DJ16,DL16,DN16,DP16,DR16,DT16,DV16,DX16,DZ16,EB16,ED16) -> 94058 | EG16: =SUM(DI16,DK16,DM16,DO16,DQ16,DS16,DU16,DW16,DY16,EA16,EC16,EE16) -> 94058
A17: 12 | B17: Kaung Kyi (1 Liter)_40% | C17: ‌ကော်ဘူး | D17: =RANK(DF17,$DF$4:$DF$144) -> 35 | E17: 1 | F17: 1 * 12 | I17: =H17*$E17 -> 0 | K17: =J17*$E17 -> 0 | M17: =L17*$E17 -> 0 | O17: =N17*$E17 -> 0 | Q17: =P17*$E17 -> 0 | S17: =R17*$E17 -> 0 | U17: =T17*$E17 -> 0 | W17: =V17*$E17 -> 0 | Y17: =X17*$E17 -> 0 | AA17: =Z17*$E17 -> 0 | AC17: =AB17*$E17 -> 0 | AE17: =AD17*$E17 -> 0 | AF17: =(AD17+AB17+Z17+X17+V17+T17+R17+P17+N17+L17+J17+H17)/1 -> 0 | AG17: =AF17*$E17 -> 0 | AI17: =AH17*$E17 -> 0 | AK17: =AJ17*$E17 -> 0 | AM17: =AL17*$E17 -> 0 | AO17: =AN17*$E17 -> 0 | AQ17: =AP17*$E17 -> 0 | AS17: =AR17*$E17 -> 0 | AU17: =AT17*$E17 -> 0 | AW17: =AV17*$E17 -> 0 | AY17: =AX17*$E17 -> 0 | BA17: =AZ17*$E17 -> 0 | BC17: =BB17*$E17 -> 0 | BE17: =BD17*$E17 -> 0 | BF17: =(BD17+BB17+AZ17+AX17+AV17+AT17+AR17+AP17+AN17+AL17+AJ17+AH17)/1 -> 0 | BG17: =BF17*$E17 -> 0 | BI17: =BH17*$E17 -> 0 | BK17: =BJ17*$E17 -> 0 | BM17: =BL17*$E17 -> 0 | BO17: =BN17*$E17 -> 0 | BQ17: =BP17*$E17 -> 0 | BS17: =BR17*$E17 -> 0 | BU17: =BT17*$E17 -> 0 | BW17: =BV17*$E17 -> 0 | BY17: =BX17*$E17 -> 0 | CA17: =BZ17*$E17 -> 0 | CC17: =CB17*$E17 -> 0 | CE17: =CD17*$E17 -> 0 | CF17: =(CD17+CB17+BZ17+BX17+BV17+BT17+BR17+BP17+BN17+BL17+BJ17+BH17)/1 -> 0 | CG17: =CF17*$E17 -> 0 | CI17: =CH17*$E17 -> 0 | CK17: =CJ17*$E17 -> 0 | CM17: =CL17*$E17 -> 0 | CO17: =CN17*$E17 -> 0 | CQ17: =CP17*$E17 -> 0 | CS17: =CR17*$E17 -> 0 | CU17: =CT17*$E17 -> 0 | CW17: =CV17*$E17 -> 0 | CY17: 0 | DA17: 0 | DC17: 0 | DE17: 0 | DF17: =SUM(CH17,CJ17,CL17,CN17,CP17,CR17,CT17,CV17,CX17,CZ17,DB17,DD17) -> 0 | DG17: =DF17*$E17 -> 0 | DI17: 0 | DK17: =DJ17*$E17 -> 0 | EF17: =SUM(DH17,DJ17,DL17,DN17,DP17,DR17,DT17,DV17,DX17,DZ17,EB17,ED17) -> 0 | EG17: =SUM(DI17,DK17,DM17,DO17,DQ17,DS17,DU17,DW17,DY17,EA17,EC17,EE17) -> 0
A18: 13 | B18: Kaung Kyi (0.6 Liter)_25% | C18: ‌ကော်ဘူး | D18: =RANK(DF18,$DF$4:$DF$144) -> 25 | E18: 0.6 | F18: 1 * 12 | G18: 1090 | H18: 1824 | I18: =H18*$E18 -> 1094.4 | J18: 1464 | K18: =J18*$E18 -> 878.4 | L18: 3360 | M18: =L18*$E18 -> 2016 | N18: 3240 | O18: =N18*$E18 -> 1944 | P18: 660 | Q18: =P18*$E18 -> 396 | R18: 720 | S18: =R18*$E18 -> 432 | T18: 1056 | U18: =T18*$E18 -> 633.6 | V18: 1224 | W18: =V18*$E18 -> 734.4 | X18: 852 | Y18: =X18*$E18 -> 511.2 | Z18: 480 | AA18: =Z18*$E18 -> 288 | AB18: 744 | AC18: =AB18*$E18 -> 446.4 | AD18: 1608 | AE18: =AD18*$E18 -> 964.8 | AF18: =(AD18+AB18+Z18+X18+V18+T18+R18+P18+N18+L18+J18+H18)/1 -> 17232 | AG18: =AF18*$E18 -> 10339.2 | AH18: 1488 | AI18: =AH18*$E18 -> 892.8 | AJ18: 492 | AK18: =AJ18*$E18 -> 295.2 | AL18: 552 | AM18: =AL18*$E18 -> 331.2 | AN18: 600 | AO18: =AN18*$E18 -> 360 | AP18: 780 | AQ18: =AP18*$E18 -> 468 | AR18: 648 | AS18: =AR18*$E18 -> 388.8 | AT18: 564 | AU18: =AT18*$E18 -> 338.4 | AV18: 636 | AW18: =AV18*$E18 -> 381.6 | AX18: 600 | AY18: =AX18*$E18 -> 360 | AZ18: 876 | BA18: =AZ18*$E18 -> 525.6 | BB18: 720 | BC18: =BB18*$E18 -> 432 | BD18: 576 | BE18: =BD18*$E18 -> 345.6 | BF18: =(BD18+BB18+AZ18+AX18+AV18+AT18+AR18+AP18+AN18+AL18+AJ18+AH18)/1 -> 8532 | BG18: =BF18*$E18 -> 5119.2 | BH18: 900 | BI18: =BH18*$E18 -> 540 | BJ18: 564 | BK18: =BJ18*$E18 -> 338.4 | BL18: 744 | BM18: =BL18*$E18 -> 446.4 | BN18: 612 | BO18: =BN18*$E18 -> 367.2 | BP18: 12 | BQ18: =BP18*$E18 -> 7.2 | BR18: 336 | BS18: =BR18*$E18 -> 201.6 | BT18: 408 | BU18: =BT18*$E18 -> 244.8 | BV18: 336 | BW18: =BV18*$E18 -> 201.6 | BX18: 840 | BY18: =BX18*$E18 -> 504 | BZ18: 1152 | CA18: =BZ18*$E18 -> 691.2 | CB18: 1776 | CC18: =CB18*$E18 -> 1065.6 | CD18: 600 | CE18: =CD18*$E18 -> 360 | CF18: =(CD18+CB18+BZ18+BX18+BV18+BT18+BR18+BP18+BN18+BL18+BJ18+BH18)/1 -> 8280 | CG18: =CF18*$E18 -> 4968 | CH18: 672 | CI18: =CH18*$E18 -> 403.2 | CJ18: 756 | CK18: =CJ18*$E18 -> 453.6 | CL18: 540 | CM18: =CL18*$E18 -> 324 | CN18: 756 | CO18: =CN18*$E18 -> 453.6 | CP18: 720 | CQ18: =CP18*$E18 -> 432 | CR18: 456 | CS18: =CR18*$E18 -> 273.6 | CT18: 648 | CU18: =CT18*$E18 -> 388.8 | CV18: 552 | CW18: =CV18*$E18 -> 331.2 | CX18: 660 | CY18: 396 | CZ18: 840 | DA18: 504 | DB18: 456 | DC18: 273.6 | DD18: 516 | DE18: 309.6 | DF18: =SUM(CH18,CJ18,CL18,CN18,CP18,CR18,CT18,CV18,CX18,CZ18,DB18,DD18) -> 7572 | DG18: =DF18*$E18 -> 4543.2 | DH18: 216 | DI18: 129.6 | DK18: =DJ18*$E18 -> 0 | EF18: =SUM(DH18,DJ18,DL18,DN18,DP18,DR18,DT18,DV18,DX18,DZ18,EB18,ED18) -> 216 | EG18: =SUM(DI18,DK18,DM18,DO18,DQ18,DS18,DU18,DW18,DY18,EA18,EC18,EE18) -> 129.6
A19: 14 | B19: Kaung Kyi (0.6 Liter)_40% | C19: ‌ကော်ဘူး | D19: =RANK(DF19,$DF$4:$DF$144) -> 35 | E19: 0.6 | F19: 1 * 12 | I19: =H19*$E19 -> 0 | K19: =J19*$E19 -> 0 | M19: =L19*$E19 -> 0 | O19: =N19*$E19 -> 0 | Q19: =P19*$E19 -> 0 | S19: =R19*$E19 -> 0 | U19: =T19*$E19 -> 0 | W19: =V19*$E19 -> 0 | Y19: =X19*$E19 -> 0 | AA19: =Z19*$E19 -> 0 | AC19: =AB19*$E19 -> 0 | AE19: =AD19*$E19 -> 0 | AF19: =(AD19+AB19+Z19+X19+V19+T19+R19+P19+N19+L19+J19+H19)/1 -> 0 | AG19: =AF19*$E19 -> 0 | AI19: =AH19*$E19 -> 0 | AK19: =AJ19*$E19 -> 0 | AM19: =AL19*$E19 -> 0 | AO19: =AN19*$E19 -> 0 | AQ19: =AP19*$E19 -> 0 | AS19: =AR19*$E19 -> 0 | AU19: =AT19*$E19 -> 0 | AW19: =AV19*$E19 -> 0 | AY19: =AX19*$E19 -> 0 | BA19: =AZ19*$E19 -> 0 | BC19: =BB19*$E19 -> 0 | BE19: =BD19*$E19 -> 0 | BF19: =(BD19+BB19+AZ19+AX19+AV19+AT19+AR19+AP19+AN19+AL19+AJ19+AH19)/1 -> 0 | BG19: =BF19*$E19 -> 0 | BI19: =BH19*$E19 -> 0 | BK19: =BJ19*$E19 -> 0 | BM19: =BL19*$E19 -> 0 | BO19: =BN19*$E19 -> 0 | BQ19: =BP19*$E19 -> 0 | BS19: =BR19*$E19 -> 0 | BU19: =BT19*$E19 -> 0 | BW19: =BV19*$E19 -> 0 | BY19: =BX19*$E19 -> 0 | CA19: =BZ19*$E19 -> 0 | CC19: =CB19*$E19 -> 0 | CE19: =CD19*$E19 -> 0 | CF19: =(CD19+CB19+BZ19+BX19+BV19+BT19+BR19+BP19+BN19+BL19+BJ19+BH19)/1 -> 0 | CG19: =CF19*$E19 -> 0 | CI19: =CH19*$E19 -> 0 | CK19: =CJ19*$E19 -> 0 | CM19: =CL19*$E19 -> 0 | CO19: =CN19*$E19 -> 0 | CQ19: =CP19*$E19 -> 0 | CS19: =CR19*$E19 -> 0 | CU19: =CT19*$E19 -> 0 | CW19: =CV19*$E19 -> 0 | CY19: 0 | DA19: 0 | DC19: 0 | DE19: 0 | DF19: =SUM(CH19,CJ19,CL19,CN19,CP19,CR19,CT19,CV19,CX19,CZ19,DB19,DD19) -> 0 | DG19: =DF19*$E19 -> 0 | DI19: 0 | DK19: =DJ19*$E19 -> 0 | EF19: =SUM(DH19,DJ19,DL19,DN19,DP19,DR19,DT19,DV19,DX19,DZ19,EB19,ED19) -> 0 | EG19: =SUM(DI19,DK19,DM19,DO19,DQ19,DS19,DU19,DW19,DY19,EA19,EC19,EE19) -> 0
A20: 15 | B20: Kaung Kyi (0.35 Liter)_25% | C20: ‌ကော်ဘူး | D20: =RANK(DF20,$DF$4:$DF$144) -> 35 | E20: 0.35 | F20: 1 * 40 | I20: =H20*$E20 -> 0 | K20: =J20*$E20 -> 0 | M20: =L20*$E20 -> 0 | O20: =N20*$E20 -> 0 | Q20: =P20*$E20 -> 0 | S20: =R20*$E20 -> 0 | U20: =T20*$E20 -> 0 | W20: =V20*$E20 -> 0 | Y20: =X20*$E20 -> 0 | AA20: =Z20*$E20 -> 0 | AC20: =AB20*$E20 -> 0 | AE20: =AD20*$E20 -> 0 | AF20: =(AD20+AB20+Z20+X20+V20+T20+R20+P20+N20+L20+J20+H20)/1 -> 0 | AG20: =AF20*$E20 -> 0 | AI20: =AH20*$E20 -> 0 | AK20: =AJ20*$E20 -> 0 | AM20: =AL20*$E20 -> 0 | AO20: =AN20*$E20 -> 0 | AQ20: =AP20*$E20 -> 0 | AS20: =AR20*$E20 -> 0 | AU20: =AT20*$E20 -> 0 | AW20: =AV20*$E20 -> 0 | AY20: =AX20*$E20 -> 0 | BA20: =AZ20*$E20 -> 0 | BC20: =BB20*$E20 -> 0 | BE20: =BD20*$E20 -> 0 | BF20: =(BD20+BB20+AZ20+AX20+AV20+AT20+AR20+AP20+AN20+AL20+AJ20+AH20)/1 -> 0 | BG20: =BF20*$E20 -> 0 | BI20: =BH20*$E20 -> 0 | BK20: =BJ20*$E20 -> 0 | BM20: =BL20*$E20 -> 0 | BO20: =BN20*$E20 -> 0 | BQ20: =BP20*$E20 -> 0 | BS20: =BR20*$E20 -> 0 | BU20: =BT20*$E20 -> 0 | BW20: =BV20*$E20 -> 0 | BY20: =BX20*$E20 -> 0 | CA20: =BZ20*$E20 -> 0 | CC20: =CB20*$E20 -> 0 | CE20: =CD20*$E20 -> 0 | CF20: =(CD20+CB20+BZ20+BX20+BV20+BT20+BR20+BP20+BN20+BL20+BJ20+BH20)/1 -> 0 | CG20: =CF20*$E20 -> 0 | CI20: =CH20*$E20 -> 0 | CK20: =CJ20*$E20 -> 0 | CM20: =CL20*$E20 -> 0 | CO20: =CN20*$E20 -> 0 | CQ20: =CP20*$E20 -> 0 | CS20: =CR20*$E20 -> 0 | CU20: =CT20*$E20 -> 0 | CW20: =CV20*$E20 -> 0 | CY20: 0 | DA20: 0 | DC20: 0 | DE20: 0 | DF20: =SUM(CH20,CJ20,CL20,CN20,CP20,CR20,CT20,CV20,CX20,CZ20,DB20,DD20) -> 0 | DG20: =DF20*$E20 -> 0 | DI20: 0 | DK20: =DJ20*$E20 -> 0 | EF20: =SUM(DH20,DJ20,DL20,DN20,DP20,DR20,DT20,DV20,DX20,DZ20,EB20,ED20) -> 0 | EG20: =SUM(DI20,DK20,DM20,DO20,DQ20,DS20,DU20,DW20,DY20,EA20,EC20,EE20) -> 0
A21: 16 | B21: Kaung Kyi ( 0.35 Liter) - 40% | C21: ‌ကော်ဘူး | D21: =RANK(DF21,$DF$4:$DF$144) -> 35 | E21: 0.35 | F21: 1 * 40 | I21: =H21*$E21 -> 0 | K21: =J21*$E21 -> 0 | M21: =L21*$E21 -> 0 | O21: =N21*$E21 -> 0 | Q21: =P21*$E21 -> 0 | S21: =R21*$E21 -> 0 | U21: =T21*$E21 -> 0 | W21: =V21*$E21 -> 0 | Y21: =X21*$E21 -> 0 | AA21: =Z21*$E21 -> 0 | AC21: =AB21*$E21 -> 0 | AE21: =AD21*$E21 -> 0 | AF21: =(AD21+AB21+Z21+X21+V21+T21+R21+P21+N21+L21+J21+H21)/1 -> 0 | AG21: =AF21*$E21 -> 0 | AI21: =AH21*$E21 -> 0 | AK21: =AJ21*$E21 -> 0 | AM21: =AL21*$E21 -> 0 | AO21: =AN21*$E21 -> 0 | AQ21: =AP21*$E21 -> 0 | AS21: =AR21*$E21 -> 0 | AU21: =AT21*$E21 -> 0 | AW21: =AV21*$E21 -> 0 | AY21: =AX21*$E21 -> 0 | BA21: =AZ21*$E21 -> 0 | BC21: =BB21*$E21 -> 0 | BE21: =BD21*$E21 -> 0 | BF21: =(BD21+BB21+AZ21+AX21+AV21+AT21+AR21+AP21+AN21+AL21+AJ21+AH21)/1 -> 0 | BG21: =BF21*$E21 -> 0 | BI21: =BH21*$E21 -> 0 | BK21: =BJ21*$E21 -> 0 | BM21: =BL21*$E21 -> 0 | BO21: =BN21*$E21 -> 0 | BQ21: =BP21*$E21 -> 0 | BS21: =BR21*$E21 -> 0 | BU21: =BT21*$E21 -> 0 | BW21: =BV21*$E21 -> 0 | BY21: =BX21*$E21 -> 0 | CA21: =BZ21*$E21 -> 0 | CC21: =CB21*$E21 -> 0 | CE21: =CD21*$E21 -> 0 | CF21: =(CD21+CB21+BZ21+BX21+BV21+BT21+BR21+BP21+BN21+BL21+BJ21+BH21)/1 -> 0 | CG21: =CF21*$E21 -> 0 | CI21: =CH21*$E21 -> 0 | CK21: =CJ21*$E21 -> 0 | CM21: =CL21*$E21 -> 0 | CO21: =CN21*$E21 -> 0 | CQ21: =CP21*$E21 -> 0 | CS21: =CR21*$E21 -> 0 | CU21: =CT21*$E21 -> 0 | CW21: =CV21*$E21 -> 0 | CY21: 0 | DA21: 0 | DC21: 0 | DE21: 0 | DF21: =SUM(CH21,CJ21,CL21,CN21,CP21,CR21,CT21,CV21,CX21,CZ21,DB21,DD21) -> 0 | DG21: =DF21*$E21 -> 0 | DI21: 0 | DK21: =DJ21*$E21 -> 0 | EF21: =SUM(DH21,DJ21,DL21,DN21,DP21,DR21,DT21,DV21,DX21,DZ21,EB21,ED21) -> 0 | EG21: =SUM(DI21,DK21,DM21,DO21,DQ21,DS21,DU21,DW21,DY21,EA21,EC21,EE21) -> 0
A22: 17 | B22: Kaung Kyi | C22: ပုလင်း | D22: =RANK(DF22,$DF$4:$DF$144) -> 4 | E22: 0.64 | F22: 1 * 14 | G22: 1330 | H22: 70658 | I22: =H22*$E22 -> 45221.12 | J22: 66416 | K22: =J22*$E22 -> 42506.24 | L22: 74508 | M22: =L22*$E22 -> 47685.12 | N22: 54532 | O22: =N22*$E22 -> 34900.48 | P22: 57792 | Q22: =P22*$E22 -> 36986.88 | R22: 64400 | S22: =R22*$E22 -> 41216 | T22: 60830 | U22: =T22*$E22 -> 38931.2 | V22: 64428 | W22: =V22*$E22 -> 41233.92 | X22: 58705 | Y22: =X22*$E22 -> 37571.2 | Z22: 62384 | AA22: =Z22*$E22 -> 39925.76 | AB22: 67326 | AC22: =AB22*$E22 -> 43088.64 | AD22: 82770 | AE22: =AD22*$E22 -> 52972.8 | AF22: =(AD22+AB22+Z22+X22+V22+T22+R22+P22+N22+L22+J22+H22)/1 -> 784749 | AG22: =AF22*$E22 -> 502239.36 | AH22: 67662 | AI22: =AH22*$E22 -> 43303.68 | AJ22: 58922 | AK22: =AJ22*$E22 -> 37710.08 | AL22: 61334 | AM22: =AL22*$E22 -> 39253.76 | AN22: 59794 | AO22: =AN22*$E22 -> 38268.16 | AP22: 45528 | AQ22: =AP22*$E22 -> 29137.92 | AR22: 58940 | AS22: =AR22*$E22 -> 37721.6 | AT22: 68562 | AU22: =AT22*$E22 -> 43879.68 | AV22: 62636 | AW22: =AV22*$E22 -> 40087.04 | AX22: 66628 | AY22: =AX22*$E22 -> 42641.92 | AZ22: 67270 | BA22: =AZ22*$E22 -> 43052.8 | BB22: 65856 | BC22: =BB22*$E22 -> 42147.84 | BD22: 87710 | BE22: =BD22*$E22 -> 56134.4 | BF22: =(BD22+BB22+AZ22+AX22+AV22+AT22+AR22+AP22+AN22+AL22+AJ22+AH22)/1 -> 770842 | BG22: =BF22*$E22 -> 493338.88 | BH22: 75935 | BI22: =BH22*$E22 -> 48598.4 | BJ22: 64518 | BK22: =BJ22*$E22 -> 41291.52 | BL22: 69272 | BM22: =BL22*$E22 -> 44334.08 | BN22: 59570 | BO22: =BN22*$E22 -> 38124.8 | BP22: 65708 | BQ22: =BP22*$E22 -> 42053.12 | BR22: 66472 | BS22: =BR22*$E22 -> 42542.08 | BT22: 71516 | BU22: =BT22*$E22 -> 45770.24 | BV22: 59500 | BW22: =BV22*$E22 -> 38080 | BX22: 66640 | BY22: =BX22*$E22 -> 42649.6 | BZ22: 76510 | CA22: =BZ22*$E22 -> 48966.4 | CB22: 66934 | CC22: =CB22*$E22 -> 42837.76 | CD22: 79688 | CE22: =CD22*$E22 -> 51000.32 | CF22: =(CD22+CB22+BZ22+BX22+BV22+BT22+BR22+BP22+BN22+BL22+BJ22+BH22)/1 -> 822263 | CG22: =CF22*$E22 -> 526248.32 | CH22: 78915 | CI22: =CH22*$E22 -> 50505.6 | CJ22: 57960 | CK22: =CJ22*$E22 -> 37094.4 | CL22: 67424 | CM22: =CL22*$E22 -> 43151.36 | CN22: 59108 | CO22: =CN22*$E22 -> 37829.12 | CP22: 62751 | CQ22: =CP22*$E22 -> 40160.64 | CR22: 60505 | CS22: =CR22*$E22 -> 38723.2 | CT22: 62881 | CU22: =CT22*$E22 -> 40243.84 | CV22: 62132 | CW22: =CV22*$E22 -> 39764.48 | CX22: 62320 | CY22: 39884.8 | CZ22: 61037 | DA22: 39063.68 | DB22: 68404 | DC22: 43778.56 | DD22: 62636 | DE22: 40087.04 | DF22: =SUM(CH22,CJ22,CL22,CN22,CP22,CR22,CT22,CV22,CX22,CZ22,DB22,DD22) -> 766073 | DG22: =DF22*$E22 -> 490286.72 | DH22: 58716 | DI22: 37578.24 | DJ22: 55034 | DK22: =DJ22*$E22 -> 35221.76 | EF22: =SUM(DH22,DJ22,DL22,DN22,DP22,DR22,DT22,DV22,DX22,DZ22,EB22,ED22) -> 113750 | EG22: =SUM(DI22,DK22,DM22,DO22,DQ22,DS22,DU22,DW22,DY22,EA22,EC22,EE22) -> 72800
A23: 18 | B23: Kaung Kyi (40%) | C23: ပုလင်း | D23: =RANK(DF23,$DF$4:$DF$144) -> 35 | E23: 0.64 | F23: 1 * 14 | I23: =H23*$E23 -> 0 | K23: =J23*$E23 -> 0 | M23: =L23*$E23 -> 0 | O23: =N23*$E23 -> 0 | Q23: =P23*$E23 -> 0 | S23: =R23*$E23 -> 0 | U23: =T23*$E23 -> 0 | W23: =V23*$E23 -> 0 | Y23: =X23*$E23 -> 0 | AA23: =Z23*$E23 -> 0 | AC23: =AB23*$E23 -> 0 | AE23: =AD23*$E23 -> 0 | AF23: =(AD23+AB23+Z23+X23+V23+T23+R23+P23+N23+L23+J23+H23)/1 -> 0 | AG23: =AF23*$E23 -> 0 | AI23: =AH23*$E23 -> 0 | AK23: =AJ23*$E23 -> 0 | AM23: =AL23*$E23 -> 0 | AO23: =AN23*$E23 -> 0 | AQ23: =AP23*$E23 -> 0 | AS23: =AR23*$E23 -> 0 | AU23: =AT23*$E23 -> 0 | AW23: =AV23*$E23 -> 0 | AY23: =AX23*$E23 -> 0 | BA23: =AZ23*$E23 -> 0 | BC23: =BB23*$E23 -> 0 | BE23: =BD23*$E23 -> 0 | BF23: =(BD23+BB23+AZ23+AX23+AV23+AT23+AR23+AP23+AN23+AL23+AJ23+AH23)/1 -> 0 | BG23: =BF23*$E23 -> 0 | BI23: =BH23*$E23 -> 0 | BK23: =BJ23*$E23 -> 0 | BM23: =BL23*$E23 -> 0 | BO23: =BN23*$E23 -> 0 | BQ23: =BP23*$E23 -> 0 | BS23: =BR23*$E23 -> 0 | BU23: =BT23*$E23 -> 0 | BW23: =BV23*$E23 -> 0 | BY23: =BX23*$E23 -> 0 | CA23: =BZ23*$E23 -> 0 | CC23: =CB23*$E23 -> 0 | CE23: =CD23*$E23 -> 0 | CF23: =(CD23+CB23+BZ23+BX23+BV23+BT23+BR23+BP23+BN23+BL23+BJ23+BH23)/1 -> 0 | CG23: =CF23*$E23 -> 0 | CI23: =CH23*$E23 -> 0 | CK23: =CJ23*$E23 -> 0 | CM23: =CL23*$E23 -> 0 | CO23: =CN23*$E23 -> 0 | CQ23: =CP23*$E23 -> 0 | CS23: =CR23*$E23 -> 0 | CU23: =CT23*$E23 -> 0 | CW23: =CV23*$E23 -> 0 | CY23: 0 | DA23: 0 | DC23: 0 | DE23: 0 | DF23: =SUM(CH23,CJ23,CL23,CN23,CP23,CR23,CT23,CV23,CX23,CZ23,DB23,DD23) -> 0 | DG23: =DF23*$E23 -> 0 | DI23: 0 | DK23: =DJ23*$E23 -> 0 | EF23: =SUM(DH23,DJ23,DL23,DN23,DP23,DR23,DT23,DV23,DX23,DZ23,EB23,ED23) -> 0 | EG23: =SUM(DI23,DK23,DM23,DO23,DQ23,DS23,DU23,DW23,DY23,EA23,EC23,EE23) -> 0
A24: 19 | B24: Kaung Kyi (46%) | C24: ပုလင်း | D24: =RANK(DF24,$DF$4:$DF$144) -> 35 | E24: 0.64 | F24: 1 * 14 | I24: =H24*$E24 -> 0 | K24: =J24*$E24 -> 0 | M24: =L24*$E24 -> 0 | O24: =N24*$E24 -> 0 | Q24: =P24*$E24 -> 0 | S24: =R24*$E24 -> 0 | U24: =T24*$E24 -> 0 | W24: =V24*$E24 -> 0 | Y24: =X24*$E24 -> 0 | AA24: =Z24*$E24 -> 0 | AC24: =AB24*$E24 -> 0 | AE24: =AD24*$E24 -> 0 | AF24: =(AD24+AB24+Z24+X24+V24+T24+R24+P24+N24+L24+J24+H24)/1 -> 0 | AG24: =AF24*$E24 -> 0 | AI24: =AH24*$E24 -> 0 | AK24: =AJ24*$E24 -> 0 | AM24: =AL24*$E24 -> 0 | AO24: =AN24*$E24 -> 0 | AQ24: =AP24*$E24 -> 0 | AS24: =AR24*$E24 -> 0 | AU24: =AT24*$E24 -> 0 | AW24: =AV24*$E24 -> 0 | AY24: =AX24*$E24 -> 0 | BA24: =AZ24*$E24 -> 0 | BC24: =BB24*$E24 -> 0 | BE24: =BD24*$E24 -> 0 | BF24: =(BD24+BB24+AZ24+AX24+AV24+AT24+AR24+AP24+AN24+AL24+AJ24+AH24)/1 -> 0 | BG24: =BF24*$E24 -> 0 | BI24: =BH24*$E24 -> 0 | BK24: =BJ24*$E24 -> 0 | BM24: =BL24*$E24 -> 0 | BO24: =BN24*$E24 -> 0 | BQ24: =BP24*$E24 -> 0 | BS24: =BR24*$E24 -> 0 | BU24: =BT24*$E24 -> 0 | BW24: =BV24*$E24 -> 0 | BY24: =BX24*$E24 -> 0 | CA24: =BZ24*$E24 -> 0 | CC24: =CB24*$E24 -> 0 | CE24: =CD24*$E24 -> 0 | CF24: =(CD24+CB24+BZ24+BX24+BV24+BT24+BR24+BP24+BN24+BL24+BJ24+BH24)/1 -> 0 | CG24: =CF24*$E24 -> 0 | CI24: =CH24*$E24 -> 0 | CK24: =CJ24*$E24 -> 0 | CM24: =CL24*$E24 -> 0 | CO24: =CN24*$E24 -> 0 | CQ24: =CP24*$E24 -> 0 | CS24: =CR24*$E24 -> 0 | CU24: =CT24*$E24 -> 0 | CW24: =CV24*$E24 -> 0 | CY24: 0 | DA24: 0 | DC24: 0 | DE24: 0 | DF24: =SUM(CH24,CJ24,CL24,CN24,CP24,CR24,CT24,CV24,CX24,CZ24,DB24,DD24) -> 0 | DG24: =DF24*$E24 -> 0 | DI24: 0 | DK24: =DJ24*$E24 -> 0 | EF24: =SUM(DH24,DJ24,DL24,DN24,DP24,DR24,DT24,DV24,DX24,DZ24,EB24,ED24) -> 0 | EG24: =SUM(DI24,DK24,DM24,DO24,DQ24,DS24,DU24,DW24,DY24,EA24,EC24,EE24) -> 0
I25: =H25*$E25 -> 0 | K25: =J25*$E25 -> 0 | M25: =L25*$E25 -> 0 | O25: =N25*$E25 -> 0 | Q25: =P25*$E25 -> 0 | S25: =R25*$E25 -> 0 | U25: =T25*$E25 -> 0 | W25: =V25*$E25 -> 0 | Y25: =X25*$E25 -> 0 | AA25: =Z25*$E25 -> 0 | AC25: =AB25*$E25 -> 0 | AE25: =AD25*$E25 -> 0 | AF25: =(AD25+AB25+Z25+X25+V25+T25+R25+P25+N25+L25+J25+H25)/1 -> 0 | AG25: =AF25*$E25 -> 0 | AI25: =AH25*$E25 -> 0 | AK25: =AJ25*$E25 -> 0 | AM25: =AL25*$E25 -> 0 | AO25: =AN25*$E25 -> 0 | AQ25: =AP25*$E25 -> 0 | AS25: =AR25*$E25 -> 0 | AU25: =AT25*$E25 -> 0 | AW25: =AV25*$E25 -> 0 | AY25: =AX25*$E25 -> 0 | BA25: =AZ25*$E25 -> 0 | BC25: =BB25*$E25 -> 0 | BE25: =BD25*$E25 -> 0 | BF25: =(BD25+BB25+AZ25+AX25+AV25+AT25+AR25+AP25+AN25+AL25+AJ25+AH25)/1 -> 0 | BG25: =BF25*$E25 -> 0 | BI25: =BH25*$E25 -> 0 | BK25: =BJ25*$E25 -> 0 | BM25: =BL25*$E25 -> 0 | BO25: =BN25*$E25 -> 0 | BQ25: =BP25*$E25 -> 0 | BS25: =BR25*$E25 -> 0 | BU25: =BT25*$E25 -> 0 | BW25: =BV25*$E25 -> 0 | BY25: =BX25*$E25 -> 0 | CA25: =BZ25*$E25 -> 0 | CC25: =CB25*$E25 -> 0 | CE25: =CD25*$E25 -> 0 | CF25: =(CD25+CB25+BZ25+BX25+BV25+BT25+BR25+BP25+BN25+BL25+BJ25+BH25)/1 -> 0 | CG25: =CF25*$E25 -> 0 | CI25: =CH25*$E25 -> 0 | CK25: =CJ25*$E25 -> 0 | CM25: =CL25*$E25 -> 0 | CO25: =CN25*$E25 -> 0 | CQ25: =CP25*$E25 -> 0 | CS25: =CR25*$E25 -> 0 | CU25: =CT25*$E25 -> 0 | CW25: =CV25*$E25 -> 0 | CY25: 0 | DA25: 0 | DC25: 0 | DE25: 0 | DF25: =SUM(CH25,CJ25,CL25,CN25,CP25,CR25,CT25,CV25,CX25,CZ25,DB25,DD25) -> 0 | DG25: =DF25*$E25 -> 0 | DI25: 0 | DK25: =DJ25*$E25 -> 0 | EF25: =SUM(DH25,DJ25,DL25,DN25,DP25,DR25,DT25,DV25,DX25,DZ25,EB25,ED25) -> 0 | EG25: =SUM(DI25,DK25,DM25,DO25,DQ25,DS25,DU25,DW25,DY25,EA25,EC25,EE25) -> 0
A26: 20 | B26: မိုးနဲကွန်ကီကော်ဘူး(1 Liter) | C26: ‌ကော်ဘူး | D26: =RANK(DF26,$DF$4:$DF$144) -> 19 | E26: 1 | F26: 1 * 12 | G26: 2100 | I26: =H26*$E26 -> 0 | K26: =J26*$E26 -> 0 | M26: =L26*$E26 -> 0 | O26: =N26*$E26 -> 0 | Q26: =P26*$E26 -> 0 | S26: =R26*$E26 -> 0 | U26: =T26*$E26 -> 0 | W26: =V26*$E26 -> 0 | Y26: =X26*$E26 -> 0 | AA26: =Z26*$E26 -> 0 | AC26: =AB26*$E26 -> 0 | AE26: =AD26*$E26 -> 0 | AF26: =(AD26+AB26+Z26+X26+V26+T26+R26+P26+N26+L26+J26+H26)/1 -> 0 | AG26: =AF26*$E26 -> 0 | AI26: =AH26*$E26 -> 0 | AK26: =AJ26*$E26 -> 0 | AM26: =AL26*$E26 -> 0 | AO26: =AN26*$E26 -> 0 | AQ26: =AP26*$E26 -> 0 | AS26: =AR26*$E26 -> 0 | AU26: =AT26*$E26 -> 0 | AW26: =AV26*$E26 -> 0 | AY26: =AX26*$E26 -> 0 | BA26: =AZ26*$E26 -> 0 | BC26: =BB26*$E26 -> 0 | BE26: =BD26*$E26 -> 0 | BF26: =(BD26+BB26+AZ26+AX26+AV26+AT26+AR26+AP26+AN26+AL26+AJ26+AH26)/1 -> 0 | BG26: =BF26*$E26 -> 0 | BI26: =BH26*$E26 -> 0 | BK26: =BJ26*$E26 -> 0 | BM26: =BL26*$E26 -> 0 | BO26: =BN26*$E26 -> 0 | BQ26: =BP26*$E26 -> 0 | BS26: =BR26*$E26 -> 0 | BU26: =BT26*$E26 -> 0 | BW26: =BV26*$E26 -> 0 | BY26: =BX26*$E26 -> 0 | CA26: =BZ26*$E26 -> 0 | CC26: =CB26*$E26 -> 0 | CE26: =CD26*$E26 -> 0 | CF26: =(CD26+CB26+BZ26+BX26+BV26+BT26+BR26+BP26+BN26+BL26+BJ26+BH26)/1 -> 0 | CG26: =CF26*$E26 -> 0 | CI26: =CH26*$E26 -> 0 | CK26: =CJ26*$E26 -> 0 | CL26: 16608 | CM26: =CL26*$E26 -> 16608 | CN26: 6468 | CO26: =CN26*$E26 -> 6468 | CP26: 8040 | CQ26: =CP26*$E26 -> 8040 | CR26: 1188 | CS26: =CR26*$E26 -> 1188 | CT26: 1740 | CU26: =CT26*$E26 -> 1740 | CV26: 1872 | CW26: =CV26*$E26 -> 1872 | CX26: 348 | CY26: 348 | CZ26: 1704 | DA26: 1704 | DB26: 3192 | DC26: 3192 | DD26: 420 | DE26: 420 | DF26: =SUM(CH26,CJ26,CL26,CN26,CP26,CR26,CT26,CV26,CX26,CZ26,DB26,DD26) -> 41580 | DG26: =DF26*$E26 -> 41580 | DH26: 1356 | DI26: 1356 | DJ26: 1032 | DK26: =DJ26*$E26 -> 1032 | EF26: =SUM(DH26,DJ26,DL26,DN26,DP26,DR26,DT26,DV26,DX26,DZ26,EB26,ED26) -> 2388 | EG26: =SUM(DI26,DK26,DM26,DO26,DQ26,DS26,DU26,DW26,DY26,EA26,EC26,EE26) -> 2388
A27: 21 | B27: မိုးနဲကွန်ကီကော်ဘူး(0.6 Liter) | C27: ‌ကော်ဘူး | D27: =RANK(DF27,$DF$4:$DF$144) -> 35 | E27: 0.6 | F27: 1*12 | I27: =H27*$E27 -> 0 | K27: =J27*$E27 -> 0 | M27: =L27*$E27 -> 0 | O27: =N27*$E27 -> 0 | Q27: =P27*$E27 -> 0 | S27: =R27*$E27 -> 0 | U27: =T27*$E27 -> 0 | W27: =V27*$E27 -> 0 | Y27: =X27*$E27 -> 0 | AA27: =Z27*$E27 -> 0 | AC27: =AB27*$E27 -> 0 | AE27: =AD27*$E27 -> 0 | AF27: =(AD27+AB27+Z27+X27+V27+T27+R27+P27+N27+L27+J27+H27)/1 -> 0 | AG27: =AF27*$E27 -> 0 | AI27: =AH27*$E27 -> 0 | AK27: =AJ27*$E27 -> 0 | AM27: =AL27*$E27 -> 0 | AO27: =AN27*$E27 -> 0 | AQ27: =AP27*$E27 -> 0 | AS27: =AR27*$E27 -> 0 | AU27: =AT27*$E27 -> 0 | AW27: =AV27*$E27 -> 0 | AY27: =AX27*$E27 -> 0 | BA27: =AZ27*$E27 -> 0 | BC27: =BB27*$E27 -> 0 | BE27: =BD27*$E27 -> 0 | BF27: =(BD27+BB27+AZ27+AX27+AV27+AT27+AR27+AP27+AN27+AL27+AJ27+AH27)/1 -> 0 | BG27: =BF27*$E27 -> 0 | BI27: =BH27*$E27 -> 0 | BK27: =BJ27*$E27 -> 0 | BM27: =BL27*$E27 -> 0 | BO27: =BN27*$E27 -> 0 | BQ27: =BP27*$E27 -> 0 | BS27: =BR27*$E27 -> 0 | BU27: =BT27*$E27 -> 0 | BW27: =BV27*$E27 -> 0 | BY27: =BX27*$E27 -> 0 | CA27: =BZ27*$E27 -> 0 | CC27: =CB27*$E27 -> 0 | CE27: =CD27*$E27 -> 0 | CF27: =(CD27+CB27+BZ27+BX27+BV27+BT27+BR27+BP27+BN27+BL27+BJ27+BH27)/1 -> 0 | CG27: =CF27*$E27 -> 0 | CI27: =CH27*$E27 -> 0 | CK27: =CJ27*$E27 -> 0 | CM27: =CL27*$E27 -> 0 | CO27: =CN27*$E27 -> 0 | CQ27: =CP27*$E27 -> 0 | CS27: =CR27*$E27 -> 0 | CU27: =CT27*$E27 -> 0 | CW27: =CV27*$E27 -> 0 | CY27: 0 | DA27: 0 | DC27: 0 | DE27: 0 | DF27: =SUM(CH27,CJ27,CL27,CN27,CP27,CR27,CT27,CV27,CX27,CZ27,DB27,DD27) -> 0 | DG27: =DF27*$E27 -> 0 | DI27: 0 | DK27: =DJ27*$E27 -> 0 | EF27: =SUM(DH27,DJ27,DL27,DN27,DP27,DR27,DT27,DV27,DX27,DZ27,EB27,ED27) -> 0 | EG27: =SUM(DI27,DK27,DM27,DO27,DQ27,DS27,DU27,DW27,DY27,EA27,EC27,EE27) -> 0
A28: 22 | B28: Moe Nae Kon Ki | C28: ပုလင်း | D28: =RANK(DF28,$DF$4:$DF$144) -> 6 | E28: 0.64 | F28: 1 * 14 | G28: 1700 | H28: 19838 | I28: =H28*$E28 -> 12696.32 | J28: 21560 | K28: =J28*$E28 -> 13798.4 | L28: 33040 | M28: =L28*$E28 -> 21145.6 | N28: 33390 | O28: =N28*$E28 -> 21369.6 | P28: 41692 | Q28: =P28*$E28 -> 26682.88 | R28: 61586 | S28: =R28*$E28 -> 39415.04 | T28: 77210 | U28: =T28*$E28 -> 49414.4 | V28: 85148 | W28: =V28*$E28 -> 54494.72 | X28: 78722 | Y28: =X28*$E28 -> 50382.08 | Z28: 46494 | AA28: =Z28*$E28 -> 29756.16 | AB28: 52136 | AC28: =AB28*$E28 -> 33367.04 | AD28: 53018 | AE28: =AD28*$E28 -> 33931.52 | AF28: =(AD28+AB28+Z28+X28+V28+T28+R28+P28+N28+L28+J28+H28)/1 -> 603834 | AG28: =AF28*$E28 -> 386453.76 | AH28: 44912 | AI28: =AH28*$E28 -> 28743.68 | AJ28: 31654 | AK28: =AJ28*$E28 -> 20258.56 | AL28: 34804 | AM28: =AL28*$E28 -> 22274.56 | AN28: 36498 | AO28: =AN28*$E28 -> 23358.72 | AP28: 35546 | AQ28: =AP28*$E28 -> 22749.44 | AR28: 54246 | AS28: =AR28*$E28 -> 34717.44 | AT28: 73412 | AU28: =AT28*$E28 -> 46983.68 | AV28: 66720 | AW28: =AV28*$E28 -> 42700.8 | AX28: 68740 | AY28: =AX28*$E28 -> 43993.6 | AZ28: 81158 | BA28: =AZ28*$E28 -> 51941.12 | BB28: 93086 | BC28: =BB28*$E28 -> 59575.04 | BD28: 97244 | BE28: =BD28*$E28 -> 62236.16 | BF28: =(BD28+BB28+AZ28+AX28+AV28+AT28+AR28+AP28+AN28+AL28+AJ28+AH28)/1 -> 718020 | BG28: =BF28*$E28 -> 459532.8 | BH28: 91784 | BI28: =BH28*$E28 -> 58741.76 | BJ28: 70816 | BK28: =BJ28*$E28 -> 45322.24 | BL28: 67550 | BM28: =BL28*$E28 -> 43232 | BN28: 56644 | BO28: =BN28*$E28 -> 36252.16 | BP28: 80334 | BQ28: =BP28*$E28 -> 51413.76 | BR28: 84071 | BS28: =BR28*$E28 -> 53805.44 | BT28: 80080 | BU28: =BT28*$E28 -> 51251.2 | BV28: 73961 | BW28: =BV28*$E28 -> 47335.04 | BX28: 72380 | BY28: =BX28*$E28 -> 46323.2 | BZ28: 74174 | CA28: =BZ28*$E28 -> 47471.36 | CB28: 68837 | CC28: =CB28*$E28 -> 44055.68 | CD28: 70386 | CE28: =CD28*$E28 -> 45047.04 | CF28: =(CD28+CB28+BZ28+BX28+BV28+BT28+BR28+BP28+BN28+BL28+BJ28+BH28)/1 -> 891017 | CG28: =CF28*$E28 -> 570250.88 | CH28: 58032 | CI28: =CH28*$E28 -> 37140.48 | CJ28: 56770 | CK28: =CJ28*$E28 -> 36332.8 | CL28: 36787 | CM28: =CL28*$E28 -> 23543.68 | CN28: 36194 | CO28: =CN28*$E28 -> 23164.16 | CP28: 70375 | CQ28: =CP28*$E28 -> 45040 | CR28: 54995 | CS28: =CR28*$E28 -> 35196.8 | CT28: 53721 | CU28: =CT28*$E28 -> 34381.44 | CV28: 56280 | CW28: =CV28*$E28 -> 36019.2 | CX28: 40221 | CY28: 25741.44 | CZ28: 65648 | DA28: 42014.72 | DB28: 79478 | DC28: 50865.92 | DD28: 51447 | DE28: 32926.08 | DF28: =SUM(CH28,CJ28,CL28,CN28,CP28,CR28,CT28,CV28,CX28,CZ28,DB28,DD28) -> 659948 | DG28: =DF28*$E28 -> 422366.72 | DH28: 50320 | DI28: 32204.8 | DJ28: 27412 | DK28: =DJ28*$E28 -> 17543.68 | EF28: =SUM(DH28,DJ28,DL28,DN28,DP28,DR28,DT28,DV28,DX28,DZ28,EB28,ED28) -> 77732 | EG28: =SUM(DI28,DK28,DM28,DO28,DQ28,DS28,DU28,DW28,DY28,EA28,EC28,EE28) -> 49748.48
A29: 23 | B29: ‌မျောက်ရှယ် | C29: ပုလင်း | D29: =RANK(DF29,$DF$4:$DF$144) -> 35 | E29: 0.64 | F29: 1 * 14 | I29: =H29*$E29 -> 0 | K29: =J29*$E29 -> 0 | M29: =L29*$E29 -> 0 | O29: =N29*$E29 -> 0 | Q29: =P29*$E29 -> 0 | S29: =R29*$E29 -> 0 | U29: =T29*$E29 -> 0 | W29: =V29*$E29 -> 0 | Y29: =X29*$E29 -> 0 | AA29: =Z29*$E29 -> 0 | AC29: =AB29*$E29 -> 0 | AE29: =AD29*$E29 -> 0 | AF29: =(AD29+AB29+Z29+X29+V29+T29+R29+P29+N29+L29+J29+H29)/1 -> 0 | AG29: =AF29*$E29 -> 0 | AI29: =AH29*$E29 -> 0 | AK29: =AJ29*$E29 -> 0 | AM29: =AL29*$E29 -> 0 | AO29: =AN29*$E29 -> 0 | AQ29: =AP29*$E29 -> 0 | AS29: =AR29*$E29 -> 0 | AU29: =AT29*$E29 -> 0 | AW29: =AV29*$E29 -> 0 | AY29: =AX29*$E29 -> 0 | BA29: =AZ29*$E29 -> 0 | BC29: =BB29*$E29 -> 0 | BE29: =BD29*$E29 -> 0 | BF29: =(BD29+BB29+AZ29+AX29+AV29+AT29+AR29+AP29+AN29+AL29+AJ29+AH29)/1 -> 0 | BG29: =BF29*$E29 -> 0 | BI29: =BH29*$E29 -> 0 | BK29: =BJ29*$E29 -> 0 | BM29: =BL29*$E29 -> 0 | BO29: =BN29*$E29 -> 0 | BQ29: =BP29*$E29 -> 0 | BS29: =BR29*$E29 -> 0 | BU29: =BT29*$E29 -> 0 | BW29: =BV29*$E29 -> 0 | BY29: =BX29*$E29 -> 0 | CA29: =BZ29*$E29 -> 0 | CC29: =CB29*$E29 -> 0 | CE29: =CD29*$E29 -> 0 | CF29: =(CD29+CB29+BZ29+BX29+BV29+BT29+BR29+BP29+BN29+BL29+BJ29+BH29)/1 -> 0 | CG29: =CF29*$E29 -> 0 | CI29: =CH29*$E29 -> 0 | CK29: =CJ29*$E29 -> 0 | CM29: =CL29*$E29 -> 0 | CO29: =CN29*$E29 -> 0 | CQ29: =CP29*$E29 -> 0 | CS29: =CR29*$E29 -> 0 | CU29: =CT29*$E29 -> 0 | CW29: =CV29*$E29 -> 0 | CY29: 0 | DA29: 0 | DC29: 0 | DE29: 0 | DF29: =SUM(CH29,CJ29,CL29,CN29,CP29,CR29,CT29,CV29,CX29,CZ29,DB29,DD29) -> 0 | DG29: =DF29*$E29 -> 0 | DI29: 0 | DK29: =DJ29*$E29 -> 0 | EF29: =SUM(DH29,DJ29,DL29,DN29,DP29,DR29,DT29,DV29,DX29,DZ29,EB29,ED29) -> 0 | EG29: =SUM(DI29,DK29,DM29,DO29,DQ29,DS29,DU29,DW29,DY29,EA29,EC29,EE29) -> 0
