Workbook

Sheet Sales Price
A1: စဉ် | B1: အမည် | C1: မြို့နယ် | D1: ရောင်းဈေး+ကားခ | E1: ရောင်းဈေး | F1: ကားခ | G1: ကုန်ရောင်း အမျိုးအစား
A2: 1 | B2: ရွှေမြင်း | C2: မိတ္ထီလာ | D2: =E2+F2 -> 600000 | E2: 600000 | G2: Credit Sale
A3: 2 | B3: ဦးအေးခင်မောင် | C3: မိတ္ထီလာ | D3: =E3+F3 -> 610000 | E3: 610000 | G3: Credit Sale
A4: 3 | B4: ဦးဝင်းနိုင် | C4: ဝမ်းတွင်း | D4: =E4+F4 -> 610000 | E4: 610000 | G4: Credit Sale
A5: 4 | B5: ကိုဇော်ကိုနိုင် | C5: ဝမ်းတွင်း | D5: =E5+F5 -> 610000 | E5: 610000 | G5: Cash Sale
A6: 5 | B6: ဦးကျော်လှ | C6: သာစည် | D6: =E6+F6 -> 610000 | E6: 610000 | G6: Credit Sale
A7: 6 | B7: မင်းစုဝေ | C7: သာစည် | D7: =E7+F7 -> 616000 | E7: 610000 | F7: 6000 | G7: Cash Sale
A8: 7 | B8: ဦးသိန်းစိုး | C8: ကျောက်ပန်းတောင်း | D8: =E8+F8 -> 616000 | E8: 610000 | F8: 6000 | G8: Cash Sale
A9: 8 | B9: ကောင်းစုဝေ | C9: ကျောက်ပန်းတောင်း | D9: =E9+F9 -> 616000 | E9: 610000 | F9: 6000 | G9: Credit Sale
A10: 9 | B10: ကောင်းထက်သူ | C10: ကျောက်ပန်းတောင်း | D10: =E10+F10 -> 616000 | E10: 610000 | F10: 6000 | G10: Credit Sale
A11: 10 | B11: ပျားနက် | C11: ပခုက္ကူ | D11: =E11+F11 -> 625000 | E11: 610000 | F11: 15000 | G11: Credit Sale
A12: 11 | B12: ဦးတင်မောင် | C12: ပခုက္ကူ | D12: =E12+F12 -> 625000 | E12: 610000 | F12: 15000 | G12: Credit Sale
A13: 12 | B13: ဦးရဲမြင့် | C13: ရွှေဒါး | D13: =E13+F13 -> 610000 | E13: 610000 | G13: Cash Sale
A14: 13 | B14: ဦးသန်းဝင်း | C14: ပခုက္ကူ | D14: =E14+F14 -> 625000 | E14: 610000 | F14: 15000 | G14: Cash Sale
A15: 14 | B15: ကောင်းသန့် | C15: မိတ္ထီလာ | D15: =E15+F15 -> 610000 | E15: 610000 | G15: Cash Sale
A16: 15 | B16: ဦးရဲတင့် | C16: ပခုက္ကူ | D16: =E16+F16 -> 0 | G16: Cash Sale
A17: 16 | B17: မိုးယံ | C17: ရမည်းသင်း | D17: =E17+F17 -> 610000 | E17: 610000 | G17: Cash Sale
A18: 17 | B18: ကိုခင်မောင်ညွန့် | C18: မိတ္ထီလာ | D18: =E18+F18 -> 0 | G18: Cash Sale
A19: 18 | B19: မြို့မ | C19: တောင်သာ | D19: =E19+F19 -> 616000 | E19: 610000 | F19: 6000 | G19: Cash Sale
A20: 19 | B20: ပြည့်ဖြိုးကြွယ် | C20: မြင်းခြံ | D20: =E20+F20 -> 0 | G20: Cash Sale
A21: 20 | B21: မယဉ်ယဉ်အေး | C21: မလှိုင် | D21: =E21+F21 -> 615000 | E21: 610000 | F21: 5000 | G21: Cash Sale
A22: 21 | B22: စိန် | C22: မလှိုင် | D22: =E22+F22 -> 616000 | E22: 610000 | F22: 6000 | G22: Credit Sale
A23: 22 | B23: မိုးကျော် | C23: မလှိုင် | D23: =E23+F23 -> 616000 | E23: 610000 | F23: 6000 | G23: Credit Sale
A24: 23 | B24: ရွှေခြင်္သေ့ | C24: မိတ္ထီလာ | D24: =E24+F24 -> 610000 | E24: 610000 | G24: Cash Sale
A25: 24 | B25: ကိုချစ်ကို | C25: သာစည် | D25: =E25+F25 -> 610000 | E25: 610000 | G25: Cash Sale
A26: 25 | B26: ဒေါ်ခင်စန်းမြင့် | C26: ကျောက်ပန်းတောင်း | D26: =E26+F26 -> 616000 | E26: 610000 | F26: 6000 | G26: Cash Sale
A27: 26 | B27: မမာမာအုန်း | C27: မိတ္ထီလာ | D27: =E27+F27 -> 0
A28: 27 | B28: ဦးစိုးဝင်း | C28: ကျောက်ပန်းတောင်း | D28: =E28+F28 -> 616000 | E28: 610000 | F28: 6000 | G28: Cash Sale
A29: 28 | B29: စံချိန် | C29: ရမည်းသင်း | D29: =E29+F29 -> 610000 | E29: 610000 | G29: Cash Sale
A30: 29 | B30: ဦးမြင့်ဆွေ | C30: ပခုက္ကူ | D30: =E30+F30 -> 625000 | E30: 610000 | F30: 15000 | G30: Cash Sale
A31: 30 | B31: ရွှေတောင် | C31: ပုဂံ | D31: =E31+F31 -> 620000 | E31: 610000 | F31: 10000 | G31: Cash Sale
A32: 31 | B32: ကျော်ကြား | C32: မလှိုင် | D32: =E32+F32 -> 616000 | E32: 610000 | F32: 6000 | G32: Cash Sale
A33: 32 | B33: ရွှေကမ္ဘာ | C33: မိတ္ထီလာ | D33: =E33+F33 -> 610000 | E33: 610000 | G33: Cash Sale
A34: 33 | B34: ဘိုရှယ် | C34: မလှိုင် | D34: =E34+F34 -> 616000 | E34: 610000 | F34: 6000 | G34: Credit Sale
A35: 34 | B35: ရတနာ | C35: ပုဂံ | D35: =E35+F35 -> 620000 | E35: 610000 | F35: 10000 | G35: Cash Sale
A36: 35 | B36: 90 | C36: ပခုက္ကူ | D36: =E36+F36 -> 625000 | E36: 610000 | F36: 15000 | G36: Credit Sale
A37: 36 | B37: A1 | C37: ပုဂံ | D37: =E37+F37 -> 620000 | E37: 610000 | F37: 10000 | G37: Cash Sale
A38: 37
A39: 38
A40: 39
...

Sheet MTL Sales Summary
A1: OP Sales Summary for MTL -2024 | S1: OP Sales Summary for MTL - 2025 | AG1: OP Sales Summary for MTL - 2026
A2: No | B2: အမည် | C2: မြို့နယ် | D2: Type | E2: Jan | F2: Feb | G2: Mar | H2: Apr | I2: May | J2: Jun | K2: Jul | L2: Aug | M2: Sep | N2: Oct | O2: Nov | P2: Dec | Q2: Total | S2: Jan | T2: Feb | U2: Mar | V2: Apr | W2: May | X2: Jun | Y2: Jul | Z2: Aug | AA2: Sep | AB2: Oct | AC2: Nov | AD2: Dec | AE2: Total | AG2: Jan | AH2: Feb | AI2: Mar | AJ2: Apr | AK2: May | AL2: Jun | AM2: Jul | AN2: Aug | AO2: Sep | AP2: Oct | AQ2: Nov | AR2: Dec | AS2: Total
A3: 1 | B3: ရွှေမြင်း | C3: မိတ္ထီလာ | D3: Credit Sale | E3: 173 | F3: 162 | G3: 162 | H3: 155 | I3: 168 | J3: 164 | K3: 165 | L3: 196 | M3: 175 | N3: 215 | O3: 234 | P3: 241 | Q3: =SUM(E3:P3) -> 2210 | S3: 198 | T3: 166 | U3: 160 | V3: 144 | W3: 159 | X3: 159 | Y3: 132 | Z3: 137 | AA3: 145 | AB3: 139 | AC3: 157 | AD3: 177 | AE3: =SUM(S3:AD3) -> 1873 | AG3: 175 | AH3: 114 | AI3: ='MTL OP Debtor'!F85 -> 105 | AS3: =SUM(AG3:AR3) -> 394
A4: 2 | B4: ဦးအေးခင်မောင် | C4: မိတ္ထီလာ | D4: Cash Sale | E4: 2 | F4: 3 | G4: 2 | H4: 2 | I4: 3 | J4: 5 | K4: 2 | L4: 4 | M4: 3 | N4: 4 | O4: 5 | P4: 3 | Q4: =SUM(E4:P4) -> 38 | S4: 2 | T4: 3 | U4: 3 | V4: 2 | W4: 2 | X4: 4 | Y4: 2 | Z4: 3 | AA4: 2 | AB4: 1 | AC4: 3 | AD4: 1 | AE4: =SUM(S4:AD4) -> 28 | AG4: 3 | AH4: 0 | AI4: ='MTL OP Debtor'!F86 -> 1 | AS4: =SUM(AG4:AR4) -> 4
A5: 3 | B5: ဦးဝင်းနိုင် | C5: လျှော်ပင် | D5: Credit Sale | E5: 4 | F5: 12 | G5: 12 | H5: 17 | I5: 10 | J5: 8 | K5: 8 | L5: 12 | M5: 6 | N5: 12 | O5: 3 | P5: 2 | Q5: =SUM(E5:P5) -> 106 | S5: 11 | T5: 7 | U5: 6 | V5: 10 | W5: 14 | X5: 14 | Y5: 19 | Z5: 12 | AA5: 13 | AB5: 18 | AC5: 9 | AD5: 15 | AE5: =SUM(S5:AD5) -> 148 | AG5: 14 | AH5: 8 | AI5: ='MTL OP Debtor'!F87 -> 9 | AS5: =SUM(AG5:AR5) -> 31
A6: 4 | B6: ကိုဇော်ကိုနိုင် | C6: ဝမ်းတွင်း | D6: Cash Sale | G6: 1 | J6: 1 | M6: 1 | O6: 1 | P6: 0 | Q6: =SUM(E6:P6) -> 4 | S6: 1 | T6: 0 | U6: 0 | V6: 0 | W6: 0 | X6: 1 | Y6: 0 | Z6: 0 | AA6: 0 | AB6: 1 | AC6: 0 | AD6: 0 | AE6: =SUM(S6:AD6) -> 3 | AG6: 1 | AH6: 0 | AI6: ='MTL OP Debtor'!F88 -> 0 | AS6: =SUM(AG6:AR6) -> 1
A7: 5 | B7: ဦးကျော်လှ | C7: သာစည် | D7: Cash Sale | N7: 3 | O7: 1 | P7: 2 | Q7: =SUM(E7:P7) -> 6 | S7: 2 | T7: 2 | U7: 2 | V7: 4 | W7: 1 | X7: 3 | Y7: 2 | Z7: 3 | AA7: 2 | AB7: 3 | AC7: 2 | AD7: 2 | AE7: =SUM(S7:AD7) -> 28 | AG7: 1 | AH7: 3 | AI7: ='MTL OP Debtor'!F89 -> 0 | AS7: =SUM(AG7:AR7) -> 4
A8: 6 | B8: မင်းစုဝေ | C8: သာစည် | D8: Cash Sale | N8: 14 | O8: 8 | P8: 10 | Q8: =SUM(E8:P8) -> 32 | S8: 2 | T8: 2 | U8: 10 | V8: 9 | W8: 8 | X8: 0 | Y8: 0 | Z8: 0 | AA8: 0 | AB8: 0 | AC8: 0 | AD8: 0 | AE8: =SUM(S8:AD8) -> 31 | AG8: 0 | AH8: 0 | AI8: ='MTL OP Debtor'!F90 -> 0 | AS8: =SUM(AG8:AR8) -> 0
A9: 7 | B9: ဦးသိန်းစိုး | C9: ကျောက်ပန်းတောင်း | D9: Cash Sale | K9: 5 | L9: 20 | M9: 10 | N9: 15 | O9: 20 | P9: 15 | Q9: =SUM(E9:P9) -> 85 | S9: 20 | T9: 10 | U9: 15 | V9: 18 | W9: 5 | X9: 10 | Y9: 15 | Z9: 10 | AA9: 10 | AB9: 10 | AC9: 8 | AD9: 10 | AE9: =SUM(S9:AD9) -> 141 | AG9: 10 | AH9: 5 | AI9: ='MTL OP Debtor'!F91 -> 8 | AS9: =SUM(AG9:AR9) -> 23
A10: 8 | B10: ကောင်းစုဝေ | C10: ကျောက်ပန်းတောင်း | D10: Cash Sale | N10: 11 | O10: 10 | P10: 0 | Q10: =SUM(E10:P10) -> 21 | S10: 0 | T10: 10 | U10: 10 | V10: 10 | W10: 10 | X10: 10 | Y10: 10 | Z10: 8 | AA10: 10 | AB10: 0 | AC10: 10 | AD10: 10 | AE10: =SUM(S10:AD10) -> 98 | AG10: 10 | AH10: 0 | AI10: ='MTL OP Debtor'!F92 -> 10 | AS10: =SUM(AG10:AR10) -> 20
A11: 9 | B11: ကောင်းထက်သူ | C11: ကျောက်ပန်းတောင်း | D11: Cash Sale | M11: 5 | O11: 0 | P11: 0 | Q11: =SUM(E11:P11) -> 5 | S11: 0 | T11: 0 | U11: 0 | V11: 0 | W11: 2 | X11: 2 | Y11: 2 | Z11: 0 | AA11: 2 | AB11: 0 | AC11: 0 | AD11: 0 | AE11: =SUM(S11:AD11) -> 8 | AG11: 0 | AH11: 0 | AI11: ='MTL OP Debtor'!F93 -> 0 | AS11: =SUM(AG11:AR11) -> 0
A12: 10 | B12: ပျားနက် | C12: ပခုက္ကူ | D12: Cash Sale | M12: 10 | N12: 50 | O12: 40 | P12: 40 | Q12: =SUM(E12:P12) -> 140 | S12: 30 | T12: 25 | U12: 20 | V12: 90 | W12: 20 | X12: 20 | Y12: 10 | Z12: 30 | AA12: 10 | AB12: 30 | AC12: 20 | AD12: 20 | AE12: =SUM(S12:AD12) -> 325 | AG12: 20 | AH12: 10 | AI12: ='MTL OP Debtor'!F94 -> 0 | AS12: =SUM(AG12:AR12) -> 30
A13: 11 | B13: ဦးတင်မောင် | C13: ပခုက္ကူ | D13: Credit Sale | M13: 20 | N13: 30 | O13: 5 | P13: 40 | Q13: =SUM(E13:P13) -> 95 | S13: 15 | T13: 15 | U13: 15 | V13: 30 | W13: 20 | X13: 35 | Y13: 10 | Z13: 25 | AA13: 10 | AB13: 25 | AC13: 30 | AD13: 10 | AE13: =SUM(S13:AD13) -> 240 | AG13: 30 | AH13: 10 | AI13: ='MTL OP Debtor'!F95 -> 10 | AS13: =SUM(AG13:AR13) -> 50
A14: 12 | B14: ဦးရဲမြင့် | C14: ရွှေဒါး | D14: Cash Sale | N14: 10 | O14: 10 | P14: 10 | Q14: =SUM(E14:P14) -> 30 | S14: 10 | T14: 15 | U14: 11 | V14: 9 | W14: 9 | X14: 12 | Y14: 9 | Z14: 12 | AA14: 9 | AB14: 18 | AC14: 18 | AD14: 12 | AE14: =SUM(S14:AD14) -> 144 | AG14: 24 | AH14: 9 | AI14: ='MTL OP Debtor'!F96 -> 6 | AS14: =SUM(AG14:AR14) -> 39
A15: 13 | B15: ဦးသန်းဝင်း | C15: ပခုက္ကူ | D15: Cash Sale | N15: 20 | O15: 20 | P15: 10 | Q15: =SUM(E15:P15) -> 50 | S15: 20 | T15: 10 | U15: 15 | V15: 25 | W15: 25 | X15: 10 | Y15: 10 | Z15: 10 | AA15: 10 | AB15: 10 | AC15: 10 | AD15: 10 | AE15: =SUM(S15:AD15) -> 165 | AG15: 10 | AH15: 10 | AI15: ='MTL OP Debtor'!F97 -> 10 | AS15: =SUM(AG15:AR15) -> 30
A16: 14 | B16: ကောင်းသန့် | C16: မိတ္ထီလာ | D16: Cash Sale | N16: 5 | O16: 1 | P16: 3 | Q16: =SUM(E16:P16) -> 9 | S16: 9 | T16: 11 | U16: 3 | V16: 9 | W16: 11 | X16: 13 | Y16: 17 | Z16: 11 | AA16: 20 | AB16: 18 | AC16: 17 | AD16: 18 | AE16: =SUM(S16:AD16) -> 157 | AG16: 11 | AH16: 1 | AI16: ='MTL OP Debtor'!F98 -> 0 | AS16: =SUM(AG16:AR16) -> 12
A17: 15 | B17: ဦးရဲတင့် | C17: ပခုက္ကူ | D17: Cash Sale | N17: 2 | O17: 0 | P17: 0 | Q17: =SUM(E17:P17) -> 2 | S17: 0 | T17: 0 | U17: 0 | V17: 0 | W17: 0 | X17: 0 | Y17: 0 | Z17: 0 | AA17: 0 | AB17: 0 | AC17: 0 | AD17: 0 | AE17: =SUM(S17:AD17) -> 0 | AG17: 0 | AH17: 0 | AI17: ='MTL OP Debtor'!F99 -> 0 | AS17: =SUM(AG17:AR17) -> 0
A18: 16 | B18: မိုးယံ | C18: ရမည်းသင်း | D18: Cash Sale | K18: 16 | L18: 13 | M18: 5 | N18: 10 | O18: 15 | P18: 20 | Q18: =SUM(E18:P18) -> 79 | S18: 20 | T18: 20 | U18: 5 | V18: 20 | W18: 15 | X18: 5 | Y18: 10 | Z18: 7 | AA18: 2 | AB18: 0 | AC18: 1 | AD18: 0 | AE18: =SUM(S18:AD18) -> 105 | AG18: 0 | AH18: 3 | AI18: ='MTL OP Debtor'!F100 -> 0 | AS18: =SUM(AG18:AR18) -> 3
A19: 17 | B19: ကိုခင်မောင်ညွန့် | C19: မိတ္ထီလာ | D19: Cash Sale | N19: 3 | O19: 0 | P19: 0 | Q19: =SUM(E19:P19) -> 3 | S19: 0 | T19: 0 | U19: 0 | V19: 0 | W19: 0 | X19: 0 | Y19: 0 | Z19: 0 | AA19: 0 | AB19: 0 | AC19: 0 | AD19: 0 | AE19: =SUM(S19:AD19) -> 0 | AG19: 0 | AH19: 0 | AI19: ='MTL OP Debtor'!F101 -> 0 | AS19: =SUM(AG19:AR19) -> 0
A20: 18 | B20: မြို့မ | C20: တောင်သာ | D20: Cash Sale | N20: 1 | O20: 0 | P20: 0 | Q20: =SUM(E20:P20) -> 1 | S20: 0 | T20: 0 | U20: 0 | V20: 0 | W20: 0 | X20: 0 | Y20: 0 | Z20: 0 | AA20: 0 | AB20: 0 | AC20: 0 | AD20: 0 | AE20: =SUM(S20:AD20) -> 0 | AG20: 0 | AH20: 0 | AI20: ='MTL OP Debtor'!F102 -> 0 | AS20: =SUM(AG20:AR20) -> 0
A21: 19 | B21: ပြည့်ဖြိုးကြွယ် | C21: မြင်းခြံ | D21: Cash Sale | M21: 10 | N21: 20 | O21: 0 | P21: 0 | Q21: =SUM(E21:P21) -> 30 | S21: 0 | T21: 0 | U21: 0 | V21: 0 | W21: 0 | X21: 0 | Y21: 0 | Z21: 0 | AA21: 0 | AB21: 0 | AC21: 0 | AD21: 0 | AE21: =SUM(S21:AD21) -> 0 | AG21: 0 | AH21: 0 | AI21: ='MTL OP Debtor'!F103 -> 0 | AS21: =SUM(AG21:AR21) -> 0
A22: 20 | B22: မယဉ်ယဉ်အေး | C22: မလှိုင် | D22: Cash Sale | O22: 10 | P22: 10 | Q22: =SUM(E22:P22) -> 20 | S22: 10 | T22: 5 | U22: 5 | V22: 0 | W22: 0 | X22: 0 | Y22: 0 | Z22: 0 | AA22: 0 | AB22: 0 | AC22: 0 | AD22: 0 | AE22: =SUM(S22:AD22) -> 20 | AG22: 0 | AH22: 0 | AI22: ='MTL OP Debtor'!F104 -> 0 | AS22: =SUM(AG22:AR22) -> 0
A23: 21 | B23: စိန် | C23: မလှိုင် | D23: Cash Sale | O23: 1 | P23: 3 | Q23: =SUM(E23:P23) -> 4 | S23: 3 | T23: 0 | U23: 1 | V23: 2 | W23: 0 | X23: 2 | Y23: 2 | Z23: 0 | AA23: 2 | AB23: 0 | AC23: 2 | AD23: 2 | AE23: =SUM(S23:AD23) -> 16 | AG23: 2 | AH23: 0 | AI23: ='MTL OP Debtor'!F105 -> 0 | AS23: =SUM(AG23:AR23) -> 2
A24: 22 | B24: မိုးကျော် | C24: မလှိုင် | D24: Cash Sale | O24: 2 | P24: 3 | Q24: =SUM(E24:P24) -> 5 | S24: 3 | T24: 0 | U24: 0 | V24: 1 | W24: 0 | X24: 1 | Y24: 0 | Z24: 1 | AA24: 0 | AB24: 1 | AC24: 1 | AD24: 0 | AE24: =SUM(S24:AD24) -> 8 | AG24: 1 | AH24: 0 | AI24: ='MTL OP Debtor'!F106 -> 0 | AS24: =SUM(AG24:AR24) -> 1
A25: 23 | B25: ရွှေခြင်္သေ့ | C25: မိတ္ထီလာ | D25: Cash Sale | O25: 9 | P25: 12 | Q25: =SUM(E25:P25) -> 21 | S25: 15 | T25: 12 | U25: 12 | V25: 14 | W25: 15 | X25: 15 | Y25: 12 | Z25: 15 | AA25: 15 | AB25: 20 | AC25: 12 | AD25: 18 | AE25: =SUM(S25:AD25) -> 175 | AG25: 15 | AH25: 13 | AI25: ='MTL OP Debtor'!F107 -> 3 | AS25: =SUM(AG25:AR25) -> 31
A26: 24 | B26: ကိုချစ်ကို | C26: သာစည် | D26: Cash Sale | O26: 2 | P26: 4 | Q26: =SUM(E26:P26) -> 6 | S26: 2 | T26: 0 | U26: 0 | V26: 0 | W26: 0 | X26: 0 | Y26: 0 | Z26: 0 | AA26: 0 | AB26: 0 | AC26: 0 | AD26: 0 | AE26: =SUM(S26:AD26) -> 2 | AG26: 0 | AH26: 0 | AI26: ='MTL OP Debtor'!F108 -> 0 | AS26: =SUM(AG26:AR26) -> 0
A27: 25 | B27: ဒေါ်ခင်စန်းမြင့် | C27: ကျောက်ပန်းတောင်း | D27: Cash Sale | M27: 1 | O27: 5 | P27: 0 | Q27: =SUM(E27:P27) -> 6 | S27: 0 | T27: 3 | U27: 0 | V27: 10 | W27: 0 | X27: 3 | Y27: 0 | Z27: 3 | AA27: 0 | AB27: 0 | AC27: 0 | AD27: 0 | AE27: =SUM(S27:AD27) -> 19 | AG27: 0 | AH27: 0 | AI27: ='MTL OP Debtor'!F109 -> 0 | AS27: =SUM(AG27:AR27) -> 0
A28: 26 | B28: မမာမာအုန်း | C28: မိတ္ထီလာ | D28: Cash Sale | O28: 0 | P28: 0 | Q28: =SUM(E28:P28) -> 0 | S28: 0 | T28: 0 | U28: 0 | V28: 0 | W28: 0 | X28: 0 | Y28: 0 | Z28: 0 | AA28: 0 | AB28: 0 | AC28: 0 | AD28: 0 | AE28: =SUM(S28:AD28) -> 0 | AG28: 0 | AH28: 0 | AI28: ='MTL OP Debtor'!F110 -> 0 | AS28: =SUM(AG28:AR28) -> 0
A29: 27 | B29: ဦးစိုးဝင်း | C29: ကျောက်ပန်းတောင်း | D29: Cash Sale | O29: 5 | P29: 0 | Q29: =SUM(E29:P29) -> 5 | S29: 5 | T29: 0 | U29: 0 | V29: 0 | W29: 0 | X29: 0 | Y29: 0 | Z29: 0 | AA29: 0 | AB29: 0 | AC29: 0 | AD29: 0 | AE29: =SUM(S29:AD29) -> 5 | AG29: 0 | AH29: 0 | AI29: ='MTL OP Debtor'!F111 -> 0 | AS29: =SUM(AG29:AR29) -> 0
A30: 28 | B30: စံချိန် | C30: ရမည်းသင်း | D30: Credit Sale | O30: 5 | P30: 20 | Q30: =SUM(E30:P30) -> 25 | S30: 20 | T30: 20 | U30: 0 | V30: 0 | W30: 0 | X30: 0 | Y30: 0 | Z30: 0 | AA30: 0 | AB30: 0 | AC30: 0 | AD30: 0 | AE30: =SUM(S30:AD30) -> 40 | AG30: 0 | AH30: 0 | AI30: ='MTL OP Debtor'!F112 -> 0 | AS30: =SUM(AG30:AR30) -> 0
A31: 29 | B31: ဦးမြင့်ဆွေ | C31: ပခုက္ကူ | D31: Credit Sale | O31: 20 | P31: 0 | Q31: =SUM(E31:P31) -> 20 | S31: 20 | T31: 20 | U31: 20 | V31: 0 | W31: 20 | X31: 30 | Y31: 0 | Z31: 20 | AA31: 0 | AB31: 20 | AC31: 20 | AD31: 0 | AE31: =SUM(S31:AD31) -> 170 | AG31: 0 | AH31: 0 | AI31: ='MTL OP Debtor'!F113 -> 20 | AS31: =SUM(AG31:AR31) -> 20
A32: 30 | B32: ရွှေတောင် | C32: ပုဂံ | D32: Cash Sale | O32: 1 | P32: 0 | Q32: =SUM(E32:P32) -> 1 | S32: 2 | T32: 2 | U32: 0 | V32: 3 | W32: 0 | X32: 0 | Y32: 0 | Z32: 0 | AA32: 0 | AB32: 0 | AC32: 0 | AD32: 0 | AE32: =SUM(S32:AD32) -> 7 | AG32: 0 | AH32: 0 | AI32: ='MTL OP Debtor'!F114 -> 0 | AS32: =SUM(AG32:AR32) -> 0
A33: 31 | B33: ကျော်ကြား | C33: မလှိုင် | D33: Cash Sale | O33: 0 | P33: 10 | Q33: =SUM(E33:P33) -> 10 | S33: 5 | T33: 5 | U33: 5 | V33: 5 | W33: 5 | X33: 5 | Y33: 5 | Z33: 5 | AA33: 5 | AB33: 5 | AC33: 5 | AD33: 3 | AE33: =SUM(S33:AD33) -> 58 | AG33: 5 | AH33: 5 | AI33: ='MTL OP Debtor'!F115 -> 0 | AS33: =SUM(AG33:AR33) -> 10
A34: 32 | B34: ဘိုရှယ် | C34: မလှိုင် | D34: Cash Sale | P34: 1 | Q34: =SUM(E34:P34) -> 1 | S34: 4 | T34: 4 | U34: 6 | V34: 4 | W34: 4 | X34: 5 | Y34: 7 | Z34: 5 | AA34: 4 | AB34: 7 | AC34: 6 | AD34: 3 | AE34: =SUM(S34:AD34) -> 59 | AG34: 7 | AH34: 3 | AI34: ='MTL OP Debtor'!F116 -> 3 | AS34: =SUM(AG34:AR34) -> 13
A35: 33 | B35: ‌ရွှေကမ္ဘာ | C35: မိတ္ထီလာ | D35: Cash Sale | P35: 2 | Q35: =SUM(E35:P35) -> 2 | S35: 4 | T35: 8 | U35: 7 | V35: 8 | W35: 8 | X35: 8 | Y35: 5 | Z35: 5 | AA35: 5 | AB35: 7 | AC35: 1 | AD35: 0 | AE35: =SUM(S35:AD35) -> 66 | AG35: 0 | AH35: 0 | AI35: ='MTL OP Debtor'!F117 -> 0 | AS35: =SUM(AG35:AR35) -> 0
A36: 34 | B36: ရတနာ | C36: ပုဂံ | D36: Cash Sale | T36: 2 | U36: 1 | V36: 7 | W36: 0 | X36: 0 | Y36: 0 | Z36: 7 | AA36: 0 | AB36: 0 | AC36: 0 | AD36: 5 | AE36: =SUM(S36:AD36) -> 22 | AG36: 0 | AH36: 3 | AI36: ='MTL OP Debtor'!F118 -> 0 | AS36: =SUM(AG36:AR36) -> 3
A37: 35 | B37: 90 | C37: ပခုက္ကူ | D37: Cash Sale | W37: 15 | X37: 5 | Y37: 10 | Z37: 15 | AA37: 0 | AB37: 10 | AC37: 0 | AD37: 20 | AE37: =SUM(S37:AD37) -> 75 | AG37: 10 | AH37: 5 | AI37: ='MTL OP Debtor'!F119 -> 0 | AS37: =SUM(AG37:AR37) -> 15
A38: 36 | B38: A1 | C38: ပုဂံ | D38: Cash Sale | Z38: 8 | AA38: 40 | AB38: 0 | AC38: 0 | AD38: 15 | AE38: =SUM(S38:AD38) -> 63 | AG38: 0 | AH38: 5 | AI38: ='MTL OP Debtor'!F120 -> 0 | AS38: =SUM(AG38:AR38) -> 5
B40: Total Outlet | E40: =SUM(E3:E35) -> 179 | F40: =SUM(F3:F35) -> 177 | G40: =SUM(G3:G35) -> 177 | H40: =SUM(H3:H35) -> 174 | I40: =SUM(I3:I35) -> 181 | J40: =SUM(J3:J35) -> 178 | K40: =SUM(K3:K35) -> 196 | L40: =SUM(L3:L35) -> 245 | ... Q40: =SUM(Q3:Q35) -> 3072 | S40: =SUM(S3:S39) -> 433 | T40: =SUM(T3:T39) -> 377 | U40: =SUM(U3:U39) -> 332 | V40: =SUM(V3:V39) -> 434 | W40: =SUM(W3:W39) -> 368 | X40: =SUM(X3:X39) -> 372 | Y40: =SUM(Y3:Y39) -> 289 | Z40: =SUM(Z3:Z39) -> 352 | ... AE40: =SUM(AE3:AE39) -> 4299 | AG40: =SUM(AG3:AG39) -> 349 | AH40: =SUM(AH3:AH39) -> 207 | AI40: =SUM(AI3:AI39) -> 185 | AJ40: =SUM(AJ3:AJ39) -> 0 | AK40: =SUM(AK3:AK39) -> 0 | AL40: =SUM(AL3:AL39) -> 0 | AM40: =SUM(AM3:AM39) -> 0 | AN40: =SUM(AN3:AN39) -> 0 | ... AS40: =SUM(AS3:AS39) -> 741
B41: New Outlet
...

Sheet MTL OP Debtor
A1: 2026- January
A2: စဉ် | B2: အမည် | C2: မြို့နယ် | D2: ရောင်းဈေး | E2: စာရင်းဖွင့် | F2: ကုန်ရောင်း လုံးရေ | G2: ကုန်ရောင်း ရငွေ | H2: သွင်းငွေ | I2: ကျန်ငွေ | K2: စာရင်းဖွင့် ကော်ခွံ | L2: ကုန်ရောင်း ကော်ခွံ | M2: ပြန်ရ ကော်ခွံ | N2: စာရင်းပိတ် ကော်ခွံ
A3: 1 | B3: ရွှေမြင်း | C3: မိတ္ထီလာ | E3: 100003931 | F3: =SUMIF('Daily Sales'!$B$3:$B$63,'MTL OP Debtor'!B3,'Daily Sales'!$G$3:$G$63) -> 175 | G3: =SUMIF('Daily Sales'!$B$3:$B$63,'MTL OP Debtor'!B3,'Daily Sales'!$H$3:$H$63) -> 100625000 | H3: 90915205 | I3: =E3+G3-H3 -> 109713726 | K3: 143 | L3: =F3 -> 175 | M3: 175 | N3: =+K3+L3-M3 -> 143
A4: 2 | B4: ဦးအေးခင်မောင် | C4: မိတ္ထီလာ | E4: 0 | F4: =SUMIF('Daily Sales'!$B$3:$B$63,'MTL OP Debtor'!B4,'Daily Sales'!$G$3:$G$63) -> 3 | G4: =SUMIF('Daily Sales'!$B$3:$B$63,'MTL OP Debtor'!B4,'Daily Sales'!$H$3:$H$63) -> 1755000 | H4: 1755000 | I4: =E4+G4-H4 -> 0 | K4: 18 | L4: =F4 -> 3 | M4: 3 | N4: =+K4+L4-M4 -> 18
A5: 3 | B5: ဦးဝင်းနိုင် | C5: လျှော်ပင် | E5: 8775000 | F5: =SUMIF('Daily Sales'!$B$3:$B$63,'MTL OP Debtor'!B5,'Daily Sales'!$G$3:$G$63) -> 14 | G5: =SUMIF('Daily Sales'!$B$3:$B$63,'MTL OP Debtor'!B5,'Daily Sales'!$H$3:$H$63) -> 8190000 | H5: 8775000 | I5: =E5+G5-H5 -> 8190000 | K5: 0 | L5: =F5 -> 14 | M5: 14 | N5: =+K5+L5-M5 -> 0
A6: 4 | B6: ကိုဇော်ကိုနိုင် | C6: ဝမ်းတွင်း | E6: 0 | F6: =SUMIF('Daily Sales'!$B$3:$B$63,'MTL OP Debtor'!B6,'Daily Sales'!$G$3:$G$63) -> 1 | G6: =SUMIF('Daily Sales'!$B$3:$B$63,'MTL OP Debtor'!B6,'Daily Sales'!$H$3:$H$63) -> 585000 | H6: 585000 | I6: =E6+G6-H6 -> 0 | K6: 0 | L6: =F6 -> 1 | M6: 1 | N6: =+K6+L6-M6 -> 0
A7: 5 | B7: ဦးကျော်လှ | C7: သာစည် | E7: 1170000 | F7: =SUMIF('Daily Sales'!$B$3:$B$63,'MTL OP Debtor'!B7,'Daily Sales'!$G$3:$G$63) -> 1 | G7: =SUMIF('Daily Sales'!$B$3:$B$63,'MTL OP Debtor'!B7,'Daily Sales'!$H$3:$H$63) -> 585000 | H7: 1170000 | I7: =E7+G7-H7 -> 585000 | K7: 0 | L7: =F7 -> 1 | M7: 1 | N7: =+K7+L7-M7 -> 0
A8: 6 | B8: မင်းစုဝေ | C8: သာစည် | E8: 0 | F8: =SUMIF('Daily Sales'!$B$3:$B$63,'MTL OP Debtor'!B8,'Daily Sales'!$G$3:$G$63) -> 0 | G8: =SUMIF('Daily Sales'!$B$3:$B$63,'MTL OP Debtor'!B8,'Daily Sales'!$H$3:$H$63) -> 0 | I8: =E8+G8-H8 -> 0 | K8: 0 | L8: =F8 -> 0 | M8: 0 | N8: =+K8+L8-M8 -> 0
A9: 7 | B9: ဦးသိန်းစိုး | C9: ကျောက်ပန်းတောင်း | E9: 0 | F9: =SUMIF('Daily Sales'!$B$3:$B$63,'MTL OP Debtor'!B9,'Daily Sales'!$G$3:$G$63) -> 10 | G9: =SUMIF('Daily Sales'!$B$3:$B$63,'MTL OP Debtor'!B9,'Daily Sales'!$H$3:$H$63) -> 5910000 | H9: 5910000 | I9: =E9+G9-H9 -> 0 | K9: 10 | L9: =F9 -> 10 | M9: 10 | N9: =+K9+L9-M9 -> 10
A10: 8 | B10: ကောင်းစုဝေ | C10: ကျောက်ပန်းတောင်း | E10: 5960000 | F10: =SUMIF('Daily Sales'!$B$3:$B$63,'MTL OP Debtor'!B10,'Daily Sales'!$G$3:$G$63) -> 10 | G10: =SUMIF('Daily Sales'!$B$3:$B$63,'MTL OP Debtor'!B10,'Daily Sales'!$H$3:$H$63) -> 5960000 | H10: 5960000 | I10: =E10+G10-H10 -> 5960000 | K10: 5 | L10: =F10 -> 10 | M10: 10 | N10: =+K10+L10-M10 -> 5
A11: 9 | B11: ကောင်းထက်သူ | C11: ကျောက်ပန်းတောင်း | E11: 0 | F11: =SUMIF('Daily Sales'!$B$3:$B$63,'MTL OP Debtor'!B11,'Daily Sales'!$G$3:$G$63) -> 0 | G11: =SUMIF('Daily Sales'!$B$3:$B$63,'MTL OP Debtor'!B11,'Daily Sales'!$H$3:$H$63) -> 0 | I11: =E11+G11-H11 -> 0 | K11: 6 | L11: =F11 -> 0 | M11: 0 | N11: =+K11+L11-M11 -> 6
A12: 10 | B12: ပျားနက် | C12: ပခုက္ကူ | E12: 12140000 | F12: =SUMIF('Daily Sales'!$B$3:$B$63,'MTL OP Debtor'!B12,'Daily Sales'!$G$3:$G$63) -> 20 | G12: =SUMIF('Daily Sales'!$B$3:$B$63,'MTL OP Debtor'!B12,'Daily Sales'!$H$3:$H$63) -> 12140000 | H12: 18210000 | I12: =E12+G12-H12 -> 6070000 | K12: 0 | L12: =F12 -> 20 | M12: 20 | N12: =+K12+L12-M12 -> 0
A13: 11 | B13: ဦးတင်မောင် | C13: ပခုက္ကူ | E13: 6020000 | F13: =SUMIF('Daily Sales'!$B$3:$B$63,'MTL OP Debtor'!B13,'Daily Sales'!$G$3:$G$63) -> 30 | G13: =SUMIF('Daily Sales'!$B$3:$B$63,'MTL OP Debtor'!B13,'Daily Sales'!$H$3:$H$63) -> 18210000 | H13: 18210000 | I13: =E13+G13-H13 -> 6020000 | K13: 25 | L13: =F13 -> 30 | M13: 31 | N13: =+K13+L13-M13 -> 24
A14: 12 | B14: ဦးရဲမြင့် | C14: ရွှေဒါး | E14: 0 | F14: =SUMIF('Daily Sales'!$B$3:$B$63,'MTL OP Debtor'!B14,'Daily Sales'!$G$3:$G$63) -> 24 | G14: =SUMIF('Daily Sales'!$B$3:$B$63,'MTL OP Debtor'!B14,'Daily Sales'!$H$3:$H$63) -> 14040000 | H14: 14040000 | I14: =E14+G14-H14 -> 0 | K14: 20 | L14: =F14 -> 24 | M14: 24 | N14: =+K14+L14-M14 -> 20
A15: 13 | B15: ဦးသန်းဝင်း | C15: ပခုက္ကူ | E15: 0 | F15: =SUMIF('Daily Sales'!$B$3:$B$63,'MTL OP Debtor'!B15,'Daily Sales'!$G$3:$G$63) -> 10 | G15: =SUMIF('Daily Sales'!$B$3:$B$63,'MTL OP Debtor'!B15,'Daily Sales'!$H$3:$H$63) -> 6070000 | H15: 6070000 | I15: =E15+G15-H15 -> 0 | K15: 0 | L15: =F15 -> 10 | M15: 10 | N15: =+K15+L15-M15 -> 0
A16: 14 | B16: ကောင်းသန့် | C16: မိတ္ထီလာ | E16: 0 | F16: =SUMIF('Daily Sales'!$B$3:$B$63,'MTL OP Debtor'!B16,'Daily Sales'!$G$3:$G$63) -> 11 | G16: =SUMIF('Daily Sales'!$B$3:$B$63,'MTL OP Debtor'!B16,'Daily Sales'!$H$3:$H$63) -> 6435000 | H16: 5850000 | I16: =E16+G16-H16 -> 585000 | K16: 0 | L16: =F16 -> 11 | M16: 11 | N16: =+K16+L16-M16 -> 0
A17: 15 | B17: ဦးရဲတင့် | C17: ပခုက္ကူ | E17: 0 | F17: =SUMIF('Daily Sales'!$B$3:$B$63,'MTL OP Debtor'!B17,'Daily Sales'!$G$3:$G$63) -> 0 | G17: =SUMIF('Daily Sales'!$B$3:$B$63,'MTL OP Debtor'!B17,'Daily Sales'!$H$3:$H$63) -> 0 | I17: =E17+G17-H17 -> 0 | K17: 2 | L17: =F17 -> 0 | M17: 0 | N17: =+K17+L17-M17 -> 2
A18: 16 | B18: မိုးယံ | C18: ရမည်းသင်း | E18: 0 | F18: =SUMIF('Daily Sales'!$B$3:$B$63,'MTL OP Debtor'!B18,'Daily Sales'!$G$3:$G$63) -> 0 | G18: =SUMIF('Daily Sales'!$B$3:$B$63,'MTL OP Debtor'!B18,'Daily Sales'!$H$3:$H$63) -> 0 | I18: =E18+G18-H18 -> 0 | K18: 2 | L18: =F18 -> 0 | N18: =+K18+L18-M18 -> 2
A19: 17 | B19: ကိုခင်မောင်ညွန့် | C19: မိတ္ထီလာ | E19: 0 | F19: =SUMIF('Daily Sales'!$B$3:$B$63,'MTL OP Debtor'!B19,'Daily Sales'!$G$3:$G$63) -> 0 | G19: =SUMIF('Daily Sales'!$B$3:$B$63,'MTL OP Debtor'!B19,'Daily Sales'!$H$3:$H$63) -> 0 | I19: =E19+G19-H19 -> 0 | K19: 0 | L19: =F19 -> 0 | M19: 0 | N19: =+K19+L19-M19 -> 0
A20: 18 | B20: မြို့မ | C20: တောင်သာ | E20: 0 | F20: =SUMIF('Daily Sales'!$B$3:$B$63,'MTL OP Debtor'!B20,'Daily Sales'!$G$3:$G$63) -> 0 | G20: =SUMIF('Daily Sales'!$B$3:$B$63,'MTL OP Debtor'!B20,'Daily Sales'!$H$3:$H$63) -> 0 | I20: =E20+G20-H20 -> 0 | K20: 0 | L20: =F20 -> 0 | M20: 0 | N20: =+K20+L20-M20 -> 0
A21: 19 | B21: ပြည့်ဖြိုးကြွယ် | C21: မြင်းခြံ | E21: 0 | F21: =SUMIF('Daily Sales'!$B$3:$B$63,'MTL OP Debtor'!B21,'Daily Sales'!$G$3:$G$63) -> 0 | G21: =SUMIF('Daily Sales'!$B$3:$B$63,'MTL OP Debtor'!B21,'Daily Sales'!$H$3:$H$63) -> 0 | I21: =E21+G21-H21 -> 0 | K21: 0 | L21: =F21 -> 0 | M21: 0 | N21: =+K21+L21-M21 -> 0
A22: 20 | B22: မယဉ်ယဉ်အေး | C22: မလှိုင် | E22: 0 | F22: =SUMIF('Daily Sales'!$B$3:$B$63,'MTL OP Debtor'!B22,'Daily Sales'!$G$3:$G$63) -> 0 | G22: =SUMIF('Daily Sales'!$B$3:$B$63,'MTL OP Debtor'!B22,'Daily Sales'!$H$3:$H$63) -> 0 | I22: =E22+G22-H22 -> 0 | K22: 10 | L22: =F22 -> 0 | M22: 0 | N22: =+K22+L22-M22 -> 10
A23: 21 | B23: စိန် | C23: မလှိုင် | E23: 0 | F23: =SUMIF('Daily Sales'!$B$3:$B$63,'MTL OP Debtor'!B23,'Daily Sales'!$G$3:$G$63) -> 2 | G23: =SUMIF('Daily Sales'!$B$3:$B$63,'MTL OP Debtor'!B23,'Daily Sales'!$H$3:$H$63) -> 1192000 | I23: =E23+G23-H23 -> 1192000 | K23: 0 | L23: =F23 -> 2 | M23: 2 | N23: =+K23+L23-M23 -> 0
A24: 22 | B24: မိုးကျော် | C24: မလှိုင် | E24: 0 | F24: =SUMIF('Daily Sales'!$B$3:$B$63,'MTL OP Debtor'!B24,'Daily Sales'!$G$3:$G$63) -> 1 | G24: =SUMIF('Daily Sales'!$B$3:$B$63,'MTL OP Debtor'!B24,'Daily Sales'!$H$3:$H$63) -> 596000 | H24: 596000 | I24: =E24+G24-H24 -> 0 | K24: 0 | L24: =F24 -> 1 | M24: 1 | N24: =+K24+L24-M24 -> 0
A25: 23 | B25: ရွှေခြင်္သေ့ | C25: မိတ္ထီလာ | E25: 0 | F25: =SUMIF('Daily Sales'!$B$3:$B$63,'MTL OP Debtor'!B25,'Daily Sales'!$G$3:$G$63) -> 15 | G25: =SUMIF('Daily Sales'!$B$3:$B$63,'MTL OP Debtor'!B25,'Daily Sales'!$H$3:$H$63) -> 8775000 | H25: 8775000 | I25: =E25+G25-H25 -> 0 | K25: 0 | L25: =F25 -> 15 | M25: 15 | N25: =+K25+L25-M25 -> 0
A26: 24 | B26: ကိုချစ်ကို | C26: သာစည် | E26: 0 | F26: =SUMIF('Daily Sales'!$B$3:$B$63,'MTL OP Debtor'!B26,'Daily Sales'!$G$3:$G$63) -> 0 | G26: =SUMIF('Daily Sales'!$B$3:$B$63,'MTL OP Debtor'!B26,'Daily Sales'!$H$3:$H$63) -> 0 | I26: =E26+G26-H26 -> 0 | K26: 0 | L26: =F26 -> 0 | M26: 0 | N26: =+K26+L26-M26 -> 0
A27: 25 | B27: ဒေါ်ခင်စန်းမြင့် | C27: ကျောက်ပန်းတောင်း | E27: 0 | F27: =SUMIF('Daily Sales'!$B$3:$B$63,'MTL OP Debtor'!B27,'Daily Sales'!$G$3:$G$63) -> 0 | G27: =SUMIF('Daily Sales'!$B$3:$B$63,'MTL OP Debtor'!B27,'Daily Sales'!$H$3:$H$63) -> 0 | I27: =E27+G27-H27 -> 0 | K27: 1 | L27: =F27 -> 0 | N27: =+K27+L27-M27 -> 1
A28: 26 | B28: မမာမာအုန်း | C28: မိတ္ထီလာ | E28: 0 | F28: =SUMIF('Daily Sales'!$B$3:$B$63,'MTL OP Debtor'!B28,'Daily Sales'!$G$3:$G$63) -> 0 | G28: =SUMIF('Daily Sales'!$B$3:$B$63,'MTL OP Debtor'!B28,'Daily Sales'!$H$3:$H$63) -> 0 | I28: =E28+G28-H28 -> 0 | K28: 14 | L28: =F28 -> 0 | M28: 0 | N28: =+K28+L28-M28 -> 14
A29: 27 | B29: ဦးစိုးဝင်း | C29: ကျောက်ပန်းတောင်း | E29: 0 | F29: =SUMIF('Daily Sales'!$B$3:$B$63,'MTL OP Debtor'!B29,'Daily Sales'!$G$3:$G$63) -> 0 | G29: =SUMIF('Daily Sales'!$B$3:$B$63,'MTL OP Debtor'!B29,'Daily Sales'!$H$3:$H$63) -> 0 | I29: =E29+G29-H29 -> 0 | K29: 0 | L29: =F29 -> 0 | M29: 0 | N29: =+K29+L29-M29 -> 0
A30: 28 | B30: စံချိန် | C30: ရမည်းသင်း | E30: 0 | F30: =SUMIF('Daily Sales'!$B$3:$B$63,'MTL OP Debtor'!B30,'Daily Sales'!$G$3:$G$63) -> 0 | G30: =SUMIF('Daily Sales'!$B$3:$B$63,'MTL OP Debtor'!B30,'Daily Sales'!$H$3:$H$63) -> 0 | I30: =E30+G30-H30 -> 0 | K30: 0 | L30: =F30 -> 0 | M30: 0 | N30: =+K30+L30-M30 -> 0
A31: 29 | B31: ဦးမြင့်ဆွေ | C31: ပခုက္ကူ | E31: 12140000 | F31: =SUMIF('Daily Sales'!$B$3:$B$63,'MTL OP Debtor'!B31,'Daily Sales'!$G$3:$G$63) -> 0 | G31: =SUMIF('Daily Sales'!$B$3:$B$63,'MTL OP Debtor'!B31,'Daily Sales'!$H$3:$H$63) -> 0 | H31: 12140000 | I31: =E31+G31-H31 -> 0 | K31: 0 | L31: =F31 -> 0 | M31: 0 | N31: =+K31+L31-M31 -> 0
A32: 30 | B32: ရွှေတောင် | C32: ပုဂံ | E32: 0 | F32: =SUMIF('Daily Sales'!$B$3:$B$63,'MTL OP Debtor'!B32,'Daily Sales'!$G$3:$G$63) -> 0 | G32: =SUMIF('Daily Sales'!$B$3:$B$63,'MTL OP Debtor'!B32,'Daily Sales'!$H$3:$H$63) -> 0 | I32: =E32+G32-H32 -> 0 | K32: 0 | L32: =F32 -> 0 | M32: 0 | N32: =+K32+L32-M32 -> 0
A33: 31 | B33: ကျော်ကြား | C33: မလှိုင် | E33: 0 | F33: =SUMIF('Daily Sales'!$B$3:$B$63,'MTL OP Debtor'!B33,'Daily Sales'!$G$3:$G$63) -> 5 | G33: =SUMIF('Daily Sales'!$B$3:$B$63,'MTL OP Debtor'!B33,'Daily Sales'!$H$3:$H$63) -> 2955000 | H33: 2955000 | I33: =E33+G33-H33 -> 0 | K33: 1 | L33: =F33 -> 5 | M33: 6 | N33: =+K33+L33-M33 -> 0
A34: 32 | B34: ဘိုရှယ် | C34: မလှိုင် | E34: 0 | F34: =SUMIF('Daily Sales'!$B$3:$B$63,'MTL OP Debtor'!B34,'Daily Sales'!$G$3:$G$63) -> 7 | G34: =SUMIF('Daily Sales'!$B$3:$B$63,'MTL OP Debtor'!B34,'Daily Sales'!$H$3:$H$63) -> 4137000 | H34: 2364000 | I34: =E34+G34-H34 -> 1773000 | K34: 0 | L34: =F34 -> 7 | M34: 7 | N34: =+K34+L34-M34 -> 0
A35: 33 | B35: ‌ရွှေကမ္ဘာ | C35: မိတ္ထီလာ | E35: 0 | F35: =SUMIF('Daily Sales'!$B$3:$B$63,'MTL OP Debtor'!B35,'Daily Sales'!$G$3:$G$63) -> 0 | G35: =SUMIF('Daily Sales'!$B$3:$B$63,'MTL OP Debtor'!B35,'Daily Sales'!$H$3:$H$63) -> 0 | I35: =E35+G35-H35 -> 0 | K35: 0 | L35: =F35 -> 0 | M35: 0 | N35: =+K35+L35-M35 -> 0
A36: 34 | B36: ရတနာ | C36: ပုဂံ | E36: 0 | F36: =SUMIF('Daily Sales'!$B$3:$B$63,'MTL OP Debtor'!B36,'Daily Sales'!$G$3:$G$63) -> 0 | G36: =SUMIF('Daily Sales'!$B$3:$B$63,'MTL OP Debtor'!B36,'Daily Sales'!$H$3:$H$63) -> 0 | I36: =E36+G36-H36 -> 0 | K36: 6 | L36: =F36 -> 0 | N36: =+K36+L36-M36 -> 6
A37: 35 | B37: 90 | C37: ပခုက္ကူ | E37: 2600000 | F37: =SUMIF('Daily Sales'!$B$3:$B$63,'MTL OP Debtor'!B37,'Daily Sales'!$G$3:$G$63) -> 10 | G37: =SUMIF('Daily Sales'!$B$3:$B$63,'MTL OP Debtor'!B37,'Daily Sales'!$H$3:$H$63) -> 6100000 | H37: 8700000 | I37: =E37+G37-H37 -> 0 | K37: 15 | L37: =F37 -> 10 | M37: 4 | N37: =+K37+L37-M37 -> 21
A38: 36 | B38: A1 | C38: ပုဂံ | E38: 0 | F38: =SUMIF('Daily Sales'!$B$3:$B$63,'MTL OP Debtor'!B38,'Daily Sales'!$G$3:$G$63) -> 0 | G38: =SUMIF('Daily Sales'!$B$3:$B$63,'MTL OP Debtor'!B38,'Daily Sales'!$H$3:$H$63) -> 0 | I38: =E38+G38-H38 -> 0 | K38: 5 | L38: =F38 -> 0 | N38: =+K38+L38-M38 -> 5
E39: =SUM(E3:E38) -> 148808931 | F39: =SUM(F3:F38) -> 349 | G39: =SUM(G3:G38) -> 204260000 | H39: =SUM(H3:H38) -> 212980205 | I39: =SUM(I3:I38) -> 140088726 | K39: =SUM(K3:K38) -> 283 | L39: =SUM(L3:L38) -> 349 | M39: =SUM(M3:M38) -> 345 | N39: =SUM(N3:N38) -> 287
A42: 2026- February
...

Sheet Daily Sales
A1: Daily Sale -January
A2: Date | B2: အမည် | C2: မြို့နယ် | D2: Vr No | E2: List | F2: ရောင်းဈေး +ကားခ | G2: ကုန်ရောင်း (လုံး) | H2: ကုန်ရောင်း (ကျပ်)
A3: 46024 | B3: ရွှေမြင်း | C3: =VLOOKUP(B3,'Sales Price'!B:C,2,0) -> မိတ္ထီလာ | E3: Credit Sale | F3: 575000 | G3: 5 | H3: =F3*G3 -> 2875000 | O3: ကျပ် | P3: လုံး
A4: 46024 | B4: ဦးဝင်းနိုင် | C4: =VLOOKUP(B4,'Sales Price'!B:C,2,0) -> ဝမ်းတွင်း | E4: Credit Sale | F4: 585000 | G4: 3 | H4: =F4*G4 -> 1755000 | O4: 575000 | P4: =SUMIF(F3:F63,O4,G3:G63) -> 175
A5: 46025 | B5: ဘိုရှယ် | C5: =VLOOKUP(B5,'Sales Price'!B:C,2,0) -> မလှိုင် | E5: Credit Sale | F5: 591000 | G5: 3 | H5: =F5*G5 -> 1773000 | O5: 585000 | P5: =SUMIF(F4:F64,O5,G4:G64) -> 69
A6: 46025 | B6: ဦးဝင်းနိုင် | C6: =VLOOKUP(B6,'Sales Price'!B:C,2,0) -> ဝမ်းတွင်း | E6: Credit Sale | F6: 585000 | G6: 1 | H6: =F6*G6 -> 585000 | O6: 591000 | P6: =SUMIF(F5:F65,O6,G5:G65) -> 22
A7: 46025 | B7: ကောင်းသန့် | C7: =VLOOKUP(B7,'Sales Price'!B:C,2,0) -> မိတ္ထီလာ | E7: Credit Sale | F7: 585000 | G7: 1 | H7: =F7*G7 -> 585000 | O7: 596000 | P7: =SUMIF(F6:F66,O7,G6:G66) -> 13
A8: 46025 | B8: ဦးအေးခင်မောင် | C8: =VLOOKUP(B8,'Sales Price'!B:C,2,0) -> မိတ္ထီလာ | E8: Credit Sale | F8: 585000 | G8: 1 | H8: =F8*G8 -> 585000 | O8: 600000 | P8: =SUMIF(F7:F67,O8,G7:G67) -> 0
A9: 46025 | B9: ရွှေမြင်း | C9: =VLOOKUP(B9,'Sales Price'!B:C,2,0) -> မိတ္ထီလာ | E9: Credit Sale | F9: 575000 | G9: 10 | H9: =F9*G9 -> 5750000 | O9: 607000 | P9: =SUMIF(F8:F68,O9,G8:G68) -> 60
A10: 46027 | B10: ဦးရဲမြင့် | C10: =VLOOKUP(B10,'Sales Price'!B:C,2,0) -> ရွှေဒါး | E10: Cash Sale | F10: 585000 | G10: 9 | H10: =F10*G10 -> 5265000 | O10: 610000 | P10: =SUMIF(F9:F69,O10,G9:G69) -> 10
A11: 46027 | B11: ရွှေမြင်း | C11: =VLOOKUP(B11,'Sales Price'!B:C,2,0) -> မိတ္ထီလာ | E11: Credit Sale | F11: 575000 | G11: 5 | H11: =F11*G11 -> 2875000 | O11: 595000 | P11: =SUMIF(F10:F70,O11,G10:G70) -> 0
A12: 46027 | B12: ရွှေခြင်္သေ့ | C12: =VLOOKUP(B12,'Sales Price'!B:C,2,0) -> မိတ္ထီလာ | E12: Cash Sale | F12: 585000 | G12: 3 | H12: =F12*G12 -> 1755000
A13: 46028 | B13: ဦးသိန်းစိုး | C13: =VLOOKUP(B13,'Sales Price'!B:C,2,0) -> ကျောက်ပန်းတောင်း | E13: Credit Sale | F13: 591000 | G13: 5 | H13: =F13*G13 -> 2955000 | P13: =SUM(P4:P12) -> 349
A14: 46028 | B14: ကောင်းသန့် | C14: =VLOOKUP(B14,'Sales Price'!B:C,2,0) -> မိတ္ထီလာ | E14: Credit Sale | F14: 585000 | G14: 1 | H14: =F14*G14 -> 585000 | P14: =SUMPRODUCT(O4:O12,P4:P12) -> 204260000
A15: 46028 | B15: ရွှေမြင်း | C15: =VLOOKUP(B15,'Sales Price'!B:C,2,0) -> မိတ္ထီလာ | E15: Credit Sale | F15: 575000 | G15: 15 | H15: =F15*G15 -> 8625000
A16: 46029 | B16: ဦးတင်မောင် | C16: =VLOOKUP(B16,'Sales Price'!B:C,2,0) -> ပခုက္ကူ | E16: Credit Sale | F16: 607000 | G16: 20 | H16: =F16*G16 -> 12140000
A17: 46029 | B17: ပျားနက် | C17: =VLOOKUP(B17,'Sales Price'!B:C,2,0) -> ပခုက္ကူ | E17: Credit Sale | F17: 607000 | G17: 10 | H17: =F17*G17 -> 6070000
A18: 46029 | B18: ဦးသန်းဝင်း | C18: =VLOOKUP(B18,'Sales Price'!B:C,2,0) -> ပခုက္ကူ | E18: Credit Sale | F18: 607000 | G18: 10 | H18: =F18*G18 -> 6070000
A19: 46029 | B19: မိုးကျော် | C19: =VLOOKUP(B19,'Sales Price'!B:C,2,0) -> မလှိုင် | E19: Credit Sale | F19: 596000 | G19: 1 | H19: =F19*G19 -> 596000
A20: 46029 | B20: စိန် | C20: =VLOOKUP(B20,'Sales Price'!B:C,2,0) -> မလှိုင် | E20: Credit Sale | F20: 596000 | G20: 2 | H20: =F20*G20 -> 1192000
A21: 46029 | B21: ဦးဝင်းနိုင် | C21: =VLOOKUP(B21,'Sales Price'!B:C,2,0) -> ဝမ်းတွင်း | E21: Credit Sale | F21: 585000 | G21: 5 | H21: =F21*G21 -> 2925000
A22: 46030 | B22: ကောင်းသန့် | C22: =VLOOKUP(B22,'Sales Price'!B:C,2,0) -> မိတ္ထီလာ | E22: Credit Sale | F22: 585000 | G22: 1 | H22: =F22*G22 -> 585000
A23: 46030 | B23: ရွှေမြင်း | C23: =VLOOKUP(B23,'Sales Price'!B:C,2,0) -> မိတ္ထီလာ | E23: Credit Sale | F23: 575000 | G23: 5 | H23: =F23*G23 -> 2875000
A24: 46031 | B24: ရွှေမြင်း | C24: =VLOOKUP(B24,'Sales Price'!B:C,2,0) -> မိတ္ထီလာ | E24: Credit Sale | F24: 575000 | G24: 15 | H24: =F24*G24 -> 8625000
A25: 46031 | B25: ကောင်းသန့် | C25: =VLOOKUP(B25,'Sales Price'!B:C,2,0) -> မိတ္ထီလာ | E25: Credit Sale | F25: 585000 | G25: 1 | H25: =F25*G25 -> 585000
A26: 46032 | B26: ရွှေမြင်း | C26: =VLOOKUP(B26,'Sales Price'!B:C,2,0) -> မိတ္ထီလာ | E26: Credit Sale | F26: 575000 | G26: 10 | H26: =F26*G26 -> 5750000
... A59: 46052 | B59: ပျားနက် | C59: =VLOOKUP(B59,'Sales Price'!B:C,2,0) -> ပခုက္ကူ | E59: Credit Sale | F59: 607000 | G59: 10 | H59: =F59*G59 -> 6070000
A60: 46052 | B60: 90 | C60: =VLOOKUP(B60,'Sales Price'!B:C,2,0) -> ပခုက္ကူ | E60: Credit Sale | F60: 610000 | G60: 10 | H60: =F60*G60 -> 6100000
A61: 46052 | B61: ဦးတင်မောင် | C61: =VLOOKUP(B61,'Sales Price'!B:C,2,0) -> ပခုက္ကူ | E61: Credit Sale | F61: 607000 | G61: 10 | H61: =F61*G61 -> 6070000
A62: 46052 | B62: ရွှေမြင်း | C62: =VLOOKUP(B62,'Sales Price'!B:C,2,0) -> မိတ္ထီလာ | E62: Credit Sale | F62: 575000 | G62: 10 | H62: =F62*G62 -> 5750000
A63: 46053 | B63: ကောင်းသန့် | C63: =VLOOKUP(B63,'Sales Price'!B:C,2,0) -> မိတ္ထီလာ | E63: Credit Sale | F63: 585000 | G63: 1 | H63: =F63*G63 -> 585000
G64: =SUBTOTAL(9,G3:G63) -> 349 | H64: =SUBTOTAL(9,H3:H63) -> 204260000
A67: Daily Sale -February
A68: Date | B68: အမည် | C68: မြို့နယ် | D68: Vr No | E68: List | F68: ရောင်းဈေး +ကားခ | G68: ကုန်ရောင်း (လုံး) | H68: ကုန်ရောင်း (ကျပ်)
A69: 46055 | B69: ဦးဝင်းနိုင် | C69: =VLOOKUP(B69,'Sales Price'!B:C,2,0) -> ဝမ်းတွင်း | E69: Credit Sale | F69: 585000 | G69: 3 | H69: =F69*G69 -> 1755000 | O69: ကျပ် | P69: လုံး
A70: 46056 | B70: ရွှေမြင်း | C70: =VLOOKUP(B70,'Sales Price'!B:C,2,0) -> မိတ္ထီလာ | E70: Credit Sale | F70: 575000 | G70: 6 | H70: =F70*G70 -> 3450000 | O70: 575000 | P70: =SUMIF($F$69:$F$101,O70,$G$69:$G$101) -> 66
A71: 46057 | B71: ရွှေမြင်း | C71: =VLOOKUP(B71,'Sales Price'!B:C,2,0) -> မိတ္ထီလာ | E71: Credit Sale | F71: 575000 | G71: 5 | H71: =F71*G71 -> 2875000 | O71: 585000 | P71: =SUMIF($F$69:$F$101,O71,$G$69:$G$101) -> 37
A72: 46057 | B72: ရွှေခြင်္သေ့ | C72: =VLOOKUP(B72,'Sales Price'!B:C,2,0) -> မိတ္ထီလာ | E72: Cash Sale | F72: 585000 | G72: 3 | H72: =F72*G72 -> 1755000 | O72: 591000 | P72: =SUMIF($F$69:$F$101,O72,$G$69:$G$101) -> 13
A73: 46058 | B73: ရွှေမြင်း | C73: =VLOOKUP(B73,'Sales Price'!B:C,2,0) -> မိတ္ထီလာ | E73: Credit Sale | F73: 575000 | G73: 10 | H73: =F73*G73 -> 5750000 | O73: 596000 | P73: =SUMIF($F$69:$F$101,O73,$G$69:$G$101) -> 0
A74: 46059 | B74: ဦးရဲမြင့် | C74: =VLOOKUP(B74,'Sales Price'!B:C,2,0) -> ရွှေဒါး | E74: Credit Sale | F74: 585000 | G74: 3 | H74: =F74*G74 -> 1755000 | O74: 600000 | P74: =SUMIF($F$69:$F$101,O74,$G$69:$G$101) -> 5
...
