Workbook

Sheet Sales Price
A1: စဉ် | B1: အမည် | C1: မြို့နယ် | D1: ရောင်းဈေး | E1: ကုန်ရောင်း အမျိုးအစား
A2: 1 | B2: ပြည့်လျှံ | C2: ဈေးကြို | D2: 590000 | E2: Cash Sale
A3: 2 | B3: ကိုထွန်းနိုင် | C3: ရေး | D3: 610000 | E3: Credit Sale
A4: 3 | B4: ကိုမျိုးအောင် | C4: ဈေးကြို | D4: 575000 | E4: Advance Sale
A5: 4 | B5: ဒေါ်ထွန်းမေ | C5: ဈေးကြို | D5: 605000
A6: 5 | B6: နော်သင်းစုလှိုင် | C6: ကျုံဒိုး | D6: 600000
A7: 6 | B7: ရွှေပင်လယ် | C7: အစင် | D7: 615000
A8: 7 | B8: ကိုအာနိုး | C8: ရေး | D8: 615000
A9: 8 | B9: မချော | C9: ဇီးဖြူသောင် | D9: 605000
A10: 9 | B10: ဝင်းအောင်ရွှေ | C10: ဇာသပြင် | D10: 590000
A11: 10 | B11: ဇော်လင်းမြတ် | C11: ဇီးဖြူသောင် | D11: 615000
A12: 11 | B12: ဦးဝင်းမြင့် | C12: ဖက်တန်း | D12: 610000
A13: 12 | B13: ပျားထန်းစက်ရုံ | C13: သံလွင်ဥယျာဉ် | D13: 590000
A14: 13 | B14: မစန္ဒာ | C14: ဇာသပြင် | D14: 620000
A15: 14 | B15: ကိုမောင်+မသူဇာ | C15: လမိုင်း | D15: 615000
A16: 15 | B16: ဦးမင်းလွင် | C16: ဈေးကြီး | D16: 595000
... A21: 20 | B21: ၀ါးအိမ် | C21: သိမ်ဇရပ် | D21: 625000

Sheet MLM Sales Summary
A1: OP Sales Summary for MLM-2024 | S1: OP Sales Summary for MLM-2025 | AF1: OP Sales Summary for MLM-2026
A2: No | B2: အမည် | C2: မြို့နယ် | D2: Type | E2: Jan | F2: Feb | G2: Mar | H2: Apr | I2: May | J2: June | K2: July | L2: August | M2: Sep | N2: Oct | O2: Nov | P2: Dec | Q2: Total | S2: Jan | T2: Feb | U2: Mar | V2: Apr | W2: May | X2: June | Y2: July | Z2: August | AA2: Sep | AB2: Oct | AC2: Nov | AD2: Dec | AE2: Total | AG2: Jan | AH2: Feb | AI2: Mar | AJ2: Apr | AK2: May | AL2: June | AM2: July | AN2: August | AO2: Sep | AP2: Oct | AQ2: Nov | AR2: Dec | AS2: Total
A3: 1 | B3: ပြည့်လျှံ | C3: ဈေးကြို | D3: Cash Sales | J3: 25 | L3: 50 | M3: 20 | N3: 25 | O3: 30 | P3: 10 | Q3: =SUM(E3:P3) -> 160 | S3: 23 | U3: 5 | V3: 10 | W3: 50 | X3: 50 | AA3: 100 | AB3: 100 | AD3: 100 | AE3: =SUM(S3:AD3) -> 438 | AS3: =SUM(AG3:AR3) -> 0
A4: 2 | B4: ကိုထွန်းနိုင် | C4: ရေး | D4: Cash Sales | Q4: =SUM(E4:P4) -> 0 | S4: 1 | T4: 16 | U4: 10 | V4: 4 | W4: 7 | X4: 3 | Y4: 2 | Z4: 4 | AA4: 2 | AB4: 7 | AE4: =SUM(S4:AD4) -> 56 | AG4: 2 | AH4: 4 | AI4: 3 | AS4: =SUM(AG4:AR4) -> 9
A5: 3 | B5: ကိုမျိုးအောင် | C5: ဈေးကြို | D5: Cash Sales | O5: 28 | P5: 20 | Q5: =SUM(E5:P5) -> 48 | S5: 18 | T5: 21 | U5: 23 | V5: 17 | W5: 22 | X5: 31 | Y5: 16 | Z5: 18 | AA5: 22 | AB5: 20 | AC5: 19 | AD5: 16 | AE5: =SUM(S5:AD5) -> 243 | AG5: 16 | AH5: 15 | AI5: 5 | AS5: =SUM(AG5:AR5) -> 36
A6: 4 | B6: ဒေါ်ထွန်းမေ | C6: ဈေးကြို | D6: Cash Sales | M6: 10 | O6: 5 | Q6: =SUM(E6:P6) -> 15 | W6: 15 | AE6: =SUM(S6:AD6) -> 15 | AS6: =SUM(AG6:AR6) -> 0
A7: 5 | B7: နော်သင်းစုလှိုင် | C7: ကျုံဒိုး | D7: Cash Sales | I7: 5 | L7: 72 | M7: 150 | N7: 170 | O7: 130 | P7: 180 | Q7: =SUM(E7:P7) -> 707 | S7: 185 | T7: 140 | U7: 135 | V7: 120 | W7: 15 | Y7: 15 | Z7: 75 | AA7: 75 | AB7: 120 | AC7: 60 | AD7: 78 | AE7: =SUM(S7:AD7) -> 1018 | AG7: 75 | AH7: 60 | AI7: 15 | AS7: =SUM(AG7:AR7) -> 150
A8: 6 | B8: ကိုအာနိုး | C8: ရေး | D8: Cash Sales | L8: 14 | N8: 3 | O8: 2 | P8: 12 | Q8: =SUM(E8:P8) -> 31 | S8: 16 | T8: 9 | V8: 2 | W8: 3 | X8: 2 | Z8: 2 | AA8: 2 | AD8: 1 | AE8: =SUM(S8:AD8) -> 37 | AS8: =SUM(AG8:AR8) -> 0
A9: 7 | B9: မချော | C9: ဇီးဖြူသောင် | D9: Cash Sales | I9: 7 | M9: 4 | Q9: =SUM(E9:P9) -> 11 | S9: 5 | U9: 5 | W9: 5 | X9: 5 | Z9: 5 | AA9: 7 | AE9: =SUM(S9:AD9) -> 32 | AG9: 5 | AH9: 5 | AI9: 5 | AS9: =SUM(AG9:AR9) -> 15
A10: 8 | B10: ဝင်းအောင်ရွှေ | C10: ဇာသပြင် | D10: Cash Sales | J10: 1 | M10: 1 | O10: 1 | P10: 1 | Q10: =SUM(E10:P10) -> 4 | T10: 2 | AA10: 1 | AB10: 1 | AD10: 2 | AE10: =SUM(S10:AD10) -> 6 | AG10: 1 | AH10: 1 | AI10: 1 | AS10: =SUM(AG10:AR10) -> 3
A11: 9 | B11: ဇော်လင်းမြတ် | C11: ဇီးဖြူသောင် | D11: Cash Sales | I11: 2 | J11: 2 | K11: 2 | L11: 3 | M11: 4 | O11: 4 | P11: 2 | Q11: =SUM(E11:P11) -> 19 | T11: 2 | U11: 7 | V11: 5 | W11: 4 | X11: 1 | Y11: 1 | Z11: 2 | AA11: 1 | AB11: 1 | AD11: 2 | AE11: =SUM(S11:AD11) -> 26 | AG11: 4 | AH11: 2 | AI11: 2 | AS11: =SUM(AG11:AR11) -> 8
A12: 10 | B12: ဦးဝင်းမြင့် | C12: ဖက်တန်း | D12: Cash Sales | I12: 9 | J12: 5 | K12: 7 | L12: 3 | M12: 6 | N12: 6 | O12: 8 | P12: 8 | Q12: =SUM(E12:P12) -> 52 | S12: 5 | T12: 7 | U12: 6 | V12: 9 | W12: 9 | X12: 7 | Y12: 6 | Z12: 8 | AA12: 5 | AB12: 6 | AC12: 3 | AD12: 5 | AE12: =SUM(S12:AD12) -> 76 | AG12: 4 | AH12: 4 | AI12: 4 | AS12: =SUM(AG12:AR12) -> 12
A13: 11 | B13: ပျားထန်းစက်ရုံ | C13: သံလွင်ဥယျာဉ် | D13: Cash Sales | I13: 100 | J13: 20 | Q13: =SUM(E13:P13) -> 120 | AE13: =SUM(S13:AD13) -> 0 | AS13: =SUM(AG13:AR13) -> 0
A14: 12 | B14: မစန္ဒာ | C14: ဇာသပြင် | D14: Cash Sales | J14: 1 | Q14: =SUM(E14:P14) -> 1 | AE14: =SUM(S14:AD14) -> 0 | AS14: =SUM(AG14:AR14) -> 0
A15: 13 | B15: ကိုမောင်+မသူဇာ | C15: လမိုင်း | D15: Cash Sales | J15: 1 | Q15: =SUM(E15:P15) -> 1 | AE15: =SUM(S15:AD15) -> 0 | AG15: 2 | AH15: 2 | AI15: 5 | AS15: =SUM(AG15:AR15) -> 9
A16: 14 | B16: ရွှေပင်လယ် | C16: အစင် | D16: Cash Sales | L16: 2 | P16: 2 | Q16: =SUM(E16:P16) -> 4 | AE16: =SUM(S16:AD16) -> 0 | AS16: =SUM(AG16:AR16) -> 0
A17: 15 | B17: ရွှေသစ်ထွန်း | C17: မြိတ် | D17: Cash Sales | M17: 10 | P17: 10 | Q17: =SUM(E17:P17) -> 20 | AE17: =SUM(S17:AD17) -> 0 | AS17: =SUM(AG17:AR17) -> 0
A18: 16 | B18: ဦးမင်းလွင် | C18: ဈေးကြီး | D18: Cash Sales | O18: 2 | P18: 10 | Q18: =SUM(E18:P18) -> 12 | S18: 37 | T18: 53 | U18: 19 | V18: 53 | W18: 57 | X18: 69 | Y18: 52 | Z18: 46 | AA18: 22 | AB18: 44 | AC18: 14 | AE18: =SUM(S18:AD18) -> 466 | AG18: 43 | AH18: 34 | AI18: 23 | AS18: =SUM(AG18:AR18) -> 100
A19: 17 | B19: ကိုဘာဘူ | C19: ဇာသပြင် | D19: Cash Sales | P19: 1 | Q19: =SUM(E19:P19) -> 1 | AE19: =SUM(S19:AD19) -> 0 | AS19: =SUM(AG19:AR19) -> 0
A20: 18 | B20: အမိရင်ခွင် | C20: မုဒွန်း | D20: Cash Sales | Q20: =SUM(E20:P20) -> 0 | T20: 1 | AE20: =SUM(S20:AD20) -> 1 | AS20: =SUM(AG20:AR20) -> 0
A21: 19 | B21: ဦးအောင်မြင့် | C21: ကမာမို | D21: Cash Sales | Q21: =SUM(E21:P21) -> 0 | T21: 1 | X21: 1 | AE21: =SUM(S21:AD21) -> 2 | AS21: =SUM(AG21:AR21) -> 0
A22: 20 | B22: ကိုချမ်းသာ | C22: မုဒုံ | Y22: 1 | Z22: 1 | AB22: 1 | AD22: 1 | AE22: =SUM(S22:AD22) -> 4 | AG22: 1 | AS22: =SUM(AG22:AR22) -> 1
A23: 21 | B23: ၀ါးအိမ် | C23: သိမ်ဇရပ် | AD23: 3 | AE23: =SUM(S23:AD23) -> 3 | AS23: =SUM(AG23:AR23) -> 0
B24: Total Outlet | E24: =SUM(E3:E22) -> 0 | F24: =SUM(F3:F22) -> 0 | G24: =SUM(G3:G22) -> 0 | H24: =SUM(H3:H22) -> 0 | I24: =SUM(I3:I22) -> 123 | J24: =SUM(J3:J22) -> 55 | K24: =SUM(K3:K22) -> 9 | L24: =SUM(L3:L22) -> 144 | ... Q24: =SUM(Q3:Q22) -> 1206 | S24: =SUM(S3:S22) -> 290 | T24: =SUM(T3:T22) -> 252 | U24: =SUM(U3:U22) -> 210 | V24: =SUM(V3:V22) -> 220 | W24: =SUM(W3:W22) -> 187 | X24: =SUM(X3:X23) -> 169 | Y24: =SUM(Y3:Y23) -> 93 | Z24: =SUM(Z3:Z23) -> 161 | AA24: =SUM(AA3:AA23) -> 237 | AB24: =SUM(AB3:AB23) -> 300 | AC24: =SUM(AC3:AC23) -> 96 | AD24: =SUM(AD3:AD23) -> 208 | AE24: =SUM(AE3:AE23) -> 2423 | AG24: =SUM(AG3:AG23) -> 153 | AH24: =SUM(AH3:AH23) -> 127 | AI24: =SUM(AI3:AI23) -> 63 | AJ24: =SUM(AJ3:AJ23) -> 0 | AK24: =SUM(AK3:AK23) -> 0 | AL24: =SUM(AL3:AL23) -> 0 | AM24: =SUM(AM3:AM23) -> 0 | AN24: =SUM(AN3:AN23) -> 0 | ... AS24: =SUM(AS3:AS23) -> 343
B25: New Outlet | Q25: =SUM(E25:P25) -> 0 | AE25: =SUM(S25:AD25) -> 0 | AS25: =SUM(AG25:AR25) -> 0
B26: Total | C26: MLM | E26: =SUM(E3:E21) -> 0 | F26: =SUM(F3:F11) -> 0 | G26: =SUM(G3:G11) -> 0 | H26: =SUM(H3:H11) -> 0 | I26: =SUM(I3:I13) -> 123 | J26: =SUM(J3:J15) -> 55 | K26: =SUM(K3:K22) -> 9 | L26: =SUM(L3:L22) -> 144 | M26: =SUM(M3:M22) -> 205 | N26: =SUM(N3:N22) -> 204 | O26: =SUM(O3:O22) -> 210 | P26: =SUM(P3:P22) -> 256 | Q26: =SUM(E26:P26) -> 1206 | S26: =SUM(S3:S21) -> 290 | T26: =SUM(T3:T21) -> 252 | U26: =SUM(U3:U21) -> 210 | V26: =SUM(V3:V22) -> 220 | W26: =SUM(W3:W21) -> 187 | X26: =SUM(X3:X23) -> 169 | Y26: =SUM(Y3:Y23) -> 93 | Z26: =SUM(Z3:Z23) -> 161 | AA26: =SUM(AA3:AA23) -> 237 | AB26: =SUM(AB3:AB23) -> 300 | AC26: =SUM(AC3:AC23) -> 96 | AD26: =SUM(AD3:AD23) -> 208 | AE26: =SUM(AE3:AE23) -> 2423 | AG26: =SUM(AG3:AG23) -> 153 | AH26: =SUM(AH3:AH23) -> 127 | AI26: =SUM(AI3:AI23) -> 63 | AJ26: =SUM(AJ3:AJ23) -> 0 | AK26: =SUM(AK3:AK23) -> 0 | AL26: =SUM(AL3:AL23) -> 0 | AM26: =SUM(AM3:AM23) -> 0 | AN26: =SUM(AN3:AN23) -> 0 | ... AR26: =SUM(AR3:AR23) -> 0 | AS26: =SUM(AG26:AR26) -> 343
AA29: .

Sheet MLM OP Debtors
A1: စဉ် | B1: အမည် | C1: မြို့နယ် | D1: ရောင်းဈေး | E1: စာရင်းဖွင့် | F1: ကုန်ရောင်း လုံးရေ | G1: ကုန်ရောင်း ရငွေ | H1: သွင်းငွေ | I1: ကျန်ငွေ | K1: စာရင်းဖွင့် ကော်ခွံ | L1: ကုန်ရောင်း ကော်ခွံ | M1: ပြန်ရ ကော်ခွံ | N1: စာရင်းပိတ် ကော်ခွံ
A2: 1 | B2: ပြည့်လျှံ | C2: ဈေးကြို | D2: 590000 | F2: =SUMIF('Daily Sale'!B:B,'MLM OP Debtors'!B2,'Daily Sale'!G:G) -> 0 | G2: =SUMIF('Daily Sale'!B:B,'MLM OP Debtors'!B2,'Daily Sale'!H:H) -> 0 | H2: =F2*D2 -> 0 | I2: =E2+G2-H2 -> 0 | L2: =+F2 -> 0 | N2: =+K2+L2-M2 -> 0
A3: 2 | B3: ကိုထွန်းနိုင် | C3: ရေး | D3: 610000 | F3: =SUMIF('Daily Sale'!B:B,'MLM OP Debtors'!B3,'Daily Sale'!G:G) -> 3 | G3: =SUMIF('Daily Sale'!B:B,'MLM OP Debtors'!B3,'Daily Sale'!H:H) -> 1830000 | H3: 610000 | I3: =E3+G3-H3 -> 1220000 | L3: =+F3 -> 3 | N3: =+K3+L3-M3 -> 3
A4: 3 | B4: ကိုမျိုးအောင် | C4: ဈေးကြို | D4: 575000 | F4: =SUMIF('Daily Sale'!B:B,'MLM OP Debtors'!B4,'Daily Sale'!G:G) -> 5 | G4: =SUMIF('Daily Sale'!B:B,'MLM OP Debtors'!B4,'Daily Sale'!H:H) -> 2875000 | H4: =F4*D4 -> 2875000 | I4: =E4+G4-H4 -> 0 | L4: =+F4 -> 5 | M4: 5 | N4: =+K4+L4-M4 -> 0
A5: 4 | B5: ဒေါ်ထွန်းမေ | C5: ဈေးကြို | D5: 605000 | F5: =SUMIF('Daily Sale'!B:B,'MLM OP Debtors'!B5,'Daily Sale'!G:G) -> 0 | G5: =SUMIF('Daily Sale'!B:B,'MLM OP Debtors'!B5,'Daily Sale'!H:H) -> 0 | H5: =F5*D5 -> 0 | I5: =E5+G5-H5 -> 0 | L5: =+F5 -> 0 | N5: =+K5+L5-M5 -> 0
A6: 5 | B6: နော်သင်းစုလှိုင် | C6: ကျုံဒိုး | D6: 600000 | F6: =SUMIF('Daily Sale'!B:B,'MLM OP Debtors'!B6,'Daily Sale'!G:G) -> 15 | G6: =SUMIF('Daily Sale'!B:B,'MLM OP Debtors'!B6,'Daily Sale'!H:H) -> 9000000 | H6: =F6*D6 -> 9000000 | I6: =E6+G6-H6 -> 0 | L6: =+F6 -> 15 | N6: =+K6+L6-M6 -> 15
A7: 6 | B7: ရွှေပင်လယ် | C7: အစင် | D7: 615000 | F7: =SUMIF('Daily Sale'!B:B,'MLM OP Debtors'!B7,'Daily Sale'!G:G) -> 0 | G7: =SUMIF('Daily Sale'!B:B,'MLM OP Debtors'!B7,'Daily Sale'!H:H) -> 0 | H7: =F7*D7 -> 0 | I7: =E7+G7-H7 -> 0 | L7: =+F7 -> 0 | N7: =+K7+L7-M7 -> 0
A8: 7 | B8: ကိုအာနိုး | C8: ရေး | D8: 615000 | F8: =SUMIF('Daily Sale'!B:B,'MLM OP Debtors'!B8,'Daily Sale'!G:G) -> 0 | G8: =SUMIF('Daily Sale'!B:B,'MLM OP Debtors'!B8,'Daily Sale'!H:H) -> 0 | H8: =F8*D8 -> 0 | I8: =E8+G8-H8 -> 0 | L8: =+F8 -> 0 | N8: =+K8+L8-M8 -> 0
A9: 8 | B9: မချော | C9: ဇီးဖြူသောင် | D9: 605000 | F9: =SUMIF('Daily Sale'!B:B,'MLM OP Debtors'!B9,'Daily Sale'!G:G) -> 5 | G9: =SUMIF('Daily Sale'!B:B,'MLM OP Debtors'!B9,'Daily Sale'!H:H) -> 3025000 | H9: =F9*D9 -> 3025000 | I9: =E9+G9-H9 -> 0 | L9: =+F9 -> 5 | N9: =+K9+L9-M9 -> 5
A10: 9 | B10: ဝင်းအောင်ရွှေ | C10: ဇာသပြင် | D10: 590000 | F10: =SUMIF('Daily Sale'!B:B,'MLM OP Debtors'!B10,'Daily Sale'!G:G) -> 1 | G10: =SUMIF('Daily Sale'!B:B,'MLM OP Debtors'!B10,'Daily Sale'!H:H) -> 590000 | H10: =F10*D10 -> 590000 | I10: =E10+G10-H10 -> 0 | L10: =+F10 -> 1 | M10: 1 | N10: =+K10+L10-M10 -> 0
A11: 10 | B11: ဇော်လင်းမြတ် | C11: ဇီးဖြူသောင် | D11: 615000 | F11: =SUMIF('Daily Sale'!B:B,'MLM OP Debtors'!B11,'Daily Sale'!G:G) -> 2 | G11: =SUMIF('Daily Sale'!B:B,'MLM OP Debtors'!B11,'Daily Sale'!H:H) -> 1230000 | H11: =F11*D11 -> 1230000 | I11: =E11+G11-H11 -> 0 | L11: =+F11 -> 2 | N11: =+K11+L11-M11 -> 2
A12: 11 | B12: ဦးဝင်းမြင့် | C12: ဖက်တန်း | D12: 610000 | F12: =SUMIF('Daily Sale'!B:B,'MLM OP Debtors'!B12,'Daily Sale'!G:G) -> 4 | G12: =SUMIF('Daily Sale'!B:B,'MLM OP Debtors'!B12,'Daily Sale'!H:H) -> 2430000 | H12: 2430000 | I12: =E12+G12-H12 -> 0 | L12: =+F12 -> 4 | M12: 3 | N12: =+K12+L12-M12 -> 1
A13: 12 | B13: ပျားထန်းစက်ရုံ | C13: သံလွင်ဥယျာဉ် | D13: 590000 | F13: =SUMIF('Daily Sale'!B:B,'MLM OP Debtors'!B13,'Daily Sale'!G:G) -> 0 | G13: =SUMIF('Daily Sale'!B:B,'MLM OP Debtors'!B13,'Daily Sale'!H:H) -> 0 | H13: =F13*D13 -> 0 | I13: =E13+G13-H13 -> 0 | L13: =+F13 -> 0 | N13: =+K13+L13-M13 -> 0
A14: 13 | B14: မစန္ဒာ | C14: ဇာသပြင် | D14: 620000 | F14: =SUMIF('Daily Sale'!B:B,'MLM OP Debtors'!B14,'Daily Sale'!G:G) -> 0 | G14: =SUMIF('Daily Sale'!B:B,'MLM OP Debtors'!B14,'Daily Sale'!H:H) -> 0 | H14: =F14*D14 -> 0 | I14: =E14+G14-H14 -> 0 | L14: =+F14 -> 0 | N14: =+K14+L14-M14 -> 0
A15: 14 | B15: ကိုမောင်+မသူဇာ | C15: လမိုင်း | D15: 615000 | F15: =SUMIF('Daily Sale'!B:B,'MLM OP Debtors'!B15,'Daily Sale'!G:G) -> 5 | G15: =SUMIF('Daily Sale'!B:B,'MLM OP Debtors'!B15,'Daily Sale'!H:H) -> 3075000 | H15: =F15*D15 -> 3075000 | I15: =E15+G15-H15 -> 0 | L15: =+F15 -> 5 | M15: 5 | N15: =+K15+L15-M15 -> 0
A16: 15 | B16: ဦးမင်းလွင် | C16: ဈေးကြီး | D16: 595000 | F16: =SUMIF('Daily Sale'!B:B,'MLM OP Debtors'!B16,'Daily Sale'!G:G) -> 23 | G16: =SUMIF('Daily Sale'!B:B,'MLM OP Debtors'!B16,'Daily Sale'!H:H) -> 13325000 | H16: 13325000 | I16: =E16+G16-H16 -> 0 | L16: =+F16 -> 23 | M16: 23 | N16: =+K16+L16-M16 -> 0
A17: 16 | B17: ကိုဘာဘူ | C17: ဇာသပြင် | D17: 620000 | F17: =SUMIF('Daily Sale'!B:B,'MLM OP Debtors'!B17,'Daily Sale'!G:G) -> 0 | G17: =SUMIF('Daily Sale'!B:B,'MLM OP Debtors'!B17,'Daily Sale'!H:H) -> 0 | H17: =F17*D17 -> 0 | I17: =E17+G17-H17 -> 0 | L17: =+F17 -> 0 | N17: =+K17+L17-M17 -> 0
A18: 17 | B18: အမိရင်ခွင် | C18: မုဒွန်း | D18: 620000 | F18: =SUMIF('Daily Sale'!B:B,'MLM OP Debtors'!B18,'Daily Sale'!G:G) -> 0 | G18: =SUMIF('Daily Sale'!B:B,'MLM OP Debtors'!B18,'Daily Sale'!H:H) -> 0 | H18: =F18*D18 -> 0 | I18: =E18+G18-H18 -> 0 | L18: =+F18 -> 0 | N18: =+K18+L18-M18 -> 0
A19: 18 | B19: ဦးအောင်မြင့် | C19: ကမာမို | D19: 620000 | F19: =SUMIF('Daily Sale'!B:B,'MLM OP Debtors'!B19,'Daily Sale'!G:G) -> 0 | G19: =SUMIF('Daily Sale'!B:B,'MLM OP Debtors'!B19,'Daily Sale'!H:H) -> 0 | H19: =D19*F19 -> 0 | I19: =E19+G19-H19 -> 0 | L19: =+F19 -> 0 | N19: =+K19+L19-M19 -> 0
A20: 19 | B20: ကိုချမ်းသာ | C20: မုဒုံ | D20: 615000 | F20: =SUMIF('Daily Sale'!B:B,'MLM OP Debtors'!B20,'Daily Sale'!G:G) -> 0 | G20: =SUMIF('Daily Sale'!B:B,'MLM OP Debtors'!B20,'Daily Sale'!H:H) -> 0 | H20: =D20*F20 -> 0 | I20: =E20+G20-H20 -> 0 | L20: =+F20 -> 0 | N20: =+K20+L20-M20 -> 0
A21: 20 | B21: ၀ါးအိမ် | C21: သိမ်ဇရပ် | D21: 625000 | F21: =SUMIF('Daily Sale'!B:B,'MLM OP Debtors'!B21,'Daily Sale'!G:G) -> 0 | G21: =SUMIF('Daily Sale'!B:B,'MLM OP Debtors'!B21,'Daily Sale'!H:H) -> 0 | H21: =D21*F21 -> 0 | I21: =E21+G21-H21 -> 0 | L21: =+F21 -> 0 | N21: =+K21+L21-M21 -> 0
E22: =SUM(E2:E19) -> 0 | F22: =SUM(F2:F21) -> 63 | G22: =SUM(G2:G21) -> 37380000 | H22: =SUM(H2:H21) -> 36160000 | I22: =SUM(I2:I21) -> 1220000 | K22: =SUM(K2:K19) -> 0 | L22: =SUM(L2:L21) -> 63 | M22: =SUM(M2:M21) -> 37 | N22: =SUM(N2:N21) -> 26

Sheet Daily Sale
A1: Daily Sale
A2: Date | B2: အမည် | C2: မြို့နယ် | D2: Vr No | E2: List | F2: Rate | G2: ကုန်ရောင်း (လုံး) | H2: ကုန်ရောင်း (ကျပ်)
A3: 46084 | B3: ဝင်းအောင်ရွှေ | C3: ဇာသပြင် | D3: 05600 | E3: Cash Sale | F3: 590000 | G3: 1 | H3: =F3*G3 -> 590000
A4: 46085 | B4: ကိုမျိုးအောင် | C4: ဈေးကြို | D4: 06053 | E4: Advance Sale | F4: 575000 | G4: 2 | H4: =F4*G4 -> 1150000
A5: 46085 | B5: ဦးမင်းလွင် | C5: ဈေးကြီး | D5: 06055 | E5: Cash Sale | F5: 575000 | G5: 3 | H5: =F5*G5 -> 1725000
A6: 46086 | B6: ကိုမျိုးအောင် | C6: ဈေးကြို | D6: 06068 | E6: Advance Sale | F6: 575000 | G6: 1 | H6: =F6*G6 -> 575000
A7: 46086 | B7: ဦးဝင်းမြင့် | C7: ဖက်တန်း | D7: 06026 | E7: Cash Sale | F7: 600000 | G7: 1 | H7: =F7*G7 -> 600000
A8: 46088 | B8: ဦးမင်းလွင် | C8: ဈေးကြီး | D8: 06085 | E8: Cash Sale | F8: 575000 | G8: 3 | H8: =F8*G8 -> 1725000
A9: 46090 | B9: ကိုထွန်းနိုင် | C9: ရေး | D9: 06158 | E9: Credit Sale | F9: 610000 | G9: 2 | H9: =F9*G9 -> 1220000
A10: 46090 | B10: ဦးမင်းလွင် | C10: ဈေးကြီး | D10: 06100 | E10: Cash Sale | F10: 575000 | G10: 5 | H10: =F10*G10 -> 2875000
A11: 46091 | B11: ဦးမင်းလွင် | C11: ဈေးကြီး | D11: 06161 | E11: Cash Sale | F11: 575000 | G11: 3 | H11: =F11*G11 -> 1725000
A12: 46092 | B12: ဦးဝင်းမြင့် | C12: ဖက်တန်းလမ်း | D12: 06164 | E12: Cash Sale | F12: 610000 | G12: 1 | H12: =F12*G12 -> 610000
A13: 46093 | B13: ကိုမောင်+မသူဇာ | C13: လမိုင်း | D13: 06182 | E13: Cash Sale | F13: 615000 | G13: 2 | H13: =F13*G13 -> 1230000
A14: 46095 | B14: ကိုမောင်+မသူဇာ | C14: လမိုင်း | D14: 06193 | E14: Cash Sale | F14: 615000 | G14: 3 | H14: =F14*G14 -> 1845000
... A24: 46100 | B24: ဦးဝင်းမြင့် | C24: ဖက်တန်းလမ်း | D24: 06294 | E24: Cash Sale | F24: 610000 | G24: 1 | H24: =F24*G24 -> 610000
H25: =F25*G25 -> 0
H26: =F26*G26 -> 0
H27: =F27*G27 -> 0
H28: =F28*G28 -> 0
H29: =F29*G29 -> 0
H30: =F30*G30 -> 0
H31: =F31*G31 -> 0
H32: =F32*G32 -> 0
H33: =F33*G33 -> 0
H34: =F34*G34 -> 0
H35: =F35*G35 -> 0
H36: =F36*G36 -> 0
... H82: =F82*G82 -> 0
F742: =IFERROR(INDEX('Sales Price'!D:D,MATCH('Daily Sale'!B742,'Sales Price'!B:B,0)),"-") -> -
F743: =IFERROR(INDEX('Sales Price'!D:D,MATCH('Daily Sale'!B743,'Sales Price'!B:B,0)),"-") -> -
F744: =IFERROR(INDEX('Sales Price'!D:D,MATCH('Daily Sale'!B744,'Sales Price'!B:B,0)),"-") -> -
F745: =IFERROR(INDEX('Sales Price'!D:D,MATCH('Daily Sale'!B745,'Sales Price'!B:B,0)),"-") -> -
F746: =IFERROR(INDEX('Sales Price'!D:D,MATCH('Daily Sale'!B746,'Sales Price'!B:B,0)),"-") -> -
F747: =IFERROR(INDEX('Sales Price'!D:D,MATCH('Daily Sale'!B747,'Sales Price'!B:B,0)),"-") -> -
F748: =IFERROR(INDEX('Sales Price'!D:D,MATCH('Daily Sale'!B748,'Sales Price'!B:B,0)),"-") -> -
F749: =IFERROR(INDEX('Sales Price'!D:D,MATCH('Daily Sale'!B749,'Sales Price'!B:B,0)),"-") -> -
F750: =IFERROR(INDEX('Sales Price'!D:D,MATCH('Daily Sale'!B750,'Sales Price'!B:B,0)),"-") -> -
F751: =IFERROR(INDEX('Sales Price'!D:D,MATCH('Daily Sale'!B751,'Sales Price'!B:B,0)),"-") -> -
F752: =IFERROR(INDEX('Sales Price'!D:D,MATCH('Daily Sale'!B752,'Sales Price'!B:B,0)),"-") -> -
F753: =IFERROR(INDEX('Sales Price'!D:D,MATCH('Daily Sale'!B753,'Sales Price'!B:B,0)),"-") -> -
...
