Workbook
Name a: #REF!
Name aa: #REF!
Name aa: #REF!
Name aa: #REF!
Name aaa: #REF!
Name aaa: #REF!
Name aaa: #REF!
Name aaaaa: #REF!
Name aaaaaaa: #REF!
Name aaaaaaa: #REF!
Name aaaaaaa: #REF!
Name asd: '[1]Market ( Mar) '!#REF!
Name asd: '[1]Market ( Mar) '!#REF!
Name asd: '[1]Market ( Mar) '!#REF!
Name atr: #REF!
Name atr: #REF!
Name atr: #REF!
Name b: #REF!
Name b: #REF!
Name b: #REF!
Name bb: #REF!
Name bb: #REF!
Name bb: #REF!
Name Beg_Bal: #REF!
Name Beg_Bal: #REF!
Name Beg_Bal: #REF!
Name Cash_Cr: #REF!
Name Cash_Cr: #REF!
Name Cash_Cr: #REF!
Name Cash_Dr: #REF!
Name Cash_Dr: #REF!
Name Cash_Dr: #REF!
Name cc: #REF!
Name cc: #REF!
Name cc: #REF!
Name ccc: #REF!
Name ccc: #REF!
Name ccc: #REF!
Name cft: #REF!
Name cft: #REF!
Name cr: #REF!
Name cr: #REF!
Name cr: #REF!
Name crs: #REF!
Name crs: #REF!
Name crs: #REF!
Name cvvvv: #REF!
Name cwer: #REF!
Name cwer: #REF!
Name Data: #REF!
Name Data: #REF!
Name Data: #REF!
Name dd: #REF!
Name dd: #REF!
Name dd: #REF!
Name ddd: #REF!
Name ddd: #REF!
Name ddd: #REF!
Name dddd: OFFSET(Full_Print,0,0,Last_Row)
Name dr: #REF!

Sheet 2025 Follow up sales 
J1: Q1 | M1: Q2 | P1: Q3 | S1: Q4
E2: Standard Norm for O/L Category | J2: January | K2: February | L2: March | M2: April | N2: May | O2: June | P2: July | Q2: August | R2: September | S2: Novermber | T2: Novermber | U2: December
E3: SLAB Carton | F3: Contribution | I3: Category | J3: 275500.13 | K3: 236142.97 | L3: 314857.3 | M3: 354214.46 | N3: 354214.46 | O3: 354214.46 | P3: 354214.46 | Q3: 393571.62 | R3: 314857.3 | S3: 393571.62 | T3: 275500.13 | U3: 314857.3
F4: 0.66 | I4: WS | J4: =J3*F4 -> 181830.09 | K4: =K3*F4 -> 155854.36 | L4: =L3*F4 -> 207805.82
F5: 0.29 | I5: SWS | J5: =J3*F5 -> 79895.039 | K5: =K3*F5 -> 68481.462 | L5: =L3*F5 -> 91308.616
F6: 0.03 | I6: Mini | J6: =J3*F6 -> 8265.004 | K6: =F6*K3 -> 7084.2892 | L6: =L3*F6 -> 9445.7189
F7: 0.02 | I7: Van | J7: =J3*F7 -> 5510.0027 | K7: =K3*F7 -> 4722.8594 | L7: =L3*F7 -> 6297.1459
F8: =SUM(F4:F7) -> 1 | I8: Total Sales | J8: =SUM(J4:J7) -> 275500.13 | K8: =SUM(K4:K7) -> 236142.97 | L8: =SUM(L4:L7) -> 314857.3
I9: Ach %
I12: Quarter 1
B13: Wholesales Follow Up - (MLM) | I13: Jan'25 | O13: 45713 | U13: 45741 | AA13: Q1 Total
I14: =J3*F4 -> 181830.09 | K14: 10 | L14: 20 | M14: 30 | N14: Ach % | O14: =K3*F4 -> 155854.36 | Q14: 10 | R14: 20 | S14: 30 | T14: Ach % | U14: =L3*F4 -> 207805.82 | W14: 10 | X14: 20 | Y14: 30 | Z14: Ach % | AA14: Target | AB14: Sales | AC14: Ach %
A15: Sr No. | B15: Customer Name | D15: Area | F15: Outlet Type | G15: Cons% | H15: Resp by | I15: PKT | J15: Bottle | K15: Bottle | L15: Bottle | M15: Bottle | O15: PKT | P15: Bottle | Q15: Bottle | R15: Bottle | S15: Bottle | U15: PKT | V15: Bottle | W15: Bottle | X15: Bottle | Y15: Bottle | AA15: Bottle | AB15: Bottle
A16: 1 | B16: ကျော်စတား | C16: Kyaw Star | D16: ရေးမြို့ | E16: Yaye | F16: WS | G16: 0.31729809 | I16: =J16/14 -> 4121.0242 | J16: =I14*G16 -> 57694.339 | O16: =P16/14 -> 3532.3065 | P16: =G16*O14 -> 49452.291 | U16: =V16/14 -> 4709.742 | V16: =G16*U14 -> 65936.387
A17: 2 | B17: ဒေါ်နွယ်နွယ်ရီ(ရွှေတောင်ကြား) | C17: Daw New New Yi | D17: ရေးမြို့ | E17: Yayae | F17: WS | G17: 0.26991484 | I17: =J17/14 -> 3505.6171 | J17: =I14*G17 -> 49078.64 | O17: =P17/14 -> 3004.8147 | P17: =G17*O14 -> 42067.405 | U17: =V17/14 -> 4006.4196 | V17: =G17*U14 -> 56089.874
A18: 3 | B18: ပြည့်လျှံ | C18: Pyae Hlan | D18: မော်လမြိုင် | E18: Mawlamyaing | F18: WS | G18: 0.07466018 | I18: =J18/14 -> 969.67622 | J18: =I14*G18 -> 13575.467 | O18: =P18/14 -> 831.15105 | P18: =G18*O14 -> 11636.115 | U18: =V18/14 -> 1108.2014 | V18: =G18*U14 -> 15514.82
A19: 4 | B19: ဦးမင်းလွင်(ထင်းပုံ) | C19: U Min Lwin | D19: မော်လမြိုင် | E19: Mawlamyaing | F19: WS | G19: 0.058876304 | I19: =J19/14 -> 764.6774 | J19: =I14*G19 -> 10705.484 | O19: =P19/14 -> 655.43777 | P19: =G19*O14 -> 9176.1288 | U19: =V19/14 -> 873.91703 | V19: =G19*U14 -> 12234.838
A20: 5 | B20: ရွှေပင်လယ် | C20: Ma Wint War Htike | D20: ရေးမြို့ | E20: Yaye | F20: WS | G20: 0.044488976 | I20: =J20/14 -> 577.81674 | J20: =I14*G20 -> 8089.4344 | O20: =P20/14 -> 495.27149 | P20: =G20*O14 -> 6933.8009 | U20: =V20/14 -> 660.36199 | V20: =G20*U14 -> 9245.0679
A21: 6 | B21: ဒေါ်ထွန်းမေ | C21: Daw Htun May | D21: မော်လမြိုင် | E21: Mawlamyaing | F21: WS | G21: 0.043770829 | I21: =J21/14 -> 568.48955 | J21: =I14*G21 -> 7958.8537 | O21: =P21/14 -> 487.27676 | P21: =G21*O14 -> 6821.8746 | U21: =V21/14 -> 649.70234 | V21: =G21*U14 -> 9095.8328
A22: 7 | B22: ကိုထွန်းနိုင် | C22: Ko Htun Naing | D22: ရေးမြို့ | E22: Yaye | F22: WS | G22: 0.039177399 | I22: =J22/14 -> 508.8307 | J22: =I14*G22 -> 7123.6299 | O22: =P22/14 -> 436.1406 | P22: =G22*O14 -> 6105.9684 | U22: =V22/14 -> 581.5208 | V22: =G22*U14 -> 8141.2913
A23: 8 | B23: ကိုမျိုးအောင် | C23: Ko Myo Aung | D23: မော်လမြိုင် | E23: Mawlamyaing | F23: WS | G23: 0.036802383 | I23: =J23/14 -> 477.98432 | J23: =I14*G23 -> 6691.7805 | O23: =P23/14 -> 409.70085 | P23: =G23*O14 -> 5735.8119 | U23: =V23/14 -> 546.2678 | V23: =G23*U14 -> 7647.7492
A24: 9 | B24: ကိုမောင်+မသူဇာ | C24: Ko Mg+Ma Thu Zar | D24: ရေးမြို့ | E24: Yayae | F24: WS | G24: 0.032185629 | I24: =J24/14 -> 418.02255 | J24: =I14*G24 -> 5852.3157 | O24: =P24/14 -> 358.30504 | P24: =G24*O14 -> 5016.2706 | U24: =V24/14 -> 477.74006 | V24: =G24*U14 -> 6688.3608
A25: 10 | B25: ကိုညီညီဆွေ | C25: Ko Nyi Nyi Swe-1 | D25: မော်လမြိုင် | E25: Mawlamyaing | F25: WS | G25: 0.032013996 | I25: =J25/14 -> 415.79341 | J25: =I14*G25 -> 5821.1077 | O25: =P25/14 -> 356.39435 | P25: =G25*O14 -> 4989.5209 | U25: =V25/14 -> 475.19247 | V25: =G25*U14 -> 6652.6945
A26: 11 | B26: မိုးဆန်းချာလီ | C26: Moe San Char Li | D26: ကျိုက်ထိုမြို့ | E26: Kyaikto | F26: WS | G26: 0.02863464 | I26: =J26/14 -> 371.9028 | J26: =I14*G26 -> 5206.6392 | O26: =P26/14 -> 318.77383 | P26: =G26*O14 -> 4462.8336 | U26: =V26/14 -> 425.03177 | V26: =G26*U14 -> 5950.4448
A27: 12 | B27: ကိုထိုက်စိုး | C27: Ko Htike Soe | D27: ရေးမြို့ | E27: Yaye | F27: WS | G27: 0.022176738 | I27: =J27/14 -> 288.02845 | J27: =I14*G27 -> 4032.3983 | O27: =P27/14 -> 246.88153 | P27: =G27*O14 -> 3456.3414 | U27: =V27/14 -> 329.17537 | V27: =G27*U14 -> 4608.4552
B29: Total Wholesales ( 12) | I29: =SUM(I16:I28) -> 12987.863 | J29: =SUM(J16:J28) -> 181830.09 | O29: =SUM(O16:O28) -> 11132.454 | P29: =SUM(P16:P28) -> 155854.36 | U29: =SUM(U16:U28) -> 14843.273 | V29: =SUM(V16:V28) -> 207805.82 | AA29: =SUM(AA28:AA28) -> 0
I31: Quarter 1
B32: Semi Wholesales Follow Up - (MLM) | I32: Jan'25 | O32: 45713 | U32: 45741 | AA32: Q1 Total
I33: =J3*F5 -> 79895.039 | K33: 10 | L33: 20 | M33: 30 | N33: Ach % | O33: =K3*F5 -> 68481.462 | Q33: 10 | R33: 20 | S33: 30 | T33: Ach % | U33: =J3*F5 -> 79895.039 | W33: 10 | X33: 20 | Y33: 30 | Z33: Ach % | AA33: Target | AB33: Sales | AC33: Ach %
A34: Sr No. | B34: Customer Name | D34: Area | F34: Outlet Type | G34: Cons% | H34: Resp by | I34: PKT | J34: Bottle | K34: Bottle | L34: Bottle | M34: Bottle | O34: PKT | P34: Bottle | Q34: Bottle | R34: Bottle | S34: Bottle | U34: PKT | V34: Bottle | W34: Bottle | X34: Bottle | Y34: Bottle | AA34: Bottle | AB34: Bottle
A35: 1 | B35: ကိုနေနိုင် | C35: Ko Nay Naing | D35: ပေါင် | F35: Semi WS | G35: 0.0065071101 | I35: =J35/14 -> 37.134701 | J35: =G35*I33 -> 519.88581 | O35: =P35/14 -> 31.829744 | P35: =G35*O33 -> 445.61641 | U35: =V35/14 -> 37.134701 | V35: =G35*U33 -> 519.88581
A36: 2 | B36: ဒေါ်မိစိန် | C36: Daw Mi Sein | D36: ရေးမြို့ | F36: Semi WS | G36: 0.079492931 | I36: =J36/14 -> 453.64934 | J36: =G36*I33 -> 6351.0908 | O36: =P36/14 -> 388.8423 | P36: =G36*O33 -> 5443.7921 | U36: =V36/14 -> 453.64934 | V36: =G36*U33 -> 6351.0908
A37: 3 | B37: 3 Brother | C37: 3 Brother | D37: ရေးမြို့ | F37: Semi WS | G37: 0.050603996 | I37: =J37/14 -> 288.78631 | J37: =G37*I33 -> 4043.0083 | O37: =P37/14 -> 247.53112 | P37: =G37*O33 -> 3465.4357 | U37: =V37/14 -> 288.78631 | V37: =G37*U33 -> 4043.0083
A38: 4 | B38: ကိုဇော်လင်းမြတ် | C38: Ko Zaw Lin Myat | D38: ရေးမြို့ | F38: Semi WS | G38: 0.037453954 | I38: =J38/14 -> 213.7418 | J38: =G38*I33 -> 2992.3851 | O38: =P38/14 -> 183.20725 | P38: =G38*O33 -> 2564.9015 | U38: =V38/14 -> 213.7418 | V38: =G38*U33 -> 2992.3851
A39: 5 | B39: ကိုရှမ်း | C39: Ko Shan | D39: ရေးမြို့ | F39: Semi WS | G39: 0.029901426 | I39: =J39/14 -> 170.64111 | J39: =G39*I33 -> 2388.9756 | O39: =P39/14 -> 146.26381 | P39: =G39*O33 -> 2047.6934 | U39: =V39/14 -> 170.64111 | V39: =G39*U33 -> 2388.9756
A40: 6 | B40: မမော် | C40: Ma Maw | D40: ဘားအံ | F40: Semi WS | G40: 0.023785319 | I40: =J40/14 -> 135.73778 | J40: =G40*I33 -> 1900.329 | O40: =P40/14 -> 116.34667 | P40: =G40*O33 -> 1628.8534 | U40: =V40/14 -> 135.73778 | V40: =G40*U33 -> 1900.329
A41: 7 | B41: A1 | C41: A-1 | D41: မော်လမြိုင် | F41: Semi WS | G41: 0.021945548 | I41: =J41/14 -> 125.2386 | J41: =G41*I33 -> 1753.3404 | O41: =P41/14 -> 107.34737 | P41: =G41*O33 -> 1502.8632 | U41: =V41/14 -> 125.2386 | V41: =G41*U33 -> 1753.3404
A42: 8 | B42: မသီတာ၀င်း | C42: Ma Thida Win | D42: မုဒုံမြို့ | F42: Semi WS | G42: 0.020167514 | I42: =J42/14 -> 115.09174 | J42: =G42*I33 -> 1611.2843 | O42: =P42/14 -> 98.650059 | P42: =G42*O33 -> 1381.1008 | U42: =V42/14 -> 115.09174 | V42: =G42*U33 -> 1611.2843
A43: 9 | B43: Thailand | C43: Thailand | D43: မုဒုံမြို့ | F43: Semi WS | G43: 0.015125635 | I43: =J43/14 -> 86.318802 | J43: =G43*I33 -> 1208.4632 | O43: =P43/14 -> 73.987545 | P43: =G43*O33 -> 1035.8256 | U43: =V43/14 -> 86.318802 | V43: =G43*U33 -> 1208.4632
A44: 10 | B44: ကိုရန်နိုင်ဦး | C44: Ko Yan Naing Oo | D44: ဘားအံ | F44: Semi WS | G44: 0.014961003 | I44: =J44/14 -> 85.379278 | J44: =G44*I33 -> 1195.3099 | O44: =P44/14 -> 73.182238 | P44: =G44*O33 -> 1024.5513 | U44: =V44/14 -> 85.379278 | V44: =G44*U33 -> 1195.3099
...

Sheet FUS-Working
A2: Myaw La Myaing- Wholesales List(January-2026)
A3: No | B3: Names | D3: Township | F3: Type | G3: Contact Name | I3: Contact No. | J3: Responsibility | K3: 1st January | N3: 2nd January | Q3: 3rd January | T3: 4th January | W3: 5th January | Z3: 6th January | AC3: 7th January | AF3: 8th January | AI3: 9th January | AL3: 10th January | AO3: 10-days | AR3: 11th January | AU3: 12th January | AX3: 13th January | BA3: 14th January | BD3: 15th January | BG3: 16th January | BJ3: 17th January | BM3: 18th January | BP3: 19th January | BS3: 20th January | BV3: 20-days | BY3: 21st January | CB3: 22nd January | CE3: 23rd January | CH3: 24th January | CK3: 25th January | CN3: 26th January | CQ3: 27th January | CT3: 28th January | CW3: 29th January | CZ3: 30th January | DC3: 31st January | DF3: Month Till Date
K4: PKT | L4: BOT | M4: Liter | N4: PKT | O4: BOT | P4: Liter | Q4: PKT | R4: BOT | S4: Liter | T4: PKT | U4: BOT | V4: Liter | W4: PKT | X4: BOT | Y4: Liter | Z4: PKT | AA4: BOT | AB4: Liter | AC4: PKT | AD4: BOT | AE4: Liter | AF4: PKT | AG4: BOT | AH4: Liter | AI4: PKT | AJ4: BOT | AK4: Liter | AL4: PKT | AM4: BOT | AN4: Liter | AO4: PKT | AP4: BOT | AQ4: Liter | AR4: PKT | AS4: BOT | AT4: Liter | AU4: PKT | AV4: BOT | AW4: Liter | AX4: PKT | AY4: BOT | AZ4: Liter | BA4: PKT | BB4: BOT | BC4: Liter | BD4: PKT | BE4: BOT | BF4: Liter | BG4: PKT | BH4: BOT | BI4: Liter | BJ4: PKT | BK4: BOT | BL4: Liter | BM4: PKT | BN4: BOT | BO4: Liter | BP4: PKT | BQ4: BOT | BR4: Liter | BS4: PKT | BT4: BOT | BU4: Liter | BV4: PKT | BW4: BOT | BX4: Liter | BY4: PKT | BZ4: BOT | CA4: Liter | CB4: PKT | CC4: BOT | CD4: Liter | CE4: PKT | CF4: BOT | CG4: Liter | CH4: PKT | CI4: BOT | CJ4: Liter | CK4: PKT | CL4: BOT | CM4: Liter | CN4: PKT | CO4: BOT | CP4: Liter | CQ4: PKT | CR4: BOT | CS4: Liter | CT4: PKT | CU4: BOT | CV4: Liter | CW4: PKT | CX4: BOT | CY4: Liter | CZ4: PKT | DA4: BOT | DB4: Liter | DC4: PKT | DD4: BOT | DE4: Liter | DF4: PKT | DG4: BOT | DH4: Liter
A5: 1 | B5: ကျော်စတား | C5: Kyaw Star | D5: ရေးမြို့ | E5: Yaye | F5: WholeSales | G5: ဖူးငုံစိုး | H5: Phoo Ngone Soe | I5: 09-798788870 | J5: RSM | N5: 305 | O5: 4070 | P5: 3036.8 | W5: 390 | X5: 5160 | Y5: 3950.4 | Z5: 300 | AA5: 4000 | AB5: 2992 | AF5: 300 | AG5: 3800 | AH5: 3296 | AI5: 200 | AJ5: 2800 | AK5: 1792 | AL5: 100 | AM5: 1200 | AN5: 1200 | AO5: =+K5+N5+Q5+T5+W5+Z5+AC5+AF5+AI5+AL5 -> 1595 | AP5: =+L5+O5+R5+U5+X5+AA5+AD5+AG5+AJ5+AM5 -> 21030 | AQ5: =+M5+P5+S5+V5+Y5+AB5+AE5+AH5+AK5+AN5 -> 16267.2 | AU5: 500 | AV5: 6600 | AW5: 5088 | AX5: 300 | AY5: 3900 | AZ5: 3144 | BA5: 300 | BB5: 4000 | BC5: 2992 | BD5: 200 | BE5: 2500 | BF5: 2248 | BG5: 200 | BH5: 2800 | BI5: 1792 | BJ5: 230 | BK5: 2960 | BL5: 2456 | BP5: 430 | BQ5: 5620 | BR5: 4460.8 | BS5: 270 | BT5: 3580 | BU5: 2723.2 | BV5: =+AR5+AU5+AX5+BA5+BD5+BG5+BJ5+BM5+BP5+BS5+AO5 -> 4025 | BW5: =+AS5+AV5+AY5+BB5+BE5+BH5+BK5+BN5+BQ5+BT5+AP5 -> 52990 | BX5: =+AT5+AW5+AZ5+BC5+BF5+BI5+BL5+BO5+BR5+BU5+AQ5 -> 41171.2 | BY5: 450 | BZ5: 5800 | CA5: 4792 | CB5: 300 | CC5: 4000 | CD5: 2992 | CE5: 155 | CF5: 1960 | CG5: 1708 | CH5: 250 | CI5: 3200 | CJ5: 2696 | CN5: 310 | CO5: 4020 | CP5: 3264 | CQ5: 170 | CR5: 2140 | CS5: 1888 | CW5: 180 | CX5: 2320 | CY5: 1916.8 | CZ5: 250 | DA5: 3300 | DB5: 2544 | DC5: 410 | DD5: 5420 | DE5: 4160 | DF5: =BV5+CB5+CE5+CH5+CK5+CN5+CQ5+CT5+CW5+CZ5+DC5+BY5 -> 6500 | DG5: =BW5+CC5+CF5+CI5+CL5+CO5+CR5+CU5+CX5+DA5+DD5+BZ5 -> 85150 | DH5: =BX5+CD5+CG5+CJ5+CM5+CP5+CS5+CV5+CY5+DB5+DE5+CA5 -> 67132
A6: 2 | B6: ဒေါ်နွယ်နွယ်ရီ(ရွှေတောင်ကြား) | C6: Daw New New Yi | D6: ရေးမြို့ | E6: Yayae | F6: WholeSales | G6: ဖူးငုံစိုး | H6: Phoo Ngone Soe | I6: 09-798788870 | J6: RSM | W6: 100 | X6: 1200 | Y6: 1200 | AI6: 400 | AJ6: 5200 | AK6: 4192 | AO6: =+K6+N6+Q6+T6+W6+Z6+AC6+AF6+AI6+AL6 -> 500 | AP6: =+L6+O6+R6+U6+X6+AA6+AD6+AG6+AJ6+AM6 -> 6400 | AQ6: =+M6+P6+S6+V6+Y6+AB6+AE6+AH6+AK6+AN6 -> 5392 | AU6: 400 | AV6: 5400 | AW6: 3888 | BD6: 100 | BE6: 1200 | BF6: 1200 | BJ6: 600 | BK6: 8200 | BL6: 5680 | BV6: =+AR6+AU6+AX6+BA6+BD6+BG6+BJ6+BM6+BP6+BS6+AO6 -> 1600 | BW6: =+AS6+AV6+AY6+BB6+BE6+BH6+BK6+BN6+BQ6+BT6+AP6 -> 21200 | BX6: =+AT6+AW6+AZ6+BC6+BF6+BI6+BL6+BO6+BR6+BU6+AQ6 -> 16160 | CB6: 200 | CC6: 2400 | CD6: 2400 | CH6: 200 | CI6: 2800 | CJ6: 1792 | CT6: 100 | CU6: 1200 | CV6: 1200 | CW6: 300 | CX6: 4200 | CY6: 2688 | DC6: 700 | DD6: 9400 | DE6: 6880 | DF6: =BV6+CB6+CE6+CH6+CK6+CN6+CQ6+CT6+CW6+CZ6+DC6+BY6 -> 3100 | DG6: =BW6+CC6+CF6+CI6+CL6+CO6+CR6+CU6+CX6+DA6+DD6+BZ6 -> 41200 | DH6: =BX6+CD6+CG6+CJ6+CM6+CP6+CS6+CV6+CY6+DB6+DE6+CA6 -> 31120
A7: 3 | B7: ပြည့်လျှံ | C7: Pyae Hlan | D7: မော်လမြိုင် | E7: Mawlamyaing | F7: WholeSales | G7: ထိန်လင်း | H7: Htein Lin | I7: 09-443988251 | J7: RSM | AC7: 300 | AD7: 3800 | AE7: 3296 | AO7: =+K7+N7+Q7+T7+W7+Z7+AC7+AF7+AI7+AL7 -> 300 | AP7: =+L7+O7+R7+U7+X7+AA7+AD7+AG7+AJ7+AM7 -> 3800 | AQ7: =+M7+P7+S7+V7+Y7+AB7+AE7+AH7+AK7+AN7 -> 3296 | AX7: 200 | AY7: 2600 | AZ7: 2096 | BV7: =+AR7+AU7+AX7+BA7+BD7+BG7+BJ7+BM7+BP7+BS7+AO7 -> 500 | BW7: =+AS7+AV7+AY7+BB7+BE7+BH7+BK7+BN7+BQ7+BT7+AP7 -> 6400 | BX7: =+AT7+AW7+AZ7+BC7+BF7+BI7+BL7+BO7+BR7+BU7+AQ7 -> 5392 | CE7: 500 | CF7: 6600 | CG7: 5088 | DF7: =BV7+CB7+CE7+CH7+CK7+CN7+CQ7+CT7+CW7+CZ7+DC7+BY7 -> 1000 | DG7: =BW7+CC7+CF7+CI7+CL7+CO7+CR7+CU7+CX7+DA7+DD7+BZ7 -> 13000 | DH7: =BX7+CD7+CG7+CJ7+CM7+CP7+CS7+CV7+CY7+DB7+DE7+CA7 -> 10480
A8: 4 | B8: ကိုမျိုးအောင် | C8: Ko Myo Aung | D8: မော်လမြိုင် | E8: Mawlamyaing | F8: WholeSales | G8: ထိန်လင်း | H8: Htein Lin | I8: 09-443988251 | J8: RSM | W8: 40 | X8: 560 | Y8: 358.4 | Z8: 60 | AA8: 800 | AB8: 598.4 | AF8: 20 | AG8: 280 | AH8: 179.2 | AO8: =+K8+N8+Q8+T8+W8+Z8+AC8+AF8+AI8+AL8 -> 120 | AP8: =+L8+O8+R8+U8+X8+AA8+AD8+AG8+AJ8+AM8 -> 1640 | AQ8: =+M8+P8+S8+V8+Y8+AB8+AE8+AH8+AK8+AN8 -> 1136 | AU8: 50 | AV8: 640 | AW8: 539.2 | BG8: 85 | BH8: 1130 | BI8: 852.8 | BV8: =+AR8+AU8+AX8+BA8+BD8+BG8+BJ8+BM8+BP8+BS8+AO8 -> 255 | BW8: =+AS8+AV8+AY8+BB8+BE8+BH8+BK8+BN8+BQ8+BT8+AP8 -> 3410 | BX8: =+AT8+AW8+AZ8+BC8+BF8+BI8+BL8+BO8+BR8+BU8+AQ8 -> 2528 | CH8: 50 | CI8: 600 | CJ8: 600 | CN8: 30 | CO8: 420 | CP8: 268.8 | CZ8: 70 | DA8: 880 | DB8: 779.2 | DF8: =BV8+CB8+CE8+CH8+CK8+CN8+CQ8+CT8+CW8+CZ8+DC8+BY8 -> 405 | DG8: =BW8+CC8+CF8+CI8+CL8+CO8+CR8+CU8+CX8+DA8+DD8+BZ8 -> 5310 | DH8: =BX8+CD8+CG8+CJ8+CM8+CP8+CS8+CV8+CY8+DB8+DE8+CA8 -> 4176
A9: 5 | B9: ကိုထိုက်စိုး | C9: Ko Htike Soe | D9: ရေးမြို့ | E9: Yaye | F9: WholeSales | G9: ဖူးငုံစိုး | H9: Phoo Ngone Soe | I9: 09-798788870 | J9: RSM | AO9: =+K9+N9+Q9+T9+W9+Z9+AC9+AF9+AI9+AL9 -> 0 | AP9: =+L9+O9+R9+U9+X9+AA9+AD9+AG9+AJ9+AM9 -> 0 | AQ9: =+M9+P9+S9+V9+Y9+AB9+AE9+AH9+AK9+AN9 -> 0 | BV9: =+AR9+AU9+AX9+BA9+BD9+BG9+BJ9+BM9+BP9+BS9+AO9 -> 0 | BW9: =+AS9+AV9+AY9+BB9+BE9+BH9+BK9+BN9+BQ9+BT9+AP9 -> 0 | BX9: =+AT9+AW9+AZ9+BC9+BF9+BI9+BL9+BO9+BR9+BU9+AQ9 -> 0 | CB9: 100 | CC9: 1200 | CD9: 1200 | DC9: 500 | DD9: 6200 | DE9: 5696 | DF9: =BV9+CB9+CE9+CH9+CK9+CN9+CQ9+CT9+CW9+CZ9+DC9+BY9 -> 600 | DG9: =BW9+CC9+CF9+CI9+CL9+CO9+CR9+CU9+CX9+DA9+DD9+BZ9 -> 7400 | DH9: =BX9+CD9+CG9+CJ9+CM9+CP9+CS9+CV9+CY9+DB9+DE9+CA9 -> 6896
A10: 6 | B10: ဦးမင်းလွင် | C10: U Min Lwin | D10: မော်လမြိုင် | E10: Mawlamyaing | F10: WholeSales | G10: ထိန်လင်း | H10: Htein Lin | I10: 09-443988251 | J10: RSM | Q10: 50 | R10: 1200 | S10: 768 | AF10: 50 | AG10: 1000 | AH10: 640 | AI10: 2 | AJ10: 24 | AK10: 24 | AL10: 30 | AM10: 720 | AN10: 460.8 | AO10: =+K10+N10+Q10+T10+W10+Z10+AC10+AF10+AI10+AL10 -> 132 | AP10: =+L10+O10+R10+U10+X10+AA10+AD10+AG10+AJ10+AM10 -> 2944 | AQ10: =+M10+P10+S10+V10+Y10+AB10+AE10+AH10+AK10+AN10 -> 1892.8 | AX10: 50 | AY10: 1100 | AZ10: 704 | BD10: 50 | BE10: 1200 | BF10: 768 | BS10: 59 | BT10: 1416 | BU10: 906.24 | BV10: =+AR10+AU10+AX10+BA10+BD10+BG10+BJ10+BM10+BP10+BS10+AO10 -> 291 | BW10: =+AS10+AV10+AY10+BB10+BE10+BH10+BK10+BN10+BQ10+BT10+AP10 -> 6660 | BX10: =+AT10+AW10+AZ10+BC10+BF10+BI10+BL10+BO10+BR10+BU10+AQ10 -> 4271.04 | CN10: 30 | CO10: 720 | CP10: 460.8 | CQ10: 20 | CR10: 480 | CS10: 307.2 | CT10: 22 | CU10: 304 | CV10: 203.2 | CW10: 49 | CX10: 1176 | CY10: 752.64 | DC10: 20 | DD10: 480 | DE10: 307.2 | DF10: =BV10+CB10+CE10+CH10+CK10+CN10+CQ10+CT10+CW10+CZ10+DC10+BY10 -> 432 | DG10: =BW10+CC10+CF10+CI10+CL10+CO10+CR10+CU10+CX10+DA10+DD10+BZ10 -> 9820 | DH10: =BX10+CD10+CG10+CJ10+CM10+CP10+CS10+CV10+CY10+DB10+DE10+CA10 -> 6302.08
A11: 7 | B11: ကိုထွန်းနိုင် | C11: Ko Htun Naing | D11: ရေးမြို့ | E11: Yaye | F11: WholeSales | G11: ဖူးငုံစိုး | H11: Phoo Ngone Soe | I11: 09-798788870 | J11: RSM | AO11: =+K11+N11+Q11+T11+W11+Z11+AC11+AF11+AI11+AL11 -> 0 | AP11: =+L11+O11+R11+U11+X11+AA11+AD11+AG11+AJ11+AM11 -> 0 | AQ11: =+M11+P11+S11+V11+Y11+AB11+AE11+AH11+AK11+AN11 -> 0 | AU11: 200 | AV11: 2800 | AW11: 1792 | BV11: =+AR11+AU11+AX11+BA11+BD11+BG11+BJ11+BM11+BP11+BS11+AO11 -> 200 | BW11: =+AS11+AV11+AY11+BB11+BE11+BH11+BK11+BN11+BQ11+BT11+AP11 -> 2800 | BX11: =+AT11+AW11+AZ11+BC11+BF11+BI11+BL11+BO11+BR11+BU11+AQ11 -> 1792 | CE11: 250 | CF11: 3300 | CG11: 2544 | DF11: =BV11+CB11+CE11+CH11+CK11+CN11+CQ11+CT11+CW11+CZ11+DC11+BY11 -> 450 | DG11: =BW11+CC11+CF11+CI11+CL11+CO11+CR11+CU11+CX11+DA11+DD11+BZ11 -> 6100 | DH11: =BX11+CD11+CG11+CJ11+CM11+CP11+CS11+CV11+CY11+DB11+DE11+CA11 -> 4336
A12: 8 | B12: ဒေါ်ထွန်းမေ | C12: Daw Htun May | D12: မော်လမြိုင် | E12: Mawlamyaing | F12: WholeSales | G12: ထိန်လင်း | H12: Htein Lin | I12: 09-443988251 | J12: RSM | N12: 60 | O12: 1440 | P12: 921.6 | Z12: 110 | AA12: 2140 | AB12: 1369.6 | AO12: =+K12+N12+Q12+T12+W12+Z12+AC12+AF12+AI12+AL12 -> 170 | AP12: =+L12+O12+R12+U12+X12+AA12+AD12+AG12+AJ12+AM12 -> 3580 | AQ12: =+M12+P12+S12+V12+Y12+AB12+AE12+AH12+AK12+AN12 -> 2291.2 | AU12: 50 | AV12: 700 | AW12: 448 | BA12: 50 | BB12: 700 | BC12: 448 | BJ12: 85 | BK12: 1790 | BL12: 1145.6 | BS12: 85 | BT12: 1790 | BU12: 1145.6 | BV12: =+AR12+AU12+AX12+BA12+BD12+BG12+BJ12+BM12+BP12+BS12+AO12 -> 440 | BW12: =+AS12+AV12+AY12+BB12+BE12+BH12+BK12+BN12+BQ12+BT12+AP12 -> 8560 | BX12: =+AT12+AW12+AZ12+BC12+BF12+BI12+BL12+BO12+BR12+BU12+AQ12 -> 5478.4 | CW12: 50 | CX12: 700 | CY12: 448 | CZ12: 60 | DA12: 1440 | DB12: 921.6 | DC12: 50 | DD12: 700 | DE12: 448 | DF12: =BV12+CB12+CE12+CH12+CK12+CN12+CQ12+CT12+CW12+CZ12+DC12+BY12 -> 600 | DG12: =BW12+CC12+CF12+CI12+CL12+CO12+CR12+CU12+CX12+DA12+DD12+BZ12 -> 11400 | DH12: =BX12+CD12+CG12+CJ12+CM12+CP12+CS12+CV12+CY12+DB12+DE12+CA12 -> 7296
A13: 9 | B13: မဝင့်ဝါထိုက်(ရွှေပင်လယ်) | C13: Ma Wint War Htike | D13: ရေးမြို့ | E13: Yayae | F13: WholeSales | G13: ဖူးငုံစိုး | H13: Phoo Ngone Soe | I13: 09-798788870 | J13: RSM | AO13: =+K13+N13+Q13+T13+W13+Z13+AC13+AF13+AI13+AL13 -> 0 | AP13: =+L13+O13+R13+U13+X13+AA13+AD13+AG13+AJ13+AM13 -> 0 | AQ13: =+M13+P13+S13+V13+Y13+AB13+AE13+AH13+AK13+AN13 -> 0 | BG13: 100 | BH13: 1400 | BI13: 896 | BV13: =+AR13+AU13+AX13+BA13+BD13+BG13+BJ13+BM13+BP13+BS13+AO13 -> 100 | BW13: =+AS13+AV13+AY13+BB13+BE13+BH13+BK13+BN13+BQ13+BT13+AP13 -> 1400 | BX13: =+AT13+AW13+AZ13+BC13+BF13+BI13+BL13+BO13+BR13+BU13+AQ13 -> 896 | BY13: 100 | BZ13: 1200 | CA13: 1200 | DF13: =BV13+CB13+CE13+CH13+CK13+CN13+CQ13+CT13+CW13+CZ13+DC13+BY13 -> 200 | DG13: =BW13+CC13+CF13+CI13+CL13+CO13+CR13+CU13+CX13+DA13+DD13+BZ13 -> 2600 | DH13: =BX13+CD13+CG13+CJ13+CM13+CP13+CS13+CV13+CY13+DB13+DE13+CA13 -> 2096
A14: 10 | B14: ကိုညီညီဆွေ | C14: Ko Nyi Nyi Swe | D14: မော်လမြိုင် | E14: Mawlamyaing | F14: WholeSales | G14: ထိန်လင်း | H14: Htein Lin | I14: 09-443988251 | J14: RSM | AF14: 100 | AG14: 1400 | AH14: 896 | AI14: 150 | AJ14: 2000 | AK14: 1496 | AO14: =+K14+N14+Q14+T14+W14+Z14+AC14+AF14+AI14+AL14 -> 250 | AP14: =+L14+O14+R14+U14+X14+AA14+AD14+AG14+AJ14+AM14 -> 3400 | AQ14: =+M14+P14+S14+V14+Y14+AB14+AE14+AH14+AK14+AN14 -> 2392 | BS14: 150 | BT14: 1900 | BU14: 1648 | BV14: =+AR14+AU14+AX14+BA14+BD14+BG14+BJ14+BM14+BP14+BS14+AO14 -> 400 | BW14: =+AS14+AV14+AY14+BB14+BE14+BH14+BK14+BN14+BQ14+BT14+AP14 -> 5300 | BX14: =+AT14+AW14+AZ14+BC14+BF14+BI14+BL14+BO14+BR14+BU14+AQ14 -> 4040 | DF14: =BV14+CB14+CE14+CH14+CK14+CN14+CQ14+CT14+CW14+CZ14+DC14+BY14 -> 400 | DG14: =BW14+CC14+CF14+CI14+CL14+CO14+CR14+CU14+CX14+DA14+DD14+BZ14 -> 5300 | DH14: =BX14+CD14+CG14+CJ14+CM14+CP14+CS14+CV14+CY14+DB14+DE14+CA14 -> 4040
A15: 11 | B15: လင်းသစ် | C15: Lin Thit | D15: ကျိုက်ထိုမြို့ | E15: Yaye | F15: WholeSales | G15: ပြည့်ဖြိုးမောင် | H15: Pyae Phyo Maung | I15: 09-679797489 | J15: RSM | N15: 100 | O15: 1280 | P15: 1078.4 | AL15: 100 | AM15: 1280 | AN15: 1078.4 | AO15: =+K15+N15+Q15+T15+W15+Z15+AC15+AF15+AI15+AL15 -> 200 | AP15: =+L15+O15+R15+U15+X15+AA15+AD15+AG15+AJ15+AM15 -> 2560 | AQ15: =+M15+P15+S15+V15+Y15+AB15+AE15+AH15+AK15+AN15 -> 2156.8 | BG15: 50 | BH15: 650 | BI15: 524 | BV15: =+AR15+AU15+AX15+BA15+BD15+BG15+BJ15+BM15+BP15+BS15+AO15 -> 250 | BW15: =+AS15+AV15+AY15+BB15+BE15+BH15+BK15+BN15+BQ15+BT15+AP15 -> 3210 | BX15: =+AT15+AW15+AZ15+BC15+BF15+BI15+BL15+BO15+BR15+BU15+AQ15 -> 2680.8 | CE15: 100 | CF15: 1300 | CG15: 1048 | DC15: 150 | DD15: 1950 | DE15: 1572 | DF15: =BV15+CB15+CE15+CH15+CK15+CN15+CQ15+CT15+CW15+CZ15+DC15+BY15 -> 500 | DG15: =BW15+CC15+CF15+CI15+CL15+CO15+CR15+CU15+CX15+DA15+DD15+BZ15 -> 6460 | DH15: =BX15+CD15+CG15+CJ15+CM15+CP15+CS15+CV15+CY15+DB15+DE15+CA15 -> 5300.8
A16: 12 | B16: ကိုမောင်+မသူဇာ | C16: Ko Mg+Ma Thu Zar | D16: ရေးမြို့ | E16: Yaye | F16: WholeSales | G16: ဖူးငုံစိုး | H16: Phoo Ngone Soe | I16: 09-798788870 | J16: RSM | Q16: 150 | R16: 1800 | S16: 1800 | AC16: 50 | AD16: 600 | AE16: 600 | AO16: =+K16+N16+Q16+T16+W16+Z16+AC16+AF16+AI16+AL16 -> 200 | AP16: =+L16+O16+R16+U16+X16+AA16+AD16+AG16+AJ16+AM16 -> 2400 | AQ16: =+M16+P16+S16+V16+Y16+AB16+AE16+AH16+AK16+AN16 -> 2400 | AU16: 50 | AV16: 600 | AW16: 600 | BA16: 100 | BB16: 1200 | BC16: 1200 | BG16: 100 | BH16: 1200 | BI16: 1200 | BJ16: 50 | BK16: 600 | BL16: 600 | BP16: 30 | BQ16: 420 | BR16: 268.8 | BV16: =+AR16+AU16+AX16+BA16+BD16+BG16+BJ16+BM16+BP16+BS16+AO16 -> 530 | BW16: =+AS16+AV16+AY16+BB16+BE16+BH16+BK16+BN16+BQ16+BT16+AP16 -> 6420 | BX16: =+AT16+AW16+AZ16+BC16+BF16+BI16+BL16+BO16+BR16+BU16+AQ16 -> 6268.8 | CB16: 100 | CC16: 1200 | CD16: 1200 | CQ16: 50 | CR16: 600 | CS16: 600 | CT16: 120 | CU16: 1440 | CV16: 1440 | DF16: =BV16+CB16+CE16+CH16+CK16+CN16+CQ16+CT16+CW16+CZ16+DC16+BY16 -> 800 | DG16: =BW16+CC16+CF16+CI16+CL16+CO16+CR16+CU16+CX16+DA16+DD16+BZ16 -> 9660 | DH16: =BX16+CD16+CG16+CJ16+CM16+CP16+CS16+CV16+CY16+DB16+DE16+CA16 -> 9508.8
A17: 13 | B17: မိုးဆန်းချာလီ | C17: Moe San Char Li | D17: သိမ်ဇရပ် | E17: Thein Za Yat | F17: WholeSales | AO17: =+K17+N17+Q17+T17+W17+Z17+AC17+AF17+AI17+AL17 -> 0 | AP17: =+L17+O17+R17+U17+X17+AA17+AD17+AG17+AJ17+AM17 -> 0 | AQ17: =+M17+P17+S17+V17+Y17+AB17+AE17+AH17+AK17+AN17 -> 0 | BD17: 220 | BE17: 3180 | BF17: 2251.2 | BV17: =+AR17+AU17+AX17+BA17+BD17+BG17+BJ17+BM17+BP17+BS17+AO17 -> 220 | BW17: =+AS17+AV17+AY17+BB17+BE17+BH17+BK17+BN17+BQ17+BT17+AP17 -> 3180 | BX17: =+AT17+AW17+AZ17+BC17+BF17+BI17+BL17+BO17+BR17+BU17+AQ17 -> 2251.2 | CB17: 101 | CC17: 1414 | CD17: 904.96 | DF17: =BV17+CB17+CE17+CH17+CK17+CN17+CQ17+CT17+CW17+CZ17+DC17+BY17 -> 321 | DG17: =BW17+CC17+CF17+CI17+CL17+CO17+CR17+CU17+CX17+DA17+DD17+BZ17 -> 4594 | DH17: =BX17+CD17+CG17+CJ17+CM17+CP17+CS17+CV17+CY17+DB17+DE17+CA17 -> 3156.16
A18: 14 | B18: ကိုမြခက် | C18: Ko Mya Khat | D18: ရေးမြို့ | E18: Yaye | F18: WholeSales | W18: 100 | X18: 1400 | Y18: 896 | AO18: =+K18+N18+Q18+T18+W18+Z18+AC18+AF18+AI18+AL18 -> 100 | AP18: =+L18+O18+R18+U18+X18+AA18+AD18+AG18+AJ18+AM18 -> 1400 | AQ18: =+M18+P18+S18+V18+Y18+AB18+AE18+AH18+AK18+AN18 -> 896 | BV18: =+AR18+AU18+AX18+BA18+BD18+BG18+BJ18+BM18+BP18+BS18+AO18 -> 100 | BW18: =+AS18+AV18+AY18+BB18+BE18+BH18+BK18+BN18+BQ18+BT18+AP18 -> 1400 | BX18: =+AT18+AW18+AZ18+BC18+BF18+BI18+BL18+BO18+BR18+BU18+AQ18 -> 896 | DF18: =BV18+CB18+CE18+CH18+CK18+CN18+CQ18+CT18+CW18+CZ18+DC18+BY18 -> 100 | DG18: =BW18+CC18+CF18+CI18+CL18+CO18+CR18+CU18+CX18+DA18+DD18+BZ18 -> 1400 | DH18: =BX18+CD18+CG18+CJ18+CM18+CP18+CS18+CV18+CY18+DB18+DE18+CA18 -> 896
A19: Total | K19: =SUM(K5:K18) -> 0 | L19: =SUM(L5:L18) -> 0 | M19: =SUM(M5:M18) -> 0 | N19: =SUM(N5:N18) -> 465 | O19: =SUM(O5:O18) -> 6790 | P19: =SUM(P5:P18) -> 5036.8 | Q19: =SUM(Q5:Q18) -> 200 | R19: =SUM(R5:R18) -> 3000 | ... DH19: =SUM(DH5:DH18) -> 162735.84
A21: No | B21: Names | D21: Township | F21: Type | G21: Contact Name | I21: Contact No. | J21: Responsibility | K21: 1st January | N21: 2nd January | Q21: 3rd January | T21: 4th January | W21: 5th January | Z21: 6th January | AC21: 7th January | AF21: 8th January | AI21: 9th January | AL21: 10th January | AO21: 10-days | AR21: 11th January | AU21: 12th January | AX21: 13th January | BA21: 14th January | BD21: 15th January | BG21: 16th January | BJ21: 17th January | BM21: 18th January | BP21: 19th January | BS21: 20th January | BV21: 20-days | BY21: 21st January | CB21: 22nd January | CE21: 23rd January | CH21: 24th January | CK21: 25th January | CN21: 26th January | CQ21: 27th January | CT21: 28th January | CW21: 29th January | CZ21: 30th January | DC21: 31st January | DF21: Month Till Date
K22: PKT | L22: BOT | M22: Liter | N22: PKT | O22: BOT | P22: Liter | Q22: PKT | R22: BOT | S22: Liter | T22: PKT | U22: BOT | V22: Liter | W22: PKT | X22: BOT | Y22: Liter | Z22: PKT | AA22: BOT | AB22: Liter | AC22: PKT | AD22: BOT | AE22: Liter | AF22: PKT | AG22: BOT | AH22: Liter | AI22: PKT | AJ22: BOT | AK22: Liter | AL22: PKT | AM22: BOT | AN22: Liter | AO22: PKT | AP22: BOT | AQ22: Liter | AR22: PKT | AS22: BOT | AT22: Liter | AU22: PKT | AV22: BOT | AW22: Liter | AX22: PKT | AY22: BOT | AZ22: Liter | BA22: PKT | BB22: BOT | BC22: Liter | BD22: PKT | BE22: BOT | BF22: Liter | BG22: PKT | BH22: BOT | BI22: Liter | BJ22: PKT | BK22: BOT | BL22: Liter | BM22: PKT | BN22: BOT | BO22: Liter | BP22: PKT | BQ22: BOT | BR22: Liter | BS22: PKT | BT22: BOT | BU22: Liter | BV22: PKT | BW22: BOT | BX22: Liter | BY22: PKT | BZ22: BOT | CA22: Liter | CB22: PKT | CC22: BOT | CD22: Liter | CE22: PKT | CF22: BOT | CG22: Liter | CH22: PKT | CI22: BOT | CJ22: Liter | CK22: PKT | CL22: BOT | CM22: Liter | CN22: PKT | CO22: BOT | CP22: Liter | CQ22: PKT | CR22: BOT | CS22: Liter | CT22: PKT | CU22: BOT | CV22: Liter | CW22: PKT | CX22: BOT | CY22: Liter | CZ22: PKT | DA22: BOT | DB22: Liter | DC22: PKT | DD22: BOT | DE22: Liter | DF22: PKT | DG22: BOT | DH22: Liter
A23: 1 | B23: ၀င်းအောင်ရွှေ | C23: Win Aung Shwe | D23: ပေါင် | E23: Hpa-an | F23: Semi WS | Z23: 50 | AA23: 600 | AB23: 600 | AO23: =+K23+N23+Q23+T23+W23+Z23+AC23+AF23+AI23+AL23 -> 50 | AP23: =+L23+O23+R23+U23+X23+AA23+AD23+AG23+AJ23+AM23 -> 600 | AQ23: =+M23+P23+S23+V23+Y23+AB23+AE23+AH23+AK23+AN23 -> 600 | BV23: =+AO23+AR23+AU23+AX23+BA23+BD23+BG23+BJ23+BM23+BP23+BS23 -> 50 | BW23: =+AP23+AS23+AV23+AY23+BB23+BE23+BH23+BK23+BN23+BQ23+BT23 -> 600 | BX23: =+AQ23+AT23+AW23+AZ23+BC23+BF23+BI23+BL23+BO23+BR23+BU23 -> 600 | BY23: 210 | BZ23: 2920 | CA23: 1912 | CN23: 50 | CO23: 600 | CP23: 600 | DF23: =BV23+CB23+CE23+CH23+CK23+CN23+CQ23+CT23+CW23+CZ23+DC23+BY23 -> 310 | DG23: =BW23+CC23+CF23+CI23+CL23+CO23+CR23+CU23+CX23+DA23+DD23+BZ23 -> 4120 | DH23: =BX23+CD23+CG23+CJ23+CM23+CP23+CS23+CV23+CY23+DB23+DE23+CA23 -> 3112
A24: 2 | B24: ဦးအေးမြင့် | C24: U Aye Myint | D24: ရေးမြို့ | E24: Thein Zayet | F24: Semi WS | AO24: =+K24+N24+Q24+T24+W24+Z24+AC24+AF24+AI24+AL24 -> 0 | AP24: =+L24+O24+R24+U24+X24+AA24+AD24+AG24+AJ24+AM24 -> 0 | AQ24: =+M24+P24+S24+V24+Y24+AB24+AE24+AH24+AK24+AN24 -> 0 | BV24: =+AO24+AR24+AU24+AX24+BA24+BD24+BG24+BJ24+BM24+BP24+BS24 -> 0 | BW24: =+AP24+AS24+AV24+AY24+BB24+BE24+BH24+BK24+BN24+BQ24+BT24 -> 0 | BX24: =+AQ24+AT24+AW24+AZ24+BC24+BF24+BI24+BL24+BO24+BR24+BU24 -> 0 | DF24: =BV24+CB24+CE24+CH24+CK24+CN24+CQ24+CT24+CW24+CZ24+DC24+BY24 -> 0 | DG24: =BW24+CC24+CF24+CI24+CL24+CO24+CR24+CU24+CX24+DA24+DD24+BZ24 -> 0 | DH24: =BX24+CD24+CG24+CJ24+CM24+CP24+CS24+CV24+CY24+DB24+DE24+CA24 -> 0
A25: 3 | B25: ကိုမွန်လေး | C25: Ko Mon Lay | D25: ရေးမြို့ | E25: Yay | F25: Semi WS | AI25: 100 | AJ25: 1400 | AK25: 896 | AO25: =+K25+N25+Q25+T25+W25+Z25+AC25+AF25+AI25+AL25 -> 100 | AP25: =+L25+O25+R25+U25+X25+AA25+AD25+AG25+AJ25+AM25 -> 1400 | AQ25: =+M25+P25+S25+V25+Y25+AB25+AE25+AH25+AK25+AN25 -> 896 | BV25: =+AO25+AR25+AU25+AX25+BA25+BD25+BG25+BJ25+BM25+BP25+BS25 -> 100 | BW25: =+AP25+AS25+AV25+AY25+BB25+BE25+BH25+BK25+BN25+BQ25+BT25 -> 1400 | BX25: =+AQ25+AT25+AW25+AZ25+BC25+BF25+BI25+BL25+BO25+BR25+BU25 -> 896 | BY25: 100 | BZ25: 1300 | CA25: 1048 | DC25: 50 | DD25: 700 | DE25: 448 | DF25: =BV25+CB25+CE25+CH25+CK25+CN25+CQ25+CT25+CW25+CZ25+DC25+BY25 -> 250 | DG25: =BW25+CC25+CF25+CI25+CL25+CO25+CR25+CU25+CX25+DA25+DD25+BZ25 -> 3400 | DH25: =BX25+CD25+CG25+CJ25+CM25+CP25+CS25+CV25+CY25+DB25+DE25+CA25 -> 2392
A26: 4 | B26: ကိုကျော်ရွှေ | C26: Ko Kyaw Shwe | D26: ရေးမြို့ | E26: Mudon | F26: Semi WS | AC26: 50 | AD26: 700 | AE26: 448 | AO26: =+K26+N26+Q26+T26+W26+Z26+AC26+AF26+AI26+AL26 -> 50 | AP26: =+L26+O26+R26+U26+X26+AA26+AD26+AG26+AJ26+AM26 -> 700 | AQ26: =+M26+P26+S26+V26+Y26+AB26+AE26+AH26+AK26+AN26 -> 448 | AU26: 50 | AV26: 700 | AW26: 448 | BD26: 60 | BE26: 820 | BF26: 568 | BP26: 50 | BQ26: 700 | BR26: 448 | BV26: =+AO26+AR26+AU26+AX26+BA26+BD26+BG26+BJ26+BM26+BP26+BS26 -> 210 | BW26: =+AP26+AS26+AV26+AY26+BB26+BE26+BH26+BK26+BN26+BQ26+BT26 -> 2920 | BX26: =+AQ26+AT26+AW26+AZ26+BC26+BF26+BI26+BL26+BO26+BR26+BU26 -> 1912 | CH26: 50 | CI26: 700 | CJ26: 448 | CQ26: 60 | CR26: 820 | CS26: 568 | DC26: 30 | DD26: 420 | DE26: 268.8 | DF26: =BV26+CB26+CE26+CH26+CK26+CN26+CQ26+CT26+CW26+CZ26+DC26+BY26 -> 350 | DG26: =BW26+CC26+CF26+CI26+CL26+CO26+CR26+CU26+CX26+DA26+DD26+BZ26 -> 4860 | DH26: =BX26+CD26+CG26+CJ26+CM26+CP26+CS26+CV26+CY26+DB26+DE26+CA26 -> 3196.8
A27: 5 | B27: ကိုကျော်နိုင်စိုး | C27: Ko Kyaw Naing Soe | D27: ရေးမြို့ | E27: Yay | F27: Semi WS | AO27: =+K27+N27+Q27+T27+W27+Z27+AC27+AF27+AI27+AL27 -> 0 | AP27: =+L27+O27+R27+U27+X27+AA27+AD27+AG27+AJ27+AM27 -> 0 | AQ27: =+M27+P27+S27+V27+Y27+AB27+AE27+AH27+AK27+AN27 -> 0 | BV27: =+AO27+AR27+AU27+AX27+BA27+BD27+BG27+BJ27+BM27+BP27+BS27 -> 0 | BW27: =+AP27+AS27+AV27+AY27+BB27+BE27+BH27+BK27+BN27+BQ27+BT27 -> 0 | BX27: =+AQ27+AT27+AW27+AZ27+BC27+BF27+BI27+BL27+BO27+BR27+BU27 -> 0 | CQ27: 300 | CR27: 3600 | CS27: 3600 | DF27: =BV27+CB27+CE27+CH27+CK27+CN27+CQ27+CT27+CW27+CZ27+DC27+BY27 -> 300 | DG27: =BW27+CC27+CF27+CI27+CL27+CO27+CR27+CU27+CX27+DA27+DD27+BZ27 -> 3600 | DH27: =BX27+CD27+CG27+CJ27+CM27+CP27+CS27+CV27+CY27+DB27+DE27+CA27 -> 3600
A28: 6 | B28: ကိုဘာဘူ | C28: Ko Bar Buu | D28: ဘားအံ | E28: Hpa-an | F28: Semi WS | AO28: =+K28+N28+Q28+T28+W28+Z28+AC28+AF28+AI28+AL28 -> 0 | AP28: =+L28+O28+R28+U28+X28+AA28+AD28+AG28+AJ28+AM28 -> 0 | AQ28: =+M28+P28+S28+V28+Y28+AB28+AE28+AH28+AK28+AN28 -> 0 | BD28: 200 | BE28: 2660 | BF28: 2004.8 | BV28: =+AO28+AR28+AU28+AX28+BA28+BD28+BG28+BJ28+BM28+BP28+BS28 -> 200 | BW28: =+AP28+AS28+AV28+AY28+BB28+BE28+BH28+BK28+BN28+BQ28+BT28 -> 2660 | BX28: =+AQ28+AT28+AW28+AZ28+BC28+BF28+BI28+BL28+BO28+BR28+BU28 -> 2004.8 | DF28: =BV28+CB28+CE28+CH28+CK28+CN28+CQ28+CT28+CW28+CZ28+DC28+BY28 -> 200 | DG28: =BW28+CC28+CF28+CI28+CL28+CO28+CR28+CU28+CX28+DA28+DD28+BZ28 -> 2660 | DH28: =BX28+CD28+CG28+CJ28+CM28+CP28+CS28+CV28+CY28+DB28+DE28+CA28 -> 2004.8
A29: 7 | B29: တော်၀င် | C29: Taw Win | D29: မော်လမြိုင် | E29: Belin | F29: Semi WS | AO29: =+K29+N29+Q29+T29+W29+Z29+AC29+AF29+AI29+AL29 -> 0 | AP29: =+L29+O29+R29+U29+X29+AA29+AD29+AG29+AJ29+AM29 -> 0 | AQ29: =+M29+P29+S29+V29+Y29+AB29+AE29+AH29+AK29+AN29 -> 0 | BV29: =+AO29+AR29+AU29+AX29+BA29+BD29+BG29+BJ29+BM29+BP29+BS29 -> 0 | BW29: =+AP29+AS29+AV29+AY29+BB29+BE29+BH29+BK29+BN29+BQ29+BT29 -> 0 | BX29: =+AQ29+AT29+AW29+AZ29+BC29+BF29+BI29+BL29+BO29+BR29+BU29 -> 0 | CZ29: 210 | DA29: 2920 | DB29: 1876 | DF29: =BV29+CB29+CE29+CH29+CK29+CN29+CQ29+CT29+CW29+CZ29+DC29+BY29 -> 210 | DG29: =BW29+CC29+CF29+CI29+CL29+CO29+CR29+CU29+CX29+DA29+DD29+BZ29 -> 2920 | DH29: =BX29+CD29+CG29+CJ29+CM29+CP29+CS29+CV29+CY29+DB29+DE29+CA29 -> 1876
A30: 8 | B30: မမော် | C30: Ma Maw | D30: မုဒုံမြို့ | E30: Hpa-an | F30: Semi WS | Z30: 70 | AA30: 840 | AB30: 840 | AO30: =+K30+N30+Q30+T30+W30+Z30+AC30+AF30+AI30+AL30 -> 70 | AP30: =+L30+O30+R30+U30+X30+AA30+AD30+AG30+AJ30+AM30 -> 840 | AQ30: =+M30+P30+S30+V30+Y30+AB30+AE30+AH30+AK30+AN30 -> 840 | BV30: =+AO30+AR30+AU30+AX30+BA30+BD30+BG30+BJ30+BM30+BP30+BS30 -> 70 | BW30: =+AP30+AS30+AV30+AY30+BB30+BE30+BH30+BK30+BN30+BQ30+BT30 -> 840 | BX30: =+AQ30+AT30+AW30+AZ30+BC30+BF30+BI30+BL30+BO30+BR30+BU30 -> 840 | DF30: =BV30+CB30+CE30+CH30+CK30+CN30+CQ30+CT30+CW30+CZ30+DC30+BY30 -> 70 | DG30: =BW30+CC30+CF30+CI30+CL30+CO30+CR30+CU30+CX30+DA30+DD30+BZ30 -> 840 | DH30: =BX30+CD30+CG30+CJ30+CM30+CP30+CS30+CV30+CY30+DB30+DE30+CA30 -> 840
A31: 9 | B31: မ‌ချော | C31: Ma Chaw | D31: မုဒုံမြို့ | E31: Yay | F31: Semi WS | G31: ဖူးငုံစိုး | H31: Phoo Ngone Soe | I31: 09-798788870 | J31: RSM | AO31: =+K31+N31+Q31+T31+W31+Z31+AC31+AF31+AI31+AL31 -> 0 | AP31: =+L31+O31+R31+U31+X31+AA31+AD31+AG31+AJ31+AM31 -> 0 | AQ31: =+M31+P31+S31+V31+Y31+AB31+AE31+AH31+AK31+AN31 -> 0 | BV31: =+AO31+AR31+AU31+AX31+BA31+BD31+BG31+BJ31+BM31+BP31+BS31 -> 0 | BW31: =+AP31+AS31+AV31+AY31+BB31+BE31+BH31+BK31+BN31+BQ31+BT31 -> 0 | BX31: =+AQ31+AT31+AW31+AZ31+BC31+BF31+BI31+BL31+BO31+BR31+BU31 -> 0 | CB31: 200 | CC31: 2400 | CD31: 2400 | DF31: =BV31+CB31+CE31+CH31+CK31+CN31+CQ31+CT31+CW31+CZ31+DC31+BY31 -> 200 | DG31: =BW31+CC31+CF31+CI31+CL31+CO31+CR31+CU31+CX31+DA31+DD31+BZ31 -> 2400 | DH31: =BX31+CD31+CG31+CJ31+CM31+CP31+CS31+CV31+CY31+DB31+DE31+CA31 -> 2400
A32: 10 | B32: ဒေါ်စိန် | C32: Daw Sein | D32: ဘားအံ | E32: Thein Zayet | F32: Semi WS | G32: ထိန်လင်း | H32: Htein Lin | I32: 09-443988251 | J32: RSM | AO32: =+K32+N32+Q32+T32+W32+Z32+AC32+AF32+AI32+AL32 -> 0 | AP32: =+L32+O32+R32+U32+X32+AA32+AD32+AG32+AJ32+AM32 -> 0 | AQ32: =+M32+P32+S32+V32+Y32+AB32+AE32+AH32+AK32+AN32 -> 0 | BV32: =+AO32+AR32+AU32+AX32+BA32+BD32+BG32+BJ32+BM32+BP32+BS32 -> 0 | BW32: =+AP32+AS32+AV32+AY32+BB32+BE32+BH32+BK32+BN32+BQ32+BT32 -> 0 | BX32: =+AQ32+AT32+AW32+AZ32+BC32+BF32+BI32+BL32+BO32+BR32+BU32 -> 0 | CB32: 100 | CC32: 1300 | CD32: 1048 | DF32: =BV32+CB32+CE32+CH32+CK32+CN32+CQ32+CT32+CW32+CZ32+DC32+BY32 -> 100 | DG32: =BW32+CC32+CF32+CI32+CL32+CO32+CR32+CU32+CX32+DA32+DD32+BZ32 -> 1300 | DH32: =BX32+CD32+CG32+CJ32+CM32+CP32+CS32+CV32+CY32+DB32+DE32+CA32 -> 1048
A33: 11 | B33: ကိုဇော်လင်းမြတ် | C33: Ko Zaw Lin Myat | D33: မော်လမြိုင် | E33: Yay | F33: Semi WS | G33: ပြည့်ဖြိုးမောင် | H33: Pyae Phyo Maung | I33: 09-679797489 | J33: RSM | AO33: =+K33+N33+Q33+T33+W33+Z33+AC33+AF33+AI33+AL33 -> 0 | AP33: =+L33+O33+R33+U33+X33+AA33+AD33+AG33+AJ33+AM33 -> 0 | AQ33: =+M33+P33+S33+V33+Y33+AB33+AE33+AH33+AK33+AN33 -> 0 | BV33: =+AO33+AR33+AU33+AX33+BA33+BD33+BG33+BJ33+BM33+BP33+BS33 -> 0 | BW33: =+AP33+AS33+AV33+AY33+BB33+BE33+BH33+BK33+BN33+BQ33+BT33 -> 0 | BX33: =+AQ33+AT33+AW33+AZ33+BC33+BF33+BI33+BL33+BO33+BR33+BU33 -> 0 | CN33: 50 | CO33: 600 | CP33: 600 | DF33: =BV33+CB33+CE33+CH33+CK33+CN33+CQ33+CT33+CW33+CZ33+DC33+BY33 -> 50 | DG33: =BW33+CC33+CF33+CI33+CL33+CO33+CR33+CU33+CX33+DA33+DD33+BZ33 -> 600 | DH33: =BX33+CD33+CG33+CJ33+CM33+CP33+CS33+CV33+CY33+DB33+DE33+CA33 -> 600
A34: 12 | B34: စိတ်တိုင်းကျ | C34: Sate Tine Kya | D34: မော်လမြိုင် | E34: Hpa-an | F34: Semi WS | G34: ဖူးငုံစိုး | H34: Phoo Ngone Soe | I34: 09-798788870 | J34: RSM | AO34: =+K34+N34+Q34+T34+W34+Z34+AC34+AF34+AI34+AL34 -> 0 | AP34: =+L34+O34+R34+U34+X34+AA34+AD34+AG34+AJ34+AM34 -> 0 | AQ34: =+M34+P34+S34+V34+Y34+AB34+AE34+AH34+AK34+AN34 -> 0 | BA34: 204 | BB34: 2856 | BC34: 1827.84 | BV34: =+AO34+AR34+AU34+AX34+BA34+BD34+BG34+BJ34+BM34+BP34+BS34 -> 204 | BW34: =+AP34+AS34+AV34+AY34+BB34+BE34+BH34+BK34+BN34+BQ34+BT34 -> 2856 | BX34: =+AQ34+AT34+AW34+AZ34+BC34+BF34+BI34+BL34+BO34+BR34+BU34 -> 1827.84 | DF34: =BV34+CB34+CE34+CH34+CK34+CN34+CQ34+CT34+CW34+CZ34+DC34+BY34 -> 204 | DG34: =BW34+CC34+CF34+CI34+CL34+CO34+CR34+CU34+CX34+DA34+DD34+BZ34 -> 2856 | DH34: =BX34+CD34+CG34+CJ34+CM34+CP34+CS34+CV34+CY34+DB34+DE34+CA34 -> 1827.84
A35: 13 | B35: ဒေါ်မိစိန် | C35: Daw Mi Sen | D35: မော်လမြိုင် | E35: Yay | F35: Semi WS | G35: ထိန်လင်း | H35: Htein Lin | I35: 09-443988251 | AO35: =+K35+N35+Q35+T35+W35+Z35+AC35+AF35+AI35+AL35 -> 0 | AP35: =+L35+O35+R35+U35+X35+AA35+AD35+AG35+AJ35+AM35 -> 0 | AQ35: =+M35+P35+S35+V35+Y35+AB35+AE35+AH35+AK35+AN35 -> 0 | AX35: 50 | AY35: 640 | AZ35: 539.2 | BP35: 80 | BQ35: 1020 | BR35: 868.8 | BV35: =+AO35+AR35+AU35+AX35+BA35+BD35+BG35+BJ35+BM35+BP35+BS35 -> 130 | BW35: =+AP35+AS35+AV35+AY35+BB35+BE35+BH35+BK35+BN35+BQ35+BT35 -> 1660 | BX35: =+AQ35+AT35+AW35+AZ35+BC35+BF35+BI35+BL35+BO35+BR35+BU35 -> 1408 | DF35: =BV35+CB35+CE35+CH35+CK35+CN35+CQ35+CT35+CW35+CZ35+DC35+BY35 -> 130 | DG35: =BW35+CC35+CF35+CI35+CL35+CO35+CR35+CU35+CX35+DA35+DD35+BZ35 -> 1660 | DH35: =BX35+CD35+CG35+CJ35+CM35+CP35+CS35+CV35+CY35+DB35+DE35+CA35 -> 1408
A36: 14 | B36: ကိုရှမ်း | C36: Ko Shan | D36: မုဒုံမြို့ | E36: Yay | F36: Semi WS | AO36: =+K36+N36+Q36+T36+W36+Z36+AC36+AF36+AI36+AL36 -> 0 | AP36: =+L36+O36+R36+U36+X36+AA36+AD36+AG36+AJ36+AM36 -> 0 | AQ36: =+M36+P36+S36+V36+Y36+AB36+AE36+AH36+AK36+AN36 -> 0 | BV36: =+AO36+AR36+AU36+AX36+BA36+BD36+BG36+BJ36+BM36+BP36+BS36 -> 0 | BW36: =+AP36+AS36+AV36+AY36+BB36+BE36+BH36+BK36+BN36+BQ36+BT36 -> 0 | BX36: =+AQ36+AT36+AW36+AZ36+BC36+BF36+BI36+BL36+BO36+BR36+BU36 -> 0 | DC36: 100 | DD36: 1400 | DE36: 896 | DF36: =BV36+CB36+CE36+CH36+CK36+CN36+CQ36+CT36+CW36+CZ36+DC36+BY36 -> 100 | DG36: =BW36+CC36+CF36+CI36+CL36+CO36+CR36+CU36+CX36+DA36+DD36+BZ36 -> 1400 | DH36: =BX36+CD36+CG36+CJ36+CM36+CP36+CS36+CV36+CY36+DB36+DE36+CA36 -> 896
A37: 15 | B37: မစန္ဒာ | C37: Ma Sandar | D37: ချောင်းဆုံမြို့ | E37: Hpa-an | F37: Semi WS | AO37: =+K37+N37+Q37+T37+W37+Z37+AC37+AF37+AI37+AL37 -> 0 | AP37: =+L37+O37+R37+U37+X37+AA37+AD37+AG37+AJ37+AM37 -> 0 | AQ37: =+M37+P37+S37+V37+Y37+AB37+AE37+AH37+AK37+AN37 -> 0 | BP37: 200 | BQ37: 2600 | BR37: 2096 | BV37: =+AO37+AR37+AU37+AX37+BA37+BD37+BG37+BJ37+BM37+BP37+BS37 -> 200 | BW37: =+AP37+AS37+AV37+AY37+BB37+BE37+BH37+BK37+BN37+BQ37+BT37 -> 2600 | BX37: =+AQ37+AT37+AW37+AZ37+BC37+BF37+BI37+BL37+BO37+BR37+BU37 -> 2096 | DF37: =BV37+CB37+CE37+CH37+CK37+CN37+CQ37+CT37+CW37+CZ37+DC37+BY37 -> 200 | DG37: =BW37+CC37+CF37+CI37+CL37+CO37+CR37+CU37+CX37+DA37+DD37+BZ37 -> 2600 | DH37: =BX37+CD37+CG37+CJ37+CM37+CP37+CS37+CV37+CY37+DB37+DE37+CA37 -> 2096
A38: 16 | B38: ကိုအောင်နိုင်ဦး | C38: Ko Aung Naing Oo | D38: မုဒုံမြို့ | E38: Mudon | F38: Semi WS | AO38: =+K38+N38+Q38+T38+W38+Z38+AC38+AF38+AI38+AL38 -> 0 | AP38: =+L38+O38+R38+U38+X38+AA38+AD38+AG38+AJ38+AM38 -> 0 | AQ38: =+M38+P38+S38+V38+Y38+AB38+AE38+AH38+AK38+AN38 -> 0 | BV38: =+AO38+AR38+AU38+AX38+BA38+BD38+BG38+BJ38+BM38+BP38+BS38 -> 0 | BW38: =+AP38+AS38+AV38+AY38+BB38+BE38+BH38+BK38+BN38+BQ38+BT38 -> 0 | BX38: =+AQ38+AT38+AW38+AZ38+BC38+BF38+BI38+BL38+BO38+BR38+BU38 -> 0 | CB38: 100 | CC38: 1400 | CD38: 896 | DF38: =BV38+CB38+CE38+CH38+CK38+CN38+CQ38+CT38+CW38+CZ38+DC38+BY38 -> 100 | DG38: =BW38+CC38+CF38+CI38+CL38+CO38+CR38+CU38+CX38+DA38+DD38+BZ38 -> 1400 | DH38: =BX38+CD38+CG38+CJ38+CM38+CP38+CS38+CV38+CY38+DB38+DE38+CA38 -> 896
A39: 17 | B39: ဦးပြည်အေး | C39: U Pyi Aye | D39: မုဒုံမြို့ | E39: Paung | F39: Semi WS | AO39: =+K39+N39+Q39+T39+W39+Z39+AC39+AF39+AI39+AL39 -> 0 | AP39: =+L39+O39+R39+U39+X39+AA39+AD39+AG39+AJ39+AM39 -> 0 | AQ39: =+M39+P39+S39+V39+Y39+AB39+AE39+AH39+AK39+AN39 -> 0 | AX39: 100 | AY39: 1400 | AZ39: 896 | BV39: =+AO39+AR39+AU39+AX39+BA39+BD39+BG39+BJ39+BM39+BP39+BS39 -> 100 | BW39: =+AP39+AS39+AV39+AY39+BB39+BE39+BH39+BK39+BN39+BQ39+BT39 -> 1400 | BX39: =+AQ39+AT39+AW39+AZ39+BC39+BF39+BI39+BL39+BO39+BR39+BU39 -> 896 | DF39: =BV39+CB39+CE39+CH39+CK39+CN39+CQ39+CT39+CW39+CZ39+DC39+BY39 -> 100 | DG39: =BW39+CC39+CF39+CI39+CL39+CO39+CR39+CU39+CX39+DA39+DD39+BZ39 -> 1400 | DH39: =BX39+CD39+CG39+CJ39+CM39+CP39+CS39+CV39+CY39+DB39+DE39+CA39 -> 896
A40: 18 | B40: မသီတာ၀င်း | C40: Ma Thida Win | D40: ကျိုက်ထိုမြို့ | E40: Mudon | F40: Semi WS | AC40: 49 | AD40: 686 | AE40: 439.04 | AO40: =+K40+N40+Q40+T40+W40+Z40+AC40+AF40+AI40+AL40 -> 49 | AP40: =+L40+O40+R40+U40+X40+AA40+AD40+AG40+AJ40+AM40 -> 686 | AQ40: =+M40+P40+S40+V40+Y40+AB40+AE40+AH40+AK40+AN40 -> 439.04 | BD40: 25 | BE40: 350 | BF40: 224 | BV40: =+AO40+AR40+AU40+AX40+BA40+BD40+BG40+BJ40+BM40+BP40+BS40 -> 74 | BW40: =+AP40+AS40+AV40+AY40+BB40+BE40+BH40+BK40+BN40+BQ40+BT40 -> 1036 | BX40: =+AQ40+AT40+AW40+AZ40+BC40+BF40+BI40+BL40+BO40+BR40+BU40 -> 663.04 | CB40: 25 | CC40: 350 | CD40: 224 | CQ40: 25 | CR40: 350 | CS40: 224 | DC40: 25 | DD40: 350 | DE40: 224 | DF40: =BV40+CB40+CE40+CH40+CK40+CN40+CQ40+CT40+CW40+CZ40+DC40+BY40 -> 149 | DG40: =BW40+CC40+CF40+CI40+CL40+CO40+CR40+CU40+CX40+DA40+DD40+BZ40 -> 2086 | DH40: =BX40+CD40+CG40+CJ40+CM40+CP40+CS40+CV40+CY40+DB40+DE40+CA40 -> 1335.04
A41: 19 | B41: A1 | C41: A1 | D41: မော်လမြိုင် | E41: Maw La Myaing | F41: Semi WS | AL41: 35 | AM41: 470 | AN41: 344 | AO41: =+K41+N41+Q41+T41+W41+Z41+AC41+AF41+AI41+AL41 -> 35 | AP41: =+L41+O41+R41+U41+X41+AA41+AD41+AG41+AJ41+AM41 -> 470 | AQ41: =+M41+P41+S41+V41+Y41+AB41+AE41+AH41+AK41+AN41 -> 344 | BP41: 40 | BQ41: 530 | BR41: 404 | BV41: =+AO41+AR41+AU41+AX41+BA41+BD41+BG41+BJ41+BM41+BP41+BS41 -> 75 | BW41: =+AP41+AS41+AV41+AY41+BB41+BE41+BH41+BK41+BN41+BQ41+BT41 -> 1000 | BX41: =+AQ41+AT41+AW41+AZ41+BC41+BF41+BI41+BL41+BO41+BR41+BU41 -> 748 | CW41: 35 | CX41: 470 | CY41: 344 | DF41: =BV41+CB41+CE41+CH41+CK41+CN41+CQ41+CT41+CW41+CZ41+DC41+BY41 -> 110 | DG41: =BW41+CC41+CF41+CI41+CL41+CO41+CR41+CU41+CX41+DA41+DD41+BZ41 -> 1470 | DH41: =BX41+CD41+CG41+CJ41+CM41+CP41+CS41+CV41+CY41+DB41+DE41+CA41 -> 1092
A42: 20 | B42: KP | C42: KP | D42: မော်လမြိုင် | E42: Maw La Myaing | F42: Semi WS | AO42: =+K42+N42+Q42+T42+W42+Z42+AC42+AF42+AI42+AL42 -> 0 | AP42: =+L42+O42+R42+U42+X42+AA42+AD42+AG42+AJ42+AM42 -> 0 | AQ42: =+M42+P42+S42+V42+Y42+AB42+AE42+AH42+AK42+AN42 -> 0 | BA42: 0.5 | BB42: 6 | BC42: 6 | BS42: 5 | BT42: 60 | BU42: 60 | BV42: =+AO42+AR42+AU42+AX42+BA42+BD42+BG42+BJ42+BM42+BP42+BS42 -> 5.5 | BW42: =+AP42+AS42+AV42+AY42+BB42+BE42+BH42+BK42+BN42+BQ42+BT42 -> 66 | BX42: =+AQ42+AT42+AW42+AZ42+BC42+BF42+BI42+BL42+BO42+BR42+BU42 -> 66 | DF42: =BV42+CB42+CE42+CH42+CK42+CN42+CQ42+CT42+CW42+CZ42+DC42+BY42 -> 5.5 | DG42: =BW42+CC42+CF42+CI42+CL42+CO42+CR42+CU42+CX42+DA42+DD42+BZ42 -> 66 | DH42: =BX42+CD42+CG42+CJ42+CM42+CP42+CS42+CV42+CY42+DB42+DE42+CA42 -> 66
...

Sheet MLM FU
I1: Target | J1: Q1 | M1: Q2 | P1: Q3 | S1: Q4 | V1: 2026 Total
J2: January | K2: February | L2: March | M2: April | N2: May | O2: June | P2: July | Q2: August | R2: September | S2: October | T2: Novermber | U2: December
I3: Target (BOT) | J3: 350249.1 | K3: 350249.1 | L3: 350249.1 | M3: 323306.86 | N3: 323306.86 | O3: 323306.86 | P3: 336777.98 | Q3: 336777.98 | R3: 336777.98 | S3: 336777.98 | T3: 336777.98 | U3: 336777.98 | V3: =SUM(J3:U3) -> 4041335.7
I4: Target (Liters) | J4: 261295.08 | K4: 261295.08 | L4: 261295.08 | M4: 241195.46 | N4: 241195.46 | O4: 241195.46 | P4: 251245.27 | Q4: 251245.27 | R4: 251245.27 | S4: 251245.27 | T4: 251245.27 | U4: 251245.27 | V4: =SUM(J4:U4) -> 3014943.2
H5: 0.75027824 | I5: WS | J5: =+O35 -> 209394 | K5: =+X35 -> 209092 | L5: =+AG35 -> 166192 | M5: =+AU35 -> 0 | N5: =+BD35 -> 0 | O5: =BM35 -> 0 | P5: =+CA35 -> 0 | Q5: =+CJ35 -> 0 | R5: =+CS35 -> 0 | S5: =+DG35 -> 0 | T5: =+DP35 -> 0 | U5: =+DY35 -> 0 | V5: =SUM(J5:U5) -> 584678
H6: 0.16624611 | I6: SWS | J6: =+O65 -> 45078 | K6: =+X65 -> 43254 | L6: =+AG65 -> 60358 | M6: =+AU65 -> 0 | N6: =+BD65 -> 0 | O6: =BM65 -> 0 | P6: =+CA65 -> 0 | Q6: =+CJ65 -> 0 | R6: =+CS65 -> 0 | S6: =+DG65 -> 0 | T6: =+DP65 -> 0 | U6: =+DY65 -> 0 | V6: =SUM(J6:U6) -> 148690
H7: 0.037669226 | I7: Mini | J7: =+O86 -> 11242 | K7: =+X86 -> 8236 | L7: =+AG86 -> 11306 | M7: =+AU86 -> 0 | N7: =+BD86 -> 0 | O7: =BM86 -> 0 | P7: =+CA86 -> 0 | Q7: =+CJ86 -> 0 | R7: =+CS86 -> 0 | S7: =+DG86 -> 0 | T7: =+DP86 -> 0 | U7: =+DY86 -> 0 | V7: =SUM(J7:U7) -> 30784
H8: 0.045806423 | I8: Van | J8: =+O93 -> 33461 | K8: =+X93 -> 25317 | L8: =+AG93 -> 31645 | M8: =+AU93 -> 0 | N8: =+BD93 -> 0 | O8: =BM93 -> 0 | P8: =+CA93 -> 0 | Q8: =+CJ93 -> 0 | R8: =+CS93 -> 0 | S8: =+DG93 -> 0 | T8: =+DP93 -> 0 | U8: =+DY93 -> 0 | V8: =SUM(J8:U8) -> 90423
I9: Total Sales(BOT) | J9: =SUM(J5:J8) -> 299175 | K9: =SUM(K5:K8) -> 285899 | L9: =SUM(L5:L8) -> 269501 | M9: =SUM(M5:M8) -> 0 | N9: =SUM(N5:N8) -> 0 | O9: =SUM(O5:O8) -> 0 | P9: =SUM(P5:P8) -> 0 | Q9: =SUM(Q5:Q8) -> 0 | ... V9: =SUM(V5:V8) -> 854575
I10: Total Sales(Liters) | J10: =+P35+P65+P86+P93 -> 233525.95 | K10: =+Y35+Y65+Y86+Y93 -> 221678.61 | L10: =+AH93+AH86+AH65+AH35 -> 214103.73 | M10: =+AV35+AV65+AV86+AV93 -> 0 | N10: =+BE35+BE65+BE86+BE93 -> 0 | O10: =BN35+BN65+BN86+BN93 -> 0 | P10: =+CB35+CB65+CB86+CB93 -> 0 | Q10: =+CK35+CK65+CK86+CK93 -> 0 | R10: =+CT35+CT65+CT86+CT93 -> 0 | S10: =+DH35+DH65+DH86+DH93 -> 0 | T10: =+DQ35+DQ65+DQ86+DQ93 -> 0 | U10: =+DZ35+DZ65+DZ86+DZ93 -> 0 | V10: =SUM(J10:U10) -> 669308.29
I11: Ach % (BOT) | J11: =+J9/J3 -> 0.85417779 | K11: =+K9/K3 -> 0.81627334 | L11: =+L9/L3 -> 0.76945523 | M11: =+M9/M3 -> 0 | N11: =+N9/N3 -> 0 | O11: =+O9/O3 -> 0 | P11: =+P9/P3 -> 0 | Q11: =+Q9/Q3 -> 0 | ... U11: =+U9/U3 -> 0 | V11: =IFERROR((V9/V3),0) -> 0.21145855
I12: Ach % (Liters) | J12: =+J10/J4 -> 0.89372502 | K12: =+K10/K4 -> 0.84838417 | L12: =+L10/L4 -> 0.81939442 | M12: =+M10/M4 -> 0 | N12: =+N10/N4 -> 0 | O12: =+O10/O4 -> 0 | P12: =+P10/P4 -> 0 | Q12: =+Q10/Q4 -> 0 | ... U12: =+U10/U4 -> 0 | V12: =IFERROR((V10/V4),0) -> 0.22199698
I14: =+I17+I39+I70+I90-J4 -> 0 | R14: =+R17+R39+R70+R90-J4 -> 0 | AA14: =+AA17+AA39+AA70+AA90-J4 -> 0 | AO14: =+AO17+AO39+AO70+AO90-M3 -> -323306.86 | AX14: =+AX17+AX39+AX70+AX90-N3 -> -323306.86 | BG14: =+BG17+BG39+BG70+BG90-O3 -> -323306.86 | BU14: =+BU17+BU39+BU70+BU90-P3 -> -336777.98 | CD14: =+CD17+CD39+CD70+CD90-Q3 -> -336777.98 | CM14: =+CM17+CM39+CM70+CM90-R3 -> -336777.98 | DA14: =+DA17+DA39+DA70+DA90-S3 -> -336777.98 | DJ14: =+DJ17+DJ39+DJ70+DJ90-T3 -> -336777.98 | DS14: =+DS17+DS39+DS70+DS90-U3 -> -336777.98
I15: Quarter 1 | AO15: Quarter 2 | BU15: Quarter 3 | DA15: Quarter 4
B16: Wholesales Follow Up - (MLM) | I16: 46023 | R16: 46054 | AA16: 46082 | AJ16: Q1 Total | AO16: 46113 | AX16: 46143 | BG16: 46174 | BP16: Q2 Total | BU16: 46204 | CD16: 46235 | CM16: 46266 | CV16: Q3 Total | DA16: 46296 | DJ16: 46327 | DS16: 46357 | EB16: Q4 Total
I17: =J4*H5 -> 196044.01 | K17: 10 | M17: 20 | O17: 30 | Q17: ACH% | R17: =J4*H5 -> 196044.01 | T17: 10 | V17: 20 | X17: 30 | Z17: ACH% | AA17: =J4*H5 -> 196044.01 | AC17: 10 | AE17: 20 | AG17: 30 | AI17: ACH% | AJ17: Target | AK17: Sales | AL17: Ach % | AQ17: 10 | AS17: 20 | AU17: 30 | AW17: Ach % | AZ17: 10 | BB17: 20 | BD17: 31 | BF17: Ach % | BI17: 10 | BK17: 20 | BM17: 30 | BO17: Ach % | BP17: Target | BQ17: Sales | BR17: Ach % | BW17: 10 | BY17: 20 | CA17: 30 | CC17: Ach % | CF17: 10 | CH17: 20 | CJ17: 30 | CL17: Ach % | CO17: 10 | CQ17: 20 | CS17: 30 | CU17: Ach % | CV17: Target | CW17: Sales | CX17: Ach % | DC17: 10 | DE17: 20 | DG17: 30 | DI17: Ach % | DL17: 10 | DN17: 20 | DP17: 30 | DR17: Ach % | DU17: 10 | DW17: 20 | DY17: 30 | EA17: Ach % | EB17: Target | EC17: Sales | ED17: Ach %
A18: Sr No. | B18: Customer Name | D18: Area | F18: Outlet Type | G18: Cons% | H18: Resp by | I18: Bottle | J18: Liter | K18: Bottle | L18: Liter | M18: Bottle | N18: Liter | O18: Bottle | P18: Liter | Q18: Liter | R18: Bottle | S18: Liter | T18: Bottle | U18: Liter | V18: Bottle | W18: Liter | X18: Bottle | Y18: Liter | Z18: Liter | AA18: Bottle | AB18: Liter | AC18: Bottle | AD18: Liter | AE18: Bottle | AF18: Liter | AG18: Bottle | AH18: Liter | AI18: Liter | AJ18: Liter | AK18: Liter | AN18: Cons% | AO18: PKT | AP18: Bottle | AQ18: Bottle | AR18: Ltr | AS18: Bottle | AT18: Ltr | AU18: Bottle | AV18: Ltr | AW18: Bottle | AX18: PKT | AY18: Bottle | AZ18: Bottle | BA18: Ltr | BB18: Bottle | BC18: Ltr | BD18: Bottle | BE18: Ltr | BF18: Bottle | BG18: PKT | BH18: Bottle | BI18: Bottle | BJ18: Ltr | BK18: Bottle | BL18: Ltr | BM18: Bottle | BN18: Ltr | BO18: Bottle | BP18: Bottle | BQ18: Bottle | BR18: Bottle | BT18: Cons% | BU18: PKT | BV18: Bottle | BW18: Bottle | BX18: Ltr | BY18: Bottle | BZ18: Ltr | CA18: Bottle | CB18: Ltr | CC18: Bottle | CD18: PKT | CE18: Bottle | CF18: Bottle | CG18: Ltr | CH18: Bottle | CI18: Ltr | CJ18: Bottle | CK18: Ltr | CL18: Bottle | CM18: PKT | CN18: Bottle | CO18: Bottle | CP18: Ltr | CQ18: Bottle | CR18: Ltr | CS18: Bottle | CT18: Ltr | CU18: Bottle | CV18: Bottle | CW18: Bottle | CX18: Bottle | CZ18: Cons% | DA18: PKT | DB18: Bottle | DC18: Bottle | DD18: Ltr | DE18: Bottle | DF18: Ltr | DG18: Bottle | DH18: Ltr | DI18: Bottle | DJ18: PKT | DK18: Bottle | DL18: Bottle | DM18: Ltr | DN18: Bottle | DO18: Ltr | DP18: Bottle | DQ18: Ltr | DR18: Bottle | DS18: PKT | DT18: Bottle | DU18: Bottle | DV18: Ltr | DW18: Bottle | DX18: Ltr | DY18: Bottle | DZ18: Ltr | EA18: Bottle | EB18: Bottle | EC18: Bottle | ED18: Bottle
A19: 1 | B19: ကျော်စတား | C19: Kyaw Star | D19: ရေးမြို့ | E19: Yaye | F19: WholeSales | G19: 0.37131125 | I19: 97574.759 | J19: =I17*G19 -> 72793.348 | K19: 21030 | L19: 16267.2 | M19: ='FUS-Working'!BW5 -> 52990 | N19: ='FUS-Working'!BX5 -> 41171.2 | O19: ='FUS-Working'!DG5 -> 85150 | P19: ='FUS-Working'!DH5 -> 67132 | Q19: =IFERROR((P19/J19),0) -> 0.92222712 | R19: 97574.759 | S19: =R17*G19 -> 72793.348 | T19: ='FUS-Working'!DG77 -> 78590 | U19: ='FUS-Working'!DH77 -> 61983.2 | V19: ='FUS-Working'!DG77 -> 78590 | W19: ='FUS-Working'!DH77 -> 61983.2 | X19: ='FUS-Working'!DG77 -> 78590 | Y19: ='FUS-Working'!DH77 -> 61983.2 | Z19: =IFERROR((Y19/S19),0) -> 0.85149539 | AA19: 97574.759 | AB19: 72793.348 | AC19: =+'FUS-Working'!AP148 -> 35070 | AD19: =+'FUS-Working'!AQ148 -> 28190.4 | AE19: ='FUS-Working'!BW148 -> 66130 | AF19: ='FUS-Working'!BX148 -> 52496.8 | AG19: ='FUS-Working'!DG148 -> 66130 | AH19: ='FUS-Working'!DH148 -> 52496.8 | AI19: =IFERROR((AH19/AB19),0) -> 0.72117579 | AJ19: =+AB19+S19+J19 -> 218380.04 | AK19: =P19+Y19+AH19 -> 181612 | AL19: =IFERROR((AK19/AJ19),0) -> 0.83163277 | AW19: =IFERROR((AU19/AP19),0) -> 0 | BF19: =IFERROR((BD19/AY19),0) -> 0 | BO19: =IFERROR((BM19/BH19),0) -> 0 | BP19: =+BH19+AY19+AP19 -> 0 | BQ19: =+BM19+BD19+AU19 -> 0 | BR19: =IFERROR((BQ19/BP19),0) -> 0 | CC19: =IFERROR((CA19/BV19),0) -> 0 | CL19: =IFERROR((CJ19/CE19),0) -> 0 | CU19: =IFERROR((CS19/CN19),0) -> 0 | CV19: =+CN19+CE19+BV19 -> 0 | CW19: =+CS19+CJ19+CA19 -> 0 | CX19: =IFERROR((CW19/CV19),0) -> 0 | DI19: =IFERROR((DG19/DB19),0) -> 0 | DR19: =IFERROR((DP19/DK19),0) -> 0 | EA19: =IFERROR((DY19/DT19),0) -> 0 | EB19: =+DT19+DK19+DB19 -> 0 | EC19: =+DY19+DP19+DG19 -> 0 | ED19: =IFERROR((EC19/EB19),0) -> 0
A20: 2 | B20: ဒေါ်နွယ်နွယ်ရီ(ရွှေတောင်ကြား) | C20: Daw New New Yi | D20: ရေးမြို့ | E20: Yayae | F20: WholeSales | G20: 0.17049091 | I20: 44802.331 | J20: 33423.723 | K20: 6400 | L20: 5392 | M20: ='FUS-Working'!BW6 -> 21200 | N20: ='FUS-Working'!BX6 -> 16160 | O20: ='FUS-Working'!DG6 -> 41200 | P20: ='FUS-Working'!DH6 -> 31120 | Q20: =IFERROR((P20/J20),0) -> 0.93107522 | R20: 44802.331 | S20: 33423.723 | T20: ='FUS-Working'!DG78 -> 33000 | U20: ='FUS-Working'!DH78 -> 25440 | V20: ='FUS-Working'!DG78 -> 33000 | W20: ='FUS-Working'!DH78 -> 25440 | X20: ='FUS-Working'!DG78 -> 33000 | Y20: ='FUS-Working'!DH78 -> 25440 | Z20: =IFERROR((Y20/S20),0) -> 0.76113604 | AA20: 44802.331 | AB20: 33423.723 | AC20: =+'FUS-Working'!AP149 -> 10600 | AD20: =+'FUS-Working'!AQ149 -> 8080 | AE20: ='FUS-Working'!BW149 -> 30600 | AF20: ='FUS-Working'!BX149 -> 23040 | AG20: ='FUS-Working'!DG149 -> 30600 | AH20: ='FUS-Working'!DH149 -> 23040 | AI20: =IFERROR((AH20/AB20),0) -> 0.68933075 | AJ20: =+AB20+S20+J20 -> 100271.17 | AK20: =P20+Y20+AH20 -> 79600 | AL20: =IFERROR((AK20/AJ20),0) -> 0.79384733 | AW20: =IFERROR((AU20/AP20),0) -> 0 | BF20: =IFERROR((BD20/AY20),0) -> 0 | BO20: =IFERROR((BM20/BH20),0) -> 0 | BP20: =+BH20+AY20+AP20 -> 0 | BQ20: =+BM20+BD20+AU20 -> 0 | BR20: =IFERROR((BQ20/BP20),0) -> 0 | CC20: =IFERROR((CA20/BV20),0) -> 0 | CL20: =IFERROR((CJ20/CE20),0) -> 0 | CU20: =IFERROR((CS20/CN20),0) -> 0 | CV20: =+CN20+CE20+BV20 -> 0 | CW20: =+CS20+CJ20+CA20 -> 0 | CX20: =IFERROR((CW20/CV20),0) -> 0 | DI20: =IFERROR((DG20/DB20),0) -> 0 | DR20: =IFERROR((DP20/DK20),0) -> 0 | EA20: =IFERROR((DY20/DT20),0) -> 0 | EB20: =+DT20+DK20+DB20 -> 0 | EC20: =+DY20+DP20+DG20 -> 0 | ED20: =IFERROR((EC20/EB20),0) -> 0
A21: 3 | B21: ပြည့်လျှံ | C21: Pyae Hlan | D21: မော်လမြိုင် | E21: Mawlamyaing | F21: WholeSales | G21: 0.10777756 | I21: 28322.25 | J21: 21129.147 | K21: 3800 | L21: 3296 | M21: ='FUS-Working'!BW7 -> 6400 | N21: ='FUS-Working'!BX7 -> 5392 | O21: ='FUS-Working'!DG7 -> 13000 | P21: ='FUS-Working'!DH7 -> 10480 | Q21: =IFERROR((P21/J21),0) -> 0.49599732 | R21: 28322.25 | S21: 21129.147 | T21: ='FUS-Working'!DG79 -> 18040 | U21: ='FUS-Working'!DH79 -> 14915.2 | V21: ='FUS-Working'!DG79 -> 18040 | W21: ='FUS-Working'!DH79 -> 14915.2 | X21: ='FUS-Working'!DG79 -> 18040 | Y21: ='FUS-Working'!DH79 -> 14915.2 | Z21: =IFERROR((Y21/S21),0) -> 0.70590641 | AA21: 28322.25 | AB21: 21129.147 | AC21: =+'FUS-Working'!AP150 -> 2400 | AD21: =+'FUS-Working'!AQ150 -> 2400 | AE21: ='FUS-Working'!BW150 -> 12700 | AF21: ='FUS-Working'!BX150 -> 10936 | AG21: ='FUS-Working'!DG150 -> 12700 | AH21: ='FUS-Working'!DH150 -> 10936 | AI21: =IFERROR((AH21/AB21),0) -> 0.51757888 | AJ21: =+AB21+S21+J21 -> 63387.44 | AK21: =P21+Y21+AH21 -> 36331.2 | AL21: =IFERROR((AK21/AJ21),0) -> 0.57316087 | AW21: =IFERROR((AU21/AP21),0) -> 0 | BF21: =IFERROR((BD21/AY21),0) -> 0 | BO21: =IFERROR((BM21/BH21),0) -> 0 | BP21: =+BH21+AY21+AP21 -> 0 | BQ21: =+BM21+BD21+AU21 -> 0 | BR21: =IFERROR((BQ21/BP21),0) -> 0 | CC21: =IFERROR((CA21/BV21),0) -> 0 | CL21: =IFERROR((CJ21/CE21),0) -> 0 | CU21: =IFERROR((CS21/CN21),0) -> 0 | CV21: =+CN21+CE21+BV21 -> 0 | CW21: =+CS21+CJ21+CA21 -> 0 | CX21: =IFERROR((CW21/CV21),0) -> 0 | DI21: =IFERROR((DG21/DB21),0) -> 0 | DR21: =IFERROR((DP21/DK21),0) -> 0 | EA21: =IFERROR((DY21/DT21),0) -> 0 | EB21: =+DT21+DK21+DB21 -> 0 | EC21: =+DY21+DP21+DG21 -> 0 | ED21: =IFERROR((EC21/EB21),0) -> 0
A22: 4 | B22: ကိုမျိုးအောင် | C22: Ko Myo Aung | D22: မော်လမြိုင် | E22: Mawlamyaing | F22: WholeSales | G22: 0.044480871 | I22: 11688.873 | J22: 8720.2084 | K22: 1640 | L22: 1136 | M22: ='FUS-Working'!BW8 -> 3410 | N22: ='FUS-Working'!BX8 -> 2528 | O22: ='FUS-Working'!DG8 -> 5310 | P22: ='FUS-Working'!DH8 -> 4176 | Q22: =IFERROR((P22/J22),0) -> 0.47888764 | R22: 11688.873 | S22: 8720.2084 | T22: ='FUS-Working'!DG80 -> 5130 | U22: ='FUS-Working'!DH80 -> 3844.8 | V22: ='FUS-Working'!DG80 -> 5130 | W22: ='FUS-Working'!DH80 -> 3844.8 | X22: ='FUS-Working'!DG80 -> 5130 | Y22: ='FUS-Working'!DH80 -> 3844.8 | Z22: =IFERROR((Y22/S22),0) -> 0.44090689 | AA22: 11688.873 | AB22: 8720.2084 | AC22: =+'FUS-Working'!AP151 -> 2616 | AD22: =+'FUS-Working'!AQ151 -> 1890.24 | AE22: ='FUS-Working'!BW151 -> 3956 | AF22: ='FUS-Working'!BX151 -> 2877.44 | AG22: ='FUS-Working'!DG151 -> 3956 | AH22: ='FUS-Working'!DH151 -> 2877.44 | AI22: =IFERROR((AH22/AB22),0) -> 0.32997376 | AJ22: =+AB22+S22+J22 -> 26160.625 | AK22: =P22+Y22+AH22 -> 10898.24 | AL22: =IFERROR((AK22/AJ22),0) -> 0.41658943 | AW22: =IFERROR((AU22/AP22),0) -> 0 | BF22: =IFERROR((BD22/AY22),0) -> 0 | BO22: =IFERROR((BM22/BH22),0) -> 0 | BP22: =+BH22+AY22+AP22 -> 0 | BQ22: =+BM22+BD22+AU22 -> 0 | BR22: =IFERROR((BQ22/BP22),0) -> 0 | CC22: =IFERROR((CA22/BV22),0) -> 0 | CL22: =IFERROR((CJ22/CE22),0) -> 0 | CU22: =IFERROR((CS22/CN22),0) -> 0 | CV22: =+CN22+CE22+BV22 -> 0 | CW22: =+CS22+CJ22+CA22 -> 0 | CX22: =IFERROR((CW22/CV22),0) -> 0 | DI22: =IFERROR((DG22/DB22),0) -> 0 | DR22: =IFERROR((DP22/DK22),0) -> 0 | EA22: =IFERROR((DY22/DT22),0) -> 0 | EB22: =+DT22+DK22+DB22 -> 0 | EC22: =+DY22+DP22+DG22 -> 0 | ED22: =IFERROR((EC22/EB22),0) -> 0
A23: 5 | B23: ကိုထိုက်စိုး | C23: Ko Htike Soe | D23: ရေးမြို့ | E23: Yaye | F23: WholeSales | G23: 0.035543497 | I23: 9340.2721 | J23: 6968.0898 | K23: 0 | L23: 0 | M23: ='FUS-Working'!BW9 -> 0 | N23: ='FUS-Working'!BX9 -> 0 | O23: ='FUS-Working'!DG9 -> 7400 | P23: ='FUS-Working'!DH9 -> 6896 | Q23: =IFERROR((P23/J23),0) -> 0.9896543 | R23: 9340.2721 | S23: 6968.0898 | T23: ='FUS-Working'!DG81 -> 6400 | U23: ='FUS-Working'!DH81 -> 5392 | V23: ='FUS-Working'!DG81 -> 6400 | W23: ='FUS-Working'!DH81 -> 5392 | X23: ='FUS-Working'!DG81 -> 6400 | Y23: ='FUS-Working'!DH81 -> 5392 | Z23: =IFERROR((Y23/S23),0) -> 0.77381322 | AA23: 9340.2721 | AB23: 6968.0898 | AC23: =+'FUS-Working'!AP152 -> 0 | AD23: =+'FUS-Working'!AQ152 -> 0 | AE23: ='FUS-Working'!BW152 -> 0 | AF23: ='FUS-Working'!BX152 -> 0 | AG23: ='FUS-Working'!DG152 -> 0 | AH23: ='FUS-Working'!DH152 -> 0 | AI23: =IFERROR((AH23/AB23),0) -> 0 | AJ23: =+AB23+S23+J23 -> 20904.269 | AK23: =P23+Y23+AH23 -> 12288 | AL23: =IFERROR((AK23/AJ23),0) -> 0.58782251 | AW23: =IFERROR((AU23/AP23),0) -> 0 | BF23: =IFERROR((BD23/AY23),0) -> 0 | BO23: =IFERROR((BM23/BH23),0) -> 0 | BP23: =+BH23+AY23+AP23 -> 0 | BQ23: =+BM23+BD23+AU23 -> 0 | BR23: =IFERROR((BQ23/BP23),0) -> 0 | CC23: =IFERROR((CA23/BV23),0) -> 0 | CL23: =IFERROR((CJ23/CE23),0) -> 0 | CU23: =IFERROR((CS23/CN23),0) -> 0 | CV23: =+CN23+CE23+BV23 -> 0 | CW23: =+CS23+CJ23+CA23 -> 0 | CX23: =IFERROR((CW23/CV23),0) -> 0 | DI23: =IFERROR((DG23/DB23),0) -> 0 | DR23: =IFERROR((DP23/DK23),0) -> 0 | EA23: =IFERROR((DY23/DT23),0) -> 0 | EB23: =+DT23+DK23+DB23 -> 0 | EC23: =+DY23+DP23+DG23 -> 0 | ED23: =IFERROR((EC23/EB23),0) -> 0
