Workbook
Name a: #REF!
Name aa: #REF!
Name aa: #REF!
Name aa: #REF!
Name aa: #REF!
Name aa: #REF!
Name aa: #REF!
Name aa: #REF!
Name aa: #REF!
Name aa: #REF!
Name aa: #REF!
Name aa: #REF!
Name aa: #REF!
Name aa: #REF!
Name aa: #REF!
Name aaa: #REF!
Name aaa: #REF!
Name aaa: #REF!
Name aaaaa: #REF!
Name aaaaaaa: #REF!
Name asd: '[1]Market ( Mar) '!#REF!
Name atr: #REF!
Name atr: #REF!
Name atr: #REF!
Name b: #REF!
Name b: #REF!
Name b: #REF!
Name bb: #REF!
Name bb: #REF!
Name bb: #REF!
Name Beg_Bal: #REF!
Name Beg_Bal: #REF!
Name Beg_Bal: #REF!
Name Cash_Cr: #REF!
Name Cash_Cr: #REF!
Name Cash_Cr: #REF!
Name Cash_Dr: #REF!
Name Cash_Dr: #REF!
Name Cash_Dr: #REF!
Name cc: #REF!
Name cc: #REF!
Name cc: #REF!
Name ccc: #REF!
Name ccc: #REF!
Name ccc: #REF!
Name cft: #REF!
Name cr: #REF!
Name cr: #REF!
Name cr: #REF!
Name crs: #REF!
Name crs: #REF!
Name crs: #REF!
Name cvvvv: #REF!
Name cwer: #REF!
Name Data: #REF!
Name Data: #REF!
Name Data: #REF!
Name dd: #REF!
Name dd: #REF!
Name dd: #REF!

Sheet 4-Township Summary
A1: Maw La Myaing Region ( Townwise Report ) (2024, 2025) (BE Bottle & Liter)
A2: No | B2: TownShip | D2: 45292 | F2: 45323 | H2: 45352 | J2: 45383 | L2: 45413 | N2: 45444 | P2: 45474 | R2: 45505 | T2: 45536 | V2: 45566 | X2: 45597 | Z2: 45627 | AB2: 2024 Total | AD2: Average - 2024 | AF2: 45658 | AH2: 45689 | AJ2: 45717 | AL2: 45748 | AN2: 45778 | AP2: 45809 | AR2: 45839 | AT2: 45870 | AV2: 45901 | AX2: 45931 | AZ2: 45962 | BB2: 45992 | BD2: 2025 Total | BF2: Average - 2025 | BH2: 46023 | BJ2: 46054 | BL2: 46082 | BN2: 46113 | BP2: 46143 | BR2: 46174 | BT2: 46204 | BV2: 46235 | BX2: 46266 | BZ2: 46296 | CB2: 46327 | CD2: 46357 | CF2: 2026 Total | CH2: Average | CJ2: Town wise Contribution | CK2: Contirbution wise Priority Town
D3: Bottle | E3: Liter | F3: Bottle | G3: Liter | H3: Bottle | I3: Liter | J3: Bottle | K3: Liter | L3: Bottle | M3: Liter | N3: Bottle | O3: Liter | P3: Bottle | Q3: Liter | R3: Bottle | S3: Liter | T3: Bottle | U3: Liter | V3: Bottle | W3: Liter | X3: Bottle | Y3: Liter | Z3: Bottle | AA3: Liter | AB3: Bottle | AC3: Liter | AD3: Bottle | AE3: Liter | AF3: Bottle | AG3: Liter | AH3: Bottle | AI3: Liter | AJ3: Bottle | AK3: Liter | AL3: Bottle | AM3: Liter | AN3: Bottle | AO3: Liter | AP3: Bottle | AQ3: Liter | AR3: Bottle | AS3: Liter | AT3: Bottle | AU3: Liter | AV3: Bottle | AW3: Liter | AX3: Bottle | AY3: Liter | AZ3: Bottle | BA3: Liter | BB3: Bottle | BC3: Liter | BD3: Bottle | BE3: Liter | BH3: Bottle | BI3: Liter | BJ3: Bottle | BK3: Liter | BL3: Bottle | BM3: Liter | BN3: Bottle | BO3: Liter | BP3: Bottle | BQ3: Liter | BR3: Bottle | BS3: Liter | BT3: Bottle | BU3: Liter | BV3: Bottle | BW3: Liter | BX3: Bottle | BY3: Liter | BZ3: Bottle | CA3: Liter | CB3: Bottle | CC3: Liter | CD3: Bottle | CE3: Liter | CF3: Bottle | CG3: Liter | CH3: Bottle | CI3: Liter
A4: 1 | B4: Maw La Myaing | D4: ='4-MawLaMyaing'!F19 -> 56202 | E4: ='4-MawLaMyaing'!G19 -> 38107.8 | F4: ='4-MawLaMyaing'!I19 -> 45514 | G4: ='4-MawLaMyaing'!J19 -> 30964.96 | H4: ='4-MawLaMyaing'!L19 -> 53936 | I4: ='4-MawLaMyaing'!M19 -> 35894.96 | J4: ='4-MawLaMyaing'!O19 -> 63394 | K4: ='4-MawLaMyaing'!P19 -> 43411.76 | L4: ='4-MawLaMyaing'!R19 -> 63813 | M4: ='4-MawLaMyaing'!S19 -> 43308.06 | N4: ='4-MawLaMyaing'!U19 -> 71716 | O4: ='4-MawLaMyaing'!V19 -> 50823.76 | P4: ='4-MawLaMyaing'!X19 -> 64060 | Q4: ='4-MawLaMyaing'!Y19 -> 45375.28 | R4: ='4-MawLaMyaing'!AA19 -> 71562 | S4: ='4-MawLaMyaing'!AB19 -> 49290.24 | T4: ='4-MawLaMyaing'!AD19 -> 53115 | U4: ='4-MawLaMyaing'!AE19 -> 37443.42 | V4: ='4-MawLaMyaing'!AG19 -> 83208 | W4: ='4-MawLaMyaing'!AH19 -> 59850.12 | X4: ='4-MawLaMyaing'!AJ19 -> 64196 | Y4: ='4-MawLaMyaing'!AK19 -> 46431.08 | Z4: ='4-MawLaMyaing'!AM19 -> 70903 | AA4: ='4-MawLaMyaing'!AN19 -> 51537.46 | AB4: =SUM(D4+F4+H4+J4+L4+N4+P4+R4+T4+V4+X4+Z4) -> 761619 | AC4: =SUM(E4+G4+I4+K4+M4+O4+Q4+S4+U4+W4+Y4+AA4) -> 532438.9 | AD4: =AB4/12 -> 63468.25 | AE4: =AC4/12 -> 44369.908 | AF4: 72061 | AG4: 53802.46 | AH4: 73600 | AI4: 54732.04 | AJ4: 87386 | AK4: 62489.12 | AL4: 57052 | AM4: 40867.84 | AN4: 94218 | AO4: 73311.36 | AP4: 75020 | AQ4: 56777.6 | AR4: 69718 | AS4: 51481.12 | AT4: 73507 | AU4: 55470.07 | AV4: 71613 | AW4: 54656.99 | AX4: 70493 | AY4: 52464.3 | AZ4: 59132 | BA4: 44412.02 | BB4: 68033 | BC4: 50739.83 | BD4: =+AF4+AH4+AJ4+AL4+AN4+AP4+AR4+AT4+AV4+AX4+AZ4+BB4 -> 871833 | BE4: =+AG4+AI4+AK4+AM4+AO4+AQ4+AS4+AU4+AW4+AY4+BA4+BC4 -> 651204.75 | BF4: =BD4/12 -> 72652.75 | BG4: =BE4/12 -> 54267.062 | BH4: 56203 | BI4: 41060.67 | BJ4: 66607 | BK4: 50582.77 | BL4: 32373 | BM4: 24441.73 | CF4: =BH4+BJ4+BL4+BN4+BP4+BR4+BT4+BV4+BX4+BZ4+CB4+CD4 -> 155183 | CG4: =BI4+BK4+BM4+BO4+BQ4+BS4+BU4+BW4+BY4+CA4+CC4+CE4 -> 116085.17 | CH4: =CF4/2.5 -> 62073.2 | CI4: =CG4/2.5 -> 46434.068 | CJ4: =BF4/$BF$16% -> 23.315213 | CK4: 14
A5: 2 | B5: Hpa-an | D5: ='4-Hpa-An'!F18 -> 11846 | E5: ='4-Hpa-An'!G18 -> 8761.68 | F5: ='4-Hpa-An'!I18 -> 11808 | G5: ='4-Hpa-An'!J18 -> 8544.24 | H5: ='4-Hpa-An'!L18 -> 16834 | I5: ='4-Hpa-An'!M18 -> 11570.4 | J5: ='4-Hpa-An'!O18 -> 22252 | K5: ='4-Hpa-An'!P18 -> 15247.84 | L5: ='4-Hpa-An'!R18 -> 14478 | M5: ='4-Hpa-An'!S18 -> 10162.08 | N5: ='4-Hpa-An'!U18 -> 19720 | O5: ='4-Hpa-An'!V18 -> 13886 | P5: ='4-Hpa-An'!X18 -> 19380 | Q5: ='4-Hpa-An'!Y18 -> 13776.4 | R5: ='4-Hpa-An'!AA18 -> 21800 | S5: ='4-Hpa-An'!AB18 -> 15362.8 | T5: ='4-Hpa-An'!AD18 -> 17740 | U5: ='4-Hpa-An'!AE18 -> 13477.2 | V5: ='4-Hpa-An'!AG18 -> 17980 | W5: ='4-Hpa-An'!AH18 -> 13162.4 | X5: ='4-Hpa-An'!AJ18 -> 14780 | Y5: ='4-Hpa-An'!AK18 -> 10409.6 | Z5: ='4-Hpa-An'!AM18 -> 13940 | AA5: ='4-Hpa-An'!AN18 -> 9553.6 | AB5: =SUM(D5+F5+H5+J5+L5+N5+P5+R5+T5+V5+X5+Z5) -> 202558 | AC5: =SUM(E5+G5+I5+K5+M5+O5+Q5+S5+U5+W5+Y5+AA5) -> 143914.24 | AD5: =AB5/12 -> 16879.833 | AE5: =AC5/12 -> 11992.853 | AF5: 16350 | AG5: 12450 | AH5: 10260 | AI5: 7560 | AJ5: 27620 | AK5: 20108.4 | AL5: 8860 | AM5: 6145.6 | AN5: 12154 | AO5: 8842.56 | AP5: 21076 | AQ5: 15676.08 | AR5: 16294 | AS5: 12134 | AT5: 11930 | AU5: 9197.2 | AV5: 17376 | AW5: 12421.6 | AX5: 15760 | AY5: 11460.8 | AZ5: 18390 | BA5: 13928.4 | BB5: 10444 | BC5: 8218.4 | BD5: =+AF5+AH5+AJ5+AL5+AN5+AP5+AR5+AT5+AV5+AX5+AZ5+BB5 -> 186514 | BE5: =+AG5+AI5+AK5+AM5+AO5+AQ5+AS5+AU5+AW5+AY5+BA5+BC5 -> 138143.04 | BF5: =BD5/12 -> 15542.833 | BG5: =BE5/12 -> 11511.92 | BH5: 18556 | BI5: 14840.64 | BJ5: 13406 | BK5: 10399.2 | BL5: 11020 | BM5: 7744 | CF5: =BH5+BJ5+BL5+BN5+BP5+BR5+BT5+BV5+BX5+BZ5+CB5+CD5 -> 42982 | CG5: =BI5+BK5+BM5+BO5+BQ5+BS5+BU5+BW5+BY5+CA5+CC5+CE5 -> 32983.84 | CH5: =CF5/2.5 -> 17192.8 | CI5: =CG5/2.5 -> 13193.536 | CJ5: =BF5/$BF$16% -> 4.9878976 | CK5: 2
A6: 3 | B6: Paung | D6: ='4-Paung'!F13 -> 4546 | E6: ='4-Paung'!G13 -> 3030.4 | F6: ='4-Paung'!I13 -> 4120 | G6: ='4-Paung'!J13 -> 2636.8 | H6: ='4-Paung'!L13 -> 3532 | I6: ='4-Paung'!M13 -> 2260.48 | J6: ='4-Paung'!O13 -> 4980 | K6: ='4-Paung'!P13 -> 3398.88 | L6: ='4-Paung'!R13 -> 6232 | M6: ='4-Paung'!S13 -> 4054 | N6: ='4-Paung'!U13 -> 3020 | O6: ='4-Paung'!V13 -> 2084 | P6: ='4-Paung'!X13 -> 6164 | Q6: ='4-Paung'!Y13 -> 4040 | R6: ='4-Paung'!AA13 -> 5300 | S6: ='4-Paung'!AB13 -> 3518 | T6: ='4-Paung'!AD13 -> 4430 | U6: ='4-Paung'!AE13 -> 2939.6 | V6: ='4-Paung'!AG13 -> 3774 | W6: ='4-Paung'!AH13 -> 2462.16 | X6: ='4-Paung'!AJ13 -> 3782 | Y6: ='4-Paung'!AK13 -> 2518.4 | Z6: ='4-Paung'!AM13 -> 5250 | AA6: ='4-Paung'!AN13 -> 3360 | AB6: =SUM(D6+F6+H6+J6+L6+N6+P6+R6+T6+V6+X6+Z6) -> 55130 | AC6: =SUM(E6+G6+I6+K6+M6+O6+Q6+S6+U6+W6+Y6+AA6) -> 36302.72 | AD6: =AB6/12 -> 4594.1667 | AE6: =AC6/12 -> 3025.2267 | AF6: 5476 | AG6: 3571.6 | AH6: 5740 | AI6: 3738.4 | AJ6: 5880 | AK6: 3835.2 | AL6: 4766 | AM6: 3052.4 | AN6: 5836 | AO6: 3798.4 | AP6: 5326 | AQ6: 3410.8 | AR6: 5256 | AS6: 3366 | AT6: 2924 | AU6: 1898 | AV6: 4616 | AW6: 2960 | AX6: 1990 | AY6: 1273.6 | AZ6: 6932 | BA6: 4501.28 | BB6: 2970 | BC6: 1900.8 | BD6: =+AF6+AH6+AJ6+AL6+AN6+AP6+AR6+AT6+AV6+AX6+AZ6+BB6 -> 57712 | BE6: =+AG6+AI6+AK6+AM6+AO6+AQ6+AS6+AU6+AW6+AY6+BA6+BC6 -> 37306.48 | BF6: =BD6/12 -> 4809.3333 | BG6: =BE6/12 -> 3108.8733 | BH6: 4586 | BI6: 2998.4 | BJ6: 3150 | BK6: 2016 | BL6: 5206 | BM6: 3334 | CF6: =BH6+BJ6+BL6+BN6+BP6+BR6+BT6+BV6+BX6+BZ6+CB6+CD6 -> 12942 | CG6: =BI6+BK6+BM6+BO6+BQ6+BS6+BU6+BW6+BY6+CA6+CC6+CE6 -> 8348.4 | CH6: =CF6/2.5 -> 5176.8 | CI6: =CG6/2.5 -> 3339.36 | CJ6: =BF6/$BF$16% -> 1.5433777 | CK6: 11
A7: 4 | B7: Mudon | D7: ='4-Mu Don'!F8 -> 11340 | E7: ='4-Mu Don'!G8 -> 7257.6 | F7: ='4-Mu Don'!I8 -> 12306 | G7: ='4-Mu Don'!J8 -> 7875.84 | H7: ='4-Mu Don'!L8 -> 9870 | I7: ='4-Mu Don'!M8 -> 6316.8 | J7: ='4-Mu Don'!O8 -> 9842 | K7: ='4-Mu Don'!P8 -> 6298.88 | L7: ='4-Mu Don'!R8 -> 14826 | M7: ='4-Mu Don'!S8 -> 9488.64 | N7: ='4-Mu Don'!U8 -> 12180 | O7: ='4-Mu Don'!V8 -> 7795.2 | P7: ='4-Mu Don'!X8 -> 15400 | Q7: ='4-Mu Don'!Y8 -> 9856 | R7: ='4-Mu Don'!AA8 -> 11410 | S7: ='4-Mu Don'!AB8 -> 7302.4 | T7: ='4-Mu Don'!AD8 -> 9870 | U7: ='4-Mu Don'!AE8 -> 6316.8 | V7: ='4-Mu Don'!AG8 -> 14014 | W7: ='4-Mu Don'!AH8 -> 8968.96 | X7: ='4-Mu Don'!AJ8 -> 13484 | Y7: ='4-Mu Don'!AK8 -> 8629.76 | Z7: ='4-Mu Don'!AM8 -> 16160 | AA7: ='4-Mu Don'!AN8 -> 10342.4 | AB7: =SUM(D7+F7+H7+J7+L7+N7+P7+R7+T7+V7+X7+Z7) -> 150702 | AC7: =SUM(E7+G7+I7+K7+M7+O7+Q7+S7+U7+W7+Y7+AA7) -> 96449.28 | AD7: =AB7/12 -> 12558.5 | AE7: =AC7/12 -> 8037.44 | AF7: 18000 | AG7: 11520 | AH7: 15470 | AI7: 10116.8 | AJ7: 25462 | AK7: 16425.28 | AL7: 13890 | AM7: 8932.8 | AN7: 17472 | AO7: 11182.08 | AP7: 22736 | AQ7: 14551.04 | AR7: 16280 | AS7: 10635.2 | AT7: 13930 | AU7: 8915.2 | AV7: 16142 | AW7: 10330.88 | AX7: 20144 | AY7: 13626.56 | AZ7: 19950 | BA7: 13178.4 | BB7: 20996 | BC7: 13761.44 | BD7: =+AF7+AH7+AJ7+AL7+AN7+AP7+AR7+AT7+AV7+AX7+AZ7+BB7 -> 220472 | BE7: =+AG7+AI7+AK7+AM7+AO7+AQ7+AS7+AU7+AW7+AY7+BA7+BC7 -> 143175.68 | BF7: =BD7/12 -> 18372.667 | BG7: =BE7/12 -> 11931.307 | BH7: 17328 | BI7: 11400.96 | BJ7: 14072 | BK7: 9546.08 | BL7: 9770 | BM7: 6317.6 | CF7: =BH7+BJ7+BL7+BN7+BP7+BR7+BT7+BV7+BX7+BZ7+CB7+CD7 -> 41170 | CG7: =BI7+BK7+BM7+BO7+BQ7+BS7+BU7+BW7+BY7+CA7+CC7+CE7 -> 27264.64 | CH7: =CF7/2.5 -> 16468 | CI7: =CG7/2.5 -> 10905.856 | CJ7: =BF7/$BF$16% -> 5.8960279 | CK7: 8
A8: 5 | B8: ThaHtone | D8: ='4-ThaHtone'!F16 -> 25850 | E8: ='4-ThaHtone'!G16 -> 17150.24 | F8: ='4-ThaHtone'!I16 -> 21570 | G8: ='4-ThaHtone'!J16 -> 14078.4 | H8: ='4-ThaHtone'!L16 -> 23948 | I8: ='4-ThaHtone'!M16 -> 15737.12 | J8: ='4-ThaHtone'!O16 -> 28878 | K8: ='4-ThaHtone'!P16 -> 18844.8 | L8: ='4-ThaHtone'!R16 -> 19746 | M8: ='4-ThaHtone'!S16 -> 12889.44 | N8: ='4-ThaHtone'!U16 -> 23630 | O8: ='4-ThaHtone'!V16 -> 15368 | P8: ='4-ThaHtone'!X16 -> 23622 | Q8: ='4-ThaHtone'!Y16 -> 15262.08 | R8: ='4-ThaHtone'!AA16 -> 27836 | S8: ='4-ThaHtone'!AB16 -> 18085.76 | T8: ='4-ThaHtone'!AD16 -> 14486 | U8: ='4-ThaHtone'!AE16 -> 9530.24 | V8: ='4-ThaHtone'!AG16 -> 23086 | W8: ='4-ThaHtone'!AH16 -> 15174.64 | X8: ='4-ThaHtone'!AJ16 -> 12490 | Y8: ='4-ThaHtone'!AK16 -> 8112.4 | Z8: ='4-ThaHtone'!AM16 -> 13314 | AA8: ='4-ThaHtone'!AN16 -> 8875.2 | AB8: =SUM(D8+F8+H8+J8+L8+N8+P8+R8+T8+V8+X8+Z8) -> 258456 | AC8: =SUM(E8+G8+I8+K8+M8+O8+Q8+S8+U8+W8+Y8+AA8) -> 169108.32 | AD8: =AB8/12 -> 21538 | AE8: =AC8/12 -> 14092.36 | AF8: 10500 | AG8: 6720 | AH8: 17230 | AI8: 11304.4 | AJ8: 17144 | AK8: 11195.36 | AL8: 17402 | AM8: 11543.36 | AN8: 14050 | AO8: 9280 | AP8: 14250 | AQ8: 9156 | AR8: 16590 | AS8: 10718.4 | AT8: 18890 | AU8: 13205.6 | AV8: 12120 | AW8: 7828.8 | AX8: 12550 | AY8: 8140 | AZ8: 16978 | BA8: 11729.92 | BB8: 15180 | BC8: 10816.8 | BD8: =+AF8+AH8+AJ8+AL8+AN8+AP8+AR8+AT8+AV8+AX8+AZ8+BB8 -> 182884 | BE8: =+AG8+AI8+AK8+AM8+AO8+AQ8+AS8+AU8+AW8+AY8+BA8+BC8 -> 121638.64 | BF8: =BD8/12 -> 15240.333 | BG8: =BE8/12 -> 10136.553 | BH8: 8410 | BI8: 5785.6 | BJ8: 5400 | BK8: 3528 | BL8: 1200 | BM8: 840 | CF8: =BH8+BJ8+BL8+BN8+BP8+BR8+BT8+BV8+BX8+BZ8+CB8+CD8 -> 15010 | CG8: =BI8+BK8+BM8+BO8+BQ8+BS8+BU8+BW8+BY8+CA8+CC8+CE8 -> 10153.6 | CH8: =CF8/2.5 -> 6004 | CI8: =CG8/2.5 -> 4061.44 | CJ8: =BF8/$BF$16% -> 4.8908214 | CK8: 7
A9: 6 | B9: KawKareik | D9: ='4-KawKariek'!F7 -> 0 | E9: ='4-KawKariek'!G7 -> 0 | F9: ='4-KawKariek'!I7 -> 0 | G9: ='4-KawKariek'!J7 -> 0 | H9: ='4-KawKariek'!L7 -> 288 | I9: ='4-KawKariek'!M7 -> 201.6 | J9: ='4-KawKariek'!O7 -> 480 | K9: ='4-KawKariek'!P7 -> 336 | L9: ='4-KawKariek'!R7 -> 108 | M9: ='4-KawKariek'!S7 -> 75.6 | N9: ='4-KawKariek'!U7 -> 0 | O9: ='4-KawKariek'!V7 -> 0 | P9: ='4-KawKariek'!X7 -> 0 | Q9: ='4-KawKariek'!Y7 -> 0 | R9: ='4-KawKariek'!AA7 -> 0 | S9: ='4-KawKariek'!AB7 -> 0 | T9: ='4-KawKariek'!AD7 -> 0 | U9: ='4-KawKariek'!AE7 -> 0 | V9: ='4-KawKariek'!AG7 -> 0 | W9: ='4-KawKariek'!AH7 -> 0 | X9: ='4-KawKariek'!AJ7 -> 348 | Y9: ='4-KawKariek'!AK7 -> 243.6 | Z9: ='4-KawKariek'!AM7 -> 0 | AA9: ='4-KawKariek'!AN7 -> 0 | AB9: =SUM(D9+F9+H9+J9+L9+N9+P9+R9+T9+V9+X9+Z9) -> 1224 | AC9: =SUM(E9+G9+I9+K9+M9+O9+Q9+S9+U9+W9+Y9+AA9) -> 856.8 | AD9: =AB9/12 -> 102 | AE9: =AC9/12 -> 71.4 | AV9: 132 | AW9: 132 | AX9: 240 | AY9: 240 | BD9: =+AF9+AH9+AJ9+AL9+AN9+AP9+AR9+AT9+AV9+AX9+AZ9+BB9 -> 372 | BE9: =+AG9+AI9+AK9+AM9+AO9+AQ9+AS9+AU9+AW9+AY9+BA9+BC9 -> 372 | BF9: =BD9/12 -> 31 | BG9: =BE9/12 -> 31 | BH9: 120 | BI9: 120 | BJ9: 60 | BK9: 60 | CF9: =BH9+BJ9+BL9+BN9+BP9+BR9+BT9+BV9+BX9+BZ9+CB9+CD9 -> 180 | CG9: =BI9+BK9+BM9+BO9+BQ9+BS9+BU9+BW9+BY9+CA9+CC9+CE9 -> 180 | CH9: =CF9/2.5 -> 72 | CI9: =CG9/2.5 -> 72 | CJ9: =BF9/$BF$16% -> 0.0099483036 | CK9: 10
A10: 7 | B10: Yay | D10: ='4-Yaye'!F9 -> 169526 | E10: ='4-Yaye'!G9 -> 122709.44 | F10: ='4-Yaye'!I9 -> 146888 | G10: ='4-Yaye'!J9 -> 105106.4 | H10: ='4-Yaye'!L9 -> 191080 | I10: ='4-Yaye'!M9 -> 138966.4 | J10: ='4-Yaye'!O9 -> 181370 | K10: ='4-Yaye'!P9 -> 131329.28 | L10: ='4-Yaye'!R9 -> 192794 | M10: ='4-Yaye'!S9 -> 135816.8 | N10: ='4-Yaye'!U9 -> 181674 | O10: ='4-Yaye'!V9 -> 131823.36 | P10: ='4-Yaye'!X9 -> 174746 | Q10: ='4-Yaye'!Y9 -> 127749.44 | R10: ='4-Yaye'!AA9 -> 215318 | S10: ='4-Yaye'!AB9 -> 160760 | T10: ='4-Yaye'!AD9 -> 185158 | U10: ='4-Yaye'!AE9 -> 138980.8 | V10: ='4-Yaye'!AG9 -> 186142 | W10: ='4-Yaye'!AH9 -> 138640 | X10: ='4-Yaye'!AJ9 -> 135916 | Y10: ='4-Yaye'!AK9 -> 100888 | Z10: ='4-Yaye'!AM9 -> 175596 | AA10: ='4-Yaye'!AN9 -> 134620.8 | AB10: =SUM(D10+F10+H10+J10+L10+N10+P10+R10+T10+V10+X10+Z10) -> 2136208 | AC10: =SUM(E10+G10+I10+K10+M10+O10+Q10+S10+U10+W10+Y10+AA10) -> 1567390.7 | AD10: =AB10/12 -> 178017.33 | AE10: =AC10/12 -> 130615.89 | AF10: 164430 | AG10: 124740 | AH10: 167688 | AI10: 126108 | AJ10: 197792 | AK10: 147150.08 | AL10: 145772 | AM10: 103230.08 | AN10: 216684 | AO10: 162070.56 | AP10: 201666 | AQ10: 154869.6 | AR10: 188250 | AS10: 143419.2 | AT10: 179600 | AU10: 142354.4 | AV10: 186272 | AW10: 147484.16 | AX10: 176400 | AY10: 136785.6 | AZ10: 158310 | BA10: 126331.2 | BB10: 182410 | BC10: 147608.8 | BD10: =+AF10+AH10+AJ10+AL10+AN10+AP10+AR10+AT10+AV10+AX10+AZ10+BB10 -> 2165274 | BE10: =+AG10+AI10+AK10+AM10+AO10+AQ10+AS10+AU10+AW10+AY10+BA10+BC10 -> 1662151.7 | BF10: =BD10/12 -> 180439.5 | BG10: =BE10/12 -> 138512.64 | BH10: 184310 | BI10: 150164 | BJ10: 170230 | BK10: 135580 | BL10: 125522 | BM10: 105286.4 | CF10: =BH10+BJ10+BL10+BN10+BP10+BR10+BT10+BV10+BX10+BZ10+CB10+CD10 -> 480062 | CG10: =BI10+BK10+BM10+BO10+BQ10+BS10+BU10+BW10+BY10+CA10+CC10+CE10 -> 391030.4 | CH10: =CF10/2.5 -> 192024.8 | CI10: =CG10/2.5 -> 156412.16 | CJ10: =BF10/$BF$16% -> 57.905385 | CK10: 17
A11: 8 | B11: Phar Pun | D11: ='4-Phar Pon'!F8 -> 2800 | E11: ='4-Phar Pon'!G8 -> 1792 | F11: ='4-Phar Pon'!I8 -> 2800 | G11: ='4-Phar Pon'!J8 -> 1792 | H11: ='4-Phar Pon'!L8 -> 2800 | I11: ='4-Phar Pon'!M8 -> 1792 | J11: ='4-Phar Pon'!O8 -> 0 | K11: ='4-Phar Pon'!P8 -> 0 | L11: ='4-Phar Pon'!R8 -> 2800 | M11: ='4-Phar Pon'!S8 -> 1792 | N11: ='4-Phar Pon'!U8 -> 2800 | O11: ='4-Phar Pon'!V8 -> 1792 | P11: ='4-Phar Pon'!X8 -> 2800 | Q11: ='4-Phar Pon'!Y8 -> 1792 | R11: ='4-Phar Pon'!AA8 -> 2800 | S11: ='4-Phar Pon'!AB8 -> 1792 | T11: ='4-Phar Pon'!AD8 -> 2800 | U11: ='4-Phar Pon'!AE8 -> 1792 | V11: ='4-Phar Pon'!AG8 -> 2800 | W11: ='4-Phar Pon'!AH8 -> 1792 | X11: ='4-Phar Pon'!AJ8 -> 1400 | Y11: ='4-Phar Pon'!AK8 -> 896 | Z11: ='4-Phar Pon'!AM8 -> 0 | AA11: ='4-Phar Pon'!AN8 -> 0 | AB11: =SUM(D11+F11+H11+J11+L11+N11+P11+R11+T11+V11+X11+Z11) -> 26600 | AC11: =SUM(E11+G11+I11+K11+M11+O11+Q11+S11+U11+W11+Y11+AA11) -> 17024 | AD11: =AB11/12 -> 2216.6667 | AE11: =AC11/12 -> 1418.6667 | AF11: 560 | AG11: 358.4 | AJ11: 840 | AK11: 537.6 | AL11: 1680 | AM11: 1075.2 | AN11: 2800 | AO11: 1792 | AR11: 2800 | AS11: 1792 | AT11: 2800 | AU11: 1792 | AX11: 2800 | AY11: 1792 | BB11: 2800 | BC11: 1792 | BD11: =+AF11+AH11+AJ11+AL11+AN11+AP11+AR11+AT11+AV11+AX11+AZ11+BB11 -> 17080 | BE11: =+AG11+AI11+AK11+AM11+AO11+AQ11+AS11+AU11+AW11+AY11+BA11+BC11 -> 10931.2 | BF11: =BD11/12 -> 1423.3333 | BG11: =BE11/12 -> 910.93333 | CF11: =BH11+BJ11+BL11+BN11+BP11+BR11+BT11+BV11+BX11+BZ11+CB11+CD11 -> 0 | CG11: =BI11+BK11+BM11+BO11+BQ11+BS11+BU11+BW11+BY11+CA11+CC11+CE11 -> 0 | CH11: =CF11/2.5 -> 0 | CI11: =CG11/2.5 -> 0 | CJ11: =BF11/$BF$16% -> 0.4567662 | CK11: 19
A12: 9 | B12: Bagoda-3 | F12: ='4-Bagoda-3'!I8 -> 3800 | G12: ='4-Bagoda-3'!J8 -> 3296 | H12: ='4-Bagoda-3'!L8 -> 2400 | I12: ='4-Bagoda-3'!M8 -> 2400 | J12: ='4-Bagoda-3'!O8 -> 0 | K12: ='4-Bagoda-3'!P8 -> 0 | L12: ='4-Bagoda-3'!R8 -> 700 | M12: ='4-Bagoda-3'!S8 -> 448 | N12: ='4-Bagoda-3'!U8 -> 2600 | O12: ='4-Bagoda-3'!V8 -> 2096 | P12: ='4-Bagoda-3'!X8 -> 0 | Q12: ='4-Bagoda-3'!Y8 -> 0 | R12: ='4-Bagoda-3'!AA8 -> 0 | S12: ='4-Bagoda-3'!AB8 -> 0 | T12: ='4-Bagoda-3'!AD8 -> 0 | U12: ='4-Bagoda-3'!AE8 -> 0 | V12: ='4-Bagoda-3'!AG8 -> 0 | W12: ='4-Bagoda-3'!AH8 -> 0 | X12: ='4-Bagoda-3'!AJ8 -> 0 | Y12: ='4-Bagoda-3'!AK8 -> 0 | Z12: ='4-Bagoda-3'!AM8 -> 0 | AA12: ='4-Bagoda-3'!AN8 -> 0 | AB12: =SUM(D12+F12+H12+J12+L12+N12+P12+R12+T12+V12+X12+Z12) -> 9500 | AC12: =SUM(E12+G12+I12+K12+M12+O12+Q12+S12+U12+W12+Y12+AA12) -> 8240 | AD12: =AB12/12 -> 791.66667 | AE12: =AC12/12 -> 686.66667 | AF12: 2400 | AG12: 2400 | AH12: 140 | AI12: 89.6 | AR12: 2520 | AS12: 2520 | BB12: 2400 | BC12: 2400 | BD12: =+AF12+AH12+AJ12+AL12+AN12+AP12+AR12+AT12+AV12+AX12+AZ12+BB12 -> 7460 | BE12: =+AG12+AI12+AK12+AM12+AO12+AQ12+AS12+AU12+AW12+AY12+BA12+BC12 -> 7409.6 | BF12: =BD12/12 -> 621.66667 | BG12: =BE12/12 -> 617.46667 | CF12: =BH12+BJ12+BL12+BN12+BP12+BR12+BT12+BV12+BX12+BZ12+CB12+CD12 -> 0 | CG12: =BI12+BK12+BM12+BO12+BQ12+BS12+BU12+BW12+BY12+CA12+CC12+CE12 -> 0 | CH12: =CF12/2.5 -> 0 | CI12: =CG12/2.5 -> 0 | CJ12: =BF12/$BF$16% -> 0.19950093 | CK12: 5
A13: 10 | B13: Chang Sone | D13: ='4-Chang Sone'!F11 -> 2870 | E13: ='4-Chang Sone'!G11 -> 1836.8 | F13: ='4-Chang Sone'!I11 -> 1596 | G13: ='4-Chang Sone'!J11 -> 1053.12 | H13: ='4-Chang Sone'!L11 -> 1492 | I13: ='4-Chang Sone'!M11 -> 962.08 | J13: ='4-Chang Sone'!O11 -> 2010 | K13: ='4-Chang Sone'!P11 -> 1293.6 | L13: ='4-Chang Sone'!R11 -> 4026 | M13: ='4-Chang Sone'!S11 -> 2984.16 | N13: ='4-Chang Sone'!U11 -> 2080 | O13: ='4-Chang Sone'!V11 -> 1338.4 | P13: ='4-Chang Sone'!X11 -> 3040 | Q13: ='4-Chang Sone'!Y11 -> 1960 | R13: ='4-Chang Sone'!AA11 -> 2240 | S13: ='4-Chang Sone'!AB11 -> 1433.6 | T13: ='4-Chang Sone'!AD11 -> 1870 | U13: ='4-Chang Sone'!AE11 -> 1204 | V13: ='4-Chang Sone'!AG11 -> 3420 | W13: ='4-Chang Sone'!AH11 -> 2192.4 | X13: ='4-Chang Sone'!AJ11 -> 4900 | Y13: ='4-Chang Sone'!AK11 -> 3136 | Z13: ='4-Chang Sone'!AM11 -> 2930 | AA13: ='4-Chang Sone'!AN11 -> 1878.8 | AB13: =SUM(D13+F13+H13+J13+L13+N13+P13+R13+T13+V13+X13+Z13) -> 32474 | AC13: =SUM(E13+G13+I13+K13+M13+O13+Q13+S13+U13+W13+Y13+AA13) -> 21272.96 | AD13: =AB13/12 -> 2706.1667 | AE13: =AC13/12 -> 1772.7467 | AF13: 1590 | AG13: 1024.8 | AH13: 2486 | AI13: 1593.2 | AJ13: 2300 | AK13: 1475.6 | AL13: 700 | AM13: 448 | AN13: 2510 | AO13: 1610 | AP13: 2634 | AQ13: 1690.08 | AR13: 910 | AS13: 582.4 | AT13: 1936 | AU13: 1242.64 | AV13: 1860 | AW13: 1406.4 | AX13: 1310 | AY13: 845.6 | AZ13: 2240 | BA13: 1433.6 | BB13: 1400 | BC13: 896 | BD13: =+AF13+AH13+AJ13+AL13+AN13+AP13+AR13+AT13+AV13+AX13+AZ13+BB13 -> 21876 | BE13: =+AG13+AI13+AK13+AM13+AO13+AQ13+AS13+AU13+AW13+AY13+BA13+BC13 -> 14248.32 | BF13: =BD13/12 -> 1823 | BG13: =BE13/12 -> 1187.36 | BH13: 840 | BI13: 537.6 | BJ13: 840 | BK13: 537.6 | BL13: 1762 | BM13: 1132 | CF13: =BH13+BJ13+BL13+BN13+BP13+BR13+BT13+BV13+BX13+BZ13+CB13+CD13 -> 3442 | CG13: =BI13+BK13+BM13+BO13+BQ13+BS13+BU13+BW13+BY13+CA13+CC13+CE13 -> 2207.2 | CH13: =CF13/2.5 -> 1376.8 | CI13: =CG13/2.5 -> 882.88 | CJ13: =BF13/$BF$16% -> 0.58502443 | CK13: 3
A14: 11 | B14: Than Phyu ZaYat | D14: ='4-Than Phyu Zayat'!F8 -> 0 | E14: ='4-Than Phyu Zayat'!G8 -> 0 | F14: ='4-Than Phyu Zayat'!I8 -> 0 | G14: ='4-Than Phyu Zayat'!J8 -> 0 | H14: ='4-Than Phyu Zayat'!L8 -> 0 | I14: ='4-Than Phyu Zayat'!M8 -> 0 | J14: ='4-Than Phyu Zayat'!O8 -> 0 | K14: ='4-Than Phyu Zayat'!P8 -> 0 | N14: ='4-Than Phyu Zayat'!U8 -> 0 | O14: ='4-Than Phyu Zayat'!V8 -> 0 | P14: ='4-Than Phyu Zayat'!X8 -> 0 | Q14: ='4-Than Phyu Zayat'!Y8 -> 0 | R14: ='4-Than Phyu Zayat'!AA8 -> 0 | S14: ='4-Than Phyu Zayat'!AB8 -> 0 | T14: ='4-Than Phyu Zayat'!AD8 -> 0 | U14: ='4-Than Phyu Zayat'!AE8 -> 0 | V14: ='4-Than Phyu Zayat'!AG8 -> 0 | W14: ='4-Than Phyu Zayat'!AH8 -> 0 | X14: ='4-Than Phyu Zayat'!AJ8 -> 0 | Y14: ='4-Than Phyu Zayat'!AK8 -> 0 | Z14: ='4-Than Phyu Zayat'!AM8 -> 432 | AA14: ='4-Than Phyu Zayat'!AN8 -> 277.2 | AB14: =SUM(D14+F14+H14+J14+L14+N14+P14+R14+T14+V14+X14+Z14) -> 432 | AC14: =SUM(E14+G14+I14+K14+M14+O14+Q14+S14+U14+W14+Y14+AA14) -> 277.2 | AD14: =AB14/12 -> 36 | AE14: =AC14/12 -> 23.1 | AF14: 700 | AG14: 448 | AH14: 980 | AI14: 627.2 | AJ14: 700 | AK14: 448 | AN14: 700 | AO14: 448 | AR14: 714 | AS14: 462 | AT14: 700 | AU14: 448 | AV14: 420 | AW14: 268.8 | AX14: 700 | AY14: 448 | AZ14: 700 | BA14: 448 | BB14: 1540 | BC14: 985.6 | BD14: =+AF14+AH14+AJ14+AL14+AN14+AP14+AR14+AT14+AV14+AX14+AZ14+BB14 -> 7854 | BE14: =+AG14+AI14+AK14+AM14+AO14+AQ14+AS14+AU14+AW14+AY14+BA14+BC14 -> 5031.6 | BF14: =BD14/12 -> 654.5 | BG14: =BE14/12 -> 419.3 | BJ14: 714 | BK14: 456.96 | BL14: 736 | BM14: 484 | CF14: =BH14+BJ14+BL14+BN14+BP14+BR14+BT14+BV14+BX14+BZ14+CB14+CD14 -> 1450 | CG14: =BI14+BK14+BM14+BO14+BQ14+BS14+BU14+BW14+BY14+CA14+CC14+CE14 -> 940.96 | CH14: =CF14/2.5 -> 580 | CI14: =CG14/2.5 -> 376.384 | CJ14: =BF14/$BF$16% -> 0.21003757 | CK14: 18
A15: 12 | B15: Thein ZatYat | AB15: =SUM(D15+F15+H15+J15+L15+N15+P15+R15+T15+V15+X15+Z15) -> 0 | AC15: =SUM(E15+G15+I15+K15+M15+O15+Q15+S15+U15+W15+Y15+AA15) -> 0 | BH15: 8822 | BI15: 6618.08 | BJ15: 11420 | BK15: 8972 | BL15: 10256 | BM15: 7989.44 | CF15: =BH15+BJ15+BL15+BN15+BP15+BR15+BT15+BV15+BX15+BZ15+CB15+CD15 -> 30498 | CG15: =BI15+BK15+BM15+BO15+BQ15+BS15+BU15+BW15+BY15+CA15+CC15+CE15 -> 23579.52 | CH15: =CF15/2.5 -> 12199.2 | CI15: =CG15/2.5 -> 9431.808
B16: Wholesales Total | D16: =SUM(D4:D14) -> 284980 | E16: =SUM(E4:E14) -> 200645.96 | F16: =SUM(F4:F15) -> 250402 | G16: =SUM(G4:G15) -> 175347.76 | H16: =SUM(H4:H15) -> 306180 | I16: =SUM(I4:I15) -> 216101.84 | J16: =SUM(J4:J15) -> 313206 | K16: =SUM(K4:K15) -> 220161.04 | L16: =SUM(L4:L15) -> 319523 | M16: =SUM(M4:M15) -> 221018.78 | ... CI16: =SUM(CI4:CI15) -> 245109.49 | CJ16: 100%
CJ17: =292067-CJ16 -> 292066 | CK17: =292067-CK16 -> 292067
A18: No | B18: TownShip | C18: Van | D18: 45292 | F18: 45323 | H18: 45352 | J18: 45383 | L18: 45413 | N18: 45444 | P18: 45474 | R18: 45505 | T18: 45536 | V18: 45566 | X18: 45597 | Z18: 45627 | AB18: 2024 Total | AD18: Average - 2024 | AF18: 45658 | AH18: 45689 | AJ18: 45717 | AL18: 45748 | AN18: 45778 | AP18: 45809 | AR18: 45839 | AT18: 45870 | AV18: 45901 | AX18: 45931 | AZ18: 45962 | BB18: 45992 | BD18: 2025 Total | BF18: Average - 2025 | BH18: 46023 | BJ18: 46054 | BL18: 46082 | BN18: 46113 | BP18: 46143 | BR18: 46174 | BT18: 46204 | BV18: 46235 | BX18: 46266 | BZ18: 46296 | CB18: 46327 | CD18: 46357 | CF18: 2026 Total | CH18: Average | CJ18: Town wise Contribution | CK18: Contirbution wise Priority Town
D19: Bottle | E19: Liter | F19: Bottle | G19: Liter | H19: Bottle | I19: Liter | J19: Bottle | K19: Liter | L19: Bottle | M19: Liter | N19: Bottle | O19: Liter | P19: Bottle | Q19: Liter | R19: Bottle | S19: Liter | T19: Bottle | U19: Liter | V19: Bottle | W19: Liter | X19: Bottle | Y19: Liter | Z19: Bottle | AA19: Liter | AB19: Bottle | AC19: Liter | AD19: Bottle | AE19: Liter | AF19: Bottle | AG19: Liter | AH19: Bottle | AI19: Liter | AJ19: Bottle | AK19: Liter | AL19: Bottle | AM19: Liter | AN19: Bottle | AO19: Liter | AP19: Bottle | AQ19: Liter | AR19: Bottle | AS19: Liter | AT19: Bottle | AU19: Liter | AV19: Bottle | AW19: Liter | AX19: Bottle | AY19: Liter | AZ19: Bottle | BA19: Liter | BB19: Bottle | BC19: Liter | BD19: Bottle | BE19: Liter | BH19: Bottle | BI19: Liter | BJ19: Bottle | BK19: Liter | BL19: Bottle | BM19: Liter | BN19: Bottle | BO19: Liter | BP19: Bottle | BQ19: Liter | BR19: Bottle | BS19: Liter | BT19: Bottle | BU19: Liter | BV19: Bottle | BW19: Liter | BX19: Bottle | BY19: Liter | BZ19: Bottle | CA19: Liter | CB19: Bottle | CC19: Liter | CD19: Bottle | CE19: Liter | CF19: Bottle | CG19: Liter | CH19: Bottle | CI19: Liter
A20: 1 | B20: Maw La Myaing | C20: Van 3 | D20: 1470 | E20: 940.8 | F20: 348 | G20: 348 | H20: 1980 | I20: 1980 | J20: 2800 | K20: 1792 | L20: 1540 | M20: 985.6 | N20: 1534 | O20: 1202.8 | P20: 1750 | Q20: 1120 | T20: 2870 | U20: 1836.8 | V20: 8220 | W20: 6708 | X20: 3114 | Y20: 2286 | Z20: 5007 | AA20: 3927 | AB20: =SUM(D20+F20+H20+J20+L20+N20+P20+R20+T20+V20+X20+Z20) -> 30633 | AC20: =SUM(E20+G20+I20+K20+M20+O20+Q20+S20+U20+W20+Y20+AA20) -> 23127 | AD20: =AB20/12 -> 2552.75 | AE20: =AC20/12 -> 1927.25 | AF20: 893 | AG20: 789.98 | AH20: 1802 | AI20: 1587.8 | AJ20: 3310 | AK20: 2541.04 | AL20: 2214 | AM20: 1874.88 | AN20: 3798 | AO20: 3156.48 | AP20: 3578 | AQ20: 2731.28 | AR20: 2584 | AS20: 2306.8 | AT20: 3316 | AU20: 2796.67 | AV20: 2721 | AW20: 2265.95 | AX20: 3833 | AY20: 3158.46 | AZ20: 3152 | BA20: 2772.98 | BB20: 5759 | BC20: 4849.43 | BD20: =+AF20+AH20+AJ20+AL20+AN20+AP20+AR20+AT20+AV20+AX20+AZ20+BB20 -> 36960 | BE20: =+AG20+AI20+AK20+AM20+AO20+AQ20+AS20+AU20+AW20+AY20+BA20+BC20 -> 30831.75 | BF20: =BD20/12 -> 3080 | BG20: =BE20/12 -> 2569.3125 | BH20: 8355 | BI20: 6655.79 | BJ20: 8479 | BK20: 7355.89 | BL20: 6513 | BM20: 5368.45 | CF20: =BH20+BJ20+BL20+BN20+BP20+BR20+BT20+BV20+BX20+BZ20+CB20+CD20 -> 23347 | CG20: =BI20+BK20+BM20+BO20+BQ20+BS20+BU20+BW20+BY20+CA20+CC20+CE4 -> 19380.13 | CH20: =CF20/2.5 -> 9338.8 | CI20: =CG20/2.5 -> 7752.052 | CJ20: =IFERROR(BF20/$BF$32%,0) -> 32.774093 | CK20: 8
A21: 2 | B21: Hpa-an | C21: Van 2 | F21: 36 | G21: 25.2 | H21: 200 | I21: 70 | J21: 720 | K21: 504 | N21: 700 | O21: 448 | T21: 200 | U21: 70 | X21: 280 | Y21: 179.2 | Z21: 420 | AA21: 268.8 | AB21: =SUM(D21+F21+H21+J21+L21+N21+P21+R21+T21+V21+X21+Z21) -> 2556 | AC21: =SUM(E21+G21+I21+K21+M21+O21+Q21+S21+U21+W21+Y21+AA21) -> 1565.2 | AD21: =AB21/12 -> 213 | AE21: =AC21/12 -> 130.43333 | AH21: 120 | AI21: 120 | AJ21: 1940 | AK21: 1587.2 | AL21: 720 | AM21: 504 | AP21: 1200 | AQ21: 1200 | AT21: 360 | AU21: 584 | AZ21: 780 | BA21: 628.8 | BD21: =+AF21+AH21+AJ21+AL21+AN21+AP21+AR21+AT21+AV21+AX21+AZ21+BB21 -> 5120 | BE21: =+AG21+AI21+AK21+AM21+AO21+AQ21+AS21+AU21+AW21+AY21+BA21+BC21 -> 4624 | BF21: =BD21/12 -> 426.66667 | BG21: =BE21/12 -> 385.33333 | BH21: 2520 | BI21: 2520 | BJ21: 1040 | BK21: 910 | CF21: =BH21+BJ21+BL21+BN21+BP21+BR21+BT21+BV21+BX21+BZ21+CB21+CD21 -> 3560 | CG21: =BI21+BK21+BM21+BO21+BQ21+BS21+BU21+BW21+BY21+CA21+CC21+CE5 -> 3430 | CH21: =CF21/2.5 -> 1424 | CI21: =CG21/2.5 -> 1372 | CJ21: =IFERROR(BF21/$BF$32%,0) -> 4.5401341 | CK21: 14
A22: 3 | B22: Paung | C22: Van 2 | F22: 176 | G22: 114.8 | T22: 280 | U22: 179.2 | X22: 392 | Y22: 330.8 | Z22: 1250 | AA22: 800 | AB22: =SUM(D22+F22+H22+J22+L22+N22+P22+R22+T22+V22+X22+Z22) -> 2098 | AC22: =SUM(E22+G22+I22+K22+M22+O22+Q22+S22+U22+W22+Y22+AA22) -> 1424.8 | AD22: =AB22/12 -> 174.83333 | AE22: =AC22/12 -> 118.73333 | AH22: 176 | AI22: 114.8 | BD22: =+AF22+AH22+AJ22+AL22+AN22+AP22+AR22+AT22+AV22+AX22+AZ22+BB22 -> 176 | BE22: =+AG22+AI22+AK22+AM22+AO22+AQ22+AS22+AU22+AW22+AY22+BA22+BC22 -> 114.8 | BF22: =BD22/12 -> 14.666667 | BG22: =BE22/12 -> 9.5666667 | BH22: 3186 | BI22: 2102.4 | BJ22: 1970 | BK22: 1260.8 | BL22: 4506 | BM22: 2886 | CF22: =BH22+BJ22+BL22+BN22+BP22+BR22+BT22+BV22+BX22+BZ22+CB22+CD22 -> 9662 | CG22: =BI22+BK22+BM22+BO22+BQ22+BS22+BU22+BW22+BY22+CA22+CC22+CE6 -> 6249.2 | CH22: =CF22/2.5 -> 3864.8 | CI22: =CG22/2.5 -> 2499.68 | CJ22: =IFERROR(BF22/$BF$32%,0) -> 0.15606711 | CK22: 13
A23: 4 | B23: Mudon | C23: Van 1 | H23: 360 | I23: 360 | L23: 1288 | M23: 824.32 | P23: 700 | Q23: 448 | X23: 280 | Y23: 179.2 | Z23: 280 | AA23: 179.2 | AB23: =SUM(D23+F23+H23+J23+L23+N23+P23+R23+T23+V23+X23+Z23) -> 2908 | AC23: =SUM(E23+G23+I23+K23+M23+O23+Q23+S23+U23+W23+Y23+AA23) -> 1990.72 | AD23: =AB23/12 -> 242.33333 | AE23: =AC23/12 -> 165.89333 | AJ23: 360 | AK23: 360 | AN23: 1288 | AO23: 824.32 | AP23: 700 | AQ23: 448 | AR23: 1720 | AS23: 1316.8 | AT23: 1120 | AU23: 448 | AV23: 602 | AW23: 385.28 | AX23: 350 | AY23: 224 | AZ23: 700 | BA23: 448 | BB23: 1470 | BC23: 940.8 | BD23: =+AF23+AH23+AJ23+AL23+AN23+AP23+AR23+AT23+AV23+AX23+AZ23+BB23 -> 8310 | BE23: =+AG23+AI23+AK23+AM23+AO23+AQ23+AS23+AU23+AW23+AY23+BA23+BC23 -> 5395.2 | BF23: =BD23/12 -> 692.5 | BG23: =BE23/12 -> 449.6 | BH23: 4362 | BI23: 3016.32 | BJ23: 3338 | BK23: 2667.68 | BL23: 3060 | BM23: 2001.6 | CF23: =BH23+BJ23+BL23+BN23+BP23+BR23+BT23+BV23+BX23+BZ23+CB23+CD23 -> 10760 | CG23: =BI23+BK23+BM23+BO23+BQ23+BS23+BU23+BW23+BY23+CA23+CC23+CE7 -> 7685.6 | CH23: =CF23/2.5 -> 4304 | CI23: =CG23/2.5 -> 3074.24 | CJ23: =IFERROR(BF23/$BF$32%,0) -> 7.3688504 | CK23: 12
A24: 5 | B24: ThaHtone | C24: Van 1 | F24: 660 | G24: 436.8 | J24: 440 | K24: 299.6 | P24: 70 | Q24: 44.8 | Z24: 140 | AA24: 89.6 | AB24: =SUM(D24+F24+H24+J24+L24+N24+P24+R24+T24+V24+X24+Z24) -> 1310 | AC24: =SUM(E24+G24+I24+K24+M24+O24+Q24+S24+U24+W24+Y24+AA24) -> 870.8 | AD24: =AB24/12 -> 109.16667 | AE24: =AC24/12 -> 72.566667 | AH24: 660 | AI24: 436.8 | AL24: 440 | AM24: 299.6 | AR24: 980 | AS24: 627.2 | AV24: 700 | AW24: 448 | AZ24: 700 | BA24: 448 | BB24: 700 | BC24: 448 | BD24: =+AF24+AH24+AJ24+AL24+AN24+AP24+AR24+AT24+AV24+AX24+AZ24+BB24 -> 4180 | BE24: =+AG24+AI24+AK24+AM24+AO24+AQ24+AS24+AU24+AW24+AY24+BA24+BC24 -> 2707.6 | BF24: =BD24/12 -> 348.33333 | BG24: =BE24/12 -> 225.63333 | BH24: 4290 | BI24: 3069.6 | BJ24: 700 | BK24: 448 | CF24: =BH24+BJ24+BL24+BN24+BP24+BR24+BT24+BV24+BX24+BZ24+CB24+CD24 -> 4990 | CG24: =BI24+BK24+BM24+BO24+BQ24+BS24+BU24+BW24+BY24+CA24+CC24+CE8 -> 3517.6 | CH24: =CF24/2.5 -> 1996 | CI24: =CG24/2.5 -> 1407.04 | CJ24: =IFERROR(BF24/$BF$32%,0) -> 3.7065938 | CK24: 9
A25: 6 | B25: KawKareik | C25: Van 4 | R25: 168 | S25: 117.6 | AB25: =SUM(D25+F25+H25+J25+L25+N25+P25+R25+T25+V25+X25+Z25) -> 168 | AC25: =SUM(E25+G25+I25+K25+M25+O25+Q25+S25+U25+W25+Y25+AA25) -> 117.6 | AD25: =AB25/12 -> 14 | AE25: =AC25/12 -> 9.8 | AP25: 2160 | AQ25: 2160 | AV25: 12 | AW25: 12 | BD25: =+AF25+AH25+AJ25+AL25+AN25+AP25+AR25+AT25+AV25+AX25+AZ25+BB25 -> 2172 | BE25: =+AG25+AI25+AK25+AM25+AO25+AQ25+AS25+AU25+AW25+AY25+BA25+BC25 -> 2172 | BF25: =BD25/12 -> 181 | BG25: =BE25/12 -> 181 | BH25: 120 | BI25: 120 | BJ25: 60 | BK25: 60 | CF25: =BH25+BJ25+BL25+BN25+BP25+BR25+BT25+BV25+BX25+BZ25+CB25+CD25 -> 180 | CG25: =BI25+BK25+BM25+BO25+BQ25+BS25+BU25+BW25+BY25+CA25+CC25+CE9 -> 180 | CH25: =CF25/2.5 -> 72 | CI25: =CG25/2.5 -> 72 | CJ25: =IFERROR(BF25/$BF$32%,0) -> 1.92601 | CK25: 6
A26: 7 | B26: Yay | C26: Van 4 | F26: 640 | G26: 539.2 | H26: 1200 | I26: 1200 | L26: 8220 | M26: 6708 | N26: 1800 | O26: 1800 | V26: 1940 | W26: 1587.2 | Z26: 1520 | AA26: 1016 | AB26: =SUM(D26+F26+H26+J26+L26+N26+P26+R26+T26+V26+X26+Z26) -> 15320 | AC26: =SUM(E26+G26+I26+K26+M26+O26+Q26+S26+U26+W26+Y26+AA26) -> 12850.4 | AD26: =AB26/12 -> 1276.6667 | AE26: =AC26/12 -> 1070.8667 | AF26: 540 | AG26: 540 | AH26: 640 | AI26: 539.2 | AJ26: 1200 | AK26: 1200 | AN26: 8220 | AO26: 6708 | AR26: 4300 | AS26: 4048 | AT26: 5460 | AU26: 5308.8 | AV26: 3600 | AW26: 3600 | AX26: 8400 | AY26: 8400 | AZ26: 5320 | BA26: 5219.2 | BB26: 8080 | BC26: 7979.2 | BD26: =+AF26+AH26+AJ26+AL26+AN26+AP26+AR26+AT26+AV26+AX26+AZ26+BB26 -> 45760 | BE26: =+AG26+AI26+AK26+AM26+AO26+AQ26+AS26+AU26+AW26+AY26+BA26+BC26 -> 43542.4 | BF26: =BD26/12 -> 3813.3333 | BG26: =BE26/12 -> 3628.5333 | BH26: 11160 | BI26: 11160 | BJ26: 7280 | BK26: 6776 | BL26: 5100 | BM26: 5100 | CF26: =BH26+BJ26+BL26+BN26+BP26+BR26+BT26+BV26+BX26+BZ26+CB26+CD26 -> 23540 | CG26: =BI26+BK26+BM26+BO26+BQ26+BS26+BU26+BW26+BY26+CA26+CC26+CE10 -> 23036 | CH26: =CF26/2.5 -> 9416 | CI26: =CG26/2.5 -> 9214.4 | CJ26: =IFERROR(BF26/$BF$32%,0) -> 40.577448 | CK26: 11
A27: 8 | B27: Phar Pun | C27: Van 4 | AB27: =SUM(D27+F27+H27+J27+L27+N27+P27+R27+T27+V27+X27+Z27) -> 0 | AC27: =SUM(E27+G27+I27+K27+M27+O27+Q27+S27+U27+W27+Y27+AA27) -> 0 | AD27: =AB27/12 -> 0 | AE27: =AC27/12 -> 0 | BD27: =+AF27+AH27+AJ27+AL27+AN27+AP27+AR27+AT27+AV27+AX27+AZ27+BB27 -> 0 | BE27: =+AG27+AI27+AK27+AM27+AO27+AQ27+AS27+AU27+AW27+AY27+BA27+BC27 -> 0 | BF27: =BD27/12 -> 0 | BG27: =BE27/12 -> 0 | CF27: =BH27+BJ27+BL27+BN27+BP27+BR27+BT27+BV27+BX27+BZ27+CB27+CD27 -> 0 | CG27: =BI27+BK27+BM27+BO27+BQ27+BS27+BU27+BW27+BY27+CA27+CC27+CE11 -> 0 | CH27: =CF27/2.5 -> 0 | CI27: =CG27/2.5 -> 0 | CJ27: =IFERROR(BF27/$BF$32%,0) -> 0 | CK27: 5
A28: 9 | B28: Bagoda-3 | C28: Van 5 | V28: 700 | W28: 448 | AB28: =SUM(D28+F28+H28+J28+L28+N28+P28+R28+T28+V28+X28+Z28) -> 700 | AC28: =SUM(E28+G28+I28+K28+M28+O28+Q28+S28+U28+W28+Y28+AA28) -> 448 | AD28: =AB28/12 -> 58.333333 | AE28: =AC28/12 -> 37.333333 | BD28: =+AF28+AH28+AJ28+AL28+AN28+AP28+AR28+AT28+AV28+AX28+AZ28+BB28 -> 0 | BE28: =+AG28+AI28+AK28+AM28+AO28+AQ28+AS28+AU28+AW28+AY28+BA28+BC28 -> 0 | BF28: =BD28/12 -> 0 | BG28: =BE28/12 -> 0 | CF28: =BH28+BJ28+BL28+BN28+BP28+BR28+BT28+BV28+BX28+BZ28+CB28+CD28 -> 0 | CG28: =BI28+BK28+BM28+BO28+BQ28+BS28+BU28+BW28+BY28+CA28+CC28+CE12 -> 0 | CH28: =CF28/2.5 -> 0 | CI28: =CG28/2.5 -> 0 | CJ28: =IFERROR(BF28/$BF$32%,0) -> 0 | CK28: 2
A29: 10 | B29: Chang Sone | C29: Van 9 | D29: 700 | E29: 448 | H29: 350 | I29: 224 | X29: 3360 | Y29: 2150.4 | Z29: 1670 | AA29: 1072.4 | AB29: =SUM(D29+F29+H29+J29+L29+N29+P29+R29+T29+V29+X29+Z29) -> 6080 | AC29: =SUM(E29+G29+I29+K29+M29+O29+Q29+S29+U29+W29+Y29+AA29) -> 3894.8 | AD29: =AB29/12 -> 506.66667 | AE29: =AC29/12 -> 324.56667 | AF29: 560 | AG29: 358.4 | AJ29: 350 | AK29: 224 | AP29: 420 | AQ29: 268.8 | AX29: 420 | AY29: 268.8 | AZ29: 70 | BA29: 44.8 | BB29: 420 | BC29: 268.8 | BD29: =+AF29+AH29+AJ29+AL29+AN29+AP29+AR29+AT29+AV29+AX29+AZ29+BB29 -> 2240 | BE29: =+AG29+AI29+AK29+AM29+AO29+AQ29+AS29+AU29+AW29+AY29+BA29+BC29 -> 1433.6 | BF29: =BD29/12 -> 186.66667 | BG29: =BE29/12 -> 119.46667 | BH29: 840 | BI29: 537.6 | BJ29: 840 | BK29: 537.6 | BL29: 1762 | BM29: 1132 | CF29: =BH29+BJ29+BL29+BN29+BP29+BR29+BT29+BV29+BX29+BZ29+CB29+CD29 -> 3442 | CG29: =BI29+BK29+BM29+BO29+BQ29+BS29+BU29+BW29+BY29+CA29+CC29+CE13 -> 2207.2 | CH29: =CF29/2.5 -> 1376.8 | CI29: =CG29/2.5 -> 882.88 | CJ29: =IFERROR(BF29/$BF$32%,0) -> 1.9863087 | CK29: 1
A30: 11 | B30: Than Phyu ZaYat | C30: Van 6 | AB30: =SUM(D30+F30+H30+J30+L30+N30+P30+R30+T30+V30+X30+Z30) -> 0 | AC30: =SUM(E30+G30+I30+K30+M30+O30+Q30+S30+U30+W30+Y30+AA30) -> 0 | AD30: =AB30/12 -> 0 | AE30: =AC30/12 -> 0 | AF30: 700 | AG30: 448 | AH30: 980 | AI30: 627.2 | AJ30: 700 | AK30: 448 | AN30: 700 | AO30: 448 | AR30: 714 | AS30: 462 | AT30: 700 | AU30: 448 | AV30: 420 | AW30: 268.8 | AX30: 700 | AY30: 448 | AZ30: 700 | BA30: 448 | BB30: 1540 | BC30: 985.6 | BD30: =+AF30+AH30+AJ30+AL30+AN30+AP30+AR30+AT30+AV30+AX30+AZ30+BB30 -> 7854 | BE30: =+AG30+AI30+AK30+AM30+AO30+AQ30+AS30+AU30+AW30+AY30+BA30+BC30 -> 5031.6 | BF30: =BD30/12 -> 654.5 | BG30: =BE30/12 -> 419.3 | BJ30: 714 | BK30: 456.96 | BL30: 736 | BM30: 484 | CF30: =BH30+BJ30+BL30+BN30+BP30+BR30+BT30+BV30+BX30+BZ30+CB30+CD30 -> 1450 | CG30: =BI30+BK30+BM30+BO30+BQ30+BS30+BU30+BW30+BY30+CA30+CC30+CE14 -> 940.96 | CH30: =CF30/2.5 -> 580 | CI30: =CG30/2.5 -> 376.384 | CJ30: =IFERROR(BF30/$BF$32%,0) -> 6.9644947 | CK30: 7
A31: 12 | B31: Thein ZatYat | C31: Van 6 | AB31: =SUM(D31+F31+H31+J31+L31+N31+P31+R31+T31+V31+X31+Z31) -> 0 | AC31: =SUM(E31+G31+I31+K31+M31+O31+Q31+S31+U31+W31+Y31+AA31) -> 0 | BH31: 28 | BI31: 17.92 | BJ31: 300 | BK31: 300 | CF31: =BH31+BJ31+BL31+BN31+BP31+BR31+BT31+BV31+BX31+BZ31+CB31+CD31 -> 328 | CG31: =BI31+BK31+BM31+BO31+BQ31+BS31+BU31+BW31+BY31+CA31+CC31+CE15 -> 317.92 | CH31: =CF31/2.5 -> 131.2 | CI31: =CG31/2.5 -> 127.168
B32: Market Total | D32: =SUM(D20:D30) -> 2170 | E32: =SUM(E20:E30) -> 1388.8 | F32: =SUM(F20:F31) -> 1860 | G32: =SUM(G20:G31) -> 1464 | H32: =SUM(H20:H31) -> 4090 | I32: =SUM(I20:I31) -> 3834 | J32: =SUM(J20:J31) -> 3960 | K32: =SUM(K20:K31) -> 2595.6 | L32: =SUM(L20:L31) -> 11048 | M32: =SUM(M20:M31) -> 8517.92 | ... CI32: =SUM(CI20:CI31) -> 26777.844 | CJ32: 100%
A34: Sale Data Percentage
A35: No | B35: TownShip | D35: 45292 | F35: 45323 | H35: 45352 | J35: 45383 | L35: 45413 | N35: 45444 | P35: 45474 | R35: 45505 | T35: 45536 | V35: 45566 | X35: 45597 | Z35: 45627 | AB35: 2024 Total | AD35: Average - 2024 | AF35: 45658 | AH35: 45689 | AJ35: 45717 | AL35: 45748 | AN35: 45778 | AP35: 45809 | AR35: 45839 | AT35: 45870 | AV35: 45901 | AX35: 45931 | AZ35: 45962 | BB35: 45992 | BD35: 2025 Total | BF35: Average - 2025 | BH35: 46023 | BJ35: 46054 | BL35: 46082 | BN35: 46113 | BP35: 46143 | BR35: 46174 | BT35: 46204 | BV35: 46235 | BX35: 46266 | BZ35: 46296 | CB35: 46327 | CD35: 46357 | CF35: 2026 Total | CH35: Average | CJ35: Town wise Contribution | CK35: Contirbution wise Priority Town
D36: Bottle | E36: Liter | F36: Bottle | G36: Liter | H36: Bottle | I36: Liter | J36: Bottle | K36: Liter | L36: Bottle | M36: Liter | N36: Bottle | O36: Liter | P36: Bottle | Q36: Liter | R36: Bottle | S36: Liter | T36: Bottle | U36: Liter | V36: Bottle | W36: Liter | X36: Bottle | Y36: Liter | Z36: Bottle | AA36: Liter | AB36: Bottle | AC36: Liter | AD36: Bottle | AE36: Liter | AF36: Bottle | AG36: Liter | AH36: Bottle | AI36: Liter | AJ36: Bottle | AK36: Liter | AL36: Bottle | AM36: Liter | AN36: Bottle | AO36: Liter | AP36: Bottle | AQ36: Liter | AR36: Bottle | AS36: Liter | AT36: Bottle | AU36: Liter | AV36: Bottle | AW36: Liter | AX36: Bottle | AY36: Liter | AZ36: Bottle | BA36: Liter | BB36: Bottle | BC36: Liter | BD36: Bottle | BE36: Liter | BF36: Bottle | BG36: Liter | BH36: Bottle | BI36: Liter | BJ36: Bottle | BK36: Liter | BL36: Bottle | BM36: Liter | BN36: Bottle | BO36: Liter | BP36: Bottle | BQ36: Liter | BR36: Bottle | BS36: Liter | BT36: Bottle | BU36: Liter | BV36: Bottle | BW36: Liter | BX36: Bottle | BY36: Liter | BZ36: Bottle | CA36: Liter | CB36: Bottle | CC36: Liter | CD36: Bottle | CE36: Liter | CF36: Bottle | CG36: Liter | CH36: Bottle | CI36: Liter
A37: 1 | B37: Wholesales | D37: =D16-D32 -> 282810 | E37: =E16-E32 -> 199257.16 | F37: =F16-F32 -> 248542 | G37: =G16-G32 -> 173883.76 | H37: =H16-H32 -> 302090 | I37: =I16-I32 -> 212267.84 | J37: =J16-J32 -> 309246 | K37: =K16-K32 -> 217565.44 | ... CI37: =CI16-CI32 -> 218331.65
A38: 2 | B38: Market | D38: =D32 -> 2170 | E38: =E32 -> 1388.8 | F38: =F32 -> 1860 | G38: =G32 -> 1464 | H38: =H32 -> 4090 | I38: =I32 -> 3834 | J38: =J32 -> 3960 | K38: =K32 -> 2595.6 | ... CI38: =CI32 -> 26777.844
A39: Total Sales | D39: =SUM(D37:D38) -> 284980 | E39: =SUM(E37:E38) -> 200645.96 | F39: =SUM(F37:F38) -> 250402 | G39: =SUM(G37:G38) -> 175347.76 | H39: =SUM(H37:H38) -> 306180 | I39: =SUM(I37:I38) -> 216101.84 | J39: =SUM(J37:J38) -> 313206 | K39: =SUM(K37:K38) -> 220161.04 | ... CI39: =SUM(CI37:CI38) -> 245109.49
A40: 1 | B40: Wholesales (%) | D40: =D37/D39 -> 0.99238543 | E40: =E37/E39 -> 0.99307836 | F40: =F37/F39 -> 0.99257194 | G40: =G37/G39 -> 0.99165088 | H40: =H37/H39 -> 0.98664184 | I40: =I37/I39 -> 0.98225836 | J40: =J37/J39 -> 0.98735656 | K40: =K37/K39 -> 0.98821045 | ... CI40: =CI37/CI39 -> 0.8907515
A41: 2 | B41: Market (%) | D41: =D38/D39 -> 0.0076145694 | E41: =E38/E39 -> 0.0069216445 | F41: =F38/F39 -> 0.0074280557 | G41: =G38/G39 -> 0.0083491229 | H41: =H38/H39 -> 0.013358155 | I41: =I38/I39 -> 0.017741635 | J41: =J38/J39 -> 0.012643436 | K41: =K38/K39 -> 0.011789552 | ... CI41: =CI38/CI39 -> 0.1092485

Sheet 4--Township summary
A2: No | B2: TownShip | C2: Van | D2: 2024 Average | F2: Mawlamyaing Report (2025) | AG2: Town wise Contribution | AH2: Contirbution wise Priority Town
F3: January | H3: February | J3: March | L3: April | N3: May | P3: June | R3: July | T3: August | V3: September | X3: October | Z3: November | AB3: December | AD3: Jan to Dec | AF3: Average
D4: BT | E4: Liter | F4: BT | G4: Liter | H4: BT | I4: Liter | J4: BT | K4: Liter | L4: BT | M4: Liter | N4: BT | O4: Liter | P4: BT | Q4: Liter | R4: BT | S4: Liter | T4: BT | U4: Liter | V4: BT | W4: Liter | X4: BT | Y4: Liter | Z4: BT | AA4: Liter | AB4: BT | AC4: Liter | AD4: BT | AE4: Liter
A5: 1 | B5: Maw La Myaing | D5: 63709 | E5: 40522 | F5: 72061 | G5: 53802.46 | H5: 73600 | I5: 54732.04 | J5: 87386 | K5: 62489.12 | L5: 57052 | M5: 40867.84 | N5: 94218 | O5: 73311.36 | P5: 40456 | Q5: 32318.8 | AD5: =+F5+H5+J5+L5+N5+P5+R5+T5+V5+X5+Z5+AB5 -> 424773 | AE5: =+G5+I5+K5+M5+O5+Q5+S5+U5+W5+Y5+AA5+AC5 -> 317521.62 | AF5: =AD5/6 -> 70795.5 | AG5: =AF5/$AF$22% -> 25.32739 | AH5: 2
A6: 2 | B6: Hpa-an | D6: 16330 | E6: 11066 | F6: 16350 | G6: 12450 | H6: 10260 | I6: 7560 | J6: 27620 | K6: 20108.4 | L6: 8860 | M6: 6145.6 | N6: 12154 | O6: 8842.56 | P6: 16344 | Q6: 12015.6 | AD6: =+F6+H6+J6+L6+N6+P6+R6+T6+V6+X6+Z6+AB6 -> 91588 | AE6: =+G6+I6+K6+M6+O6+Q6+S6+U6+W6+Y6+AA6+AC6 -> 67122.16 | AF6: =AD6/6 -> 15264.667 | AG6: =AF6/$AF$22% -> 5.4609991 | AH6: 3
A7: 3 | B7: Paung | D7: 4617 | E7: 3022 | F7: 5476 | G7: 3571.6 | H7: 5740 | I7: 3738.4 | J7: 5880 | K7: 3835.2 | L7: 4766 | M7: 3052.4 | N7: 5836 | O7: 3798.4 | P7: 3056 | Q7: 1958 | AD7: =+F7+H7+J7+L7+N7+P7+R7+T7+V7+X7+Z7+AB7 -> 30754 | AE7: =+G7+I7+K7+M7+O7+Q7+S7+U7+W7+Y7+AA7+AC7 -> 19954 | AF7: =AD7/6 -> 5125.6667 | AG7: =AF7/$AF$22% -> 1.8337289 | AH7: 5
A8: 4 | B8: Mudon | D8: 12859 | E8: 8229 | F8: 18000 | G8: 11520 | H8: 15470 | I8: 10116.8 | J8: 25462 | K8: 16425.28 | L8: 13890 | M8: 8932.8 | N8: 17472 | O8: 11182.08 | P8: 10374 | Q8: 6639.36 | AD8: 18000 | AE8: =+G8+I8+K8+M8+O8+Q8+S8+U8+W8+Y8+AA8+AC8 -> 64816.32 | AF8: =AD8/6 -> 3000 | AG8: =AF8/$AF$22% -> 1.0732627 | AH8: 6
A9: 5 | B9: ThaHtone | D9: 21740 | E9: 14194 | F9: 10500 | G9: 6720 | H9: 17230 | I9: 11304.4 | J9: 17144 | K9: 11195.36 | L9: 17402 | M9: 11543.36 | N9: 14050 | O9: 9280 | P9: 7250 | Q9: 4676 | AD9: =+F9+H9+J9+L9+N9+P9+R9+T9+V9+X9+Z9+AB9 -> 83576 | AE9: =+G9+I9+K9+M9+O9+Q9+S9+U9+W9+Y9+AA9+AC9 -> 54719.12 | AF9: =AD9/6 -> 13929.333 | AG9: =AF9/$AF$22% -> 4.983278 | AH9: 4
A10: 6 | B10: KawKareik | D10: 146 | E10: 3605 | AD10: =+F10+H10+J10+L10+N10+P10+R10+T10+V10+X10+Z10+AB10 -> 0 | AE10: =+G10+I10+K10+M10+O10+Q10+S10+U10+W10+Y10+AA10+AC10 -> 0 | AF10: =AD10/6 -> 0 | AG10: =AF10/$AF$22% -> 0 | AH10: 8
A11: 7 | B11: Yay | D11: 178316 | E11: 129850 | F11: 164430 | G11: 124740 | H11: 167688 | I11: 126108 | J11: 197792 | K11: 147150.08 | L11: 145772 | M11: 103230.08 | N11: 216684 | O11: 162070.56 | P11: 113550 | Q11: 87316.8 | AD11: =+F11+H11+J11+L11+N11+P11+R11+T11+V11+X11+Z11+AB11 -> 1005916 | AE11: =+G11+I11+K11+M11+O11+Q11+S11+U11+W11+Y11+AA11+AC11 -> 750615.52 | AF11: =AD11/6 -> 167652.67 | AG11: =AF11/$AF$22% -> 59.978451 | AH11: 1
A12: 8 | B12: Phar Pun | D12: 2252 | E12: 1453 | F12: 560 | G12: 358.4 | J12: 840 | K12: 537.6 | L12: 1680 | M12: 1075.2 | N12: 2800 | O12: 1792 | AD12: =+F12+H12+J12+L12+N12+P12+R12+T12+V12+X12+Z12+AB12 -> 5880 | AE12: =+G12+I12+K12+M12+O12+Q12+S12+U12+W12+Y12+AA12+AC12 -> 3763.2 | AF12: =AD12/6 -> 980 | AG12: =AF12/$AF$22% -> 0.35059915 | AH12: 9
A13: 9 | B13: Bagoda-3 | D13: 733 | E13: 649 | F13: 2400 | G13: 2400 | H13: 140 | I13: 89.6 | AD13: =+F13+H13+J13+L13+N13+P13+R13+T13+V13+X13+Z13+AB13 -> 2540 | AE13: =+G13+I13+K13+M13+O13+Q13+S13+U13+W13+Y13+AA13+AC13 -> 2489.6 | AF13: =AD13/6 -> 423.33333 | AG13: =AF13/$AF$22% -> 0.15144929 | AH13: 10
A14: 10 | B14: Chang Sone | D14: 2719 | E14: 1745 | F14: 1590 | G14: 1024.8 | H14: 2486 | I14: 1593.2 | J14: 2300 | K14: 1475.6 | L14: 700 | M14: 448 | N14: 2510 | O14: 1610 | P14: 1436 | Q14: 921.2 | AD14: =+F14+H14+J14+L14+N14+P14+R14+T14+V14+X14+Z14+AB14 -> 11022 | AE14: =+G14+I14+K14+M14+O14+Q14+S14+U14+W14+Y14+AA14+AC14 -> 7072.8 | AF14: =AD14/6 -> 1837 | AG14: =AF14/$AF$22% -> 0.65719453 | AH14: 7
A15: 11 | B15: Than Phyu ZaYat | D15: 36 | E15: 23 | F15: 700 | G15: 448 | H15: 980 | I15: 627.2 | J15: 700 | K15: 448 | N15: 700 | O15: 448 | AD15: =+F15+H15+J15+L15+N15+P15+R15+T15+V15+X15+Z15+AB15 -> 3080 | AE15: =+G15+I15+K15+M15+O15+Q15+S15+U15+W15+Y15+AA15+AC15 -> 1971.2 | AF15: =AD15/6 -> 513.33333 | AG15: =AF15/$AF$22% -> 0.18364717 | AH15: 11
A16: 15 | AD16: =SUM(F16:AC16) -> 0 | AF16: =AD16/10 -> 0 | AG16: =AF16/$AF$22% -> 0 | AH16: 13
A17: 16 | AD17: =SUM(F17:AC17) -> 0 | AF17: =AD17/10 -> 0 | AG17: =AF17/$AF$22% -> 0 | AH17: 9
A18: 17 | AD18: =SUM(F18:AC18) -> 0 | AF18: =AD18/10 -> 0 | AG18: =AF18/$AF$22% -> 0 | AH18: 12
A19: 18 | AD19: =SUM(F19:AC19) -> 0 | AF19: =AD19/10 -> 0 | AG19: =AF19/$AF$22% -> 0 | AH19: 4
A20: 19 | AD20: =SUM(F20:AC20) -> 0 | AF20: =AD20/10 -> 0 | AG20: =AF20/$AF$22% -> 0 | AH20: 15
B22: Wholesales Total | D22: =SUM(D5:D15) -> 303457 | E22: =SUM(E5:E15) -> 214358 | F22: =SUM(F5:F21) -> 292067 | G22: =SUM(G5:G21) -> 217035.26 | H22: =SUM(H5:H21) -> 293594 | I22: =SUM(I5:I21) -> 215869.64 | J22: =SUM(J5:J21) -> 365124 | K22: =SUM(K5:K21) -> 263664.64 | L22: =SUM(L5:L21) -> 250122 | M22: =SUM(M5:M21) -> 175295.28 | ... AF22: =SUM(AF5:AF21) -> 279521.5 | AG22: 100%
A24: No | B24: TownShip | C24: Van | F24: Market ( Townwise Report ) (2025) | AG24: Town wise Contribution | AH24: Contirbution wise Priority Town
D25: 2024 Average | F25: January | H25: February | J25: March | L25: April | N25: May | P25: June | R25: July | T25: August | V25: September | X25: October | Z25: November | AB25: December | AD25: Jan to Dec | AF25: Average
D26: BT | E26: Liter | F26: BT | G26: Liter | H26: BT | I26: Liter | J26: BT | K26: Liter | L26: BT | M26: Liter | N26: BT | O26: Liter | P26: BT | Q26: Liter | R26: BT | S26: Liter | T26: BT | U26: Liter | V26: BT | W26: Liter | X26: BT | Y26: Liter | Z26: BT | AA26: Liter | AB26: BT | AC26: Liter | AD26: BT | AE26: Liter
A27: 1 | B27: Maw La Myaing | C27: Van 3 | D27: 8730.5 | F27: 893 | G27: 789.98 | H27: 1802 | I27: 1587.8 | J27: 3310 | K27: 2541.04 | L27: 2214 | M27: 1874.88 | N27: 3798 | O27: 3156.48 | P27: 1534 | Q27: 1202.8 | AD27: =+F27+H27+J27+L27+N27+P27+R27+T27+V27+X27+Z27+AB27 -> 13551 | AE27: =+G27+I27+K27+M27+O27+Q27+S27+U27+W27+Y27+AA27+AC27 -> 11152.98 | AF27: =AD27/5 -> 2710.2 | AG27: =IFERROR(AF27/$AF$42%,0) -> 36.778396 | AH27: 1
A28: 2 | B28: Hpa-an | C28: Van 2 | D28: 1710 | H28: 120 | I28: 120 | J28: 1940 | K28: 1587.2 | L28: 720 | M28: 504 | P28: 1200 | Q28: 1200 | AD28: =+F28+H28+J28+L28+N28+P28+R28+T28+V28+X28+Z28+AB28 -> 3980 | AE28: =+G28+I28+K28+M28+O28+Q28+S28+U28+W28+Y28+AA28+AC28 -> 3411.2 | AF28: =AD28/5 -> 796 | AG28: =IFERROR(AF28/$AF$42%,0) -> 10.802008 | AH28: 2
A29: 3 | B29: Paung | C29: Van 2 | D29: 1358 | H29: 176 | I29: 114.8 | AD29: =+F29+H29+J29+L29+N29+P29+R29+T29+V29+X29+Z29+AB29 -> 176 | AE29: =+G29+I29+K29+M29+O29+Q29+S29+U29+W29+Y29+AA29+AC29 -> 114.8 | AF29: =AD29/5 -> 35.2 | AG29: =IFERROR(AF29/$AF$42%,0) -> 0.47767675 | AH29: 8
A30: 4 | B30: Mudon | C30: Van 1 | D30: 6160 | J30: 360 | K30: 360 | N30: 1288 | O30: 824.32 | AD30: =+F30+H30+J30+L30+N30+P30+R30+T30+V30+X30+Z30+AB30 -> 1648 | AE30: =+G30+I30+K30+M30+O30+Q30+S30+U30+W30+Y30+AA30+AC30 -> 1184.32 | AF30: =AD30/5 -> 329.6 | AG30: =IFERROR(AF30/$AF$42%,0) -> 4.4727914 | AH30: 7
A31: 5 | B31: ThaHtone | C31: Van 1 | D31: 389 | H31: 660 | I31: 436.8 | L31: 440 | M31: 299.6 | AD31: =+F31+H31+J31+L31+N31+P31+R31+T31+V31+X31+Z31+AB31 -> 1100 | AE31: =+G31+I31+K31+M31+O31+Q31+S31+U31+W31+Y31+AA31+AC31 -> 736.4 | AF31: =AD31/5 -> 220 | AG31: =IFERROR(AF31/$AF$42%,0) -> 2.9854797 | AH31: 5
A32: 6 | B32: KawKareik | C32: Van 4 | D32: 0 | AD32: =+F32+H32+J32+L32+N32+P32+R32+T32+V32+X32+Z32+AB32 -> 0 | AE32: =+G32+I32+K32+M32+O32+Q32+S32+U32+W32+Y32+AA32+AC32 -> 0 | AF32: =AD32/5 -> 0 | AG32: =IFERROR(AF32/$AF$42%,0) -> 0 | AH32: 9
A33: 7 | B33: Yay | C33: Van 4 | D33: 5548 | F33: 540 | G33: 540 | H33: 640 | I33: 539.2 | J33: 1200 | K33: 1200 | N33: 8220 | O33: 6708 | P33: 1800 | Q33: 1800 | AD33: =+F33+H33+J33+L33+N33+P33+R33+T33+V33+X33+Z33+AB33 -> 12400 | AE33: =+G33+I33+K33+M33+O33+Q33+S33+U33+W33+Y33+AA33+AC33 -> 10787.2 | AF33: =AD33/5 -> 2480 | AG33: =IFERROR(AF33/$AF$42%,0) -> 33.654499 | AH33: 4
A34: 8 | B34: Phar Pun | C34: Van 4 | D34: 0 | AD34: =+F34+H34+J34+L34+N34+P34+R34+T34+V34+X34+Z34+AB34 -> 0 | AE34: =+G34+I34+K34+M34+O34+Q34+S34+U34+W34+Y34+AA34+AC34 -> 0 | AF34: =AD34/5 -> 0 | AG34: =IFERROR(AF34/$AF$42%,0) -> 0 | AH34: 10
A35: 9 | B35: Bagoda-3 | C35: Van 5 | D35: 0 | AD35: =+F35+H35+J35+L35+N35+P35+R35+T35+V35+X35+Z35+AB35 -> 0 | AE35: =+G35+I35+K35+M35+O35+Q35+S35+U35+W35+Y35+AA35+AC35 -> 0 | AF35: =AD35/5 -> 0 | AG35: =IFERROR(AF35/$AF$42%,0) -> 0 | AH35: 11
A36: 10 | B36: Chang Sone | C36: Van 9 | D36: 2515 | F36: 560 | G36: 358.4 | J36: 350 | K36: 224 | AD36: =+F36+H36+J36+L36+N36+P36+R36+T36+V36+X36+Z36+AB36 -> 910 | AE36: =+G36+I36+K36+M36+O36+Q36+S36+U36+W36+Y36+AA36+AC36 -> 582.4 | AF36: =AD36/5 -> 182 | AG36: =IFERROR(AF36/$AF$42%,0) -> 2.4698059 | AH36: 6
A37: 11 | B37: Than Phyu ZaYat | C37: Van 6 | D37: 216 | F37: 700 | G37: 448 | H37: 980 | I37: 627.2 | J37: 700 | K37: 448 | N37: 700 | O37: 448 | AD37: =+F37+H37+J37+L37+N37+P37+R37+T37+V37+X37+Z37+AB37 -> 3080 | AE37: =+G37+I37+K37+M37+O37+Q37+S37+U37+W37+Y37+AA37+AC37 -> 1971.2 | AF37: =AD37/5 -> 616 | AG37: =IFERROR(AF37/$AF$42%,0) -> 8.3593432 | AH37: 3
A38: 12 | C38: Van 8 | D38: 216 | AD38: =SUM(F38:AC38) -> 0 | AG38: =IFERROR(AF38/$AF$42%,0) -> 0 | AH38: 4
A39: 13 | C39: Van 7 | AD39: =SUM(F39:AC39) -> 0 | AG39: =IFERROR(AF39/$AF$42%,0) -> 0 | AH39: 3
A40: 14 | C40: Van 4 | AD40: =SUM(F40:AC40) -> 0 | AG40: =IFERROR(AF40/$AF$42%,0) -> 0 | AH40: 10
B42: Market Total | D42: =SUM(D27:D37) -> 26626.5 | F42: =SUM(F27:F41) -> 2693 | G42: =SUM(G27:G41) -> 2136.38 | H42: =SUM(H27:H41) -> 4378 | I42: =SUM(I27:I41) -> 3425.8 | J42: =SUM(J27:J41) -> 7860 | K42: =SUM(K27:K41) -> 6360.24 | L42: =SUM(L27:L41) -> 3374 | M42: =SUM(M27:M41) -> 2678.48 | ... AF42: =SUM(AF27:AF41) -> 7369 | AG42: 100%
A44: Sale Data Percentage
D45: 2024 Average | F45: January | H45: February | J45: March | L45: April | N45: May | P45: June | R45: July | T45: August | V45: September | X45: October | Z45: November | AB45: December
...

Sheet 4-MawLaMyaing
B1: 2024 - Sales Details MLM (MawLaMyaing)
A3: စဉ် | B3: အမျိုးအမည် | C3: Li | D3: Packing | E3: January | H3: February | K3: March | N3: April | Q3: May | T3: June | W3: July | Z3: August | AC3: September | AF3: October | AI3: November | AL3: December | AO3: Total
E4: Pk | F4: BT | G4: Liter | H4: Pk | I4: BT | J4: Liter. | K4: Pk | L4: BT | M4: Liter. | N4: Pk | O4: BT | P4: Liter. | Q4: Pk | R4: BT | S4: Liter. | T4: Pk | U4: BT | V4: Liter. | W4: Pk | X4: BT | Y4: Liter. | Z4: Pk | AA4: BT | AB4: Liter. | AC4: Pk | AD4: BT | AE4: Liter. | AF4: Pk | AG4: BT | AH4: Liter. | AI4: Pk | AJ4: BT | AK4: Liter. | AL4: Pk | AM4: BT | AN4: Liter. | AO4: Pk | AP4: BT | AQ4: Liter.
A5: 1 | B5: "Zay" Vodka 700-ml | C5: 0.7 | D5: 1 * 12 | E5: 6 | F5: 72 | G5: =F5*C5 -> 50.4 | I5: 0 | J5: =I5*C5 -> 0 | K5: 15 | L5: 180 | M5: =L5*C5 -> 126 | N5: 1 | O5: 12 | P5: =O5*C5 -> 8.4 | Q5: 24 | R5: 288 | S5: =R5*C5 -> 201.6 | T5: 32 | U5: 384 | V5: =U5*C5 -> 268.8 | W5: 38 | X5: 456 | Y5: =X5*C5 -> 319.2 | Z5: 45 | AA5: 540 | AB5: =AA5*C5 -> 378 | AC5: 18 | AD5: 216 | AE5: =AD5*C5 -> 151.2 | AF5: 8 | AG5: 96 | AH5: =AG5*C5 -> 67.2 | AI5: 15 | AJ5: 180 | AK5: =AJ5*C5 -> 126 | AL5: 8 | AM5: 90 | AN5: =AM5*C5 -> 63 | AO5: =E5+H5+K5+N5+Q5+T5+W5+Z5+AC5+AF5+AI5+AL5 -> 210 | AP5: =F5+I5+L5+O5+R5+U5+X5+AA5+AD5+AG5+AJ5+AM5 -> 2514 | AQ5: =G5+J5+M5+P5+S5+V5+Y5+AB5+AE5+AH5+AK5+AN5 -> 1759.8
A6: 3 | B6: "Zay" (1 Liter) | C6: 1 | D6: 1 * 12 | E6: 90 | F6: 1080 | G6: =F6*C6 -> 1080 | H6: 29 | I6: 348 | J6: =I6*C6 -> 348 | K6: 149 | L6: 1788 | M6: =L6*C6 -> 1788 | N6: 91 | O6: 1092 | P6: =O6*C6 -> 1092 | Q6: 55 | R6: 660 | S6: =R6*C6 -> 660 | T6: 51 | U6: 612 | V6: =U6*C6 -> 612 | W6: 99 | X6: 1188 | Y6: =X6*C6 -> 1188 | Z6: 80 | AA6: 960 | AB6: =AA6*C6 -> 960 | AC6: 35 | AD6: 420 | AE6: =AD6*C6 -> 420 | AF6: 100 | AG6: 1200 | AH6: =AG6*C6 -> 1200 | AI6: 211 | AJ6: 2532 | AK6: =AJ6*C6 -> 2532 | AL6: 136 | AM6: 1632 | AN6: =AM6*C6 -> 1632 | AO6: =E6+H6+K6+N6+Q6+T6+W6+Z6+AC6+AF6+AI6+AL6 -> 1126 | AP6: =F6+I6+L6+O6+R6+U6+X6+AA6+AD6+AG6+AJ6+AM6 -> 13512 | AQ6: =G6+J6+M6+P6+S6+V6+Y6+AB6+AE6+AH6+AK6+AN6 -> 13512
A7: 4 | B7: "Zay" (0.6 Liter) | C7: 0.6 | D7: 1 * 12 | G7: =F7*C7 -> 0 | J7: =I7*C7 -> 0 | M7: =L7*C7 -> 0 | P7: =O7*C7 -> 0 | S7: =R7*C7 -> 0 | V7: =U7*C7 -> 0 | Y7: =X7*C7 -> 0 | Z7: 3 | AA7: 36 | AB7: =AA7*C7 -> 21.6 | AE7: =AD7*C7 -> 0 | AH7: =AG7*C7 -> 0 | AK7: =AJ7*C7 -> 0 | AN7: =AM7*C7 -> 0 | AO7: =E7+H7+K7+N7+Q7+T7+W7+Z7+AC7+AF7+AI7+AL7 -> 3 | AP7: =F7+I7+L7+O7+R7+U7+X7+AA7+AD7+AG7+AJ7+AM7 -> 36 | AQ7: =G7+J7+M7+P7+S7+V7+Y7+AB7+AE7+AH7+AK7+AN7 -> 21.6
A8: 5 | B8: "Zay" (0.35 Liter) | C8: 0.35 | D8: 1 * 40 | E8: 0 | K8: 0 | M8: =L8*C8 -> 0 | N8: 10 | O8: 400 | P8: =O8*C8 -> 140 | Q8: 0 | S8: =R8*C8 -> 0 | T8: 0 | V8: =U8*C8 -> 0 | Y8: =X8*C8 -> 0 | AB8: =AA8*C8 -> 0 | AE8: =AD8*C8 -> 0 | AH8: =AG8*C8 -> 0 | AK8: =AJ8*C8 -> 0 | AN8: =AM8*C8 -> 0 | AO8: =E8+H8+K8+N8+Q8+T8+W8+Z8+AC8+AF8+AI8+AL8 -> 10 | AP8: =F8+I8+L8+O8+R8+U8+X8+AA8+AD8+AG8+AJ8+AM8 -> 400 | AQ8: =G8+J8+M8+P8+S8+V8+Y8+AB8+AE8+AH8+AK8+AN8 -> 140
A9: 6 | B9: "Zay" Vodka- 640ml | C9: 0.64 | D9: 1 * 14 | E9: 1999 | F9: 27986 | G9: =F9*C9 -> 17911.04 | H9: 1435 | I9: 20090 | J9: =I9*C9 -> 12857.6 | K9: 2013 | L9: 28182 | M9: =L9*C9 -> 18036.48 | N9: 2113 | O9: 29582 | P9: =O9*C9 -> 18932.48 | Q9: 1910 | R9: 26740 | S9: =R9*C9 -> 17113.6 | T9: 634 | U9: 31696 | V9: =U9*C9 -> 20285.44 | W9: 599 | X9: 29932 | Y9: =X9*C9 -> 19156.48 | Z9: 2253 | AA9: 31542 | AB9: =AA9*C9 -> 20186.88 | AC9: 1601 | AD9: 22414 | AE9: =AD9*C9 -> 14344.96 | AF9: 2782 | AG9: 38948 | AH9: =AG9*C9 -> 24926.72 | AI9: 1712 | AJ9: 23968 | AK9: =AJ9*C9 -> 15339.52 | AL9: 1855 | AM9: 25970 | AN9: =AM9*C9 -> 16620.8 | AO9: =E9+H9+K9+N9+Q9+T9+W9+Z9+AC9+AF9+AI9+AL9 -> 20906 | AP9: =F9+I9+L9+O9+R9+U9+X9+AA9+AD9+AG9+AJ9+AM9 -> 337050 | AQ9: =G9+J9+M9+P9+S9+V9+Y9+AB9+AE9+AH9+AK9+AN9 -> 215712
A10: 7 | B10: Kaung Kyi (1 Liter)_25% | C10: 1 | D10: 1 * 12 | G10: =F10*C10 -> 0 | J10: =I10*C10 -> 0 | M10: =L10*C10 -> 0 | P10: =O10*C10 -> 0 | S10: =R10*C10 -> 0 | V10: =U10*C10 -> 0 | Y10: =X10*C10 -> 0 | AB10: =AA10*C10 -> 0 | AE10: =AD10*C10 -> 0 | AH10: =AG10*C10 -> 0 | AK10: =AJ10*C10 -> 0 | AN10: =AM10*C10 -> 0 | AO10: =E10+H10+K10+N10+Q10+T10+W10+Z10+AC10+AF10+AI10+AL10 -> 0 | AP10: =F10+I10+L10+O10+R10+U10+X10+AA10+AD10+AG10+AJ10+AM10 -> 0 | AQ10: =G10+J10+M10+P10+S10+V10+Y10+AB10+AE10+AH10+AK10+AN10 -> 0
A11: 8 | B11: Zayawaddy Red(1 Liter)30% | C11: 1 | D11: 1 * 12 | E11: 402 | F11: 4824 | G11: =F11*C11 -> 4824 | H11: 375 | I11: 4500 | J11: =I11*C11 -> 4500 | K11: 165 | L11: 1980 | M11: =L11*C11 -> 1980 | N11: 591 | O11: 7092 | P11: =O11*C11 -> 7092 | Q11: 510 | R11: 6120 | S11: =R11*C11 -> 6120 | T11: 1080 | U11: 12960 | V11: =U11*C11 -> 12960 | W11: 905 | X11: 10860 | Y11: =X11*C11 -> 10860 | Z11: 700 | AA11: 8400 | AB11: =AA11*C11 -> 8400 | AC11: 750 | AD11: 9000 | AE11: =AD11*C11 -> 9000 | AF11: 1410 | AG11: 16920 | AH11: =AG11*C11 -> 16920 | AI11: 1012 | AJ11: 12144 | AK11: =AJ11*C11 -> 12144 | AL11: 1253 | AM11: 15036 | AN11: =AM11*C11 -> 15036 | AO11: =E11+H11+K11+N11+Q11+T11+W11+Z11+AC11+AF11+AI11+AL11 -> 9153 | AP11: =F11+I11+L11+O11+R11+U11+X11+AA11+AD11+AG11+AJ11+AM11 -> 109836 | AQ11: =G11+J11+M11+P11+S11+V11+Y11+AB11+AE11+AH11+AK11+AN11 -> 109836
A12: 9 | B12: Zeyawaddy Rum (43%) | C12: 0.64 | D12: 1 * 14 | E12: 105 | F12: 1470 | G12: =F12*C12 -> 940.8 | H12: 102 | I12: 1428 | J12: =I12*C12 -> 913.92 | K12: 120 | L12: 1680 | M12: =L12*C12 -> 1075.2 | N12: 200 | O12: 2800 | P12: =O12*C12 -> 1792 | Q12: 110 | R12: 1540 | S12: =R12*C12 -> 985.6 | T12: 145 | U12: 2030 | V12: =U12*C12 -> 1299.2 | W12: 125 | X12: 1750 | Y12: =X12*C12 -> 1120 | Z12: 180 | AA12: 2520 | AB12: =AA12*C12 -> 1612.8 | AC12: 60 | AD12: 840 | AE12: =AD12*C12 -> 537.6 | AF12: 110 | AG12: 1540 | AH12: =AG12*C12 -> 985.6 | AI12: 175 | AJ12: 2450 | AK12: =AJ12*C12 -> 1568 | AL12: 100 | AM12: 1400 | AN12: =AM12*C12 -> 896 | AO12: =E12+H12+K12+N12+Q12+T12+W12+Z12+AC12+AF12+AI12+AL12 -> 1532 | AP12: =F12+I12+L12+O12+R12+U12+X12+AA12+AD12+AG12+AJ12+AM12 -> 21448 | AQ12: =G12+J12+M12+P12+S12+V12+Y12+AB12+AE12+AH12+AK12+AN12 -> 13726.72
A13: 10 | B13: Zayawaddy Red | C13: 0.64 | D13: 1 * 14 | E13: 384 | F13: 5376 | G13: =F13*C13 -> 3440.64 | H13: 406 | I13: 5684 | J13: =I13*C13 -> 3637.76 | K13: 390 | L13: 5460 | M13: =L13*C13 -> 3494.4 | N13: 512 | O13: 7168 | P13: =O13*C13 -> 4587.52 | Q13: 476 | R13: 6664 | S13: =R13*C13 -> 4264.96 | T13: 611 | U13: 8554 | V13: =U13*C13 -> 5474.56 | W13: 348 | X13: 4872 | Y13: =X13*C13 -> 3118.08 | Z13: 936 | AA13: 13104 | AB13: =AA13*C13 -> 8386.56 | AC13: 205 | AD13: 2870 | AE13: =AD13*C13 -> 1836.8 | AF13: 511 | AG13: 7154 | AH13: =AG13*C13 -> 4578.56 | AI13: 490 | AJ13: 6860 | AK13: =AJ13*C13 -> 4390.4 | AL13: 816 | AM13: 11424 | AN13: 7311.36 | AO13: =E13+H13+K13+N13+Q13+T13+W13+Z13+AC13+AF13+AI13+AL13 -> 6085 | AP13: =F13+I13+L13+O13+R13+U13+X13+AA13+AD13+AG13+AJ13+AM13 -> 85190 | AQ13: =G13+J13+M13+P13+S13+V13+Y13+AB13+AE13+AH13+AK13+AN13 -> 54521.6
A14: 11 | B14: Dagon Tamarind (1 Liter) | C14: 1 | D14: 1 * 12 | E14: 2 | F14: 24 | G14: =F14*C14 -> 24 | H14: 21 | I14: 252 | J14: =I14*C14 -> 252 | K14: 2 | L14: 24 | M14: =L14*C14 -> 24 | N14: 2 | O14: 24 | P14: =O14*C14 -> 24 | Q14: 2 | R14: 24 | S14: =R14*C14 -> 24 | T14: 3 | U14: 36 | V14: =U14*C14 -> 36 | W14: 2 | X14: 24 | Y14: =X14*C14 -> 24 | Z14: 18 | AA14: 216 | AB14: =AA14*C14 -> 216 | AC14: 10 | AD14: 120 | AE14: =AD14*C14 -> 120 | AF14: 15 | AG14: 180 | AH14: =AG14*C14 -> 180 | AI14: 11 | AJ14: 132 | AK14: =AJ14*C14 -> 132 | AL14: 35 | AM14: 420 | AN14: =AM14*C14 -> 420 | AO14: =E14+H14+K14+N14+Q14+T14+W14+Z14+AC14+AF14+AI14+AL14 -> 123 | AP14: =F14+I14+L14+O14+R14+U14+X14+AA14+AD14+AG14+AJ14+AM14 -> 1476 | AQ14: =G14+J14+M14+P14+S14+V14+Y14+AB14+AE14+AH14+AK14+AN14 -> 1476
A15: 12 | B15: Dagon Pineapple | C15: 0.64 | D15: 1 * 14 | E15: 28 | F15: 392 | G15: =F15*C15 -> 250.88 | H15: 18 | I15: 252 | J15: =I15*C15 -> 161.28 | K15: 19 | L15: 266 | M15: =L15*C15 -> 170.24 | N15: 34 | O15: 476 | P15: =O15*C15 -> 304.64 | Q15: 20 | R15: 280 | S15: =R15*C15 -> 179.2 | T15: 36 | U15: 504 | V15: =U15*C15 -> 322.56 | W15: 37 | X15: 518 | Y15: =X15*C15 -> 331.52 | AA15: 0 | AB15: =AA15*C15 -> 0 | AC15: 11 | AD15: 154 | AE15: =AD15*C15 -> 98.56 | AF15: 14 | AG15: 196 | AH15: =AG15*C15 -> 125.44 | AI15: 26 | AJ15: 364 | AK15: =AJ15*C15 -> 232.96 | AL15: 10 | AM15: 140 | AN15: =AM15*C15 -> 89.6 | AO15: =E15+H15+K15+N15+Q15+T15+W15+Z15+AC15+AF15+AI15+AL15 -> 253 | AP15: =F15+I15+L15+O15+R15+U15+X15+AA15+AD15+AG15+AJ15+AM15 -> 3542 | AQ15: =G15+J15+M15+P15+S15+V15+Y15+AB15+AE15+AH15+AK15+AN15 -> 2266.88
