Workbook
Name aa: #REF!
Name aaa: #REF!
Name aaaaaaa: #REF!
Name atr: #REF!
Name b: #REF!
Name bb: #REF!
Name Beg_Bal: #REF!
Name Cash_Cr: #REF!
Name Cash_Dr: #REF!
Name cc: #REF!
Name ccc: #REF!
Name cr: #REF!
Name crs: #REF!
Name Data: #REF!
Name dd: #REF!
Name ddd: #REF!
Name dr: #REF!
Name drs: #REF!
Name End_Bal: #REF!
Name Extra_Pay: #REF!
Name fgf: #REF!
Name fgjhj: #REF!
Name Full_Print: #REF!
Name Header_Row: ROW(#REF!)
Name hjj: #REF!
Name hjkjk: #REF!
Name hmjhj: #REF!
Name Int: #REF!
Name Interest_Rate: #REF!
Name jbkjkl: #REF!
Name Journal_Cr: #REF!
Name Journal_Dr: #REF!
Name kdt: #REF!
Name Last_Row: IF(Values_Entered,Header_Row+Number_of_Payments,Header_Row)
Name Loan_Amount: #REF!
Name Loan_Start: #REF!
Name Loan_Years: #REF!
Name LSO: #REF!
Name lsoq: #REF!
Name mms: #REF!
Name neew: #REF!
Name New: #REF!
Name Num_Pmt_Per_Year: #REF!
Name Number_of_Payments: MATCH(0.01,End_Bal,-1)+1
Name Opening_Cr: #REF!
Name Opening_Dr: #REF!
Name Pay_Date: #REF!
Name Pay_Num: #REF!
Name Payment_Date: DATE(YEAR([0]!Loan_Start),MONTH([0]!Loan_Start)+Payment_Number,DAY([0]!Loan_Start))
Name Payment_Date: DATE(YEAR([0]!Loan_Start),MONTH([0]!Loan_Start)+Payment_Number,DAY([0]!Loan_Start))
Name Payment_Date: DATE(YEAR([0]!Loan_Start),MONTH([0]!Loan_Start)+Payment_Number,DAY([0]!Loan_Start))
Name Payment_Date: DATE(YEAR(Loan_Start),MONTH(Loan_Start)+Payment_Number,DAY(Loan_Start))
Name Princ: #REF!
Name Print_Area_Reset: OFFSET(Full_Print,0,0,Last_Row)
Name s: #REF!
Name Sched_Pay: #REF!
Name Scheduled_Extra_Payments: #REF!
Name Scheduled_Interest_Rate: #REF!
Name Scheduled_Monthly_Payment: #REF!
Name smm: #REF!

Sheet Compare for MLM
A1: BE Sales For MLM (All In Bottle)
A2: No | B2: Month | C2: 2022 (BE) | E2: 2023 (BE) | G2: 2024 (BE) | I2: 2025 (BE) | K2: 2026 (BE) | M2: Total
C3: Bottle | D3: Liters | E3: Bottle | F3: Liters | G3: Bottle | H3: Liters | I3: Bottle | J3: Liters | K3: Bottle | L3: Liters | M3: Bottle | N3: Liters
A4: 1 | B4: January | C4: 285358 | D4: 185180.78 | E4: =+'2025'!AH142 -> 325646 | F4: 221628.56 | G4: 284980 | H4: 200645.96 | I4: =+'2025'!CH142 -> 292067 | J4: =+'2025'!CI142 -> 217035.26 | K4: ='2026'!DH148 -> 299175 | L4: ='2026'!DI148 -> 233525.95 | M4: =C4+E4+G4+I4+K4 -> 1487226 | N4: =D4+F4+H4+J4+L4 -> 1058016.5
A5: 2 | B5: February | C5: =+'2025'!J142 -> 265299 | D5: =+'2025'!K142 -> 173179.26 | E5: =+'2025'!AJ142 -> 268997 | F5: 180251.2 | G5: 250402 | H5: 175347.76 | I5: =+'2025'!CJ142 -> 293594 | J5: =+'2025'!CK142 -> 215869.64 | K5: ='2026'!DJ148 -> 285899 | L5: ='2026'!DK148 -> 221678.61 | M5: =C5+E5+G5+I5+K5 -> 1364191 | N5: =D5+F5+H5+J5+L5 -> 966326.47
A6: 3 | B6: March | C6: =+'2025'!L142 -> 337952 | D6: =+'2025'!M142 -> 219847.95 | E6: =+'2025'!AL142 -> 343569 | F6: 234109.38 | G6: 306180 | H6: 216101.84 | I6: =+'2025'!CL142 -> 365124 | J6: =+'2025'!CM142 -> 263664.64 | M6: =C6+E6+G6+I6+K6 -> 1352825 | N6: =D6+F6+H6+J6+L6 -> 933723.81
A7: 4 | B7: April | C7: 303706 | D7: 197944.9 | E7: =+'2025'!AN142 -> 330260 | F7: 224286 | G7: 313206 | H7: 220161.04 | I7: ='2025'!CN142 -> 250122 | J7: ='2025'!CO142 -> 175295.28 | M7: =C7+E7+G7+I7+K7 -> 1197294 | N7: =D7+F7+H7+J7+L7 -> 817687.22
A8: 5 | B8: May | C8: 366957 | D8: 238095.09 | E8: =+'2025'!AP142 -> 346266 | F8: 236673.48 | G8: 319523 | H8: 221018.78 | I8: ='2025'!CP142 -> 366424 | J8: ='2025'!CQ142 -> 272334.96 | M8: =C8+E8+G8+I8+K8 -> 1399170 | N8: =D8+F8+H8+J8+L8 -> 968122.31
A9: 6 | B9: June | C9: 333259 | D9: 218441.14 | E9: =+'2025'!AR142 -> 308961 | F9: 212208.12 | G9: 319420 | H9: 227006.72 | I9: ='2025'!CR142 -> 342708 | J9: ='2025'!CS142 -> 256131.2 | M9: =C9+E9+G9+I9+K9 -> 1304348 | N9: =D9+F9+H9+J9+L9 -> 913787.18
A10: 7 | B10: July | C10: 294089 | D10: 192043.21 | E10: =+'2025'!AT142 -> 316734 | F10: 216206.28 | G10: 309212 | H10: 219811.2 | I10: ='2025'!CT142 -> 319332 | J10: ='2025'!CU142 -> 237110.32 | M10: =C10+E10+G10+I10+K10 -> 1239367 | N10: =D10+F10+H10+J10+L10 -> 865171.01
A11: 8 | B11: August | C11: 346406 | D11: 226613.72 | E11: =+'2025'!AV142 -> 380944 | F11: 255979.2 | G11: 358266 | H11: 257544.8 | I11: ='2025'!CV142 -> 306217 | J11: ='2025'!CW142 -> 234523.11 | M11: =C11+E11+G11+I11+K11 -> 1391833 | N11: =D11+F11+H11+J11+L11 -> 974660.83
A12: 9 | B12: September | C12: =+'2025'!X142 -> 290124 | D12: =+'2025'!Y142 -> 192315.12 | E12: =+'2025'!AX142 -> 202293 | F12: 141859.87 | G12: 289469 | H12: 211684.06 | I12: ='2025'!CX142 -> 310551 | J12: ='2025'!CY142 -> 237489.63 | M12: =C12+E12+G12+I12+K12 -> 1092437 | N12: =D12+F12+H12+J12+L12 -> 783348.68
A13: 10 | B13: October | C13: =+'2025'!Z142 -> 247021 | D13: =+'2025'!AA142 -> 165927.72 | E13: =+'2025'!AZ142 -> 226479 | F13: 156523.74 | G13: 334424 | H13: 242242.68 | I13: ='2025'!CZ142 -> 302387 | J13: ='2025'!DA142 -> 227076.46 | M13: =C13+E13+G13+I13+K13 -> 1110311 | N13: =D13+F13+H13+J13+L13 -> 791770.6
A14: 11 | B14: November | C14: 252029 | D14: 167403.14 | E14: =+'2025'!BB142 -> 262455 | F14: 181771.08 | G14: 251296 | H14: 181264.84 | I14: ='2025'!DB142 -> 282632 | J14: ='2025'!DC142 -> 215962.82 | M14: =C14+E14+G14+I14+K14 -> 1048412 | N14: =D14+F14+H14+J14+L14 -> 746401.88
A15: 12 | B15: December | C15: =+'2025'!AD142 -> 320655 | D15: =+'2025'!AE142 -> 216544.5 | E15: =+'2025'!BD142 -> 287068 | F15: 200616.88 | G15: 298525 | H15: 220445.46 | I15: ='2025'!DD142 -> 308173 | J15: ='2025'!DE142 -> 239119.67 | M15: =C15+E15+G15+I15+K15 -> 1214421 | N15: =D15+F15+H15+J15+L15 -> 876726.51
B16: လက်ဆောင်ပေးစာရင်း | K16: 72 | L16: 63.36 | M16: =C16+E16+G16+I16+K16 -> 72 | N16: =D16+F16+H16+J16+L16 -> 63.36
M17: =C17+E17+G17+I17+K17 -> 0 | N17: =D17+F17+H17+J17+L17 -> 0
B18: Total | C18: =SUM(C4:C17) -> 3642855 | D18: =SUM(D4:D17) -> 2393536.5 | E18: =SUM(E4:E17) -> 3599672 | F18: =SUM(F4:F17) -> 2462113.8 | G18: =SUM(G4:G17) -> 3634903 | H18: =SUM(H4:H17) -> 2593275.1 | I18: =SUM(I4:I17) -> 3739331 | J18: =SUM(J4:J17) -> 2791613 | ... N18: =SUM(N4:N17) -> 10695806
C19: =+C18-'2025'!AF142 -> 0 | D19: =+D18-'2025'!AG142 -> 0 | E19: =+E18-'2025'!BF142 -> 0 | F19: =+F18-'2025'!BG142 -> 0 | G19: =G18-'2025'!CF142 -> 0 | H19: =H18-'2025'!CG142 -> 0 | I19: =I18-'2025'!DF142 -> 0 | J19: =J18-'2025'!DG142 -> 0
A21: BE (KK) Sales For MLM (All In Bottle)
A22: No | B22: Month | C22: 2022 (KK) | E22: 2023 (KK) | G22: 2024 (KK) | I22: 2025 (KK) | K22: 2026 (KK) | M22: Total
C23: Bottle | D23: Liters | E23: Bottle | F23: Liters | G23: Bottle | H23: Liters | I23: Bottle | J23: Liters | M23: Bottle | N23: Liters
A24: 1 | B24: Kaung Kyi (1 Liter)_25% | C24: =+'2025'!AF16 -> 0 | D24: =+'2025'!AG16 -> 0 | E24: =+'2025'!BF16 -> 0 | F24: =+'2025'!BG16 -> 0 | G24: =+'2025'!CF16 -> 0 | H24: =+'2025'!CG16 -> 0 | I24: =+'2025'!DF16 -> 276 | J24: =+'2025'!DG16 -> 276 | K24: ='2026'!EF16 -> 901 | L24: ='2026'!EG16 -> 901 | M24: =C24+E24+G24+I24+K24 -> 1177 | N24: =D24+F24+H24+J24+L24 -> 1177
A25: 2 | B25: Kaung Kyi (1 Liter)_40% | C25: =+'2025'!AF17 -> 0 | D25: =+'2025'!AG17 -> 0 | E25: =+'2025'!BF17 -> 492 | F25: =+'2025'!BG17 -> 492 | G25: =+'2025'!CF17 -> 0 | H25: =+'2025'!CG17 -> 0 | I25: =+'2025'!DF17 -> 1934 | J25: =+'2025'!DG17 -> 1934 | K25: ='2026'!EF17 -> 1282 | L25: ='2026'!EG17 -> 1282 | M25: =C25+E25+G25+I25+K25 -> 3708 | N25: =D25+F25+H25+J25+L25 -> 3708
A26: 3 | B26: Kaung Kyi (0.6 Liter)_25% | C26: =+'2025'!AF18 -> 0 | D26: =+'2025'!AG18 -> 0 | E26: =+'2025'!BF18 -> 0 | F26: =+'2025'!BG18 -> 0 | G26: =+'2025'!CF18 -> 0 | H26: =+'2025'!CG18 -> 0 | I26: =+'2025'!DF18 -> 0 | J26: =+'2025'!DG18 -> 0 | K26: ='2026'!EF18 -> 0 | L26: ='2026'!EG18 -> 0 | M26: =C26+E26+G26+I26+K26 -> 0 | N26: =D26+F26+H26+J26+L26 -> 0
A27: 4 | B27: Kaung Kyi (0.6 Liter)_40% | C27: =+'2025'!AF19 -> 0 | D27: =+'2025'!AG19 -> 0 | E27: =+'2025'!BF19 -> 0 | F27: =+'2025'!BG19 -> 0 | G27: =+'2025'!CF19 -> 0 | H27: =+'2025'!CG19 -> 0 | I27: =+'2025'!DF19 -> 0 | J27: =+'2025'!DG19 -> 0 | K27: ='2026'!EF19 -> 0 | L27: ='2026'!EG19 -> 0 | M27: =C27+E27+G27+I27+K27 -> 0 | N27: =D27+F27+H27+J27+L27 -> 0
A28: 5 | B28: Kaung Kyi (0.35 Liter)_25% | C28: =+'2025'!AF20 -> 0 | D28: =+'2025'!AG20 -> 0 | E28: =+'2025'!BF20 -> 0 | F28: =+'2025'!BG20 -> 0 | G28: =+'2025'!CF20 -> 0 | H28: =+'2025'!CG20 -> 0 | I28: =+'2025'!DF20 -> 0 | J28: =+'2025'!DG20 -> 0 | K28: ='2026'!EF20 -> 0 | L28: ='2026'!EG20 -> 0 | M28: =C28+E28+G28+I28+K28 -> 0 | N28: =D28+F28+H28+J28+L28 -> 0
A29: 6 | B29: Kaung Kyi ( 0.35 Liter) - 40% | C29: =+'2025'!AF21 -> 0 | D29: =+'2025'!AG21 -> 0 | E29: =+'2025'!BF21 -> 0 | F29: =+'2025'!BG21 -> 0 | G29: =+'2025'!CF21 -> 0 | H29: =+'2025'!CG21 -> 0 | I29: =+'2025'!DF21 -> 0 | J29: =+'2025'!DG21 -> 0 | K29: ='2026'!EF21 -> 0 | L29: ='2026'!EG21 -> 0 | M29: =C29+E29+G29+I29+K29 -> 0 | N29: =D29+F29+H29+J29+L29 -> 0
A30: 7 | B30: Kaung Kyi | C30: =+'2025'!AF22 -> 29144 | D30: =+'2025'!AG22 -> 18652.16 | E30: =+'2025'!BF22 -> 27972 | F30: =+'2025'!BG22 -> 17902.08 | G30: =+'2025'!CF22 -> 36260 | H30: =+'2025'!CG22 -> 23206.4 | I30: =+'2025'!DF22 -> 30800 | J30: =+'2025'!DG22 -> 19712 | K30: ='2026'!EF22 -> 7042 | L30: ='2026'!EG22 -> 4506.88 | M30: =C30+E30+G30+I30+K30 -> 131218 | N30: =D30+F30+H30+J30+L30 -> 83979.52
A31: 8 | B31: Kaung Kyi (40%) | C31: =+'2025'!AF23 -> 0 | D31: =+'2025'!AG23 -> 0 | E31: =+'2025'!BF23 -> 0 | F31: =+'2025'!BG23 -> 0 | G31: =+'2025'!CF23 -> 0 | H31: =+'2025'!CG23 -> 0 | I31: =+'2025'!DF23 -> 0 | J31: =+'2025'!DG23 -> 0 | K31: ='2026'!EF23 -> 0 | L31: ='2026'!EG23 -> 0 | M31: =C31+E31+G31+I31+K31 -> 0 | N31: =D31+F31+H31+J31+L31 -> 0
A32: 9 | B32: Kaung Kyi (46%) | C32: =+'2025'!AF24 -> 0 | D32: =+'2025'!AG24 -> 0 | E32: =+'2025'!BF24 -> 0 | F32: =+'2025'!BG24 -> 0 | G32: =+'2025'!CF24 -> 0 | H32: =+'2025'!CG24 -> 0 | I32: =+'2025'!DF24 -> 0 | J32: =+'2025'!DG24 -> 0 | K32: ='2026'!EF24 -> 0 | L32: ='2026'!EG24 -> 0 | M32: =C32+E32+G32+I32+K32 -> 0 | N32: =D32+F32+H32+J32+L32 -> 0
B34: Total | C34: =SUM(C24:C33) -> 29144 | D34: =SUM(D24:D33) -> 18652.16 | E34: =SUM(E24:E33) -> 28464 | F34: =SUM(F24:F33) -> 18394.08 | G34: =SUM(G24:G33) -> 36260 | H34: =SUM(H24:H33) -> 23206.4 | I34: =SUM(I24:I33) -> 33010 | J34: =SUM(J24:J33) -> 21922 | ... N34: =SUM(N24:N33) -> 88864.52

Sheet 2024
B1: SKU Summary for MLM (2024)
A2: SR. | B2: Description | C2: Li | D2: 45292 | F2: 45323 | H2: 45352 | J2: 45383 | L2: 45413 | N2: 45444 | P2: 45474 | R2: 45505 | T2: 45536 | V2: 45566 | X2: 45597 | Z2: 45627 | AB2: Total
D3: Bottle | E3: Li | F3: Bottle | G3: Li | H3: Bottle | I3: Li | J3: Bottle | K3: ml | L3: Bottle | M3: ml | N3: Bottle | O3: ml | P3: Bottle | Q3: ml | R3: Bottle | S3: ml | T3: Bottle | U3: ml | V3: Bottle | W3: ml | X3: Bottle | Y3: ml | Z3: Bottle | AA3: ml | AB3: Bottle | AC3: ml
A4: 1 | B4: ဇေ Vodka | C4: 0.7 | D4: 3696 | E4: =D4*$C4 -> 2587.2 | F4: 2892 | G4: =F4*$C4 -> 2024.4 | H4: 2748 | I4: =H4*$C4 -> 1923.6 | J4: 3288 | K4: =J4*$C4 -> 2301.6 | L4: 1764 | M4: =L4*$C4 -> 1234.8 | N4: 3144 | O4: =N4*$C4 -> 2200.8 | P4: 3696 | Q4: =P4*$C4 -> 2587.2 | R4: 3840 | S4: =R4*$C4 -> 2688 | T4: 756 | U4: =T4*$C4 -> 529.2 | V4: 3636 | W4: =V4*$C4 -> 2545.2 | X4: 2556 | Y4: =X4*$C4 -> 1789.2 | Z4: 4626 | AA4: =Z4*$C4 -> 3238.2 | AB4: =Z4+X4+V4+T4+R4+P4+N4+L4+J4+H4+F4+D4 -> 36642 | AC4: =AB4*$C4 -> 25649.4
A5: 2 | B5: ဇေ အရက်သန့် | C5: 0.64 | D5: 36036 | E5: =D5*$C5 -> 23063.04 | F5: 30366 | G5: =F5*$C5 -> 19434.24 | H5: =36848+42 -> 36890 | I5: =H5*$C5 -> 23609.6 | J5: 40880 | K5: =J5*$C5 -> 26163.2 | L5: 39648 | M5: =L5*$C5 -> 25374.72 | N5: 37646 | O5: =N5*$C5 -> 24093.44 | P5: 44604 | Q5: =P5*$C5 -> 28546.56 | R5: 43442 | S5: =R5*$C5 -> 27802.88 | T5: 27664 | U5: =T5*$C5 -> 17704.96 | V5: 47852 | W5: =V5*$C5 -> 30625.28 | X5: 31528 | Y5: =X5*$C5 -> 20177.92 | Z5: 35280 | AA5: =Z5*$C5 -> 22579.2 | AB5: =Z5+X5+V5+T5+R5+P5+N5+L5+J5+H5+F5+D5 -> 451836 | AC5: =AB5*$C5 -> 289175.04
A6: 3 | B6: "ဇေ" ကော်ဘူး (1 Liter) | C6: 1 | D6: 4680 | E6: =D6*$C6 -> 4680 | F6: 2868 | G6: =F6*$C6 -> 2868 | H6: 4572 | I6: =H6*$C6 -> 4572 | J6: 4032 | K6: =J6*$C6 -> 4032 | L6: 2760 | M6: =L6*$C6 -> 2760 | N6: 4632 | O6: =N6*$C6 -> 4632 | P6: 5772 | Q6: =P6*$C6 -> 5772 | R6: 4980 | S6: =R6*$C6 -> 4980 | T6: 4320 | U6: =T6*$C6 -> 4320 | V6: 4980 | W6: =V6*$C6 -> 4980 | X6: 5388 | Y6: =X6*$C6 -> 5388 | Z6: 2772 | AA6: =Z6*$C6 -> 2772 | AB6: =Z6+X6+V6+T6+R6+P6+N6+L6+J6+H6+F6+D6 -> 51756 | AC6: =AB6*$C6 -> 51756
A7: 4 | B7: "ဇေ" ကော်ဘူး (0.6 Liter) | C7: 0.6 | E7: =D7*$C7 -> 0 | G7: =F7*$C7 -> 0 | I7: =H7*$C7 -> 0 | K7: =J7*$C7 -> 0 | L7: 60 | M7: =L7*$C7 -> 36 | O7: =N7*$C7 -> 0 | Q7: =P7*$C7 -> 0 | R7: 36 | S7: =R7*$C7 -> 21.6 | U7: =T7*$C7 -> 0 | W7: =V7*$C7 -> 0 | Y7: =X7*$C7 -> 0 | AA7: =Z7*$C7 -> 0 | AB7: =Z7+X7+V7+T7+R7+P7+N7+L7+J7+H7+F7+D7 -> 96 | AC7: =AB7*$C7 -> 57.6
B8: "ဇေ" ကော်ဘူး (0.3Liter) | C8: 0.35 | D8: 280 | E8: =D8*$C8 -> 98 | F8: 38316 | G8: =F8*$C8 -> 13410.6 | H8: 200 | I8: =H8*$C8 -> 70 | J8: 400 | K8: =J8*$C8 -> 140 | N8: 1000 | O8: =N8*$C8 -> 350 | P8: 1000 | Q8: =P8*$C8 -> 350 | R8: 200 | S8: =R8*$C8 -> 70 | T8: 200 | U8: =T8*$C8 -> 70 | V8: 400 | W8: =V8*$C8 -> 140 | Y8: =X8*$C8 -> 0 | Z8: 800 | AA8: =Z8*$C8 -> 280 | AB8: =Z8+X8+V8+T8+R8+P8+N8+L8+J8+H8+F8+D8 -> 42796 | AC8: =AB8*$C8 -> 14978.6
A9: 5 | B9: ဇေယျဝတီ Red (1 Liter) 30% | C9: 1 | D9: 45624 | E9: =D9*$C9 -> 45624 | G9: =F9*$C9 -> 0 | H9: 51060 | I9: =H9*$C9 -> 51060 | J9: 50352 | K9: =J9*$C9 -> 50352 | L9: 42816 | M9: =L9*$C9 -> 42816 | N9: 58200 | O9: =N9*$C9 -> 58200 | P9: 55260 | Q9: =P9*$C9 -> 55260 | R9: 72780 | S9: =R9*$C9 -> 72780 | T9: 68988 | U9: =T9*$C9 -> 68988 | V9: 72912 | W9: =V9*$C9 -> 72912 | X9: 50760 | Y9: =X9*$C9 -> 50760 | Z9: 78312 | AA9: =Z9*$C9 -> 78312 | AB9: =Z9+X9+V9+T9+R9+P9+N9+L9+J9+H9+F9+D9 -> 647064 | AC9: =AB9*$C9 -> 647064
A10: 6 | B10: ကောင်းကြည် (1 Liter ) 25% | C10: 2 | E10: =D10*$C10 -> 0 | G10: =F10*$C10 -> 0 | I10: =H10*$C10 -> 0 | K10: =J10*$C10 -> 0 | M10: =L10*$C10 -> 0 | O10: =N10*$C10 -> 0 | Q10: =P10*$C10 -> 0 | S10: =R10*$C10 -> 0 | U10: =T10*$C10 -> 0 | W10: =V10*$C10 -> 0 | Y10: =X10*$C10 -> 0 | AA10: =Z10*$C10 -> 0 | AB10: =Z10+X10+V10+T10+R10+P10+N10+L10+J10+H10+F10+D10 -> 0 | AC10: =AB10*$C10 -> 0
A11: 7 | B11: ကောင်းကြည် (0.6 Liter ) 25% | C11: 0.6 | E11: =D11*$C11 -> 0 | G11: =F11*$C11 -> 0 | I11: =H11*$C11 -> 0 | K11: =J11*$C11 -> 0 | M11: =L11*$C11 -> 0 | O11: =N11*$C11 -> 0 | Q11: =P11*$C11 -> 0 | S11: =R11*$C11 -> 0 | U11: =T11*$C11 -> 0 | W11: =V11*$C11 -> 0 | Y11: =X11*$C11 -> 0 | AA11: =Z11*$C11 -> 0 | AB11: =Z11+X11+V11+T11+R11+P11+N11+L11+J11+H11+F11+D11 -> 0 | AC11: =AB11*$C11 -> 0
A12: 8 | B12: ကောင်းကြည် (1 Liter ) 40% | C12: 1 | E12: =D12*$C12 -> 0 | G12: =F12*$C12 -> 0 | I12: =H12*$C12 -> 0 | K12: =J12*$C12 -> 0 | M12: =L12*$C12 -> 0 | N12: 156 | O12: =N12*$C12 -> 156 | Q12: =P12*$C12 -> 0 | S12: =R12*$C12 -> 0 | U12: =T12*$C12 -> 0 | W12: =V12*$C12 -> 0 | Y12: =X12*$C12 -> 0 | AA12: =Z12*$C12 -> 0 | AB12: =Z12+X12+V12+T12+R12+P12+N12+L12+J12+H12+F12+D12 -> 156 | AC12: =AB12*$C12 -> 156
A13: 9 | B13: ဒဂုံမန်ကျည်း ကော်ဘူး (1 Liter) | C13: 1 | D13: 24 | E13: =D13*$C13 -> 24 | F13: 252 | G13: =F13*$C13 -> 252 | H13: 24 | I13: =H13*$C13 -> 24 | J13: 108 | K13: =J13*$C13 -> 108 | L13: 24 | M13: =L13*$C13 -> 24 | O13: =N13*$C13 -> 0 | P13: 24 | Q13: =P13*$C13 -> 24 | R13: 216 | S13: =R13*$C13 -> 216 | T13: 120 | U13: =T13*$C13 -> 120 | V13: 180 | W13: =V13*$C13 -> 180 | X13: 132 | Y13: =X13*$C13 -> 132 | Z13: 420 | AA13: =Z13*$C13 -> 420 | AB13: =Z13+X13+V13+T13+R13+P13+N13+L13+J13+H13+F13+D13 -> 1524 | AC13: =AB13*$C13 -> 1524
A14: 10 | B14: ရွှေမင်းသားခေါင်ရည် (0.6 Liter) | C14: 0.3 | E14: =D14*$C14 -> 0 | G14: =F14*$C14 -> 0 | I14: =H14*$C14 -> 0 | K14: =J14*$C14 -> 0 | M14: =L14*$C14 -> 0 | O14: =N14*$C14 -> 0 | Q14: =P14*$C14 -> 0 | S14: =R14*$C14 -> 0 | U14: =T14*$C14 -> 0 | W14: =V14*$C14 -> 0 | Y14: =X14*$C14 -> 0 | AA14: =Z14*$C14 -> 0 | AB14: =Z14+X14+V14+T14+R14+P14+N14+L14+J14+H14+F14+D14 -> 0 | AC14: =AB14*$C14 -> 0
A15: 11 | B15: ဇေယျဝတီ High 43% | C15: 0.64 | D15: 4200 | E15: =D15*$C15 -> 2688 | F15: 3416 | G15: =F15*$C15 -> 2186.24 | I15: =H15*$C15 -> 0 | K15: =J15*$C15 -> 0 | L15: 4564 | M15: =L15*$C15 -> 2920.96 | N15: 4830 | O15: =N15*$C15 -> 3091.2 | P15: 4270 | Q15: =P15*$C15 -> 2732.8 | R15: 6440 | S15: =R15*$C15 -> 4121.6 | T15: 4690 | U15: =T15*$C15 -> 3001.6 | V15: 6580 | W15: =V15*$C15 -> 4211.2 | X15: 3990 | Y15: =X15*$C15 -> 2553.6 | Z15: 3570 | AA15: =Z15*$C15 -> 2284.8 | AB15: =Z15+X15+V15+T15+R15+P15+N15+L15+J15+H15+F15+D15 -> 46550 | AC15: =AB15*$C15 -> 29792
A16: 12 | B16: ဇေယျဝတီ Red(14) | C16: 0.64 | D16: 157346 | E16: =D16*$C16 -> 100701.44 | F16: 138684 | G16: =F16*$C16 -> 88757.76 | H16: 176428 | I16: =H16*$C16 -> 112913.92 | J16: 172830 | K16: =J16*$C16 -> 110611.2 | L16: 184324 | M16: =L16*$C16 -> 117967.36 | N16: 173068 | O16: =N16*$C16 -> 110763.52 | P16: 155078 | Q16: =P16*$C16 -> 99249.92 | R16: 193578 | S16: =R16*$C16 -> 123889.92 | T16: 148946 | U16: =T16*$C16 -> 95325.44 | V16: 163114 | W16: =V16*$C16 -> 104392.96 | X16: 118650 | Y16: =X16*$C16 -> 75936 | Z16: 138414 | AA16: =Z16*$C16 -> 88584.96 | AB16: =Z16+X16+V16+T16+R16+P16+N16+L16+J16+H16+F16+D16 -> 1920460 | AC16: =AB16*$C16 -> 1229094.4
A17: 13 | B17: ဇေယျဝတီ Red(24) | C17: 0.64 | D17: 1200 | E17: =D17*$C17 -> 768 | F17: 720 | G17: =F17*$C17 -> 460.8 | H17: 960 | I17: =H17*$C17 -> 614.4 | J17: 720 | K17: =J17*$C17 -> 460.8 | L17: 1920 | M17: =L17*$C17 -> 1228.8 | O17: =N17*$C17 -> 0 | P17: 1200 | Q17: =P17*$C17 -> 768 | S17: =R17*$C17 -> 0 | T17: 2160 | U17: =T17*$C17 -> 1382.4 | V17: 480 | W17: =V17*$C17 -> 307.2 | X17: 2400 | Y17: =X17*$C17 -> 1536 | AA17: =Z17*$C17 -> 0 | AB17: =Z17+X17+V17+T17+R17+P17+N17+L17+J17+H17+F17+D17 -> 11760 | AC17: =AB17*$C17 -> 7526.4
A18: 14 | B18: ဇေယျဝတီ Red (ပု) | C18: 0.64 | D18: 11410 | E18: =D18*$C18 -> 7302.4 | F18: 12726 | G18: =F18*$C18 -> 8144.64 | H18: 9450 | I18: =H18*$C18 -> 6048 | J18: 11620 | K18: =J18*$C18 -> 7436.8 | L18: 14826 | M18: =L18*$C18 -> 9488.64 | N18: 12180 | O18: =N18*$C18 -> 7795.2 | P18: 14840 | Q18: =P18*$C18 -> 9497.6 | R18: 11410 | S18: =R18*$C18 -> 7302.4 | T18: 10150 | U18: =T18*$C18 -> 6496 | V18: 10500 | W18: =V18*$C18 -> 6720 | X18: 12040 | Y18: =X18*$C18 -> 7705.6 | Z18: 14070 | AA18: =Z18*$C18 -> 9004.8 | AB18: =Z18+X18+V18+T18+R18+P18+N18+L18+J18+H18+F18+D18 -> 145222 | AC18: =AB18*$C18 -> 92942.08
A19: 15 | B19: ဒဂုံမန်ကျည်းအရက် | C19: 0.64 | E19: =D19*$C19 -> 0 | G19: =F19*$C19 -> 0 | I19: =H19*$C19 -> 0 | K19: =J19*$C19 -> 0 | M19: =L19*$C19 -> 0 | O19: =N19*$C19 -> 0 | Q19: =P19*$C19 -> 0 | S19: =R19*$C19 -> 0 | U19: =T19*$C19 -> 0 | W19: =V19*$C19 -> 0 | Y19: =X19*$C19 -> 0 | AA19: =Z19*$C19 -> 0 | AB19: =Z19+X19+V19+T19+R19+P19+N19+L19+J19+H19+F19+D19 -> 0 | AC19: =AB19*$C19 -> 0
A20: 16 | B20: ကောင်းကြည် | C20: 0.64 | D20: 1400 | E20: =D20*$C20 -> 896 | F20: 1960 | G20: =F20*$C20 -> 1254.4 | H20: 6412 | I20: =H20*$C20 -> 4103.68 | J20: 7490 | K20: =J20*$C20 -> 4793.6 | L20: 2100 | M20: =L20*$C20 -> 1344 | N20: 4200 | O20: =N20*$C20 -> 2688 | P20: 3500 | Q20: =P20*$C20 -> 2240 | R20: 3500 | S20: =R20*$C20 -> 2240 | T20: 2800 | U20: =T20*$C20 -> 1792 | V20: 3500 | W20: =V20*$C20 -> 2240 | X20: 4200 | Y20: =X20*$C20 -> 2688 | Z20: 2800 | AA20: =Z20*$C20 -> 1792 | AB20: =Z20+X20+V20+T20+R20+P20+N20+L20+J20+H20+F20+D20 -> 43862 | AC20: =AB20*$C20 -> 28071.68
A21: 23 | B21: ဒဂုံနာနတ်ဝိုင်-14 | C21: 0.64 | D21: 434 | E21: =D21*$C21 -> 277.76 | F21: 322 | G21: =F21*$C21 -> 206.08 | H21: 336 | I21: =H21*$C21 -> 215.04 | J21: 546 | K21: =J21*$C21 -> 349.44 | L21: 280 | M21: =L21*$C21 -> 179.2 | N21: 504 | O21: =N21*$C21 -> 322.56 | P21: 588 | Q21: =P21*$C21 -> 376.32 | S21: =R21*$C21 -> 0 | T21: 154 | U21: =T21*$C21 -> 98.56 | V21: 196 | W21: =V21*$C21 -> 125.44 | X21: 434 | Y21: =X21*$C21 -> 277.76 | Z21: 140 | AA21: =Z21*$C21 -> 89.6 | AB21: =Z21+X21+V21+T21+R21+P21+N21+L21+J21+H21+F21+D21 -> 3934 | AC21: =AB21*$C21 -> 2517.76
B22: ဒဂုံနာနတ်ဝိုင်-24 | C22: 0.64 | D22: 18648 | E22: =D22*$C22 -> 11934.72 | W22: =V22*$C22 -> 0 | AB22: =Z22+X22+V22+T22+R22+P22+N22+L22+J22+H22+F22+D22 -> 18648 | AC22: =AB22*$C22 -> 11934.72
A23: 24 | B23: ဒဂုံအရက်သန့် | C23: 0.64 | E23: =D23*$C23 -> 0 | F23: 17880 | G23: =F23*$C23 -> 11443.2 | H23: 17040 | I23: =H23*$C23 -> 10905.6 | J23: 20760 | K23: =J23*$C23 -> 13286.4 | L23: 24360 | M23: =L23*$C23 -> 15590.4 | N23: 19800 | O23: =N23*$C23 -> 12672 | P23: 19320 | Q23: =P23*$C23 -> 12364.8 | R23: 17640 | S23: =R23*$C23 -> 11289.6 | T23: 18480 | U23: =T23*$C23 -> 11827.2 | V23: 20040 | W23: =V23*$C23 -> 12825.6 | X23: 18864 | Y23: =X23*$C23 -> 12072.96 | Z23: 17280 | AA23: =Z23*$C23 -> 11059.2 | AB23: =Z23+X23+V23+T23+R23+P23+N23+L23+J23+H23+F23+D23 -> 211464 | AC23: =AB23*$C23 -> 135336.96
A24: 26 | B24: Formula Rum 700ml | C24: 0.7 | D24: 2 | E24: =D24*$C24 -> 1.4 | G24: =F24*$C24 -> 0 | H24: 60 | I24: =H24*$C24 -> 42 | J24: 180 | K24: =J24*$C24 -> 126 | L24: 77 | M24: =L24*$C24 -> 53.9 | N24: 60 | O24: =N24*$C24 -> 42 | P24: 60 | Q24: =P24*$C24 -> 42 | R24: 204 | S24: =R24*$C24 -> 142.8 | T24: 41 | U24: =T24*$C24 -> 28.7 | V24: 54 | W24: =V24*$C24 -> 37.8 | X24: 354 | Y24: =X24*$C24 -> 247.8 | Z24: 41 | AA24: =Z24*$C24 -> 28.7 | AB24: =Z24+X24+V24+T24+R24+P24+N24+L24+J24+H24+F24+D24 -> 1133 | AC24: =AB24*$C24 -> 793.1
A25: 27 | B25: Formula Rum 350ml | C25: 0.35 | E25: =D25*$C25 -> 0 | G25: =F25*$C25 -> 0 | I25: =H25*$C25 -> 0 | K25: =J25*$C25 -> 0 | M25: =L25*$C25 -> 0 | O25: =N25*$C25 -> 0 | Q25: =P25*$C25 -> 0 | S25: =R25*$C25 -> 0 | U25: =T25*$C25 -> 0 | W25: =V25*$C25 -> 0 | Y25: =X25*$C25 -> 0 | AA25: =Z25*$C25 -> 0 | AB25: =Z25+X25+V25+T25+R25+P25+N25+L25+J25+H25+F25+D25 -> 0
E28: =D28*$C28 -> 0 | G28: =F28*$C28 -> 0 | I28: =H28*$C28 -> 0 | K28: =J28*$C28 -> 0 | M28: =L28*$C28 -> 0 | O28: =N28*$C28 -> 0 | Q28: =P28*$C28 -> 0 | S28: =R28*$C28 -> 0 | U28: =T28*$C28 -> 0 | W28: =V28*$C28 -> 0 | Y28: =X28*$C28 -> 0 | AA28: =Z28*$C28 -> 0 | AB28: =Z28+X28+V28+T28+R28+P28+N28+L28+J28+H28+F28+D28 -> 0 | AC28: =AB28*$C28 -> 0
B29: Total ( BE) | D29: =SUM(D4:D28) -> 284980 | E29: =SUM(E4:E28) -> 200645.96 | F29: =SUM(F4:F28) -> 250402 | G29: =SUM(G4:G28) -> 150442.36 | H29: =SUM(H4:H28) -> 306180 | I29: =SUM(I4:I28) -> 216101.84 | J29: =SUM(J4:J28) -> 313206 | K29: =SUM(K4:K24) -> 220161.04 | L29: =SUM(L4:L28) -> 319523 | M29: =SUM(M4:M28) -> 221018.78 | N29: =SUM(N4:N28) -> 319420 | O29: =SUM(O4:O28) -> 227006.72 | P29: =SUM(P4:P28) -> 309212 | Q29: =SUM(Q4:Q28) -> 219811.2 | R29: =SUM(R4:R28) -> 358266 | S29: =SUM(S4:S28) -> 257544.8 | ... AA29: =SUM(AA4:AA28) -> 220445.46 | AB29: =SUM(D29+F29+H29+J29+L29+N29+P29+R29+T29+V29+X29+Z29) -> 3634903 | AC29: =AA29+Y29+W29+U29+S29+Q29+O29+M29+K29+I29+G29+E29 -> 2568369.7
B30: Total ( BE) in Liters | E30: 200631.96 | G30: 148526.56 | I30: 216091.84 | K30: 220021.04 | M30: 221018.78 | O30: 226656.72 | Q30: 219461.2 | S30: 257534.8 | U30: 211674.06 | W30: 242222.68 | Y30: 181264.84 | Z30: 298525 | AA30: 220405.46 | AC30: 2566109.9
A32: 1 | B32: Columbus 700ml | C32: 0.7 | D32: 348 | E32: =D32*$C32 -> 243.6 | F32: 12 | G32: =F32*$C32 -> 8.4 | H32: 192 | I32: =H32*$C32 -> 134.4 | J32: 12 | K32: =J32*$C32 -> 8.4 | L32: 240 | M32: =L32*$C32 -> 168 | N32: 180 | O32: =N32*$C32 -> 126 | P32: 48 | Q32: =P32*$C32 -> 33.6 | R32: 240 | S32: =R32*$C32 -> 168 | T32: 324 | U32: =T32*$C32 -> 226.8 | V32: 300 | W32: =V32*C32 -> 210 | X32: 444 | Y32: =X32*C32 -> 310.8 | Z32: 120 | AA32: =Z32*C32 -> 84 | AB32: =SUM(D32:Z32) -> 4098 | AC32: =SUM(E32:AA32) -> 3834
A33: 2 | B33: Columbus 350ml | C33: 0.35 | D33: 72 | E33: =D33*$C33 -> 25.2 | F33: 24 | G33: =F33*$C33 -> 8.4 | H33: 96 | I33: =H33*$C33 -> 33.6 | K33: =J33*$C33 -> 0 | M33: =L33*$C33 -> 0 | O33: =N33*$C33 -> 0 | Q33: =P33*$C33 -> 0 | R33: 24 | S33: =R33*$C33 -> 8.4 | T33: 24 | U33: =T33*$C33 -> 8.4 | W33: =V33*C33 -> 0 | X33: 24 | Y33: =X33*C33 -> 8.4 | Z33: 24 | AA33: =Z33*C33 -> 8.4 | AB33: =SUM(D33:Z33) -> 380.4 | AC33: =SUM(E33:AA33) -> 316.8
A34: 3 | B34: Columbus 175ml | C34: 0.175 | E34: =D34*$C34 -> 0 | G34: =F34*$C34 -> 0 | I34: =H34*$C34 -> 0 | K34: =J34*$C34 -> 0 | M34: =L34*$C34 -> 0 | O34: =N34*$C34 -> 0 | Q34: =P34*$C34 -> 0 | S34: =R34*$C34 -> 0 | U34: =T34*$C34 -> 0 | W34: =V34*C34 -> 0 | X34: 2 | Y34: =X34*C34 -> 0.35 | AA34: =Z34*C34 -> 0 | AB34: =SUM(D34:Z34) -> 2.35 | AC34: =SUM(E34:AA34) -> 2.35
A35: 4 | B35: Columbus 700ml Super Red Smooth | C35: 0.7 | D35: 252 | E35: =D35*$C35 -> 176.4 | F35: 336 | G35: =F35*$C35 -> 235.2 | H35: 456 | I35: =H35*$C35 -> 319.2 | J35: 72 | K35: =J35*$C35 -> 50.4 | L35: 183 | M35: =L35*$C35 -> 128.1 | N35: 84 | O35: =N35*$C35 -> 58.8 | P35: 48 | Q35: =P35*$C35 -> 33.6 | R35: 216 | S35: =R35*$C35 -> 151.2 | T35: 24 | U35: =T35*$C35 -> 16.8 | V35: 168 | W35: =V35*C35 -> 117.6 | X35: 246 | Y35: =X35*C35 -> 172.2 | AA35: =Z35*C35 -> 0 | AB35: =SUM(D35:Z35) -> 3544.5 | AC35: =SUM(E35:AA35) -> 3292.5
A36: 5 | B36: Columbus 350ml Super Red Smooth | C36: 0.35 | D36: 72 | E36: =D36*$C36 -> 25.2 | F36: 126 | G36: =F36*$C36 -> 44.1 | H36: 126 | I36: =H36*$C36 -> 44.1 | J36: 96 | K36: =J36*$C36 -> 33.6 | L36: 77 | M36: =L36*$C36 -> 26.95 | N36: 24 | O36: =N36*$C36 -> 8.4 | P36: 6 | Q36: =P36*$C36 -> 2.1 | R36: 24 | S36: =R36*$C36 -> 8.4 | T36: 24 | U36: =T36*$C36 -> 8.4 | W36: =V36*C36 -> 0 | Y36: =X36*C36 -> 0 | Z36: 120 | AA36: =Z36*C36 -> 42 | AB36: =SUM(D36:Z36) -> 896.25 | AC36: =SUM(E36:AA36) -> 866.25
A37: 6 | B37: Columbus 175ml Super Red Smooth | C37: 0.175 | D37: 168 | E37: =D37*$C37 -> 29.4 | F37: 60 | G37: =F37*$C37 -> 10.5 | H37: 108 | I37: =H37*$C37 -> 18.9 | J37: 48 | K37: =J37*$C37 -> 8.4 | M37: =L37*$C37 -> 0 | O37: =N37*$C37 -> 0 | P37: 12 | Q37: =P37*$C37 -> 2.1 | R37: 96 | S37: =R37*$C37 -> 16.8 | U37: =T37*$C37 -> 0 | W37: =V37*C37 -> 0 | Y37: =X37*C37 -> 0 | Z37: 144 | AA37: =Z37*C37 -> 25.2 | AB37: =SUM(D37:Z37) -> 722.1 | AC37: =SUM(E37:AA37) -> 579.3
A38: 7 | B38: Columbus 700ml X'Mass | C38: 0.7 | E38: =D38*$C38 -> 0 | K38: =J38*$C38 -> 0 | M38: =L38*$C38 -> 0 | O38: =N38*$C38 -> 0 | Q38: =P38*$C38 -> 0 | S38: =R38*$C38 -> 0 | W38: =V38*C38 -> 0 | Y38: =X38*C38 -> 0 | AA38: =Z38*C38 -> 0 | AB38: =SUM(D38:Z38) -> 0 | AC38: =SUM(E38:AA38) -> 0
A39: 8 | B39: Columbus 175-ml Super Red Smooth | C39: 0.7 | E39: =D39*$C39 -> 0 | K39: =J39*$C39 -> 0 | M39: =L39*$C39 -> 0 | O39: =N39*$C39 -> 0 | Q39: =P39*$C39 -> 0 | S39: =R39*$C39 -> 0 | W39: =V39*C39 -> 0 | Y39: =X39*C39 -> 0 | AA39: =Z39*C39 -> 0 | AB39: =SUM(D39:Z39) -> 0 | AC39: =SUM(E39:AA39) -> 0
B40: Ngwe Taung 700ml | C40: 0.7 | D40: 24 | E40: =D40*$C40 -> 16.8 | J40: 180 | K40: =J40*$C40 -> 126 | L40: 60 | M40: =L40*$C40 -> 42 | O40: =N40*$C40 -> 0 | Q40: =P40*$C40 -> 0 | R40: 156 | S40: =R40*$C40 -> 109.2 | W40: =V40*C40 -> 0 | Y40: =X40*C40 -> 0 | AA40: =Z40*C40 -> 0 | AB40: =SUM(D40:Z40) -> 714 | AC40: =SUM(E40:AA40) -> 690
B41: Columbus Steel ပဲ့ထိန်း 350ml | C41: 0.7 | Y41: =X41*C41 -> 0 | AB41: =D41+F41+H41+J41+L41+N41+P41+R41+T41+V41+X41+Z41 -> 0
B42: Columbus Steel ပဲ့ထိန်း 175ml | C42: 0.35 | Y42: =X42*C42 -> 0 | AB42: =D42+F42+H42+J42+L42+N42+P42+R42+T42+V42+X42+Z42 -> 0
B43: Columbus Steel ရွက်လှေ 175ml | Y43: =X43*C43 -> 0 | AB43: =D43+F43+H43+J43+L43+N43+P43+R43+T43+V43+X43+Z43 -> 0
...

Sheet 2025
A1: MLM | CH1: 2025
A2: Sr. | B2: Product Name | D2: Ranking | E2: ML | F2: Packing | G2: Sales Price | H2: 44562 | J2: 44593 | L2: 44621 | N2: 44652 | P2: 44682 | R2: 44713 | T2: 44743 | V2: 44774 | X2: 44805 | Z2: 44835 | AB2: 44866 | AD2: 44896 | AF2: 2022 Total | AH2: 44927 | AJ2: 44958 | AL2: 44986 | AN2: 45017 | AP2: 45047 | AR2: 45078 | AT2: 45108 | AV2: 45139 | AX2: 45170 | AZ2: 45200 | BB2: 45231 | BD2: 45261 | BF2: 2023 Total | BH2: 45292 | BJ2: 45323 | BL2: 45352 | BN2: 45383 | BP2: 45413 | BR2: 45444 | BT2: 45474 | BV2: 45505 | BX2: 45536 | BZ2: 45566 | CB2: 45597 | CD2: 45627 | CF2: 2024 Total | CH2: 45658 | CJ2: 45689 | CL2: 45717 | CN2: 45748 | CP2: 45778 | CR2: 45809 | CT2: 45839 | CV2: 45870 | CX2: 45901 | CZ2: 45931 | DB2: 45962 | DD2: 45992 | DF2: 2025 Total
H3: Bot | I3: Lit | J3: Bot | K3: Lit | L3: Bot | M3: Lit | N3: Bot | O3: Lit | P3: Bot | Q3: Lit | R3: Bot | S3: Lit | T3: Bot | U3: Lit | V3: Bot | W3: Lit | X3: Bot | Y3: Lit | Z3: Bot | AA3: Lit | AB3: Bot | AC3: Lit | AD3: Bot | AE3: Lit | AF3: Bot | AG3: Lit | AH3: Bot | AI3: Lit | AJ3: Bot | AK3: Lit | AL3: Bot | AM3: Lit | AN3: Bot | AO3: Lit | AP3: Bot | AQ3: Lit | AR3: Bot | AS3: Lit | AT3: Bot | AU3: Lit | AV3: Bot | AW3: Lit | AX3: Bot | AY3: Lit | AZ3: Bot | BA3: Lit | BB3: Bot | BC3: Lit | BD3: Bot | BE3: Lit | BF3: Bot | BG3: Lit | BH3: Bot | BI3: Lit | BJ3: Bot | BK3: Lit | BL3: Bot | BM3: Lit | BN3: Bot | BO3: Lit | BP3: Bot | BQ3: Lit | BR3: Bot | BS3: Lit | BT3: Bot | BU3: Lit | BV3: Bot | BW3: Lit | BX3: Bot | BY3: Lit | BZ3: Bot | CA3: Lit | CB3: Bot | CC3: Lit | CD3: Bot | CE3: Lit | CF3: Bot | CG3: Lit | CH3: Bot | CI3: Lit | CJ3: Bot | CK3: Lit | CL3: Bot | CM3: Lit | CN3: Bot | CO3: Lit | CP3: Bot | CQ3: Lit | CR3: Bot | CS3: Lit | CT3: Bot | CU3: Lit | CV3: Bot | CW3: Lit | CX3: Bot | CY3: Lit | CZ3: Bot | DA3: Lit | DB3: Bot | DC3: Lit | DD3: Bot | DE3: Lit | DF3: Bot | DG3: Lit
A4: 1 | B4: "Zay" Vodka 700-ml | C4: ပုလင်း | D4: =RANK(DF4,$DF$4:$DF$141) -> 9 | E4: 0.7 | F4: 1 * 12 | G4: 2020 | H4: 7044 | I4: =H4*$E4 -> 4930.8 | J4: 29058 | K4: =J4*$E4 -> 20340.6 | L4: 9060 | M4: =L4*$E4 -> 6342 | N4: =480+9348 -> 9828 | O4: =N4*$E4 -> 6879.6 | P4: 3240 | Q4: =P4*$E4 -> 2268 | R4: 7611 | S4: =R4*$E4 -> 5327.7 | T4: 4356 | U4: =T4*$E4 -> 3049.2 | V4: 6353 | W4: =V4*$E4 -> 4447.1 | X4: 3384 | Y4: =X4*$E4 -> 2368.8 | Z4: 2831 | AA4: =Z4*$E4 -> 1981.7 | AB4: 5556 | AC4: =AB4*$E4 -> 3889.2 | AD4: 4176 | AE4: =AD4*$E4 -> 2923.2 | AF4: =(AD4+AB4+Z4+X4+V4+T4+R4+P4+N4+L4+J4+H4)/1 -> 92497 | AG4: =AF4*$E4 -> 64747.9 | AH4: 5472 | AI4: =AH4*$E4 -> 3830.4 | AJ4: 1265 | AK4: =AJ4*$E4 -> 885.5 | AL4: 3960 | AM4: =AL4*$E4 -> 2772 | AN4: 6888 | AO4: =AN4*$E4 -> 4821.6 | AP4: 3792 | AQ4: =AP4*$E4 -> 2654.4 | AR4: 1872 | AS4: =AR4*$E4 -> 1310.4 | AT4: 1500 | AU4: =AT4*$E4 -> 1050 | AV4: 3600 | AW4: =AV4*$E4 -> 2520 | AX4: 1896 | AY4: =AX4*$E4 -> 1327.2 | AZ4: 3168 | BA4: =AZ4*$E4 -> 2217.6 | BB4: 3168 | BC4: =BB4*$E4 -> 2217.6 | BD4: 3168 | BE4: =BD4*$E4 -> 2217.6 | BF4: =(BD4+BB4+AZ4+AX4+AV4+AT4+AR4+AP4+AN4+AL4+AJ4+AH4)/1 -> 39749 | BG4: =BF4*$E4 -> 27824.3 | BH4: 3696 | BI4: =BH4*$E4 -> 2587.2 | BJ4: 2892 | BK4: =BJ4*$E4 -> 2024.4 | BL4: 2748 | BM4: =BL4*$E4 -> 1923.6 | BN4: 3288 | BO4: =BN4*$E4 -> 2301.6 | BP4: 1764 | BQ4: =BP4*$E4 -> 1234.8 | BR4: 3144 | BS4: =BR4*$E4 -> 2200.8 | BT4: 3696 | BU4: =BT4*$E4 -> 2587.2 | BV4: 3840 | BW4: =BV4*$E4 -> 2688 | BX4: 756 | BY4: =BX4*$E4 -> 529.2 | BZ4: 3636 | CA4: =BZ4*$E4 -> 2545.2 | CB4: 2556 | CC4: =CB4*$E4 -> 1789.2 | CD4: 4626 | CE4: =CD4*$E4 -> 3238.2 | CF4: =(CD4+CB4+BZ4+BX4+BV4+BT4+BR4+BP4+BN4+BL4+BJ4+BH4)/1 -> 36642 | CG4: =CF4*$E4 -> 25649.4 | CH4: 528 | CI4: =CH4*$E4 -> 369.6 | CJ4: 1716 | CK4: =CJ4*$E4 -> 1201.2 | CL4: 2772 | CM4: =CL4*$E4 -> 1940.4 | CN4: 3960 | CO4: =CN4*$E4 -> 2772 | CP4: 1632 | CQ4: =CP4*$E4 -> 1142.4 | CR4: 1092 | CS4: =CR4*$E4 -> 764.4 | CT4: 1764 | CU4: =CT4*$E4 -> 1234.8 | CV4: 3096 | CW4: =CV4*$E4 -> 2167.2 | CX4: 1392 | CY4: =CX4*$E4 -> 974.4 | CZ4: 588 | DA4: =CZ4*$E4 -> 411.6 | DB4: 3996 | DC4: =DB4*$E4 -> 2797.2 | DD4: 24 | DE4: =DD4*$E4 -> 16.8 | DF4: =SUM(CH4,CJ4,CL4,CN4,CP4,CR4,CT4,CV4,CX4,CZ4,DB4,DD4) -> 22560 | DG4: =DF4*$E4 -> 15792
I5: =H5*$E5 -> 0 | K5: =J5*$E5 -> 0 | M5: =L5*$E5 -> 0 | O5: =N5*$E5 -> 0 | Q5: =P5*$E5 -> 0 | S5: =R5*$E5 -> 0 | U5: =T5*$E5 -> 0 | W5: =V5*$E5 -> 0 | Y5: =X5*$E5 -> 0 | AA5: =Z5*$E5 -> 0 | AC5: =AB5*$E5 -> 0 | AE5: =AD5*$E5 -> 0 | AF5: =(AD5+AB5+Z5+X5+V5+T5+R5+P5+N5+L5+J5+H5)/1 -> 0 | AG5: =AF5*$E5 -> 0 | AI5: =AH5*$E5 -> 0 | AK5: =AJ5*$E5 -> 0 | AM5: =AL5*$E5 -> 0 | AO5: =AN5*$E5 -> 0 | AQ5: =AP5*$E5 -> 0 | AS5: =AR5*$E5 -> 0 | AU5: =AT5*$E5 -> 0 | AW5: =AV5*$E5 -> 0 | AY5: =AX5*$E5 -> 0 | BA5: =AZ5*$E5 -> 0 | BC5: =BB5*$E5 -> 0 | BE5: =BD5*$E5 -> 0 | BF5: =(BD5+BB5+AZ5+AX5+AV5+AT5+AR5+AP5+AN5+AL5+AJ5+AH5)/1 -> 0 | BG5: =BF5*$E5 -> 0 | BI5: =BH5*$E5 -> 0 | BK5: =BJ5*$E5 -> 0 | BM5: =BL5*$E5 -> 0 | BO5: =BN5*$E5 -> 0 | BQ5: =BP5*$E5 -> 0 | BS5: =BR5*$E5 -> 0 | BU5: =BT5*$E5 -> 0 | BW5: =BV5*$E5 -> 0 | BY5: =BX5*$E5 -> 0 | CA5: =BZ5*$E5 -> 0 | CC5: =CB5*$E5 -> 0 | CE5: =CD5*$E5 -> 0 | CF5: =(CD5+CB5+BZ5+BX5+BV5+BT5+BR5+BP5+BN5+BL5+BJ5+BH5)/1 -> 0 | CG5: =CF5*$E5 -> 0 | CI5: =CH5*$E5 -> 0 | CK5: =CJ5*$E5 -> 0 | CM5: =CL5*$E5 -> 0 | CO5: =CN5*$E5 -> 0 | CQ5: =CP5*$E5 -> 0 | CS5: =CR5*$E5 -> 0 | CU5: =CT5*$E5 -> 0 | CW5: =CV5*$E5 -> 0 | CY5: =CX5*$E5 -> 0 | DA5: =CZ5*$E5 -> 0 | DC5: =DB5*$E5 -> 0 | DE5: =DD5*$E5 -> 0 | DF5: =SUM(CH5,CJ5,CL5,CN5,CP5,CR5,CT5,CV5,CX5,CZ5,DB5,DD5) -> 0 | DG5: =DF5*$E5 -> 0
A6: 2 | B6: "Zay" Vodka (1 Liter) | C6: ‌ကော်ဘူး | D6: =RANK(DF6,$DF$4:$DF$141) -> 21 | E6: 1 | F6: 1 * 12 | I6: =H6*$E6 -> 0 | K6: =J6*$E6 -> 0 | M6: =L6*$E6 -> 0 | O6: =N6*$E6 -> 0 | Q6: =P6*$E6 -> 0 | S6: =R6*$E6 -> 0 | U6: =T6*$E6 -> 0 | W6: =V6*$E6 -> 0 | Y6: =X6*$E6 -> 0 | AA6: =Z6*$E6 -> 0 | AC6: =AB6*$E6 -> 0 | AE6: =AD6*$E6 -> 0 | AF6: =(AD6+AB6+Z6+X6+V6+T6+R6+P6+N6+L6+J6+H6)/1 -> 0 | AG6: =AF6*$E6 -> 0 | AI6: =AH6*$E6 -> 0 | AK6: =AJ6*$E6 -> 0 | AM6: =AL6*$E6 -> 0 | AO6: =AN6*$E6 -> 0 | AQ6: =AP6*$E6 -> 0 | AS6: =AR6*$E6 -> 0 | AU6: =AT6*$E6 -> 0 | AW6: =AV6*$E6 -> 0 | AY6: =AX6*$E6 -> 0 | BA6: =AZ6*$E6 -> 0 | BC6: =BB6*$E6 -> 0 | BE6: =BD6*$E6 -> 0 | BF6: =(BD6+BB6+AZ6+AX6+AV6+AT6+AR6+AP6+AN6+AL6+AJ6+AH6)/1 -> 0 | BG6: =BF6*$E6 -> 0 | BI6: =BH6*$E6 -> 0 | BK6: =BJ6*$E6 -> 0 | BM6: =BL6*$E6 -> 0 | BO6: =BN6*$E6 -> 0 | BQ6: =BP6*$E6 -> 0 | BS6: =BR6*$E6 -> 0 | BU6: =BT6*$E6 -> 0 | BW6: =BV6*$E6 -> 0 | BY6: =BX6*$E6 -> 0 | CA6: =BZ6*$E6 -> 0 | CC6: =CB6*$E6 -> 0 | CE6: =CD6*$E6 -> 0 | CF6: =(CD6+CB6+BZ6+BX6+BV6+BT6+BR6+BP6+BN6+BL6+BJ6+BH6)/1 -> 0 | CG6: =CF6*$E6 -> 0 | CI6: =CH6*$E6 -> 0 | CK6: =CJ6*$E6 -> 0 | CM6: =CL6*$E6 -> 0 | CO6: =CN6*$E6 -> 0 | CQ6: =CP6*$E6 -> 0 | CS6: =CR6*$E6 -> 0 | CU6: =CT6*$E6 -> 0 | CW6: =CV6*$E6 -> 0 | CY6: =CX6*$E6 -> 0 | DA6: =CZ6*$E6 -> 0 | DC6: =DB6*$E6 -> 0 | DE6: =DD6*$E6 -> 0 | DF6: =SUM(CH6,CJ6,CL6,CN6,CP6,CR6,CT6,CV6,CX6,CZ6,DB6,DD6) -> 0 | DG6: =DF6*$E6 -> 0
A7: 3 | B7: "Zay" (1 Liter) | C7: ‌ကော်ဘူး | D7: =RANK(DF7,$DF$4:$DF$141) -> 6 | E7: 1 | F7: 1 * 12 | G7: 1675 | H7: 1176 | I7: =H7*$E7 -> 1176 | J7: 1380 | K7: =J7*$E7 -> 1380 | L7: 1716 | M7: =L7*$E7 -> 1716 | N7: 2796 | O7: =N7*$E7 -> 2796 | P7: 1416 | Q7: =P7*$E7 -> 1416 | R7: 1740 | S7: =R7*$E7 -> 1740 | T7: 1308 | U7: =T7*$E7 -> 1308 | V7: 1476 | W7: =V7*$E7 -> 1476 | X7: 1260 | Y7: =X7*$E7 -> 1260 | Z7: 2148 | AA7: =Z7*$E7 -> 2148 | AB7: 1620 | AC7: =AB7*$E7 -> 1620 | AD7: 3258 | AE7: =AD7*$E7 -> 3258 | AF7: =(AD7+AB7+Z7+X7+V7+T7+R7+P7+N7+L7+J7+H7)/1 -> 21294 | AG7: =AF7*$E7 -> 21294 | AH7: 4020 | AI7: =AH7*$E7 -> 4020 | AJ7: 2580 | AK7: =AJ7*$E7 -> 2580 | AL7: 4392 | AM7: =AL7*$E7 -> 4392 | AN7: 1884 | AO7: =AN7*$E7 -> 1884 | AP7: 2868 | AQ7: =AP7*$E7 -> 2868 | AR7: 2052 | AS7: =AR7*$E7 -> 2052 | AT7: 3672 | AU7: =AT7*$E7 -> 3672 | AV7: 3984 | AW7: =AV7*$E7 -> 3984 | AX7: 1404 | AY7: =AX7*$E7 -> 1404 | AZ7: 2760 | BA7: =AZ7*$E7 -> 2760 | BB7: 3305 | BC7: =BB7*$E7 -> 3305 | BD7: 3144 | BE7: =BD7*$E7 -> 3144 | BF7: =(BD7+BB7+AZ7+AX7+AV7+AT7+AR7+AP7+AN7+AL7+AJ7+AH7)/1 -> 36065 | BG7: =BF7*$E7 -> 36065 | BH7: 4680 | BI7: =BH7*$E7 -> 4680 | BJ7: 2868 | BK7: =BJ7*$E7 -> 2868 | BL7: 4572 | BM7: =BL7*$E7 -> 4572 | BN7: 4032 | BO7: =BN7*$E7 -> 4032 | BP7: 2760 | BQ7: =BP7*$E7 -> 2760 | BR7: 4632 | BS7: =BR7*$E7 -> 4632 | BT7: 5772 | BU7: =BT7*$E7 -> 5772 | BV7: 4980 | BW7: =BV7*$E7 -> 4980 | BX7: 4320 | BY7: =BX7*$E7 -> 4320 | BZ7: 4980 | CA7: =BZ7*$E7 -> 4980 | CB7: 5388 | CC7: =CB7*$E7 -> 5388 | CD7: 2832 | CE7: =CD7*$E7 -> 2832 | CF7: =(CD7+CB7+BZ7+BX7+BV7+BT7+BR7+BP7+BN7+BL7+BJ7+BH7)/1 -> 51816 | CG7: =CF7*$E7 -> 51816 | CH7: 6672 | CI7: =CH7*$E7 -> 6672 | CJ7: 4896 | CK7: =CJ7*$E7 -> 4896 | CL7: 10248 | CM7: =CL7*$E7 -> 10248 | CN7: 5028 | CO7: =CN7*$E7 -> 5028 | CP7: 3492 | CQ7: =CP7*$E7 -> 3492 | CR7: 10224 | CS7: =CR7*$E7 -> 10224 | CT7: 8388 | CU7: =CT7*$E7 -> 8388 | CV7: 6667 | CW7: =CV7*$E7 -> 6667 | CX7: 5072 | CY7: =CX7*$E7 -> 5072 | CZ7: 6852 | DA7: =CZ7*$E7 -> 6852 | DB7: 8076 | DC7: =DB7*$E7 -> 8076 | DD7: 11868 | DE7: =DD7*$E7 -> 11868 | DF7: =SUM(CH7,CJ7,CL7,CN7,CP7,CR7,CT7,CV7,CX7,CZ7,DB7,DD7) -> 87483 | DG7: =DF7*$E7 -> 87483
A8: 4 | B8: "Zay" (0.6 Liter) | C8: ‌ကော်ဘူး | D8: =RANK(DF8,$DF$4:$DF$141) -> 16 | E8: 0.6 | F8: 1 * 12 | I8: =H8*$E8 -> 0 | K8: =J8*$E8 -> 0 | M8: =L8*$E8 -> 0 | O8: =N8*$E8 -> 0 | Q8: =P8*$E8 -> 0 | S8: =R8*$E8 -> 0 | U8: =T8*$E8 -> 0 | W8: =V8*$E8 -> 0 | Y8: =X8*$E8 -> 0 | AA8: =Z8*$E8 -> 0 | AC8: =AB8*$E8 -> 0 | AE8: =AD8*$E8 -> 0 | AF8: =(AD8+AB8+Z8+X8+V8+T8+R8+P8+N8+L8+J8+H8)/1 -> 0 | AG8: =AF8*$E8 -> 0 | AH8: 612 | AI8: =AH8*$E8 -> 367.2 | AJ8: 444 | AK8: =AJ8*$E8 -> 266.4 | AL8: 120 | AM8: =AL8*$E8 -> 72 | AN8: 216 | AO8: =AN8*$E8 -> 129.6 | AP8: 480 | AQ8: =AP8*$E8 -> 288 | AR8: 156 | AS8: =AR8*$E8 -> 93.6 | AT8: 276 | AU8: =AT8*$E8 -> 165.6 | AV8: 420 | AW8: =AV8*$E8 -> 252 | AX8: 12 | AY8: =AX8*$E8 -> 7.2 | BA8: =AZ8*$E8 -> 0 | BB8: 48 | BC8: =BB8*$E8 -> 28.8 | BE8: =BD8*$E8 -> 0 | BF8: =(BD8+BB8+AZ8+AX8+AV8+AT8+AR8+AP8+AN8+AL8+AJ8+AH8)/1 -> 2784 | BG8: =BF8*$E8 -> 1670.4 | BI8: =BH8*$E8 -> 0 | BK8: =BJ8*$E8 -> 0 | BM8: =BL8*$E8 -> 0 | BO8: =BN8*$E8 -> 0 | BP8: 60 | BQ8: =BP8*$E8 -> 36 | BS8: =BR8*$E8 -> 0 | BU8: =BT8*$E8 -> 0 | BV8: 36 | BW8: =BV8*$E8 -> 21.6 | BY8: =BX8*$E8 -> 0 | CA8: =BZ8*$E8 -> 0 | CC8: =CB8*$E8 -> 0 | CE8: =CD8*$E8 -> 0 | CF8: =(CD8+CB8+BZ8+BX8+BV8+BT8+BR8+BP8+BN8+BL8+BJ8+BH8)/1 -> 96 | CG8: =CF8*$E8 -> 57.6 | CI8: =CH8*$E8 -> 0 | CK8: =CJ8*$E8 -> 0 | CM8: =CL8*$E8 -> 0 | CO8: =CN8*$E8 -> 0 | CQ8: =CP8*$E8 -> 0 | CR8: 480 | CS8: =CR8*$E8 -> 288 | CU8: =CT8*$E8 -> 0 | CW8: =CV8*$E8 -> 0 | CY8: =CX8*$E8 -> 0 | DA8: =CZ8*$E8 -> 0 | DC8: =DB8*$E8 -> 0 | DE8: =DD8*$E8 -> 0 | DF8: =SUM(CH8,CJ8,CL8,CN8,CP8,CR8,CT8,CV8,CX8,CZ8,DB8,DD8) -> 480 | DG8: =DF8*$E8 -> 288
A9: 5 | B9: "Zay" (0.35 Liter) | C9: ‌ကော်ဘူး | D9: =RANK(DF9,$DF$4:$DF$141) -> 11 | E9: 0.35 | F9: 1 * 40 | G9: 780 | I9: =H9*$E9 -> 0 | K9: =J9*$E9 -> 0 | M9: =L9*$E9 -> 0 | O9: =N9*$E9 -> 0 | Q9: =P9*$E9 -> 0 | S9: =R9*$E9 -> 0 | U9: =T9*$E9 -> 0 | W9: =V9*$E9 -> 0 | Y9: =X9*$E9 -> 0 | AA9: =Z9*$E9 -> 0 | AC9: =AB9*$E9 -> 0 | AE9: =AD9*$E9 -> 0 | AF9: =(AD9+AB9+Z9+X9+V9+T9+R9+P9+N9+L9+J9+H9)/1 -> 0 | AG9: =AF9*$E9 -> 0 | AI9: =AH9*$E9 -> 0 | AK9: =AJ9*$E9 -> 0 | AM9: =AL9*$E9 -> 0 | AO9: =AN9*$E9 -> 0 | AQ9: =AP9*$E9 -> 0 | AS9: =AR9*$E9 -> 0 | AT9: 240 | AU9: =AT9*$E9 -> 84 | AV9: 2600 | AW9: =AV9*$E9 -> 910 | AX9: 200 | AY9: =AX9*$E9 -> 70 | BA9: =AZ9*$E9 -> 0 | BB9: 1200 | BC9: =BB9*$E9 -> 420 | BE9: =BD9*$E9 -> 0 | BF9: =(BD9+BB9+AZ9+AX9+AV9+AT9+AR9+AP9+AN9+AL9+AJ9+AH9)/1 -> 4240 | BG9: =BF9*$E9 -> 1484 | BH9: 280 | BI9: =BH9*$E9 -> 98 | BK9: =BJ9*$E9 -> 0 | BL9: 200 | BM9: =BL9*$E9 -> 70 | BN9: 400 | BO9: =BN9*$E9 -> 140 | BQ9: =BP9*$E9 -> 0 | BR9: 1000 | BS9: =BR9*$E9 -> 350 | BT9: 1000 | BU9: =BT9*$E9 -> 350 | BV9: 200 | BW9: =BV9*$E9 -> 70 | BX9: 200 | BY9: =BX9*$E9 -> 70 | BZ9: 400 | CA9: =BZ9*$E9 -> 140 | CC9: =CB9*$E9 -> 0 | CD9: 800 | CE9: =CD9*$E9 -> 280 | CF9: =(CD9+CB9+BZ9+BX9+BV9+BT9+BR9+BP9+BN9+BL9+BJ9+BH9)/1 -> 4480 | CG9: =CF9*$E9 -> 1568 | CH9: 600 | CI9: =CH9*$E9 -> 210 | CK9: =CJ9*$E9 -> 0 | CL9: 1000 | CM9: =CL9*$E9 -> 350 | CO9: =CN9*$E9 -> 0 | CP9: 800 | CQ9: =CP9*$E9 -> 280 | CR9: 1400 | CS9: =CR9*$E9 -> 490 | CT9: 1000 | CU9: =CT9*$E9 -> 350 | CV9: 200 | CW9: =CV9*$E9 -> 70 | CX9: 400 | CY9: =CX9*$E9 -> 140 | CZ9: 400 | DA9: =CZ9*$E9 -> 140 | DB9: 600 | DC9: =DB9*$E9 -> 210 | DD9: 400 | DE9: =DD9*$E9 -> 140 | DF9: =SUM(CH9,CJ9,CL9,CN9,CP9,CR9,CT9,CV9,CX9,CZ9,DB9,DD9) -> 6800 | DG9: =DF9*$E9 -> 2380
A10: 6 | B10: "Zay" Vodka | C10: ပုလင်း | D10: =RANK(DF10,$DF$4:$DF$141) -> 21 | E10: 0.7 | F10: 1 * 24 | I10: =H10*$E10 -> 0 | K10: =J10*$E10 -> 0 | M10: =L10*$E10 -> 0 | O10: =N10*$E10 -> 0 | Q10: =P10*$E10 -> 0 | S10: =R10*$E10 -> 0 | U10: =T10*$E10 -> 0 | W10: =V10*$E10 -> 0 | Y10: =X10*$E10 -> 0 | AA10: =Z10*$E10 -> 0 | AC10: =AB10*$E10 -> 0 | AE10: =AD10*$E10 -> 0 | AF10: =(AD10+AB10+Z10+X10+V10+T10+R10+P10+N10+L10+J10+H10)/1 -> 0 | AG10: =AF10*$E10 -> 0 | AI10: =AH10*$E10 -> 0 | AK10: =AJ10*$E10 -> 0 | AM10: =AL10*$E10 -> 0 | AO10: =AN10*$E10 -> 0 | AQ10: =AP10*$E10 -> 0 | AS10: =AR10*$E10 -> 0 | AU10: =AT10*$E10 -> 0 | AW10: =AV10*$E10 -> 0 | AY10: =AX10*$E10 -> 0 | BA10: =AZ10*$E10 -> 0 | BC10: =BB10*$E10 -> 0 | BE10: =BD10*$E10 -> 0 | BF10: =(BD10+BB10+AZ10+AX10+AV10+AT10+AR10+AP10+AN10+AL10+AJ10+AH10)/1 -> 0 | BG10: =BF10*$E10 -> 0 | BI10: =BH10*$E10 -> 0 | BK10: =BJ10*$E10 -> 0 | BM10: =BL10*$E10 -> 0 | BO10: =BN10*$E10 -> 0 | BQ10: =BP10*$E10 -> 0 | BS10: =BR10*$E10 -> 0 | BU10: =BT10*$E10 -> 0 | BW10: =BV10*$E10 -> 0 | BY10: =BX10*$E10 -> 0 | CA10: =BZ10*$E10 -> 0 | CC10: =CB10*$E10 -> 0 | CE10: =CD10*$E10 -> 0 | CF10: =(CD10+CB10+BZ10+BX10+BV10+BT10+BR10+BP10+BN10+BL10+BJ10+BH10)/1 -> 0 | CG10: =CF10*$E10 -> 0 | CI10: =CH10*$E10 -> 0 | CK10: =CJ10*$E10 -> 0 | CM10: =CL10*$E10 -> 0 | CO10: =CN10*$E10 -> 0 | CQ10: =CP10*$E10 -> 0 | CS10: =CR10*$E10 -> 0 | CU10: =CT10*$E10 -> 0 | CW10: =CV10*$E10 -> 0 | CY10: =CX10*$E10 -> 0 | DA10: =CZ10*$E10 -> 0 | DC10: =DB10*$E10 -> 0 | DE10: =DD10*$E10 -> 0 | DF10: =SUM(CH10,CJ10,CL10,CN10,CP10,CR10,CT10,CV10,CX10,CZ10,DB10,DD10) -> 0 | DG10: =DF10*$E10 -> 0
A11: 7 | B11: "Zay" Vodka - 640ml | C11: ပုလင်း | D11: =RANK(DF11,$DF$4:$DF$141) -> 21 | E11: 0.64 | F11: 1 * 24 | I11: =H11*$E11 -> 0 | K11: =J11*$E11 -> 0 | M11: =L11*$E11 -> 0 | O11: =N11*$E11 -> 0 | Q11: =P11*$E11 -> 0 | S11: =R11*$E11 -> 0 | U11: =T11*$E11 -> 0 | W11: =V11*$E11 -> 0 | Y11: =X11*$E11 -> 0 | AA11: =Z11*$E11 -> 0 | AC11: =AB11*$E11 -> 0 | AE11: =AD11*$E11 -> 0 | AF11: =(AD11+AB11+Z11+X11+V11+T11+R11+P11+N11+L11+J11+H11)/1 -> 0 | AG11: =AF11*$E11 -> 0 | AI11: =AH11*$E11 -> 0 | AK11: =AJ11*$E11 -> 0 | AM11: =AL11*$E11 -> 0 | AO11: =AN11*$E11 -> 0 | AQ11: =AP11*$E11 -> 0 | AS11: =AR11*$E11 -> 0 | AU11: =AT11*$E11 -> 0 | AW11: =AV11*$E11 -> 0 | AY11: =AX11*$E11 -> 0 | BA11: =AZ11*$E11 -> 0 | BC11: =BB11*$E11 -> 0 | BE11: =BD11*$E11 -> 0 | BF11: =(BD11+BB11+AZ11+AX11+AV11+AT11+AR11+AP11+AN11+AL11+AJ11+AH11)/1 -> 0 | BG11: =BF11*$E11 -> 0 | BI11: =BH11*$E11 -> 0 | BK11: =BJ11*$E11 -> 0 | BM11: =BL11*$E11 -> 0 | BO11: =BN11*$E11 -> 0 | BQ11: =BP11*$E11 -> 0 | BS11: =BR11*$E11 -> 0 | BU11: =BT11*$E11 -> 0 | BW11: =BV11*$E11 -> 0 | BY11: =BX11*$E11 -> 0 | CA11: =BZ11*$E11 -> 0 | CC11: =CB11*$E11 -> 0 | CE11: =CD11*$E11 -> 0 | CF11: =(CD11+CB11+BZ11+BX11+BV11+BT11+BR11+BP11+BN11+BL11+BJ11+BH11)/1 -> 0 | CG11: =CF11*$E11 -> 0 | CI11: =CH11*$E11 -> 0 | CK11: =CJ11*$E11 -> 0 | CM11: =CL11*$E11 -> 0 | CO11: =CN11*$E11 -> 0 | CQ11: =CP11*$E11 -> 0 | CS11: =CR11*$E11 -> 0 | CU11: =CT11*$E11 -> 0 | CW11: =CV11*$E11 -> 0 | CY11: =CX11*$E11 -> 0 | DA11: =CZ11*$E11 -> 0 | DC11: =DB11*$E11 -> 0 | DE11: =DD11*$E11 -> 0 | DF11: =SUM(CH11,CJ11,CL11,CN11,CP11,CR11,CT11,CV11,CX11,CZ11,DB11,DD11) -> 0 | DG11: =DF11*$E11 -> 0
A12: 8 | B12: "Zay" Vodka - 640ml | C12: ပုလင်း | D12: =RANK(DF12,$DF$4:$DF$141) -> 3 | E12: 0.64 | F12: 1 * 14 | G12: 1400 | H12: 31336 | I12: =H12*$E12 -> 20055.04 | K12: =J12*$E12 -> 0 | L12: 41174 | M12: =L12*$E12 -> 26351.36 | N12: 37772 | O12: =N12*$E12 -> 24174.08 | P12: 47936 | Q12: =P12*$E12 -> 30679.04 | R12: 35826 | S12: =R12*$E12 -> 22928.64 | T12: 37100 | U12: =T12*$E12 -> 23744 | V12: 51772 | W12: =V12*$E12 -> 33134.08 | X12: 34496 | Y12: =X12*$E12 -> 22077.44 | Z12: 21462 | AA12: =Z12*$E12 -> 13735.68 | AB12: 26740 | AC12: =AB12*$E12 -> 17113.6 | AD12: 42784 | AE12: =AD12*$E12 -> 27381.76 | AF12: =(AD12+AB12+Z12+X12+V12+T12+R12+P12+N12+L12+J12+H12)/1 -> 408398 | AG12: =AF12*$E12 -> 261374.72 | AH12: 47815 | AI12: =AH12*$E12 -> 30601.6 | AJ12: 33572 | AK12: =AJ12*$E12 -> 21486.08 | AL12: 43638 | AM12: =AL12*$E12 -> 27928.32 | AN12: 40964 | AO12: =AN12*$E12 -> 26216.96 | AP12: 38962 | AQ12: =AP12*$E12 -> 24935.68 | AR12: 38066 | AS12: =AR12*$E12 -> 24362.24 | AT12: 34216 | AU12: =AT12*$E12 -> 21898.24 | AV12: 63504 | AW12: =AV12*$E12 -> 40642.56 | AX12: 29414 | AY12: =AX12*$E12 -> 18824.96 | AZ12: 29232 | BA12: =AZ12*$E12 -> 18708.48 | BB12: 30534 | BC12: =BB12*$E12 -> 19541.76 | BD12: 32956 | BE12: =BD12*$E12 -> 21091.84 | BF12: =(BD12+BB12+AZ12+AX12+AV12+AT12+AR12+AP12+AN12+AL12+AJ12+AH12)/1 -> 462873 | BG12: =BF12*$E12 -> 296238.72 | BH12: 36036 | BI12: =BH12*$E12 -> 23063.04 | BJ12: 30366 | BK12: =BJ12*$E12 -> 19434.24 | BL12: 36890 | BM12: =BL12*$E12 -> 23609.6 | BN12: 40880 | BO12: =BN12*$E12 -> 26163.2 | BP12: 39648 | BQ12: =BP12*$E12 -> 25374.72 | BR12: 37646 | BS12: =BR12*$E12 -> 24093.44 | BT12: 44604 | BU12: =BT12*$E12 -> 28546.56 | BV12: 43442 | BW12: =BV12*$E12 -> 27802.88 | BX12: 27664 | BY12: =BX12*$E12 -> 17704.96 | BZ12: 47852 | CA12: =BZ12*$E12 -> 30625.28 | CB12: 31528 | CC12: =CB12*$E12 -> 20177.92 | CD12: 35280 | CE12: =CD12*$E12 -> 22579.2 | CF12: =(CD12+CB12+BZ12+BX12+BV12+BT12+BR12+BP12+BN12+BL12+BJ12+BH12)/1 -> 451836 | CG12: =CF12*$E12 -> 289175.04 | CH12: 33824 | CI12: =CH12*$E12 -> 21647.36 | CJ12: 38360 | CK12: =CJ12*$E12 -> 24550.4 | CL12: 49336 | CM12: =CL12*$E12 -> 31575.04 | CN12: 30996 | CO12: =CN12*$E12 -> 19837.44 | CP12: 42126 | CQ12: =CP12*$E12 -> 26960.64 | CR12: 28644 | CS12: =CR12*$E12 -> 18332.16 | CT12: 42588 | CU12: =CT12*$E12 -> 27256.32 | CV12: 33698 | CW12: =CV12*$E12 -> 21566.72 | CX12: 32466 | CY12: =CX12*$E12 -> 20778.24 | CZ12: 29624 | DA12: =CZ12*$E12 -> 18959.36 | DB12: 28448 | DC12: =DB12*$E12 -> 18206.72 | DD12: 29554 | DE12: =DD12*$E12 -> 18914.56 | DF12: =SUM(CH12,CJ12,CL12,CN12,CP12,CR12,CT12,CV12,CX12,CZ12,DB12,DD12) -> 419664 | DG12: =DF12*$E12 -> 268584.96
A13: 9 | B13: "Zay" Vodka - 640ml | C13: ပုလင်း | D13: =RANK(DF13,$DF$4:$DF$141) -> 21 | E13: 0.64 | F13: 1 * 12 | I13: =H13*$E13 -> 0 | K13: =J13*$E13 -> 0 | M13: =L13*$E13 -> 0 | O13: =N13*$E13 -> 0 | Q13: =P13*$E13 -> 0 | S13: =R13*$E13 -> 0 | U13: =T13*$E13 -> 0 | W13: =V13*$E13 -> 0 | Y13: =X13*$E13 -> 0 | AA13: =Z13*$E13 -> 0 | AC13: =AB13*$E13 -> 0 | AE13: =AD13*$E13 -> 0 | AF13: =(AD13+AB13+Z13+X13+V13+T13+R13+P13+N13+L13+J13+H13)/1 -> 0 | AG13: =AF13*$E13 -> 0 | AI13: =AH13*$E13 -> 0 | AK13: =AJ13*$E13 -> 0 | AM13: =AL13*$E13 -> 0 | AO13: =AN13*$E13 -> 0 | AQ13: =AP13*$E13 -> 0 | AS13: =AR13*$E13 -> 0 | AU13: =AT13*$E13 -> 0 | AW13: =AV13*$E13 -> 0 | AY13: =AX13*$E13 -> 0 | BA13: =AZ13*$E13 -> 0 | BC13: =BB13*$E13 -> 0 | BE13: =BD13*$E13 -> 0 | BF13: =(BD13+BB13+AZ13+AX13+AV13+AT13+AR13+AP13+AN13+AL13+AJ13+AH13)/1 -> 0 | BG13: =BF13*$E13 -> 0 | BI13: =BH13*$E13 -> 0 | BK13: =BJ13*$E13 -> 0 | BM13: =BL13*$E13 -> 0 | BO13: =BN13*$E13 -> 0 | BQ13: =BP13*$E13 -> 0 | BS13: =BR13*$E13 -> 0 | BU13: =BT13*$E13 -> 0 | BW13: =BV13*$E13 -> 0 | BY13: =BX13*$E13 -> 0 | CA13: =BZ13*$E13 -> 0 | CC13: =CB13*$E13 -> 0 | CE13: =CD13*$E13 -> 0 | CF13: =(CD13+CB13+BZ13+BX13+BV13+BT13+BR13+BP13+BN13+BL13+BJ13+BH13)/1 -> 0 | CG13: =CF13*$E13 -> 0 | CI13: =CH13*$E13 -> 0 | CK13: =CJ13*$E13 -> 0 | CM13: =CL13*$E13 -> 0 | CO13: =CN13*$E13 -> 0 | CQ13: =CP13*$E13 -> 0 | CS13: =CR13*$E13 -> 0 | CU13: =CT13*$E13 -> 0 | CW13: =CV13*$E13 -> 0 | CY13: =CX13*$E13 -> 0 | DA13: =CZ13*$E13 -> 0 | DC13: =DB13*$E13 -> 0 | DE13: =DD13*$E13 -> 0 | DF13: =SUM(CH13,CJ13,CL13,CN13,CP13,CR13,CT13,CV13,CX13,CZ13,DB13,DD13) -> 0 | DG13: =DF13*$E13 -> 0
A14: 10 | B14: "Zay" - 640ml | C14: ပုလင်း | D14: =RANK(DF14,$DF$4:$DF$141) -> 21 | E14: 0.64 | F14: 1 * 14 | I14: =H14*$E14 -> 0 | K14: =J14*$E14 -> 0 | M14: =L14*$E14 -> 0 | O14: =N14*$E14 -> 0 | Q14: =P14*$E14 -> 0 | S14: =R14*$E14 -> 0 | U14: =T14*$E14 -> 0 | W14: =V14*$E14 -> 0 | Y14: =X14*$E14 -> 0 | AA14: =Z14*$E14 -> 0 | AC14: =AB14*$E14 -> 0 | AE14: =AD14*$E14 -> 0 | AF14: =(AD14+AB14+Z14+X14+V14+T14+R14+P14+N14+L14+J14+H14)/1 -> 0 | AG14: =AF14*$E14 -> 0 | AI14: =AH14*$E14 -> 0 | AK14: =AJ14*$E14 -> 0 | AM14: =AL14*$E14 -> 0 | AO14: =AN14*$E14 -> 0 | AQ14: =AP14*$E14 -> 0 | AS14: =AR14*$E14 -> 0 | AU14: =AT14*$E14 -> 0 | AW14: =AV14*$E14 -> 0 | AY14: =AX14*$E14 -> 0 | BA14: =AZ14*$E14 -> 0 | BC14: =BB14*$E14 -> 0 | BE14: =BD14*$E14 -> 0 | BF14: =(BD14+BB14+AZ14+AX14+AV14+AT14+AR14+AP14+AN14+AL14+AJ14+AH14)/1 -> 0 | BG14: =BF14*$E14 -> 0 | BI14: =BH14*$E14 -> 0 | BK14: =BJ14*$E14 -> 0 | BM14: =BL14*$E14 -> 0 | BO14: =BN14*$E14 -> 0 | BQ14: =BP14*$E14 -> 0 | BS14: =BR14*$E14 -> 0 | BU14: =BT14*$E14 -> 0 | BW14: =BV14*$E14 -> 0 | BY14: =BX14*$E14 -> 0 | CA14: =BZ14*$E14 -> 0 | CC14: =CB14*$E14 -> 0 | CE14: =CD14*$E14 -> 0 | CF14: =(CD14+CB14+BZ14+BX14+BV14+BT14+BR14+BP14+BN14+BL14+BJ14+BH14)/1 -> 0 | CG14: =CF14*$E14 -> 0 | CI14: =CH14*$E14 -> 0 | CK14: =CJ14*$E14 -> 0 | CM14: =CL14*$E14 -> 0 | CO14: =CN14*$E14 -> 0 | CQ14: =CP14*$E14 -> 0 | CS14: =CR14*$E14 -> 0 | CU14: =CT14*$E14 -> 0 | CW14: =CV14*$E14 -> 0 | CY14: =CX14*$E14 -> 0 | DA14: =CZ14*$E14 -> 0 | DC14: =DB14*$E14 -> 0 | DE14: =DD14*$E14 -> 0 | DF14: =SUM(CH14,CJ14,CL14,CN14,CP14,CR14,CT14,CV14,CX14,CZ14,DB14,DD14) -> 0 | DG14: =DF14*$E14 -> 0
I15: =H15*$E15 -> 0 | K15: =J15*$E15 -> 0 | M15: =L15*$E15 -> 0 | O15: =N15*$E15 -> 0 | Q15: =P15*$E15 -> 0 | S15: =R15*$E15 -> 0 | U15: =T15*$E15 -> 0 | W15: =V15*$E15 -> 0 | Y15: =X15*$E15 -> 0 | AA15: =Z15*$E15 -> 0 | AC15: =AB15*$E15 -> 0 | AE15: =AD15*$E15 -> 0 | AF15: =(AD15+AB15+Z15+X15+V15+T15+R15+P15+N15+L15+J15+H15)/1 -> 0 | AG15: =AF15*$E15 -> 0 | AI15: =AH15*$E15 -> 0 | AK15: =AJ15*$E15 -> 0 | AM15: =AL15*$E15 -> 0 | AO15: =AN15*$E15 -> 0 | AQ15: =AP15*$E15 -> 0 | AS15: =AR15*$E15 -> 0 | AU15: =AT15*$E15 -> 0 | AW15: =AV15*$E15 -> 0 | AY15: =AX15*$E15 -> 0 | BA15: =AZ15*$E15 -> 0 | BC15: =BB15*$E15 -> 0 | BE15: =BD15*$E15 -> 0 | BF15: =(BD15+BB15+AZ15+AX15+AV15+AT15+AR15+AP15+AN15+AL15+AJ15+AH15)/1 -> 0 | BG15: =BF15*$E15 -> 0 | BI15: =BH15*$E15 -> 0 | BK15: =BJ15*$E15 -> 0 | BM15: =BL15*$E15 -> 0 | BO15: =BN15*$E15 -> 0 | BQ15: =BP15*$E15 -> 0 | BS15: =BR15*$E15 -> 0 | BU15: =BT15*$E15 -> 0 | BW15: =BV15*$E15 -> 0 | BY15: =BX15*$E15 -> 0 | CA15: =BZ15*$E15 -> 0 | CC15: =CB15*$E15 -> 0 | CE15: =CD15*$E15 -> 0 | CF15: =(CD15+CB15+BZ15+BX15+BV15+BT15+BR15+BP15+BN15+BL15+BJ15+BH15)/1 -> 0 | CG15: =CF15*$E15 -> 0 | CI15: =CH15*$E15 -> 0 | CK15: =CJ15*$E15 -> 0 | CM15: =CL15*$E15 -> 0 | CO15: =CN15*$E15 -> 0 | CQ15: =CP15*$E15 -> 0 | CS15: =CR15*$E15 -> 0 | CU15: =CT15*$E15 -> 0 | CW15: =CV15*$E15 -> 0 | CY15: =CX15*$E15 -> 0 | DA15: =CZ15*$E15 -> 0 | DC15: =DB15*$E15 -> 0 | DE15: =DD15*$E15 -> 0 | DF15: =SUM(CH15,CJ15,CL15,CN15,CP15,CR15,CT15,CV15,CX15,CZ15,DB15,DD15) -> 0 | DG15: =DF15*$E15 -> 0
A16: 11 | B16: Kaung Kyi (1 Liter)_25% | C16: ‌ကော်ဘူး | D16: =RANK(DF16,$DF$4:$DF$141) -> 18 | E16: 1 | F16: 1 * 12 | G16: 1500 | I16: =H16*$E16 -> 0 | K16: =J16*$E16 -> 0 | M16: =L16*$E16 -> 0 | O16: =N16*$E16 -> 0 | Q16: =P16*$E16 -> 0 | S16: =R16*$E16 -> 0 | U16: =T16*$E16 -> 0 | W16: =V16*$E16 -> 0 | Y16: =X16*$E16 -> 0 | AA16: =Z16*$E16 -> 0 | AC16: =AB16*$E16 -> 0 | AE16: =AD16*$E16 -> 0 | AF16: =(AD16+AB16+Z16+X16+V16+T16+R16+P16+N16+L16+J16+H16)/1 -> 0 | AG16: =AF16*$E16 -> 0 | AI16: =AH16*$E16 -> 0 | AK16: =AJ16*$E16 -> 0 | AM16: =AL16*$E16 -> 0 | AO16: =AN16*$E16 -> 0 | AQ16: =AP16*$E16 -> 0 | AS16: =AR16*$E16 -> 0 | AU16: =AT16*$E16 -> 0 | AW16: =AV16*$E16 -> 0 | AY16: =AX16*$E16 -> 0 | BA16: =AZ16*$E16 -> 0 | BC16: =BB16*$E16 -> 0 | BE16: =BD16*$E16 -> 0 | BF16: =(BD16+BB16+AZ16+AX16+AV16+AT16+AR16+AP16+AN16+AL16+AJ16+AH16)/1 -> 0 | BG16: =BF16*$E16 -> 0 | BI16: =BH16*$E16 -> 0 | BK16: =BJ16*$E16 -> 0 | BM16: =BL16*$E16 -> 0 | BO16: =BN16*$E16 -> 0 | BQ16: =BP16*$E16 -> 0 | BS16: =BR16*$E16 -> 0 | BU16: =BT16*$E16 -> 0 | BW16: =BV16*$E16 -> 0 | BY16: =BX16*$E16 -> 0 | CA16: =BZ16*$E16 -> 0 | CC16: =CB16*$E16 -> 0 | CE16: =CD16*$E16 -> 0 | CF16: =(CD16+CB16+BZ16+BX16+BV16+BT16+BR16+BP16+BN16+BL16+BJ16+BH16)/1 -> 0 | CG16: =CF16*$E16 -> 0 | CH16: 24 | CI16: =CH16*$E16 -> 24 | CK16: =CJ16*$E16 -> 0 | CM16: =CL16*$E16 -> 0 | CO16: =CN16*$E16 -> 0 | CQ16: =CP16*$E16 -> 0 | CS16: =CR16*$E16 -> 0 | CT16: 192 | CU16: =CT16*$E16 -> 192 | CV16: 60 | CW16: =CV16*$E16 -> 60 | CY16: =CX16*$E16 -> 0 | DA16: =CZ16*$E16 -> 0 | DC16: =DB16*$E16 -> 0 | DE16: =DD16*$E16 -> 0 | DF16: =SUM(CH16,CJ16,CL16,CN16,CP16,CR16,CT16,CV16,CX16,CZ16,DB16,DD16) -> 276 | DG16: =DF16*$E16 -> 276
A17: 12 | B17: Kaung Kyi (1 Liter)_40% | C17: ‌ကော်ဘူး | D17: =RANK(DF17,$DF$4:$DF$141) -> 14 | E17: 1 | F17: 1 * 12 | G17: 1850 | I17: =H17*$E17 -> 0 | K17: =J17*$E17 -> 0 | M17: =L17*$E17 -> 0 | O17: =N17*$E17 -> 0 | Q17: =P17*$E17 -> 0 | S17: =R17*$E17 -> 0 | U17: =T17*$E17 -> 0 | W17: =V17*$E17 -> 0 | Y17: =X17*$E17 -> 0 | AA17: =Z17*$E17 -> 0 | AC17: =AB17*$E17 -> 0 | AE17: =AD17*$E17 -> 0 | AF17: =(AD17+AB17+Z17+X17+V17+T17+R17+P17+N17+L17+J17+H17)/1 -> 0 | AG17: =AF17*$E17 -> 0 | AI17: =AH17*$E17 -> 0 | AK17: =AJ17*$E17 -> 0 | AL17: 84 | AM17: =AL17*$E17 -> 84 | AN17: 336 | AO17: =AN17*$E17 -> 336 | AQ17: =AP17*$E17 -> 0 | AS17: =AR17*$E17 -> 0 | AT17: 72 | AU17: =AT17*$E17 -> 72 | AW17: =AV17*$E17 -> 0 | AY17: =AX17*$E17 -> 0 | BA17: =AZ17*$E17 -> 0 | BC17: =BB17*$E17 -> 0 | BE17: =BD17*$E17 -> 0 | BF17: =(BD17+BB17+AZ17+AX17+AV17+AT17+AR17+AP17+AN17+AL17+AJ17+AH17)/1 -> 492 | BG17: =BF17*$E17 -> 492 | BI17: =BH17*$E17 -> 0 | BK17: =BJ17*$E17 -> 0 | BM17: =BL17*$E17 -> 0 | BO17: =BN17*$E17 -> 0 | BQ17: =BP17*$E17 -> 0 | BS17: =BR17*$E17 -> 0 | BU17: =BT17*$E17 -> 0 | BW17: =BV17*$E17 -> 0 | BY17: =BX17*$E17 -> 0 | CA17: =BZ17*$E17 -> 0 | CC17: =CB17*$E17 -> 0 | CE17: =CD17*$E17 -> 0 | CF17: =(CD17+CB17+BZ17+BX17+BV17+BT17+BR17+BP17+BN17+BL17+BJ17+BH17)/1 -> 0 | CG17: =CF17*$E17 -> 0 | CI17: =CH17*$E17 -> 0 | CK17: =CJ17*$E17 -> 0 | CM17: =CL17*$E17 -> 0 | CO17: =CN17*$E17 -> 0 | CQ17: =CP17*$E17 -> 0 | CS17: =CR17*$E17 -> 0 | CT17: 206 | CU17: =CT17*$E17 -> 206 | CV17: 480 | CW17: =CV17*$E17 -> 480 | CX17: 468 | CY17: =CX17*$E17 -> 468 | CZ17: 300 | DA17: =CZ17*$E17 -> 300 | DB17: 120 | DC17: =DB17*$E17 -> 120 | DD17: 360 | DE17: =DD17*$E17 -> 360 | DF17: =SUM(CH17,CJ17,CL17,CN17,CP17,CR17,CT17,CV17,CX17,CZ17,DB17,DD17) -> 1934 | DG17: =DF17*$E17 -> 1934
A18: 13 | B18: Kaung Kyi (0.6 Liter)_25% | C18: ‌ကော်ဘူး | D18: =RANK(DF18,$DF$4:$DF$141) -> 21 | E18: 0.6 | F18: 1 * 12 | G18: 1085 | I18: =H18*$E18 -> 0 | K18: =J18*$E18 -> 0 | M18: =L18*$E18 -> 0 | O18: =N18*$E18 -> 0 | Q18: =P18*$E18 -> 0 | S18: =R18*$E18 -> 0 | U18: =T18*$E18 -> 0 | W18: =V18*$E18 -> 0 | Y18: =X18*$E18 -> 0 | AA18: =Z18*$E18 -> 0 | AC18: =AB18*$E18 -> 0 | AE18: =AD18*$E18 -> 0 | AF18: =(AD18+AB18+Z18+X18+V18+T18+R18+P18+N18+L18+J18+H18)/1 -> 0 | AG18: =AF18*$E18 -> 0 | AI18: =AH18*$E18 -> 0 | AK18: =AJ18*$E18 -> 0 | AM18: =AL18*$E18 -> 0 | AO18: =AN18*$E18 -> 0 | AQ18: =AP18*$E18 -> 0 | AS18: =AR18*$E18 -> 0 | AU18: =AT18*$E18 -> 0 | AW18: =AV18*$E18 -> 0 | AY18: =AX18*$E18 -> 0 | BA18: =AZ18*$E18 -> 0 | BC18: =BB18*$E18 -> 0 | BE18: =BD18*$E18 -> 0 | BF18: =(BD18+BB18+AZ18+AX18+AV18+AT18+AR18+AP18+AN18+AL18+AJ18+AH18)/1 -> 0 | BG18: =BF18*$E18 -> 0 | BI18: =BH18*$E18 -> 0 | BK18: =BJ18*$E18 -> 0 | BM18: =BL18*$E18 -> 0 | BO18: =BN18*$E18 -> 0 | BQ18: =BP18*$E18 -> 0 | BS18: =BR18*$E18 -> 0 | BU18: =BT18*$E18 -> 0 | BW18: =BV18*$E18 -> 0 | BY18: =BX18*$E18 -> 0 | CA18: =BZ18*$E18 -> 0 | CC18: =CB18*$E18 -> 0 | CE18: =CD18*$E18 -> 0 | CF18: =(CD18+CB18+BZ18+BX18+BV18+BT18+BR18+BP18+BN18+BL18+BJ18+BH18)/1 -> 0 | CG18: =CF18*$E18 -> 0 | CI18: =CH18*$E18 -> 0 | CK18: =CJ18*$E18 -> 0 | CM18: =CL18*$E18 -> 0 | CO18: =CN18*$E18 -> 0 | CQ18: =CP18*$E18 -> 0 | CS18: =CR18*$E18 -> 0 | CU18: =CT18*$E18 -> 0 | CW18: =CV18*$E18 -> 0 | CY18: =CX18*$E18 -> 0 | DA18: =CZ18*$E18 -> 0 | DC18: =DB18*$E18 -> 0 | DE18: =DD18*$E18 -> 0 | DF18: =SUM(CH18,CJ18,CL18,CN18,CP18,CR18,CT18,CV18,CX18,CZ18,DB18,DD18) -> 0 | DG18: =DF18*$E18 -> 0
A19: 14 | B19: Kaung Kyi (0.6 Liter)_40% | C19: ‌ကော်ဘူး | D19: =RANK(DF19,$DF$4:$DF$141) -> 21 | E19: 0.6 | F19: 1 * 12 | I19: =H19*$E19 -> 0 | K19: =J19*$E19 -> 0 | M19: =L19*$E19 -> 0 | O19: =N19*$E19 -> 0 | Q19: =P19*$E19 -> 0 | S19: =R19*$E19 -> 0 | U19: =T19*$E19 -> 0 | W19: =V19*$E19 -> 0 | Y19: =X19*$E19 -> 0 | AA19: =Z19*$E19 -> 0 | AC19: =AB19*$E19 -> 0 | AE19: =AD19*$E19 -> 0 | AF19: =(AD19+AB19+Z19+X19+V19+T19+R19+P19+N19+L19+J19+H19)/1 -> 0 | AG19: =AF19*$E19 -> 0 | AI19: =AH19*$E19 -> 0 | AK19: =AJ19*$E19 -> 0 | AM19: =AL19*$E19 -> 0 | AO19: =AN19*$E19 -> 0 | AQ19: =AP19*$E19 -> 0 | AS19: =AR19*$E19 -> 0 | AU19: =AT19*$E19 -> 0 | AW19: =AV19*$E19 -> 0 | AY19: =AX19*$E19 -> 0 | BA19: =AZ19*$E19 -> 0 | BC19: =BB19*$E19 -> 0 | BE19: =BD19*$E19 -> 0 | BF19: =(BD19+BB19+AZ19+AX19+AV19+AT19+AR19+AP19+AN19+AL19+AJ19+AH19)/1 -> 0 | BG19: =BF19*$E19 -> 0 | BI19: =BH19*$E19 -> 0 | BK19: =BJ19*$E19 -> 0 | BM19: =BL19*$E19 -> 0 | BO19: =BN19*$E19 -> 0 | BQ19: =BP19*$E19 -> 0 | BS19: =BR19*$E19 -> 0 | BU19: =BT19*$E19 -> 0 | BW19: =BV19*$E19 -> 0 | BY19: =BX19*$E19 -> 0 | CA19: =BZ19*$E19 -> 0 | CC19: =CB19*$E19 -> 0 | CE19: =CD19*$E19 -> 0 | CF19: =(CD19+CB19+BZ19+BX19+BV19+BT19+BR19+BP19+BN19+BL19+BJ19+BH19)/1 -> 0 | CG19: =CF19*$E19 -> 0 | CI19: =CH19*$E19 -> 0 | CK19: =CJ19*$E19 -> 0 | CM19: =CL19*$E19 -> 0 | CO19: =CN19*$E19 -> 0 | CQ19: =CP19*$E19 -> 0 | CS19: =CR19*$E19 -> 0 | CU19: =CT19*$E19 -> 0 | CW19: =CV19*$E19 -> 0 | CY19: =CX19*$E19 -> 0 | DA19: =CZ19*$E19 -> 0 | DC19: =DB19*$E19 -> 0 | DE19: =DD19*$E19 -> 0 | DF19: =SUM(CH19,CJ19,CL19,CN19,CP19,CR19,CT19,CV19,CX19,CZ19,DB19,DD19) -> 0 | DG19: =DF19*$E19 -> 0
A20: 15 | B20: Kaung Kyi (0.35 Liter)_25% | C20: ‌ကော်ဘူး | D20: =RANK(DF20,$DF$4:$DF$141) -> 21 | E20: 0.35 | F20: 1 * 40 | I20: =H20*$E20 -> 0 | K20: =J20*$E20 -> 0 | M20: =L20*$E20 -> 0 | O20: =N20*$E20 -> 0 | Q20: =P20*$E20 -> 0 | S20: =R20*$E20 -> 0 | U20: =T20*$E20 -> 0 | W20: =V20*$E20 -> 0 | Y20: =X20*$E20 -> 0 | AA20: =Z20*$E20 -> 0 | AC20: =AB20*$E20 -> 0 | AE20: =AD20*$E20 -> 0 | AF20: =(AD20+AB20+Z20+X20+V20+T20+R20+P20+N20+L20+J20+H20)/1 -> 0 | AG20: =AF20*$E20 -> 0 | AI20: =AH20*$E20 -> 0 | AK20: =AJ20*$E20 -> 0 | AM20: =AL20*$E20 -> 0 | AO20: =AN20*$E20 -> 0 | AQ20: =AP20*$E20 -> 0 | AS20: =AR20*$E20 -> 0 | AU20: =AT20*$E20 -> 0 | AW20: =AV20*$E20 -> 0 | AY20: =AX20*$E20 -> 0 | BA20: =AZ20*$E20 -> 0 | BC20: =BB20*$E20 -> 0 | BE20: =BD20*$E20 -> 0 | BF20: =(BD20+BB20+AZ20+AX20+AV20+AT20+AR20+AP20+AN20+AL20+AJ20+AH20)/1 -> 0 | BG20: =BF20*$E20 -> 0 | BI20: =BH20*$E20 -> 0 | BK20: =BJ20*$E20 -> 0 | BM20: =BL20*$E20 -> 0 | BO20: =BN20*$E20 -> 0 | BQ20: =BP20*$E20 -> 0 | BS20: =BR20*$E20 -> 0 | BU20: =BT20*$E20 -> 0 | BW20: =BV20*$E20 -> 0 | BY20: =BX20*$E20 -> 0 | CA20: =BZ20*$E20 -> 0 | CC20: =CB20*$E20 -> 0 | CE20: =CD20*$E20 -> 0 | CF20: =(CD20+CB20+BZ20+BX20+BV20+BT20+BR20+BP20+BN20+BL20+BJ20+BH20)/1 -> 0 | CG20: =CF20*$E20 -> 0 | CI20: =CH20*$E20 -> 0 | CK20: =CJ20*$E20 -> 0 | CM20: =CL20*$E20 -> 0 | CO20: =CN20*$E20 -> 0 | CQ20: =CP20*$E20 -> 0 | CS20: =CR20*$E20 -> 0 | CU20: =CT20*$E20 -> 0 | CW20: =CV20*$E20 -> 0 | CY20: =CX20*$E20 -> 0 | DA20: =CZ20*$E20 -> 0 | DC20: =DB20*$E20 -> 0 | DE20: =DD20*$E20 -> 0 | DF20: =SUM(CH20,CJ20,CL20,CN20,CP20,CR20,CT20,CV20,CX20,CZ20,DB20,DD20) -> 0 | DG20: =DF20*$E20 -> 0
