Workbook
Name aa: #REF!
Name aaa: #REF!
Name aaaaa: #REF!
Name aaaaaaa: #REF!
Name asd: '[1]Market ( Mar) '!#REF!
Name atr: #REF!
Name b: #REF!
Name bb: #REF!
Name Beg_Bal: #REF!
Name Cash_Cr: #REF!
Name Cash_Dr: #REF!
Name cc: #REF!
Name ccc: #REF!
Name cr: #REF!
Name crs: #REF!
Name cvvvv: #REF!
Name Data: #REF!
Name dd: #REF!
Name ddd: #REF!
Name dddd: #N/A
Name dr: #REF!
Name drs: #REF!
Name dsfas: #REF!
Name eeee: #REF!
Name End_Bal: #REF!
Name Extra_Pay: #REF!
Name fgf: #REF!
Name fgjhj: #REF!
Name Full_Print: #REF!
Name Header_Row: ROW(#REF!)
Name hjj: #REF!
Name hjkjk: #REF!
Name hmjhj: #REF!
Name ii: #REF!
Name III: #REF!
Name Int: #REF!
Name Interest_Rate: #REF!
Name jbkjkl: #REF!
Name Journal_Cr: #REF!
Name Journal_Dr: #REF!
Name kdt: #REF!
Name Last_Row: IF(Values_Entered,Header_Row+Number_of_Payments,Header_Row)
Name Loan_Amount: #REF!
Name Loan_Start: #REF!
Name Loan_Years: #REF!
Name LSO: #REF!
Name lsoq: #REF!
Name mms: #REF!
Name neew: #REF!
Name New: #REF!
Name NOV: #REF!
Name Num_Pmt_Per_Year: #REF!
Name Number_of_Payments: MATCH(0.01,End_Bal,-1)+1
Name ooo: #REF!
Name Opening_Cr: #REF!
Name Opening_Dr: #REF!
Name Pay_Date: #REF!
Name Pay_Num: #REF!
Name Payment_Date: DATE(YEAR(Loan_Start),MONTH(Loan_Start)+Payment_Number,DAY(Loan_Start))
Name Princ: #REF!

Sheet Compare for YGN (2022 To 2026) 
A1: BE Sales For Yangon (All In Bottle)
A2: No | B2: Month | C2: 2022 (BE) | E2: 2023 (BE) | G2: 2024 (BE) | I2: 2025 (BE) | K2: 2026 (BE) | M2: Total
C3: Bottle | D3: Liters | E3: Bottle | F3: Liters | G3: Bottle | H3: Liters | I3: Bottle | J3: Liters | K3: Bottle | L3: Liters | M3: Bottle | N3: Liters
A4: 1 | B4: January | C4: =+'SKU 2025'!H142 -> 2905396 | D4: =+'SKU 2025'!I142 -> 1973831.3 | E4: =+'SKU 2025'!AH142 -> 3028281 | F4: =+'SKU 2025'!AI142 -> 2123061.2 | G4: =+'SKU 2025'!BH142 -> 2635501 | H4: =+'SKU 2025'!BI142 -> 1945479.8 | I4: =+'SKU 2025'!CH142 -> 2088118 | J4: =+'SKU 2025'!CI142 -> 1573223.2 | K4: ='SKU 2026'!DH148 -> 2170348 | L4: ='SKU 2026'!DI148 -> 1642001.3 | M4: =+G4+E4+C4+I4+K4 -> 12827644 | N4: =+H4+F4+D4+J4+L4 -> 9257596.8
A5: 2 | B5: February | C5: =+'SKU 2025'!J142 -> 2675328 | D5: =+'SKU 2025'!K142 -> 1821908.3 | E5: =+'SKU 2025'!AJ142 -> 2480575 | F5: =+'SKU 2025'!AK142 -> 1732604.3 | G5: =+'SKU 2025'!BJ142 -> 2188605 | H5: =+'SKU 2025'!BK142 -> 1613415.5 | I5: =+'SKU 2025'!CJ142 -> 2119137 | J5: =+'SKU 2025'!CK142 -> 1588117.3 | K5: ='SKU 2026'!DJ148 -> 1964569 | L5: ='SKU 2026'!DK148 -> 1494502.4 | M5: =+G5+E5+C5+I5+K5 -> 11428214 | N5: =+H5+F5+D5+J5+L5 -> 8250547.8
A6: 3 | B6: March | C6: =+'SKU 2025'!L142 -> 4002433 | D6: =+'SKU 2025'!M142 -> 2701832.4 | E6: =+'SKU 2025'!AL142 -> 3273071 | F6: =+'SKU 2025'!AM142 -> 2282645.7 | G6: =+'SKU 2025'!BL142 -> 2467561 | H6: =+'SKU 2025'!BM142 -> 1832925.2 | I6: =+'SKU 2025'!CL142 -> 3118431 | J6: =+'SKU 2025'!CM142 -> 2360939.6 | M6: =+G6+E6+C6+I6+K6 -> 12861496 | N6: =+H6+F6+D6+J6+L6 -> 9178342.8
A7: 4 | B7: April | C7: =+'SKU 2025'!N142 -> 3026203 | D7: =+'SKU 2025'!O142 -> 2085945.7 | E7: =+'SKU 2025'!AN142 -> 2609941 | F7: =+'SKU 2025'!AO142 -> 1851666.2 | G7: =+'SKU 2025'!BN142 -> 2441256 | H7: =+'SKU 2025'!BO142 -> 1823736.2 | I7: ='SKU 2025'!CN142 -> 1794739 | J7: ='SKU 2025'!CO142 -> 1331643.9 | M7: =+G7+E7+C7+I7+K7 -> 9872139 | N7: =+H7+F7+D7+J7+L7 -> 7092992
A8: 5 | B8: May | C8: =+'SKU 2025'!P142 -> 2887735 | D8: =+'SKU 2025'!Q142 -> 2006992 | E8: =+'SKU 2025'!AP142 -> 2590552 | F8: =+'SKU 2025'!AQ142 -> 1891760 | G8: =+'SKU 2025'!BP142 -> 2524506 | H8: =+'SKU 2025'!BQ142 -> 1876603.9 | I8: ='SKU 2025'!CP142 -> 2221723 | J8: ='SKU 2025'!CQ142 -> 1682932.2 | M8: =+G8+E8+C8+I8+K8 -> 10224516 | N8: =+H8+F8+D8+J8+L8 -> 7458288.1
A9: 6 | B9: June | C9: =+'SKU 2025'!R142 -> 3003194 | D9: =+'SKU 2025'!S142 -> 2087997.2 | E9: =+'SKU 2025'!AR142 -> 2454565 | F9: =+'SKU 2025'!AS142 -> 1825451 | G9: =+'SKU 2025'!BR142 -> 2791984 | H9: =+'SKU 2025'!BS142 -> 2093949.5 | I9: ='SKU 2025'!CR142 -> 2279600 | J9: ='SKU 2025'!CS142 -> 1732105.4 | M9: =+G9+E9+C9+I9+K9 -> 10529343 | N9: =+H9+F9+D9+J9+L9 -> 7739503
A10: 7 | B10: July | C10: =+'SKU 2025'!T142 -> 2836346 | D10: =+'SKU 2025'!U142 -> 1943349.4 | E10: =+'SKU 2025'!AT142 -> 2779248 | F10: =+'SKU 2025'!AU142 -> 2016338.1 | G10: =+'SKU 2025'!BT142 -> 2562242 | H10: =+'SKU 2025'!BU142 -> 1929114.5 | I10: ='SKU 2025'!CT142 -> 2251328 | J10: ='SKU 2025'!CU142 -> 1699256.9 | M10: =+G10+E10+C10+I10+K10 -> 10429164 | N10: =+H10+F10+D10+J10+L10 -> 7588058.9
A11: 8 | B11: August | C11: =+'SKU 2025'!V142 -> 3483097 | D11: =+'SKU 2025'!W142 -> 2426535.9 | E11: =+'SKU 2025'!AV142 -> 2940873 | F11: =+'SKU 2025'!AW142 -> 2133100.4 | G11: =+'SKU 2025'!BV142 -> 2263539 | H11: =+'SKU 2025'!BW142 -> 1696048.9 | I11: ='SKU 2025'!CV142 -> 2239523 | J11: ='SKU 2025'!CW142 -> 1689285.9 | M11: =+G11+E11+C11+I11+K11 -> 10927032 | N11: =+H11+F11+D11+J11+L11 -> 7944971.1
A12: 9 | B12: September | C12: =+'SKU 2025'!X142 -> 2436131 | D12: =+'SKU 2025'!Y142 -> 1694399.2 | E12: =+'SKU 2025'!AX142 -> 2038669 | F12: =+'SKU 2025'!AY142 -> 1465445.6 | G12: =+'SKU 2025'!BX142 -> 2144607 | H12: =+'SKU 2025'!BY142 -> 1615266 | I12: ='SKU 2025'!CX142 -> 2124541 | J12: ='SKU 2025'!CY142 -> 1606217.7 | M12: =+G12+E12+C12+I12+K12 -> 8743948 | N12: =+H12+F12+D12+J12+L12 -> 6381328.6
A13: 10 | B13: October | C13: =+'SKU 2025'!Z142 -> 2508180 | D13: =+'SKU 2025'!AA142 -> 1734445 | E13: =+'SKU 2025'!AZ142 -> 2321631 | F13: =+'SKU 2025'!BA142 -> 1686561.7 | G13: =+'SKU 2025'!BZ142 -> 2505567 | H13: =+'SKU 2025'!CA142 -> 1884903.3 | I13: ='SKU 2025'!CZ142 -> 2219563 | J13: ='SKU 2025'!DA142 -> 1676170.3 | M13: =+G13+E13+C13+I13+K13 -> 9554941 | N13: =+H13+F13+D13+J13+L13 -> 6982080.4
A14: 11 | B14: November | C14: =+'SKU 2025'!AB142 -> 2588009 | D14: =+'SKU 2025'!AC142 -> 1783502 | E14: =+'SKU 2025'!BB142 -> 2357171 | F14: =+'SKU 2025'!BC142 -> 1724714.2 | G14: =+'SKU 2025'!CB142 -> 2317593 | H14: =+'SKU 2025'!CC142 -> 1714170.5 | I14: ='SKU 2025'!DB142 -> 2095754 | J14: ='SKU 2025'!DC142 -> 1580591.3 | M14: =+G14+E14+C14+I14+K14 -> 9358527 | N14: =+H14+F14+D14+J14+L14 -> 6802977.9
A15: 12 | B15: December | C15: =+'SKU 2025'!AD142 -> 2863648 | D15: =+'SKU 2025'!AE142 -> 1992385.9 | E15: =+'SKU 2025'!BD142 -> 2553960 | F15: =+'SKU 2025'!BE142 -> 1871502.7 | G15: =+'SKU 2025'!CD142 -> 2218222 | H15: =+'SKU 2025'!CE142 -> 1646715.6 | I15: ='SKU 2025'!DD142 -> 2252568 | J15: ='SKU 2025'!DE142 -> 1706072 | M15: =+G15+E15+C15+I15+K15 -> 9888398 | N15: =+H15+F15+D15+J15+L15 -> 7216676.2
B16: Gift ( DT - 1 Liter) | C16: =Q37 -> 106670 | D16: =C16*1 -> 106670 | E16: =Q55 -> 154126 | F16: =E16*1 -> 154126 | G16: =V37 -> 183659 | H16: =G16*1 -> 183659 | I16: =V55 -> 172648 | J16: =I16*1 -> 172648 | K16: =AA37 -> 25168 | L16: =K16*1 -> 25168 | M16: =+G16+E16+C16+I16+K16 -> 642271 | N16: =+H16+F16+D16+J16+L16 -> 642271
B17: Gift ( DT - 0.6 Liter) | C17: =R37 -> 240 | D17: =C17*0.6 -> 144 | E17: =R55 -> 384 | F17: =E17*0.6 -> 230.4 | G17: =W37 -> 0 | H17: =G17*0.6 -> 0 | I17: =W55 -> 0 | J17: =I17*0.6 -> 0 | K17: =AB37 -> 0 | L17: =K17*0.6 -> 0 | M17: =+G17+E17+C17+I17+K17 -> 624 | N17: =+H17+F17+D17+J17+L17 -> 374.4
B18: Gift ( DT - 0.35 Liter) | C18: =S37 -> 0 | D18: =C18*0.35 -> 0 | E18: =S55 -> 1498 | F18: =E18*0.35 -> 524.3 | G18: =X37 -> 29515 | H18: =G18*0.35 -> 10330.25 | I18: =X55 -> 58996 | J18: =I18*0.35 -> 20648.6 | K18: =AC37 -> 8400 | L18: =K18*0.35 -> 2940 | M18: =+G18+E18+C18+I18+K18 -> 98409 | N18: =+H18+F18+D18+J18+L18 -> 34443.15
B19: Total | C19: =SUM(C4:C18) -> 35322610 | D19: =SUM(D4:D18) -> 24359938 | E19: =SUM(E4:E18) -> 31584545 | F19: =SUM(F4:F18) -> 22759732 | G19: =SUM(G4:G18) -> 29274357 | H19: =SUM(H4:H18) -> 21866318 | I19: =SUM(I4:I18) -> 27036669 | J19: =SUM(J4:J18) -> 20419852 | ... N19: =SUM(N4:N18) -> 92570452
A22: BE Sales For Yangon (KK In Bottle) | P22: 2022 - FOC (Tarmarind) - Yangon | U22: 2024 - FOC (Tarmarind) - Yangon | Z22: 2026 - FOC (Tarmarind) - Yangon
A23: No | B23: Month | C23: 2022 (KK) | E23: 2023 (KK) | G23: 2024 (KK) | I23: 2025 (KK) | K23: 2026 (KK) | M23: Total | P23: လ | Q23: 1-Liter | R23: .600ml | S23: .350ml | U23: လ | V23: 1-Liter | W23: .600ml | X23: .350ml | Z23: လ | AA23: 1-Liter | AB23: .600ml | AC23: .350ml
C24: Bottle | D24: Liters | E24: Bottle | F24: Liters | G24: Bottle | H24: Liters | I24: Bottle | J24: Liters | K24: Bottle | L24: Liters | M24: Bottle | N24: Liters | P24: Jan | Q24: 6446 | S24: 0 | U24: Jan | V24: 13243 | X24: 655 | Z24: Jan | AA24: 12994 | AC24: 4640
A25: 1 | B25: Kaung Kyi (1 Liter)_25% | C25: =+'SKU 2025'!AF16 -> 312 | D25: ='SKU 2025'!AG16 -> 312 | E25: ='SKU 2025'!BF16 -> 360 | F25: ='SKU 2025'!BG16 -> 360 | G25: ='SKU 2025'!CF16 -> 6951 | H25: ='SKU 2025'!CG16 -> 6951 | I25: ='SKU 2025'!DF16 -> 20817 | J25: ='SKU 2025'!DG16 -> 20817 | K25: ='SKU 2026'!EF16 -> 3479 | L25: ='SKU 2026'!EG16 -> 3479 | M25: =+G25+E25+C25+I25+K25 -> 31919 | N25: =+H25+F25+D25+J25+L25 -> 31919 | P25: Feb | Q25: 5328 | S25: 0 | U25: Feb | V25: 12300 | X25: 664 | Z25: Feb | AA25: 12174 | AC25: 3760
A26: 2 | B26: Kaung Kyi (1 Liter)_40% | C26: =+'SKU 2025'!AF17 -> 108 | D26: ='SKU 2025'!AG17 -> 108 | E26: ='SKU 2025'!BF17 -> 360 | F26: ='SKU 2025'!BG17 -> 360 | G26: ='SKU 2025'!CF17 -> 4164 | H26: ='SKU 2025'!CG17 -> 4164 | I26: ='SKU 2025'!DF17 -> 2848 | J26: ='SKU 2025'!DG17 -> 2848 | K26: ='SKU 2026'!EF17 -> 468 | L26: ='SKU 2026'!EG17 -> 468 | M26: =+G26+E26+C26+I26+K26 -> 7948 | N26: =+H26+F26+D26+J26+L26 -> 7948 | P26: Mar | Q26: 8064 | U26: Mar | V26: 13744 | X26: 590 | Z26: Mar
A27: 3 | B27: Kaung Kyi (0.6 Liter)_25% | C27: =+'SKU 2025'!AF18 -> 0 | D27: ='SKU 2025'!AG18 -> 0 | E27: ='SKU 2025'!BF18 -> 0 | F27: ='SKU 2025'!BG18 -> 0 | G27: ='SKU 2025'!CF18 -> 0 | H27: ='SKU 2025'!CG18 -> 0 | I27: ='SKU 2025'!DF18 -> 0 | J27: ='SKU 2025'!DG18 -> 0 | K27: ='SKU 2026'!EF18 -> 0 | L27: ='SKU 2026'!EG18 -> 0 | M27: =+G27+E27+C27+I27+K27 -> 0 | N27: =+H27+F27+D27+J27+L27 -> 0 | P27: April | Q27: 9276 | U27: April | V27: 13430 | X27: 630 | Z27: April
A28: 4 | B28: Kaung Kyi (0.6 Liter)_40% | C28: =+'SKU 2025'!AF19 -> 144 | D28: ='SKU 2025'!AG19 -> 86.4 | E28: ='SKU 2025'!BF19 -> 0 | F28: ='SKU 2025'!BG19 -> 0 | G28: ='SKU 2025'!CF19 -> 12 | H28: ='SKU 2025'!CG19 -> 7.2 | I28: ='SKU 2025'!DF19 -> 12 | J28: ='SKU 2025'!DG19 -> 7.2 | K28: ='SKU 2026'!EF19 -> 12 | L28: ='SKU 2026'!EG19 -> 7.2 | M28: =+G28+E28+C28+I28+K28 -> 180 | N28: =+H28+F28+D28+J28+L28 -> 108 | P28: May | Q28: 9288 | R28: 120 | U28: May | V28: 15259 | X28: 870 | Z28: May
A29: 5 | B29: Kaung Kyi (0.35 Liter)_25% | C29: =+'SKU 2025'!AF20 -> 0 | D29: ='SKU 2025'!AG20 -> 0 | E29: ='SKU 2025'!BF20 -> 0 | F29: ='SKU 2025'!BG20 -> 0 | G29: ='SKU 2025'!CF20 -> 0 | H29: ='SKU 2025'!CG20 -> 0 | I29: ='SKU 2025'!DF20 -> 0 | J29: ='SKU 2025'!DG20 -> 0 | K29: ='SKU 2026'!DH20 -> 0 | L29: ='SKU 2026'!DI20 -> 0 | M29: =+G29+E29+C29+I29+K29 -> 0 | N29: =+H29+F29+D29+J29+L29 -> 0 | P29: Jun | Q29: 9996 | U29: Jun | V29: 15283 | X29: 1070 | Z29: Jun
A30: 6 | B30: Kaung Kyi ( 0.35 Liter) - 40% | C30: =+'SKU 2025'!AF21 -> 187200 | D30: ='SKU 2025'!AG21 -> 65520 | E30: ='SKU 2025'!BF21 -> 52 | F30: ='SKU 2025'!BG21 -> 18.2 | G30: ='SKU 2025'!CF21 -> 0 | H30: ='SKU 2025'!CG21 -> 0 | I30: ='SKU 2025'!DF21 -> 480 | J30: ='SKU 2025'!DG21 -> 168 | K30: ='SKU 2026'!EF21 -> 200 | L30: ='SKU 2026'!EG21 -> 70 | M30: =+G30+E30+C30+I30+K30 -> 187932 | N30: =+H30+F30+D30+J30+L30 -> 65776.2 | P30: July | Q30: 9516 | R30: 24 | U30: July | V30: 18525 | X30: 1532 | Z30: July
A31: 7 | B31: Kaung Kyi | C31: =+'SKU 2025'!AF22 -> 0 | D31: ='SKU 2025'!AG22 -> 0 | E31: ='SKU 2025'!BF22 -> 14 | F31: ='SKU 2025'!BG22 -> 8.96 | G31: ='SKU 2025'!CF22 -> 0 | H31: ='SKU 2025'!CG22 -> 0 | I31: ='SKU 2025'!DF22 -> 0 | J31: ='SKU 2025'!DG22 -> 0 | K31: ='SKU 2026'!DH22 -> 0 | L31: ='SKU 2026'!DI22 -> 0 | M31: =+G31+E31+C31+I31+K31 -> 14 | N31: =+H31+F31+D31+J31+L31 -> 8.96 | P31: Aug | Q31: 10752 | R31: 24 | U31: Aug | V31: 16278 | X31: 1480 | Z31: Aug
A32: 8 | B32: Kaung Kyi (40%) | C32: =+'SKU 2025'!AF23 -> 0 | D32: ='SKU 2025'!AG23 -> 0 | E32: ='SKU 2025'!BF23 -> 0 | F32: ='SKU 2025'!BG23 -> 0 | G32: ='SKU 2025'!CF23 -> 0 | H32: ='SKU 2025'!CG23 -> 0 | I32: ='SKU 2025'!DF23 -> 0 | J32: ='SKU 2025'!DG23 -> 0 | K32: ='SKU 2026'!DH23 -> 0 | L32: ='SKU 2026'!DI23 -> 0 | M32: =+G32+E32+C32+I32+K32 -> 0 | N32: =+H32+F32+D32+J32+L32 -> 0 | P32: Sept | Q32: 9252 | R32: 36 | U32: Sept | V32: 16515 | X32: 7314 | Z32: Sept
A33: 9 | B33: Kaung Kyi (46%) | C33: =+'SKU 2025'!AF24 -> 0 | D33: ='SKU 2025'!AG24 -> 0 | E33: ='SKU 2025'!BF24 -> 0 | F33: ='SKU 2025'!BG24 -> 0 | G33: ='SKU 2025'!CF24 -> 0 | H33: ='SKU 2025'!CG24 -> 0 | I33: ='SKU 2025'!DF24 -> 0 | J33: ='SKU 2025'!DG24 -> 0 | K33: ='SKU 2026'!DH24 -> 0 | L33: ='SKU 2026'!DI24 -> 0 | M33: =+G33+E33+C33+I33+K33 -> 0 | N33: =+H33+F33+D33+J33+L33 -> 0 | P33: Oct | Q33: 9264 | U33: Oct | V33: 17415 | X33: 10194 | Z33: Oct
P34: Nov | Q34: 9276 | R34: 24 | U34: Nov | V34: 17159 | X34: 1101 | Z34: Nov
P35: Dec | Q35: 10212 | R35: 12 | U35: Dec | V35: 14508 | X35: 3415 | Z35: Dec
B36: Total | C36: =SUM(C25:C33) -> 187764 | D36: =SUM(D25:D33) -> 66026.4 | E36: =SUM(E25:E33) -> 786 | F36: =SUM(F25:F33) -> 747.16 | G36: =SUM(G25:G33) -> 11127 | H36: =SUM(H25:H33) -> 11122.2 | I36: =SUM(I25:I33) -> 24157 | J36: =SUM(J25:J33) -> 23840.2 | ... N36: =SUM(N25:N33) -> 105760.16
Q37: =SUM(Q24:Q36) -> 106670 | R37: =SUM(R24:R36) -> 240 | S37: =SUM(S24:S36) -> 0 | V37: =SUM(V24:V36) -> 183659 | W37: =SUM(W24:W36) -> 0 | X37: =SUM(X24:X36) -> 29515 | AA37: =SUM(AA24:AA36) -> 25168 | AB37: =SUM(AB24:AB36) -> 0 | AC37: =SUM(AC24:AC36) -> 8400
P40: 2023 - FOC (Tarmarind) - Yangon | U40: 2025 - FOC (Tarmarind) - Yangon
P41: လ | Q41: 1-Liter | R41: .600ml | S41: .350ml | U41: လ | V41: 1-Liter | W41: .600ml | X41: .350ml
P42: Jan | Q42: 11184 | R42: 48 | U42: Jan | V42: 13556 | X42: 9498
P43: Feb | Q43: 11412 | R43: 60 | U43: Feb | V43: 13307 | X43: 8335
P44: Mar | Q44: 17628 | U44: Mar | V44: 19676 | X44: 7039
...

Sheet SKU 2026
A1: Yangon | CH1: 2025
A2: Sr. | B2: Product Name | D2: Ranking | E2: ML | F2: Packing | G2: Sales Price | H2: 44562 | J2: 44593 | L2: 44621 | N2: 44652 | P2: 44682 | R2: 44713 | T2: 44743 | V2: 44774 | X2: 44805 | Z2: 44835 | AB2: 44866 | AD2: 44896 | AF2: 2022 Total | AH2: 44927 | AJ2: 44958 | AL2: 44986 | AN2: 45017 | AP2: 45047 | AR2: 45078 | AT2: 45108 | AV2: 45139 | AX2: 45170 | AZ2: 45200 | BB2: 45231 | BD2: 45261 | BF2: 2023 Total | BH2: 45292 | BJ2: 45323 | BL2: 45352 | BN2: 45383 | BP2: 45413 | BR2: 45444 | BT2: 45474 | BV2: 45505 | BX2: 45536 | BZ2: 45566 | CB2: 45597 | CD2: 45627 | CF2: 2024 Total | CH2: 45658 | CJ2: 45689 | CL2: 45717 | CN2: 45748 | CP2: 45778 | CR2: 45809 | CT2: 45839 | CV2: 45870 | CX2: 45901 | CZ2: 45931 | DB2: 45962 | DD2: 45992 | DF2: 2025 Total | DH2: 46023 | DJ2: 46054 | DL2: 46082 | DN2: 46113 | DP2: 46143 | DR2: 46174 | DT2: 46204 | DV2: 46235 | DX2: 46266 | DZ2: 46296 | EB2: 46327 | ED2: 46357 | EF2: 2026 Total
H3: Bot | I3: Lit | J3: Bot | K3: Lit | L3: Bot | M3: Lit | N3: Bot | O3: Lit | P3: Bot | Q3: Lit | R3: Bot | S3: Lit | T3: Bot | U3: Lit | V3: Bot | W3: Lit | X3: Bot | Y3: Lit | Z3: Bot | AA3: Lit | AB3: Bot | AC3: Lit | AD3: Bot | AE3: Lit | AF3: Bot | AG3: Lit | AH3: Bot | AI3: Lit | AJ3: Bot | AK3: Lit | AL3: Bot | AM3: Lit | AN3: Bot | AO3: Lit | AP3: Bot | AQ3: Lit | AR3: Bot | AS3: Lit | AT3: Bot | AU3: Lit | AV3: Bot | AW3: Lit | AX3: Bot | AY3: Lit | AZ3: Bot | BA3: Lit | BB3: Bot | BC3: Lit | BD3: Bot | BE3: Lit | BF3: Bot | BG3: Lit | BH3: Bot | BI3: Lit | BJ3: Bot | BK3: Lit | BL3: Bot | BM3: Lit | BN3: Bot | BO3: Lit | BP3: Bot | BQ3: Lit | BR3: Bot | BS3: Lit | BT3: Bot | BU3: Lit | BV3: Bot | BW3: Lit | BX3: Bot | BY3: Lit | BZ3: Bot | CA3: Lit | CB3: Bot | CC3: Lit | CD3: Bot | CE3: Lit | CF3: Bot | CG3: Lit | CH3: Bot | CI3: Lit | CJ3: Bot | CK3: Lit | CL3: Bot | CM3: Lit | CN3: Bot | CO3: Lit | CP3: Bot | CQ3: Lit | CR3: Bot | CS3: Lit | CT3: Bot | CU3: Lit | CV3: Bot | CW3: Lit | CX3: Bot | CY3: Lit | CZ3: Bot | DA3: Lit | DB3: Bot | DC3: Lit | DD3: Bot | DE3: Lit | DF3: Bot | DG3: Lit | DH3: Bot | DI3: Lit | DJ3: Bot | DK3: Lit | DL3: Bot | DM3: Lit | DN3: Bot | DO3: Lit | DP3: Bot | DQ3: Lit | DR3: Bot | DS3: Lit | DT3: Bot | DU3: Lit | DV3: Bot | DW3: Lit | DX3: Bot | DY3: Lit | DZ3: Bot | EA3: Lit | EB3: Bot | EC3: Lit | ED3: Bot | EE3: Lit | EF3: Bot | EG3: Lit
A4: 1 | B4: "Zay" Vodka 700-ml | C4: ပုလင်း | D4: =RANK(DF4,$DF$4:$DF$147) -> 11 | E4: 0.7 | F4: 1 * 12 | G4: 2000 | H4: 124523 | I4: =H4*$E4 -> 87166.1 | J4: 116620 | K4: =J4*$E4 -> 81634 | L4: 181840 | M4: =L4*$E4 -> 127288 | N4: 108012 | O4: =N4*$E4 -> 75608.4 | P4: 114210 | Q4: =P4*$E4 -> 79947 | R4: 119568 | S4: =R4*$E4 -> 83697.6 | T4: 96592 | U4: =T4*$E4 -> 67614.4 | V4: 131952 | W4: =V4*$E4 -> 92366.4 | X4: 89903 | Y4: =X4*$E4 -> 62932.1 | Z4: 61110 | AA4: =Z4*$E4 -> 42777 | AB4: 51726 | AC4: =AB4*$E4 -> 36208.2 | AD4: 78719 | AE4: =AD4*$E4 -> 55103.3 | AF4: =(AD4+AB4+Z4+X4+V4+T4+R4+P4+N4+L4+J4+H4)/1 -> 1274775 | AG4: =AF4*$E4 -> 892342.5 | AH4: 77141 | AI4: =AH4*$E4 -> 53998.7 | AJ4: 72972 | AK4: =AJ4*$E4 -> 51080.4 | AL4: 70308 | AM4: =AL4*$E4 -> 49215.6 | AN4: 58392 | AO4: =AN4*$E4 -> 40874.4 | AP4: 58378 | AQ4: =AP4*$E4 -> 40864.6 | AR4: 43500 | AS4: =AR4*$E4 -> 30450 | AT4: 42396 | AU4: =AT4*$E4 -> 29677.2 | AV4: 53793 | AW4: =AV4*$E4 -> 37655.1 | AX4: 32216 | AY4: =AX4*$E4 -> 22551.2 | AZ4: 41076 | BA4: =AZ4*$E4 -> 28753.2 | BB4: 38508 | BC4: =BB4*$E4 -> 26955.6 | BD4: 38963 | BE4: =BD4*$E4 -> 27274.1 | BF4: =(BD4+BB4+AZ4+AX4+AV4+AT4+AR4+AP4+AN4+AL4+AJ4+AH4)/1 -> 627643 | BG4: =BF4*$E4 -> 439350.1 | BH4: 48252 | BI4: =BH4*$E4 -> 33776.4 | BJ4: 36072 | BK4: =BJ4*$E4 -> 25250.4 | BL4: 42647 | BM4: =BL4*$E4 -> 29852.9 | BN4: 36856 | BO4: =BN4*$E4 -> 25799.2 | BP4: 33804 | BQ4: =BP4*$E4 -> 23662.8 | BR4: 35760 | BS4: =BR4*$E4 -> 25032 | BT4: 30059 | BU4: =BT4*$E4 -> 21041.3 | BV4: 28524 | BW4: =BV4*$E4 -> 19966.8 | BX4: 22953 | BY4: =BX4*$E4 -> 16067.1 | BZ4: 22835 | CA4: =BZ4*$E4 -> 15984.5 | CB4: 23747 | CC4: =CB4*$E4 -> 16622.9 | CD4: 26058 | CE4: =CD4*$E4 -> 18240.6 | CF4: =(CD4+CB4+BZ4+BX4+BV4+BT4+BR4+BP4+BN4+BL4+BJ4+BH4)/1 -> 387567 | CG4: =CF4*$E4 -> 271296.9 | CH4: 22051 | CI4: =CH4*$E4 -> 15435.7 | CJ4: 19282 | CK4: =CJ4*$E4 -> 13497.4 | CL4: 28498 | CM4: =CL4*$E4 -> 19948.6 | CN4: 22811 | CO4: =CN4*$E4 -> 15967.7 | CP4: 21036 | CQ4: =CP4*$E4 -> 14725.2 | CR4: 21198 | CS4: =CR4*$E4 -> 14838.6 | CT4: 16910 | CU4: =CT4*$E4 -> 11837 | CV4: 17784 | CW4: =CV4*$E4 -> 12448.8 | CX4: 17328 | CY4: =CX4*$E4 -> 12129.6 | CZ4: 18888 | DA4: =CZ4*$E4 -> 13221.6 | DB4: 22091 | DC4: =DB4*$E4 -> 15463.7 | DD4: 18869 | DE4: =DD4*$E4 -> 13208.3 | DF4: =SUM(CH4,CJ4,CL4,CN4,CP4,CR4,CT4,CV4,CX4,CZ4,DB4,DD4)/1 -> 246746 | DG4: =DF4*$E4 -> 172722.2 | DH4: 16824 | DI4: =DH4*$E4 -> 11776.8 | DJ4: 13551 | DK4: =DJ4*$E4 -> 9485.7 | DM4: =DL4*$E4 -> 0 | DO4: =DN4*$E4 -> 0 | DQ4: =DP4*$E4 -> 0 | DS4: =DR4*$E4 -> 0 | DU4: =DT4*$E4 -> 0 | DW4: =DV4*$E4 -> 0 | DY4: =DX4*$E4 -> 0 | EA4: =DZ4*$E4 -> 0 | EC4: =EB4*$E4 -> 0 | EE4: =ED4*$E4 -> 0 | EF4: =SUM(DH4,DJ4,DL4,DN4,DP4,DR4,DT4,DV4,DX4,DZ4,EB4,ED4) -> 30375 | EG4: =SUM(DI4,DK4,DM4,DO4,DQ4,DS4,DU4,DW4,DY4,EA4,EC4,EE4) -> 21262.5
I5: =H5*$E5 -> 0 | K5: =J5*$E5 -> 0 | M5: =L5*$E5 -> 0 | O5: =N5*$E5 -> 0 | Q5: =P5*$E5 -> 0 | S5: =R5*$E5 -> 0 | U5: =T5*$E5 -> 0 | W5: =V5*$E5 -> 0 | Y5: =X5*$E5 -> 0 | AA5: =Z5*$E5 -> 0 | AC5: =AB5*$E5 -> 0 | AE5: =AD5*$E5 -> 0 | AF5: =(AD5+AB5+Z5+X5+V5+T5+R5+P5+N5+L5+J5+H5)/1 -> 0 | AG5: =AF5*$E5 -> 0 | AI5: =AH5*$E5 -> 0 | AK5: =AJ5*$E5 -> 0 | AM5: =AL5*$E5 -> 0 | AO5: =AN5*$E5 -> 0 | AQ5: =AP5*$E5 -> 0 | AS5: =AR5*$E5 -> 0 | AU5: =AT5*$E5 -> 0 | AW5: =AV5*$E5 -> 0 | AY5: =AX5*$E5 -> 0 | BA5: =AZ5*$E5 -> 0 | BC5: =BB5*$E5 -> 0 | BE5: =BD5*$E5 -> 0 | BF5: =(BD5+BB5+AZ5+AX5+AV5+AT5+AR5+AP5+AN5+AL5+AJ5+AH5)/1 -> 0 | BG5: =BF5*$E5 -> 0 | BI5: =BH5*$E5 -> 0 | BK5: =BJ5*$E5 -> 0 | BM5: =BL5*$E5 -> 0 | BO5: =BN5*$E5 -> 0 | BQ5: =BP5*$E5 -> 0 | BS5: =BR5*$E5 -> 0 | BU5: =BT5*$E5 -> 0 | BW5: =BV5*$E5 -> 0 | BY5: =BX5*$E5 -> 0 | CA5: =BZ5*$E5 -> 0 | CC5: =CB5*$E5 -> 0 | CE5: =CD5*$E5 -> 0 | CF5: =(CD5+CB5+BZ5+BX5+BV5+BT5+BR5+BP5+BN5+BL5+BJ5+BH5)/1 -> 0 | CG5: =CF5*$E5 -> 0 | CI5: =CH5*$E5 -> 0 | CK5: =CJ5*$E5 -> 0 | CM5: =CL5*$E5 -> 0 | CO5: =CN5*$E5 -> 0 | CQ5: =CP5*$E5 -> 0 | CS5: =CR5*$E5 -> 0 | CU5: =CT5*$E5 -> 0 | CW5: =CV5*$E5 -> 0 | CY5: =CX5*$E5 -> 0 | DA5: =CZ5*$E5 -> 0 | DC5: =DB5*$E5 -> 0 | DE5: =DD5*$E5 -> 0 | DF5: =SUM(CH5,CJ5,CL5,CN5,CP5,CR5,CT5,CV5,CX5,CZ5,DB5,DD5)/1 -> 0 | DG5: =DF5*$E5 -> 0
A6: 2 | B6: "Zay" Vodka (1 Liter) | C6: ‌ကော်ဘူး | D6: =RANK(DF6,$DF$4:$DF$147) -> 3 | E6: 1 | F6: 1 * 12 | G6: 1650 | I6: =H6*$E6 -> 0 | K6: =J6*$E6 -> 0 | L6: 4332 | M6: =L6*$E6 -> 4332 | N6: 564 | O6: =N6*$E6 -> 564 | P6: 312 | Q6: =P6*$E6 -> 312 | R6: 600 | S6: =R6*$E6 -> 600 | T6: 4020 | U6: =T6*$E6 -> 4020 | V6: 428 | W6: =V6*$E6 -> 428 | X6: 1452 | Y6: =X6*$E6 -> 1452 | Z6: 1464 | AA6: =Z6*$E6 -> 1464 | AB6: 3300 | AC6: =AB6*$E6 -> 3300 | AD6: 408 | AE6: =AD6*$E6 -> 408 | AF6: =(AD6+AB6+Z6+X6+V6+T6+R6+P6+N6+L6+J6+H6)/1 -> 16880 | AG6: =AF6*$E6 -> 16880 | AI6: =AH6*$E6 -> 0 | AK6: =AJ6*$E6 -> 0 | AL6: 60 | AM6: =AL6*$E6 -> 60 | AN6: 1152 | AO6: =AN6*$E6 -> 1152 | AP6: 1512 | AQ6: =AP6*$E6 -> 1512 | AR6: 1416 | AS6: =AR6*$E6 -> 1416 | AT6: 588 | AU6: =AT6*$E6 -> 588 | AW6: =AV6*$E6 -> 0 | AX6: 840 | AY6: =AX6*$E6 -> 840 | AZ6: 1152 | BA6: =AZ6*$E6 -> 1152 | BB6: 1608 | BC6: =BB6*$E6 -> 1608 | BE6: =BD6*$E6 -> 0 | BF6: =(BD6+BB6+AZ6+AX6+AV6+AT6+AR6+AP6+AN6+AL6+AJ6+AH6)/1 -> 8328 | BG6: =BF6*$E6 -> 8328 | BH6: 0 | BI6: =BH6*$E6 -> 0 | BJ6: 0 | BK6: =BJ6*$E6 -> 0 | BL6: 12 | BM6: =BL6*$E6 -> 12 | BN6: 0 | BO6: =BN6*$E6 -> 0 | BP6: 0 | BQ6: =BP6*$E6 -> 0 | BR6: 1152 | BS6: =BR6*$E6 -> 1152 | BT6: 0 | BU6: =BT6*$E6 -> 0 | BV6: 0 | BW6: =BV6*$E6 -> 0 | BX6: 0 | BY6: =BX6*$E6 -> 0 | CA6: =BZ6*$E6 -> 0 | CC6: =CB6*$E6 -> 0 | CE6: =CD6*$E6 -> 0 | CF6: =(CD6+CB6+BZ6+BX6+BV6+BT6+BR6+BP6+BN6+BL6+BJ6+BH6)/1 -> 1164 | CG6: =CF6*$E6 -> 1164 | CH6: 2040 | CI6: =CH6*$E6 -> 2040 | CJ6: 7200 | CK6: =CJ6*$E6 -> 7200 | CL6: 36 | CM6: =CL6*$E6 -> 36 | CO6: =CN6*$E6 -> 0 | CQ6: =CP6*$E6 -> 0 | CS6: =CR6*$E6 -> 0 | CT6: 656309 | CU6: =CT6*$E6 -> 656309 | CV6: 783152 | CW6: =CV6*$E6 -> 783152 | CX6: 767283 | CY6: =CX6*$E6 -> 767283 | CZ6: 794208 | DA6: =CZ6*$E6 -> 794208 | DB6: 759250 | DC6: =DB6*$E6 -> 759250 | DD6: 829714 | DE6: =DD6*$E6 -> 829714 | DF6: =SUM(CH6,CJ6,CL6,CN6,CP6,CR6,CT6,CV6,CX6,CZ6,DB6,DD6)/1 -> 4599192 | DG6: =DF6*$E6 -> 4599192 | DH6: 808786 | DI6: =DH6*$E6 -> 808786 | DJ6: 748440 | DK6: =DJ6*$E6 -> 748440 | DM6: =DL6*$E6 -> 0 | DO6: =DN6*$E6 -> 0 | DQ6: =DP6*$E6 -> 0 | DS6: =DR6*$E6 -> 0 | DU6: =DT6*$E6 -> 0 | DW6: =DV6*$E6 -> 0 | DY6: =DX6*$E6 -> 0 | EA6: =DZ6*$E6 -> 0 | EC6: =EB6*$E6 -> 0 | EE6: =ED6*$E6 -> 0 | EF6: =SUM(DH6,DJ6,DL6,DN6,DP6,DR6,DT6,DV6,DX6,DZ6,EB6,ED6) -> 1557226 | EG6: =SUM(DI6,DK6,DM6,DO6,DQ6,DS6,DU6,DW6,DY6,EA6,EC6,EE6) -> 1557226
A7: 3 | B7: "Zay" (1 Liter) | C7: ‌ကော်ဘူး | D7: =RANK(DF7,$DF$4:$DF$147) -> 2 | E7: 1 | F7: 1 * 12 | G7: 1650 | H7: 473472 | I7: =H7*$E7 -> 473472 | J7: 450804 | K7: =J7*$E7 -> 450804 | L7: 626052 | M7: =L7*$E7 -> 626052 | N7: 511680 | O7: =N7*$E7 -> 511680 | P7: 550272 | Q7: =P7*$E7 -> 550272 | R7: 592536 | S7: =R7*$E7 -> 592536 | T7: 565716 | U7: =T7*$E7 -> 565716 | V7: 765972 | W7: =V7*$E7 -> 765972 | X7: 498072 | Y7: =X7*$E7 -> 498072 | Z7: 500448 | AA7: =Z7*$E7 -> 500448 | AB7: 500652 | AC7: =AB7*$E7 -> 500652 | AD7: 592176 | AE7: =AD7*$E7 -> 592176 | AF7: =(AD7+AB7+Z7+X7+V7+T7+R7+P7+N7+L7+J7+H7)/1 -> 6627852 | AG7: =AF7*$E7 -> 6627852 | AH7: 703416 | AI7: =AH7*$E7 -> 703416 | AJ7: 510672 | AK7: =AJ7*$E7 -> 510672 | AL7: 684900 | AM7: =AL7*$E7 -> 684900 | AN7: 604764 | AO7: =AN7*$E7 -> 604764 | AP7: 644832 | AQ7: =AP7*$E7 -> 644832 | AR7: 663312 | AS7: =AR7*$E7 -> 663312 | AT7: 715536 | AU7: =AT7*$E7 -> 715536 | AV7: 771876 | AW7: =AV7*$E7 -> 771876 | AX7: 503604 | AY7: =AX7*$E7 -> 503604 | AZ7: 612828 | BA7: =AZ7*$E7 -> 612828 | BB7: 631164 | BC7: =BB7*$E7 -> 631164 | BD7: 699420 | BE7: =BD7*$E7 -> 699420 | BF7: =(BD7+BB7+AZ7+AX7+AV7+AT7+AR7+AP7+AN7+AL7+AJ7+AH7)/1 -> 7746324 | BG7: =BF7*$E7 -> 7746324 | BH7: 763500 | BI7: =BH7*$E7 -> 763500 | BJ7: 625956 | BK7: =BJ7*$E7 -> 625956 | BL7: 730020 | BM7: =BL7*$E7 -> 730020 | BN7: 739728 | BO7: =BN7*$E7 -> 739728 | BP7: 736560 | BQ7: =BP7*$E7 -> 736560 | BR7: 845592 | BS7: =BR7*$E7 -> 845592 | BT7: 811500 | BU7: =BT7*$E7 -> 811500 | BV7: 706632 | BW7: =BV7*$E7 -> 706632 | BX7: 670944 | BY7: =BX7*$E7 -> 670944 | BZ7: 814836 | CA7: =BZ7*$E7 -> 814836 | CB7: 725722 | CC7: =CB7*$E7 -> 725722 | CD7: 687720 | CE7: =CD7*$E7 -> 687720 | CF7: =(CD7+CB7+BZ7+BX7+BV7+BT7+BR7+BP7+BN7+BL7+BJ7+BH7)/1 -> 8858710 | CG7: =CF7*$E7 -> 8858710 | CH7: 693995 | CI7: =CH7*$E7 -> 693995 | CJ7: 680976 | CK7: =CJ7*$E7 -> 680976 | CL7: 1104079 | CM7: =CL7*$E7 -> 1104079 | CN7: 557195 | CO7: =CN7*$E7 -> 557195 | CP7: 766488 | CQ7: =CP7*$E7 -> 766488 | CR7: 790289 | CS7: =CR7*$E7 -> 790289 | CT7: 113229 | CU7: =CT7*$E7 -> 113229 | CW7: =CV7*$E7 -> 0 | CY7: =CX7*$E7 -> 0 | DA7: =CZ7*$E7 -> 0 | DC7: =DB7*$E7 -> 0 | DE7: =DD7*$E7 -> 0 | DF7: =SUM(CH7,CJ7,CL7,CN7,CP7,CR7,CT7,CV7,CX7,CZ7,DB7,DD7)/1 -> 4706251 | DG7: =DF7*$E7 -> 4706251 | DI7: =DH7*$E7 -> 0 | DK7: 0 | DM7: =DL7*$E7 -> 0 | DO7: =DN7*$E7 -> 0 | DQ7: =DP7*$E7 -> 0 | DS7: =DR7*$E7 -> 0 | DU7: =DT7*$E7 -> 0 | DW7: =DV7*$E7 -> 0 | DY7: =DX7*$E7 -> 0 | EA7: =DZ7*$E7 -> 0 | EC7: =EB7*$E7 -> 0 | EE7: =ED7*$E7 -> 0 | EF7: =SUM(DH7,DJ7,DL7,DN7,DP7,DR7,DT7,DV7,DX7,DZ7,EB7,ED7) -> 0 | EG7: =SUM(DI7,DK7,DM7,DO7,DQ7,DS7,DU7,DW7,DY7,EA7,EC7,EE7) -> 0
A8: 4 | B8: "Zay" (0.6 Liter) | C8: ‌ကော်ဘူး | D8: =RANK(DF8,$DF$4:$DF$147) -> 8 | E8: 0.6 | F8: 1 * 12 | G8: 1130 | H8: 52464 | I8: =H8*$E8 -> 31478.4 | J8: 41544 | K8: =J8*$E8 -> 24926.4 | L8: 61080 | M8: =L8*$E8 -> 36648 | N8: 44568 | O8: =N8*$E8 -> 26740.8 | P8: 38844 | Q8: =P8*$E8 -> 23306.4 | R8: 42405 | S8: =R8*$E8 -> 25443 | T8: 38460 | U8: =T8*$E8 -> 23076 | V8: 46740 | W8: =V8*$E8 -> 28044 | X8: 36324 | Y8: =X8*$E8 -> 21794.4 | Z8: 38988 | AA8: =Z8*$E8 -> 23392.8 | AB8: 26892 | AC8: =AB8*$E8 -> 16135.2 | AD8: 30576 | AE8: =AD8*$E8 -> 18345.6 | AF8: =(AD8+AB8+Z8+X8+V8+T8+R8+P8+N8+L8+J8+H8)/1 -> 498885 | AG8: =AF8*$E8 -> 299331 | AH8: 34128 | AI8: =AH8*$E8 -> 20476.8 | AJ8: 26004 | AK8: =AJ8*$E8 -> 15602.4 | AL8: 34092 | AM8: =AL8*$E8 -> 20455.2 | AN8: 20184 | AO8: =AN8*$E8 -> 12110.4 | AP8: 42588 | AQ8: =AP8*$E8 -> 25552.8 | AR8: 42192 | AS8: =AR8*$E8 -> 25315.2 | AT8: 58176 | AU8: =AT8*$E8 -> 34905.6 | AV8: 50544 | AW8: =AV8*$E8 -> 30326.4 | AX8: 38592 | AY8: =AX8*$E8 -> 23155.2 | AZ8: 44376 | BA8: =AZ8*$E8 -> 26625.6 | BB8: 41700 | BC8: =BB8*$E8 -> 25020 | BD8: 48672 | BE8: =BD8*$E8 -> 29203.2 | BF8: =(BD8+BB8+AZ8+AX8+AV8+AT8+AR8+AP8+AN8+AL8+AJ8+AH8)/1 -> 481248 | BG8: =BF8*$E8 -> 288748.8 | BH8: 49908 | BI8: =BH8*$E8 -> 29944.8 | BJ8: 45801 | BK8: =BJ8*$E8 -> 27480.6 | BL8: 47844 | BM8: =BL8*$E8 -> 28706.4 | BN8: 50160 | BO8: =BN8*$E8 -> 30096 | BP8: 47652 | BQ8: =BP8*$E8 -> 28591.2 | BR8: 60372 | BS8: =BR8*$E8 -> 36223.2 | BT8: 54036 | BU8: =BT8*$E8 -> 32421.6 | BV8: 30299 | BW8: =BV8*$E8 -> 18179.4 | BX8: 42360 | BY8: =BX8*$E8 -> 25416 | BZ8: 47242 | CA8: =BZ8*$E8 -> 28345.2 | CB8: 51708 | CC8: =CB8*$E8 -> 31024.8 | CD8: 42680 | CE8: =CD8*$E8 -> 25608 | CF8: =(CD8+CB8+BZ8+BX8+BV8+BT8+BR8+BP8+BN8+BL8+BJ8+BH8)/1 -> 570062 | CG8: =CF8*$E8 -> 342037.2 | CH8: 44616 | CI8: =CH8*$E8 -> 26769.6 | CJ8: 44988 | CK8: =CJ8*$E8 -> 26992.8 | CL8: 72693 | CM8: =CL8*$E8 -> 43615.8 | CN8: 39864 | CO8: =CN8*$E8 -> 23918.4 | CP8: 47964 | CQ8: =CP8*$E8 -> 28778.4 | CR8: 57216 | CS8: =CR8*$E8 -> 34329.6 | CT8: 54312 | CU8: =CT8*$E8 -> 32587.2 | CV8: 53556 | CW8: =CV8*$E8 -> 32133.6 | CX8: 57468 | CY8: =CX8*$E8 -> 34480.8 | CZ8: 56448 | DA8: =CZ8*$E8 -> 33868.8 | DB8: 54108 | DC8: =DB8*$E8 -> 32464.8 | DD8: 52391 | DE8: =DD8*$E8 -> 31434.6 | DF8: =SUM(CH8,CJ8,CL8,CN8,CP8,CR8,CT8,CV8,CX8,CZ8,DB8,DD8)/1 -> 635624 | DG8: =DF8*$E8 -> 381374.4 | DH8: 53484 | DI8: =DH8*$E8 -> 32090.4 | DJ8: 48720 | DK8: =DJ8*$E8 -> 29232 | DM8: =DL8*$E8 -> 0 | DO8: =DN8*$E8 -> 0 | DQ8: =DP8*$E8 -> 0 | DS8: =DR8*$E8 -> 0 | DU8: =DT8*$E8 -> 0 | DW8: =DV8*$E8 -> 0 | DY8: =DX8*$E8 -> 0 | EA8: =DZ8*$E8 -> 0 | EC8: =EB8*$E8 -> 0 | EE8: =ED8*$E8 -> 0 | EF8: =SUM(DH8,DJ8,DL8,DN8,DP8,DR8,DT8,DV8,DX8,DZ8,EB8,ED8) -> 102204 | EG8: =SUM(DI8,DK8,DM8,DO8,DQ8,DS8,DU8,DW8,DY8,EA8,EC8,EE8) -> 61322.4
A9: 5 | B9: "Zay" (0.35 Liter) | C9: ‌ကော်ဘူး | D9: =RANK(DF9,$DF$4:$DF$147) -> 4 | E9: 0.35 | F9: 1 * 40 | G9: 760 | H9: 150760 | I9: =H9*$E9 -> 52766 | J9: 308440 | K9: =J9*$E9 -> 107954 | L9: 487360 | M9: =L9*$E9 -> 170576 | N9: 316840 | O9: =N9*$E9 -> 110894 | P9: 334160 | Q9: =P9*$E9 -> 116956 | R9: 376440 | S9: =R9*$E9 -> 131754 | T9: 367720 | U9: =T9*$E9 -> 128702 | V9: 491400 | W9: =V9*$E9 -> 171990 | X9: 339120 | Y9: =X9*$E9 -> 118692 | Z9: 353920 | AA9: =Z9*$E9 -> 123872 | AB9: 363320 | AC9: =AB9*$E9 -> 127162 | AD9: 384200 | AE9: =AD9*$E9 -> 134470 | AF9: =(AD9+AB9+Z9+X9+V9+T9+R9+P9+N9+L9+J9+H9)/1 -> 4273680 | AG9: =AF9*$E9 -> 1495788 | AH9: 451920 | AI9: =AH9*$E9 -> 158172 | AJ9: 331680 | AK9: =AJ9*$E9 -> 116088 | AL9: 444400 | AM9: =AL9*$E9 -> 155540 | AN9: 342440 | AO9: =AN9*$E9 -> 119854 | AP9: 272560 | AQ9: =AP9*$E9 -> 95396 | AR9: 179680 | AS9: =AR9*$E9 -> 62888 | AT9: 310960 | AU9: =AT9*$E9 -> 108836 | AV9: 373600 | AW9: =AV9*$E9 -> 130760 | AX9: 274800 | AY9: =AX9*$E9 -> 96180 | AZ9: 270280 | BA9: =AZ9*$E9 -> 94598 | BB9: 262400 | BC9: =BB9*$E9 -> 91840 | BD9: 282960 | BE9: =BD9*$E9 -> 99036 | BF9: =(BD9+BB9+AZ9+AX9+AV9+AT9+AR9+AP9+AN9+AL9+AJ9+AH9)/1 -> 3797680 | BG9: =BF9*$E9 -> 1329188 | BH9: 289690 | BI9: =BH9*$E9 -> 101391.5 | BJ9: 258000 | BK9: =BJ9*$E9 -> 90300 | BL9: 277000 | BM9: =BL9*$E9 -> 96950 | BN9: 256600 | BO9: =BN9*$E9 -> 89810 | BP9: 282700 | BQ9: =BP9*$E9 -> 98945 | BR9: 285700 | BS9: =BR9*$E9 -> 99995 | BT9: 296440 | BU9: =BT9*$E9 -> 103754 | BV9: 301520 | BW9: =BV9*$E9 -> 105532 | BX9: 274960 | BY9: =BX9*$E9 -> 96236 | BZ9: 335760 | CA9: =BZ9*$E9 -> 117516 | CB9: 316080 | CC9: =CB9*$E9 -> 110628 | CD9: 293036 | CE9: =CD9*$E9 -> 102562.6 | CF9: =(CD9+CB9+BZ9+BX9+BV9+BT9+BR9+BP9+BN9+BL9+BJ9+BH9)/1 -> 3467486 | CG9: =CF9*$E9 -> 1213620.1 | CH9: 252553 | CI9: =CH9*$E9 -> 88393.55 | CJ9: 258745 | CK9: =CJ9*$E9 -> 90560.75 | CL9: 397880 | CM9: =CL9*$E9 -> 139258 | CN9: 205800 | CO9: =CN9*$E9 -> 72030 | CP9: 253440 | CQ9: =CP9*$E9 -> 88704 | CR9: 268480 | CS9: =CR9*$E9 -> 93968 | CT9: 283028 | CU9: =CT9*$E9 -> 99059.8 | CV9: 290121 | CW9: =CV9*$E9 -> 101542.35 | CX9: 288390 | CY9: =CX9*$E9 -> 100936.5 | CZ9: 297360 | DA9: =CZ9*$E9 -> 104076 | DB9: 278720 | DC9: =DB9*$E9 -> 97552 | DD9: 307120 | DE9: =DD9*$E9 -> 107492 | DF9: =SUM(CH9,CJ9,CL9,CN9,CP9,CR9,CT9,CV9,CX9,CZ9,DB9,DD9)/1 -> 3381637 | DG9: =DF9*$E9 -> 1183572.9 | DH9: 295720 | DI9: =DH9*$E9 -> 103502 | DJ9: 271320 | DK9: =DJ9*$E9 -> 94962 | DM9: =DL9*$E9 -> 0 | DO9: =DN9*$E9 -> 0 | DQ9: =DP9*$E9 -> 0 | DS9: =DR9*$E9 -> 0 | DU9: =DT9*$E9 -> 0 | DW9: =DV9*$E9 -> 0 | DY9: =DX9*$E9 -> 0 | EA9: =DZ9*$E9 -> 0 | EC9: =EB9*$E9 -> 0 | EE9: =ED9*$E9 -> 0 | EF9: =SUM(DH9,DJ9,DL9,DN9,DP9,DR9,DT9,DV9,DX9,DZ9,EB9,ED9) -> 567040 | EG9: =SUM(DI9,DK9,DM9,DO9,DQ9,DS9,DU9,DW9,DY9,EA9,EC9,EE9) -> 198464
A10: 6 | B10: "Zay" Vodka | C10: ပုလင်း | D10: =RANK(DF10,$DF$4:$DF$147) -> 31 | E10: 0.7 | F10: 1 * 24 | G10: 1850 | I10: =H10*$E10 -> 0 | K10: =J10*$E10 -> 0 | M10: =L10*$E10 -> 0 | O10: =N10*$E10 -> 0 | Q10: =P10*$E10 -> 0 | S10: =R10*$E10 -> 0 | U10: =T10*$E10 -> 0 | W10: =V10*$E10 -> 0 | Y10: =X10*$E10 -> 0 | AA10: =Z10*$E10 -> 0 | AC10: =AB10*$E10 -> 0 | AE10: =AD10*$E10 -> 0 | AF10: =(AD10+AB10+Z10+X10+V10+T10+R10+P10+N10+L10+J10+H10)/1 -> 0 | AG10: =AF10*$E10 -> 0 | AI10: =AH10*$E10 -> 0 | AJ10: 24 | AK10: =AJ10*$E10 -> 16.8 | AM10: =AL10*$E10 -> 0 | AO10: =AN10*$E10 -> 0 | AQ10: =AP10*$E10 -> 0 | AS10: =AR10*$E10 -> 0 | AU10: =AT10*$E10 -> 0 | AW10: =AV10*$E10 -> 0 | AY10: =AX10*$E10 -> 0 | BA10: =AZ10*$E10 -> 0 | BC10: =BB10*$E10 -> 0 | BE10: =BD10*$E10 -> 0 | BF10: =(BD10+BB10+AZ10+AX10+AV10+AT10+AR10+AP10+AN10+AL10+AJ10+AH10)/1 -> 24 | BG10: =BF10*$E10 -> 16.8 | BI10: =BH10*$E10 -> 0 | BK10: =BJ10*$E10 -> 0 | BM10: =BL10*$E10 -> 0 | BO10: =BN10*$E10 -> 0 | BQ10: =BP10*$E10 -> 0 | BS10: =BR10*$E10 -> 0 | BU10: =BT10*$E10 -> 0 | BW10: =BV10*$E10 -> 0 | BY10: =BX10*$E10 -> 0 | CA10: =BZ10*$E10 -> 0 | CC10: =CB10*$E10 -> 0 | CE10: =CD10*$E10 -> 0 | CF10: =(CD10+CB10+BZ10+BX10+BV10+BT10+BR10+BP10+BN10+BL10+BJ10+BH10)/1 -> 0 | CG10: =CF10*$E10 -> 0 | CI10: =CH10*$E10 -> 0 | CK10: =CJ10*$E10 -> 0 | CM10: =CL10*$E10 -> 0 | CO10: =CN10*$E10 -> 0 | CQ10: =CP10*$E10 -> 0 | CS10: =CR10*$E10 -> 0 | CU10: =CT10*$E10 -> 0 | CW10: =CV10*$E10 -> 0 | CY10: =CX10*$E10 -> 0 | DA10: =CZ10*$E10 -> 0 | DC10: =DB10*$E10 -> 0 | DE10: =DD10*$E10 -> 0 | DF10: =SUM(CH10,CJ10,CL10,CN10,CP10,CR10,CT10,CV10,CX10,CZ10,DB10,DD10)/1 -> 0 | DG10: =DF10*$E10 -> 0 | DI10: =DH10*$E10 -> 0 | DK10: =DJ10*$E10 -> 0 | DM10: =DL10*$E10 -> 0 | DO10: =DN10*$E10 -> 0 | DQ10: =DP10*$E10 -> 0 | DS10: =DR10*$E10 -> 0 | DU10: =DT10*$E10 -> 0 | DW10: =DV10*$E10 -> 0 | DY10: =DX10*$E10 -> 0 | EA10: =DZ10*$E10 -> 0 | EC10: =EB10*$E10 -> 0 | EE10: =ED10*$E10 -> 0 | EF10: =SUM(DH10,DJ10,DL10,DN10,DP10,DR10,DT10,DV10,DX10,DZ10,EB10,ED10) -> 0 | EG10: =SUM(DI10,DK10,DM10,DO10,DQ10,DS10,DU10,DW10,DY10,EA10,EC10,EE10) -> 0
A11: 7 | B11: "Zay" Vodka - 640ml | C11: ပုလင်း | D11: =RANK(AH11,$AH$4:$AH$147) -> 7 | E11: 0.64 | F11: 1 * 24 | G11: 1400 | H11: 45600 | I11: =H11*$E11 -> 29184 | J11: =43632+2400 -> 46032 | K11: =J11*$E11 -> 29460.48 | L11: 91560 | M11: =L11*$E11 -> 58598.4 | N11: 52200 | O11: =N11*$E11 -> 33408 | P11: 49440 | Q11: =P11*$E11 -> 31641.6 | R11: 50648 | S11: =R11*$E11 -> 32414.72 | T11: 45384 | U11: =T11*$E11 -> 29045.76 | V11: 43704 | W11: =V11*$E11 -> 27970.56 | X11: 31920 | Y11: =X11*$E11 -> 20428.8 | Z11: 39912 | AA11: =Z11*$E11 -> 25543.68 | AB11: 28512 | AC11: =AB11*$E11 -> 18247.68 | AD11: 53808 | AE11: =AD11*$E11 -> 34437.12 | AF11: =(AD11+AB11+Z11+X11+V11+T11+R11+P11+N11+L11+J11+H11)/1 -> 578720 | AG11: =AF11*$E11 -> 370380.8 | AH11: 51288 | AI11: =AH11*$E11 -> 32824.32 | AJ11: 27816 | AK11: =AJ11*$E11 -> 17802.24 | AL11: 53160 | AM11: =AL11*$E11 -> 34022.4 | AN11: 38184 | AO11: =AN11*$E11 -> 24437.76 | AP11: 46512 | AQ11: =AP11*$E11 -> 29767.68 | AR11: 35304 | AS11: =AR11*$E11 -> 22594.56 | AT11: 29616 | AU11: =AT11*$E11 -> 18954.24 | AV11: 29712 | AW11: =AV11*$E11 -> 19015.68 | AX11: 22632 | AY11: =AX11*$E11 -> 14484.48 | AZ11: 31008 | BA11: =AZ11*$E11 -> 19845.12 | BB11: 30024 | BC11: =BB11*$E11 -> 19215.36 | BD11: 30120 | BE11: =BD11*$E11 -> 19276.8 | BF11: =(BD11+BB11+AZ11+AX11+AV11+AT11+AR11+AP11+AN11+AL11+AJ11+AH11)/1 -> 425376 | BG11: =BF11*$E11 -> 272240.64 | BH11: 40752 | BI11: =BH11*$E11 -> 26081.28 | BJ11: 24000 | BK11: =BJ11*$E11 -> 15360 | BL11: 29232 | BM11: =BL11*$E11 -> 18708.48 | BN11: 34080 | BO11: =BN11*$E11 -> 21811.2 | BP11: 31704 | BQ11: =BP11*$E11 -> 20290.56 | BR11: 24672 | BS11: =BR11*$E11 -> 15790.08 | BT11: 26640 | BU11: =BT11*$E11 -> 17049.6 | BV11: 26928 | BW11: =BV11*$E11 -> 17233.92 | BX11: 12312 | BY11: =BX11*$E11 -> 7879.68 | BZ11: 16080 | CA11: =BZ11*$E11 -> 10291.2 | CB11: 15720 | CC11: =CB11*$E11 -> 10060.8 | CD11: 26880 | CE11: =CD11*$E11 -> 17203.2 | CF11: =(CD11+CB11+BZ11+BX11+BV11+BT11+BR11+BP11+BN11+BL11+BJ11+BH11)/1 -> 309000 | CG11: =CF11*$E11 -> 197760 | CH11: 28320 | CI11: =CH11*$E11 -> 18124.8 | CJ11: 18720 | CK11: =CJ11*$E11 -> 11980.8 | CL11: 33984 | CM11: =CL11*$E11 -> 21749.76 | CN11: 37440 | CO11: =CN11*$E11 -> 23961.6 | CP11: 20520 | CQ11: =CP11*$E11 -> 13132.8 | CR11: 27120 | CS11: =CR11*$E11 -> 17356.8 | CT11: 19800 | CU11: =CT11*$E11 -> 12672 | CV11: 17160 | CW11: =CV11*$E11 -> 10982.4 | CX11: 17520 | CY11: =CX11*$E11 -> 11212.8 | CZ11: 20040 | DA11: =CZ11*$E11 -> 12825.6 | DB11: 31800 | DC11: =DB11*$E11 -> 20352 | DD11: 17520 | DE11: =DD11*$E11 -> 11212.8 | DF11: =SUM(CH11,CJ11,CL11,CN11,CP11,CR11,CT11,CV11,CX11,CZ11,DB11,DD11)/1 -> 289944 | DG11: =DF11*$E11 -> 185564.16 | DH11: 24960 | DI11: =DH11*$E11 -> 15974.4 | DJ11: 12360 | DK11: =DJ11*$E11 -> 7910.4 | DM11: =DL11*$E11 -> 0 | DO11: =DN11*$E11 -> 0 | DQ11: =DP11*$E11 -> 0 | DS11: =DR11*$E11 -> 0 | DU11: =DT11*$E11 -> 0 | DW11: =DV11*$E11 -> 0 | DY11: =DX11*$E11 -> 0 | EA11: =DZ11*$E11 -> 0 | EC11: =EB11*$E11 -> 0 | EE11: =ED11*$E11 -> 0 | EF11: =SUM(DH11,DJ11,DL11,DN11,DP11,DR11,DT11,DV11,DX11,DZ11,EB11,ED11) -> 37320 | EG11: =SUM(DI11,DK11,DM11,DO11,DQ11,DS11,DU11,DW11,DY11,EA11,EC11,EE11) -> 23884.8
A12: 8 | B12: "Zay" Vodka - 640ml | C12: ပုလင်း | D12: =RANK(AH12,$AH$4:$AH$147) -> 1 | E12: 0.64 | F12: 1 * 14 | G12: 1400 | H12: =1607217+5280 -> 1612497 | I12: =H12*$E12 -> 1031998.1 | J12: 1487206 | K12: =J12*$E12 -> 951811.84 | L12: 2198434 | M12: =L12*$E12 -> 1406997.8 | N12: 1666056 | O12: =N12*$E12 -> 1066275.8 | P12: 1496012 | Q12: =P12*$E12 -> 957447.68 | R12: =1515416+560 -> 1515976 | S12: =R12*$E12 -> 970224.64 | T12: =1423576+840 -> 1424416 | U12: =T12*$E12 -> 911626.24 | V12: 1674932 | W12: =V12*$E12 -> 1071956.5 | X12: 1158486 | Y12: =X12*$E12 -> 741431.04 | Z12: 1230558 | AA12: =Z12*$E12 -> 787557.12 | AB12: =1325646+6 -> 1325652 | AC12: =AB12*$E12 -> 848417.28 | AD12: 1410990 | AE12: =AD12*$E12 -> 903033.6 | AF12: =(AD12+AB12+Z12+X12+V12+T12+R12+P12+N12+L12+J12+H12)/1 -> 18201215 | AG12: =AF12*$E12 -> 11648778 | AH12: 1399258 | AI12: =AH12*$E12 -> 895525.12 | AJ12: 1181866 | AK12: =AJ12*$E12 -> 756394.24 | AL12: 1568917 | AM12: =AL12*$E12 -> 1004106.9 | AN12: 1249780 | AO12: =AN12*$E12 -> 799859.2 | AP12: 1141630 | AQ12: =AP12*$E12 -> 730643.2 | AR12: 1176224 | AS12: =AR12*$E12 -> 752783.36 | AT12: 1274322 | AU12: =AT12*$E12 -> 815566.08 | AV12: 1294006 | AW12: =AV12*$E12 -> 828163.84 | AX12: 890078 | AY12: =AX12*$E12 -> 569649.92 | AZ12: 999712 | BA12: =AZ12*$E12 -> 639815.68 | BB12: 1046766 | BC12: =BB12*$E12 -> 669930.24 | BD12: 1107288 | BE12: =BD12*$E12 -> 708664.32 | BF12: =(BD12+BB12+AZ12+AX12+AV12+AT12+AR12+AP12+AN12+AL12+AJ12+AH12)/1 -> 14329847 | BG12: =BF12*$E12 -> 9171102.1 | BH12: 1062432 | BI12: =BH12*$E12 -> 679956.48 | BJ12: 888174 | BK12: =BJ12*$E12 -> 568431.36 | BL12: 985152 | BM12: =BL12*$E12 -> 630497.28 | BN12: 966210 | BO12: =BN12*$E12 -> 618374.4 | BP12: 1008938 | BQ12: =BP12*$E12 -> 645720.32 | BR12: 1108953 | BS12: =BR12*$E12 -> 709729.92 | BT12: 925364 | BU12: =BT12*$E12 -> 592232.96 | BV12: 766892 | BW12: =BV12*$E12 -> 490810.88 | BX12: 730395 | BY12: =BX12*$E12 -> 467452.8 | BZ12: 834624 | CA12: =BZ12*$E12 -> 534159.36 | CB12: 812171 | CC12: =CB12*$E12 -> 519789.44 | CD12: 764567 | CE12: =CD12*$E12 -> 489322.88 | CF12: =(CD12+CB12+BZ12+BX12+BV12+BT12+BR12+BP12+BN12+BL12+BJ12+BH12)/1 -> 10853872 | CG12: =CF12*$E12 -> 6946478.1 | CH12: 694078 | CI12: =CH12*$E12 -> 444209.92 | CJ12: 743873 | CK12: =CJ12*$E12 -> 476078.72 | CL12: 967690 | CM12: =CL12*$E12 -> 619321.6 | CN12: 599298 | CO12: =CN12*$E12 -> 383550.72 | CP12: 696682 | CQ12: =CP12*$E12 -> 445876.48 | CR12: 698141 | CS12: =CR12*$E12 -> 446810.24 | CT12: 682290 | CU12: =CT12*$E12 -> 436665.6 | CV12: 655446 | CW12: =CV12*$E12 -> 419485.44 | CX12: 579448 | CY12: =CX12*$E12 -> 370846.72 | CZ12: 606088 | DA12: =CZ12*$E12 -> 387896.32 | DB12: 571213 | DC12: =DB12*$E12 -> 365576.32 | DD12: 588305 | DE12: =DD12*$E12 -> 376515.2 | DF12: =SUM(CH12,CJ12,CL12,CN12,CP12,CR12,CT12,CV12,CX12,CZ12,DB12,DD12)/1 -> 8082552 | DG12: =DF12*$E12 -> 5172833.3 | DH12: 557228 | DI12: =DH12*$E12 -> 356625.92 | DJ12: 502194 | DK12: =DJ12*$E12 -> 321404.16 | DM12: =DL12*$E12 -> 0 | DO12: =DN12*$E12 -> 0 | DQ12: =DP12*$E12 -> 0 | DS12: =DR12*$E12 -> 0 | DU12: =DT12*$E12 -> 0 | DW12: =DV12*$E12 -> 0 | DY12: =DX12*$E12 -> 0 | EA12: =DZ12*$E12 -> 0 | EC12: =EB12*$E12 -> 0 | EE12: =ED12*$E12 -> 0 | EF12: =SUM(DH12,DJ12,DL12,DN12,DP12,DR12,DT12,DV12,DX12,DZ12,EB12,ED12) -> 1059422 | EG12: =SUM(DI12,DK12,DM12,DO12,DQ12,DS12,DU12,DW12,DY12,EA12,EC12,EE12) -> 678030.08
A13: 9 | B13: "Zay" Vodka - 640ml | C13: ပုလင်း | D13: =RANK(AH13,$AH$4:$AH$147) -> #N/A | E13: 0.64 | F13: 1 * 12 | G13: 1250 | I13: =H13*$E13 -> 0 | K13: =J13*$E13 -> 0 | M13: =L13*$E13 -> 0 | O13: =N13*$E13 -> 0 | Q13: =P13*$E13 -> 0 | S13: =R13*$E13 -> 0 | U13: =T13*$E13 -> 0 | W13: =V13*$E13 -> 0 | Y13: =X13*$E13 -> 0 | AA13: =Z13*$E13 -> 0 | AC13: =AB13*$E13 -> 0 | AE13: =AD13*$E13 -> 0 | AF13: =(AD13+AB13+Z13+X13+V13+T13+R13+P13+N13+L13+J13+H13)/1 -> 0 | AG13: =AF13*$E13 -> 0 | AI13: =AH13*$E13 -> 0 | AK13: =AJ13*$E13 -> 0 | AM13: =AL13*$E13 -> 0 | AO13: =AN13*$E13 -> 0 | AQ13: =AP13*$E13 -> 0 | AS13: =AR13*$E13 -> 0 | AU13: =AT13*$E13 -> 0 | AV13: 3216 | AW13: =AV13*$E13 -> 2058.24 | AY13: =AX13*$E13 -> 0 | AZ13: 1608 | BA13: =AZ13*$E13 -> 1029.12 | BB13: 24 | BC13: =BB13*$E13 -> 15.36 | BD13: 720 | BE13: =BD13*$E13 -> 460.8 | BF13: =(BD13+BB13+AZ13+AX13+AV13+AT13+AR13+AP13+AN13+AL13+AJ13+AH13)/1 -> 5568 | BG13: =BF13*$E13 -> 3563.52 | BH13: 1440 | BI13: =BH13*$E13 -> 921.6 | BJ13: 720 | BK13: =BJ13*$E13 -> 460.8 | BL13: 0 | BM13: =BL13*$E13 -> 0 | BN13: 720 | BO13: =BN13*$E13 -> 460.8 | BP13: 5664 | BQ13: =BP13*$E13 -> 3624.96 | BR13: 708 | BS13: =BR13*$E13 -> 453.12 | BT13: 708 | BU13: =BT13*$E13 -> 453.12 | BV13: 2124 | BW13: =BV13*$E13 -> 1359.36 | BX13: 708 | BY13: =BX13*$E13 -> 453.12 | BZ13: 696 | CA13: =BZ13*$E13 -> 445.44 | CB13: 1158 | CC13: =CB13*$E13 -> 741.12 | CD13: 2496 | CE13: =CD13*$E13 -> 1597.44 | CF13: =(CD13+CB13+BZ13+BX13+BV13+BT13+BR13+BP13+BN13+BL13+BJ13+BH13)/1 -> 17142 | CG13: =CF13*$E13 -> 10970.88 | CI13: =CH13*$E13 -> 0 | CK13: =CJ13*$E13 -> 0 | CL13: 1188 | CM13: =CL13*$E13 -> 760.32 | CN13: 1247 | CO13: =CN13*$E13 -> 798.08 | CP13: 1560 | CQ13: =CP13*$E13 -> 998.4 | CR13: 900 | CS13: =CR13*$E13 -> 576 | CT13: 1824 | CU13: =CT13*$E13 -> 1167.36 | CV13: 1536 | CW13: =CV13*$E13 -> 983.04 | CX13: 1428 | CY13: =CX13*$E13 -> 913.92 | CZ13: 1704 | DA13: =CZ13*$E13 -> 1090.56 | DB13: 1152 | DC13: =DB13*$E13 -> 737.28 | DD13: 1452 | DE13: =DD13*$E13 -> 929.28 | DF13: =SUM(CH13,CJ13,CL13,CN13,CP13,CR13,CT13,CV13,CX13,CZ13,DB13,DD13)/1 -> 13991 | DG13: =DF13*$E13 -> 8954.24 | DH13: 1308 | DI13: =DH13*$E13 -> 837.12 | DJ13: 1368 | DK13: =DJ13*$E13 -> 875.52 | DM13: =DL13*$E13 -> 0 | DO13: =DN13*$E13 -> 0 | DQ13: =DP13*$E13 -> 0 | DS13: =DR13*$E13 -> 0 | DU13: =DT13*$E13 -> 0 | DW13: =DV13*$E13 -> 0 | DY13: =DX13*$E13 -> 0 | EA13: =DZ13*$E13 -> 0 | EC13: =EB13*$E13 -> 0 | EE13: =ED13*$E13 -> 0 | EF13: =SUM(DH13,DJ13,DL13,DN13,DP13,DR13,DT13,DV13,DX13,DZ13,EB13,ED13) -> 2676 | EG13: =SUM(DI13,DK13,DM13,DO13,DQ13,DS13,DU13,DW13,DY13,EA13,EC13,EE13) -> 1712.64
A14: 10 | B14: "Zay" - 640ml | C14: ပုလင်း | D14: =RANK(AH14,$AH$4:$AH$147) -> #N/A | E14: 0.64 | F14: 1 * 14 | I14: =H14*$E14 -> 0 | K14: =J14*$E14 -> 0 | M14: =L14*$E14 -> 0 | O14: =N14*$E14 -> 0 | Q14: =P14*$E14 -> 0 | S14: =R14*$E14 -> 0 | U14: =T14*$E14 -> 0 | W14: =V14*$E14 -> 0 | Y14: =X14*$E14 -> 0 | AA14: =Z14*$E14 -> 0 | AC14: =AB14*$E14 -> 0 | AE14: =AD14*$E14 -> 0 | AF14: =(AD14+AB14+Z14+X14+V14+T14+R14+P14+N14+L14+J14+H14)/1 -> 0 | AG14: =AF14*$E14 -> 0 | AI14: =AH14*$E14 -> 0 | AK14: =AJ14*$E14 -> 0 | AM14: =AL14*$E14 -> 0 | AO14: =AN14*$E14 -> 0 | AQ14: =AP14*$E14 -> 0 | AS14: =AR14*$E14 -> 0 | AU14: =AT14*$E14 -> 0 | AW14: =AV14*$E14 -> 0 | AY14: =AX14*$E14 -> 0 | BA14: =AZ14*$E14 -> 0 | BC14: =BB14*$E14 -> 0 | BE14: =BD14*$E14 -> 0 | BF14: =(BD14+BB14+AZ14+AX14+AV14+AT14+AR14+AP14+AN14+AL14+AJ14+AH14)/1 -> 0 | BG14: =BF14*$E14 -> 0 | BI14: =BH14*$E14 -> 0 | BK14: =BJ14*$E14 -> 0 | BM14: =BL14*$E14 -> 0 | BO14: =BN14*$E14 -> 0 | BQ14: =BP14*$E14 -> 0 | BS14: =BR14*$E14 -> 0 | BU14: =BT14*$E14 -> 0 | BW14: =BV14*$E14 -> 0 | BY14: =BX14*$E14 -> 0 | CA14: =BZ14*$E14 -> 0 | CC14: =CB14*$E14 -> 0 | CE14: =CD14*$E14 -> 0 | CF14: =(CD14+CB14+BZ14+BX14+BV14+BT14+BR14+BP14+BN14+BL14+BJ14+BH14)/1 -> 0 | CG14: =CF14*$E14 -> 0 | CI14: =CH14*$E14 -> 0 | CK14: =CJ14*$E14 -> 0 | CM14: =CL14*$E14 -> 0 | CO14: =CN14*$E14 -> 0 | CQ14: =CP14*$E14 -> 0 | CS14: =CR14*$E14 -> 0 | CU14: =CT14*$E14 -> 0 | CW14: =CV14*$E14 -> 0 | CY14: =CX14*$E14 -> 0 | DA14: =CZ14*$E14 -> 0 | DC14: =DB14*$E14 -> 0 | DE14: =DD14*$E14 -> 0 | DF14: =SUM(CH14,CJ14,CL14,CN14,CP14,CR14,CT14,CV14,CX14,CZ14,DB14,DD14)/1 -> 0 | DG14: =DF14*$E14 -> 0 | DI14: =DH14*$E14 -> 0 | DK14: =DJ14*$E14 -> 0 | DM14: =DL14*$E14 -> 0 | DO14: =DN14*$E14 -> 0 | DQ14: =DP14*$E14 -> 0 | DS14: =DR14*$E14 -> 0 | DU14: =DT14*$E14 -> 0 | DW14: =DV14*$E14 -> 0 | DY14: =DX14*$E14 -> 0 | EA14: =DZ14*$E14 -> 0 | EC14: =EB14*$E14 -> 0 | EE14: =ED14*$E14 -> 0 | EF14: =SUM(DH14,DJ14,DL14,DN14,DP14,DR14,DT14,DV14,DX14,DZ14,EB14,ED14) -> 0 | EG14: =SUM(DI14,DK14,DM14,DO14,DQ14,DS14,DU14,DW14,DY14,EA14,EC14,EE14) -> 0
I15: =H15*$E15 -> 0 | K15: =J15*$E15 -> 0 | M15: =L15*$E15 -> 0 | O15: =N15*$E15 -> 0 | Q15: =P15*$E15 -> 0 | S15: =R15*$E15 -> 0 | U15: =T15*$E15 -> 0 | W15: =V15*$E15 -> 0 | Y15: =X15*$E15 -> 0 | AA15: =Z15*$E15 -> 0 | AC15: =AB15*$E15 -> 0 | AE15: =AD15*$E15 -> 0 | AF15: =(AD15+AB15+Z15+X15+V15+T15+R15+P15+N15+L15+J15+H15)/1 -> 0 | AG15: =AF15*$E15 -> 0 | AI15: =AH15*$E15 -> 0 | AK15: =AJ15*$E15 -> 0 | AM15: =AL15*$E15 -> 0 | AO15: =AN15*$E15 -> 0 | AQ15: =AP15*$E15 -> 0 | AS15: =AR15*$E15 -> 0 | AU15: =AT15*$E15 -> 0 | AW15: =AV15*$E15 -> 0 | AY15: =AX15*$E15 -> 0 | BA15: =AZ15*$E15 -> 0 | BC15: =BB15*$E15 -> 0 | BE15: =BD15*$E15 -> 0 | BF15: =(BD15+BB15+AZ15+AX15+AV15+AT15+AR15+AP15+AN15+AL15+AJ15+AH15)/1 -> 0 | BG15: =BF15*$E15 -> 0 | BI15: =BH15*$E15 -> 0 | BK15: =BJ15*$E15 -> 0 | BM15: =BL15*$E15 -> 0 | BO15: =BN15*$E15 -> 0 | BQ15: =BP15*$E15 -> 0 | BS15: =BR15*$E15 -> 0 | BU15: =BT15*$E15 -> 0 | BW15: =BV15*$E15 -> 0 | BY15: =BX15*$E15 -> 0 | CA15: =BZ15*$E15 -> 0 | CC15: =CB15*$E15 -> 0 | CE15: =CD15*$E15 -> 0 | CF15: =(CD15+CB15+BZ15+BX15+BV15+BT15+BR15+BP15+BN15+BL15+BJ15+BH15)/1 -> 0 | CG15: =CF15*$E15 -> 0 | CI15: =CH15*$E15 -> 0 | CK15: =CJ15*$E15 -> 0 | CM15: =CL15*$E15 -> 0 | CO15: =CN15*$E15 -> 0 | CQ15: =CP15*$E15 -> 0 | CS15: =CR15*$E15 -> 0 | CU15: =CT15*$E15 -> 0 | CW15: =CV15*$E15 -> 0 | CY15: =CX15*$E15 -> 0 | DA15: =CZ15*$E15 -> 0 | DC15: =DB15*$E15 -> 0 | DE15: =DD15*$E15 -> 0 | DF15: =SUM(CH15,CJ15,CL15,CN15,CP15,CR15,CT15,CV15,CX15,CZ15,DB15,DD15)/1 -> 0 | DG15: =DF15*$E15 -> 0
A16: 11 | B16: Kaung Kyi (1 Liter)_25% | C16: ‌ကော်ဘူး | D16: =RANK(DF16,$DF$4:$DF$147) -> 15 | E16: 1 | F16: 1 * 12 | G16: 1500 | H16: 12 | I16: =H16*$E16 -> 12 | K16: =J16*$E16 -> 0 | L16: 48 | M16: =L16*$E16 -> 48 | O16: =N16*$E16 -> 0 | Q16: =P16*$E16 -> 0 | S16: =R16*$E16 -> 0 | T16: 72 | U16: =T16*$E16 -> 72 | V16: 12 | W16: =V16*$E16 -> 12 | X16: 12 | Y16: =X16*$E16 -> 12 | Z16: 72 | AA16: =Z16*$E16 -> 72 | AB16: 48 | AC16: =AB16*$E16 -> 48 | AD16: 36 | AE16: =AD16*$E16 -> 36 | AF16: =(AD16+AB16+Z16+X16+V16+T16+R16+P16+N16+L16+J16+H16)/1 -> 312 | AG16: =AF16*$E16 -> 312 | AH16: 24 | AI16: =AH16*$E16 -> 24 | AJ16: 60 | AK16: =AJ16*$E16 -> 60 | AL16: 12 | AM16: =AL16*$E16 -> 12 | AO16: =AN16*$E16 -> 0 | AQ16: =AP16*$E16 -> 0 | AS16: =AR16*$E16 -> 0 | AU16: =AT16*$E16 -> 0 | AW16: =AV16*$E16 -> 0 | AY16: =AX16*$E16 -> 0 | AZ16: 72 | BA16: =AZ16*$E16 -> 72 | BB16: 60 | BC16: =BB16*$E16 -> 60 | BD16: 132 | BE16: =BD16*$E16 -> 132 | BF16: =(BD16+BB16+AZ16+AX16+AV16+AT16+AR16+AP16+AN16+AL16+AJ16+AH16)/1 -> 360 | BG16: =BF16*$E16 -> 360 | BH16: 260 | BI16: =BH16*$E16 -> 260 | BJ16: 278 | BK16: =BJ16*$E16 -> 278 | BL16: 552 | BM16: =BL16*$E16 -> 552 | BN16: 348 | BO16: =BN16*$E16 -> 348 | BP16: 552 | BQ16: =BP16*$E16 -> 552 | BR16: 312 | BS16: =BR16*$E16 -> 312 | BT16: 698 | BU16: =BT16*$E16 -> 698 | BV16: 1491 | BW16: =BV16*$E16 -> 1491 | BX16: 912 | BY16: =BX16*$E16 -> 912 | BZ16: 672 | CA16: =BZ16*$E16 -> 672 | CB16: 228 | CC16: =CB16*$E16 -> 228 | CD16: 648 | CE16: =CD16*$E16 -> 648 | CF16: =(CD16+CB16+BZ16+BX16+BV16+BT16+BR16+BP16+BN16+BL16+BJ16+BH16)/1 -> 6951 | CG16: =CF16*$E16 -> 6951 | CH16: 351 | CI16: =CH16*$E16 -> 351 | CJ16: 1072 | CK16: =CJ16*$E16 -> 1072 | CL16: 1178 | CM16: =CL16*$E16 -> 1178 | CN16: 168 | CO16: =CN16*$E16 -> 168 | CP16: 432 | CQ16: =CP16*$E16 -> 432 | CR16: 3978 | CS16: =CR16*$E16 -> 3978 | CT16: 4789 | CU16: =CT16*$E16 -> 4789 | CV16: 2672 | CW16: =CV16*$E16 -> 2672 | CX16: 2233 | CY16: =CX16*$E16 -> 2233 | CZ16: 1272 | DA16: =CZ16*$E16 -> 1272 | DB16: 1448 | DC16: =DB16*$E16 -> 1448 | DD16: 1224 | DE16: =DD16*$E16 -> 1224 | DF16: =SUM(CH16,CJ16,CL16,CN16,CP16,CR16,CT16,CV16,CX16,CZ16,DB16,DD16)/1 -> 20817 | DG16: =DF16*$E16 -> 20817 | DH16: 1736 | DI16: =DH16*$E16 -> 1736 | DJ16: 1743 | DK16: =DJ16*$E16 -> 1743 | DM16: =DL16*$E16 -> 0 | DO16: =DN16*$E16 -> 0 | DQ16: =DP16*$E16 -> 0 | DS16: =DR16*$E16 -> 0 | DU16: =DT16*$E16 -> 0 | DW16: =DV16*$E16 -> 0 | DY16: =DX16*$E16 -> 0 | EA16: =DZ16*$E16 -> 0 | EC16: =EB16*$E16 -> 0 | EE16: =ED16*$E16 -> 0 | EF16: =SUM(DH16,DJ16,DL16,DN16,DP16,DR16,DT16,DV16,DX16,DZ16,EB16,ED16) -> 3479 | EG16: =SUM(DI16,DK16,DM16,DO16,DQ16,DS16,DU16,DW16,DY16,EA16,EC16,EE16) -> 3479
A17: 12 | B17: Kaung Kyi (1 Liter)_40% | C17: ‌ကော်ဘူး | D17: =RANK(DF17,$DF$4:$DF$147) -> 25 | E17: 1 | F17: 1 * 12 | G17: 1930 | I17: =H17*$E17 -> 0 | J17: 108 | K17: =J17*$E17 -> 108 | M17: =L17*$E17 -> 0 | O17: =N17*$E17 -> 0 | Q17: =P17*$E17 -> 0 | S17: =R17*$E17 -> 0 | U17: =T17*$E17 -> 0 | W17: =V17*$E17 -> 0 | Y17: =X17*$E17 -> 0 | AA17: =Z17*$E17 -> 0 | AC17: =AB17*$E17 -> 0 | AE17: =AD17*$E17 -> 0 | AF17: =(AD17+AB17+Z17+X17+V17+T17+R17+P17+N17+L17+J17+H17)/1 -> 108 | AG17: =AF17*$E17 -> 108 | AI17: =AH17*$E17 -> 0 | AK17: =AJ17*$E17 -> 0 | AM17: =AL17*$E17 -> 0 | AO17: =AN17*$E17 -> 0 | AQ17: =AP17*$E17 -> 0 | AS17: =AR17*$E17 -> 0 | AT17: 120 | AU17: =AT17*$E17 -> 120 | AW17: =AV17*$E17 -> 0 | AX17: 24 | AY17: =AX17*$E17 -> 24 | AZ17: 60 | BA17: =AZ17*$E17 -> 60 | BB17: 36 | BC17: =BB17*$E17 -> 36 | BD17: 120 | BE17: =BD17*$E17 -> 120 | BF17: =(BD17+BB17+AZ17+AX17+AV17+AT17+AR17+AP17+AN17+AL17+AJ17+AH17)/1 -> 360 | BG17: =BF17*$E17 -> 360 | BH17: 132 | BI17: =BH17*$E17 -> 132 | BJ17: 240 | BK17: =BJ17*$E17 -> 240 | BL17: 204 | BM17: =BL17*$E17 -> 204 | BN17: 300 | BO17: =BN17*$E17 -> 300 | BP17: 504 | BQ17: =BP17*$E17 -> 504 | BR17: 456 | BS17: =BR17*$E17 -> 456 | BT17: 864 | BU17: =BT17*$E17 -> 864 | BV17: 372 | BW17: =BV17*$E17 -> 372 | BX17: 540 | BY17: =BX17*$E17 -> 540 | BZ17: 192 | CA17: =BZ17*$E17 -> 192 | CC17: =CB17*$E17 -> 0 | CD17: 360 | CE17: =CD17*$E17 -> 360 | CF17: =(CD17+CB17+BZ17+BX17+BV17+BT17+BR17+BP17+BN17+BL17+BJ17+BH17)/1 -> 4164 | CG17: =CF17*$E17 -> 4164 | CH17: 180 | CI17: =CH17*$E17 -> 180 | CJ17: 120 | CK17: =CJ17*$E17 -> 120 | CL17: 60 | CM17: =CL17*$E17 -> 60 | CN17: 360 | CO17: =CN17*$E17 -> 360 | CP17: 120 | CQ17: =CP17*$E17 -> 120 | CR17: 403 | CS17: =CR17*$E17 -> 403 | CT17: 528 | CU17: =CT17*$E17 -> 528 | CV17: 252 | CW17: =CV17*$E17 -> 252 | CX17: 165 | CY17: =CX17*$E17 -> 165 | CZ17: 168 | DA17: =CZ17*$E17 -> 168 | DB17: 276 | DC17: =DB17*$E17 -> 276 | DD17: 216 | DE17: =DD17*$E17 -> 216 | DF17: =SUM(CH17,CJ17,CL17,CN17,CP17,CR17,CT17,CV17,CX17,CZ17,DB17,DD17)/1 -> 2848 | DG17: =DF17*$E17 -> 2848 | DH17: 228 | DI17: =DH17*$E17 -> 228 | DJ17: 240 | DK17: =DJ17*$E17 -> 240 | DM17: =DL17*$E17 -> 0 | DO17: =DN17*$E17 -> 0 | DQ17: =DP17*$E17 -> 0 | DS17: =DR17*$E17 -> 0 | DU17: =DT17*$E17 -> 0 | DW17: =DV17*$E17 -> 0 | DY17: =DX17*$E17 -> 0 | EA17: =DZ17*$E17 -> 0 | EC17: =EB17*$E17 -> 0 | EE17: =ED17*$E17 -> 0 | EF17: =SUM(DH17,DJ17,DL17,DN17,DP17,DR17,DT17,DV17,DX17,DZ17,EB17,ED17) -> 468 | EG17: =SUM(DI17,DK17,DM17,DO17,DQ17,DS17,DU17,DW17,DY17,EA17,EC17,EE17) -> 468
A18: 13 | B18: Kaung Kyi (0.6 Liter)_25% | C18: ‌ကော်ဘူး | D18: =RANK(DF18,$DF$4:$DF$147) -> 31 | E18: 0.6 | F18: 1 * 12 | G18: 1060 | I18: =H18*$E18 -> 0 | K18: =J18*$E18 -> 0 | M18: =L18*$E18 -> 0 | O18: =N18*$E18 -> 0 | Q18: =P18*$E18 -> 0 | S18: =R18*$E18 -> 0 | U18: =T18*$E18 -> 0 | W18: =V18*$E18 -> 0 | Y18: =X18*$E18 -> 0 | AA18: =Z18*$E18 -> 0 | AC18: =AB18*$E18 -> 0 | AE18: =AD18*$E18 -> 0 | AF18: =(AD18+AB18+Z18+X18+V18+T18+R18+P18+N18+L18+J18+H18)/1 -> 0 | AG18: =AF18*$E18 -> 0 | AI18: =AH18*$E18 -> 0 | AK18: =AJ18*$E18 -> 0 | AM18: =AL18*$E18 -> 0 | AO18: =AN18*$E18 -> 0 | AQ18: =AP18*$E18 -> 0 | AS18: =AR18*$E18 -> 0 | AU18: =AT18*$E18 -> 0 | AW18: =AV18*$E18 -> 0 | AY18: =AX18*$E18 -> 0 | BA18: =AZ18*$E18 -> 0 | BC18: =BB18*$E18 -> 0 | BE18: =BD18*$E18 -> 0 | BF18: =(BD18+BB18+AZ18+AX18+AV18+AT18+AR18+AP18+AN18+AL18+AJ18+AH18)/1 -> 0 | BG18: =BF18*$E18 -> 0 | BI18: =BH18*$E18 -> 0 | BK18: =BJ18*$E18 -> 0 | BM18: =BL18*$E18 -> 0 | BO18: =BN18*$E18 -> 0 | BQ18: =BP18*$E18 -> 0 | BS18: =BR18*$E18 -> 0 | BU18: =BT18*$E18 -> 0 | BW18: =BV18*$E18 -> 0 | BY18: =BX18*$E18 -> 0 | CA18: =BZ18*$E18 -> 0 | CC18: =CB18*$E18 -> 0 | CE18: =CD18*$E18 -> 0 | CF18: =(CD18+CB18+BZ18+BX18+BV18+BT18+BR18+BP18+BN18+BL18+BJ18+BH18)/1 -> 0 | CG18: =CF18*$E18 -> 0 | CI18: =CH18*$E18 -> 0 | CK18: =CJ18*$E18 -> 0 | CM18: =CL18*$E18 -> 0 | CO18: =CN18*$E18 -> 0 | CQ18: =CP18*$E18 -> 0 | CS18: =CR18*$E18 -> 0 | CU18: =CT18*$E18 -> 0 | CW18: =CV18*$E18 -> 0 | CY18: =CX18*$E18 -> 0 | DA18: =CZ18*$E18 -> 0 | DC18: =DB18*$E18 -> 0 | DE18: =DD18*$E18 -> 0 | DF18: =SUM(CH18,CJ18,CL18,CN18,CP18,CR18,CT18,CV18,CX18,CZ18,DB18,DD18)/1 -> 0 | DG18: =DF18*$E18 -> 0 | DI18: =DH18*$E18 -> 0 | DK18: =DJ18*$E18 -> 0 | DM18: =DL18*$E18 -> 0 | DO18: =DN18*$E18 -> 0 | DQ18: =DP18*$E18 -> 0 | DS18: =DR18*$E18 -> 0 | DU18: =DT18*$E18 -> 0 | DW18: =DV18*$E18 -> 0 | DY18: =DX18*$E18 -> 0 | EA18: =DZ18*$E18 -> 0 | EC18: =EB18*$E18 -> 0 | EE18: =ED18*$E18 -> 0 | EF18: =SUM(DH18,DJ18,DL18,DN18,DP18,DR18,DT18,DV18,DX18,DZ18,EB18,ED18) -> 0 | EG18: =SUM(DI18,DK18,DM18,DO18,DQ18,DS18,DU18,DW18,DY18,EA18,EC18,EE18) -> 0
A19: 14 | B19: Kaung Kyi (0.6 Liter)_40% | C19: ‌ကော်ဘူး | D19: =RANK(DF19,$DF$4:$DF$147) -> 30 | E19: 0.6 | F19: 1 * 12 | G19: 1310 | H19: 12 | I19: =H19*$E19 -> 7.2 | K19: =J19*$E19 -> 0 | M19: =L19*$E19 -> 0 | O19: =N19*$E19 -> 0 | Q19: =P19*$E19 -> 0 | R19: 132 | S19: =R19*$E19 -> 79.2 | U19: =T19*$E19 -> 0 | W19: =V19*$E19 -> 0 | Y19: =X19*$E19 -> 0 | AA19: =Z19*$E19 -> 0 | AC19: =AB19*$E19 -> 0 | AE19: =AD19*$E19 -> 0 | AF19: =(AD19+AB19+Z19+X19+V19+T19+R19+P19+N19+L19+J19+H19)/1 -> 144 | AG19: =AF19*$E19 -> 86.4 | AI19: =AH19*$E19 -> 0 | AK19: =AJ19*$E19 -> 0 | AM19: =AL19*$E19 -> 0 | AO19: =AN19*$E19 -> 0 | AQ19: =AP19*$E19 -> 0 | AS19: =AR19*$E19 -> 0 | AU19: =AT19*$E19 -> 0 | AW19: =AV19*$E19 -> 0 | AY19: =AX19*$E19 -> 0 | BA19: =AZ19*$E19 -> 0 | BC19: =BB19*$E19 -> 0 | BE19: =BD19*$E19 -> 0 | BF19: =(BD19+BB19+AZ19+AX19+AV19+AT19+AR19+AP19+AN19+AL19+AJ19+AH19)/1 -> 0 | BG19: =BF19*$E19 -> 0 | BH19: 12 | BI19: =BH19*$E19 -> 7.2 | BJ19: 0 | BK19: =BJ19*$E19 -> 0 | BL19: 0 | BM19: =BL19*$E19 -> 0 | BN19: 0 | BO19: =BN19*$E19 -> 0 | BP19: 0 | BQ19: =BP19*$E19 -> 0 | BR19: 0 | BS19: =BR19*$E19 -> 0 | BT19: 0 | BU19: =BT19*$E19 -> 0 | BV19: 0 | BW19: =BV19*$E19 -> 0 | BX19: 0 | BY19: =BX19*$E19 -> 0 | CA19: =BZ19*$E19 -> 0 | CC19: =CB19*$E19 -> 0 | CE19: =CD19*$E19 -> 0 | CF19: =(CD19+CB19+BZ19+BX19+BV19+BT19+BR19+BP19+BN19+BL19+BJ19+BH19)/1 -> 12 | CG19: =CF19*$E19 -> 7.2 | CI19: =CH19*$E19 -> 0 | CK19: =CJ19*$E19 -> 0 | CM19: =CL19*$E19 -> 0 | CO19: =CN19*$E19 -> 0 | CQ19: =CP19*$E19 -> 0 | CS19: =CR19*$E19 -> 0 | CU19: =CT19*$E19 -> 0 | CV19: 12 | CW19: =CV19*$E19 -> 7.2 | CY19: =CX19*$E19 -> 0 | DA19: =CZ19*$E19 -> 0 | DC19: =DB19*$E19 -> 0 | DE19: =DD19*$E19 -> 0 | DF19: =SUM(CH19,CJ19,CL19,CN19,CP19,CR19,CT19,CV19,CX19,CZ19,DB19,DD19)/1 -> 12 | DG19: =DF19*$E19 -> 7.2 | DH19: 12 | DI19: =DH19*$E19 -> 7.2 | DK19: =DJ19*$E19 -> 0 | DM19: =DL19*$E19 -> 0 | DO19: =DN19*$E19 -> 0 | DQ19: =DP19*$E19 -> 0 | DS19: =DR19*$E19 -> 0 | DU19: =DT19*$E19 -> 0 | DW19: =DV19*$E19 -> 0 | DY19: =DX19*$E19 -> 0 | EA19: =DZ19*$E19 -> 0 | EC19: =EB19*$E19 -> 0 | EE19: =ED19*$E19 -> 0 | EF19: =SUM(DH19,DJ19,DL19,DN19,DP19,DR19,DT19,DV19,DX19,DZ19,EB19,ED19) -> 12 | EG19: =SUM(DI19,DK19,DM19,DO19,DQ19,DS19,DU19,DW19,DY19,EA19,EC19,EE19) -> 7.2
A20: 15 | B20: Kaung Kyi (0.35 Liter)_25% | C20: ‌ကော်ဘူး | D20: =RANK(DF20,$DF$4:$DF$147) -> 31 | E20: 0.35 | F20: 1 * 40 | G20: 730 | I20: =H20*$E20 -> 0 | K20: =J20*$E20 -> 0 | M20: =L20*$E20 -> 0 | O20: =N20*$E20 -> 0 | Q20: =P20*$E20 -> 0 | S20: =R20*$E20 -> 0 | U20: =T20*$E20 -> 0 | W20: =V20*$E20 -> 0 | Y20: =X20*$E20 -> 0 | AA20: =Z20*$E20 -> 0 | AC20: =AB20*$E20 -> 0 | AE20: =AD20*$E20 -> 0 | AF20: =(AD20+AB20+Z20+X20+V20+T20+R20+P20+N20+L20+J20+H20)/1 -> 0 | AG20: =AF20*$E20 -> 0 | AI20: =AH20*$E20 -> 0 | AK20: =AJ20*$E20 -> 0 | AM20: =AL20*$E20 -> 0 | AO20: =AN20*$E20 -> 0 | AQ20: =AP20*$E20 -> 0 | AS20: =AR20*$E20 -> 0 | AU20: =AT20*$E20 -> 0 | AW20: =AV20*$E20 -> 0 | AY20: =AX20*$E20 -> 0 | BA20: =AZ20*$E20 -> 0 | BC20: =BB20*$E20 -> 0 | BE20: =BD20*$E20 -> 0 | BF20: =(BD20+BB20+AZ20+AX20+AV20+AT20+AR20+AP20+AN20+AL20+AJ20+AH20)/1 -> 0 | BG20: =BF20*$E20 -> 0 | BI20: =BH20*$E20 -> 0 | BK20: =BJ20*$E20 -> 0 | BM20: =BL20*$E20 -> 0 | BO20: =BN20*$E20 -> 0 | BQ20: =BP20*$E20 -> 0 | BS20: =BR20*$E20 -> 0 | BU20: =BT20*$E20 -> 0 | BW20: =BV20*$E20 -> 0 | BY20: =BX20*$E20 -> 0 | CA20: =BZ20*$E20 -> 0 | CC20: =CB20*$E20 -> 0 | CE20: =CD20*$E20 -> 0 | CF20: =(CD20+CB20+BZ20+BX20+BV20+BT20+BR20+BP20+BN20+BL20+BJ20+BH20)/1 -> 0 | CG20: =CF20*$E20 -> 0 | CI20: =CH20*$E20 -> 0 | CK20: =CJ20*$E20 -> 0 | CM20: =CL20*$E20 -> 0 | CO20: =CN20*$E20 -> 0 | CQ20: =CP20*$E20 -> 0 | CS20: =CR20*$E20 -> 0 | CU20: =CT20*$E20 -> 0 | CW20: =CV20*$E20 -> 0 | CY20: =CX20*$E20 -> 0 | DA20: =CZ20*$E20 -> 0 | DC20: =DB20*$E20 -> 0 | DE20: =DD20*$E20 -> 0 | DF20: =SUM(CH20,CJ20,CL20,CN20,CP20,CR20,CT20,CV20,CX20,CZ20,DB20,DD20)/1 -> 0 | DG20: =DF20*$E20 -> 0 | DI20: =DH20*$E20 -> 0 | DK20: =DJ20*$E20 -> 0 | DM20: =DL20*$E20 -> 0 | DO20: =DN20*$E20 -> 0 | DQ20: =DP20*$E20 -> 0 | DS20: =DR20*$E20 -> 0 | DU20: =DT20*$E20 -> 0 | DW20: =DV20*$E20 -> 0 | DY20: =DX20*$E20 -> 0 | EA20: =DZ20*$E20 -> 0 | EC20: =EB20*$E20 -> 0 | EE20: =ED20*$E20 -> 0 | EF20: =SUM(DH20,DJ20,DL20,DN20,DP20,DR20,DT20,DV20,DX20,DZ20,EB20,ED20) -> 0 | EG20: =SUM(DI20,DK20,DM20,DO20,DQ20,DS20,DU20,DW20,DY20,EA20,EC20,EE20) -> 0
