Workbook
Name aa: #REF!
Name aa: #REF!
Name aaa: #REF!
Name aaa: #REF!
Name asd: '[1]Market ( Mar) '!#REF!
Name asd: '[1]Market ( Mar) '!#REF!
Name atr: #REF!
Name atr: #REF!
Name b: #REF!
Name b: #REF!
Name bb: #REF!
Name bb: #REF!
Name Beg_Bal: #REF!
Name Beg_Bal: #REF!
Name Cash_Cr: #REF!
Name Cash_Cr: #REF!
Name Cash_Dr: #REF!
Name Cash_Dr: #REF!
Name cc: #REF!
Name cc: #REF!
Name ccc: #REF!
Name ccc: #REF!
Name cr: #REF!
Name cr: #REF!
Name crs: #REF!
Name crs: #REF!
Name Data: #REF!
Name Data: #REF!
Name dd: #REF!
Name dd: #REF!
Name ddd: #REF!
Name ddd: #REF!
Name dr: #REF!
Name dr: #REF!
Name drs: #REF!
Name drs: #REF!
Name End_Bal: #REF!
Name End_Bal: #REF!
Name Extra_Pay: #REF!
Name Extra_Pay: #REF!
Name fgf: #REF!
Name fgf: #REF!
Name fgjhj: #REF!
Name fgjhj: #REF!
Name Full_Print: #REF!
Name Full_Print: #REF!
Name Header_Row: ROW(#REF!)
Name Header_Row: ROW(#REF!)
Name hjj: #REF!
Name hjj: #REF!
Name hjkjk: #REF!
Name hjkjk: #REF!
Name hmjhj: #REF!
Name hmjhj: #REF!
Name Int: #REF!
Name Int: #REF!
Name Interest_Rate: #REF!
Name Interest_Rate: #REF!
Name jbkjkl: #REF!
Name jbkjkl: #REF!

Sheet Ygn 2025 Fllow up sale
A1: Yangon Region Sales for Wholesales , Semi Wholesales and Mini Wholesales | O1: January 2025Target | R1: February-2025 Target | W1: March 2025 Target
M2: 2700000 | N2: =M2*78% -> 2106000 | R2: 2550000 | S2: =R2*77% -> 1963500 | W2: 2874759 | X2: =W2*80% -> 2299807.2
A3: No | B3: Customer Names | D3: Township (Area) | F3: Type | G3: Contact Name | I3: Contact No. | J3: Responsible by | K3: January-2024 | M3: Contribution | N3: PKT | O3: Bottle | P3: February-2024 | R3: Contribution | S3: PKT | T3: Bottle | U3: March-2024 | W3: Contribution | X3: PKT | Y3: Bottle | Z3: 2025 - Q1 Target | AB3: 2025 - Avg Q1
K4: PKT | L4: BOT | M4: 0.78 | P4: PKT | Q4: BOT | R4: 0.77 | U4: PKT | V4: BOT | W4: 0.8 | Z4: PKT | AA4: BOT | AB4: PKT | AC4: BOT
A5: 1 | B5: မိုးအောင် | C5: Moe Aung | D5: တ/ဒဂုံ | E5: Sount Dagon | F5: WS | G5: မမြ | H5: Ma Mya | I5: 09-740816390 | J5: RSM | K5: 19618 | L5: 279050 | M5: =L5/L47 -> 0.1357055 | N5: =O5/14 -> 20413.985 | O5: =M5*$N$2 -> 285795.78 | P5: 15961 | Q5: 232338 | R5: =Q5/Q47 -> 0.13798399 | S5: =T5/14 -> 19352.255 | T5: =R5*$S$2 -> 270931.57 | U5: 17929 | V5: 259548 | W5: =V5/$V$47 -> 0.13129665 | X5: =Y5/14 -> 21568.355 | Y5: =W5*$X$2 -> 301956.97 | Z5: =X5+S5+N5 -> 61334.595 | AA5: =Y5+T5+O5 -> 858684.33 | AB5: =Z5/3 -> 20444.865 | AC5: =AA5/3 -> 286228.11
A6: 2 | B6: သော်တာထွန်း | C6: Thawdar Tun | D6: လသယ | E6: Hlaing Thar Yar | F6: WS | G6: ကိုသူရ | H6: Ko Thu Ya | I6: 09-954456566 | J6: RSM | K6: 17080 | L6: 245240 | M6: =L6/L47 -> 0.11926328 | N6: =O6/14 -> 17940.604 | O6: =M6*$N$2 -> 251168.46 | P6: 12685 | Q6: 181980 | R6: =Q6/Q47 -> 0.10807671 | S6: =T6/14 -> 15157.759 | T6: =R6*$S$2 -> 212208.62 | U6: 15075 | V6: 212000 | W6: =V6/$V$47 -> 0.10724371 | X6: =Y6/14 -> 17617.132 | Y6: =W6*$X$2 -> 246639.85 | Z6: =X6+S6+N6 -> 50715.495 | AA6: =Y6+T6+O6 -> 710016.93 | AB6: =Z6/3 -> 16905.165 | AC6: =AA6/3 -> 236672.31
A7: 3 | B7: ရွှေဧရာ | C7: Shwe Ayeyar | D7: 16 St | E7: 16 street | F7: WS | G7: ကိုသာပိုး | H7: Ko Thar Poe | I7: 09-420029084 | J7: RSM | K7: 9431 | L7: 145482 | M7: =L7/L47 -> 0.070749714 | N7: =O7/14 -> 10642.778 | O7: =M7*$N$2 -> 148998.9 | P7: 5165 | Q7: 83000 | R7: =Q7/Q47 -> 0.049293148 | S7: =T7/14 -> 6913.364 | T7: =R7*$S$2 -> 96787.096 | U7: 7897 | V7: 120590 | W7: =V7/$V$47 -> 0.061002445 | X7: =Y7/14 -> 10020.99 | Y7: =W7*$X$2 -> 140293.86 | Z7: =X7+S7+N7 -> 27577.133 | AA7: =Y7+T7+O7 -> 386079.86 | AB7: =Z7/3 -> 9192.3775 | AC7: =AA7/3 -> 128693.29
A8: 4 | B8: မိဘမေတ္တာ | C8: Mi Ba Myint Thar | D8: လသယ | E8: Hlaing Thar Yar | F8: WS | G8: မပိုပို | H8: Ma Po Po | I8: 09-762811856 | J8: RSM | K8: 6968 | L8: 94352 | M8: =L8/L47 -> 0.045884556 | N8: =O8/14 -> 6902.3482 | O8: =M8*$N$2 -> 96632.875 | P8: 7510 | Q8: 101220 | R8: =Q8/Q47 -> 0.060113885 | S8: =T8/14 -> 8430.9724 | T8: =R8*$S$2 -> 118033.61 | U8: 10155 | V8: 135060 | W8: =V8/$V$47 -> 0.068322334 | X8: =Y8/14 -> 11223.443 | Y8: =W8*$X$2 -> 157128.2 | Z8: =X8+S8+N8 -> 26556.763 | AA8: =Y8+T8+O8 -> 371794.68 | AB8: =Z8/3 -> 8852.2544 | AC8: =AA8/3 -> 123931.56
A9: 5 | B9: AAA | C9: A.A.A. | D9: မ/ဒဂုံ | E9: North Dagon | F9: WS | G9: မစီ | H9: Ma Si | I9: 09-790414141 | J9: RSM | K9: 6940 | L9: 98060 | M9: =L9/L47 -> 0.047687803 | N9: =O9/14 -> 7173.6081 | O9: =M9*$N$2 -> 100430.51 | P9: 6010 | Q9: 84280 | R9: =Q9/Q47 -> 0.050053332 | S9: =T9/14 -> 7019.9798 | T9: =R9*$S$2 -> 98279.717 | U9: 7000 | V9: 97820 | W9: =V9/$V$47 -> 0.049483864 | X9: =Y9/14 -> 8128.8105 | Y9: =W9*$X$2 -> 113803.35 | Z9: =X9+S9+N9 -> 22322.398 | AA9: =Y9+T9+O9 -> 312513.58 | AB9: =Z9/3 -> 7440.7995 | AC9: =AA9/3 -> 104171.19
A10: 6 | B10: ပေါ်ဉီး | C10: Paw Oo | D10: ဒလ | E10: Dala | F10: WS | G10: ဦးပေါ်ဦး | H10: U Paw Oo | I10: 09-964436777 | J10: RSM | K10: 4705 | L10: 69020 | M10: =L10/L47 -> 0.033565288 | N10: =O10/14 -> 5049.1784 | O10: =M10*$N$2 -> 70688.497 | P10: 4535 | Q10: 66620 | R10: =Q10/Q47 -> 0.039565175 | S10: =T10/14 -> 5549.0158 | T10: =R10*$S$2 -> 77686.221 | U10: 4005 | V10: 59600 | W10: =V10/$V$47 -> 0.030149645 | X10: =Y10/14 -> 4952.7408 | Y10: =W10*$X$2 -> 69338.372 | Z10: =X10+S10+N10 -> 15550.935 | AA10: =Y10+T10+O10 -> 217713.09 | AB10: =Z10/3 -> 5183.645 | AC10: =AA10/3 -> 72571.03
A11: 7 | B11: ဘောဂ | C11: Baw Ga | D11: သန်လျင် | E11: Thanlyin | F11: WS | G11: ကိုဇင်လင်းထွန်း | H11: Ko Zin Lin Htun | I11: 09-421022592 | J11: RSM | K11: 5205 | L11: 74780 | M11: =L11/L47 -> 0.036366448 | N11: =O11/14 -> 5470.5528 | O11: =M11*$N$2 -> 76587.74 | P11: 5220 | Q11: 75080 | R11: =Q11/Q47 -> 0.044589513 | S11: =T11/14 -> 6253.6792 | T11: =R11*$S$2 -> 87551.508 | U11: 5100 | V11: 71300 | W11: =V11/$V$47 -> 0.036068284 | X11: =Y11/14 -> 5925.0071 | Y11: =W11*$X$2 -> 82950.099 | Z11: =X11+S11+N11 -> 17649.239 | AA11: =Y11+T11+O11 -> 247089.35 | AB11: =Z11/3 -> 5883.0797 | AC11: =AA11/3 -> 82363.116
A12: 8 | B12: ရတနာတိုး (H) | C12: Yatanar Toe | D12: မှော်ဘီ | E12: Hmawbi | F12: WS | G12: ဦးသစ်လွင် | H12: U Thit Lwin | I12: 09-5137424 | J12: RSM | K12: 6520 | L12: 92280 | M12: =L12/L47 -> 0.044876917 | N12: =O12/14 -> 6750.7705 | O12: =M12*$N$2 -> 94510.787 | P12: 4340 | Q12: 61820 | R12: =Q12/Q47 -> 0.036714487 | S12: =T12/14 -> 5149.2068 | T12: =R12*$S$2 -> 72088.895 | U12: 5375 | V12: 76560 | W12: =V12/$V$47 -> 0.038729142 | X12: =Y12/14 -> 6362.1114 | Y12: =W12*$X$2 -> 89069.559 | Z12: =X12+S12+N12 -> 18262.089 | AA12: =Y12+T12+O12 -> 255669.24 | AB12: =Z12/3 -> 6087.3629 | AC12: =AA12/3 -> 85223.08
A13: 9 | B13: မွန်မလေး | C13: Mon Ma Lay | D13: ရပသ | E13: Shwe Pyi Thar | F13: WS | G13: ဦးချစ်ဝိုင်း | H13: U Chit Wine | I13: 09-882250800 | J13: RSM | K13: 5190 | L13: 75140 | M13: =L13/L47 -> 0.036541521 | N13: =O13/14 -> 5496.8887 | O13: =M13*$N$2 -> 76956.442 | P13: 5070 | Q13: 72680 | R13: =Q13/Q47 -> 0.043164169 | S13: =T13/14 -> 6053.7747 | T13: =R13*$S$2 -> 84752.845 | U13: 5000 | V13: 72240 | W13: =V13/$V$47 -> 0.036543798 | X13: =Y13/14 -> 6003.1208 | Y13: =W13*$X$2 -> 84043.691 | Z13: =X13+S13+N13 -> 17553.784 | AA13: =Y13+T13+O13 -> 245752.98 | AB13: =Z13/3 -> 5851.2614 | AC13: =AA13/3 -> 81917.66
A14: 10 | B14: မြတ်မွှေး | C14: Myat Mhwe | D14: မ/ဥ | E14: North Okkalapa | F14: WS | G14: မမီးငယ် | H14: Ma Mee Nge' | I14: 09-263698010 | J14: RSM | K14: 5164 | L14: 74760 | M14: =L14/L47 -> 0.036356722 | N14: =O14/14 -> 5469.0897 | O14: =M14*$N$2 -> 76567.256 | P14: 4609 | Q14: 65578 | R14: =Q14/Q47 -> 0.038946338 | S14: =T14/14 -> 5462.2239 | T14: =R14*$S$2 -> 76471.135 | U14: 5212 | V14: 73940 | W14: =V14/$V$47 -> 0.037403772 | X14: =Y14/14 -> 6144.3902 | Y14: =W14*$X$2 -> 86021.463 | Z14: =X14+S14+N14 -> 17075.704 | AA14: =Y14+T14+O14 -> 239059.85 | AB14: =Z14/3 -> 5691.9013 | AC14: =AA14/3 -> 79686.618
A15: 11 | B15: ကိုဖိုးသက် | C15: Ko Phoe Thet | D15: တွံတေး | E15: Twantay | F15: WS | G15: မသန္တာ | H15: Ma Thandar | I15: 09-448004906 | J15: RSM | K15: 4945 | L15: 70060 | M15: =L15/L47 -> 0.034071053 | N15: =O15/14 -> 5125.2599 | O15: =M15*$N$2 -> 71753.638 | P15: 2945 | Q15: 41190 | R15: =Q15/Q47 -> 0.024462467 | S15: =T15/14 -> 3430.861 | T15: =R15*$S$2 -> 48032.054 | U15: 5000 | V15: 69170 | W15: =V15/$V$47 -> 0.034990788 | X15: =Y15/14 -> 5748.0048 | Y15: =W15*$X$2 -> 80472.067 | Z15: =X15+S15+N15 -> 14304.126 | AA15: =Y15+T15+O15 -> 200257.76 | AB15: =Z15/3 -> 4768.0419 | AC15: =AA15/3 -> 66752.586
A16: 12 | B16: မပို့မချို | C16: Ma Po Ma Cho | D16: ပလာဇာ | E16: Palazar | F16: WS | G16: မခိုင်လွင်ဦး | H16: Ma Kine Lwin Oo | I16: 09-250069370 | J16: RSM | K16: 4700 | L16: 68220 | M16: =L16/L47 -> 0.033176238 | N16: =O16/14 -> 4990.6541 | O16: =M16*$N$2 -> 69869.158 | P16: 4110 | Q16: 57980 | R16: =Q16/Q47 -> 0.034433936 | S16: =T16/14 -> 4829.3596 | T16: =R16*$S$2 -> 67611.034 | U16: 3980 | V16: 58460 | W16: =V16/$V$47 -> 0.029572958 | X16: =Y16/14 -> 4858.0072 | Y16: =W16*$X$2 -> 68012.101 | Z16: =X16+S16+N16 -> 14678.021 | AA16: =Y16+T16+O16 -> 205492.29 | AB16: =Z16/3 -> 4892.6736 | AC16: =AA16/3 -> 68497.431
A17: 13 | B17: ကိုကျော်ဆွေ | C17: Ko Kyaw Swe | D17: သန်လျင် | E17: Thanlyin | F17: WS | G17: ဦးကျော်ဆွေ | H17: U Kyaw Swe | I17: 09-5021923 | J17: RSM | K17: 3005 | L17: 41360 | M17: =L17/L47 -> 0.020113885 | N17: =O17/14 -> 3025.7029 | O17: =M17*$N$2 -> 42359.841 | P17: 2500 | Q17: 35120 | R17: =Q17/Q47 -> 0.020857534 | S17: =T17/14 -> 2925.2692 | T17: =R17*$S$2 -> 40953.769 | U17: 3505 | V17: 48020 | W17: =V17/$V$47 -> 0.024291711 | X17: =Y17/14 -> 3990.4466 | Y17: =W17*$X$2 -> 55866.252 | Z17: =X17+S17+N17 -> 9941.4187 | AA17: =Y17+T17+O17 -> 139179.86 | AB17: =Z17/3 -> 3313.8062 | AC17: =AA17/3 -> 46393.287
A18: 14 | B18: ဦးတင်အေး | C18: U Tin Aye | D18: မှော်ဘီ | E18: Hmawbi | F18: WS | G18: ဦးတင်အေး | H18: U Tin Aye | I18: 09-5075855 | J18: RSM | K18: 3168 | L18: 44916 | M18: =L18/L47 -> 0.021843212 | N18: =O18/14 -> 3285.8432 | O18: =M18*$N$2 -> 46001.804 | P18: 2895 | Q18: 40620 | R18: =Q18/Q47 -> 0.024123948 | S18: =T18/14 -> 3383.3837 | T18: =R18*$S$2 -> 47367.372 | U18: 3620 | V18: 50300 | W18: =V18/$V$47 -> 0.025445087 | X18: =Y18/14 -> 4179.9138 | Y18: =W18*$X$2 -> 58518.794 | Z18: =X18+S18+N18 -> 10849.141 | AA18: =Y18+T18+O18 -> 151887.97 | AB18: =Z18/3 -> 3616.3802 | AC18: =AA18/3 -> 50629.323
A19: 15 | B19: ဘဘကြီး | C19: Ba Ba Gyi | D19: မ/ဥ | E19: North Okkalapa | F19: WS | G19: မဇင်မာ | H19: Ma Zin Mar | I19: 09-421160411 | J19: RSM | K19: 2690 | L19: 37440 | M19: =L19/L47 -> 0.01820754 | N19: =O19/14 -> 2738.9342 | O19: =M19*$N$2 -> 38345.079 | P19: 3120 | Q19: 40830 | R19: =Q19/Q47 -> 0.024248666 | S19: =T19/14 -> 3400.8753 | T19: =R19*$S$2 -> 47612.255 | U19: 2270 | V19: 29600 | W19: =V19/$V$47 -> 0.014973649 | X19: =Y19/14 -> 2459.7505 | Y19: =W19*$X$2 -> 34436.507 | Z19: =X19+S19+N19 -> 8599.56 | AA19: =Y19+T19+O19 -> 120393.84 | AB19: =Z19/3 -> 2866.52 | AC19: =AA19/3 -> 40131.28
A20: 16 | B20: မချိုချိုလွင် | C20: Ma Cho Cho Lwin | D20: သင်္ဃန်းကျွန်း | E20: Thingangyun | F20: WS | G20: မချို | H20: Ma Cho | I20: 09-421183044 | J20: RSM | K20: 2700 | L20: 41800 | M20: =L20/L47 -> 0.020327862 | N20: =O20/14 -> 3057.8913 | O20: =M20*$N$2 -> 42810.478 | P20: 2740 | Q20: 41640 | R20: =Q20/Q47 -> 0.024729719 | S20: =T20/14 -> 3468.3431 | T20: =R20*$S$2 -> 48556.804 | U20: 2710 | V20: 41490 | W20: =V20/$V$47 -> 0.020988403 | X20: =Y20/14 -> 3447.8057 | Y20: =W20*$X$2 -> 48269.279 | Z20: =X20+S20+N20 -> 9974.04 | AA20: =Y20+T20+O20 -> 139636.56 | AB20: =Z20/3 -> 3324.68 | AC20: =AA20/3 -> 46545.52
A21: 17 | B21: ရွှေဇီးကွက် | C21: Shwe Zee Kwat | D21: မ/ဒဂုံ | E21: North Dagon | F21: WS | G21: မပပ | H21: Ma Pa Pa | I21: 09-450037338 | J21: RSM | K21: 2747 | L21: 38490 | M21: =L21/L47 -> 0.018718168 | N21: =O21/14 -> 2815.7472 | O21: =M21*$N$2 -> 39420.461 | P21: 2495 | Q21: 34990 | R21: =Q21/Q47 -> 0.020780328 | S21: =T21/14 -> 2914.4411 | T21: =R21*$S$2 -> 40802.175 | U21: 2739 | V21: 37996 | W21: =V21/$V$47 -> 0.019220905 | X21: =Y21/14 -> 3157.4554 | Y21: =W21*$X$2 -> 44204.375 | Z21: =X21+S21+N21 -> 8887.6437 | AA21: =Y21+T21+O21 -> 124427.01 | AB21: =Z21/3 -> 2962.5479 | AC21: =AA21/3 -> 41475.67
A22: 18 | B22: ရွှေဉယျာဉ် | C22: Shwe Oo Yin | D22: ရပသ | E22: Shwe Pyi Thar | F22: WS | G22: မမာမာဝေ | H22: Ma Mar Mar Wai | I22: 09-506718 | J22: RSM | K22: 2090 | L22: 30660 | M22: =L22/L47 -> 0.014910341 | N22: =O22/14 -> 2242.9413 | O22: =M22*$N$2 -> 31401.178 | P22: 2210 | Q22: 31730 | R22: =Q22/Q47 -> 0.018844236 | S22: =T22/14 -> 2642.9041 | T22: =R22*$S$2 -> 37000.657 | U22: 2795 | V22: 38720 | W22: =V22/$V$47 -> 0.019587152 | X22: =Y22/14 -> 3217.6195 | Y22: =W22*$X$2 -> 45046.674 | Z22: =X22+S22+N22 -> 8103.4649 | AA22: =Y22+T22+O22 -> 113448.51 | AB22: =Z22/3 -> 2701.155 | AC22: =AA22/3 -> 37816.17
A23: 19 | B23: ရွှေစည်းစိမ် | C23: Shwe See Sain | D23: တိုက်ကြီး | E23: Taikkyi | F23: WS | G23: မရင်ရင်ထိုက် | H23: Ma Yin Yin Htike | I23: 09-5007916 | J23: RSM | K23: 2070 | L23: 29080 | M23: =L23/L47 -> 0.014141967 | N23: =O23/14 -> 2127.3559 | O23: =M23*$N$2 -> 29782.983 | P23: 2095 | Q23: 29800 | R23: =Q23/Q47 -> 0.017698022 | S23: =T23/14 -> 2482.1476 | T23: =R23*$S$2 -> 34750.066 | U23: 2280 | V23: 32000 | W23: =V23/$V$47 -> 0.016187729 | X23: =Y23/14 -> 2659.1897 | Y23: =W23*$X$2 -> 37228.656 | Z23: =X23+S23+N23 -> 7268.6932 | AA23: =Y23+T23+O23 -> 101761.7 | AB23: =Z23/3 -> 2422.8977 | AC23: =AA23/3 -> 33920.568
A24: 20 | B24: ရွက်သစ် | C24: Yuat Thit | D24: တ/ဒဂုံ | E24: South Dagon | F24: WS | G24: ကိုဘုန်းသာ | H24: Ko Bhone Thar | I24: 09-5501732 | J24: RSM | K24: 2285 | L24: 33240 | M24: =L24/L47 -> 0.016165027 | N24: =O24/14 -> 2431.682 | O24: =M24*$N$2 -> 34043.547 | P24: 2235 | Q24: 32720 | R24: =Q24/Q47 -> 0.01943219 | S24: =T24/14 -> 2725.3647 | T24: =R24*$S$2 -> 38155.106 | U24: 1700 | V24: 24440 | W24: =V24/$V$47 -> 0.012363378 | X24: =Y24/14 -> 2030.9561 | Y24: =W24*$X$2 -> 28433.386 | Z24: =X24+S24+N24 -> 7188.0028 | AA24: =Y24+T24+O24 -> 100632.04 | AB24: =Z24/3 -> 2396.0009 | AC24: =AA24/3 -> 33544.013
A25: 21 | B25: ဒေလီယာ | C25: Dalia | D25: သာကေတ | E25: Thaketa | F25: WS | G25: မခိုင်နှင်းဝေ | H25: Khine Hnin Wai | I25: 09-775065014 | J25: RSM | K25: 1930 | L25: 28700 | M25: =L25/L47 -> 0.013957169 | N25: =O25/14 -> 2099.5569 | O25: =M25*$N$2 -> 29393.797 | P25: 1845 | Q25: 27830 | R25: =Q25/Q47 -> 0.016528052 | S25: =T25/14 -> 2318.0593 | T25: =R25*$S$2 -> 32452.83 | U25: 2017 | V25: 29770 | W25: =V25/$V$47 -> 0.015059647 | X25: =Y25/14 -> 2473.8774 | Y25: =W25*$X$2 -> 34634.284 | Z25: =X25+S25+N25 -> 6891.4936 | AA25: =Y25+T25+O25 -> 96480.911 | AB25: =Z25/3 -> 2297.1645 | AC25: =AA25/3 -> 32160.304
A26: 22 | B26: ဆွေသဟာ | C26: Shwe Tahar | D26: လသယ | E26: Hlaing Thar Yar | F26: WS | G26: ကိုစောလွင် | H26: Ko Saw Lwin | I26: 09-982218821 | J26: RSM | K26: 2030 | L26: 28680 | M26: =L26/L47 -> 0.013947442 | N26: =O26/14 -> 2098.0938 | O26: =M26*$N$2 -> 29373.313 | P26: 2025 | Q26: 28040 | R26: =Q26/Q47 -> 0.01665277 | S26: =T26/14 -> 2335.5509 | T26: =R26*$S$2 -> 32697.713 | U26: 1645 | V26: 24620 | W26: =V26/$V$47 -> 0.012454434 | X26: =Y26/14 -> 2045.9141 | Y26: =W26*$X$2 -> 28642.797 | Z26: =X26+S26+N26 -> 6479.5588 | AA26: =Y26+T26+O26 -> 90713.824 | AB26: =Z26/3 -> 2159.8529 | AC26: =AA26/3 -> 30237.941
A27: 23 | B27: ဦးအိရွှေ | C27: U Ei Shwe | D27: တွံတေး | E27: Twantay | F27: WS | G27: ကိုနိူင်လင်းအောင် | H27: Ko Naing Lin Aung | I27: 09-421094107 | J27: RSM | K27: 1960 | L27: 27100 | M27: =L27/L47 -> 0.013179069 | N27: =O27/14 -> 1982.5085 | O27: =M27*$N$2 -> 27755.118 | P27: 498 | Q27: 6910 | R27: =Q27/Q47 -> 0.0041038031 | S27: =T27/14 -> 575.55838 | T27: =R27*$S$2 -> 8057.8173 | U27: 1730 | V27: 23370 | W27: =V27/$V$47 -> 0.011822101 | X27: =Y27/14 -> 1942.0395 | Y27: =W27*$X$2 -> 27188.553 | Z27: =X27+S27+N27 -> 4500.1063 | AA27: =Y27+T27+O27 -> 63001.488 | AB27: =Z27/3 -> 1500.0354 | AC27: =AA27/3 -> 21000.496
A28: 24 | B28: ကိုရွှေသီး | C28: Ko Shwe Thee | D28: တ/ဥ | E28: South Okkalapa | F28: WS | G28: ကိုရွှေသီး | H28: Ko Shwe Thee | I28: 09-5089587 | J28: RSM | K28: 1925 | L28: 26860 | M28: =L28/L47 -> 0.013062354 | N28: =O28/14 -> 1964.9512 | O28: =M28*$N$2 -> 27509.317 | P28: 1570 | Q28: 22760 | R28: =Q28/Q47 -> 0.013517013 | S28: =T28/14 -> 1895.761 | T28: =R28*$S$2 -> 26540.654 | U28: 1900 | V28: 26400 | W28: =V28/$V$47 -> 0.013354877 | X28: =Y28/14 -> 2193.8315 | Y28: =W28*$X$2 -> 30713.641 | Z28: =X28+S28+N28 -> 6054.5437 | AA28: =Y28+T28+O28 -> 84763.612 | AB28: =Z28/3 -> 2018.1812 | AC28: =AA28/3 -> 28254.537
A29: 25 | B29: ပန်းသတင်း | C29: Pan Tatin | D29: တွံတေး | E29: Twantay | F29: WS | G29: မဝေဝေစန်း | H29: Ma Wai Wai San | I29: 09-758750975 | J29: RSM | K29: 2100 | L29: 26760 | M29: =L29/L47 -> 0.013013722 | N29: =O29/14 -> 1957.6357 | O29: =M29*$N$2 -> 27406.899 | P29: 1040 | Q29: 13680 | R29: =Q29/Q47 -> 0.008124461 | S29: =T29/14 -> 1139.4557 | T29: =R29*$S$2 -> 15952.379 | U29: 1720 | V29: 22280 | W29: =V29/$V$47 -> 0.011270706 | X29: =Y29/14 -> 1851.4608 | Y29: =W29*$X$2 -> 25920.452 | Z29: =X29+S29+N29 -> 4948.5521 | AA29: =Y29+T29+O29 -> 69279.73 | AB29: =Z29/3 -> 1649.5174 | AC29: =AA29/3 -> 23093.243
A30: 26 | B30: ရှယ်ထူး | C30: Shal Htoo | D30: လေးထောင့်ကန် | E30: Lay Daungkan | F30: WS | G30: ကိုသား | H30: Ko Thar | I30: 09-443211018 | J30: RSM | K30: 1220 | L30: 14940 | M30: =L30/L47 -> 0.0072655086 | N30: =O30/14 -> 1092.9401 | O30: =M30*$N$2 -> 15301.161 | P30: 1210 | Q30: 16740 | R30: =Q30/Q47 -> 0.0099417747 | S30: =T30/14 -> 1394.3339 | T30: =R30*$S$2 -> 19520.675 | U30: 1260 | V30: 15460 | W30: =V30/$V$47 -> 0.0078206966 | X30: =Y30/14 -> 1284.721 | Y30: =W30*$X$2 -> 17986.094 | Z30: =X30+S30+N30 -> 3771.995 | AA30: =Y30+T30+O30 -> 52807.93 | AB30: =Z30/3 -> 1257.3317 | AC30: =AA30/3 -> 17602.643
A31: 27 | B31: တော်ဝင် | C31: Taw Win | D31: ကြည့်မြင်တိုင် | E31: Kyee Myin Daing | F31: WS | G31: မဝါဝါလှိုင် | H31: Ma War War Hlaing | I31: 09-793565822 | J31: RSM | K31: 1570 | L31: 21840 | M31: =L31/L47 -> 0.010621065 | N31: =O31/14 -> 1597.7116 | O31: =M31*$N$2 -> 22367.963 | P31: 1086 | Q31: 15052 | R31: =Q31/Q47 -> 0.0089392827 | S31: =T31/14 -> 1253.7344 | T31: =R31*$S$2 -> 17552.282 | U31: 1060 | V31: 15350 | W31: =V31/$V$47 -> 0.0077650513 | X31: =Y31/14 -> 1275.5801 | Y31: =W31*$X$2 -> 17858.121 | Z31: =X31+S31+N31 -> 4127.0261 | AA31: =Y31+T31+O31 -> 57778.365 | AB31: =Z31/3 -> 1375.6754 | AC31: =AA31/3 -> 19259.455
A32: 28 | B32: ဦးလှဖုန်း | C32: U Hla Phone | D32: ကော့မှူး | E32: Kawhmu | F32: WS | G32: ဒေါ်ကြည်ကြည်ဝင်း | H32: Daw Kyi Kyi Win | I32: 09-794635642 | J32: RSM | K32: 1560 | L32: 21860 | M32: =L32/L47 -> 0.010630791 | N32: =O32/14 -> 1599.1747 | O32: =M32*$N$2 -> 22388.446 | P32: 710 | Q32: 10150 | R32: =Q32/Q47 -> 0.0060280175 | S32: =T32/14 -> 845.42946 | T32: =R32*$S$2 -> 11836.012 | U32: 1135 | V32: 16120 | W32: =V32/$V$47 -> 0.0081545685 | X32: =Y32/14 -> 1339.5668 | Y32: =W32*$X$2 -> 18753.935 | Z32: =X32+S32+N32 -> 3784.171 | AA32: =Y32+T32+O32 -> 52978.394 | AB32: =Z32/3 -> 1261.3903 | AC32: =AA32/3 -> 17659.465
A33: 29 | B33: မသီတာ | C33: Ma Thida | D33: သာကေတ | E33: Thaketa | F33: WS | G33: မသီတာထွန်း | H33: Ma Thidar Tun | I33: 09-5406284 | J33: RSM | K33: 695 | L33: 9460 | M33: =L33/L47 -> 0.0046005162 | N33: =O33/14 -> 692.04908 | O33: =M33*$N$2 -> 9688.6871 | P33: 1240 | Q33: 17780 | R33: =Q33/Q47 -> 0.010559424 | S33: =T33/14 -> 1480.9592 | T33: =R33*$S$2 -> 20733.429 | U33: 1565 | V33: 25900 | W33: =V33/$V$47 -> 0.013101943 | X33: =Y33/14 -> 2152.2817 | Y33: =W33*$X$2 -> 30131.943 | Z33: =X33+S33+N33 -> 4325.2899 | AA33: =Y33+T33+O33 -> 60554.059 | AB33: =Z33/3 -> 1441.7633 | AC33: =AA33/3 -> 20184.686
A34: 30 | B34: အနွယ်တော် | C34: A 'Nwe Taw | D34: သင်္ဃန်းကျွန်းကြီး | E34: Thingangyun Gyi | F34: WS | G34: မထက်ထက် | H34: Ma Htet Htet | I34: 09-793965694 | J34: RSM | K34: 1024 | L34: 14778 | M34: =L34/L47 -> 0.007186726 | N34: =O34/14 -> 1081.0889 | O34: =M34*$N$2 -> 15135.245 | P34: 1059 | Q34: 15268 | R34: =Q34/Q47 -> 0.0090675637 | S34: =T34/14 -> 1271.7258 | T34: =R34*$S$2 -> 17804.161 | U34: 1281 | V34: 17778 | W34: =V34/$V$47 -> 0.0089932952 | X34: =Y34/14 -> 1477.3461 | Y34: =W34*$X$2 -> 20682.845 | Z34: =X34+S34+N34 -> 3830.1608 | AA34: =Y34+T34+O34 -> 53622.251 | AB34: =Z34/3 -> 1276.7203 | AC34: =AA34/3 -> 17874.084
A35: 31 | B35: နေလ | C35: Nay La | D35: တိုက်ကြီး | E35: Taikkyi | F35: WS | G35: ဦးမိုးသက်နိူင် | H35: U Moe That Naing | I35: 09-5394567 | J35: RSM | K35: 943 | L35: 13496 | M35: =L35/L47 -> 0.0065632734 | N35: =O35/14 -> 987.30384 | O35: =M35*$N$2 -> 13822.254 | P35: 880 | Q35: 12540 | R35: =Q35/Q47 -> 0.0074474226 | S35: =T35/14 -> 1044.501 | T35: =R35*$S$2 -> 14623.014 | U35: 1137 | V35: 15974 | W35: =V35/$V$47 -> 0.008080712 | X35: =Y35/14 -> 1327.4343 | Y35: =W35*$X$2 -> 18584.08 | Z35: =X35+S35+N35 -> 3359.2391 | AA35: =Y35+T35+O35 -> 47029.348 | AB35: =Z35/3 -> 1119.7464 | AC35: =AA35/3 -> 15676.449
A36: 32 | B36: မမွှေးမွှေး | C36: Ma Mhwe Mhwe | D36: ကွမ်းခြံကုန်း | E36: Kungyangon | F36: WS | G36: မသဇင်ညွှန့် | H36: Ma Tha Zin Nyunt | I36: 09-266299311 | J36: RSM | K36: 1845 | L36: 25030 | M36: =L36/L47 -> 0.012172402 | N36: =O36/14 -> 1831.077 | O36: =M36*$N$2 -> 25635.078 | P36: 310 | Q36: 4220 | R36: =Q36/Q47 -> 0.0025062299 | S36: =T36/14 -> 351.49875 | T36: =R36*$S$2 -> 4920.9825 | U36: 1102 | V36: 15130 | W36: =V36/$V$47 -> 0.0076537607 | X36: =Y36/14 -> 1257.2981 | Y36: =W36*$X$2 -> 17602.174 | Z36: =X36+S36+N36 -> 3439.8739 | AA36: =Y36+T36+O36 -> 48158.234 | AB36: =Z36/3 -> 1146.6246 | AC36: =AA36/3 -> 16052.745
A37: 33 | B37: ဆင်မင်း | C37: Sin Min | D37: လှိုင်သာယာ | E37: Hlaing Thar Yar | F37: WS | G37: ကိုကျော်နိူင် | H37: Ko Kyaw Naing | I37: 09-775628364 | J37: RSM | K37: 778 | L37: 11035 | M37: =L37/L47 -> 0.0053664583 | N37: =O37/14 -> 807.26866 | O37: =M37*$N$2 -> 11301.761 | P37: 1015 | Q37: 14160 | R37: =Q37/Q47 -> 0.0084095299 | S37: =T37/14 -> 1179.4366 | T37: =R37*$S$2 -> 16512.112 | U37: 893 | V37: 12236 | W37: =V37/$V$47 -> 0.0061897829 | X37: =Y37/14 -> 1016.8077 | Y37: =W37*$X$2 -> 14235.307 | Z37: =X37+S37+N37 -> 3003.5129 | AA37: =Y37+T37+O37 -> 42049.18 | AB37: =Z37/3 -> 1001.171 | AC37: =AA37/3 -> 14016.393
A38: 34 | B38: မာဟန် | C38: Mar Han | D38: မှော်ဘီ | E38: Hmawbi | F38: WS | G38: ဖြူမာဟန် | H38: Phyu Mar Han | I38: 09-5160980 | J38: RSM | K38: 1025 | L38: 14224 | M38: =L38/L47 -> 0.0069173089 | N38: =O38/14 -> 1040.5609 | O38: =M38*$N$2 -> 14567.853 | P38: 521 | Q38: 7638 | R38: =Q38/Q47 -> 0.0045361574 | S38: =T38/14 -> 636.19608 | T38: =R38*$S$2 -> 8906.7451 | U38: 1032 | V38: 14428 | W38: =V38/$V$47 -> 0.0072986424 | X38: =Y38/14 -> 1198.9622 | Y38: =W38*$X$2 -> 16785.47 | Z38: =X38+S38+N38 -> 2875.7191 | AA38: =Y38+T38+O38 -> 40260.068 | AB38: =Z38/3 -> 958.57304 | AC38: =AA38/3 -> 13420.023
A39: 35 | B39: ကောင်းမွန် | C39: Kaung Mon | D39: တိုက်ကြီး | E39: Taikkyi | F39: WS | G39: မယဉ်နွယ်ဦး | H39: Ma Yin Nwal Oo | I39: 09-451311435 | J39: RSM | K39: 1205 | L39: 16720 | M39: =L39/L47 -> 0.0081311449 | N39: =O39/14 -> 1223.1565 | O39: =M39*$N$2 -> 17124.191 | P39: 695 | Q39: 9620 | R39: =Q39/Q47 -> 0.005713254 | S39: =T39/14 -> 801.28388 | T39: =R39*$S$2 -> 11217.974 | U39: 1355 | V39: 18860 | W39: =V39/$V$47 -> 0.0095406428 | X39: =Y39/14 -> 1567.2599 | Y39: =W39*$X$2 -> 21941.639 | Z39: =X39+S39+N39 -> 3591.7003 | AA39: =Y39+T39+O39 -> 50283.804 | AB39: =Z39/3 -> 1197.2334 | AC39: =AA39/3 -> 16761.268
A40: 36 | B40: သုခအောင် | C40: Thuka Aung | D40: အင်းစိန် | E40: Insein | F40: WS | G40: မနန်းကေသီ | H40: Ma Nan Kay Thi | I40: 09-790241274 | J40: KHM | K40: 800 | L40: 11530 | M40: =L40/L47 -> 0.005607183 | N40: =O40/14 -> 843.48053 | O40: =M40*$N$2 -> 11808.727 | P40: 948 | Q40: 13740 | R40: =Q40/Q47 -> 0.0081600946 | S40: =T40/14 -> 1144.4533 | T40: =R40*$S$2 -> 16022.346 | U40: 760 | V40: 11150 | W40: =V40/$V$47 -> 0.0056404119 | X40: =Y40/14 -> 926.56141 | Y40: =W40*$X$2 -> 12971.86 | Z40: =X40+S40+N40 -> 2914.4952 | AA40: =Y40+T40+O40 -> 40802.933 | AB40: =Z40/3 -> 971.49841 | AC40: =AA40/3 -> 13600.978
...

Sheet Team Targer Jan2025
A1: Team Sales Contribution % | F1: Target for Jan'25
A2: Sr No. | B2: Team | C2: Cover Area | D2: SR Name | E2: Sales Con % | F2: 2750705.8
A3: 1 | B3: Wholesales # | C3: YGN | D3: Ye Naung Ko | F3: 2123102.4
A4: 2 | B4: SemiWholesales # 1 | C4: YGN | D4: Hla Myo | F4: 226469.29
A5: 3 | B5: SemiWholesales # 2 | C5: YGN | D5: Kyaw Yin Htoo | F5: 131134.07
A6: 4 | B6: Van # 1 | C6: North Okkalapa/North Dagon | D6: Zay Paing Phyo | F6: 23000
A7: 5 | B7: Van # 2 | C7: South Dagon/Tharkayta | F7: 22000
A8: 6 | B8: Van # 3 | C8: Thingangyun/South Okkalapa/Yankin | D8: Naing Naing Aung | F8: 36000
A9: 7 | B9: Van # 4 | C9: Bahan/Downtown/Hlaing - Mayangon | F9: 37000
A10: 8 | B10: Van # 5 | C10: Thanlyin | D10: Ye Htun Aung | F10: 28000
A11: 9 | B11: Van # 6 | C11: Hlaingthayar | D11: Naing Naing Aung | F11: 18000
A12: 10 | B12: Van # 7 | C12: Mingaladon _ Hlegu | D12: Zayar Phyo | F12: 34000
A13: 11 | B13: Van # 8 | C13: Shwepyithar/Hmawbi | F13: 33000
A14: 12 | B14: Van # 9 | C14: Seikkyi Kanaunto | D14: Myo Swe Thant | F14: 39000
B15: Total | C15: YGN | F15: =SUM(F3:F14) -> 2750705.8

Sheet SMM YGN 
A1: Yangon Market - Wholesales List ( January 2025)
A2: No | B2: Names | D2: Township | F2: Type | G2: Contact Name | I2: Contact No. | J2: Responsibility | K2: January Target PK | L2: January Target Bottle | M2: 45689 | S2: 45660 | V2: 45661 | Y2: 45663 | AB2: 45664 | AE2: 45664 | AH2: 45665 | AK2: 45666 | AN2: 45667 | AQ2: 10-days Total | AT2: 45668 | AW2: 45669 | AZ2: 45670 | BC2: 45671 | BF2: 45672 | BI2: 45673 | BL2: 45674 | BO2: 45675 | BR2: 45676 | BU2: 45677 | BX2: 20-days Total | CA2: 45678 | CD2: 45679 | CG2: 45680 | CJ2: 45681 | CM2: 45682 | CP2: 45683 | CS2: 45684 | CV2: 45685 | CY2: 45686 | DB2: 45687 | DE2: Month Till Date | DH2: Achievement | DK2: Ach % | DL2: Time Spend % | DM2: Gap | DN2: 10.1.2025
M3: PKT | N3: BOT | O3: Liter | P3: PKT | Q3: BOT | R3: Liter | S3: PKT | T3: BOT | U3: Liter | V3: PKT | W3: BOT | X3: Liter | Y3: PKT | Z3: BOT | AA3: Liter | AB3: PKT | AC3: BOT | AD3: Liter | AE3: PKT | AF3: BOT | AG3: Liter | AH3: PKT | AI3: BOT | AJ3: Liter | AK3: PKT | AL3: BOT | AM3: Liter | AN3: PKT | AO3: BOT | AP3: Liter | AQ3: PKT | AR3: BOT | AS3: Liter | AT3: PKT | AU3: BOT | AV3: Liter | AW3: PKT | AX3: BOT | AY3: Liter | AZ3: PKT | BA3: BOT | BB3: Liter | BC3: PKT | BD3: BOT | BE3: Liter | BF3: PKT | BG3: BOT | BH3: Liter | BI3: PKT | BJ3: BOT | BK3: Liter | BL3: PKT | BM3: BOT | BN3: Liter | BO3: PKT | BP3: BOT | BQ3: Liter | BR3: PKT | BS3: BOT | BT3: Liter | BU3: PKT | BV3: BOT | BW3: Liter | BX3: PKT | BY3: BOT | BZ3: Liter | CA3: PKT | CB3: BOT | CC3: Liter | CD3: PKT | CE3: BOT | CF3: Liter | CG3: PKT | CH3: BOT | CI3: Liter | CJ3: PKT | CK3: BOT | CL3: Liter | CM3: PKT | CN3: BOT | CO3: Liter | CP3: PKT | CQ3: BOT | CR3: Liter | CS3: PKT | CT3: BOT | CU3: Liter | CV3: PKT | CW3: BOT | CX3: Liter | CY3: PKT | CZ3: BOT | DA3: Liter | DB3: PKT | DC3: BOT | DD3: Liter | DE3: PKT | DF3: BOT | DG3: Liter | DH3: PKT | DI3: BOT | DJ3: Liter | DN3: Average sales total | DQ3: =L45 -> 2123102.4
A4: 1 | B4: မိုးအောင် | C4: Moe Aung | D4: တ/ဒဂုံ | E4: Sount Dagon | F4: WS | G4: မမြ | H4: Ma Mya | I4: 09-740816390 | J4: YNK | K4: 20444.865 | L4: 286228.11 | M4: 500 | N4: 8960 | O4: 5734 | S4: 65 | T4: 870 | U4: 643.2 | V4: 545 | W4: 8440 | X4: 5400 | Y4: 545 | Z4: 8140 | AA4: 6096 | AB4: 1090 | AC4: 15060 | AD4: 12058.4 | AH4: 535 | AI4: 6620 | AJ4: 5876 | AK4: 550 | AL4: 8400 | AM4: 5852 | AN4: 525 | AO4: 7860 | AP4: 5694 | AQ4: =M4+P4+S4+V4+Y4+AB4+AE4+AH4+AK4+AN4 -> 4355 | AR4: =N4+Q4+T4+W4+Z4+AC4+AF4+AI4+AL4+AO4 -> 64350 | AS4: =O4+R4+U4+X4+AA4+AD4+AG4+AJ4+AM4+AP4 -> 47353.6 | BX4: =AQ4+AT4+AW4+AZ4+BC4+BF4+BI4+BL4+BO4+BR4+BU4 -> 4355 | BY4: =AR4+AU4+AX4+BA4+BD4+BG4+BJ4+BM4+BP4+BS4+BV4 -> 64350 | BZ4: =AS4+AV4+AY4+BB4+BE4+BH4+BK4+BN4+BQ4+BT4+BW4 -> 47353.6 | DE4: =P4+S4+V4+Y4+AB4+AE4+AH4+AK4+AN4+AT4+AW4+AZ4+BC4+BF4+BI4+BL4+BO4+BR4+BU4+CA4+CD4+CG4+CJ4+CM4+CP4+CS4+CV4+CY4+DB4+M4 -> 4355 | DF4: =AR4+AU4+AX4+BA4+BD4+BG4+BJ4+BM4+BP4+BS4+BV4+CB4+CE4+CH4+CK4+CN4+CQ4+CT4+CW4+CZ4+DC4 -> 64350 | DG4: =AS4+AV4+AY4+BB4+BE4+BH4+BK4+BN4+BQ4+BT4+BW4+CC4+CF4+CI4+CL4+CO4+CR4+CU4+CX4+DA4+DD4 -> 47353.6 | DH4: =မိုးအောင်!AE29 -> 4880 | DI4: =မိုးအောင်!AF27 -> 72350 | DJ4: =မိုးအောင်!AG27 -> 53297.6 | DK4: =DI4/L4 -> 0.25277042 | DL4: =10/31 -> 0.32258065 | DM4: =DK4-DL4 -> -0.069810224 | DN4: Total Achievement Sales | DQ4: =DF45 -> 418114
A5: 2 | B5: သော်တာထွန်း | C5: Thawdar Tun | D5: လသယ | E5: Hlaing Thar Yar | F5: WS | G5: ကိုသူရ | H5: Ko Thu Ya | I5: 09-954456566 | J5: YNK | K5: 16905.165 | L5: 236672.31 | M5: 530 | N5: 7500 | O5: 5892 | S5: 540 | T5: 7540 | U5: 5664 | V5: 530 | W5: 6960 | X5: 5448 | Y5: 500 | Z5: 7000 | AA5: 4480 | AB5: 530 | AC5: 7880 | AD5: 5688 | AH5: 950 | AI5: 17060 | AJ5: 12232 | AN5: 520 | AO5: 7200 | AP5: 5672 | AQ5: =M5+P5+S5+V5+Y5+AB5+AE5+AH5+AK5+AN5 -> 4100 | AR5: =N5+Q5+T5+W5+Z5+AC5+AF5+AI5+AL5+AO5 -> 61140 | AS5: =O5+R5+U5+X5+AA5+AD5+AG5+AJ5+AM5+AP5 -> 45076 | BX5: =AQ5+AT5+AW5+AZ5+BC5+BF5+BI5+BL5+BO5+BR5+BU5 -> 4100 | BY5: =AR5+AU5+AX5+BA5+BD5+BG5+BJ5+BM5+BP5+BS5+BV5 -> 61140 | BZ5: =AS5+AV5+AY5+BB5+BE5+BH5+BK5+BN5+BQ5+BT5+BW5 -> 45076 | DE5: =P5+S5+V5+Y5+AB5+AE5+AH5+AK5+AN5+AT5+AW5+AZ5+BC5+BF5+BI5+BL5+BO5+BR5+BU5+CA5+CD5+CG5+CJ5+CM5+CP5+CS5+CV5+CY5+DB5+M5 -> 4100 | DF5: =AR5+AU5+AX5+BA5+BD5+BG5+BJ5+BM5+BP5+BS5+BV5+CB5+CE5+CH5+CK5+CN5+CQ5+CT5+CW5+CZ5+DC5 -> 61140 | DG5: =AS5+AV5+AY5+BB5+BE5+BH5+BK5+BN5+BQ5+BT5+BW5+CC5+CF5+CI5+CL5+CO5+CR5+CU5+CX5+DA5+DD5 -> 45076 | DH5: =သော်တာထွန်း!AE30 -> 4610 | DI5: =သော်တာထွန်း!AF30 -> 68260 | DJ5: =သော်တာထွန်း!AG30 -> 50471.2 | DK5: =DI5/L5 -> 0.28841566 | DL5: =10/31 -> 0.32258065 | DM5: =DK5-DL5 -> -0.034164986 | DN5: Sales Percentage | DQ5: =DQ4/DQ3 -> 0.19693539
A6: 3 | B6: ရွှေဧရာ | C6: Shwe Ayeyar | D6: 16 St | E6: 16 St | F6: WS | G6: ကိုသာပိုး | H6: Ko Thar Poe | I6: 09-420029084 | J6: YNK | K6: 9192.3775 | L6: 128693.29 | AQ6: =M6+P6+S6+V6+Y6+AB6+AE6+AH6+AK6+AN6 -> 0 | AR6: =N6+Q6+T6+W6+Z6+AC6+AF6+AI6+AL6+AO6 -> 0 | AS6: =O6+R6+U6+X6+AA6+AD6+AG6+AJ6+AM6+AP6 -> 0 | BX6: =AQ6+AT6+AW6+AZ6+BC6+BF6+BI6+BL6+BO6+BR6+BU6 -> 0 | BY6: =AR6+AU6+AX6+BA6+BD6+BG6+BJ6+BM6+BP6+BS6+BV6 -> 0 | BZ6: =AS6+AV6+AY6+BB6+BE6+BH6+BK6+BN6+BQ6+BT6+BW6 -> 0 | DE6: =P6+S6+V6+Y6+AB6+AE6+AH6+AK6+AN6+AT6+AW6+AZ6+BC6+BF6+BI6+BL6+BO6+BR6+BU6+CA6+CD6+CG6+CJ6+CM6+CP6+CS6+CV6+CY6+DB6+M6 -> 0 | DF6: =AR6+AU6+AX6+BA6+BD6+BG6+BJ6+BM6+BP6+BS6+BV6+CB6+CE6+CH6+CK6+CN6+CQ6+CT6+CW6+CZ6+DC6 -> 0 | DG6: =AS6+AV6+AY6+BB6+BE6+BH6+BK6+BN6+BQ6+BT6+BW6+CC6+CF6+CI6+CL6+CO6+CR6+CU6+CX6+DA6+DD6 -> 0 | DH6: =ရွှေဧရာ!AG27 -> 0 | DI6: =ရွှေဧရာ!AH27 -> 0 | DJ6: =ရွှေဧရာ!AI27 -> 0 | DK6: =DI6/L6 -> 0 | DL6: =10/31 -> 0.32258065 | DM6: =DK6-DL6 -> -0.32258065
A7: 4 | B7: မိဘမေတ္တာ | C7: Mi Ba Myint Thar | D7: လသယ | E7: Hlaing Thar Yar | F7: WS | G7: မပိုပို | H7: Ma Po Po | I7: 09-762811856 | J7: YNK | K7: 8852.2544 | L7: 123931.56 | M7: 300 | N7: 3700 | O7: 3448 | S7: 450 | T7: 5800 | U7: 4792 | Y7: 650 | Z7: 8600 | AA7: 6584 | AH7: 630 | AI7: 8720 | AJ7: 6444.8 | AN7: 250 | AO7: 3000 | AP7: 3000 | AQ7: =M7+P7+S7+V7+Y7+AB7+AE7+AH7+AK7+AN7 -> 2280 | AR7: =N7+Q7+T7+W7+Z7+AC7+AF7+AI7+AL7+AO7 -> 29820 | AS7: =O7+R7+U7+X7+AA7+AD7+AG7+AJ7+AM7+AP7 -> 24268.8 | BX7: =AQ7+AT7+AW7+AZ7+BC7+BF7+BI7+BL7+BO7+BR7+BU7 -> 2280 | BY7: =AR7+AU7+AX7+BA7+BD7+BG7+BJ7+BM7+BP7+BS7+BV7 -> 29820 | BZ7: =AS7+AV7+AY7+BB7+BE7+BH7+BK7+BN7+BQ7+BT7+BW7 -> 24268.8 | DE7: =P7+S7+V7+Y7+AB7+AE7+AH7+AK7+AN7+AT7+AW7+AZ7+BC7+BF7+BI7+BL7+BO7+BR7+BU7+CA7+CD7+CG7+CJ7+CM7+CP7+CS7+CV7+CY7+DB7+M7 -> 2280 | DF7: =AR7+AU7+AX7+BA7+BD7+BG7+BJ7+BM7+BP7+BS7+BV7+CB7+CE7+CH7+CK7+CN7+CQ7+CT7+CW7+CZ7+DC7 -> 29820 | DG7: =AS7+AV7+AY7+BB7+BE7+BH7+BK7+BN7+BQ7+BT7+BW7+CC7+CF7+CI7+CL7+CO7+CR7+CU7+CX7+DA7+DD7 -> 24268.8 | DH7: =မိဘမေတ္တာ!AE22 -> 2760 | DI7: =မိဘမေတ္တာ!AF22 -> 37440 | DJ7: =မိဘမေတ္တာ!AG22 -> 30009.6 | DK7: =DI7/L7 -> 0.30210222 | DL7: =10/31 -> 0.32258065 | DM7: =DK7-DL7 -> -0.020478424
A8: 5 | B8: AAA | C8: A.A.A. | D8: မ/ဒဂုံ | E8: North Dagon | F8: WS | G8: မစီ | H8: Ma Si | I8: 09-790414141 | J8: YNK | K8: 7440.7995 | L8: 104171.19 | S8: 520 | T8: 8160 | U8: 5707.2 | Y8: 520 | Z8: 7380 | AA8: 5700 | AH8: 520 | AI8: 7480 | AJ8: 5692 | AQ8: =M8+P8+S8+V8+Y8+AB8+AE8+AH8+AK8+AN8 -> 1560 | AR8: =N8+Q8+T8+W8+Z8+AC8+AF8+AI8+AL8+AO8 -> 23020 | AS8: =O8+R8+U8+X8+AA8+AD8+AG8+AJ8+AM8+AP8 -> 17099.2 | BX8: =AQ8+AT8+AW8+AZ8+BC8+BF8+BI8+BL8+BO8+BR8+BU8 -> 1560 | BY8: =AR8+AU8+AX8+BA8+BD8+BG8+BJ8+BM8+BP8+BS8+BV8 -> 23020 | BZ8: =AS8+AV8+AY8+BB8+BE8+BH8+BK8+BN8+BQ8+BT8+BW8 -> 17099.2 | DE8: =P8+S8+V8+Y8+AB8+AE8+AH8+AK8+AN8+AT8+AW8+AZ8+BC8+BF8+BI8+BL8+BO8+BR8+BU8+CA8+CD8+CG8+CJ8+CM8+CP8+CS8+CV8+CY8+DB8+M8 -> 1560 | DF8: =AR8+AU8+AX8+BA8+BD8+BG8+BJ8+BM8+BP8+BS8+BV8+CB8+CE8+CH8+CK8+CN8+CQ8+CT8+CW8+CZ8+DC8 -> 23020 | DG8: =AS8+AV8+AY8+BB8+BE8+BH8+BK8+BN8+BQ8+BT8+BW8+CC8+CF8+CI8+CL8+CO8+CR8+CU8+CX8+DA8+DD8 -> 17099.2 | DH8: =AAA!AG27 -> 2080 | DI8: =AAA!AH27 -> 30400 | DJ8: =AAA!AI27 -> 22799.2 | DK8: =DI8/L8 -> 0.29182732 | DL8: =10/31 -> 0.32258065 | DM8: =DK8-DL8 -> -0.030753324
A9: 6 | B9: ပေါ်ဉီး | C9: Paw Oo | D9: ဒလ | E9: Dala | F9: WS | G9: ဦးပေါ်ဦး | H9: U Paw Oo | I9: 09-964436777 | J9: YNK | K9: 5183.645 | L9: 72571.03 | Y9: 1200 | Z9: 19000 | AA9: 11864 | AQ9: =M9+P9+S9+V9+Y9+AB9+AE9+AH9+AK9+AN9 -> 1200 | AR9: =N9+Q9+T9+W9+Z9+AC9+AF9+AI9+AL9+AO9 -> 19000 | AS9: =O9+R9+U9+X9+AA9+AD9+AG9+AJ9+AM9+AP9 -> 11864 | BX9: =AQ9+AT9+AW9+AZ9+BC9+BF9+BI9+BL9+BO9+BR9+BU9 -> 1200 | BY9: =AR9+AU9+AX9+BA9+BD9+BG9+BJ9+BM9+BP9+BS9+BV9 -> 19000 | BZ9: =AS9+AV9+AY9+BB9+BE9+BH9+BK9+BN9+BQ9+BT9+BW9 -> 11864 | DE9: =P9+S9+V9+Y9+AB9+AE9+AH9+AK9+AN9+AT9+AW9+AZ9+BC9+BF9+BI9+BL9+BO9+BR9+BU9+CA9+CD9+CG9+CJ9+CM9+CP9+CS9+CV9+CY9+DB9+M9 -> 1200 | DF9: =AR9+AU9+AX9+BA9+BD9+BG9+BJ9+BM9+BP9+BS9+BV9+CB9+CE9+CH9+CK9+CN9+CQ9+CT9+CW9+CZ9+DC9 -> 19000 | DG9: =AS9+AV9+AY9+BB9+BE9+BH9+BK9+BN9+BQ9+BT9+BW9+CC9+CF9+CI9+CL9+CO9+CR9+CU9+CX9+DA9+DD9 -> 11864 | DH9: =ပေါ်ဦး!AE21 -> 2500 | DI9: =ပေါ်ဦး!AF21 -> 36240 | DJ9: =ပေါ်ဦး!AG21 -> 24971.2 | DK9: =DI9/L9 -> 0.49937282 | DL9: =10/31 -> 0.32258065 | DM9: =DK9-DL9 -> 0.17679218
A10: 7 | B10: ဘောဂ | C10: Baw Ga | D10: သန်လျင် | E10: Thanlyin | F10: WS | G10: ကိုဇင်လင်းထွန်း | H10: Ko Zin Lin Htun | I10: 09-421022592 | J10: YNK | K10: 5883.0797 | L10: 82363.116 | M10: 565 | N10: 6990 | O10: 6460.8 | Y10: 550 | Z10: 8300 | AA10: 6148 | AN10: 550 | AO10: 8200 | AP10: 6396 | AQ10: =M10+P10+S10+V10+Y10+AB10+AE10+AH10+AK10+AN10 -> 1665 | AR10: =N10+Q10+T10+W10+Z10+AC10+AF10+AI10+AL10+AO10 -> 23490 | AS10: =O10+R10+U10+X10+AA10+AD10+AG10+AJ10+AM10+AP10 -> 19004.8 | BX10: =AQ10+AT10+AW10+AZ10+BC10+BF10+BI10+BL10+BO10+BR10+BU10 -> 1665 | BY10: =AR10+AU10+AX10+BA10+BD10+BG10+BJ10+BM10+BP10+BS10+BV10 -> 23490 | BZ10: =AS10+AV10+AY10+BB10+BE10+BH10+BK10+BN10+BQ10+BT10+BW10 -> 19004.8 | DE10: =P10+S10+V10+Y10+AB10+AE10+AH10+AK10+AN10+AT10+AW10+AZ10+BC10+BF10+BI10+BL10+BO10+BR10+BU10+CA10+CD10+CG10+CJ10+CM10+CP10+CS10+CV10+CY10+DB10+M10 -> 1665 | DF10: =AR10+AU10+AX10+BA10+BD10+BG10+BJ10+BM10+BP10+BS10+BV10+CB10+CE10+CH10+CK10+CN10+CQ10+CT10+CW10+CZ10+DC10 -> 23490 | DG10: =AS10+AV10+AY10+BB10+BE10+BH10+BK10+BN10+BQ10+BT10+BW10+CC10+CF10+CI10+CL10+CO10+CR10+CU10+CX10+DA10+DD10 -> 19004.8 | DH10: =ဘောဂ!AE21 -> 1665 | DI10: =ဘောဂ!AF21 -> 23490 | DJ10: =ဘောဂ!AG21 -> 19004.8 | DK10: =DI10/L10 -> 0.28520048 | DL10: =10/31 -> 0.32258065 | DM10: =DK10-DL10 -> -0.037380167
A11: 8 | B11: ရတနာတိုး (H) | C11: Yatanar Toe | D11: မှော်ဘီ | E11: Hmawbi | F11: WS | G11: ဦးသစ်လွင် | H11: U Thit Lwin | I11: 09-5137424 | J11: YNK | K11: 6087.3629 | L11: 85223.08 | M11: 220 | N11: 2780 | O11: 2427.2 | Y11: 200 | Z11: 2600 | AA11: 2096 | AH11: 100 | AI11: 2100 | AJ11: 1168.8 | AQ11: =M11+P11+S11+V11+Y11+AB11+AE11+AH11+AK11+AN11 -> 520 | AR11: =N11+Q11+T11+W11+Z11+AC11+AF11+AI11+AL11+AO11 -> 7480 | AS11: =O11+R11+U11+X11+AA11+AD11+AG11+AJ11+AM11+AP11 -> 5692 | BX11: =AQ11+AT11+AW11+AZ11+BC11+BF11+BI11+BL11+BO11+BR11+BU11 -> 520 | BY11: =AR11+AU11+AX11+BA11+BD11+BG11+BJ11+BM11+BP11+BS11+BV11 -> 7480 | BZ11: =AS11+AV11+AY11+BB11+BE11+BH11+BK11+BN11+BQ11+BT11+BW11 -> 5692 | DE11: =P11+S11+V11+Y11+AB11+AE11+AH11+AK11+AN11+AT11+AW11+AZ11+BC11+BF11+BI11+BL11+BO11+BR11+BU11+CA11+CD11+CG11+CJ11+CM11+CP11+CS11+CV11+CY11+DB11+M11 -> 520 | DF11: =AR11+AU11+AX11+BA11+BD11+BG11+BJ11+BM11+BP11+BS11+BV11+CB11+CE11+CH11+CK11+CN11+CQ11+CT11+CW11+CZ11+DC11 -> 7480 | DG11: =AS11+AV11+AY11+BB11+BE11+BH11+BK11+BN11+BQ11+BT11+BW11+CC11+CF11+CI11+CL11+CO11+CR11+CU11+CX11+DA11+DD11 -> 5692 | DH11: =ရတနာတိုး!AE27 -> 520 | DI11: =ရတနာတိုး!AF27 -> 7480 | DJ11: =ရတနာတိုး!AG27 -> 5692 | DK11: =DI11/L11 -> 0.087769651 | DL11: =10/31 -> 0.32258065 | DM11: =DK11-DL11 -> -0.23481099
A12: 9 | B12: မွန်မလေး | C12: Mon Ma Lay | D12: ရပသ | E12: Shwe Pyi Thar | F12: WS | G12: ဦးချစ်ဝိုင်း | H12: U Chit Wine | I12: 09-882250800 | J12: YNK | K12: 5851.2614 | L12: 81917.66 | S12: 525 | T12: 7030 | U12: 5300.8 | AK12: 350 | AL12: 6220 | AM12: 4008.8 | AQ12: =M12+P12+S12+V12+Y12+AB12+AE12+AH12+AK12+AN12 -> 875 | AR12: =N12+Q12+T12+W12+Z12+AC12+AF12+AI12+AL12+AO12 -> 13250 | AS12: =O12+R12+U12+X12+AA12+AD12+AG12+AJ12+AM12+AP12 -> 9309.6 | BX12: =AQ12+AT12+AW12+AZ12+BC12+BF12+BI12+BL12+BO12+BR12+BU12 -> 875 | BY12: =AR12+AU12+AX12+BA12+BD12+BG12+BJ12+BM12+BP12+BS12+BV12 -> 13250 | BZ12: =AS12+AV12+AY12+BB12+BE12+BH12+BK12+BN12+BQ12+BT12+BW12 -> 9309.6 | DE12: =P12+S12+V12+Y12+AB12+AE12+AH12+AK12+AN12+AT12+AW12+AZ12+BC12+BF12+BI12+BL12+BO12+BR12+BU12+CA12+CD12+CG12+CJ12+CM12+CP12+CS12+CV12+CY12+DB12+M12 -> 875 | DF12: =AR12+AU12+AX12+BA12+BD12+BG12+BJ12+BM12+BP12+BS12+BV12+CB12+CE12+CH12+CK12+CN12+CQ12+CT12+CW12+CZ12+DC12 -> 13250 | DG12: =AS12+AV12+AY12+BB12+BE12+BH12+BK12+BN12+BQ12+BT12+BW12+CC12+CF12+CI12+CL12+CO12+CR12+CU12+CX12+DA12+DD12 -> 9309.6 | DH12: =မွန်မလေး!AI19 -> 875 | DI12: =မွန်မလေး!AJ19 -> 13250 | DJ12: =မွန်မလေး!AK19 -> 9309.6 | DK12: =DI12/L12 -> 0.16174779 | DL12: =10/31 -> 0.32258065 | DM12: =DK12-DL12 -> -0.16083286
A13: 10 | B13: မြတ်မွှေး | C13: Myat Mhwe | D13: မ/ဥ | E13: North Okkalapa | F13: WS | G13: မမီးငယ် | H13: Ma Mee Nge' | I13: 09-263698010 | J13: YNK | K13: 5691.9013 | L13: 79686.618 | M13: 145 | N13: 1940 | O13: 1412 | S13: 313 | T13: 4336 | U13: 3508 | V13: 80 | W13: 1190 | X13: 809.2 | Y13: 75 | Z13: 1020 | AA13: 663.6 | AB13: 383 | AC13: 5556 | AD13: 4216 | AH13: 68 | AI13: 1076 | AJ13: 749.84 | AK13: 60 | AL13: 760 | AM13: 623.2 | AN13: 357 | AO13: 5194 | AP13: 3972.8 | AQ13: =M13+P13+S13+V13+Y13+AB13+AE13+AH13+AK13+AN13 -> 1481 | AR13: =N13+Q13+T13+W13+Z13+AC13+AF13+AI13+AL13+AO13 -> 21072 | AS13: =O13+R13+U13+X13+AA13+AD13+AG13+AJ13+AM13+AP13 -> 15954.64 | BX13: =AQ13+AT13+AW13+AZ13+BC13+BF13+BI13+BL13+BO13+BR13+BU13 -> 1481 | BY13: =AR13+AU13+AX13+BA13+BD13+BG13+BJ13+BM13+BP13+BS13+BV13 -> 21072 | BZ13: =AS13+AV13+AY13+BB13+BE13+BH13+BK13+BN13+BQ13+BT13+BW13 -> 15954.64 | DE13: =P13+S13+V13+Y13+AB13+AE13+AH13+AK13+AN13+AT13+AW13+AZ13+BC13+BF13+BI13+BL13+BO13+BR13+BU13+CA13+CD13+CG13+CJ13+CM13+CP13+CS13+CV13+CY13+DB13+M13 -> 1481 | DF13: =AR13+AU13+AX13+BA13+BD13+BG13+BJ13+BM13+BP13+BS13+BV13+CB13+CE13+CH13+CK13+CN13+CQ13+CT13+CW13+CZ13+DC13 -> 21072 | DG13: =AS13+AV13+AY13+BB13+BE13+BH13+BK13+BN13+BQ13+BT13+BW13+CC13+CF13+CI13+CL13+CO13+CR13+CU13+CX13+DA13+DD13 -> 15954.64 | DH13: =မြတ်မွှေး!AG33 -> 1481 | DI13: =မြတ်မွှေး!AH33 -> 21072 | DJ13: =မြတ်မွှေး!AI33 -> 15954.64 | DK13: =DI13/L13 -> 0.26443587 | DL13: =10/31 -> 0.32258065 | DM13: =DK13-DL13 -> -0.058144778
A14: 11 | B14: ကိုဖိုးသက် | C14: Ko Phoe Thet | D14: တွံတေး | E14: Twantay | F14: WS | G14: မသန္တာ | H14: Ma Thandar | I14: 09-448004906 | J14: YNK | K14: 4768.0419 | L14: 66752.586 | M14: 180 | N14: 2520 | O14: 1612.8 | S14: 475 | T14: 6600 | U14: 4332 | Y14: 100 | Z14: 1400 | AA14: 896 | AH14: 270 | AI14: 4100 | AJ14: 2824 | AN14: 150 | AO14: 2000 | AP14: 1496 | AQ14: =M14+P14+S14+V14+Y14+AB14+AE14+AH14+AK14+AN14 -> 1175 | AR14: =N14+Q14+T14+W14+Z14+AC14+AF14+AI14+AL14+AO14 -> 16620 | AS14: =O14+R14+U14+X14+AA14+AD14+AG14+AJ14+AM14+AP14 -> 11160.8 | BX14: =AQ14+AT14+AW14+AZ14+BC14+BF14+BI14+BL14+BO14+BR14+BU14 -> 1175 | BY14: =AR14+AU14+AX14+BA14+BD14+BG14+BJ14+BM14+BP14+BS14+BV14 -> 16620 | BZ14: =AS14+AV14+AY14+BB14+BE14+BH14+BK14+BN14+BQ14+BT14+BW14 -> 11160.8 | DE14: =P14+S14+V14+Y14+AB14+AE14+AH14+AK14+AN14+AT14+AW14+AZ14+BC14+BF14+BI14+BL14+BO14+BR14+BU14+CA14+CD14+CG14+CJ14+CM14+CP14+CS14+CV14+CY14+DB14+M14 -> 1175 | DF14: =AR14+AU14+AX14+BA14+BD14+BG14+BJ14+BM14+BP14+BS14+BV14+CB14+CE14+CH14+CK14+CN14+CQ14+CT14+CW14+CZ14+DC14 -> 16620 | DG14: =AS14+AV14+AY14+BB14+BE14+BH14+BK14+BN14+BQ14+BT14+BW14+CC14+CF14+CI14+CL14+CO14+CR14+CU14+CX14+DA14+DD14 -> 11160.8 | DH14: =ကိုဖိုးသက်!AE26 -> 1175 | DI14: =ကိုဖိုးသက်!AF26 -> 16620 | DJ14: =ကိုဖိုးသက်!AG25 -> 11160.8 | DK14: =DI14/L14 -> 0.24897912 | DL14: =10/31 -> 0.32258065 | DM14: =DK14-DL14 -> -0.073601528
A15: 12 | B15: မပို့မချို | C15: Ma Po Ma Cho | D15: ပလာဇာ | E15: Palazar | F15: WS | G15: မခိုင်လွင်ဦး | H15: Ma Kine Lwin Oo | I15: 09-250069370 | J15: YNK | K15: 4892.6736 | L15: 68497.431 | AB15: 510 | AC15: 7920 | AD15: 5612 | AN15: 510 | AO15: 7780 | AP15: 5716.8 | AQ15: =M15+P15+S15+V15+Y15+AB15+AE15+AH15+AK15+AN15 -> 1020 | AR15: =N15+Q15+T15+W15+Z15+AC15+AF15+AI15+AL15+AO15 -> 15700 | AS15: =O15+R15+U15+X15+AA15+AD15+AG15+AJ15+AM15+AP15 -> 11328.8 | BX15: =AQ15+AT15+AW15+AZ15+BC15+BF15+BI15+BL15+BO15+BR15+BU15 -> 1020 | BY15: =AR15+AU15+AX15+BA15+BD15+BG15+BJ15+BM15+BP15+BS15+BV15 -> 15700 | BZ15: =AS15+AV15+AY15+BB15+BE15+BH15+BK15+BN15+BQ15+BT15+BW15 -> 11328.8 | DE15: =P15+S15+V15+Y15+AB15+AE15+AH15+AK15+AN15+AT15+AW15+AZ15+BC15+BF15+BI15+BL15+BO15+BR15+BU15+CA15+CD15+CG15+CJ15+CM15+CP15+CS15+CV15+CY15+DB15+M15 -> 1020 | DF15: =AR15+AU15+AX15+BA15+BD15+BG15+BJ15+BM15+BP15+BS15+BV15+CB15+CE15+CH15+CK15+CN15+CQ15+CT15+CW15+CZ15+DC15 -> 15700 | DG15: =AS15+AV15+AY15+BB15+BE15+BH15+BK15+BN15+BQ15+BT15+BW15+CC15+CF15+CI15+CL15+CO15+CR15+CU15+CX15+DA15+DD15 -> 11328.8 | DH15: =မပို့မချို!AE22 -> 1020 | DI15: =မပို့မချို!AF22 -> 15700 | DJ15: =မပို့မချို!AG22 -> 11328.8 | DK15: =DI15/L15 -> 0.22920568 | DL15: =10/31 -> 0.32258065 | DM15: =DK15-DL15 -> -0.093374969
A16: 13 | B16: ကိုကျော်ဆွေ | C16: Ko Kyaw Swe | D16: သန်လျင် | E16: Thanlyin | F16: WS | G16: ဦးကျော်ဆွေ | H16: U Kyaw Swe | I16: 09-5021923 | J16: YNK | K16: 3313.8062 | L16: 46393.287 | V16: 75 | W16: 960 | X16: 808.8 | AQ16: =M16+P16+S16+V16+Y16+AB16+AE16+AH16+AK16+AN16 -> 75 | AR16: =N16+Q16+T16+W16+Z16+AC16+AF16+AI16+AL16+AO16 -> 960 | AS16: =O16+R16+U16+X16+AA16+AD16+AG16+AJ16+AM16+AP16 -> 808.8 | BX16: =AQ16+AT16+AW16+AZ16+BC16+BF16+BI16+BL16+BO16+BR16+BU16 -> 75 | BY16: =AR16+AU16+AX16+BA16+BD16+BG16+BJ16+BM16+BP16+BS16+BV16 -> 960 | BZ16: =AS16+AV16+AY16+BB16+BE16+BH16+BK16+BN16+BQ16+BT16+BW16 -> 808.8 | DE16: =P16+S16+V16+Y16+AB16+AE16+AH16+AK16+AN16+AT16+AW16+AZ16+BC16+BF16+BI16+BL16+BO16+BR16+BU16+CA16+CD16+CG16+CJ16+CM16+CP16+CS16+CV16+CY16+DB16+M16 -> 75 | DF16: =AR16+AU16+AX16+BA16+BD16+BG16+BJ16+BM16+BP16+BS16+BV16+CB16+CE16+CH16+CK16+CN16+CQ16+CT16+CW16+CZ16+DC16 -> 960 | DG16: =AS16+AV16+AY16+BB16+BE16+BH16+BK16+BN16+BQ16+BT16+BW16+CC16+CF16+CI16+CL16+CO16+CR16+CU16+CX16+DA16+DD16 -> 808.8 | DH16: =ကိုကျော်ဆွေ!AE20 -> 75 | DI16: =ကိုကျော်ဆွေ!AF20 -> 960 | DJ16: =ကိုကျော်ဆွေ!AG20 -> 808.8 | DK16: =DI16/L16 -> 0.020692649 | DL16: =10/31 -> 0.32258065 | DM16: =DK16-DL16 -> -0.301888
A17: 14 | B17: ဦးတင်အေး | C17: U Tin Aye | D17: မှော်ဘီ | E17: Hmawbi | F17: WS | G17: ဦးတင်အေး | H17: U Tin Aye | I17: 09-5075855 | J17: YNK | K17: 3616.3802 | L17: 50629.323 | S17: 270 | T17: 3680 | U17: 2794 | AB17: 250 | AC17: 3400 | AD17: 2392 | AK17: 250 | AL17: 3400 | AM17: 2392 | AQ17: =M17+P17+S17+V17+Y17+AB17+AE17+AH17+AK17+AN17 -> 770 | AR17: =N17+Q17+T17+W17+Z17+AC17+AF17+AI17+AL17+AO17 -> 10480 | AS17: =O17+R17+U17+X17+AA17+AD17+AG17+AJ17+AM17+AP17 -> 7578 | BX17: =AQ17+AT17+AW17+AZ17+BC17+BF17+BI17+BL17+BO17+BR17+BU17 -> 770 | BY17: =AR17+AU17+AX17+BA17+BD17+BG17+BJ17+BM17+BP17+BS17+BV17 -> 10480 | BZ17: =AS17+AV17+AY17+BB17+BE17+BH17+BK17+BN17+BQ17+BT17+BW17 -> 7578 | DE17: =P17+S17+V17+Y17+AB17+AE17+AH17+AK17+AN17+AT17+AW17+AZ17+BC17+BF17+BI17+BL17+BO17+BR17+BU17+CA17+CD17+CG17+CJ17+CM17+CP17+CS17+CV17+CY17+DB17+M17 -> 770 | DF17: =AR17+AU17+AX17+BA17+BD17+BG17+BJ17+BM17+BP17+BS17+BV17+CB17+CE17+CH17+CK17+CN17+CQ17+CT17+CW17+CZ17+DC17 -> 10480 | DG17: =AS17+AV17+AY17+BB17+BE17+BH17+BK17+BN17+BQ17+BT17+BW17+CC17+CF17+CI17+CL17+CO17+CR17+CU17+CX17+DA17+DD17 -> 7578 | DH17: =ဦးတင်အေး!AE24 -> 770 | DI17: =ဦးတင်အေး!AF24 -> 10480 | DJ17: =ဦးတင်အေး!AG24 -> 7578 | DK17: =DI17/L17 -> 0.20699467 | DL17: =10/31 -> 0.32258065 | DM17: =DK17-DL17 -> -0.11558598
A18: 15 | B18: ဘဘကြီး | C18: Ba Ba Gyi | D18: မ/ဥ | E18: North Okkalapa | F18: WS | G18: မဇင်မာ | H18: Ma Zin Mar | I18: 09-421160411 | J18: YNK | K18: 2866.52 | L18: 40131.28 | AK18: 20 | AL18: 800 | AM18: 280 | AQ18: =M18+P18+S18+V18+Y18+AB18+AE18+AH18+AK18+AN18 -> 20 | AR18: =N18+Q18+T18+W18+Z18+AC18+AF18+AI18+AL18+AO18 -> 800 | AS18: =O18+R18+U18+X18+AA18+AD18+AG18+AJ18+AM18+AP18 -> 280 | BX18: =AQ18+AT18+AW18+AZ18+BC18+BF18+BI18+BL18+BO18+BR18+BU18 -> 20 | BY18: =AR18+AU18+AX18+BA18+BD18+BG18+BJ18+BM18+BP18+BS18+BV18 -> 800 | BZ18: =AS18+AV18+AY18+BB18+BE18+BH18+BK18+BN18+BQ18+BT18+BW18 -> 280 | DE18: =P18+S18+V18+Y18+AB18+AE18+AH18+AK18+AN18+AT18+AW18+AZ18+BC18+BF18+BI18+BL18+BO18+BR18+BU18+CA18+CD18+CG18+CJ18+CM18+CP18+CS18+CV18+CY18+DB18+M18 -> 20 | DF18: =AR18+AU18+AX18+BA18+BD18+BG18+BJ18+BM18+BP18+BS18+BV18+CB18+CE18+CH18+CK18+CN18+CQ18+CT18+CW18+CZ18+DC18 -> 800 | DG18: =AS18+AV18+AY18+BB18+BE18+BH18+BK18+BN18+BQ18+BT18+BW18+CC18+CF18+CI18+CL18+CO18+CR18+CU18+CX18+DA18+DD18 -> 280 | DH18: =ဘဘကြီး!AE27 -> 20 | DI18: =ဘဘကြီး!AF27 -> 800 | DJ18: =ဘဘကြီး!AG27 -> 280 | DK18: =DI18/L18 -> 0.019934575 | DL18: =10/31 -> 0.32258065 | DM18: =DK18-DL18 -> -0.30264607
A19: 16 | B19: မချိုချိုလွင် | C19: Ma Cho Cho Lwin | D19: သင်္ဃန်းကျွန်း | E19: Thingangyun | F19: WS | G19: မချို | H19: Ma Cho | I19: 09-421183044 | J19: YNK | K19: 1257 | L19: 17602.643 | AB19: 500 | AC19: 7240 | AD19: 5338 | AQ19: =M19+P19+S19+V19+Y19+AB19+AE19+AH19+AK19+AN19 -> 500 | AR19: =N19+Q19+T19+W19+Z19+AC19+AF19+AI19+AL19+AO19 -> 7240 | AS19: =O19+R19+U19+X19+AA19+AD19+AG19+AJ19+AM19+AP19 -> 5338 | BX19: =AQ19+AT19+AW19+AZ19+BC19+BF19+BI19+BL19+BO19+BR19+BU19 -> 500 | BY19: =AR19+AU19+AX19+BA19+BD19+BG19+BJ19+BM19+BP19+BS19+BV19 -> 7240 | BZ19: =AS19+AV19+AY19+BB19+BE19+BH19+BK19+BN19+BQ19+BT19+BW19 -> 5338 | DE19: =P19+S19+V19+Y19+AB19+AE19+AH19+AK19+AN19+AT19+AW19+AZ19+BC19+BF19+BI19+BL19+BO19+BR19+BU19+CA19+CD19+CG19+CJ19+CM19+CP19+CS19+CV19+CY19+DB19+M19 -> 500 | DF19: =AR19+AU19+AX19+BA19+BD19+BG19+BJ19+BM19+BP19+BS19+BV19+CB19+CE19+CH19+CK19+CN19+CQ19+CT19+CW19+CZ19+DC19 -> 7240 | DG19: =AS19+AV19+AY19+BB19+BE19+BH19+BK19+BN19+BQ19+BT19+BW19+CC19+CF19+CI19+CL19+CO19+CR19+CU19+CX19+DA19+DD19 -> 5338 | DH19: ='မချိုချိုလွင် '!AE21 -> 500 | DI19: ='မချိုချိုလွင် '!AF21 -> 7240 | DJ19: ='မချိုချိုလွင် '!AG21 -> 5338 | DK19: =DI19/L19 -> 0.41130186 | DL19: =10/31 -> 0.32258065 | DM19: =DK19-DL19 -> 0.088721217
A20: 17 | B20: ရွှေဇီးကွက် | C20: Shwe Zee Kwat | D20: မ/ဒဂုံ | E20: North Dagon | F20: WS | G20: မပပ | H20: Ma Pa Pa | I20: 09-450037338 | J20: YNK | K20: 2962.5479 | L20: 41475.67 | AQ20: =M20+P20+S20+V20+Y20+AB20+AE20+AH20+AK20+AN20 -> 0 | AR20: =N20+Q20+T20+W20+Z20+AC20+AF20+AI20+AL20+AO20 -> 0 | AS20: =O20+R20+U20+X20+AA20+AD20+AG20+AJ20+AM20+AP20 -> 0 | BX20: =AQ20+AT20+AW20+AZ20+BC20+BF20+BI20+BL20+BO20+BR20+BU20 -> 0 | BY20: =AR20+AU20+AX20+BA20+BD20+BG20+BJ20+BM20+BP20+BS20+BV20 -> 0 | BZ20: =AS20+AV20+AY20+BB20+BE20+BH20+BK20+BN20+BQ20+BT20+BW20 -> 0 | DE20: =P20+S20+V20+Y20+AB20+AE20+AH20+AK20+AN20+AT20+AW20+AZ20+BC20+BF20+BI20+BL20+BO20+BR20+BU20+CA20+CD20+CG20+CJ20+CM20+CP20+CS20+CV20+CY20+DB20+M20 -> 0 | DF20: =AR20+AU20+AX20+BA20+BD20+BG20+BJ20+BM20+BP20+BS20+BV20+CB20+CE20+CH20+CK20+CN20+CQ20+CT20+CW20+CZ20+DC20 -> 0 | DG20: =AS20+AV20+AY20+BB20+BE20+BH20+BK20+BN20+BQ20+BT20+BW20+CC20+CF20+CI20+CL20+CO20+CR20+CU20+CX20+DA20+DD20 -> 0 | DH20: =ရွှေဇီးကွက်!AE29 -> 0 | DI20: =ရွှေဇီးကွက်!AF29 -> 0 | DJ20: =ရွှေဇီးကွက်!AG29 -> 0 | DK20: =DI20/L20 -> 0 | DL20: =10/31 -> 0.32258065 | DM20: =DK20-DL20 -> -0.32258065
A21: 18 | B21: ရွှေဉယျာဉ် | C21: Shwe Oo Yin | D21: ရပသ | E21: Shwe Pyi Thar | F21: WS | G21: မမာမာဝေ | H21: Ma Mar Mar Wai | I21: 09-506718 | J21: YNK | K21: 2701.155 | L21: 37816.17 | M21: 290 | N21: 4380 | O21: 3003.2 | AB21: 200 | AC21: 2600 | AD21: 2096 | AQ21: =M21+P21+S21+V21+Y21+AB21+AE21+AH21+AK21+AN21 -> 490 | AR21: =N21+Q21+T21+W21+Z21+AC21+AF21+AI21+AL21+AO21 -> 6980 | AS21: =O21+R21+U21+X21+AA21+AD21+AG21+AJ21+AM21+AP21 -> 5099.2 | BX21: =AQ21+AT21+AW21+AZ21+BC21+BF21+BI21+BL21+BO21+BR21+BU21 -> 490 | BY21: =AR21+AU21+AX21+BA21+BD21+BG21+BJ21+BM21+BP21+BS21+BV21 -> 6980 | BZ21: =AS21+AV21+AY21+BB21+BE21+BH21+BK21+BN21+BQ21+BT21+BW21 -> 5099.2 | DE21: =P21+S21+V21+Y21+AB21+AE21+AH21+AK21+AN21+AT21+AW21+AZ21+BC21+BF21+BI21+BL21+BO21+BR21+BU21+CA21+CD21+CG21+CJ21+CM21+CP21+CS21+CV21+CY21+DB21+M21 -> 490 | DF21: =AR21+AU21+AX21+BA21+BD21+BG21+BJ21+BM21+BP21+BS21+BV21+CB21+CE21+CH21+CK21+CN21+CQ21+CT21+CW21+CZ21+DC21 -> 6980 | DG21: =AS21+AV21+AY21+BB21+BE21+BH21+BK21+BN21+BQ21+BT21+BW21+CC21+CF21+CI21+CL21+CO21+CR21+CU21+CX21+DA21+DD21 -> 5099.2 | DH21: =ရွှေဉယျာဉ်!AE21 -> 490 | DI21: =ရွှေဉယျာဉ်!AF21 -> 6980 | DJ21: =ရွှေဉယျာဉ်!AG21 -> 5099.2 | DK21: =DI21/L21 -> 0.18457713 | DL21: =10/31 -> 0.32258065 | DM21: =DK21-DL21 -> -0.13800352
A22: 19 | B22: ရွှေစည်းစိမ် | C22: Shwe See Sain | D22: တိုက်ကြီး | E22: Taikkyi | F22: WS | G22: မရင်ရင်ထိုက် | H22: Ma Yin Yin Htike | I22: 09-5007916 | J22: YNK | K22: 2422.8977 | L22: 33920.568 | M22: 290 | N22: 4180 | O22: 3307.2 | V22: 100 | W22: 1400 | X22: 896 | Y22: 260 | Z22: 4160 | AA22: 2876 | AK22: 260 | AL22: 4080 | AM22: 2685.6 | AN22: 250 | AO22: 3100 | AP22: 2848 | AQ22: =M22+P22+S22+V22+Y22+AB22+AE22+AH22+AK22+AN22 -> 1160 | AR22: =N22+Q22+T22+W22+Z22+AC22+AF22+AI22+AL22+AO22 -> 16920 | AS22: =O22+R22+U22+X22+AA22+AD22+AG22+AJ22+AM22+AP22 -> 12612.8 | BX22: =AQ22+AT22+AW22+AZ22+BC22+BF22+BI22+BL22+BO22+BR22+BU22 -> 1160 | BY22: =AR22+AU22+AX22+BA22+BD22+BG22+BJ22+BM22+BP22+BS22+BV22 -> 16920 | BZ22: =AS22+AV22+AY22+BB22+BE22+BH22+BK22+BN22+BQ22+BT22+BW22 -> 12612.8 | DE22: =P22+S22+V22+Y22+AB22+AE22+AH22+AK22+AN22+AT22+AW22+AZ22+BC22+BF22+BI22+BL22+BO22+BR22+BU22+CA22+CD22+CG22+CJ22+CM22+CP22+CS22+CV22+CY22+DB22+M22 -> 1160 | DF22: =AR22+AU22+AX22+BA22+BD22+BG22+BJ22+BM22+BP22+BS22+BV22+CB22+CE22+CH22+CK22+CN22+CQ22+CT22+CW22+CZ22+DC22 -> 16920 | DG22: =AS22+AV22+AY22+BB22+BE22+BH22+BK22+BN22+BQ22+BT22+BW22+CC22+CF22+CI22+CL22+CO22+CR22+CU22+CX22+DA22+DD22 -> 12612.8 | DH22: =ရွှေစည်းစိမ်!AE20 -> 1160 | DI22: =ရွှေစည်းစိမ်!AF20 -> 16920 | DJ22: =ရွှေစည်းစိမ်!AG20 -> 12612.8 | DK22: =DI22/L22 -> 0.4988124 | DL22: =10/31 -> 0.32258065 | DM22: =DK22-DL22 -> 0.17623175
A23: 20 | B23: ရွက်သစ် | C23: Yuat Thit | D23: တ/ဒဂုံ | E23: South Dagon | F23: WS | G23: ကိုဘုန်းသာ | H23: Ko Bhone Thar | I23: 09-5501732 | J23: YNK | K23: 2396.0009 | L23: 33544.013 | S23: 50 | T23: 700 | U23: 448 | Y23: 20 | Z23: 280 | AA23: 179.2 | AH23: 50 | AI23: 700 | AJ23: 448 | AQ23: =M23+P23+S23+V23+Y23+AB23+AE23+AH23+AK23+AN23 -> 120 | AR23: =N23+Q23+T23+W23+Z23+AC23+AF23+AI23+AL23+AO23 -> 1680 | AS23: =O23+R23+U23+X23+AA23+AD23+AG23+AJ23+AM23+AP23 -> 1075.2 | BX23: =AQ23+AT23+AW23+AZ23+BC23+BF23+BI23+BL23+BO23+BR23+BU23 -> 120 | BY23: =AR23+AU23+AX23+BA23+BD23+BG23+BJ23+BM23+BP23+BS23+BV23 -> 1680 | BZ23: =AS23+AV23+AY23+BB23+BE23+BH23+BK23+BN23+BQ23+BT23+BW23 -> 1075.2 | DE23: =P23+S23+V23+Y23+AB23+AE23+AH23+AK23+AN23+AT23+AW23+AZ23+BC23+BF23+BI23+BL23+BO23+BR23+BU23+CA23+CD23+CG23+CJ23+CM23+CP23+CS23+CV23+CY23+DB23+M23 -> 120 | DF23: =AR23+AU23+AX23+BA23+BD23+BG23+BJ23+BM23+BP23+BS23+BV23+CB23+CE23+CH23+CK23+CN23+CQ23+CT23+CW23+CZ23+DC23 -> 1680 | DG23: =AS23+AV23+AY23+BB23+BE23+BH23+BK23+BN23+BQ23+BT23+BW23+CC23+CF23+CI23+CL23+CO23+CR23+CU23+CX23+DA23+DD23 -> 1075.2 | DH23: =ရွက်သစ်!AE19 -> 120 | DI23: =ရွက်သစ်!AF19 -> 1680 | DJ23: =ရွက်သစ်!AG19 -> 1075.2 | DK23: =DI23/L23 -> 0.050083453 | DL23: =10/31 -> 0.32258065 | DM23: =DK23-DL23 -> -0.27249719
A24: 21 | B24: ဒေလီယာ | C24: Dalia | D24: သာကေတ | E24: Thaketa | F24: WS | G24: မခိုင်နှင်းဝေ | H24: Khine Hnin Wai | I24: 09-775065014 | J24: YNK | K24: 2297.1645 | L24: 32160.304 | M24: 50 | N24: 600 | O24: 600 | S24: 100 | T24: 1820 | U24: 1148.8 | AB24: 95 | AC24: 1480 | AD24: 1044.8 | AK24: 50 | AL24: 640 | AM24: 539.2 | AQ24: =M24+P24+S24+V24+Y24+AB24+AE24+AH24+AK24+AN24 -> 295 | AR24: =N24+Q24+T24+W24+Z24+AC24+AF24+AI24+AL24+AO24 -> 4540 | AS24: =O24+R24+U24+X24+AA24+AD24+AG24+AJ24+AM24+AP24 -> 3332.8 | BX24: =AQ24+AT24+AW24+AZ24+BC24+BF24+BI24+BL24+BO24+BR24+BU24 -> 295 | BY24: =AR24+AU24+AX24+BA24+BD24+BG24+BJ24+BM24+BP24+BS24+BV24 -> 4540 | BZ24: =AS24+AV24+AY24+BB24+BE24+BH24+BK24+BN24+BQ24+BT24+BW24 -> 3332.8 | DE24: =P24+S24+V24+Y24+AB24+AE24+AH24+AK24+AN24+AT24+AW24+AZ24+BC24+BF24+BI24+BL24+BO24+BR24+BU24+CA24+CD24+CG24+CJ24+CM24+CP24+CS24+CV24+CY24+DB24+M24 -> 295 | DF24: =AR24+AU24+AX24+BA24+BD24+BG24+BJ24+BM24+BP24+BS24+BV24+CB24+CE24+CH24+CK24+CN24+CQ24+CT24+CW24+CZ24+DC24 -> 4540 | DG24: =AS24+AV24+AY24+BB24+BE24+BH24+BK24+BN24+BQ24+BT24+BW24+CC24+CF24+CI24+CL24+CO24+CR24+CU24+CX24+DA24+DD24 -> 3332.8 | DH24: =ဒေလီယာ!AE25 -> 295 | DI24: =ဒေလီယာ!AF25 -> 4540 | DJ24: =ဒေလီယာ!AG25 -> 3332.8 | DK24: =DI24/L24 -> 0.14116782 | DL24: =10/31 -> 0.32258065 | DM24: =DK24-DL24 -> -0.18141282
A25: 22 | B25: ဆွေသဟာ | C25: Shwe Tahar | D25: လသယ | E25: Hlaing Thar Yar | F25: WS | G25: ကိုစောလွင် | H25: Ko Saw Lwin | I25: 09-982218821 | J25: YNK | K25: 2159.8529 | L25: 30237.941 | AQ25: =M25+P25+S25+V25+Y25+AB25+AE25+AH25+AK25+AN25 -> 0 | AR25: =N25+Q25+T25+W25+Z25+AC25+AF25+AI25+AL25+AO25 -> 0 | AS25: =O25+R25+U25+X25+AA25+AD25+AG25+AJ25+AM25+AP25 -> 0 | BX25: =AQ25+AT25+AW25+AZ25+BC25+BF25+BI25+BL25+BO25+BR25+BU25 -> 0 | BY25: =AR25+AU25+AX25+BA25+BD25+BG25+BJ25+BM25+BP25+BS25+BV25 -> 0 | BZ25: =AS25+AV25+AY25+BB25+BE25+BH25+BK25+BN25+BQ25+BT25+BW25 -> 0 | DE25: =P25+S25+V25+Y25+AB25+AE25+AH25+AK25+AN25+AT25+AW25+AZ25+BC25+BF25+BI25+BL25+BO25+BR25+BU25+CA25+CD25+CG25+CJ25+CM25+CP25+CS25+CV25+CY25+DB25+M25 -> 0 | DF25: =AR25+AU25+AX25+BA25+BD25+BG25+BJ25+BM25+BP25+BS25+BV25+CB25+CE25+CH25+CK25+CN25+CQ25+CT25+CW25+CZ25+DC25 -> 0 | DG25: =AS25+AV25+AY25+BB25+BE25+BH25+BK25+BN25+BQ25+BT25+BW25+CC25+CF25+CI25+CL25+CO25+CR25+CU25+CX25+DA25+DD25 -> 0 | DH25: =ဆွေသဟာ!AE21 -> 0 | DI25: =ဆွေသဟာ!AF21 -> 0 | DJ25: =ဆွေသဟာ!AG21 -> 0 | DK25: =DI25/L25 -> 0 | DL25: =10/31 -> 0.32258065 | DM25: =DK25-DL25 -> -0.32258065
A26: 23 | B26: ဦးအိရွှေ | C26: U Ei Shwe | D26: တွံတေး | E26: Twantay | F26: WS | G26: ကိုနိူင်လင်းအောင် | H26: Ko Naing Lin Aung | I26: 09-421094107 | J26: YNK | K26: 1500.0354 | L26: 21000.496 | M26: 35 | N26: 460 | O26: 359.2 | Y26: 100 | Z26: 1200 | AA26: 1200 | AK26: 115 | AL26: 1580 | AM26: 1076 | AQ26: =M26+P26+S26+V26+Y26+AB26+AE26+AH26+AK26+AN26 -> 250 | AR26: =N26+Q26+T26+W26+Z26+AC26+AF26+AI26+AL26+AO26 -> 3240 | AS26: =O26+R26+U26+X26+AA26+AD26+AG26+AJ26+AM26+AP26 -> 2635.2 | BX26: =AQ26+AT26+AW26+AZ26+BC26+BF26+BI26+BL26+BO26+BR26+BU26 -> 250 | BY26: =AR26+AU26+AX26+BA26+BD26+BG26+BJ26+BM26+BP26+BS26+BV26 -> 3240 | BZ26: =AS26+AV26+AY26+BB26+BE26+BH26+BK26+BN26+BQ26+BT26+BW26 -> 2635.2 | DE26: =P26+S26+V26+Y26+AB26+AE26+AH26+AK26+AN26+AT26+AW26+AZ26+BC26+BF26+BI26+BL26+BO26+BR26+BU26+CA26+CD26+CG26+CJ26+CM26+CP26+CS26+CV26+CY26+DB26+M26 -> 250 | DF26: =AR26+AU26+AX26+BA26+BD26+BG26+BJ26+BM26+BP26+BS26+BV26+CB26+CE26+CH26+CK26+CN26+CQ26+CT26+CW26+CZ26+DC26 -> 3240 | DG26: =AS26+AV26+AY26+BB26+BE26+BH26+BK26+BN26+BQ26+BT26+BW26+CC26+CF26+CI26+CL26+CO26+CR26+CU26+CX26+DA26+DD26 -> 2635.2 | DH26: =ဦးအိရွှေ!AE21 -> 250 | DI26: =ဦးအိရွှေ!AF21 -> 3240 | DJ26: =ဦးအိရွှေ!AG21 -> 2635.2 | DK26: =DI26/L26 -> 0.15428207 | DL26: =10/31 -> 0.32258065 | DM26: =DK26-DL26 -> -0.16829858
A27: 24 | B27: ကိုရွှေသီး | C27: Ko Shwe Thee | D27: တ/ဥ | E27: South Okkalapa | F27: WS | G27: ကိုရွှေသီး | H27: Ko Shwe Thee | I27: 09-5089587 | J27: YNK | K27: 2018.1812 | L27: 28254.537 | AQ27: =M27+P27+S27+V27+Y27+AB27+AE27+AH27+AK27+AN27 -> 0 | AR27: =N27+Q27+T27+W27+Z27+AC27+AF27+AI27+AL27+AO27 -> 0 | AS27: =O27+R27+U27+X27+AA27+AD27+AG27+AJ27+AM27+AP27 -> 0 | BX27: =AQ27+AT27+AW27+AZ27+BC27+BF27+BI27+BL27+BO27+BR27+BU27 -> 0 | BY27: =AR27+AU27+AX27+BA27+BD27+BG27+BJ27+BM27+BP27+BS27+BV27 -> 0 | BZ27: =AS27+AV27+AY27+BB27+BE27+BH27+BK27+BN27+BQ27+BT27+BW27 -> 0 | DE27: =P27+S27+V27+Y27+AB27+AE27+AH27+AK27+AN27+AT27+AW27+AZ27+BC27+BF27+BI27+BL27+BO27+BR27+BU27+CA27+CD27+CG27+CJ27+CM27+CP27+CS27+CV27+CY27+DB27+M27 -> 0 | DF27: =AR27+AU27+AX27+BA27+BD27+BG27+BJ27+BM27+BP27+BS27+BV27+CB27+CE27+CH27+CK27+CN27+CQ27+CT27+CW27+CZ27+DC27 -> 0 | DG27: =AS27+AV27+AY27+BB27+BE27+BH27+BK27+BN27+BQ27+BT27+BW27+CC27+CF27+CI27+CL27+CO27+CR27+CU27+CX27+DA27+DD27 -> 0 | DH27: =ကိုရွှေသီး!AE19 -> 0 | DI27: =ကိုရွှေသီး!AF19 -> 0 | DJ27: =ကိုရွှေသီး!AG19 -> 0 | DK27: =DI27/L27 -> 0 | DL27: =10/31 -> 0.32258065 | DM27: =DK27-DL27 -> -0.32258065
A28: 25 | B28: ပန်းသတင်း | C28: Pan Tatin | D28: တွံတေး | E28: Twantay | F28: WS | G28: မဝေဝေစန်း | H28: Ma Wai Wai San | I28: 09-758750975 | J28: YNK | K28: 1649.5174 | L28: 23093.243 | Y28: 530 | Z28: 7320 | AA28: 5792 | AQ28: =M28+P28+S28+V28+Y28+AB28+AE28+AH28+AK28+AN28 -> 530 | AR28: =N28+Q28+T28+W28+Z28+AC28+AF28+AI28+AL28+AO28 -> 7320 | AS28: =O28+R28+U28+X28+AA28+AD28+AG28+AJ28+AM28+AP28 -> 5792 | BX28: =AQ28+AT28+AW28+AZ28+BC28+BF28+BI28+BL28+BO28+BR28+BU28 -> 530 | BY28: =AR28+AU28+AX28+BA28+BD28+BG28+BJ28+BM28+BP28+BS28+BV28 -> 7320 | BZ28: =AS28+AV28+AY28+BB28+BE28+BH28+BK28+BN28+BQ28+BT28+BW28 -> 5792 | DE28: =P28+S28+V28+Y28+AB28+AE28+AH28+AK28+AN28+AT28+AW28+AZ28+BC28+BF28+BI28+BL28+BO28+BR28+BU28+CA28+CD28+CG28+CJ28+CM28+CP28+CS28+CV28+CY28+DB28+M28 -> 530 | DF28: =AR28+AU28+AX28+BA28+BD28+BG28+BJ28+BM28+BP28+BS28+BV28+CB28+CE28+CH28+CK28+CN28+CQ28+CT28+CW28+CZ28+DC28 -> 7320 | DG28: =AS28+AV28+AY28+BB28+BE28+BH28+BK28+BN28+BQ28+BT28+BW28+CC28+CF28+CI28+CL28+CO28+CR28+CU28+CX28+DA28+DD28 -> 5792 | DH28: =ပန်းသတင်း!AE19 -> 530 | DI28: =ပန်းသတင်း!AF19 -> 7320 | DJ28: =ပန်းသတင်း!AG19 -> 5792 | DK28: =DI28/L28 -> 0.31697583 | DL28: =10/31 -> 0.32258065 | DM28: =DK28-DL28 -> -0.0056048143
A29: 26 | B29: ရှယ်ထူး | C29: Shal Htoo | D29: လေးထောင့်ကန် | E29: Lay Daungkan | F29: WS | G29: ကိုသား | H29: Ko Thar | I29: 09-443211018 | J29: YNK | K29: 3324.68 | L29: 46545.52 | V29: 245 | W29: 3660 | X29: 2736.8 | Y29: 320 | Z29: 4560 | AA29: 3636.8 | AH29: 235 | AI29: 3260 | AJ29: 2596.8 | AN29: 230 | AO29: 3700 | AP29: 2572 | AQ29: =M29+P29+S29+V29+Y29+AB29+AE29+AH29+AK29+AN29 -> 1030 | AR29: =N29+Q29+T29+W29+Z29+AC29+AF29+AI29+AL29+AO29 -> 15180 | AS29: =O29+R29+U29+X29+AA29+AD29+AG29+AJ29+AM29+AP29 -> 11542.4 | BX29: =AQ29+AT29+AW29+AZ29+BC29+BF29+BI29+BL29+BO29+BR29+BU29 -> 1030 | BY29: =AR29+AU29+AX29+BA29+BD29+BG29+BJ29+BM29+BP29+BS29+BV29 -> 15180 | BZ29: =AS29+AV29+AY29+BB29+BE29+BH29+BK29+BN29+BQ29+BT29+BW29 -> 11542.4 | DE29: =P29+S29+V29+Y29+AB29+AE29+AH29+AK29+AN29+AT29+AW29+AZ29+BC29+BF29+BI29+BL29+BO29+BR29+BU29+CA29+CD29+CG29+CJ29+CM29+CP29+CS29+CV29+CY29+DB29+M29 -> 1030 | DF29: =AR29+AU29+AX29+BA29+BD29+BG29+BJ29+BM29+BP29+BS29+BV29+CB29+CE29+CH29+CK29+CN29+CQ29+CT29+CW29+CZ29+DC29 -> 15180 | DG29: =AS29+AV29+AY29+BB29+BE29+BH29+BK29+BN29+BQ29+BT29+BW29+CC29+CF29+CI29+CL29+CO29+CR29+CU29+CX29+DA29+DD29 -> 11542.4 | DH29: =ရှယ်ထူး!AE20 -> 1030 | DI29: =ရှယ်ထူး!AF20 -> 15180 | DJ29: =ရှယ်ထူး!AG20 -> 11542.4 | DK29: =DI29/L29 -> 0.32613235 | DL29: =10/31 -> 0.32258065 | DM29: =DK29-DL29 -> 0.0035517077
