Workbook
Name aa: #REF!
Name aaa: #REF!
Name atr: #REF!
Name b: #REF!
Name bb: #REF!
Name Beg_Bal: #REF!
Name Cash_Cr: #REF!
Name Cash_Dr: #REF!
Name cc: #REF!
Name ccc: #REF!
Name cr: #REF!
Name crs: #REF!
Name Data: #REF!
Name dd: #REF!
Name ddd: #REF!
Name dr: #REF!
Name drs: #REF!
Name End_Bal: #REF!
Name Extra_Pay: #REF!
Name fgf: #REF!
Name fgjhj: #REF!
Name Full_Print: #REF!
Name Header_Row: ROW(#REF!)
Name hjj: #REF!
Name hjkjk: #REF!
Name hmjhj: #REF!
Name Int: #REF!
Name Interest_Rate: #REF!
Name jbkjkl: #REF!
Name kdt: #REF!
Name Last_Row: IF('PG Table'!Values_Entered,Header_Row+'PG Table'!Number_of_Payments,Header_Row)
Name Last_Row: IF(PGSales!Values_Entered,Header_Row+PGSales!Number_of_Payments,Header_Row)
Name Last_Row: IF(Values_Entered,Header_Row+Number_of_Payments,Header_Row)
Name Loan_Amount: #REF!
Name Loan_Start: #REF!
Name Loan_Years: #REF!
Name LSO: #REF!
Name lsoq: #REF!
Name mms: #REF!
Name neew: #REF!
Name New: #REF!
Name Num_Pmt_Per_Year: #REF!
Name Number_of_Payments: MATCH(0.01,End_Bal,-1)+1
Name Number_of_Payments: MATCH(0.01,End_Bal,-1)+1
Name Number_of_Payments: MATCH(0.01,End_Bal,-1)+1
Name Opening_Cr: #REF!
Name Opening_Dr: #REF!
Name Pay_Date: #REF!
Name Pay_Num: #REF!
Name Payment_Date: DATE(YEAR(Loan_Start),MONTH(Loan_Start)+Payment_Number,DAY(Loan_Start))
Name Payment_Date: DATE(YEAR(Loan_Start),MONTH(Loan_Start)+Payment_Number,DAY(Loan_Start))
Name Payment_Date: DATE(YEAR(Loan_Start),MONTH(Loan_Start)+Payment_Number,DAY(Loan_Start))
Name Princ: #REF!
Name Print_Area_Reset: OFFSET(Full_Print,0,0,'PG Table'!Last_Row)
Name Print_Area_Reset: OFFSET(Full_Print,0,0,PGSales!Last_Row)
Name Print_Area_Reset: OFFSET(Full_Print,0,0,Last_Row)
Name s: #REF!
Name Sched_Pay: #REF!
Name Scheduled_Extra_Payments: #REF!
Name Scheduled_Interest_Rate: #REF!

Sheet PG Table
A1: PG Name | B1: Mobile No. | D1: Stock ID | E1: Particular | F1: ml | G1: Qty | H1: Column1 | I1: Bonus | K1: s | L1: Shop Name | M1: လိပ်စာ | N1: Route Name
A2: Ma Thuzar Aung | B2: 09-898146525 | D2: 700-Col | E2: Columbus Whisky 700 Ml | F2: 0.7 | G2: 12 | H2: Whisky | I2: 150 | K2: 23 | L2: 23 | M2: Madalay Rd | N2: Hlaing Thar Yar
A3: Ma Jue Jue Hlaing | B3: 09-986169990 | D3: 350-Col | E3: Columbus Whisky 350 Ml | F3: 0.35 | G3: 24 | H3: Whisky | I3: 100 | K3: 29 | L3: 29 | M3: Lan Thit Lan | N3: Htauk kyant
A4: Ma Nway Hnin Moe | B4: 09-983002374 | D4: 175-Col | E4: Columbus Whisky 175 Ml | F4: 0.175 | G4: 48 | H4: Whisky | I4: 50 | K4: 99 | L4: 99 Store | M4: Bogo Rd | N4: Hlegu
A5: Ma Hnin Pwint Phyu | B5: 09-773993352 | D5: 700-SRS | E5: Columbus Super Red Smooth 700 Ml | F5: 0.7 | G5: 12 | H5: Whisky | I5: 200 | K5: 124 | L5: 124 Store | M5: Padamyar Rd | N5: Hlaing Thar Yar
A6: Ma Su Su Naing | B6: 09-954795340 | D6: 350-SRS | E6: Columbus Super Red Smooth 350 Ml | F6: 0.35 | G6: 24 | H6: Whisky | I6: 150 | K6: 161 | L6: 16 G (1) | M6: Innwa Rd | N6: S Paukkan N/Oakkala
A7: Ma Phyo Phyo Wai | B7: 09-774485332 | D7: 175-SRS | E7: Columbus Super Red Smooth 175 Ml | F7: 0.175 | G7: 48 | H7: Whisky | I7: 100 | K7: 162 | L7: 16 G(2) | M7: Taungnu Rd | N7: S Paukkan N/Oakkala
A8: Ma Sandar Hlaing | B8: 09-660417209 | D8: 700-FR | E8: Formula Rum 700ml | F8: 0.7 | G8: 12 | H8: Formula | I8: 200 | K8: 163 | L8: 16 G3 | M8: Kyout Lan Rd | N8: S Paukkan N/Oakkala
A9: Lae Lae Tun | B9: 09 677196046 | D9: 350-FR | E9: Formula Rum 350ml | F9: 0.35 | G9: 24 | H9: Formula | I9: 150 | K9: 494 | L9: 494 Store | M9: Ah Linn young nRd | N9: Tharkaytha
A10: Yee Mon Aung | B10: 09 953844858 | D10: DTP 12 | E10: ဒဂုံမန်ကျည်း ကော်ဗူး (1 Liter) | F10: 1 | G10: 12 | H10: BE | I10: 100 | K10: 901 | L10: 90(1) | M10: Bogo Rd | N10: Hlegu
A11: Shwe Sin Win | B11: 09 697220669 | D11: 680-SM | E11: Shwe Man 680ml | F11: 0.68 | G11: 12 | H11: Rum | I11: 100 | K11: 902 | L11: 90(2) | M11: Bogo Rd | N11: Hlegu
A12: Naw Kyi Phyu Thein | B12: 09-751050544 | D12: 1Liter-SM | E12: Shwe Man ကော်ဗူး (1 Liter) | F12: 1 | G12: 12 | H12: Rum | I12: 100 | K12: 124s | L12: 124 Store | M12: Yoe Lay | N12: Hlaing Thar Yar
A13: Ei May Thu | B13: 09 987339189 | K13: A | L13: A&T | M13: Pa 50 Lan Baho | N13: Hlaing
A14: Zin Mar Phyo | B14: 09 404979290 | K14: A.T | L14: AhTwae Thit | M14: Chit Kyi Yae Rd | N14: Hlaing Thar Yar
A15: Htet Htet Hlaing | B15: 09-675163225 | K15: A1 | L15: A One | M15: Joune Phyu Rd | N15: Htauk kyant
A16: Ei Thuzar Oo | B16: 09-668929420 | K16: A2 | L16: A2 | M16: Bogo Rd | N16: Hlaing Thar Yar
A17: Moe Thandar Oo | B17: 09-894618967 | K17: aat1 | L17: AATT 1 | M17: Sittwe RD | N17: Hlaing Thar Yar
A18: Shwe Yee Win | B18: 099-51659610 | K18: aat2 | L18: AATT | M18: Mandalay Rd | N18: Hlaing Thar Yar
A19: Thaw Thaw Win | B19: 09-66554047 | K19: AAT2 | L19: AATT | M19: Mandalay Rd | N19: Hlaing Thar Yar
A20: Htet Ei Ei Khaing | B20: 09-972309027 | K20: ABC | L20: ABC Store | M20: Badai Rd | N20: Hlaing Thar Yar
A21: Kaythi Aung | B21: 09-258599042 | K21: AF | L21: Aung Family | M21: SakeSan (9) Lan | N21: Mangalar T/N
A22: Nilar Shwe | B22: 09-400291313 | K22: AG | L22: Aung Gyi | M22: Bago Rd | N22: Htauk kyant
A23: Ei Zin Wai | B23: 09-773387161 | K23: AKE | L23: Akeri | M23: 20 Zay | N23: Hlaing Thar Yar
A24: Ei Ei Thu | B24: 09-403000048 | K24: AKK | L24: Aung Kyaw Kyar | M24: Ka Naung Minthargyi Rd | N24: South Dagon
... A30: Ma Aye Aye Thwe | B30: 09-694771264 | K30: ALY | L30: Ah linn Young | M30: West Yangon University Rd | N30: Htan Ta Pin
A31: Su Lae Lae Htwe | K31: AM1 | L31: Arrmann(1) | M31: Bo Aung Kyaw Rd | N31: Hlaing Thar Yar
K32: AM2 | L32: Arrmann(2) | M32: Banyar Dala Rd | N32: Hlaing Thar Yar
K33: Ama | L33: Amazing | M33: Shwe Yin Aye Zay Rd | N33: Hlaing Thar Yar
K34: AMGL | L34: Aung Mingalar | M34: Lan Thit Lan | N34: Htauk kyant
K35: ANT | L35: ANT Store | M35: Sake kan Thar Rd | N35: Hlaing Thar Yar
K36: AP | L36: April | M36: Bayin Naung St | N36: Htan Ta Pin
K37: APK | L37: APK | M37: Sittwe RD | N37: Hlaing Thar Yar
K38: AST | L38: Aswe Taw | M38: Moe maka Rd | N38: Mangalardon
K39: AT | L39: Aung Thayaphu | M39: Bogyoke Rd | N39: Hlaing Thar Yar
K40: AT2 | L40: AATT 2 | M40: Madalay Rd | N40: Hlaing Thar Yar
K41: Au | L41: Aung | M41: Pi Moe Hinn Sd | N41: Hlaing Thar Yar
K42: AY | L42: Aye Yeik | M42: School RD | N42: Hlaing Thar Yar
K43: AZ | L43: Aung Zaya | M43: Bogyoke Rd | N43: Hlaing Thar Yar
... K361: ZY | L361: Zwel yatanar | M361: Badai Rd | N361: Hlaing Thar Yar
Q380: g

Sheet 6-PG Sales
A1: Yangon PG sale report (01-12-2024) to (15-12-2024)
A2: 1 | B2: Shop name | C2: Shop Address | D2: Township | E2: PG Name | F2: Ph.no | G2: Columbus Super red smooth | J2: Columbus Original | M2: Formula Rum | O2: ဒဂုံမန်ကျည်း | P2: Total
G3: 700ml | H3: 350ml | I3: 175ml | J3: 700ml | K3: 350ml | L3: 175ml | M3: 700ml | N3: 350ml
A5: 1 | B5: Chit Paing | C5: Bo Aung Kyaw Rd | D5: Hlaing Thar Yar Route (1) | E5: Ma Thuzar Aung | F5: 09-898146525 | H5: 3 | I5: 3 | M5: 2 | N5: 4 | P5: =SUM(G5:O5) -> 12
B6: Boss | C6: Maher Badula Rd | D6: Shwepyithar | G6: 1 | H6: 12 | N6: 5 | P6: =SUM(G6:O6) -> 18
A7: 2 | B7: Soon Pyan | C7: Bo Aung Kyaw Rd | D7: Hlaing Thar Yar Route (1) | E7: Ma Jue Jue Hlaing | F7: 09-986169990 | H7: 26 | M7: 3 | N7: 13 | P7: =SUM(G7:O7) -> 42
B8: ShweSiSain | C8: Maher Badula Rd | D8: Shwepyithar | G8: 6 | H8: 41 | M8: 8 | N8: 13 | P8: =SUM(G8:O8) -> 68
A9: 3 | B9: Shwe Payi(1) | C9: Mandalay Rd | D9: Hlaing Thar Yar Route (1) | E9: Ma Nway Hnin Moe | F9: 09-983002374 | H9: 7 | I9: 16 | N9: 2 | P9: =SUM(G9:O9) -> 25
B10: Lamin | C10: No (4) Rd | D10: Shwepyithar | H10: 33 | M10: 6 | N10: 30 | P10: =SUM(G10:O10) -> 69
A11: 4 | B11: Thaka Kyi | C11: Mandalay Rd | D11: Hlaing Thar Yar Route (1) | E11: Ma Hnin Pwint Phyu | F11: 09-773993352 | H11: 2 | I11: 2 | P11: =SUM(G11:O11) -> 4
B12: Chit Paing | C12: Bo Aung Kyaw Rd | D12: Hlaing Thar Yar Route (1) | H12: 1 | N12: 1 | P12: =SUM(G12:O12) -> 2
B13: Dana Toe(1) | C13: Bogyoke Aung San Rd | D13: Hlaing Thar Yar Route (1) | H13: 8 | I13: 1 | N13: 4 | P13: =SUM(G13:O13) -> 13
B14: NI Ni Poe poe | C14: Ye Yanaing Rd | D14: Shwepyithar | G14: 3 | H14: 83 | I14: 2 | M14: 14 | N14: 26 | O14: 25 | P14: =SUM(G14:O14) -> 153
A15: 5 | B15: Su | C15: Aung Sinkhoe Rd | D15: Mangalardon | E15: Ma Phyo Phyo Wai | F15: 09-774485332 | G15: 2 | H15: 24 | M15: 9 | N15: 32 | P15: =SUM(G15:O15) -> 67
A16: 6 | B16: Linn Latt Ktaw | C16: Pamoe Hinn Rd | D16: Hlaing Thar Yar Route (1) | E16: Ma Sandar Hlaing | F16: 09-660417209 | H16: 7 | M16: 2 | N16: 15 | P16: =SUM(G16:O16) -> 24
B17: Ko Gyi Yo | C17: Maher Badula Rd | D17: Shwepyithar | H17: 13 | M17: 4 | N17: 6 | P17: =SUM(G17:O17) -> 23
A18: 7 | B18: Linn | C18: Bo Aung Kyaw Rd | D18: Hlaing Thar Yar Route (1) | E18: Ma Lae Lae Tun | F18: 09 677196046 | G18: 3 | H18: 2 | N18: 22 | O18: 24 | P18: =SUM(G18:O18) -> 51
B19: Mon lay | C19: Padamyar Rd | D19: Shwepyithar | G19: 2 | H19: 6 | I19: 4 | N19: 4 | P19: =SUM(G19:O19) -> 16
A20: 8 | B20: Soon Pyan | C20: Bo Aung Kyaw Rd | D20: Hlaing Thar Yar Route (1) | E20: Ma Yee Mon Aung | F20: 09 953844858 | H20: 1 | I20: 3 | P20: =SUM(G20:O20) -> 4
B21: GoodWaill | C21: Taungnu Rd | D21: Hlaing Thar Yar Route (1) | H21: 5 | I21: 3 | M21: 2 | N21: 11 | P21: =SUM(G21:O21) -> 21
B22: Kaung | C22: Sin Phyu Shin Rd | D22: Hlaing Thar Yar | G22: 5 | H22: 19 | I22: 6 | M22: 3 | N22: 10 | P22: =SUM(G22:O22) -> 43
A23: 9 | B23: Yazar | C23: Mandalay Rd | D23: Hlaing Thar Yar Route (1) | E23: Ma Shwe Sin Win | F23: 09 697220669 | G23: 1 | H23: 5 | N23: 15 | P23: =SUM(G23:O23) -> 21
B24: Swe Thahar | C24: Mandalay Rd | D24: Hlaing Thar Yar Route (1) | G24: 1 | H24: 7 | I24: 3 | M24: 1 | N24: 23 | P24: =SUM(G24:O24) -> 35
A25: 10 | B25: Kaung Kin Think | C25: Joephyu Rd | D25: Mangalardon | E25: Naw Kyi Phyu Thein | F25: 09-751050544 | G25: 1 | H25: 32 | N25: 19 | P25: =SUM(G25:O25) -> 52
A26: 11 | B26: Swe Thahar | C26: Mandalay Rd | D26: Hlaing Thar Yar Route (1) | E26: Ma Ei May Thu | F26: 09 987339189 | G26: 6 | H26: 29 | M26: 5 | N26: 8 | P26: =SUM(G26:O26) -> 48
B27: Lamin | C27: No (4) Rd | D27: Shwepyithar | N27: 6 | P27: =SUM(G27:O27) -> 6
B28: Lapyae | C28: Sin Phyu Shin Rd | D28: Hlaing Thar Yar | G28: 2 | H28: 12 | I28: 15 | M28: 3 | N28: 18 | P28: =SUM(G28:O28) -> 50
A29: 12 | B29: Po Po | C29: Mandalay Rd | D29: Hlaing Thar Yar Route (1) | E29: Ma Zin Mar Phyo | F29: 09 404979290 | H29: 16 | N29: 18 | P29: =SUM(G29:O29) -> 34
B30: Pyae Tawtar | C30: Chit Kyi Yae Rd | D30: Hlaing Thar Yar | H30: 14 | I30: 5 | M30: 2 | N30: 9 | P30: =SUM(G30:O30) -> 30
A31: 13 | B31: Thaka Kyi | C31: Mandalay Rd | D31: Hlaing Thar Yar Route (1) | E31: Ma Htet Htet Hlaing | F31: 09-675163225 | H31: 3 | I31: 4 | J31: 1 | N31: 2 | P31: =SUM(G31:O31) -> 10
B32: AATT | C32: Mandalay Rd | D32: Hlaing Thar Yar | H32: 4 | I32: 13 | N32: 5 | P32: =SUM(G32:O32) -> 22
A33: 14 | B33: Nadai | C33: Bogyoke Aung San Rd | D33: Hlaing Thar Yar Route (1) | E33: Ma Ei Thuzar Oo | F33: 09-668929420 | H33: 7 | N33: 5 | P33: =SUM(G33:O33) -> 12
B34: San Thit | C34: Joephyu Rd | D34: Mangalardon | H34: 31 | M34: 4 | N34: 6 | P34: =SUM(G34:O34) -> 41
A35: 15 | B35: Shwe Payi(1) | C35: Mandalay Rd | D35: Hlaing Thar Yar Route (1) | E35: Ma Moe Thandar Oo | F35: 09-894618967 | G35: 1 | H35: 8 | N35: 3 | P35: =SUM(G35:O35) -> 12
B36: Soon Pyan | C36: Bo Aung Kyaw Rd | D36: Hlaing Thar Yar Route (1) | H36: 9 | M36: 2 | N36: 18 | P36: =SUM(G36:O36) -> 29
A37: 16 | B37: Dana Toe(1) | C37: Bogyoke Aung San Rd | D37: Hlaing Thar Yar Route (1) | E37: Ma Shwe Yee Win | F37: 099-51659610 | G37: 1 | H37: 5 | I37: 2 | M37: 1 | N37: 7 | P37: =SUM(G37:O37) -> 16
B38: Shin Shin | C38: Joephyu Rd | D38: Mangalardon | H38: 7 | I38: 3 | M38: 1 | N38: 6 | P38: =SUM(G38:O38) -> 17
A39: 17 | B39: Dana Toe(2) | C39: Pamoe Hinn Rd | D39: Hlaing Thar Yar Route (1) | E39: Ma Thaw Thaw Win | F39: 09-66554047 | H39: 7 | M39: 1 | N39: 4 | P39: =SUM(G39:O39) -> 12
B40: Sein Shwe Phyo | C40: Thuka Rd | D40: Mangalardon | H40: 29 | I40: 12 | N40: 11 | P40: =SUM(G40:O40) -> 52
A41: 18 | B41: Shwe Yi Khatt | C41: Taungnu Rd | D41: Hlaing Thar Yar Route (1) | E41: Ma Htet Ei Ei Khaing | F41: 09-972309027 | H41: 17 | I41: 5 | N41: 15 | P41: =SUM(G41:O41) -> 37
...

Sheet 16.12 31.12
A1: Yangon PG sale report (16-12-2024) to (31-12-2024)
A2: 1 | B2: Shop name | C2: Shop Address | D2: Township | E2: PG Name | F2: Ph.no | G2: Columbus Super red smooth | J2: Columbus Original | M2: Formula Rum | O2: ဒဂုံမန်ကျည်း | P2: Total
G3: 700ml | H3: 350ml | I3: 175ml | J3: 700ml | K3: 350ml | L3: 175ml | M3: 700ml | N3: 350ml
A5: 1 | B5: Kyi Thar Oo(2) | C5: Bayin Naung St | D5: Htan Ta Pin | E5: Ma Thuzar Aung | F5: 09-898146525 | H5: 5 | I5: 5 | N5: 3 | P5: =SUM(G5:O5) -> 13
B6: ShweSiSain | C6: Maher Badula Rd | D6: Shwepyithar | H6: 44 | M6: 4 | N6: 16 | P6: =SUM(G6:O6) -> 64
B7: Lapyae Wunn | C7: West Yangon University Rd | D7: Htan Ta Pin | G7: 2 | H7: 21 | I7: 2 | M7: 5 | N7: 30 | P7: =SUM(G7:O7) -> 60
A8: 2 | B8: Kaung Star | C8: West Yangon University Rd | D8: Htan Ta Pin | E8: Ma Jue Jue Hlaing | F8: 09-986169990 | G8: 2 | H8: 10 | I8: 4 | M8: 17 | N8: 29 | P8: =SUM(G8:O8) -> 62
B9: Nate Thint | C9: Bayin Naung St | D9: Htan Ta Pin | H9: 10 | I9: 3 | M9: 5 | N9: 7 | P9: =SUM(G9:O9) -> 25
B10: Myintmo | C10: Bayin Naung Rd | D10: Shwepyithar | G10: 3 | H10: 37 | M10: 6 | N10: 24 | P10: =SUM(G10:O10) -> 70
A11: 3 | B11: April | C11: Bayin Naung St | D11: Htan Ta Pin | E11: Ma Nway Hnin Moe | F11: 09-983002374 | G11: 4 | H11: 25 | M11: 5 | N11: 62 | P11: =SUM(G11:O11) -> 96
B12: Lamin | C12: No (4) Rd | D12: Shwepyithar | G12: 2 | H12: 14 | I12: 9 | N12: 43 | P12: =SUM(G12:O12) -> 68
A13: 4 | B13: KMG | C13: Min Yea Kyawswar Rd | D13: Shwepyithar | E13: Ma Hnin Pwint Phyu | F13: 09-773993352 | H13: 1 | N13: 4 | P13: =SUM(G13:O13) -> 5
B14: KZ | C14: kantharyar Rd | D14: Shwepyithar | G14: 2 | H14: 22 | N14: 20 | P14: =SUM(G14:O14) -> 44
B15: Lapyae Wunn | C15: West Yangon University Rd | D15: Htan Ta Pin | G15: 2 | H15: 78 | I15: 30 | M15: 6 | N15: 82 | P15: =SUM(G15:O15) -> 198
B16: Ni Ni Lin | C16: Myoma Zay Rd | D16: Htan Ta Pin | G16: 3 | H16: 12 | N16: 19 | P16: =SUM(G16:O16) -> 34
A17: 5 | B17: Kaung Star | C17: West Yangon University Rd | D17: Htan Ta Pin | E17: Ma Phyo Phyo Wai | F17: 09-774485332 | H17: 12 | M17: 2 | N17: 9 | P17: =SUM(G17:O17) -> 23
B18: Nate Thint | C18: Bayin Naung St | D18: Htan Ta Pin | H18: 10 | I18: 6 | N18: 16 | P18: =SUM(G18:O18) -> 32
B19: Shwe Eain Si | C19: Banyar Dala Rd | D19: Hlaing Thar Yar | H19: 22 | M19: 1 | N19: 12 | P19: =SUM(G19:O19) -> 35
A20: 6 | B20: Kyi Thar Oo(1) | C20: Poe San Aye St | D20: Htan Ta Pin | E20: Ma Sandar Hlaing | F20: 09-660417209 | G20: 5 | H20: 11 | I20: 3 | N20: 3 | P20: =SUM(G20:O20) -> 22
B21: Kyi Thar Oo(2) | C21: Bayin Naung St | D21: Htan Ta Pin | G21: 1 | H21: 6 | N21: 1 | P21: =SUM(G21:O21) -> 8
B22: NI Ni Poe poe | C22: Ye Yanaing Rd | D22: Shwepyithar | G22: 2 | H22: 58 | I22: 1 | M22: 5 | N22: 25 | P22: =SUM(G22:O22) -> 91
A23: 7 | B23: KMG | C23: Min Yea Kyawswar Rd | D23: Shwepyithar | E23: Ma Lae Lae Tun | F23: 09 677196046 | H23: 3 | N23: 12 | P23: =SUM(G23:O23) -> 15
B24: Kyi Thar Oo(1) | C24: Poe San Aye St | D24: Htan Ta Pin | G24: 1 | H24: 2 | I24: 2 | M24: 2 | N24: 2 | P24: =SUM(G24:O24) -> 9
B25: Ni Ni Lin | C25: Myoma Zay Rd | D25: Htan Ta Pin | G25: 5 | H25: 16 | I25: 16 | M25: 2 | N25: 27 | P25: =SUM(G25:O25) -> 66
A26: 8 | B26: Arrmann(1) | C26: Bo Aung Kyaw Rd | D26: Hlaing Thar Yar | E26: Ma Yee Mon Aung | F26: 09 953844858 | G26: 1 | H26: 17 | M26: 3 | N26: 21 | P26: =SUM(G26:O26) -> 42
B27: Kyaw Myatter | C27: Pamoe Hinn Rd | D27: Hlaing Thar Yar | G27: 1 | H27: 13 | N27: 11 | P27: =SUM(G27:O27) -> 25
A28: 9 | B28: Arrmann(1) | C28: Bo Aung Kyaw Rd | D28: Hlaing Thar Yar | E28: Ma Shwe Sin Win | F28: 09 697220669 | H28: 19 | I28: 5 | M28: 1 | N28: 13 | P28: =SUM(G28:O28) -> 38
B29: Arrmann(2) | C29: Banyar Dala Rd | D29: Hlaing Thar Yar | H29: 24 | I29: 5 | N29: 3 | P29: =SUM(G29:O29) -> 32
B30: KoKoe Myaing | C30: Bo Aung Kyaw Rd | D30: Hlaing Thar Yar | G30: 1 | H30: 6 | P30: =SUM(G30:O30) -> 7
A31: 10 | B31: Smile Moon | C31: Joephyu Rd | D31: Mangalardon | E31: Naw Kyi Phyu Thein | F31: 09-751050544 | G31: 2 | H31: 25 | I31: 2 | M31: 1 | N31: 22 | P31: =SUM(G31:O31) -> 52
A32: 11 | B32: pyaeSone | C32: Htay Auyinn St | D32: Hlaing Thar Yar | E32: Ma Ei May Thu | F32: 09 987339189 | H32: 30 | M32: 1 | N32: 39 | P32: =SUM(G32:O32) -> 70
B33: Phoe Thar Htoo | C33: Khaing Shwe War Rd | D33: Hlaing Thar Yar | G33: 3 | H33: 11 | M33: 1 | N33: 36 | P33: =SUM(G33:O33) -> 51
B34: Shwe Pyae(2) | C34: LanThwe | D34: Hlaing Thar Yar | H34: 19 | N34: 26 | P34: =SUM(G34:O34) -> 45
A35: 12 | B35: Lapyae | C35: Sin Phyu Shin Rd | D35: Hlaing Thar Yar | E35: Ma Zin Mar Phyo | F35: 09 404979290 | H35: 9 | M35: 2 | N35: 19 | P35: =SUM(G35:O35) -> 30
B36: Phoe Thar Htoo | C36: Khaing Shwe War Rd | D36: Hlaing Thar Yar | H36: 12 | N36: 11 | P36: =SUM(G36:O36) -> 23
B37: Shwe Pyae(1) | C37: Bogyoke Rd | D37: Hlaing Thar Yar | H37: 13 | N37: 10 | P37: =SUM(G37:O37) -> 23
A38: 13 | B38: Lucky9 | C38: Htay Auyinn St | D38: Hlaing Thar Yar | E38: Ma Htet Htet Hlaing | F38: 09-675163225 | G38: 1 | H38: 7 | N38: 25 | P38: =SUM(G38:O38) -> 33
B39: Pyae Tawtar | C39: Chit Kyi Yae Rd | D39: Hlaing Thar Yar | G39: 1 | H39: 22 | I39: 14 | N39: 8 | P39: =SUM(G39:O39) -> 45
B40: Shwe Eain Si | C40: Banyar Dala Rd | D40: Hlaing Thar Yar | G40: 1 | H40: 8 | M40: 2 | N40: 8 | P40: =SUM(G40:O40) -> 19
A41: 14 | B41: KZ | C41: kantharyar Rd | D41: Shwepyithar | E41: Ma Ei Thuzar Oo | F41: 09-668929420 | H41: 29 | N41: 22 | P41: =SUM(G41:O41) -> 51
...

Sheet 1.1.25 15.1.25
A1: Yangon PG sale report (1-1-2025) to (15-1-2025)
A2: 1 | B2: Shop name | C2: Shop Address | D2: Township | E2: PG Name | F2: Ph.no | G2: Columbus Super red smooth | J2: Columbus Original | M2: Formula Rum | O2: ဒဂုံမန်ကျည်း | P2: Total
G3: 700ml | H3: 350ml | I3: 175ml | J3: 700ml | K3: 350ml | L3: 175ml | M3: 700ml | N3: 350ml
A5: 1 | B5: Lapyae Wunn | C5: West Yangon University Rd | D5: Htan Ta Pin | E5: Ma Thuzar Aung | F5: 09-898146525 | H5: 22 | M5: 3 | N5: 39 | P5: =SUM(G5:O5) -> 64
B6: Myintmo | C6: Bayin Naung Rd | D6: Shwepyithar | H6: 10 | M6: 3 | N6: 24 | P6: =SUM(G6:O6) -> 37
B7: Than Yaw Zin | C7: Rose Rd | D7: YanKin | H7: 5 | I7: 4 | N7: 5 | P7: =SUM(G7:O7) -> 14
A8: 2 | B8: Nate Thint | C8: Bayin Naung St | D8: Htan Ta Pin | E8: Ma Jue Jue Hlaing | F8: 09-986169990 | H8: 14 | I8: 8 | M8: 6 | N8: 14 | P8: =SUM(G8:O8) -> 42
B9: Wine | C9: Hlawaga Rd | D9: Shwepyithar | G9: 11 | H9: 69 | I9: 9 | M9: 4 | N9: 42 | P9: =SUM(G9:O9) -> 135
B10: Naung Yoe | C10: Thamain Bamyan Rd | D10: Mangalar T/N | H10: 27 | M10: 6 | N10: 27 | P10: =SUM(G10:O10) -> 60
A11: 3 | B11: April | C11: Bayin Naung St | D11: Htan Ta Pin | E11: Ma Nway Hnin Moe | F11: 09-983002374 | G11: 2 | H11: 8 | N11: 22 | P11: =SUM(G11:O11) -> 32
B12: Toe Twat Wai | C12: Badamar St | D12: Shwepyithar | G12: 2 | H12: 46 | M12: 1 | N12: 58 | P12: =SUM(G12:O12) -> 107
B13: Nan Htet | C13: Sitkaind Rd | D13: S Paukkan N/Oakkala | G13: 1 | H13: 29 | M13: 3 | N13: 40 | P13: =SUM(G13:O13) -> 73
A14: 4 | B14: Ni Ni Lin | C14: Myoma Zay Rd | D14: Htan Ta Pin | E14: Ma Hnin Pwint Phyu | F14: 09-773993352 | G14: 2 | H14: 14 | M14: 6 | N14: 14 | P14: =SUM(G14:O14) -> 36
B15: Kaung Thant | C15: ThanDin Zay Rd | D15: Shwepyithar | H15: 49 | I15: 5 | M15: 9 | N15: 34 | P15: =SUM(G15:O15) -> 97
B16: Demo | C16: Thamain Bamyan Rd | D16: Mangalar T/N | G16: 1 | H16: 35 | M16: 1 | N16: 7 | P16: =SUM(G16:O16) -> 44
A17: 5 | B17: Kaung Star | C17: West Yangon University Rd | D17: Htan Ta Pin | E17: Ma Phyo Phyo Wai | F17: 09-774485332 | G17: 3 | H17: 8 | M17: 3 | N17: 12 | P17: =SUM(G17:O17) -> 26
B18: Sein Si Tun | C18: Yazar Deright Rd | D18: S Paukkan N/Oakkala | H18: 12 | I18: 16 | N18: 6 | P18: =SUM(G18:O18) -> 34
B19: Ah Linn Nike | C19: ThitSar Rd | D19: YanKin | H19: 8 | I19: 18 | N19: 3 | P19: =SUM(G19:O19) -> 29
A20: 6 | B20: Kyi Thar Oo(2) | C20: Bayin Naung St | D20: Htan Ta Pin | E20: Ma Sandar Hlaing | F20: 09-660417209 | H20: 1 | I20: 2 | N20: 3 | P20: =SUM(G20:O20) -> 6
B21: Cheer | C21: ThanDin Zay Rd | D21: Shwepyithar | G21: 1 | H21: 28 | M21: 6 | N21: 16 | P21: =SUM(G21:O21) -> 51
B22: Ka Dai Hein | C22: Kan Bae Botar Zay Rd | D22: YanKin | G22: 3 | H22: 16 | I22: 4 | M22: 1 | N22: 15 | O22: 13 | P22: =SUM(G22:O22) -> 52
A23: 7 | B23: Kyi Thar Oo(1) | C23: Poe San Aye St | D23: Htan Ta Pin | E23: Ma Lae Lae Tun | F23: 09 677196046 | N23: 4 | P23: =SUM(G23:O23) -> 4
B24: Zaw Hein Kaber | C24: ThanDin Zay Rd | D24: Shwepyithar | H24: 10 | M24: 1 | N24: 46 | P24: =SUM(G24:O24) -> 57
B25: Paint Taime Thaung | C25: Aye Yake Nyein Rd | D25: Hlaing Thar Yar | H25: 4 | M25: 2 | N25: 11 | P25: =SUM(G25:O25) -> 17
A26: 8 | B26: Kyaw Myatter | C26: Pamoe Hinn Rd | D26: Hlaing Thar Yar | E26: Ma Yee Mon Aung | F26: 09 953844858 | H26: 12 | M26: 2 | N26: 15 | P26: =SUM(G26:O26) -> 29
B27: Shwe Pyae(1) | C27: Bogyoke Rd | D27: Hlaing Thar Yar | H27: 30 | M27: 4 | N27: 40 | O27: 30 | P27: =SUM(G27:O27) -> 104
A28: 9 | B28: KoKoe Myaing | C28: Bo Aung Kyaw Rd | D28: Hlaing Thar Yar | E28: Ma Shwe Sin Win | F28: 09 697220669 | H28: 15 | M28: 1 | N28: 13 | P28: =SUM(G28:O28) -> 29
B29: Mya Badathar 1 | C29: Bogyoke Rd | D29: Hlaing Thar Yar | H29: 8 | I29: 3 | M29: 1 | N29: 10 | P29: =SUM(G29:O29) -> 22
B30: Hlaing Bwar | C30: Paddue Rd | D30: Hlaing Thar Yar | G30: 1 | H30: 25 | M30: 1 | N30: 6 | O30: 4 | P30: =SUM(G30:O30) -> 37
A31: 10 | B31: Kyaw | C31: Bagan Rd | D31: S Paukkan N/Oakkala | E31: Naw Kyi Phyu Thein | F31: 09-751050544 | G31: 4 | H31: 69 | M31: 6 | N31: 50 | P31: =SUM(G31:O31) -> 129
B32: Style 2 | C32: Thamain Bamyan Rd | D32: Mangalar T/N | G32: 2 | H32: 35 | N32: 22 | P32: =SUM(G32:O32) -> 59
A33: 11 | B33: Shwe Pyae(2) | C33: LanThwe | D33: Hlaing Thar Yar | E33: Ma Ei May Thu | F33: 09 987339189 | H33: 16 | M33: 2 | N33: 33 | P33: =SUM(G33:O33) -> 51
B34: Aung Zaya | C34: Bogyoke Rd | D34: Hlaing Thar Yar | G34: 2 | H34: 47 | M34: 2 | N34: 41 | O34: 24 | P34: =SUM(G34:O34) -> 116
B35: Htate Tan | C35: Sattmu Zone (1) Zay Rd | D35: Hlaing Thar Yar | G35: 1 | H35: 15 | M35: 1 | N35: 20 | P35: =SUM(G35:O35) -> 37
A36: 12 | B36: Shwe Pyae(1) | C36: Bogyoke Rd | D36: Hlaing Thar Yar | E36: Ma Zin Mar Phyo | F36: 09 404979290 | H36: 9 | N36: 24 | P36: =SUM(G36:O36) -> 33
B37: Kyaw Myatter | C37: Pamoe Hinn Rd | D37: Hlaing Thar Yar | H37: 21 | M37: 5 | N37: 31 | O37: 12 | P37: =SUM(G37:O37) -> 69
B38: Min Thar Gyi | C38: Aye Yake Nyein Rd | D38: Hlaing Thar Yar | H38: 17 | M38: 7 | N38: 11 | P38: =SUM(G38:O38) -> 35
A39: 13 | B39: Lucky9 | C39: Htay Auyinn St | D39: Hlaing Thar Yar | E39: Ma Htet Htet Hlaing | F39: 09-675163225 | H39: 11 | N39: 7 | P39: =SUM(G39:O39) -> 18
B40: Aung Thayaphu | C40: Bogyoke Rd | D40: Hlaing Thar Yar | H40: 4 | N40: 3 | P40: =SUM(G40:O40) -> 7
B41: Shwe Dinker | C41: Paung Kan Gd | D41: S Paukkan N/Oakkala | H41: 8 | N41: 14 | P41: =SUM(G41:O41) -> 22
...

Sheet 16.1.25 31.1.25
A1: Yangon PG sale report (16-1-2025) to (31-1-2025)
A2: 1 | B2: Shop name | C2: Shop Address | D2: Township | E2: PG Name | F2: Ph.no | G2: Columbus Super red smooth | J2: Columbus Original | M2: Formula Rum | O2: ဒဂုံမန်ကျည်း | P2: Total
G3: 700ml | H3: 350ml | I3: 175ml | J3: 700ml | K3: 350ml | L3: 175ml | M3: 700ml | N3: 350ml
A5: 1 | B5: Than Yaw Zin | C5: Rose Rd | D5: YanKin | E5: Ma Thuzar Aung | F5: 09-898146525 | H5: 5 | I5: 2 | N5: 5 | P5: =SUM(G5:O5) -> 12
B6: Naung Yoe | C6: Thamain Bamyan Rd | D6: Mangalar T/N | H6: 48 | N6: 39 | P6: =SUM(G6:O6) -> 87
B7: Plantinum | C7: Thamain Bamyan Rd | D7: Mangalar T/N | H7: 17 | M7: 1 | N7: 3 | O7: 13 | P7: =SUM(G7:O7) -> 34
A8: 2 | B8: Naung Yoe | C8: Thamain Bamyan Rd | D8: Mangalar T/N | E8: Ma Jue Jue Hlaing | F8: 09-986169990 | G8: 1 | H8: 28 | M8: 2 | N8: 33 | P8: =SUM(G8:O8) -> 64
B9: Demo | C9: Thamain Bamyan Rd | D9: Mangalar T/N | G9: 2 | H9: 73 | P9: =SUM(G9:O9) -> 75
B10: KK Store | C10: Bo Min Young Rd | D10: Mangalar T/N | H10: 33 | I10: 22 | M10: 7 | N10: 26 | P10: =SUM(G10:O10) -> 88
A11: 3 | B11: Nan Htet | C11: Sitkaind Rd | D11: S Paukkan N/Oakkala | E11: Ma Nway Hnin Moe | F11: 09-983002374 | G11: 1 | H11: 20 | M11: 3 | N11: 50 | P11: =SUM(G11:O11) -> 74
B12: Paddue War | C12: Bayane naung Rd | D12: N/Oakkala | G12: 6 | H12: 35 | M12: 8 | N12: 83 | P12: =SUM(G12:O12) -> 132
B13: Paddue War | C13: Bayane naung Rd | D13: N/Oakkala | G13: 3 | H13: 21 | M13: 10 | N13: 44 | P13: =SUM(G13:O13) -> 78
A14: 4 | B14: Demo | C14: Thamain Bamyan Rd | D14: Mangalar T/N | E14: Ma Hnin Pwint Phyu | F14: 09-773993352 | G14: 1 | H14: 29 | M14: 3 | N14: 2 | P14: =SUM(G14:O14) -> 35
B15: Ah Linn Nike | C15: ThitSar Rd | D15: YanKin | G15: 2 | H15: 37 | I15: 3 | N15: 6 | P15: =SUM(G15:O15) -> 48
B16: Style 2 | C16: Thamain Bamyan Rd | D16: Mangalar T/N | G16: 1 | H16: 50 | M16: 8 | N16: 38 | P16: =SUM(G16:O16) -> 97
A17: 5 | B17: Ah Linn Nike | C17: ThitSar Rd | D17: YanKin | E17: Ma Phyo Phyo Wai | F17: 09-774485332 | H17: 17 | N17: 4 | P17: =SUM(G17:O17) -> 21
B18: Ka Dai Hein | C18: Kan Bae Botar Zay Rd | D18: YanKin | G18: 2 | H18: 26 | I18: 18 | M18: 1 | N18: 43 | P18: =SUM(G18:O18) -> 90
B19: Aung Family | C19: SakeSan (9) Lan | D19: Mangalar T/N | H19: 21 | M19: 10 | N19: 22 | P19: =SUM(G19:O19) -> 53
A20: 6 | B20: Ka Dai Hein | C20: Kan Bae Botar Zay Rd | D20: YanKin | E20: Ma Sandar Hlaing | F20: 09-660417209 | G20: 2 | H20: 12 | I20: 1 | N20: 17 | O20: 5 | P20: =SUM(G20:O20) -> 37
B21: Style 2 | C21: Thamain Bamyan Rd | D21: Mangalar T/N | H21: 30 | M21: 1 | N21: 56 | P21: =SUM(G21:O21) -> 87
B22: Demo | C22: Thamain Bamyan Rd | D22: Mangalar T/N | H22: 43 | N22: 12 | P22: =SUM(G22:O22) -> 55
A23: 7 | B23: Paint Taime Thaung | C23: Aye Yake Nyein Rd | D23: Hlaing Thar Yar | E23: Ma Lae Lae Tun | F23: 09 677196046 | H23: 1 | M23: 1 | N23: 5 | P23: =SUM(G23:O23) -> 7
B24: Min Thar Gyi | C24: Aye Yake Nyein Rd | D24: Hlaing Thar Yar | H24: 3 | M24: 6 | N24: 12 | P24: =SUM(G24:O24) -> 21
B25: Yar Pyae San | C25: Zay Rd | D25: Hlaing Thar Yar | G25: 2 | H25: 7 | M25: 4 | N25: 5 | P25: =SUM(G25:O25) -> 18
A26: 8 | B26: Shwe Pyae(1) | C26: Bogyoke Rd | D26: Hlaing Thar Yar | E26: Ma Yee Mon Aung | F26: 09 953844858 | H26: 9 | N26: 16 | O26: 29 | P26: =SUM(G26:O26) -> 54
B27: Paint Taime Thaung | C27: Aye Yake Nyein Rd | D27: Hlaing Thar Yar | G27: 1 | H27: 2 | M27: 7 | N27: 21 | O27: 4 | P27: =SUM(G27:O27) -> 35
B28: ANT Store | C28: Sake kan Thar Rd | D28: Hlaing Thar Yar | H28: 6 | M28: 1 | N28: 11 | O28: 14 | P28: =SUM(G28:O28) -> 32
A29: 9 | B29: Hlaing Bwar 1 | C29: Paddue Rd | D29: Hlaing Thar Yar | E29: Ma Shwe Sin Win | F29: 09 697220669 | H29: 10 | M29: 1 | N29: 11 | O29: 1 | P29: =SUM(G29:O29) -> 23
B30: Lucky | C30: Malar Rd | D30: Hlaing Thar Yar | G30: 1 | H30: 17 | M30: 3 | N30: 14 | O30: 6 | P30: =SUM(G30:O30) -> 41
B31: Arkar Tha 2 | C31: Sake kan Thar Rd | D31: Hlaing Thar Yar | G31: 2 | H31: 13 | M31: 1 | N31: 16 | O31: 3 | P31: =SUM(G31:O31) -> 35
A32: 10 | B32: Style 2 | C32: Thamain Bamyan Rd | D32: Mangalar T/N | E32: Naw Kyi Phyu Thein | F32: 09-751050544 | H32: 30 | M32: 2 | N32: 23 | P32: =SUM(G32:O32) -> 55
B33: Than Yaw Zin | C33: Rose Rd | D33: YanKin | H33: 17 | M33: 2 | N33: 26 | P33: =SUM(G33:O33) -> 45
B34: Family | C34: Mandalay Lan Tawe | D34: Mangalar T/N | H34: 19 | I34: 10 | N34: 4 | P34: =SUM(G34:O34) -> 33
A35: 11 | B35: Htate Tan | C35: Sattmu Zone (1) Zay Rd | D35: Hlaing Thar Yar | E35: Ma Ei May Thu | F35: 09 987339189 | G35: 5 | H35: 27 | M35: 9 | N35: 47 | P35: =SUM(G35:O35) -> 88
B36: Zaw | C36: Kyan Sitt Thar Rd | D36: Hlaing Thar Yar | G36: 4 | H36: 3 | N36: 7 | P36: =SUM(G36:O36) -> 14
A37: 12 | B37: Min Thar Gyi | C37: Aye Yake Nyein Rd | D37: Hlaing Thar Yar | E37: Ma Zin Mar Phyo | F37: 09 404979290 | H37: 13 | I37: 6 | M37: 1 | N37: 18 | P37: =SUM(G37:O37) -> 38
B38: Hlaing Bwar 1 | C38: Paddue Rd | D38: Hlaing Thar Yar | H38: 8 | M38: 1 | N38: 19 | O38: 12 | P38: =SUM(G38:O38) -> 40
B39: Hlaing Bwar 2 | C39: Sake kan Thar Rd | D39: Hlaing Thar Yar | H39: 10 | N39: 15 | P39: =SUM(G39:O39) -> 25
A40: 13 | B40: Shwe Dinker | C40: Paung Kan Gd | D40: S Paukkan N/Oakkala | E40: Ma Htet Htet Hlaing | F40: 09-675163225 | G40: 1 | H40: 4 | I40: 8 | M40: 2 | N40: 5 | P40: =SUM(G40:O40) -> 20
B41: Kyout Lan Htate | C41: Bagan Rd | D41: S Paukkan N/Oakkala | G41: 1 | H41: 13 | N41: 6 | P41: =SUM(G41:O41) -> 20
...

Sheet Jan-monthly
A1: Yangon PG sale report January monthly
A2: 1 | B2: Shop name | C2: Shop Address | D2: Township | E2: PG Name | F2: Ph.no | G2: Columbus Super red smooth | J2: Columbus Original | M2: Formula Rum | O2: ဒဂုံမန်ကျည်း | P2: Total
G3: 700ml | H3: 350ml | I3: 175ml | J3: 700ml | K3: 350ml | L3: 175ml | M3: 700ml | N3: 350ml
A5: 1 | B5: Lapyae Wunn | C5: West Yangon University Rd | D5: Htan Ta Pin | E5: Ma Thuzar Aung | F5: 09-898146525 | H5: 22 | M5: 3 | N5: 39 | P5: =SUM(G5:O5) -> 64
B6: Myintmo | C6: Bayin Naung Rd | D6: Shwepyithar | H6: 10 | M6: 3 | N6: 24 | P6: =SUM(G6:O6) -> 37
B7: Than Yaw Zin | C7: Rose Rd | D7: YanKin | H7: 10 | I7: 6 | N7: 10 | P7: =SUM(G7:O7) -> 26
B8: Naung Yoe | C8: Thamain Bamyan Rd | D8: Mangalar T/N | H8: 48 | N8: 39 | P8: =SUM(G8:O8) -> 87
B9: Plantinum | C9: Thamain Bamyan Rd | D9: Mangalar T/N | H9: 17 | M9: 1 | N9: 3 | O9: 13 | P9: =SUM(G9:O9) -> 34
A10: 2 | B10: Nate Thint | C10: Bayin Naung St | D10: Htan Ta Pin | E10: Ma Jue Jue Hlaing | F10: 09-986169990 | H10: 14 | I10: 8 | M10: 6 | N10: 14 | P10: =SUM(G10:O10) -> 42
B11: Wine | C11: Hlawaga Rd | D11: Shwepyithar | G11: 11 | H11: 69 | I11: 9 | M11: 4 | N11: 42 | P11: =SUM(G11:O11) -> 135
B12: Naung Yoe | C12: Thamain Bamyan Rd | D12: Mangalar T/N | G12: 1 | H12: 55 | M12: 8 | N12: 60 | P12: =SUM(G12:O12) -> 124
B13: Demo | C13: Thamain Bamyan Rd | D13: Mangalar T/N | G13: 2 | H13: 73 | P13: =SUM(G13:O13) -> 75
B14: KK Store | C14: Bo Min Young Rd | D14: Mangalar T/N | H14: 33 | I14: 22 | M14: 7 | N14: 26 | P14: =SUM(G14:O14) -> 88
A15: 3 | B15: April | C15: Bayin Naung St | D15: Htan Ta Pin | E15: Ma Nway Hnin Moe | F15: 09-983002374 | G15: 2 | H15: 8 | N15: 22 | P15: =SUM(G15:O15) -> 32
B16: Toe Twat Wai | C16: Badamar St | D16: Shwepyithar | G16: 2 | H16: 46 | M16: 1 | N16: 58 | P16: =SUM(G16:O16) -> 107
B17: Nan Htet | C17: Sitkaind Rd | D17: S Paukkan N/Oakkala | G17: 2 | H17: 49 | M17: 6 | N17: 90 | P17: =SUM(G17:O17) -> 147
B18: Paddue War | C18: Bayane naung Rd | D18: N/Oakkala | G18: 6 | H18: 35 | M18: 8 | N18: 83 | P18: =SUM(G18:O18) -> 132
B19: Paddue War | C19: Bayane naung Rd | D19: N/Oakkala | G19: 3 | H19: 21 | M19: 10 | N19: 44 | P19: =SUM(G19:O19) -> 78
A20: 4 | B20: Ni Ni Lin | C20: Myoma Zay Rd | D20: Htan Ta Pin | E20: Ma Hnin Pwint Phyu | F20: 09-773993352 | G20: 2 | H20: 14 | M20: 6 | N20: 14 | P20: =SUM(G20:O20) -> 36
B21: Kaung Thant | C21: ThanDin Zay Rd | D21: Shwepyithar | H21: 49 | I21: 5 | M21: 9 | N21: 34 | P21: =SUM(G21:O21) -> 97
B22: Demo | C22: Thamain Bamyan Rd | D22: Mangalar T/N | G22: 2 | H22: 64 | M22: 4 | N22: 9 | P22: =SUM(G22:O22) -> 79
B23: Ah Linn Nike | C23: ThitSar Rd | D23: YanKin | G23: 2 | H23: 37 | I23: 3 | N23: 6 | P23: =SUM(G23:O23) -> 48
B24: Style 2 | C24: Thamain Bamyan Rd | D24: Mangalar T/N | G24: 1 | H24: 50 | M24: 8 | N24: 38 | P24: =SUM(G24:O24) -> 97
A25: 5 | B25: Kaung Star | C25: West Yangon University Rd | D25: Htan Ta Pin | E25: Ma Phyo Phyo Wai | F25: 09-774485332 | G25: 3 | H25: 8 | M25: 3 | N25: 12 | P25: =SUM(G25:O25) -> 26
B26: Sein Si Tun | C26: Yazar Deright Rd | D26: S Paukkan N/Oakkala | H26: 12 | I26: 16 | N26: 6 | P26: =SUM(G26:O26) -> 34
B27: Ah Linn Nike | C27: ThitSar Rd | D27: YanKin | H27: 25 | I27: 18 | N27: 7 | P27: =SUM(G27:O27) -> 50
B28: Ka Dai Hein | C28: Kan Bae Botar Zay Rd | D28: YanKin | G28: 2 | H28: 26 | I28: 18 | M28: 1 | N28: 43 | P28: =SUM(G28:O28) -> 90
B29: Aung Family | C29: SakeSan (9) Lan | D29: Mangalar T/N | H29: 21 | M29: 10 | N29: 22 | P29: =SUM(G29:O29) -> 53
A30: 6 | B30: Kyi Thar Oo(2) | C30: Bayin Naung St | D30: Htan Ta Pin | E30: Ma Sandar Hlaing | F30: 09-660417209 | H30: 1 | I30: 2 | N30: 3 | P30: =SUM(G30:O30) -> 6
B31: Cheer | C31: ThanDin Zay Rd | D31: Shwepyithar | G31: 1 | H31: 28 | M31: 6 | N31: 16 | P31: =SUM(G31:O31) -> 51
B32: Ka Dai Hein | C32: Kan Bae Botar Zay Rd | D32: YanKin | G32: 5 | H32: 28 | I32: 5 | M32: 1 | N32: 32 | O32: 18 | P32: =SUM(G32:O32) -> 89
B33: Style 2 | C33: Thamain Bamyan Rd | D33: Mangalar T/N | H33: 30 | M33: 1 | N33: 56 | P33: =SUM(G33:O33) -> 87
B34: Demo | C34: Thamain Bamyan Rd | D34: Mangalar T/N | H34: 43 | N34: 12 | P34: =SUM(G34:O34) -> 55
A35: 7 | B35: Kyi Thar Oo(1) | C35: Poe San Aye St | D35: Htan Ta Pin | E35: Ma Lae Lae Tun | F35: 09 677196046 | N35: 4 | P35: =SUM(G35:O35) -> 4
B36: Zaw Hein Kaber | C36: ThanDin Zay Rd | D36: Shwepyithar | H36: 10 | M36: 1 | N36: 46 | P36: =SUM(G36:O36) -> 57
B37: Paint Taime Thaung | C37: Aye Yake Nyein Rd | D37: Hlaing Thar Yar | H37: 5 | M37: 3 | N37: 16 | P37: =SUM(G37:O37) -> 24
B38: Min Thar Gyi | C38: Aye Yake Nyein Rd | D38: Hlaing Thar Yar | H38: 3 | M38: 6 | N38: 12 | P38: =SUM(G38:O38) -> 21
B39: Yar Pyae San | C39: Zay Rd | D39: Hlaing Thar Yar | G39: 2 | H39: 7 | M39: 4 | N39: 5 | P39: =SUM(G39:O39) -> 18
A40: 8 | B40: Kyaw Myatter | C40: Pamoe Hinn Rd | D40: Hlaing Thar Yar | E40: Ma Yee Mon Aung | F40: 09 953844858 | H40: 12 | M40: 2 | N40: 15 | P40: =SUM(G40:O40) -> 29
B41: Shwe Pyae(1) | C41: Bogyoke Rd | D41: Hlaing Thar Yar | H41: 39 | M41: 4 | N41: 56 | O41: 59 | P41: =SUM(G41:O41) -> 158
...

Sheet 1.2.25 15.2.25
A1: Yangon PG sale report (1-2-2025) to (15-2-2025)
A2: 1 | B2: Shop name | C2: Shop Address | D2: Township | E2: PG Name | F2: Ph.no | G2: Columbus Super red smooth | J2: Columbus Original | M2: Formula Rum | O2: ဒဂုံမန်ကျည်း | P2: Total
G3: 700ml | H3: 350ml | I3: 175ml | J3: 700ml | K3: 350ml | L3: 175ml | M3: 700ml | N3: 350ml
A5: 1 | B5: Plantinum | C5: Thamain Bamyan Rd | D5: Mangalar T/N | E5: Ma Thuzar Aung | F5: 09-898146525 | G5: 1 | H5: 2 | P5: =SUM(G5:O5) -> 3
B6: Hlaing Min | C6: Tan Day Pin Sd | D6: Htauk kyant | H6: 15 | I6: 12 | M6: 2 | N6: 11 | P6: =SUM(G6:O6) -> 40
B7: 29 | C7: Lan Thit Lan | D7: Htauk kyant | G7: 2 | H7: 25 | I7: 14 | M7: 3 | N7: 16 | P7: =SUM(G7:O7) -> 60
A8: 2 | B8: KK Store | C8: Bo Min Young Rd | D8: Mangalar T/N | E8: Ma Jue Jue Hlaing | F8: 09-986169990 | H8: 5 | I8: 4 | M8: 4 | N8: 6 | P8: =SUM(G8:O8) -> 19
B9: La Ware Thant | C9: Kar ya Sd | D9: Htauk kyant | G9: 1 | H9: 27 | I9: 14 | M9: 7 | N9: 56 | P9: =SUM(G9:O9) -> 105
B10: KK | C10: Oae Yin Sd | D10: Htauk kyant | G10: 7 | H10: 37 | I10: 4 | M10: 5 | N10: 25 | P10: =SUM(G10:O10) -> 78
A11: 3 | B11: Paddue War | C11: Bayane naung Rd | D11: N/Oakkala | E11: Ma Nway Hnin Moe | F11: 09-983002374 | G11: 2 | H11: 7 | M11: 5 | N11: 8 | P11: =SUM(G11:O11) -> 22
B12: 29 | C12: Lan Thit Lan | D12: Htauk kyant | G12: 1 | H12: 28 | I12: 9 | M12: 4 | N12: 27 | P12: =SUM(G12:O12) -> 69
B13: La Ware Thant | C13: Kar ya Sd | D13: Htauk kyant | G13: 2 | H13: 32 | I13: 12 | M13: 1 | N13: 46 | P13: =SUM(G13:O13) -> 93
A14: 4 | B14: Style 2 | C14: Thamain Bamyan Rd | D14: Mangalar T/N | E14: Ma Hnin Pwint Phyu | F14: 09-773993352 | H14: 9 | M14: 1 | N14: 10 | P14: =SUM(G14:O14) -> 20
B15: Lue Gyi Min | C15: Bounk Gyi Sd | D15: Htauk kyant | G15: 6 | H15: 87 | I15: 38 | M15: 12 | N15: 114 | P15: =SUM(G15:O15) -> 257
B16: Y47 | C16: Tan Day Pin Sd | D16: Htauk kyant | G16: 1 | H16: 24 | M16: 2 | N16: 20 | P16: =SUM(G16:O16) -> 47
A17: 5 | B17: Aung Family | C17: SakeSan (9) Lan | D17: Mangalar T/N | E17: Ma Phyo Phyo Wai | F17: 09-774485332 | H17: 3 | M17: 2 | N17: 2 | P17: =SUM(G17:O17) -> 7
B18: Moe Thounk Pan | C18: Mya Yatu Sd | D18: Htauk kyant | G18: 1 | H18: 24 | I18: 16 | M18: 1 | N18: 20 | P18: =SUM(G18:O18) -> 62
B19: Hlaing Min | C19: Tan Day Pin Sd | D19: Htauk kyant | H19: 29 | I19: 10 | M19: 1 | N19: 11 | P19: =SUM(G19:O19) -> 51
A20: 6 | B20: Demo | C20: Thamain Bamyan Rd | D20: Mangalar T/N | E20: Ma Sandar Hlaing | F20: 09-660417209 | H20: 7 | N20: 2 | P20: =SUM(G20:O20) -> 9
B21: Y47 | C21: Tan Day Pin Sd | D21: Htauk kyant | G21: 2 | H21: 22 | M21: 1 | N21: 16 | P21: =SUM(G21:O21) -> 41
B22: Moe Thounk Pan | C22: Mya Yatu Sd | D22: Htauk kyant | H22: 8 | I22: 31 | M22: 4 | N22: 17 | P22: =SUM(G22:O22) -> 60
A23: 7 | B23: Yar Pyae San | C23: Zay Rd | D23: Hlaing Thar Yar | E23: Ma Lae Lae Tun | F23: 09 677196046 | G23: 1 | M23: 3 | N23: 2 | P23: =SUM(G23:O23) -> 6
B24: Ngwe Khaing | C24: Baya Thinkyan Sd | D24: S/Okkala | G24: 1 | H24: 5 | M24: 1 | N24: 9 | P24: =SUM(G24:O24) -> 16
B25: Shine | C25: Loke Thar Sd | D25: S/Okkala | H25: 37 | M25: 2 | N25: 5 | P25: =SUM(G25:O25) -> 44
A26: 8 | B26: ANT Store | C26: Sake kan Thar Rd | D26: Hlaing Thar Yar | E26: Ma Yee Mon Aung | F26: 09 953844858 | H26: 1 | N26: 7 | O26: 5 | P26: =SUM(G26:O26) -> 13
B27: 124 Store | C27: Padamyar Rd | D27: Hlaing Thar Yar | H27: 9 | N27: 24 | O27: 8 | P27: =SUM(G27:O27) -> 41
B28: Nat Thit Oo | C28: Take Htae Sd | D28: Hlaing thar Yar | H28: 12 | I28: 1 | M28: 1 | N28: 19 | O28: 8 | P28: =SUM(G28:O28) -> 41
A29: 9 | B29: Arkar Tha 2 | C29: Sake kan Thar Rd | D29: Hlaing Thar Yar | E29: Ma Shwe Sin Win | F29: 09 697220669 | H29: 4 | N29: 1 | O29: 2 | P29: =SUM(G29:O29) -> 7
B30: Yar Pyae San | C30: Zay Rd | D30: Hlaing Thar Yar | G30: 2 | H30: 9 | M30: 1 | N30: 19 | P30: =SUM(G30:O30) -> 31
B31: Okk Kar | C31: Pi Moe Hinn Sd | D31: Hlaing thar Yar | H31: 23 | I31: 1 | N31: 5 | P31: =SUM(G31:O31) -> 29
A32: 10 | B32: Family | C32: Mandalay Lan Tawe | D32: Mangalar T/N | E32: Naw Kyi Phyu Thein | F32: 09-751050544 | H32: 1 | I32: 3 | P32: =SUM(G32:O32) -> 4
P33: =SUM(G33:O33) -> 0
P34: =SUM(G34:O34) -> 0
A35: 11 | B35: Zaw | C35: Kyan Sitt Thar Rd | D35: Hlaing Thar Yar | E35: Ma Ei May Thu | F35: 09 987339189 | G35: 1 | N35: 4 | P35: =SUM(G35:O35) -> 5
B36: Nay La | C36: Kyan Sitt Thar Rd | D36: Hlaing Thar Yar | H36: 32 | I36: 8 | N36: 59 | O36: 28 | P36: =SUM(G36:O36) -> 127
B37: Hlaing Min Htet | C37: Pi Moe Hinn Sd | D37: Hlaing thar Yar | H37: 19 | I37: 3 | M37: 1 | N37: 24 | O37: 10 | P37: =SUM(G37:O37) -> 57
A38: 12 | B38: Hlaing Bwar 2 | C38: Sake kan Thar Rd | D38: Hlaing Thar Yar | E38: Ma Zin Mar Phyo | F38: 09 404979290 | H38: 3 | N38: 1 | P38: =SUM(G38:O38) -> 4
B39: Nay La2 | C39: Sake kan Thar Rd | D39: Hlaing thar Yar | H39: 2 | N39: 7 | P39: =SUM(G39:O39) -> 9
B40: Shwe Htoo | C40: (1) Thake Sd | D40: Hlaing thar Yar | H40: 10 | I40: 2 | N40: 14 | O40: 1 | P40: =SUM(G40:O40) -> 27
A41: 13 | B41: Aung zay | C41: Nawe Thar Gi Rd | D41: N/Oakkala | E41: Ma Htet Htet Hlaing | F41: 09-675163225 | H41: 2 | N41: 3 | P41: =SUM(G41:O41) -> 5
...

Sheet Feb.monthly
A1: Yangon PG sale report February Monthly
A2: 1 | B2: Shop name | C2: Shop Address | D2: Township | E2: PG Name | F2: Ph.no | G2: Columbus Super red smooth | J2: Columbus Original | M2: Formula Rum | O2: ဒဂုံမန်ကျည်း | P2: Total
G3: 700ml | H3: 350ml | I3: 175ml | J3: 700ml | K3: 350ml | L3: 175ml | M3: 700ml | N3: 350ml
A5: 1 | B5: Plantinum | C5: Thamain Bamyan Rd | D5: Mangalar T/N | E5: Ma Thuzar Aung | F5: 09-898146525 | G5: 1 | H5: 2 | P5: =SUM(G5:O5) -> 3
B6: Hlaing Min | C6: Tan Day Pin Sd | D6: Htauk kyant | H6: 15 | I6: 12 | M6: 2 | N6: 11 | P6: =SUM(G6:O6) -> 40
B7: 29 | C7: Lan Thit Lan | D7: Htauk kyant | G7: 2 | H7: 25 | I7: 14 | M7: 3 | N7: 16 | P7: =SUM(G7:O7) -> 60
B8: Kaung Kin Think 2 | C8: MyintZuu Thaka Rd | D8: Mangalardon | G8: 1 | H8: 27 | I8: 18 | N8: 14 | P8: =SUM(G8:O8) -> 60
A9: 2 | B9: KK Store | C9: Bo Min Young Rd | D9: Mangalar T/N | E9: Ma Jue Jue Hlaing | F9: 09-986169990 | H9: 5 | I9: 4 | M9: 4 | N9: 6 | P9: =SUM(G9:O9) -> 19
B10: La Ware Thant | C10: Kar ya Sd | D10: Htauk kyant | G10: 1 | H10: 27 | I10: 14 | M10: 7 | N10: 56 | P10: =SUM(G10:O10) -> 105
B11: KK | C11: Oae Yin Sd | D11: Htauk kyant | G11: 7 | H11: 37 | I11: 4 | M11: 5 | N11: 25 | P11: =SUM(G11:O11) -> 78
B12: Su | C12: Aung Sinkhoe Rd | D12: Mangalardon | G12: 1 | H12: 42 | I12: 10 | M12: 2 | N12: 28 | P12: =SUM(G12:O12) -> 83
B13: Happy Day | C13: Padamyar Rd | D13: Mangalardon | H13: 26 | I13: 18 | M13: 5 | N13: 19 | P13: =SUM(G13:O13) -> 68
A14: 3 | B14: Paddue War | C14: Bayane naung Rd | D14: N/Oakkala | E14: Ma Nway Hnin Moe | F14: 09-983002374 | G14: 2 | H14: 7 | M14: 5 | N14: 8 | P14: =SUM(G14:O14) -> 22
B15: 29 | C15: Lan Thit Lan | D15: Htauk kyant | G15: 1 | H15: 28 | I15: 9 | M15: 4 | N15: 27 | P15: =SUM(G15:O15) -> 69
B16: La Ware Thant | C16: Kar ya Sd | D16: Htauk kyant | G16: 2 | H16: 32 | I16: 12 | M16: 1 | N16: 46 | P16: =SUM(G16:O16) -> 93
B17: Kaung Kin Think | C17: Joephyu Rd | D17: Mangalardon | H17: 9 | I17: 13 | M17: 1 | N17: 15 | P17: =SUM(G17:O17) -> 38
B18: Su | C18: Aung Sinkhoe Rd | D18: Mangalardon | H18: 26 | I18: 15 | M18: 2 | N18: 16 | P18: =SUM(G18:O18) -> 59
A19: 4 | B19: Style 2 | C19: Thamain Bamyan Rd | D19: Mangalar T/N | E19: Ma Hnin Pwint Phyu | F19: 09-773993352 | H19: 9 | M19: 1 | N19: 10 | P19: =SUM(G19:O19) -> 20
B20: Lue Gyi Min | C20: Bounk Gyi Sd | D20: Htauk kyant | G20: 6 | H20: 87 | I20: 38 | M20: 12 | N20: 114 | P20: =SUM(G20:O20) -> 257
B21: Y47 | C21: Tan Day Pin Sd | D21: Htauk kyant | G21: 1 | H21: 24 | M21: 2 | N21: 20 | P21: =SUM(G21:O21) -> 47
B22: Smile Moon | C22: Joephyu Rd | D22: Mangalardon | G22: 1 | H22: 12 | I22: 6 | N22: 7 | P22: =SUM(G22:O22) -> 26
B23: San Thit | C23: Joephyu Rd | D23: Mangalardon | G23: 4 | H23: 17 | I23: 22 | N23: 4 | P23: =SUM(G23:O23) -> 47
A24: 5 | B24: Aung Family | C24: SakeSan (9) Lan | D24: Mangalar T/N | E24: Ma Phyo Phyo Wai | F24: 09-774485332 | H24: 3 | M24: 2 | N24: 2 | P24: =SUM(G24:O24) -> 7
B25: Moe Thounk Pan | C25: Mya Yatu Sd | D25: Htauk kyant | G25: 1 | H25: 24 | I25: 16 | M25: 1 | N25: 20 | P25: =SUM(G25:O25) -> 62
B26: Hlaing Min | C26: Tan Day Pin Sd | D26: Htauk kyant | H26: 29 | I26: 10 | M26: 1 | N26: 11 | P26: =SUM(G26:O26) -> 51
B27: San Thit | C27: Joephyu Rd | D27: Mangalardon | G27: 2 | H27: 11 | I27: 11 | N27: 8 | P27: =SUM(G27:O27) -> 32
B28: Smile Moon | C28: Joephyu Rd | D28: Mangalardon | H28: 4 | I28: 2 | M28: 2 | P28: =SUM(G28:O28) -> 8
A29: 6 | B29: Demo | C29: Thamain Bamyan Rd | D29: Mangalar T/N | E29: Ma Sandar Hlaing | F29: 09-660417209 | H29: 7 | N29: 2 | P29: =SUM(G29:O29) -> 9
B30: Y47 | C30: Tan Day Pin Sd | D30: Htauk kyant | G30: 2 | H30: 22 | M30: 1 | N30: 16 | P30: =SUM(G30:O30) -> 41
B31: Moe Thounk Pan | C31: Mya Yatu Sd | D31: Htauk kyant | H31: 8 | I31: 31 | M31: 4 | N31: 17 | P31: =SUM(G31:O31) -> 60
B32: Shin Shin | C32: Joephyu Rd | D32: Mangalardon | H32: 3 | M32: 1 | N32: 7 | P32: =SUM(G32:O32) -> 11
B33: Shwe Yee Linn | C33: Padamyar Rd | D33: Mangalardon | H33: 14 | I33: 23 | N33: 16 | P33: =SUM(G33:O33) -> 53
A34: 7 | B34: Yar Pyae San | C34: Zay Rd | D34: Hlaing Thar Yar | E34: Ma Lae Lae Tun | F34: 09 677196046 | G34: 1 | M34: 3 | N34: 2 | P34: =SUM(G34:O34) -> 6
B35: Ngwe Khaing | C35: Baya Thinkyan Sd | D35: S/Okkala | G35: 1 | H35: 5 | M35: 1 | N35: 9 | P35: =SUM(G35:O35) -> 16
B36: Shine | C36: Loke Thar Sd | D36: S/Okkala | H36: 37 | M36: 2 | N36: 5 | P36: =SUM(G36:O36) -> 44
B37: Yarket Nu Wai | C37: Anake Gonkone Rd | D37: Insein | G37: 2 | H37: 14 | I37: 8 | M37: 1 | N37: 7 | P37: =SUM(G37:O37) -> 32
B38: Kayae Yake | C38: Nawayat Rd | D38: Insein | H38: 4 | I38: 8 | M38: 1 | N38: 6 | P38: =SUM(G38:O38) -> 19
A39: 8 | B39: ANT Store | C39: Sake kan Thar Rd | D39: Hlaing Thar Yar | E39: Ma Yee Mon Aung | F39: 09 953844858 | H39: 1 | N39: 7 | O39: 5 | P39: =SUM(G39:O39) -> 13
B40: 124 Store | C40: Padamyar Rd | D40: Hlaing Thar Yar | H40: 9 | N40: 24 | O40: 8 | P40: =SUM(G40:O40) -> 41
B41: Nat Thit Oo | C41: Take Htae Sd | D41: Hlaing thar Yar | H41: 12 | I41: 1 | M41: 1 | N41: 19 | O41: 8 | P41: =SUM(G41:O41) -> 41
...

Sheet 1.3.25-15.3.25
A1: Yangon PG sale report (1-3-2025) to (15-3-2025)
A2: 1 | B2: Shop name | C2: Shop Address | D2: Township | E2: PG Name | F2: Ph.no | G2: Columbus Super red smooth | J2: Columbus Original | M2: Formula Rum | O2: ဒဂုံမန်ကျည်း | P2: Total
G3: 700ml | H3: 350ml | I3: 175ml | J3: 700ml | K3: 350ml | L3: 175ml | M3: 700ml | N3: 350ml
A5: 1 | B5: Kaung Kin Think 2 | C5: MyintZuu Thaka Rd | D5: Mangalardon | E5: Ma Thuzar Aung | F5: 09-898146525 | H5: 6 | I5: 3 | N5: 1 | P5: =SUM(G5:O5) -> 10
B6: Sin Pauk | C6: Hlawaga Rd | D6: Shwepyithar | H6: 8 | I6: 4 | M6: 1 | N6: 8 | P6: =SUM(G6:O6) -> 21
B7: Chit Paing | C7: Bo Aung Kyaw Rd | D7: Hlaing Thar Yar Route (1) | G7: 1 | H7: 10 | I7: 4 | N7: 6 | O7: 5 | P7: =SUM(G7:O7) -> 26
A8: 2 | B8: Happy Day | C8: Padamyar Rd | D8: Mangalardon | E8: Ma Jue Jue Hlaing | F8: 09-986169990 | H8: 9 | I8: 6 | N8: 3 | P8: =SUM(G8:O8) -> 18
B9: Min Satae Kyatt | C9: Hlawaga Rd | D9: Shwepyithar | G9: 1 | H9: 34 | I9: 8 | M9: 3 | N9: 39 | P9: =SUM(G9:O9) -> 85
B10: Wine | C10: Hlawaga Rd | D10: Shwepyithar | G10: 4 | H10: 41 | I10: 18 | M10: 7 | N10: 33 | P10: =SUM(G10:O10) -> 103
A11: 3 | B11: Su | C11: Aung Sinkhoe Rd | D11: Mangalardon | E11: Ma Nway Hnin Moe | F11: 09-983002374 | H11: 6 | I11: 5 | N11: 7 | P11: =SUM(G11:O11) -> 18
B12: Yar Noune Pyay | C12: Hlawaga Rd | D12: Shwepyithar | H12: 13 | I12: 8 | M12: 7 | N12: 58 | P12: =SUM(G12:O12) -> 86
B13: Myintmo | C13: Bayin Naung Rd | D13: Shwepyithar | H13: 14 | I13: 11 | M13: 2 | N13: 30 | P13: =SUM(G13:O13) -> 57
A14: 4 | B14: San Thit | C14: Joephyu Rd | D14: Mangalardon | E14: Ma Hnin Pwint Phyu | F14: 09-773993352 | H14: 5 | I14: 10 | N14: 1 | P14: =SUM(G14:O14) -> 16
B15: Nan Htet | C15: Sitkaind Rd | D15: S Paukkan N/Oakkala | H15: 7 | I15: 2 | N15: 6 | P15: =SUM(G15:O15) -> 15
B16: 16 G(2) | C16: Taungnu Rd | D16: S Paukkan N/Oakkala | G16: 2 | H16: 31 | I16: 5 | M16: 2 | N16: 15 | P16: =SUM(G16:O16) -> 55
A17: 5 | B17: Smile Moon | C17: Joephyu Rd | D17: Mangalardon | E17: Ma Phyo Phyo Wai | F17: 09-774485332 | H17: 1 | N17: 2 | P17: =SUM(G17:O17) -> 3
B18: Myintmo | C18: Bayin Naung Rd | D18: Shwepyithar | H18: 32 | I18: 12 | M18: 1 | N18: 15 | P18: =SUM(G18:O18) -> 60
B19: KZ | C19: kantharyar Rd | D19: Shwepyithar | H19: 21 | I19: 15 | M19: 2 | N19: 16 | P19: =SUM(G19:O19) -> 54
A20: 6 | B20: Shwe Yee Linn | C20: Padamyar Rd | D20: Mangalardon | E20: Ma Sandar Hlaing | F20: 09-660417209 | H20: 3 | I20: 4 | P20: =SUM(G20:O20) -> 7
B21: Than Htet kyaw | C21: Palal rd | D21: Shwepyithar | H21: 23 | I21: 4 | M21: 1 | N21: 6 | P21: =SUM(G21:O21) -> 34
B22: Sin Pauk | C22: Hlawaga Rd | D22: Shwepyithar | G22: 2 | H22: 6 | I22: 1 | N22: 8 | P22: =SUM(G22:O22) -> 17
A23: 7 | B23: Kayae Yake | C23: Nawayat Rd | D23: Insein | E23: Ma Lae Lae Tun | F23: 09 677196046 | G23: 1 | H23: 2 | I23: 2 | N23: 4 | P23: =SUM(G23:O23) -> 9
B24: Nan Htet | C24: Sitkaind Rd | D24: S Paukkan N/Oakkala | H24: 18 | I24: 15 | M24: 2 | N24: 23 | P24: =SUM(G24:O24) -> 58
B25: Htet Lwin | C25: Bagan Rd | D25: S Paukkan N/Oakkala | H25: 23 | I25: 19 | N25: 17 | P25: =SUM(G25:O25) -> 59
A26: 8 | B26: Pan Nadi Hlaing (2) | C26: Chit Kyi Yae Rd | D26: Hlaing thar Yar | E26: Ma Yee Mon Aung | F26: 09 953844858 | H26: 2 | I26: 1 | N26: 2 | P26: =SUM(G26:O26) -> 5
B27: Nge paung | C27: Bo Aung Kyaw Rd | D27: Hlaingtharyar | G27: 1 | H27: 10 | I27: 5 | M27: 4 | N27: 24 | O27: 5 | P27: =SUM(G27:O27) -> 49
B28: Pyae Maher | C28: Bo Aung Kyaw Rd | D28: Hlaingtharyar | G28: 1 | H28: 6 | I28: 4 | M28: 2 | N28: 27 | O28: 39 | P28: =SUM(G28:O28) -> 79
A29: 9 | B29: GC | C29: Bo Aung Kyaw Rd | D29: Hlaing thar Yar | E29: Ma Shwe Sin Win | F29: 09 697220669 | H29: 4 | I29: 1 | N29: 4 | O29: 1 | P29: =SUM(G29:O29) -> 10
B30: Soon Pyan | C30: Bo Aung Kyaw Rd | D30: Hlaing Thar Yar Route (1) | H30: 14 | N30: 3 | O30: 7 | P30: =SUM(G30:O30) -> 24
B31: Yazar | C31: Mandalay Rd | D31: Hlaing Thar Yar Route (1) | G31: 1 | H31: 5 | I31: 4 | N31: 5 | O31: 3 | P31: =SUM(G31:O31) -> 18
A32: 10 | B32: Shin Shin | C32: Joephyu Rd | D32: Mangalardon | E32: Naw Kyi Phyu Thein | F32: 09-751050544 | H32: 3 | I32: 2 | M32: 2 | N32: 2 | P32: =SUM(G32:O32) -> 9
B33: Wine | C33: Hlawaga Rd | D33: Shwepyithar | G33: 4 | H33: 55 | I33: 7 | M33: 8 | N33: 28 | P33: =SUM(G33:O33) -> 102
B34: Than Htet kyaw | C34: Palal rd | D34: Shwepyithar | G34: 2 | H34: 19 | I34: 7 | N34: 12 | P34: =SUM(G34:O34) -> 40
A35: 11 | B35: Linn | C35: Bo Aung Kyaw Rd | D35: Hlaing Thar Yar Route (1) | E35: Ma Ei May Thu | F35: 09 987339189 | H35: 3 | N35: 18 | P35: =SUM(G35:O35) -> 21
B36: Chit Paing | C36: Bo Aung Kyaw Rd | D36: Hlaing Thar Yar Route (1) | H36: 12 | I36: 1 | N36: 25 | O36: 12 | P36: =SUM(G36:O36) -> 50
B37: Thaka Kyi | C37: Mandalay Rd | D37: Hlaing Thar Yar Route (1) | H37: 10 | I37: 3 | N37: 56 | O37: 2 | P37: =SUM(G37:O37) -> 71
A38: 12 | B38: Pan Nadi Hlaing (1) | C38: Taungnu Rd | D38: Hlaing thar Yar | E38: Ma Zin Mar Phyo | F38: 09 404979290 | H38: 3 | I38: 2 | N38: 9 | P38: =SUM(G38:O38) -> 14
B39: Pan Nadi Hlaing (2) | C39: Chit Kyi Yae Rd | D39: Hlaing thar Yar | H39: 26 | M39: 1 | N39: 10 | O39: 3 | P39: =SUM(G39:O39) -> 40
B40: Shwe Payi(1) | C40: Mandalay Rd | D40: Hlaing Thar Yar Route (1) | H40: 8 | N40: 8 | P40: =SUM(G40:O40) -> 16
A41: 13 | B41: AhTwae Thit | C41: Chit Kyi Yae Rd | D41: Hlaing thar Yar | E41: Ma Htet Htet Hlaing | F41: 09-675163225 | H41: 3 | I41: 6 | P41: =SUM(G41:O41) -> 9
...

Sheet March- Monthly
A1: Yangon PG sale report March monthly
A2: 1 | B2: Shop name | C2: Shop Address | D2: Township | E2: PG Name | F2: Ph.no | G2: Columbus Super red smooth | J2: Columbus Original | M2: Formula Rum | O2: ဒဂုံမန်ကျည်း | P2: Total
G3: 700ml | H3: 350ml | I3: 175ml | J3: 700ml | K3: 350ml | L3: 175ml | M3: 700ml | N3: 350ml
A5: 1 | B5: Kaung Kin Think 2 | C5: MyintZuu Thaka Rd | D5: Mangalardon | E5: Ma Thuzar Aung | F5: 09-898146525 | H5: 6 | I5: 3 | N5: 1 | P5: =SUM(G5:O5) -> 10
B6: Sin Pauk | C6: Hlawaga Rd | D6: Shwepyithar | H6: 8 | I6: 4 | M6: 1 | N6: 8 | P6: =SUM(G6:O6) -> 21
B7: Chit Paing | C7: Bo Aung Kyaw Rd | D7: Hlaing Thar Yar Route (1) | G7: 1 | H7: 10 | I7: 4 | N7: 6 | O7: 5 | P7: =SUM(G7:O7) -> 26
B8: Nyein Nwe | C8: Innwa Rd | D8: N/Oakkala | G8: 1 | H8: 45 | I8: 9 | N8: 13 | P8: =SUM(G8:O8) -> 68
B9: Shwe Lawone | C9: Ye Yanaing Rd | D9: Shwepyithar | H9: 25 | I9: 3 | N9: 6 | P9: =SUM(G9:O9) -> 34
B10: Ka Dai Hein | C10: Kan Bae Botar Zay Rd | D10: YanKin | H10: 2 | I10: 3 | M10: 2 | N10: 5 | P10: =SUM(G10:O10) -> 12
A11: 2 | B11: Happy Day | C11: Padamyar Rd | D11: Mangalardon | E11: Ma Jue Jue Hlaing | F11: 09-986169990 | H11: 9 | I11: 6 | N11: 3 | P11: =SUM(G11:O11) -> 18
B12: Min Satae Kyatt | C12: Hlawaga Rd | D12: Shwepyithar | G12: 1 | H12: 34 | I12: 8 | M12: 3 | N12: 39 | P12: =SUM(G12:O12) -> 85
B13: Wine | C13: Hlawaga Rd | D13: Shwepyithar | G13: 4 | H13: 41 | I13: 18 | M13: 7 | N13: 33 | P13: =SUM(G13:O13) -> 103
B14: Kaung | C14: Nuaung Yann Rd | D14: S Paukkan N/Oakkala | G14: 1 | H14: 36 | I14: 6 | M14: 4 | N14: 43 | P14: =SUM(G14:O14) -> 90
B15: Cheer | C15: ThanDin Zay Rd | D15: Shwepyithar | G15: 1 | H15: 58 | I15: 4 | N15: 28 | P15: =SUM(G15:O15) -> 91
B16: Aung Family | C16: SakeSan (9) Lan | D16: Mangalar T/N | H16: 3 | M16: 1 | N16: 5 | P16: =SUM(G16:O16) -> 9
A17: 3 | B17: Su | C17: Aung Sinkhoe Rd | D17: Mangalardon | E17: Ma Nway Hnin Moe | F17: 09-983002374 | H17: 6 | I17: 5 | N17: 7 | P17: =SUM(G17:O17) -> 18
B18: Yar Noune Pyay | C18: Hlawaga Rd | D18: Shwepyithar | H18: 13 | I18: 8 | M18: 7 | N18: 58 | P18: =SUM(G18:O18) -> 86
B19: Myintmo | C19: Bayin Naung Rd | D19: Shwepyithar | H19: 14 | I19: 11 | M19: 2 | N19: 30 | P19: =SUM(G19:O19) -> 57
B20: Malar | C20: Innwa Rd | D20: N/Oakkala | G20: 1 | H20: 23 | I20: 11 | M20: 1 | N20: 10 | P20: =SUM(G20:O20) -> 46
B21: NI Ni Poe poe | C21: Ye Yanaing Rd | D21: Shwepyithar | H21: 38 | I21: 4 | M21: 15 | N21: 66 | P21: =SUM(G21:O21) -> 123
B22: Moe Htety | C22: S Paukkan Rd | D22: S Paukkan N/Oakkala | H22: 13 | N22: 4 | P22: =SUM(G22:O22) -> 17
A23: 4 | B23: San Thit | C23: Joephyu Rd | D23: Mangalardon | E23: Ma Hnin Pwint Phyu | F23: 09-773993352 | H23: 5 | I23: 10 | N23: 1 | P23: =SUM(G23:O23) -> 16
B24: Nan Htet | C24: Sitkaind Rd | D24: S Paukkan N/Oakkala | H24: 7 | I24: 2 | N24: 6 | P24: =SUM(G24:O24) -> 15
B25: 16 G(2) | C25: Taungnu Rd | D25: S Paukkan N/Oakkala | G25: 2 | H25: 31 | I25: 5 | M25: 2 | N25: 15 | P25: =SUM(G25:O25) -> 55
B26: Paddue War | C26: Bayane naung Rd | D26: N/Oakkala | H26: 44 | I26: 11 | M26: 1 | N26: 27 | P26: =SUM(G26:O26) -> 83
B27: Htar Ware htat | C27: Ae Ta ka (1) Rd | D27: N/Oakkala | G27: 3 | H27: 32 | M27: 1 | N27: 12 | P27: =SUM(G27:O27) -> 48
B28: Naung Yoe | C28: Thamain Bamyan Rd | D28: Mangalar T/N | H28: 8 | M28: 1 | N28: 4 | P28: =SUM(G28:O28) -> 13
A29: 5 | B29: Smile Moon | C29: Joephyu Rd | D29: Mangalardon | E29: Ma Phyo Phyo Wai | F29: 09-774485332 | H29: 1 | N29: 2 | P29: =SUM(G29:O29) -> 3
B30: Myintmo | C30: Bayin Naung Rd | D30: Shwepyithar | H30: 32 | I30: 12 | M30: 1 | N30: 15 | P30: =SUM(G30:O30) -> 60
B31: KZ | C31: kantharyar Rd | D31: Shwepyithar | H31: 21 | I31: 15 | M31: 2 | N31: 16 | P31: =SUM(G31:O31) -> 54
B32: Sakarwar 1 | C32: Lan Wa Rd | D32: N/Oakkala | H32: 16 | I32: 6 | M32: 8 | N32: 8 | P32: =SUM(G32:O32) -> 38
B33: Kyi Thar Oo(2) | C33: Bayin Naung St | D33: Htan Ta Pin | G33: 1 | H33: 1 | I33: 2 | M33: 4 | N33: 12 | P33: =SUM(G33:O33) -> 20
B34: Style 2 | C34: Thamain Bamyan Rd | D34: Mangalar T/N | H34: 9 | M34: 3 | N34: 6 | P34: =SUM(G34:O34) -> 18
A35: 6 | B35: Shwe Yee Linn | C35: Padamyar Rd | D35: Mangalardon | E35: Ma Sandar Hlaing | F35: 09-660417209 | H35: 3 | I35: 4 | P35: =SUM(G35:O35) -> 7
B36: Than Htet kyaw | C36: Palal rd | D36: Shwepyithar | H36: 23 | I36: 4 | M36: 1 | N36: 6 | P36: =SUM(G36:O36) -> 34
B37: Sin Pauk | C37: Hlawaga Rd | D37: Shwepyithar | G37: 2 | H37: 6 | I37: 1 | N37: 8 | P37: =SUM(G37:O37) -> 17
B38: Htar Ware htat | C38: Ae Ta ka (1) Rd | D38: N/Oakkala | H38: 6 | I38: 5 | P38: =SUM(G38:O38) -> 11
B39: U Myint Soe | C39: Danyaekone Rd | D39: Shwepyithar | G39: 1 | H39: 13 | I39: 4 | M39: 6 | N39: 56 | P39: =SUM(G39:O39) -> 80
B40: Demo | C40: Thamain Bamyan Rd | D40: Mangalar T/N | H40: 7 | P40: =SUM(G40:O40) -> 7
A41: 7 | B41: Kayae Yake | C41: Nawayat Rd | D41: Insein | E41: Ma Lae Lae Tun | F41: 09 677196046 | G41: 1 | H41: 2 | I41: 2 | N41: 4 | P41: =SUM(G41:O41) -> 9
...

Sheet 1.4.2025 to 15.4.2025
A1: Yangon PG sale report (1-4-2025) to (15-4-2025)
A2: 1 | B2: Shop name | C2: Shop Address | D2: Township | E2: PG Name | F2: Ph.no | G2: Columbus Super red smooth | J2: Columbus Original | M2: Formula Rum | O2: ဒဂုံမန်ကျည်း | P2: Total
G3: 700ml | H3: 350ml | I3: 175ml | J3: 700ml | K3: 350ml | L3: 175ml | M3: 700ml | N3: 350ml
A5: 1 | B5: Ka Dai Hein | C5: Kan Bae Botar Zay Rd | D5: YanKin | E5: Ma Thuzar Aung | F5: 09-898146525 | G5: 1 | H5: 7 | I5: 7 | M5: 2 | N5: 19 | P5: =SUM(G5:O5) -> 36
B6: Naung Yoe | C6: Thamain Bamyan Rd | D6: Mangalar T/N | H6: 21 | N6: 21 | P6: =SUM(G6:O6) -> 42
P7: =SUM(G7:O7) -> 0
P8: =SUM(G8:O8) -> 0
A9: 2 | B9: Aung Family | C9: SakeSan (9) Lan | D9: Mangalar T/N | E9: Ma Jue Jue Hlaing | F9: 09-986169990 | G9: 1 | H9: 27 | M9: 1 | N9: 31 | P9: =SUM(G9:O9) -> 60
B10: Style 2 | C10: Thamain Bamyan Rd | D10: Mangalar T/N | H10: 41 | M10: 2 | N10: 38 | P10: =SUM(G10:O10) -> 81
P11: =SUM(G11:O11) -> 0
P12: =SUM(G12:O12) -> 0
A13: 3 | B13: Moe Htety | C13: S Paukkan Rd | D13: S Paukkan N/Oakkala | E13: Ma Nway Hnin Moe | F13: 09-983002374 | G13: 1 | H13: 35 | M13: 4 | N13: 24 | P13: =SUM(G13:O13) -> 64
B14: Uncle Liquor | C14: Bonmoer Rd | D14: N/Oakkala | G14: 3 | H14: 37 | M14: 2 | N14: 38 | P14: =SUM(G14:O14) -> 80
P15: =SUM(G15:O15) -> 0
P16: =SUM(G16:O16) -> 0
A17: 4 | B17: Naung Yoe | C17: Thamain Bamyan Rd | D17: Mangalar T/N | E17: Ma Hnin Pwint Phyu | F17: 09-773993352 | G17: 1 | H17: 49 | M17: 2 | N17: 26 | P17: =SUM(G17:O17) -> 78
B18: Aung Family | C18: SakeSan (9) Lan | D18: Mangalar T/N | H18: 26 | N18: 23 | P18: =SUM(G18:O18) -> 49
P19: =SUM(G19:O19) -> 0
P20: =SUM(G20:O20) -> 0
A21: 5 | B21: Style 2 | C21: Thamain Bamyan Rd | D21: Mangalar T/N | E21: Ma Phyo Phyo Wai | F21: 09-774485332 | G21: 1 | H21: 31 | M21: 3 | N21: 29 | P21: =SUM(G21:O21) -> 64
B22: Demo | C22: Thamain Bamyan Rd | D22: Mangalar T/N | G22: 1 | H22: 21 | M22: 3 | N22: 2 | P22: =SUM(G22:O22) -> 27
P23: =SUM(G23:O23) -> 0
P24: =SUM(G24:O24) -> 0
A25: 6 | B25: Demo | C25: Thamain Bamyan Rd | D25: Mangalar T/N | E25: Ma Sandar Hlaing | F25: 09-660417209 | G25: 3 | H25: 16 | M25: 3 | P25: =SUM(G25:O25) -> 22
B26: Ah Linn Nike | C26: ThitSar Rd | D26: YanKin | H26: 30 | N26: 3 | P26: =SUM(G26:O26) -> 33
P27: =SUM(G27:O27) -> 0
P28: =SUM(G28:O28) -> 0
A29: 7 | B29: Pyae Wa | C29: S Paukkan Rd | D29: S Paukkan N/Oakkala | E29: Ma Lae Lae Tun | F29: 09 677196046 | H29: 8 | N29: 11 | P29: =SUM(G29:O29) -> 19
B30: Nate Thint | C30: Bayin Naung St | D30: Htan Ta Pin | G30: 2 | H30: 9 | I30: 12 | M30: 6 | N30: 25 | P30: =SUM(G30:O30) -> 54
P31: =SUM(G31:O31) -> 0
P32: =SUM(G32:O32) -> 0
A33: 8 | B33: Nate Thint | C33: Bayin Naung St | D33: Htan Ta Pin | E33: Ma Yee Mon Aung | F33: 09 953844858 | G33: 3 | H33: 15 | I33: 10 | N33: 29 | P33: =SUM(G33:O33) -> 57
B34: Lapyae Wunn | C34: West Yangon University Rd | D34: Htan Ta Pin | G34: 5 | H34: 33 | M34: 13 | N34: 114 | P34: =SUM(G34:O34) -> 165
P35: =SUM(G35:O35) -> 0
A36: 9 | B36: Kaung Star | C36: West Yangon University Rd | D36: Htan Ta Pin | E36: Ma Shwe Sin Win | F36: 09 697220669 | G36: 3 | H36: 10 | M36: 4 | N36: 31 | P36: =SUM(G36:O36) -> 48
B37: Ni Ni Lin | C37: Myoma Zay Rd | D37: Htan Ta Pin | G37: 1 | H37: 12 | N37: 42 | P37: =SUM(G37:O37) -> 55
P38: =SUM(G38:O38) -> 0
P39: =SUM(G39:O39) -> 0
A40: 10 | B40: Ah Linn Nike | C40: ThitSar Rd | D40: YanKin | E40: Naw Kyi Phyu Thein | F40: 09-751050544 | G40: 4 | H40: 44 | N40: 9 | P40: =SUM(G40:O40) -> 57
B41: Ka Dai Hein | C41: Kan Bae Botar Zay Rd | D41: YanKin | G41: 3 | H41: 9 | M41: 1 | N41: 22 | P41: =SUM(G41:O41) -> 35
...

Sheet April-Monthly
A1: Yangon PG sale report April Monthly
A2: 1 | B2: Shop name | C2: Shop Address | D2: Township | E2: PG Name | F2: Ph.no | G2: Columbus Super red smooth | J2: Columbus Original | M2: Formula Rum | O2: ဒဂုံမန်ကျည်း | P2: Total
G3: 700ml | H3: 350ml | I3: 175ml | J3: 700ml | K3: 350ml | L3: 175ml | M3: 700ml | N3: 350ml
A5: 1 | B5: Ka Dai Hein | C5: Kan Bae Botar Zay Rd | D5: YanKin | E5: Ma Thuzar Aung | F5: 09-898146525 | G5: 1 | H5: 7 | I5: 7 | M5: 2 | N5: 19 | P5: =SUM(G5:O5) -> 36
B6: Naung Yoe | C6: Thamain Bamyan Rd | D6: Mangalar T/N | H6: 21 | N6: 21 | P6: =SUM(G6:O6) -> 42
B7: Moe Thounk Pan | C7: Mya Yatu Sd | D7: Htauk kyant | G7: 1 | H7: 27 | M7: 1 | N7: 21 | P7: =SUM(G7:O7) -> 50
B8: KK | C8: Oae Yin Sd | D8: Htauk kyant | H8: 9 | M8: 1 | N8: 1 | P8: =SUM(G8:O8) -> 11
A9: 2 | B9: Aung Family | C9: SakeSan (9) Lan | D9: Mangalar T/N | E9: Ma Jue Jue Hlaing | F9: 09-986169990 | G9: 1 | H9: 27 | M9: 1 | N9: 31 | P9: =SUM(G9:O9) -> 60
B10: Style 2 | C10: Thamain Bamyan Rd | D10: Mangalar T/N | H10: 41 | M10: 2 | N10: 38 | P10: =SUM(G10:O10) -> 81
B11: Nagarni | C11: Tan Day Pin Sd | D11: Htauk kyant | G11: 8 | H11: 9 | M11: 2 | N11: 14 | P11: =SUM(G11:O11) -> 33
B12: Moe Thounk Pan | C12: Mya Yatu Sd | D12: Htauk kyant | H12: 21 | M12: 6 | N12: 8 | P12: =SUM(G12:O12) -> 35
A13: 3 | B13: Moe Htety | C13: S Paukkan Rd | D13: S Paukkan N/Oakkala | E13: Ma Nway Hnin Moe | F13: 09-983002374 | G13: 1 | H13: 35 | M13: 4 | N13: 24 | P13: =SUM(G13:O13) -> 64
B14: Uncle Liquor | C14: Bonmoer Rd | D14: N/Oakkala | G14: 3 | H14: 37 | M14: 2 | N14: 38 | P14: =SUM(G14:O14) -> 80
B15: Ma Thwe | C15: Nawayat Rd | D15: Insein | H15: 5 | N15: 3 | P15: =SUM(G15:O15) -> 8
B16: Ko Kyaw | C16: Magin Kyawan Rd | D16: Insein | G16: 1 | H16: 1 | N16: 7 | P16: =SUM(G16:O16) -> 9
B17: A&T | C17: Pa 50 Lan Baho | D17: Hlaing | H17: 7 | M17: 2 | N17: 7 | P17: =SUM(G17:O17) -> 16
A18: 4 | B18: Naung Yoe | C18: Thamain Bamyan Rd | D18: Mangalar T/N | E18: Ma Hnin Pwint Phyu | F18: 09-773993352 | G18: 1 | H18: 49 | M18: 2 | N18: 26 | P18: =SUM(G18:O18) -> 78
